Log file created at: 2021/07/21 18:34:41
Running on machine: gpu4
Binary: Built with gc go1.13.15 for linux/amd64
Log line format: [IWEF]mmdd hh:mm:ss.uuuuuu threadid file:line] msg
I0721 18:34:41.451553    1186 main.go:19]  "msg"="Celeste - DLT jobs scheduler"  "version"="0.0.1"
I0721 18:34:41.452575    1186 main.go:20]  "msg"="Starting service"  
I0721 18:34:41.458156    1186 placement_manager.go:65]  "msg"="Starting placement manager"  "scheduler"="default"
I0721 18:34:41.458614    1186 placement_manager.go:95]  "msg"="Started placement manager"  "nodes"={"gpu3":{},"gpu4":{},"gpu5":{}} "scheduler"="default"
I0721 18:34:41.459110    1186 jobmaster.go:82]  "msg"="Starting scheduler"  "gpuType"="default"
I0721 18:34:41.459271    1186 scheduler.go:124]  "msg"="Starting scheduler"  "scheduler"="default"
I0721 18:34:41.489965    1186 scheduler.go:432]  "msg"="Start watching mpijob"  "scheduler"="default"
I0721 18:34:48.722494    1186 jobmaster.go:155]  "msg"="Training job created"  "job"="tf2-keras-cifar10-inceptionv3-elastic-20210721-063448"
I0721 18:34:48.722699    1186 scheduler.go:135]  "msg"="Received resched event, may be blocked because of rate limit"  "blockedUntil"="2021-07-21T18:34:41.459094175+08:00" "lastResched"="2021-07-21T18:34:41.459094285+08:00" "received"="2021-07-21T18:34:48.721607529+08:00" "scheduler"="default"
I0721 18:34:48.723409    1186 scheduler.go:159]  "msg"="Started resched"  "scheduler"="default"
I0721 18:34:48.723488    1186 scheduler.go:193]  "msg"="Updating all jobs info"  "scheduler"="default"
I0721 18:34:48.725215    1186 elastic_tiresias.go:160]  "msg"="Finished scheduling"  "algorithm"="ElasticTiresias" "compactionThreshold"=4 "freeGpu"=8 "promoteKnob"=4 "queueNum"=2 "result"={"tf2-keras-cifar10-inceptionv3-elastic-20210721-063448":4} "scheduler"="default" "thresholds"=
I0721 18:34:48.725592    1186 scheduler.go:384]  "msg"="Trying to delete multiple training jobs"  "jobs"=[] "scheduler"="default"
I0721 18:34:48.725891    1186 scheduler.go:342]  "msg"="Trying to scale multiple training jobs"  "jobs"=[] "scheduler"="default"
I0721 18:34:48.726224    1186 scheduler.go:292]  "msg"="Trying to start multiple training jobs"  "jobs"=["tf2-keras-cifar10-inceptionv3-elastic-20210721-063448"] "scheduler"="default"
I0721 18:34:48.749746    1186 scheduler.go:342]  "msg"="Trying to scale multiple training jobs"  "jobs"=[] "scheduler"="default"
I0721 18:34:48.751995    1186 placement_manager.go:166]  "msg"="Started job placements adjustment"  "scheduler"="default"
I0721 18:34:48.752138    1186 placement_manager.go:192]  "msg"="Releasing slots"  "jobs"={} "nodes"={"gpu3":{},"gpu4":{},"gpu5":{}} "scheduler"="default"
I0721 18:34:48.752185    1186 placement_manager.go:250]  "msg"="Released slots"  "jobs"={} "nodes"={"gpu3":{},"gpu4":{},"gpu5":{}} "scheduler"="default"
I0721 18:34:48.752614    1186 placement_manager.go:305]  "msg"="Found best-fit"  "crossNode"=0 "nodes"=[{},{},{}] "requests"=[{},{}] "scheduler"="default"
I0721 18:34:48.753004    1186 placement_manager.go:339]  "msg"="nodeStates updated"  "new"={"gpu3":{},"gpu4":{},"gpu5":{}} "old"={"gpu3":{},"gpu4":{},"gpu5":{}} "scheduler"="default" "score"=0
I0721 18:34:48.753317    1186 placement_manager.go:387]  "msg"="jobStates updated"  "new"={"tf2-keras-cifar10-inceptionv3-elastic-20210721-063448":{}} "old"={} "scheduler"="default"
I0721 18:34:48.753764    1186 placement_manager.go:434]  "msg"="podNodeName updated"  "launchersToDelete"=0 "new"={"tf2-keras-cifar10-inceptionv3-elastic-20210721-063448-worker-0":"gpu5","tf2-keras-cifar10-inceptionv3-elastic-20210721-063448-worker-1":"gpu5","tf2-keras-cifar10-inceptionv3-elastic-20210721-063448-worker-2":"gpu5","tf2-keras-cifar10-inceptionv3-elastic-20210721-063448-worker-3":"gpu5"} "old"={} "scheduler"="default" "workersToDelete"=0
I0721 18:34:48.754170    1186 placement_manager.go:183]  "msg"="Finished job placements adjustment"  "scheduler"="default"
I0721 18:34:48.754538    1186 scheduler.go:182]  "msg"="Finished resched"  "scheduler"="default"
I0721 18:34:48.828330    1186 placement_manager.go:147]  "msg"="Adding toleration to pod"  "podName"="tf2-keras-cifar10-inceptionv3-elastic-20210721-063448-worker-0" "scheduler"="default" "toleration"={"key":"celeste/hostname","operator":"Equal","value":"gpu5","effect":"NoExecute"}
I0721 18:34:48.837064    1186 placement_manager.go:147]  "msg"="Adding toleration to pod"  "podName"="tf2-keras-cifar10-inceptionv3-elastic-20210721-063448-worker-1" "scheduler"="default" "toleration"={"key":"celeste/hostname","operator":"Equal","value":"gpu5","effect":"NoExecute"}
I0721 18:34:48.846243    1186 placement_manager.go:147]  "msg"="Adding toleration to pod"  "podName"="tf2-keras-cifar10-inceptionv3-elastic-20210721-063448-worker-2" "scheduler"="default" "toleration"={"key":"celeste/hostname","operator":"Equal","value":"gpu5","effect":"NoExecute"}
I0721 18:34:48.859015    1186 placement_manager.go:147]  "msg"="Adding toleration to pod"  "podName"="tf2-keras-cifar10-inceptionv3-elastic-20210721-063448-worker-3" "scheduler"="default" "toleration"={"key":"celeste/hostname","operator":"Equal","value":"gpu5","effect":"NoExecute"}
I0721 18:34:48.872545    1186 placement_manager.go:147]  "msg"="Adding toleration to pod"  "podName"="tf2-keras-cifar10-inceptionv3-elastic-20210721-063448-launcher" "scheduler"="default" "toleration"={"key":"celeste/hostname","operator":"Exists","effect":"NoExecute"}
I0721 18:35:11.665089    1186 jobmaster.go:155]  "msg"="Training job created"  "job"="tf2-keras-cifar10-resnet50-elastic-20210721-063511"
I0721 18:35:11.665230    1186 scheduler.go:135]  "msg"="Received resched event, may be blocked because of rate limit"  "blockedUntil"="2021-07-21T18:36:48.754781452+08:00" "lastResched"="2021-07-21T18:34:48.754781452+08:00" "received"="2021-07-21T18:35:11.664430881+08:00" "scheduler"="default"
I0721 18:35:39.693627    1186 jobmaster.go:155]  "msg"="Training job created"  "job"="tf2-keras-cifar10-inceptionv3-elastic-20210721-063539"
I0721 18:36:09.570198    1186 jobmaster.go:155]  "msg"="Training job created"  "job"="tf2-keras-cifar10-vgg16-elastic-20210721-063609"
I0721 18:36:31.491369    1186 jobmaster.go:155]  "msg"="Training job created"  "job"="tf2-keras-cifar10-vgg16-elastic-20210721-063631"
I0721 18:36:48.754908    1186 scheduler.go:159]  "msg"="Started resched"  "scheduler"="default"
I0721 18:36:48.754975    1186 scheduler.go:193]  "msg"="Updating all jobs info"  "scheduler"="default"
I0721 18:36:48.760449    1186 elastic_tiresias.go:160]  "msg"="Finished scheduling"  "algorithm"="ElasticTiresias" "compactionThreshold"=4 "freeGpu"=0 "promoteKnob"=4 "queueNum"=2 "result"={"tf2-keras-cifar10-inceptionv3-elastic-20210721-063448":3,"tf2-keras-cifar10-inceptionv3-elastic-20210721-063539":3,"tf2-keras-cifar10-resnet50-elastic-20210721-063511":2,"tf2-keras-cifar10-vgg16-elastic-20210721-063609":2,"tf2-keras-cifar10-vgg16-elastic-20210721-063631":2} "scheduler"="default" "thresholds"=
I0721 18:36:48.760939    1186 scheduler.go:384]  "msg"="Trying to delete multiple training jobs"  "jobs"=[] "scheduler"="default"
I0721 18:36:48.761269    1186 scheduler.go:342]  "msg"="Trying to scale multiple training jobs"  "jobs"=["tf2-keras-cifar10-inceptionv3-elastic-20210721-063448"] "scheduler"="default"
I0721 18:36:48.780512    1186 scheduler.go:292]  "msg"="Trying to start multiple training jobs"  "jobs"=["tf2-keras-cifar10-inceptionv3-elastic-20210721-063539","tf2-keras-cifar10-vgg16-elastic-20210721-063609","tf2-keras-cifar10-vgg16-elastic-20210721-063631","tf2-keras-cifar10-resnet50-elastic-20210721-063511"] "scheduler"="default"
I0721 18:36:48.824806    1186 scheduler.go:342]  "msg"="Trying to scale multiple training jobs"  "jobs"=[] "scheduler"="default"
I0721 18:36:48.827920    1186 placement_manager.go:166]  "msg"="Started job placements adjustment"  "scheduler"="default"
I0721 18:36:48.828036    1186 placement_manager.go:192]  "msg"="Releasing slots"  "jobs"={"tf2-keras-cifar10-inceptionv3-elastic-20210721-063448":{}} "nodes"={"gpu3":{},"gpu4":{},"gpu5":{}} "scheduler"="default"
I0721 18:36:48.828103    1186 placement_manager.go:250]  "msg"="Released slots"  "jobs"={"tf2-keras-cifar10-inceptionv3-elastic-20210721-063448":{}} "nodes"={"gpu3":{},"gpu4":{},"gpu5":{}} "scheduler"="default"
I0721 18:36:48.828565    1186 placement_manager.go:305]  "msg"="Found best-fit"  "crossNode"=0 "nodes"=[{},{},{}] "requests"=[{},{},{},{},{},{},{},{},{},{}] "scheduler"="default"
I0721 18:36:48.828893    1186 placement_manager.go:339]  "msg"="nodeStates updated"  "new"={"gpu3":{},"gpu4":{},"gpu5":{}} "old"={"gpu3":{},"gpu4":{},"gpu5":{}} "scheduler"="default" "score"=3
I0721 18:36:48.829276    1186 placement_manager.go:387]  "msg"="jobStates updated"  "new"={"tf2-keras-cifar10-inceptionv3-elastic-20210721-063448":{},"tf2-keras-cifar10-inceptionv3-elastic-20210721-063539":{},"tf2-keras-cifar10-resnet50-elastic-20210721-063511":{},"tf2-keras-cifar10-vgg16-elastic-20210721-063609":{},"tf2-keras-cifar10-vgg16-elastic-20210721-063631":{}} "old"={"tf2-keras-cifar10-inceptionv3-elastic-20210721-063448":{}} "scheduler"="default"
I0721 18:36:48.829781    1186 placement_manager.go:434]  "msg"="podNodeName updated"  "launchersToDelete"=0 "new"={"tf2-keras-cifar10-inceptionv3-elastic-20210721-063448-worker-0":"gpu5","tf2-keras-cifar10-inceptionv3-elastic-20210721-063448-worker-1":"gpu5","tf2-keras-cifar10-inceptionv3-elastic-20210721-063448-worker-2":"gpu5","tf2-keras-cifar10-inceptionv3-elastic-20210721-063539-worker-0":"gpu3","tf2-keras-cifar10-inceptionv3-elastic-20210721-063539-worker-1":"gpu3","tf2-keras-cifar10-inceptionv3-elastic-20210721-063539-worker-2":"gpu3","tf2-keras-cifar10-resnet50-elastic-20210721-063511-worker-0":"gpu4","tf2-keras-cifar10-resnet50-elastic-20210721-063511-worker-1":"gpu4","tf2-keras-cifar10-vgg16-elastic-20210721-063609-worker-0":"gpu4","tf2-keras-cifar10-vgg16-elastic-20210721-063609-worker-1":"gpu4","tf2-keras-cifar10-vgg16-elastic-20210721-063631-worker-0":"gpu3","tf2-keras-cifar10-vgg16-elastic-20210721-063631-worker-1":"gpu3","tf2-keras-cifar10-vgg16-elastic-20210721-063631-worker-2":"gpu5"} "old"={"tf2-keras-cifar10-inceptionv3-elastic-20210721-063448-worker-0":"gpu5","tf2-keras-cifar10-inceptionv3-elastic-20210721-063448-worker-1":"gpu5","tf2-keras-cifar10-inceptionv3-elastic-20210721-063448-worker-2":"gpu5","tf2-keras-cifar10-inceptionv3-elastic-20210721-063448-worker-3":"gpu5"} "scheduler"="default" "workersToDelete"=0
I0721 18:36:48.830235    1186 placement_manager.go:183]  "msg"="Finished job placements adjustment"  "scheduler"="default"
I0721 18:36:48.830579    1186 scheduler.go:182]  "msg"="Finished resched"  "scheduler"="default"
I0721 18:36:49.599088    1186 placement_manager.go:147]  "msg"="Adding toleration to pod"  "podName"="tf2-keras-cifar10-inceptionv3-elastic-20210721-063539-worker-0" "scheduler"="default" "toleration"={"key":"celeste/hostname","operator":"Equal","value":"gpu3","effect":"NoExecute"}
I0721 18:36:49.995399    1186 placement_manager.go:147]  "msg"="Adding toleration to pod"  "podName"="tf2-keras-cifar10-inceptionv3-elastic-20210721-063539-worker-1" "scheduler"="default" "toleration"={"key":"celeste/hostname","operator":"Equal","value":"gpu3","effect":"NoExecute"}
I0721 18:36:50.396464    1186 placement_manager.go:147]  "msg"="Adding toleration to pod"  "podName"="tf2-keras-cifar10-inceptionv3-elastic-20210721-063539-worker-2" "scheduler"="default" "toleration"={"key":"celeste/hostname","operator":"Equal","value":"gpu3","effect":"NoExecute"}
I0721 18:36:50.796537    1186 placement_manager.go:147]  "msg"="Adding toleration to pod"  "podName"="tf2-keras-cifar10-inceptionv3-elastic-20210721-063539-launcher" "scheduler"="default" "toleration"={"key":"celeste/hostname","operator":"Exists","effect":"NoExecute"}
I0721 18:36:50.999375    1186 placement_manager.go:147]  "msg"="Adding toleration to pod"  "podName"="tf2-keras-cifar10-vgg16-elastic-20210721-063609-worker-0" "scheduler"="default" "toleration"={"key":"celeste/hostname","operator":"Equal","value":"gpu4","effect":"NoExecute"}
I0721 18:36:51.607162    1186 placement_manager.go:147]  "msg"="Adding toleration to pod"  "podName"="tf2-keras-cifar10-vgg16-elastic-20210721-063609-worker-1" "scheduler"="default" "toleration"={"key":"celeste/hostname","operator":"Equal","value":"gpu4","effect":"NoExecute"}
I0721 18:36:52.007753    1186 placement_manager.go:147]  "msg"="Adding toleration to pod"  "podName"="tf2-keras-cifar10-vgg16-elastic-20210721-063609-launcher" "scheduler"="default" "toleration"={"key":"celeste/hostname","operator":"Exists","effect":"NoExecute"}
I0721 18:36:52.795372    1186 placement_manager.go:147]  "msg"="Adding toleration to pod"  "podName"="tf2-keras-cifar10-vgg16-elastic-20210721-063631-worker-0" "scheduler"="default" "toleration"={"key":"celeste/hostname","operator":"Equal","value":"gpu3","effect":"NoExecute"}
I0721 18:36:53.208512    1186 placement_manager.go:147]  "msg"="Adding toleration to pod"  "podName"="tf2-keras-cifar10-vgg16-elastic-20210721-063631-worker-1" "scheduler"="default" "toleration"={"key":"celeste/hostname","operator":"Equal","value":"gpu3","effect":"NoExecute"}
I0721 18:36:53.612141    1186 placement_manager.go:147]  "msg"="Adding toleration to pod"  "podName"="tf2-keras-cifar10-vgg16-elastic-20210721-063631-launcher" "scheduler"="default" "toleration"={"key":"celeste/hostname","operator":"Exists","effect":"NoExecute"}
I0721 18:36:54.008213    1186 placement_manager.go:147]  "msg"="Adding toleration to pod"  "podName"="tf2-keras-cifar10-resnet50-elastic-20210721-063511-worker-0" "scheduler"="default" "toleration"={"key":"celeste/hostname","operator":"Equal","value":"gpu4","effect":"NoExecute"}
I0721 18:36:54.410934    1186 placement_manager.go:147]  "msg"="Adding toleration to pod"  "podName"="tf2-keras-cifar10-resnet50-elastic-20210721-063511-worker-1" "scheduler"="default" "toleration"={"key":"celeste/hostname","operator":"Equal","value":"gpu4","effect":"NoExecute"}
I0721 18:36:54.660074    1186 jobmaster.go:155]  "msg"="Training job created"  "job"="tf2-keras-transformer-elastic-20210721-063654"
I0721 18:36:54.660208    1186 scheduler.go:135]  "msg"="Received resched event, may be blocked because of rate limit"  "blockedUntil"="2021-07-21T18:38:48.830836799+08:00" "lastResched"="2021-07-21T18:36:48.830836799+08:00" "received"="2021-07-21T18:36:54.659314185+08:00" "scheduler"="default"
I0721 18:36:54.808737    1186 placement_manager.go:147]  "msg"="Adding toleration to pod"  "podName"="tf2-keras-cifar10-resnet50-elastic-20210721-063511-launcher" "scheduler"="default" "toleration"={"key":"celeste/hostname","operator":"Exists","effect":"NoExecute"}
I0721 18:37:21.521528    1186 jobmaster.go:155]  "msg"="Training job created"  "job"="tf2-keras-transformer-elastic-20210721-063721"
I0721 18:37:56.466352    1186 jobmaster.go:155]  "msg"="Training job created"  "job"="tf2-keras-cifar10-inceptionv3-elastic-20210721-063756"
I0721 18:38:09.237717    1186 placement_manager.go:147]  "msg"="Adding toleration to pod"  "podName"="tf2-keras-cifar10-vgg16-elastic-20210721-063631-worker-1" "scheduler"="default" "toleration"={"key":"celeste/hostname","operator":"Equal","value":"gpu3","effect":"NoExecute"}
I0721 18:38:33.361359    1186 jobmaster.go:155]  "msg"="Training job created"  "job"="tf2-keras-cifar10-resnet50-elastic-20210721-063833"
I0721 18:38:44.198367    1186 placement_manager.go:147]  "msg"="Adding toleration to pod"  "podName"="tf2-keras-cifar10-vgg16-elastic-20210721-063631-worker-1" "scheduler"="default" "toleration"={"key":"celeste/hostname","operator":"Equal","value":"gpu3","effect":"NoExecute"}
I0721 18:38:48.830886    1186 scheduler.go:159]  "msg"="Started resched"  "scheduler"="default"
I0721 18:38:48.830964    1186 scheduler.go:193]  "msg"="Updating all jobs info"  "scheduler"="default"
I0721 18:38:48.839517    1186 elastic_tiresias.go:160]  "msg"="Finished scheduling"  "algorithm"="ElasticTiresias" "compactionThreshold"=4 "freeGpu"=0 "promoteKnob"=4 "queueNum"=2 "result"={"tf2-keras-cifar10-inceptionv3-elastic-20210721-063448":2,"tf2-keras-cifar10-inceptionv3-elastic-20210721-063539":2,"tf2-keras-cifar10-inceptionv3-elastic-20210721-063756":0,"tf2-keras-cifar10-resnet50-elastic-20210721-063511":2,"tf2-keras-cifar10-resnet50-elastic-20210721-063833":0,"tf2-keras-cifar10-vgg16-elastic-20210721-063609":2,"tf2-keras-cifar10-vgg16-elastic-20210721-063631":2,"tf2-keras-transformer-elastic-20210721-063654":2,"tf2-keras-transformer-elastic-20210721-063721":0} "scheduler"="default" "thresholds"=
I0721 18:38:48.842933    1186 scheduler.go:384]  "msg"="Trying to delete multiple training jobs"  "jobs"=[] "scheduler"="default"
I0721 18:38:48.845982    1186 scheduler.go:342]  "msg"="Trying to scale multiple training jobs"  "jobs"=["tf2-keras-cifar10-inceptionv3-elastic-20210721-063448","tf2-keras-cifar10-inceptionv3-elastic-20210721-063539"] "scheduler"="default"
I0721 18:38:48.882178    1186 scheduler.go:292]  "msg"="Trying to start multiple training jobs"  "jobs"=["tf2-keras-transformer-elastic-20210721-063654"] "scheduler"="default"
I0721 18:38:48.894876    1186 scheduler.go:342]  "msg"="Trying to scale multiple training jobs"  "jobs"=[] "scheduler"="default"
I0721 18:38:48.898215    1186 placement_manager.go:166]  "msg"="Started job placements adjustment"  "scheduler"="default"
I0721 18:38:48.898274    1186 placement_manager.go:192]  "msg"="Releasing slots"  "jobs"={"tf2-keras-cifar10-inceptionv3-elastic-20210721-063448":{},"tf2-keras-cifar10-inceptionv3-elastic-20210721-063539":{},"tf2-keras-cifar10-resnet50-elastic-20210721-063511":{},"tf2-keras-cifar10-vgg16-elastic-20210721-063609":{},"tf2-keras-cifar10-vgg16-elastic-20210721-063631":{}} "nodes"={"gpu3":{},"gpu4":{},"gpu5":{}} "scheduler"="default"
I0721 18:38:48.898336    1186 placement_manager.go:250]  "msg"="Released slots"  "jobs"={"tf2-keras-cifar10-inceptionv3-elastic-20210721-063448":{},"tf2-keras-cifar10-inceptionv3-elastic-20210721-063539":{},"tf2-keras-cifar10-resnet50-elastic-20210721-063511":{},"tf2-keras-cifar10-vgg16-elastic-20210721-063609":{},"tf2-keras-cifar10-vgg16-elastic-20210721-063631":{}} "nodes"={"gpu3":{},"gpu4":{},"gpu5":{}} "scheduler"="default"
I0721 18:38:48.898687    1186 placement_manager.go:305]  "msg"="Found best-fit"  "crossNode"=0 "nodes"=[{},{},{}] "requests"=[{},{},{},{},{},{},{},{},{},{},{},{},{},{},{},{},{},{}] "scheduler"="default"
I0721 18:38:48.898995    1186 placement_manager.go:339]  "msg"="nodeStates updated"  "new"={"gpu3":{},"gpu4":{},"gpu5":{}} "old"={"gpu3":{},"gpu4":{},"gpu5":{}} "scheduler"="default" "score"=8
I0721 18:38:48.899350    1186 placement_manager.go:387]  "msg"="jobStates updated"  "new"={"tf2-keras-cifar10-inceptionv3-elastic-20210721-063448":{},"tf2-keras-cifar10-inceptionv3-elastic-20210721-063539":{},"tf2-keras-cifar10-resnet50-elastic-20210721-063511":{},"tf2-keras-cifar10-vgg16-elastic-20210721-063609":{},"tf2-keras-cifar10-vgg16-elastic-20210721-063631":{},"tf2-keras-transformer-elastic-20210721-063654":{}} "old"={"tf2-keras-cifar10-inceptionv3-elastic-20210721-063448":{},"tf2-keras-cifar10-inceptionv3-elastic-20210721-063539":{},"tf2-keras-cifar10-resnet50-elastic-20210721-063511":{},"tf2-keras-cifar10-vgg16-elastic-20210721-063609":{},"tf2-keras-cifar10-vgg16-elastic-20210721-063631":{}} "scheduler"="default"
I0721 18:38:48.899693    1186 placement_manager.go:434]  "msg"="podNodeName updated"  "launchersToDelete"=1 "new"={"tf2-keras-cifar10-inceptionv3-elastic-20210721-063448-worker-0":"gpu5","tf2-keras-cifar10-inceptionv3-elastic-20210721-063448-worker-1":"gpu5","tf2-keras-cifar10-inceptionv3-elastic-20210721-063539-worker-0":"gpu3","tf2-keras-cifar10-inceptionv3-elastic-20210721-063539-worker-1":"gpu3","tf2-keras-cifar10-resnet50-elastic-20210721-063511-worker-0":"gpu5","tf2-keras-cifar10-resnet50-elastic-20210721-063511-worker-1":"gpu5","tf2-keras-cifar10-vgg16-elastic-20210721-063609-worker-0":"gpu4","tf2-keras-cifar10-vgg16-elastic-20210721-063609-worker-1":"gpu4","tf2-keras-cifar10-vgg16-elastic-20210721-063631-worker-0":"gpu3","tf2-keras-cifar10-vgg16-elastic-20210721-063631-worker-1":"gpu3","tf2-keras-transformer-elastic-20210721-063654-worker-0":"gpu4","tf2-keras-transformer-elastic-20210721-063654-worker-1":"gpu4"} "old"={"tf2-keras-cifar10-inceptionv3-elastic-20210721-063448-worker-0":"gpu5","tf2-keras-cifar10-inceptionv3-elastic-20210721-063448-worker-1":"gpu5","tf2-keras-cifar10-inceptionv3-elastic-20210721-063448-worker-2":"gpu5","tf2-keras-cifar10-inceptionv3-elastic-20210721-063539-worker-0":"gpu3","tf2-keras-cifar10-inceptionv3-elastic-20210721-063539-worker-1":"gpu3","tf2-keras-cifar10-inceptionv3-elastic-20210721-063539-worker-2":"gpu3","tf2-keras-cifar10-resnet50-elastic-20210721-063511-worker-0":"gpu4","tf2-keras-cifar10-resnet50-elastic-20210721-063511-worker-1":"gpu4","tf2-keras-cifar10-vgg16-elastic-20210721-063609-worker-0":"gpu4","tf2-keras-cifar10-vgg16-elastic-20210721-063609-worker-1":"gpu4","tf2-keras-cifar10-vgg16-elastic-20210721-063631-worker-0":"gpu3","tf2-keras-cifar10-vgg16-elastic-20210721-063631-worker-1":"gpu3","tf2-keras-cifar10-vgg16-elastic-20210721-063631-worker-2":"gpu5"} "scheduler"="default" "workersToDelete"=2
I0721 18:38:48.899976    1186 placement_manager.go:451]  "msg"="Deleting pod that need migration"  "podName"="tf2-keras-cifar10-resnet50-elastic-20210721-063511-worker-0" "scheduler"="default"
I0721 18:38:48.903787    1186 placement_manager.go:451]  "msg"="Deleting pod that need migration"  "podName"="tf2-keras-cifar10-resnet50-elastic-20210721-063511-worker-1" "scheduler"="default"
I0721 18:38:48.908254    1186 placement_manager.go:451]  "msg"="Deleting pod that need migration"  "podName"="tf2-keras-cifar10-resnet50-elastic-20210721-063511-launcher" "scheduler"="default"
I0721 18:38:48.912310    1186 placement_manager.go:183]  "msg"="Finished job placements adjustment"  "scheduler"="default"
I0721 18:38:48.912608    1186 scheduler.go:182]  "msg"="Finished resched"  "scheduler"="default"
I0721 18:38:50.276085    1186 placement_manager.go:147]  "msg"="Adding toleration to pod"  "podName"="tf2-keras-transformer-elastic-20210721-063654-worker-0" "scheduler"="default" "toleration"={"key":"celeste/hostname","operator":"Equal","value":"gpu4","effect":"NoExecute"}
I0721 18:38:50.683200    1186 placement_manager.go:147]  "msg"="Adding toleration to pod"  "podName"="tf2-keras-transformer-elastic-20210721-063654-worker-1" "scheduler"="default" "toleration"={"key":"celeste/hostname","operator":"Equal","value":"gpu4","effect":"NoExecute"}
I0721 18:38:51.077022    1186 placement_manager.go:147]  "msg"="Adding toleration to pod"  "podName"="tf2-keras-transformer-elastic-20210721-063654-launcher" "scheduler"="default" "toleration"={"key":"celeste/hostname","operator":"Exists","effect":"NoExecute"}
I0721 18:39:00.294728    1186 jobmaster.go:155]  "msg"="Training job created"  "job"="tf2-keras-cifar10-inceptionv3-elastic-20210721-063900"
I0721 18:39:00.294856    1186 scheduler.go:135]  "msg"="Received resched event, may be blocked because of rate limit"  "blockedUntil"="2021-07-21T18:40:48.912885159+08:00" "lastResched"="2021-07-21T18:38:48.912885159+08:00" "received"="2021-07-21T18:39:00.294209318+08:00" "scheduler"="default"
I0721 18:39:05.361729    1186 placement_manager.go:147]  "msg"="Adding toleration to pod"  "podName"="tf2-keras-cifar10-resnet50-elastic-20210721-063511-worker-1" "scheduler"="default" "toleration"={"key":"celeste/hostname","operator":"Equal","value":"gpu5","effect":"NoExecute"}
I0721 18:39:06.168783    1186 placement_manager.go:147]  "msg"="Adding toleration to pod"  "podName"="tf2-keras-cifar10-resnet50-elastic-20210721-063511-launcher" "scheduler"="default" "toleration"={"key":"celeste/hostname","operator":"Exists","effect":"NoExecute"}
I0721 18:39:06.957259    1186 placement_manager.go:147]  "msg"="Adding toleration to pod"  "podName"="tf2-keras-cifar10-resnet50-elastic-20210721-063511-worker-0" "scheduler"="default" "toleration"={"key":"celeste/hostname","operator":"Equal","value":"gpu5","effect":"NoExecute"}
I0721 18:39:27.220273    1186 jobmaster.go:155]  "msg"="Training job created"  "job"="tf2-keras-transformer-elastic-20210721-063927"
I0721 18:39:52.153499    1186 jobmaster.go:155]  "msg"="Training job created"  "job"="tf2-keras-cifar10-vgg16-elastic-20210721-063952"
I0721 18:40:19.165820    1186 jobmaster.go:155]  "msg"="Training job created"  "job"="tf2-keras-cifar10-vgg16-elastic-20210721-064019"
I0721 18:40:48.078613    1186 jobmaster.go:155]  "msg"="Training job created"  "job"="tf2-keras-cifar10-resnet50-elastic-20210721-064048"
I0721 18:40:48.912961    1186 scheduler.go:159]  "msg"="Started resched"  "scheduler"="default"
I0721 18:40:48.913034    1186 scheduler.go:193]  "msg"="Updating all jobs info"  "scheduler"="default"
I0721 18:40:48.924906    1186 elastic_tiresias.go:160]  "msg"="Finished scheduling"  "algorithm"="ElasticTiresias" "compactionThreshold"=4 "freeGpu"=0 "promoteKnob"=4 "queueNum"=2 "result"={"tf2-keras-cifar10-inceptionv3-elastic-20210721-063448":2,"tf2-keras-cifar10-inceptionv3-elastic-20210721-063539":2,"tf2-keras-cifar10-inceptionv3-elastic-20210721-063756":0,"tf2-keras-cifar10-inceptionv3-elastic-20210721-063900":0,"tf2-keras-cifar10-resnet50-elastic-20210721-063511":2,"tf2-keras-cifar10-resnet50-elastic-20210721-063833":0,"tf2-keras-cifar10-resnet50-elastic-20210721-064048":0,"tf2-keras-cifar10-vgg16-elastic-20210721-063609":2,"tf2-keras-cifar10-vgg16-elastic-20210721-063631":2,"tf2-keras-cifar10-vgg16-elastic-20210721-063952":0,"tf2-keras-cifar10-vgg16-elastic-20210721-064019":0,"tf2-keras-transformer-elastic-20210721-063654":2,"tf2-keras-transformer-elastic-20210721-063721":0,"tf2-keras-transformer-elastic-20210721-063927":0} "scheduler"="default" "thresholds"=
I0721 18:40:48.925370    1186 scheduler.go:384]  "msg"="Trying to delete multiple training jobs"  "jobs"=[] "scheduler"="default"
I0721 18:40:48.925646    1186 scheduler.go:342]  "msg"="Trying to scale multiple training jobs"  "jobs"=[] "scheduler"="default"
I0721 18:40:48.925985    1186 scheduler.go:292]  "msg"="Trying to start multiple training jobs"  "jobs"=[] "scheduler"="default"
I0721 18:40:48.926282    1186 scheduler.go:342]  "msg"="Trying to scale multiple training jobs"  "jobs"=[] "scheduler"="default"
I0721 18:40:48.926612    1186 scheduler.go:180]  "msg"="Nothing changed, skipped ajust placements"  "scheduler"="default"
I0721 18:40:48.926763    1186 scheduler.go:182]  "msg"="Finished resched"  "scheduler"="default"
I0721 18:41:17.008429    1186 jobmaster.go:155]  "msg"="Training job created"  "job"="tf2-keras-cifar10-inceptionv3-elastic-20210721-064117"
I0721 18:41:17.008574    1186 scheduler.go:135]  "msg"="Received resched event, may be blocked because of rate limit"  "blockedUntil"="2021-07-21T18:42:48.926972974+08:00" "lastResched"="2021-07-21T18:40:48.926972974+08:00" "received"="2021-07-21T18:41:17.00788703+08:00" "scheduler"="default"
I0721 18:41:52.968369    1186 jobmaster.go:155]  "msg"="Training job created"  "job"="tf2-keras-transformer-elastic-20210721-064152"
I0721 18:42:15.923334    1186 jobmaster.go:155]  "msg"="Training job created"  "job"="tf2-keras-cifar10-inceptionv3-elastic-20210721-064215"
I0721 18:42:37.907228    1186 jobmaster.go:155]  "msg"="Training job created"  "job"="tf2-keras-cifar10-resnet50-elastic-20210721-064237"
I0721 18:42:48.927048    1186 scheduler.go:159]  "msg"="Started resched"  "scheduler"="default"
I0721 18:42:48.927139    1186 scheduler.go:193]  "msg"="Updating all jobs info"  "scheduler"="default"
I0721 18:42:48.938013    1186 elastic_tiresias.go:160]  "msg"="Finished scheduling"  "algorithm"="ElasticTiresias" "compactionThreshold"=4 "freeGpu"=0 "promoteKnob"=4 "queueNum"=2 "result"={"tf2-keras-cifar10-inceptionv3-elastic-20210721-063448":2,"tf2-keras-cifar10-inceptionv3-elastic-20210721-063539":2,"tf2-keras-cifar10-inceptionv3-elastic-20210721-063756":0,"tf2-keras-cifar10-inceptionv3-elastic-20210721-063900":0,"tf2-keras-cifar10-inceptionv3-elastic-20210721-064117":0,"tf2-keras-cifar10-inceptionv3-elastic-20210721-064215":0,"tf2-keras-cifar10-resnet50-elastic-20210721-063511":2,"tf2-keras-cifar10-resnet50-elastic-20210721-063833":0,"tf2-keras-cifar10-resnet50-elastic-20210721-064048":0,"tf2-keras-cifar10-resnet50-elastic-20210721-064237":0,"tf2-keras-cifar10-vgg16-elastic-20210721-063609":2,"tf2-keras-cifar10-vgg16-elastic-20210721-063631":2,"tf2-keras-cifar10-vgg16-elastic-20210721-063952":0,"tf2-keras-cifar10-vgg16-elastic-20210721-064019":0,"tf2-keras-transformer-elastic-20210721-063654":2,"tf2-keras-transformer-elastic-20210721-063721":0,"tf2-keras-transformer-elastic-20210721-063927":0,"tf2-keras-transformer-elastic-20210721-064152":0} "scheduler"="default" "thresholds"=
I0721 18:42:48.938316    1186 scheduler.go:384]  "msg"="Trying to delete multiple training jobs"  "jobs"=[] "scheduler"="default"
I0721 18:42:48.938482    1186 scheduler.go:342]  "msg"="Trying to scale multiple training jobs"  "jobs"=[] "scheduler"="default"
I0721 18:42:48.938616    1186 scheduler.go:292]  "msg"="Trying to start multiple training jobs"  "jobs"=[] "scheduler"="default"
I0721 18:42:48.938772    1186 scheduler.go:342]  "msg"="Trying to scale multiple training jobs"  "jobs"=[] "scheduler"="default"
I0721 18:42:48.938930    1186 scheduler.go:180]  "msg"="Nothing changed, skipped ajust placements"  "scheduler"="default"
I0721 18:42:48.938949    1186 scheduler.go:182]  "msg"="Finished resched"  "scheduler"="default"
I0721 18:43:10.910960    1186 jobmaster.go:155]  "msg"="Training job created"  "job"="tf2-keras-cifar10-vgg16-elastic-20210721-064310"
I0721 18:43:10.911137    1186 scheduler.go:135]  "msg"="Received resched event, may be blocked because of rate limit"  "blockedUntil"="2021-07-21T18:44:48.939075438+08:00" "lastResched"="2021-07-21T18:42:48.939075438+08:00" "received"="2021-07-21T18:43:10.910477051+08:00" "scheduler"="default"
I0721 18:43:32.796363    1186 jobmaster.go:155]  "msg"="Training job created"  "job"="tf2-keras-transformer-elastic-20210721-064332"
I0721 18:44:12.835635    1186 jobmaster.go:155]  "msg"="Training job created"  "job"="tf2-keras-cifar10-vgg16-elastic-20210721-064412"
I0721 18:44:48.939167    1186 scheduler.go:159]  "msg"="Started resched"  "scheduler"="default"
I0721 18:44:48.939237    1186 scheduler.go:193]  "msg"="Updating all jobs info"  "scheduler"="default"
I0721 18:44:48.953118    1186 elastic_tiresias.go:160]  "msg"="Finished scheduling"  "algorithm"="ElasticTiresias" "compactionThreshold"=4 "freeGpu"=0 "promoteKnob"=4 "queueNum"=2 "result"={"tf2-keras-cifar10-inceptionv3-elastic-20210721-063448":2,"tf2-keras-cifar10-inceptionv3-elastic-20210721-063539":2,"tf2-keras-cifar10-inceptionv3-elastic-20210721-063756":0,"tf2-keras-cifar10-inceptionv3-elastic-20210721-063900":0,"tf2-keras-cifar10-inceptionv3-elastic-20210721-064117":0,"tf2-keras-cifar10-inceptionv3-elastic-20210721-064215":0,"tf2-keras-cifar10-resnet50-elastic-20210721-063511":2,"tf2-keras-cifar10-resnet50-elastic-20210721-063833":0,"tf2-keras-cifar10-resnet50-elastic-20210721-064048":0,"tf2-keras-cifar10-resnet50-elastic-20210721-064237":0,"tf2-keras-cifar10-vgg16-elastic-20210721-063609":2,"tf2-keras-cifar10-vgg16-elastic-20210721-063631":2,"tf2-keras-cifar10-vgg16-elastic-20210721-063952":0,"tf2-keras-cifar10-vgg16-elastic-20210721-064019":0,"tf2-keras-cifar10-vgg16-elastic-20210721-064310":0,"tf2-keras-cifar10-vgg16-elastic-20210721-064412":0,"tf2-keras-transformer-elastic-20210721-063654":2,"tf2-keras-transformer-elastic-20210721-063721":0,"tf2-keras-transformer-elastic-20210721-063927":0,"tf2-keras-transformer-elastic-20210721-064152":0,"tf2-keras-transformer-elastic-20210721-064332":0} "scheduler"="default" "thresholds"=
I0721 18:44:48.953472    1186 scheduler.go:384]  "msg"="Trying to delete multiple training jobs"  "jobs"=[] "scheduler"="default"
I0721 18:44:48.953811    1186 scheduler.go:342]  "msg"="Trying to scale multiple training jobs"  "jobs"=[] "scheduler"="default"
I0721 18:44:48.954082    1186 scheduler.go:292]  "msg"="Trying to start multiple training jobs"  "jobs"=[] "scheduler"="default"
I0721 18:44:48.954460    1186 scheduler.go:342]  "msg"="Trying to scale multiple training jobs"  "jobs"=[] "scheduler"="default"
I0721 18:44:48.954727    1186 scheduler.go:180]  "msg"="Nothing changed, skipped ajust placements"  "scheduler"="default"
I0721 18:44:48.954757    1186 scheduler.go:182]  "msg"="Finished resched"  "scheduler"="default"
I0721 18:44:51.861245    1186 jobmaster.go:155]  "msg"="Training job created"  "job"="tf2-keras-cifar10-resnet50-elastic-20210721-064451"
I0721 18:44:51.861401    1186 scheduler.go:135]  "msg"="Received resched event, may be blocked because of rate limit"  "blockedUntil"="2021-07-21T18:46:48.954983516+08:00" "lastResched"="2021-07-21T18:44:48.954983516+08:00" "received"="2021-07-21T18:44:51.860673534+08:00" "scheduler"="default"
I0721 18:45:17.814150    1186 jobmaster.go:155]  "msg"="Training job created"  "job"="tf2-keras-cifar10-resnet50-elastic-20210721-064517"
I0721 18:45:45.792189    1186 jobmaster.go:155]  "msg"="Training job created"  "job"="tf2-keras-transformer-elastic-20210721-064545"
I0721 18:46:48.955049    1186 scheduler.go:159]  "msg"="Started resched"  "scheduler"="default"
I0721 18:46:48.955098    1186 scheduler.go:193]  "msg"="Updating all jobs info"  "scheduler"="default"
I0721 18:46:48.965952    1186 elastic_tiresias.go:160]  "msg"="Finished scheduling"  "algorithm"="ElasticTiresias" "compactionThreshold"=4 "freeGpu"=0 "promoteKnob"=4 "queueNum"=2 "result"={"tf2-keras-cifar10-inceptionv3-elastic-20210721-063448":2,"tf2-keras-cifar10-inceptionv3-elastic-20210721-063539":2,"tf2-keras-cifar10-inceptionv3-elastic-20210721-063756":0,"tf2-keras-cifar10-inceptionv3-elastic-20210721-063900":0,"tf2-keras-cifar10-inceptionv3-elastic-20210721-064117":0,"tf2-keras-cifar10-inceptionv3-elastic-20210721-064215":0,"tf2-keras-cifar10-resnet50-elastic-20210721-063511":2,"tf2-keras-cifar10-resnet50-elastic-20210721-063833":0,"tf2-keras-cifar10-resnet50-elastic-20210721-064048":0,"tf2-keras-cifar10-resnet50-elastic-20210721-064237":0,"tf2-keras-cifar10-resnet50-elastic-20210721-064451":0,"tf2-keras-cifar10-resnet50-elastic-20210721-064517":0,"tf2-keras-cifar10-vgg16-elastic-20210721-063609":2,"tf2-keras-cifar10-vgg16-elastic-20210721-063631":2,"tf2-keras-cifar10-vgg16-elastic-20210721-063952":0,"tf2-keras-cifar10-vgg16-elastic-20210721-064019":0,"tf2-keras-cifar10-vgg16-elastic-20210721-064310":0,"tf2-keras-cifar10-vgg16-elastic-20210721-064412":0,"tf2-keras-transformer-elastic-20210721-063654":2,"tf2-keras-transformer-elastic-20210721-063721":0,"tf2-keras-transformer-elastic-20210721-063927":0,"tf2-keras-transformer-elastic-20210721-064152":0,"tf2-keras-transformer-elastic-20210721-064332":0,"tf2-keras-transformer-elastic-20210721-064545":0} "scheduler"="default" "thresholds"=
I0721 18:46:48.966252    1186 scheduler.go:384]  "msg"="Trying to delete multiple training jobs"  "jobs"=[] "scheduler"="default"
I0721 18:46:48.966462    1186 scheduler.go:342]  "msg"="Trying to scale multiple training jobs"  "jobs"=[] "scheduler"="default"
I0721 18:46:48.966674    1186 scheduler.go:292]  "msg"="Trying to start multiple training jobs"  "jobs"=[] "scheduler"="default"
I0721 18:46:48.966887    1186 scheduler.go:342]  "msg"="Trying to scale multiple training jobs"  "jobs"=[] "scheduler"="default"
I0721 18:46:48.967080    1186 scheduler.go:180]  "msg"="Nothing changed, skipped ajust placements"  "scheduler"="default"
I0721 18:46:48.967101    1186 scheduler.go:182]  "msg"="Finished resched"  "scheduler"="default"
I0721 18:46:51.483117    1186 scheduler.go:559]  "msg"="Priority demoted to training job"  "job"="tf2-keras-cifar10-inceptionv3-elastic-20210721-063448" "priority"=1 "scheduler"="default"
I0721 18:46:51.483198    1186 scheduler.go:573]  "msg"="Priority changed"  "scheduler"="default"
I0721 18:46:51.483281    1186 scheduler.go:135]  "msg"="Received resched event, may be blocked because of rate limit"  "blockedUntil"="2021-07-21T18:48:48.96728023+08:00" "lastResched"="2021-07-21T18:46:48.96728023+08:00" "received"="2021-07-21T18:46:51.483206058+08:00" "scheduler"="default"
I0721 18:48:48.967349    1186 scheduler.go:159]  "msg"="Started resched"  "scheduler"="default"
I0721 18:48:48.967417    1186 scheduler.go:193]  "msg"="Updating all jobs info"  "scheduler"="default"
I0721 18:48:48.981129    1186 elastic_tiresias.go:160]  "msg"="Finished scheduling"  "algorithm"="ElasticTiresias" "compactionThreshold"=4 "freeGpu"=0 "promoteKnob"=4 "queueNum"=2 "result"={"tf2-keras-cifar10-inceptionv3-elastic-20210721-063448":0,"tf2-keras-cifar10-inceptionv3-elastic-20210721-063539":2,"tf2-keras-cifar10-inceptionv3-elastic-20210721-063756":0,"tf2-keras-cifar10-inceptionv3-elastic-20210721-063900":0,"tf2-keras-cifar10-inceptionv3-elastic-20210721-064117":0,"tf2-keras-cifar10-inceptionv3-elastic-20210721-064215":0,"tf2-keras-cifar10-resnet50-elastic-20210721-063511":2,"tf2-keras-cifar10-resnet50-elastic-20210721-063833":0,"tf2-keras-cifar10-resnet50-elastic-20210721-064048":0,"tf2-keras-cifar10-resnet50-elastic-20210721-064237":0,"tf2-keras-cifar10-resnet50-elastic-20210721-064451":0,"tf2-keras-cifar10-resnet50-elastic-20210721-064517":0,"tf2-keras-cifar10-vgg16-elastic-20210721-063609":2,"tf2-keras-cifar10-vgg16-elastic-20210721-063631":2,"tf2-keras-cifar10-vgg16-elastic-20210721-063952":0,"tf2-keras-cifar10-vgg16-elastic-20210721-064019":0,"tf2-keras-cifar10-vgg16-elastic-20210721-064310":0,"tf2-keras-cifar10-vgg16-elastic-20210721-064412":0,"tf2-keras-transformer-elastic-20210721-063654":2,"tf2-keras-transformer-elastic-20210721-063721":2,"tf2-keras-transformer-elastic-20210721-063927":0,"tf2-keras-transformer-elastic-20210721-064152":0,"tf2-keras-transformer-elastic-20210721-064332":0,"tf2-keras-transformer-elastic-20210721-064545":0} "scheduler"="default" "thresholds"=
I0721 18:48:48.981543    1186 scheduler.go:384]  "msg"="Trying to delete multiple training jobs"  "jobs"=["tf2-keras-cifar10-inceptionv3-elastic-20210721-063448"] "scheduler"="default"
I0721 18:48:48.990953    1186 scheduler.go:342]  "msg"="Trying to scale multiple training jobs"  "jobs"=[] "scheduler"="default"
I0721 18:48:48.991217    1186 scheduler.go:292]  "msg"="Trying to start multiple training jobs"  "jobs"=["tf2-keras-transformer-elastic-20210721-063721"] "scheduler"="default"
I0721 18:48:49.014862    1186 scheduler.go:342]  "msg"="Trying to scale multiple training jobs"  "jobs"=[] "scheduler"="default"
I0721 18:48:49.018336    1186 placement_manager.go:166]  "msg"="Started job placements adjustment"  "scheduler"="default"
I0721 18:48:49.018428    1186 placement_manager.go:192]  "msg"="Releasing slots"  "jobs"={"tf2-keras-cifar10-inceptionv3-elastic-20210721-063448":{},"tf2-keras-cifar10-inceptionv3-elastic-20210721-063539":{},"tf2-keras-cifar10-resnet50-elastic-20210721-063511":{},"tf2-keras-cifar10-vgg16-elastic-20210721-063609":{},"tf2-keras-cifar10-vgg16-elastic-20210721-063631":{},"tf2-keras-transformer-elastic-20210721-063654":{}} "nodes"={"gpu3":{},"gpu4":{},"gpu5":{}} "scheduler"="default"
I0721 18:48:49.018512    1186 placement_manager.go:250]  "msg"="Released slots"  "jobs"={"tf2-keras-cifar10-inceptionv3-elastic-20210721-063448":{},"tf2-keras-cifar10-inceptionv3-elastic-20210721-063539":{},"tf2-keras-cifar10-resnet50-elastic-20210721-063511":{},"tf2-keras-cifar10-vgg16-elastic-20210721-063609":{},"tf2-keras-cifar10-vgg16-elastic-20210721-063631":{},"tf2-keras-transformer-elastic-20210721-063654":{}} "nodes"={"gpu3":{},"gpu4":{},"gpu5":{}} "scheduler"="default"
I0721 18:48:49.018955    1186 placement_manager.go:305]  "msg"="Found best-fit"  "crossNode"=0 "nodes"=[{},{},{}] "requests"=[{},{},{},{},{},{},{},{},{},{},{},{},{},{},{},{},{},{},{},{},{},{},{},{},{},{},{},{},{},{},{},{},{},{},{},{},{},{},{},{},{},{},{},{},{},{},{},{}] "scheduler"="default"
I0721 18:48:49.019236    1186 placement_manager.go:339]  "msg"="nodeStates updated"  "new"={"gpu3":{},"gpu4":{},"gpu5":{}} "old"={"gpu3":{},"gpu4":{},"gpu5":{}} "scheduler"="default" "score"=6
I0721 18:48:49.019536    1186 placement_manager.go:387]  "msg"="jobStates updated"  "new"={"tf2-keras-cifar10-inceptionv3-elastic-20210721-063539":{},"tf2-keras-cifar10-resnet50-elastic-20210721-063511":{},"tf2-keras-cifar10-vgg16-elastic-20210721-063609":{},"tf2-keras-cifar10-vgg16-elastic-20210721-063631":{},"tf2-keras-transformer-elastic-20210721-063654":{},"tf2-keras-transformer-elastic-20210721-063721":{}} "old"={"tf2-keras-cifar10-inceptionv3-elastic-20210721-063448":{},"tf2-keras-cifar10-inceptionv3-elastic-20210721-063539":{},"tf2-keras-cifar10-resnet50-elastic-20210721-063511":{},"tf2-keras-cifar10-vgg16-elastic-20210721-063609":{},"tf2-keras-cifar10-vgg16-elastic-20210721-063631":{},"tf2-keras-transformer-elastic-20210721-063654":{}} "scheduler"="default"
I0721 18:48:49.019932    1186 placement_manager.go:434]  "msg"="podNodeName updated"  "launchersToDelete"=2 "new"={"tf2-keras-cifar10-inceptionv3-elastic-20210721-063539-worker-0":"gpu3","tf2-keras-cifar10-inceptionv3-elastic-20210721-063539-worker-1":"gpu3","tf2-keras-cifar10-resnet50-elastic-20210721-063511-worker-0":"gpu5","tf2-keras-cifar10-resnet50-elastic-20210721-063511-worker-1":"gpu5","tf2-keras-cifar10-vgg16-elastic-20210721-063609-worker-0":"gpu4","tf2-keras-cifar10-vgg16-elastic-20210721-063609-worker-1":"gpu4","tf2-keras-cifar10-vgg16-elastic-20210721-063631-worker-0":"gpu5","tf2-keras-cifar10-vgg16-elastic-20210721-063631-worker-1":"gpu5","tf2-keras-transformer-elastic-20210721-063654-worker-0":"gpu3","tf2-keras-transformer-elastic-20210721-063654-worker-1":"gpu3","tf2-keras-transformer-elastic-20210721-063721-worker-0":"gpu4","tf2-keras-transformer-elastic-20210721-063721-worker-1":"gpu4"} "old"={"tf2-keras-cifar10-inceptionv3-elastic-20210721-063448-worker-0":"gpu5","tf2-keras-cifar10-inceptionv3-elastic-20210721-063448-worker-1":"gpu5","tf2-keras-cifar10-inceptionv3-elastic-20210721-063539-worker-0":"gpu3","tf2-keras-cifar10-inceptionv3-elastic-20210721-063539-worker-1":"gpu3","tf2-keras-cifar10-resnet50-elastic-20210721-063511-worker-0":"gpu5","tf2-keras-cifar10-resnet50-elastic-20210721-063511-worker-1":"gpu5","tf2-keras-cifar10-vgg16-elastic-20210721-063609-worker-0":"gpu4","tf2-keras-cifar10-vgg16-elastic-20210721-063609-worker-1":"gpu4","tf2-keras-cifar10-vgg16-elastic-20210721-063631-worker-0":"gpu3","tf2-keras-cifar10-vgg16-elastic-20210721-063631-worker-1":"gpu3","tf2-keras-transformer-elastic-20210721-063654-worker-0":"gpu4","tf2-keras-transformer-elastic-20210721-063654-worker-1":"gpu4"} "scheduler"="default" "workersToDelete"=4
I0721 18:48:49.020169    1186 placement_manager.go:451]  "msg"="Deleting pod that need migration"  "podName"="tf2-keras-transformer-elastic-20210721-063654-worker-0" "scheduler"="default"
I0721 18:48:49.029370    1186 placement_manager.go:451]  "msg"="Deleting pod that need migration"  "podName"="tf2-keras-transformer-elastic-20210721-063654-worker-1" "scheduler"="default"
I0721 18:48:49.033164    1186 placement_manager.go:451]  "msg"="Deleting pod that need migration"  "podName"="tf2-keras-transformer-elastic-20210721-063654-launcher" "scheduler"="default"
I0721 18:48:49.047051    1186 placement_manager.go:451]  "msg"="Deleting pod that need migration"  "podName"="tf2-keras-cifar10-vgg16-elastic-20210721-063631-worker-0" "scheduler"="default"
I0721 18:48:49.050715    1186 placement_manager.go:451]  "msg"="Deleting pod that need migration"  "podName"="tf2-keras-cifar10-vgg16-elastic-20210721-063631-worker-1" "scheduler"="default"
I0721 18:48:49.054114    1186 placement_manager.go:451]  "msg"="Deleting pod that need migration"  "podName"="tf2-keras-cifar10-vgg16-elastic-20210721-063631-launcher" "scheduler"="default"
I0721 18:48:49.059553    1186 placement_manager.go:183]  "msg"="Finished job placements adjustment"  "scheduler"="default"
I0721 18:48:49.059840    1186 scheduler.go:182]  "msg"="Finished resched"  "scheduler"="default"
I0721 18:48:49.083501    1186 placement_manager.go:147]  "msg"="Adding toleration to pod"  "podName"="tf2-keras-transformer-elastic-20210721-063721-worker-0" "scheduler"="default" "toleration"={"key":"celeste/hostname","operator":"Equal","value":"gpu4","effect":"NoExecute"}
I0721 18:48:49.220528    1186 placement_manager.go:147]  "msg"="Adding toleration to pod"  "podName"="tf2-keras-transformer-elastic-20210721-063721-worker-1" "scheduler"="default" "toleration"={"key":"celeste/hostname","operator":"Equal","value":"gpu4","effect":"NoExecute"}
I0721 18:48:49.827510    1186 placement_manager.go:147]  "msg"="Adding toleration to pod"  "podName"="tf2-keras-transformer-elastic-20210721-063721-launcher" "scheduler"="default" "toleration"={"key":"celeste/hostname","operator":"Exists","effect":"NoExecute"}
I0721 18:48:56.630600    1186 placement_manager.go:147]  "msg"="Adding toleration to pod"  "podName"="tf2-keras-transformer-elastic-20210721-063654-launcher" "scheduler"="default" "toleration"={"key":"celeste/hostname","operator":"Exists","effect":"NoExecute"}
I0721 18:48:57.201779    1186 placement_manager.go:147]  "msg"="Adding toleration to pod"  "podName"="tf2-keras-transformer-elastic-20210721-063654-worker-0" "scheduler"="default" "toleration"={"key":"celeste/hostname","operator":"Equal","value":"gpu3","effect":"NoExecute"}
I0721 18:48:58.999784    1186 placement_manager.go:147]  "msg"="Adding toleration to pod"  "podName"="tf2-keras-transformer-elastic-20210721-063654-worker-1" "scheduler"="default" "toleration"={"key":"celeste/hostname","operator":"Equal","value":"gpu3","effect":"NoExecute"}
I0721 18:49:00.034232    1186 placement_manager.go:147]  "msg"="Adding toleration to pod"  "podName"="tf2-keras-cifar10-vgg16-elastic-20210721-063631-launcher" "scheduler"="default" "toleration"={"key":"celeste/hostname","operator":"Exists","effect":"NoExecute"}
I0721 18:49:09.273944    1186 placement_manager.go:147]  "msg"="Adding toleration to pod"  "podName"="tf2-keras-cifar10-vgg16-elastic-20210721-063631-worker-0" "scheduler"="default" "toleration"={"key":"celeste/hostname","operator":"Equal","value":"gpu5","effect":"NoExecute"}
I0721 18:49:09.309181    1186 placement_manager.go:147]  "msg"="Adding toleration to pod"  "podName"="tf2-keras-cifar10-vgg16-elastic-20210721-063631-worker-1" "scheduler"="default" "toleration"={"key":"celeste/hostname","operator":"Equal","value":"gpu5","effect":"NoExecute"}
I0721 18:49:54.867298    1186 scheduler.go:474]  "msg"="Training job completed"  "elaspedTotalSeconds"=821.918725315 "gpuTotalSeconds"=1570.051365836 "job"="tf2-keras-cifar10-vgg16-elastic-20210721-063609" "ranTotalSeconds"=785.025682918 "scheduler"="default" "waitedTotalSeconds"=36.893042397
I0721 18:49:54.867446    1186 scheduler.go:135]  "msg"="Received resched event, may be blocked because of rate limit"  "blockedUntil"="2021-07-21T18:50:49.060089003+08:00" "lastResched"="2021-07-21T18:48:49.060089003+08:00" "received"="2021-07-21T18:49:54.867335365+08:00" "scheduler"="default"
I0721 18:50:46.490803    1186 scheduler.go:559]  "msg"="Priority demoted to training job"  "job"="tf2-keras-cifar10-inceptionv3-elastic-20210721-063539" "priority"=1 "scheduler"="default"
I0721 18:50:46.490965    1186 scheduler.go:573]  "msg"="Priority changed"  "scheduler"="default"
I0721 18:50:49.060163    1186 scheduler.go:159]  "msg"="Started resched"  "scheduler"="default"
I0721 18:50:49.060209    1186 scheduler.go:193]  "msg"="Updating all jobs info"  "scheduler"="default"
I0721 18:50:49.073617    1186 elastic_tiresias.go:160]  "msg"="Finished scheduling"  "algorithm"="ElasticTiresias" "compactionThreshold"=4 "freeGpu"=0 "promoteKnob"=4 "queueNum"=2 "result"={"tf2-keras-cifar10-inceptionv3-elastic-20210721-063448":0,"tf2-keras-cifar10-inceptionv3-elastic-20210721-063539":0,"tf2-keras-cifar10-inceptionv3-elastic-20210721-063756":2,"tf2-keras-cifar10-inceptionv3-elastic-20210721-063900":0,"tf2-keras-cifar10-inceptionv3-elastic-20210721-064117":0,"tf2-keras-cifar10-inceptionv3-elastic-20210721-064215":0,"tf2-keras-cifar10-resnet50-elastic-20210721-063511":2,"tf2-keras-cifar10-resnet50-elastic-20210721-063833":2,"tf2-keras-cifar10-resnet50-elastic-20210721-064048":0,"tf2-keras-cifar10-resnet50-elastic-20210721-064237":0,"tf2-keras-cifar10-resnet50-elastic-20210721-064451":0,"tf2-keras-cifar10-resnet50-elastic-20210721-064517":0,"tf2-keras-cifar10-vgg16-elastic-20210721-063631":2,"tf2-keras-cifar10-vgg16-elastic-20210721-063952":0,"tf2-keras-cifar10-vgg16-elastic-20210721-064019":0,"tf2-keras-cifar10-vgg16-elastic-20210721-064310":0,"tf2-keras-cifar10-vgg16-elastic-20210721-064412":0,"tf2-keras-transformer-elastic-20210721-063654":2,"tf2-keras-transformer-elastic-20210721-063721":2,"tf2-keras-transformer-elastic-20210721-063927":0,"tf2-keras-transformer-elastic-20210721-064152":0,"tf2-keras-transformer-elastic-20210721-064332":0,"tf2-keras-transformer-elastic-20210721-064545":0} "scheduler"="default" "thresholds"=
I0721 18:50:49.074013    1186 scheduler.go:384]  "msg"="Trying to delete multiple training jobs"  "jobs"=["tf2-keras-cifar10-inceptionv3-elastic-20210721-063539"] "scheduler"="default"
I0721 18:50:49.084261    1186 scheduler.go:342]  "msg"="Trying to scale multiple training jobs"  "jobs"=[] "scheduler"="default"
I0721 18:50:49.084525    1186 scheduler.go:292]  "msg"="Trying to start multiple training jobs"  "jobs"=["tf2-keras-cifar10-inceptionv3-elastic-20210721-063756","tf2-keras-cifar10-resnet50-elastic-20210721-063833"] "scheduler"="default"
I0721 18:50:49.119545    1186 scheduler.go:342]  "msg"="Trying to scale multiple training jobs"  "jobs"=[] "scheduler"="default"
I0721 18:50:49.123682    1186 placement_manager.go:166]  "msg"="Started job placements adjustment"  "scheduler"="default"
I0721 18:50:49.123772    1186 placement_manager.go:192]  "msg"="Releasing slots"  "jobs"={"tf2-keras-cifar10-inceptionv3-elastic-20210721-063539":{},"tf2-keras-cifar10-resnet50-elastic-20210721-063511":{},"tf2-keras-cifar10-vgg16-elastic-20210721-063609":{},"tf2-keras-cifar10-vgg16-elastic-20210721-063631":{},"tf2-keras-transformer-elastic-20210721-063654":{},"tf2-keras-transformer-elastic-20210721-063721":{}} "nodes"={"gpu3":{},"gpu4":{},"gpu5":{}} "scheduler"="default"
I0721 18:50:49.123849    1186 placement_manager.go:250]  "msg"="Released slots"  "jobs"={"tf2-keras-cifar10-inceptionv3-elastic-20210721-063539":{},"tf2-keras-cifar10-resnet50-elastic-20210721-063511":{},"tf2-keras-cifar10-vgg16-elastic-20210721-063609":{},"tf2-keras-cifar10-vgg16-elastic-20210721-063631":{},"tf2-keras-transformer-elastic-20210721-063654":{},"tf2-keras-transformer-elastic-20210721-063721":{}} "nodes"={"gpu3":{},"gpu4":{},"gpu5":{}} "scheduler"="default"
I0721 18:50:49.124319    1186 placement_manager.go:305]  "msg"="Found best-fit"  "crossNode"=0 "nodes"=[{},{},{}] "requests"=[{},{},{},{},{},{},{},{},{},{},{},{},{},{},{},{},{},{},{},{},{},{},{},{},{},{},{},{},{},{},{},{},{},{},{},{},{},{},{},{},{},{},{},{},{},{}] "scheduler"="default"
I0721 18:50:49.124640    1186 placement_manager.go:339]  "msg"="nodeStates updated"  "new"={"gpu3":{},"gpu4":{},"gpu5":{}} "old"={"gpu3":{},"gpu4":{},"gpu5":{}} "scheduler"="default" "score"=6
I0721 18:50:49.124914    1186 placement_manager.go:387]  "msg"="jobStates updated"  "new"={"tf2-keras-cifar10-inceptionv3-elastic-20210721-063756":{},"tf2-keras-cifar10-resnet50-elastic-20210721-063511":{},"tf2-keras-cifar10-resnet50-elastic-20210721-063833":{},"tf2-keras-cifar10-vgg16-elastic-20210721-063631":{},"tf2-keras-transformer-elastic-20210721-063654":{},"tf2-keras-transformer-elastic-20210721-063721":{}} "old"={"tf2-keras-cifar10-inceptionv3-elastic-20210721-063539":{},"tf2-keras-cifar10-resnet50-elastic-20210721-063511":{},"tf2-keras-cifar10-vgg16-elastic-20210721-063609":{},"tf2-keras-cifar10-vgg16-elastic-20210721-063631":{},"tf2-keras-transformer-elastic-20210721-063654":{},"tf2-keras-transformer-elastic-20210721-063721":{}} "scheduler"="default"
I0721 18:50:49.125295    1186 placement_manager.go:434]  "msg"="podNodeName updated"  "launchersToDelete"=1 "new"={"tf2-keras-cifar10-inceptionv3-elastic-20210721-063756-worker-0":"gpu4","tf2-keras-cifar10-inceptionv3-elastic-20210721-063756-worker-1":"gpu4","tf2-keras-cifar10-resnet50-elastic-20210721-063511-worker-0":"gpu5","tf2-keras-cifar10-resnet50-elastic-20210721-063511-worker-1":"gpu5","tf2-keras-cifar10-resnet50-elastic-20210721-063833-worker-0":"gpu5","tf2-keras-cifar10-resnet50-elastic-20210721-063833-worker-1":"gpu5","tf2-keras-cifar10-vgg16-elastic-20210721-063631-worker-0":"gpu3","tf2-keras-cifar10-vgg16-elastic-20210721-063631-worker-1":"gpu3","tf2-keras-transformer-elastic-20210721-063654-worker-0":"gpu3","tf2-keras-transformer-elastic-20210721-063654-worker-1":"gpu3","tf2-keras-transformer-elastic-20210721-063721-worker-0":"gpu4","tf2-keras-transformer-elastic-20210721-063721-worker-1":"gpu4"} "old"={"tf2-keras-cifar10-inceptionv3-elastic-20210721-063539-worker-0":"gpu3","tf2-keras-cifar10-inceptionv3-elastic-20210721-063539-worker-1":"gpu3","tf2-keras-cifar10-resnet50-elastic-20210721-063511-worker-0":"gpu5","tf2-keras-cifar10-resnet50-elastic-20210721-063511-worker-1":"gpu5","tf2-keras-cifar10-vgg16-elastic-20210721-063609-worker-0":"gpu4","tf2-keras-cifar10-vgg16-elastic-20210721-063609-worker-1":"gpu4","tf2-keras-cifar10-vgg16-elastic-20210721-063631-worker-0":"gpu5","tf2-keras-cifar10-vgg16-elastic-20210721-063631-worker-1":"gpu5","tf2-keras-transformer-elastic-20210721-063654-worker-0":"gpu3","tf2-keras-transformer-elastic-20210721-063654-worker-1":"gpu3","tf2-keras-transformer-elastic-20210721-063721-worker-0":"gpu4","tf2-keras-transformer-elastic-20210721-063721-worker-1":"gpu4"} "scheduler"="default" "workersToDelete"=2
I0721 18:50:49.125630    1186 placement_manager.go:451]  "msg"="Deleting pod that need migration"  "podName"="tf2-keras-cifar10-vgg16-elastic-20210721-063631-worker-0" "scheduler"="default"
I0721 18:50:49.130154    1186 placement_manager.go:451]  "msg"="Deleting pod that need migration"  "podName"="tf2-keras-cifar10-vgg16-elastic-20210721-063631-worker-1" "scheduler"="default"
I0721 18:50:49.134897    1186 placement_manager.go:451]  "msg"="Deleting pod that need migration"  "podName"="tf2-keras-cifar10-vgg16-elastic-20210721-063631-launcher" "scheduler"="default"
I0721 18:50:49.140555    1186 placement_manager.go:183]  "msg"="Finished job placements adjustment"  "scheduler"="default"
I0721 18:50:49.140796    1186 scheduler.go:182]  "msg"="Finished resched"  "scheduler"="default"
I0721 18:50:49.322818    1186 placement_manager.go:147]  "msg"="Adding toleration to pod"  "podName"="tf2-keras-cifar10-inceptionv3-elastic-20210721-063756-worker-0" "scheduler"="default" "toleration"={"key":"celeste/hostname","operator":"Equal","value":"gpu4","effect":"NoExecute"}
I0721 18:50:49.519400    1186 placement_manager.go:147]  "msg"="Adding toleration to pod"  "podName"="tf2-keras-cifar10-resnet50-elastic-20210721-063833-worker-0" "scheduler"="default" "toleration"={"key":"celeste/hostname","operator":"Equal","value":"gpu5","effect":"NoExecute"}
I0721 18:50:49.718945    1186 placement_manager.go:147]  "msg"="Adding toleration to pod"  "podName"="tf2-keras-cifar10-inceptionv3-elastic-20210721-063756-worker-1" "scheduler"="default" "toleration"={"key":"celeste/hostname","operator":"Equal","value":"gpu4","effect":"NoExecute"}
I0721 18:50:49.920264    1186 placement_manager.go:147]  "msg"="Adding toleration to pod"  "podName"="tf2-keras-cifar10-resnet50-elastic-20210721-063833-worker-1" "scheduler"="default" "toleration"={"key":"celeste/hostname","operator":"Equal","value":"gpu5","effect":"NoExecute"}
I0721 18:50:50.133578    1186 placement_manager.go:147]  "msg"="Adding toleration to pod"  "podName"="tf2-keras-cifar10-inceptionv3-elastic-20210721-063756-launcher" "scheduler"="default" "toleration"={"key":"celeste/hostname","operator":"Exists","effect":"NoExecute"}
I0721 18:50:50.535792    1186 placement_manager.go:147]  "msg"="Adding toleration to pod"  "podName"="tf2-keras-cifar10-resnet50-elastic-20210721-063833-launcher" "scheduler"="default" "toleration"={"key":"celeste/hostname","operator":"Exists","effect":"NoExecute"}
I0721 18:50:58.497502    1186 placement_manager.go:147]  "msg"="Adding toleration to pod"  "podName"="tf2-keras-cifar10-vgg16-elastic-20210721-063631-worker-0" "scheduler"="default" "toleration"={"key":"celeste/hostname","operator":"Equal","value":"gpu3","effect":"NoExecute"}
I0721 18:50:58.536175    1186 placement_manager.go:147]  "msg"="Adding toleration to pod"  "podName"="tf2-keras-cifar10-vgg16-elastic-20210721-063631-worker-1" "scheduler"="default" "toleration"={"key":"celeste/hostname","operator":"Equal","value":"gpu3","effect":"NoExecute"}
I0721 18:50:58.545613    1186 placement_manager.go:147]  "msg"="Adding toleration to pod"  "podName"="tf2-keras-cifar10-vgg16-elastic-20210721-063631-launcher" "scheduler"="default" "toleration"={"key":"celeste/hostname","operator":"Exists","effect":"NoExecute"}
I0721 18:51:46.493330    1186 scheduler.go:559]  "msg"="Priority demoted to training job"  "job"="tf2-keras-cifar10-resnet50-elastic-20210721-063511" "priority"=1 "scheduler"="default"
I0721 18:51:46.493411    1186 scheduler.go:559]  "msg"="Priority demoted to training job"  "job"="tf2-keras-cifar10-vgg16-elastic-20210721-063631" "priority"=1 "scheduler"="default"
I0721 18:51:46.493466    1186 scheduler.go:573]  "msg"="Priority changed"  "scheduler"="default"
I0721 18:51:46.493564    1186 scheduler.go:135]  "msg"="Received resched event, may be blocked because of rate limit"  "blockedUntil"="2021-07-21T18:52:49.140956269+08:00" "lastResched"="2021-07-21T18:50:49.140956269+08:00" "received"="2021-07-21T18:51:46.493479218+08:00" "scheduler"="default"
I0721 18:52:49.141063    1186 scheduler.go:159]  "msg"="Started resched"  "scheduler"="default"
I0721 18:52:49.141146    1186 scheduler.go:193]  "msg"="Updating all jobs info"  "scheduler"="default"
I0721 18:52:49.158862    1186 elastic_tiresias.go:160]  "msg"="Finished scheduling"  "algorithm"="ElasticTiresias" "compactionThreshold"=4 "freeGpu"=0 "promoteKnob"=4 "queueNum"=2 "result"={"tf2-keras-cifar10-inceptionv3-elastic-20210721-063448":0,"tf2-keras-cifar10-inceptionv3-elastic-20210721-063539":0,"tf2-keras-cifar10-inceptionv3-elastic-20210721-063756":2,"tf2-keras-cifar10-inceptionv3-elastic-20210721-063900":2,"tf2-keras-cifar10-inceptionv3-elastic-20210721-064117":0,"tf2-keras-cifar10-inceptionv3-elastic-20210721-064215":0,"tf2-keras-cifar10-resnet50-elastic-20210721-063511":0,"tf2-keras-cifar10-resnet50-elastic-20210721-063833":2,"tf2-keras-cifar10-resnet50-elastic-20210721-064048":0,"tf2-keras-cifar10-resnet50-elastic-20210721-064237":0,"tf2-keras-cifar10-resnet50-elastic-20210721-064451":0,"tf2-keras-cifar10-resnet50-elastic-20210721-064517":0,"tf2-keras-cifar10-vgg16-elastic-20210721-063631":0,"tf2-keras-cifar10-vgg16-elastic-20210721-063952":0,"tf2-keras-cifar10-vgg16-elastic-20210721-064019":0,"tf2-keras-cifar10-vgg16-elastic-20210721-064310":0,"tf2-keras-cifar10-vgg16-elastic-20210721-064412":0,"tf2-keras-transformer-elastic-20210721-063654":2,"tf2-keras-transformer-elastic-20210721-063721":2,"tf2-keras-transformer-elastic-20210721-063927":2,"tf2-keras-transformer-elastic-20210721-064152":0,"tf2-keras-transformer-elastic-20210721-064332":0,"tf2-keras-transformer-elastic-20210721-064545":0} "scheduler"="default" "thresholds"=
I0721 18:52:49.159288    1186 scheduler.go:384]  "msg"="Trying to delete multiple training jobs"  "jobs"=["tf2-keras-cifar10-vgg16-elastic-20210721-063631","tf2-keras-cifar10-resnet50-elastic-20210721-063511"] "scheduler"="default"
I0721 18:52:49.183366    1186 scheduler.go:342]  "msg"="Trying to scale multiple training jobs"  "jobs"=[] "scheduler"="default"
I0721 18:52:49.183880    1186 scheduler.go:292]  "msg"="Trying to start multiple training jobs"  "jobs"=["tf2-keras-cifar10-inceptionv3-elastic-20210721-063900","tf2-keras-transformer-elastic-20210721-063927"] "scheduler"="default"
I0721 18:52:49.207384    1186 scheduler.go:342]  "msg"="Trying to scale multiple training jobs"  "jobs"=[] "scheduler"="default"
I0721 18:52:49.210029    1186 placement_manager.go:166]  "msg"="Started job placements adjustment"  "scheduler"="default"
I0721 18:52:49.210084    1186 placement_manager.go:192]  "msg"="Releasing slots"  "jobs"={"tf2-keras-cifar10-inceptionv3-elastic-20210721-063756":{},"tf2-keras-cifar10-resnet50-elastic-20210721-063511":{},"tf2-keras-cifar10-resnet50-elastic-20210721-063833":{},"tf2-keras-cifar10-vgg16-elastic-20210721-063631":{},"tf2-keras-transformer-elastic-20210721-063654":{},"tf2-keras-transformer-elastic-20210721-063721":{}} "nodes"={"gpu3":{},"gpu4":{},"gpu5":{}} "scheduler"="default"
I0721 18:52:49.210128    1186 placement_manager.go:250]  "msg"="Released slots"  "jobs"={"tf2-keras-cifar10-inceptionv3-elastic-20210721-063756":{},"tf2-keras-cifar10-resnet50-elastic-20210721-063511":{},"tf2-keras-cifar10-resnet50-elastic-20210721-063833":{},"tf2-keras-cifar10-vgg16-elastic-20210721-063631":{},"tf2-keras-transformer-elastic-20210721-063654":{},"tf2-keras-transformer-elastic-20210721-063721":{}} "nodes"={"gpu3":{},"gpu4":{},"gpu5":{}} "scheduler"="default"
I0721 18:52:49.210573    1186 placement_manager.go:305]  "msg"="Found best-fit"  "crossNode"=0 "nodes"=[{},{},{}] "requests"=[{},{},{},{},{},{},{},{},{},{},{},{},{},{},{},{},{},{},{},{},{},{},{},{},{},{},{},{},{},{},{},{},{},{},{},{},{},{},{},{},{},{},{},{},{},{}] "scheduler"="default"
I0721 18:52:49.210899    1186 placement_manager.go:339]  "msg"="nodeStates updated"  "new"={"gpu3":{},"gpu4":{},"gpu5":{}} "old"={"gpu3":{},"gpu4":{},"gpu5":{}} "scheduler"="default" "score"=4
I0721 18:52:49.211084    1186 placement_manager.go:387]  "msg"="jobStates updated"  "new"={"tf2-keras-cifar10-inceptionv3-elastic-20210721-063756":{},"tf2-keras-cifar10-inceptionv3-elastic-20210721-063900":{},"tf2-keras-cifar10-resnet50-elastic-20210721-063833":{},"tf2-keras-transformer-elastic-20210721-063654":{},"tf2-keras-transformer-elastic-20210721-063721":{},"tf2-keras-transformer-elastic-20210721-063927":{}} "old"={"tf2-keras-cifar10-inceptionv3-elastic-20210721-063756":{},"tf2-keras-cifar10-resnet50-elastic-20210721-063511":{},"tf2-keras-cifar10-resnet50-elastic-20210721-063833":{},"tf2-keras-cifar10-vgg16-elastic-20210721-063631":{},"tf2-keras-transformer-elastic-20210721-063654":{},"tf2-keras-transformer-elastic-20210721-063721":{}} "scheduler"="default"
I0721 18:52:49.211344    1186 placement_manager.go:434]  "msg"="podNodeName updated"  "launchersToDelete"=2 "new"={"tf2-keras-cifar10-inceptionv3-elastic-20210721-063756-worker-0":"gpu3","tf2-keras-cifar10-inceptionv3-elastic-20210721-063756-worker-1":"gpu3","tf2-keras-cifar10-inceptionv3-elastic-20210721-063900-worker-0":"gpu4","tf2-keras-cifar10-inceptionv3-elastic-20210721-063900-worker-1":"gpu4","tf2-keras-cifar10-resnet50-elastic-20210721-063833-worker-0":"gpu5","tf2-keras-cifar10-resnet50-elastic-20210721-063833-worker-1":"gpu5","tf2-keras-transformer-elastic-20210721-063654-worker-0":"gpu5","tf2-keras-transformer-elastic-20210721-063654-worker-1":"gpu5","tf2-keras-transformer-elastic-20210721-063721-worker-0":"gpu4","tf2-keras-transformer-elastic-20210721-063721-worker-1":"gpu4","tf2-keras-transformer-elastic-20210721-063927-worker-0":"gpu3","tf2-keras-transformer-elastic-20210721-063927-worker-1":"gpu3"} "old"={"tf2-keras-cifar10-inceptionv3-elastic-20210721-063756-worker-0":"gpu4","tf2-keras-cifar10-inceptionv3-elastic-20210721-063756-worker-1":"gpu4","tf2-keras-cifar10-resnet50-elastic-20210721-063511-worker-0":"gpu5","tf2-keras-cifar10-resnet50-elastic-20210721-063511-worker-1":"gpu5","tf2-keras-cifar10-resnet50-elastic-20210721-063833-worker-0":"gpu5","tf2-keras-cifar10-resnet50-elastic-20210721-063833-worker-1":"gpu5","tf2-keras-cifar10-vgg16-elastic-20210721-063631-worker-0":"gpu3","tf2-keras-cifar10-vgg16-elastic-20210721-063631-worker-1":"gpu3","tf2-keras-transformer-elastic-20210721-063654-worker-0":"gpu3","tf2-keras-transformer-elastic-20210721-063654-worker-1":"gpu3","tf2-keras-transformer-elastic-20210721-063721-worker-0":"gpu4","tf2-keras-transformer-elastic-20210721-063721-worker-1":"gpu4"} "scheduler"="default" "workersToDelete"=4
I0721 18:52:49.211586    1186 placement_manager.go:451]  "msg"="Deleting pod that need migration"  "podName"="tf2-keras-cifar10-inceptionv3-elastic-20210721-063756-worker-0" "scheduler"="default"
I0721 18:52:49.220036    1186 placement_manager.go:451]  "msg"="Deleting pod that need migration"  "podName"="tf2-keras-cifar10-inceptionv3-elastic-20210721-063756-worker-1" "scheduler"="default"
I0721 18:52:49.229031    1186 placement_manager.go:451]  "msg"="Deleting pod that need migration"  "podName"="tf2-keras-cifar10-inceptionv3-elastic-20210721-063756-launcher" "scheduler"="default"
I0721 18:52:49.233371    1186 placement_manager.go:451]  "msg"="Deleting pod that need migration"  "podName"="tf2-keras-transformer-elastic-20210721-063654-worker-0" "scheduler"="default"
I0721 18:52:49.236196    1186 placement_manager.go:451]  "msg"="Deleting pod that need migration"  "podName"="tf2-keras-transformer-elastic-20210721-063654-worker-1" "scheduler"="default"
I0721 18:52:49.240585    1186 placement_manager.go:451]  "msg"="Deleting pod that need migration"  "podName"="tf2-keras-transformer-elastic-20210721-063654-launcher" "scheduler"="default"
I0721 18:52:49.245591    1186 placement_manager.go:183]  "msg"="Finished job placements adjustment"  "scheduler"="default"
I0721 18:52:49.245905    1186 scheduler.go:182]  "msg"="Finished resched"  "scheduler"="default"
I0721 18:52:49.410162    1186 placement_manager.go:147]  "msg"="Adding toleration to pod"  "podName"="tf2-keras-cifar10-inceptionv3-elastic-20210721-063900-worker-0" "scheduler"="default" "toleration"={"key":"celeste/hostname","operator":"Equal","value":"gpu4","effect":"NoExecute"}
I0721 18:52:49.605986    1186 placement_manager.go:147]  "msg"="Adding toleration to pod"  "podName"="tf2-keras-transformer-elastic-20210721-063927-worker-0" "scheduler"="default" "toleration"={"key":"celeste/hostname","operator":"Equal","value":"gpu3","effect":"NoExecute"}
I0721 18:52:50.019777    1186 placement_manager.go:147]  "msg"="Adding toleration to pod"  "podName"="tf2-keras-cifar10-inceptionv3-elastic-20210721-063900-worker-1" "scheduler"="default" "toleration"={"key":"celeste/hostname","operator":"Equal","value":"gpu4","effect":"NoExecute"}
I0721 18:52:50.423225    1186 placement_manager.go:147]  "msg"="Adding toleration to pod"  "podName"="tf2-keras-transformer-elastic-20210721-063927-worker-1" "scheduler"="default" "toleration"={"key":"celeste/hostname","operator":"Equal","value":"gpu3","effect":"NoExecute"}
I0721 18:52:50.819530    1186 placement_manager.go:147]  "msg"="Adding toleration to pod"  "podName"="tf2-keras-cifar10-inceptionv3-elastic-20210721-063900-launcher" "scheduler"="default" "toleration"={"key":"celeste/hostname","operator":"Exists","effect":"NoExecute"}
I0721 18:52:51.222937    1186 placement_manager.go:147]  "msg"="Adding toleration to pod"  "podName"="tf2-keras-transformer-elastic-20210721-063927-launcher" "scheduler"="default" "toleration"={"key":"celeste/hostname","operator":"Exists","effect":"NoExecute"}
I0721 18:52:57.539549    1186 placement_manager.go:147]  "msg"="Adding toleration to pod"  "podName"="tf2-keras-transformer-elastic-20210721-063654-worker-0" "scheduler"="default" "toleration"={"key":"celeste/hostname","operator":"Equal","value":"gpu5","effect":"NoExecute"}
I0721 18:52:57.948420    1186 placement_manager.go:147]  "msg"="Adding toleration to pod"  "podName"="tf2-keras-transformer-elastic-20210721-063654-worker-1" "scheduler"="default" "toleration"={"key":"celeste/hostname","operator":"Equal","value":"gpu5","effect":"NoExecute"}
I0721 18:53:05.292265    1186 placement_manager.go:147]  "msg"="Adding toleration to pod"  "podName"="tf2-keras-cifar10-inceptionv3-elastic-20210721-063756-launcher" "scheduler"="default" "toleration"={"key":"celeste/hostname","operator":"Exists","effect":"NoExecute"}
I0721 18:53:06.086678    1186 placement_manager.go:147]  "msg"="Adding toleration to pod"  "podName"="tf2-keras-cifar10-inceptionv3-elastic-20210721-063756-worker-0" "scheduler"="default" "toleration"={"key":"celeste/hostname","operator":"Equal","value":"gpu3","effect":"NoExecute"}
I0721 18:53:06.884794    1186 placement_manager.go:147]  "msg"="Adding toleration to pod"  "podName"="tf2-keras-cifar10-inceptionv3-elastic-20210721-063756-worker-1" "scheduler"="default" "toleration"={"key":"celeste/hostname","operator":"Equal","value":"gpu3","effect":"NoExecute"}
I0721 18:53:07.696759    1186 placement_manager.go:147]  "msg"="Adding toleration to pod"  "podName"="tf2-keras-transformer-elastic-20210721-063654-launcher" "scheduler"="default" "toleration"={"key":"celeste/hostname","operator":"Exists","effect":"NoExecute"}
I0721 18:53:46.497734    1186 scheduler.go:559]  "msg"="Priority demoted to training job"  "job"="tf2-keras-transformer-elastic-20210721-063654" "priority"=1 "scheduler"="default"
I0721 18:53:46.497803    1186 scheduler.go:573]  "msg"="Priority changed"  "scheduler"="default"
I0721 18:53:46.497871    1186 scheduler.go:135]  "msg"="Received resched event, may be blocked because of rate limit"  "blockedUntil"="2021-07-21T18:54:49.246145289+08:00" "lastResched"="2021-07-21T18:52:49.246145289+08:00" "received"="2021-07-21T18:53:46.497811207+08:00" "scheduler"="default"
I0721 18:54:49.246225    1186 scheduler.go:159]  "msg"="Started resched"  "scheduler"="default"
I0721 18:54:49.246329    1186 scheduler.go:193]  "msg"="Updating all jobs info"  "scheduler"="default"
I0721 18:54:49.256495    1186 elastic_tiresias.go:160]  "msg"="Finished scheduling"  "algorithm"="ElasticTiresias" "compactionThreshold"=4 "freeGpu"=0 "promoteKnob"=4 "queueNum"=2 "result"={"tf2-keras-cifar10-inceptionv3-elastic-20210721-063448":0,"tf2-keras-cifar10-inceptionv3-elastic-20210721-063539":0,"tf2-keras-cifar10-inceptionv3-elastic-20210721-063756":2,"tf2-keras-cifar10-inceptionv3-elastic-20210721-063900":2,"tf2-keras-cifar10-inceptionv3-elastic-20210721-064117":0,"tf2-keras-cifar10-inceptionv3-elastic-20210721-064215":0,"tf2-keras-cifar10-resnet50-elastic-20210721-063511":0,"tf2-keras-cifar10-resnet50-elastic-20210721-063833":2,"tf2-keras-cifar10-resnet50-elastic-20210721-064048":0,"tf2-keras-cifar10-resnet50-elastic-20210721-064237":0,"tf2-keras-cifar10-resnet50-elastic-20210721-064451":0,"tf2-keras-cifar10-resnet50-elastic-20210721-064517":0,"tf2-keras-cifar10-vgg16-elastic-20210721-063631":0,"tf2-keras-cifar10-vgg16-elastic-20210721-063952":2,"tf2-keras-cifar10-vgg16-elastic-20210721-064019":0,"tf2-keras-cifar10-vgg16-elastic-20210721-064310":0,"tf2-keras-cifar10-vgg16-elastic-20210721-064412":0,"tf2-keras-transformer-elastic-20210721-063654":0,"tf2-keras-transformer-elastic-20210721-063721":2,"tf2-keras-transformer-elastic-20210721-063927":2,"tf2-keras-transformer-elastic-20210721-064152":0,"tf2-keras-transformer-elastic-20210721-064332":0,"tf2-keras-transformer-elastic-20210721-064545":0} "scheduler"="default" "thresholds"=
I0721 18:54:49.256776    1186 scheduler.go:384]  "msg"="Trying to delete multiple training jobs"  "jobs"=["tf2-keras-transformer-elastic-20210721-063654"] "scheduler"="default"
I0721 18:54:49.268567    1186 scheduler.go:342]  "msg"="Trying to scale multiple training jobs"  "jobs"=[] "scheduler"="default"
I0721 18:54:49.268953    1186 scheduler.go:292]  "msg"="Trying to start multiple training jobs"  "jobs"=["tf2-keras-cifar10-vgg16-elastic-20210721-063952"] "scheduler"="default"
I0721 18:54:49.294761    1186 scheduler.go:342]  "msg"="Trying to scale multiple training jobs"  "jobs"=[] "scheduler"="default"
I0721 18:54:49.298420    1186 placement_manager.go:166]  "msg"="Started job placements adjustment"  "scheduler"="default"
I0721 18:54:49.298517    1186 placement_manager.go:192]  "msg"="Releasing slots"  "jobs"={"tf2-keras-cifar10-inceptionv3-elastic-20210721-063756":{},"tf2-keras-cifar10-inceptionv3-elastic-20210721-063900":{},"tf2-keras-cifar10-resnet50-elastic-20210721-063833":{},"tf2-keras-transformer-elastic-20210721-063654":{},"tf2-keras-transformer-elastic-20210721-063721":{},"tf2-keras-transformer-elastic-20210721-063927":{}} "nodes"={"gpu3":{},"gpu4":{},"gpu5":{}} "scheduler"="default"
I0721 18:54:49.298586    1186 placement_manager.go:250]  "msg"="Released slots"  "jobs"={"tf2-keras-cifar10-inceptionv3-elastic-20210721-063756":{},"tf2-keras-cifar10-inceptionv3-elastic-20210721-063900":{},"tf2-keras-cifar10-resnet50-elastic-20210721-063833":{},"tf2-keras-transformer-elastic-20210721-063654":{},"tf2-keras-transformer-elastic-20210721-063721":{},"tf2-keras-transformer-elastic-20210721-063927":{}} "nodes"={"gpu3":{},"gpu4":{},"gpu5":{}} "scheduler"="default"
I0721 18:54:49.298967    1186 placement_manager.go:305]  "msg"="Found best-fit"  "crossNode"=0 "nodes"=[{},{},{}] "requests"=[{},{},{},{},{},{},{},{},{},{},{},{},{},{},{},{},{},{},{},{},{},{},{},{},{},{},{},{},{},{},{},{},{},{},{},{},{},{},{},{},{},{},{},{},{},{}] "scheduler"="default"
I0721 18:54:49.299275    1186 placement_manager.go:339]  "msg"="nodeStates updated"  "new"={"gpu3":{},"gpu4":{},"gpu5":{}} "old"={"gpu3":{},"gpu4":{},"gpu5":{}} "scheduler"="default" "score"=8
I0721 18:54:49.299614    1186 placement_manager.go:387]  "msg"="jobStates updated"  "new"={"tf2-keras-cifar10-inceptionv3-elastic-20210721-063756":{},"tf2-keras-cifar10-inceptionv3-elastic-20210721-063900":{},"tf2-keras-cifar10-resnet50-elastic-20210721-063833":{},"tf2-keras-cifar10-vgg16-elastic-20210721-063952":{},"tf2-keras-transformer-elastic-20210721-063721":{},"tf2-keras-transformer-elastic-20210721-063927":{}} "old"={"tf2-keras-cifar10-inceptionv3-elastic-20210721-063756":{},"tf2-keras-cifar10-inceptionv3-elastic-20210721-063900":{},"tf2-keras-cifar10-resnet50-elastic-20210721-063833":{},"tf2-keras-transformer-elastic-20210721-063654":{},"tf2-keras-transformer-elastic-20210721-063721":{},"tf2-keras-transformer-elastic-20210721-063927":{}} "scheduler"="default"
I0721 18:54:49.300025    1186 placement_manager.go:434]  "msg"="podNodeName updated"  "launchersToDelete"=1 "new"={"tf2-keras-cifar10-inceptionv3-elastic-20210721-063756-worker-0":"gpu3","tf2-keras-cifar10-inceptionv3-elastic-20210721-063756-worker-1":"gpu3","tf2-keras-cifar10-inceptionv3-elastic-20210721-063900-worker-0":"gpu5","tf2-keras-cifar10-inceptionv3-elastic-20210721-063900-worker-1":"gpu5","tf2-keras-cifar10-resnet50-elastic-20210721-063833-worker-0":"gpu5","tf2-keras-cifar10-resnet50-elastic-20210721-063833-worker-1":"gpu5","tf2-keras-cifar10-vgg16-elastic-20210721-063952-worker-0":"gpu4","tf2-keras-cifar10-vgg16-elastic-20210721-063952-worker-1":"gpu4","tf2-keras-transformer-elastic-20210721-063721-worker-0":"gpu4","tf2-keras-transformer-elastic-20210721-063721-worker-1":"gpu4","tf2-keras-transformer-elastic-20210721-063927-worker-0":"gpu3","tf2-keras-transformer-elastic-20210721-063927-worker-1":"gpu3"} "old"={"tf2-keras-cifar10-inceptionv3-elastic-20210721-063756-worker-0":"gpu3","tf2-keras-cifar10-inceptionv3-elastic-20210721-063756-worker-1":"gpu3","tf2-keras-cifar10-inceptionv3-elastic-20210721-063900-worker-0":"gpu4","tf2-keras-cifar10-inceptionv3-elastic-20210721-063900-worker-1":"gpu4","tf2-keras-cifar10-resnet50-elastic-20210721-063833-worker-0":"gpu5","tf2-keras-cifar10-resnet50-elastic-20210721-063833-worker-1":"gpu5","tf2-keras-transformer-elastic-20210721-063654-worker-0":"gpu5","tf2-keras-transformer-elastic-20210721-063654-worker-1":"gpu5","tf2-keras-transformer-elastic-20210721-063721-worker-0":"gpu4","tf2-keras-transformer-elastic-20210721-063721-worker-1":"gpu4","tf2-keras-transformer-elastic-20210721-063927-worker-0":"gpu3","tf2-keras-transformer-elastic-20210721-063927-worker-1":"gpu3"} "scheduler"="default" "workersToDelete"=2
I0721 18:54:49.300332    1186 placement_manager.go:451]  "msg"="Deleting pod that need migration"  "podName"="tf2-keras-cifar10-inceptionv3-elastic-20210721-063900-worker-0" "scheduler"="default"
I0721 18:54:49.305035    1186 placement_manager.go:451]  "msg"="Deleting pod that need migration"  "podName"="tf2-keras-cifar10-inceptionv3-elastic-20210721-063900-worker-1" "scheduler"="default"
I0721 18:54:49.311180    1186 placement_manager.go:451]  "msg"="Deleting pod that need migration"  "podName"="tf2-keras-cifar10-inceptionv3-elastic-20210721-063900-launcher" "scheduler"="default"
I0721 18:54:49.315654    1186 placement_manager.go:183]  "msg"="Finished job placements adjustment"  "scheduler"="default"
I0721 18:54:49.315925    1186 scheduler.go:182]  "msg"="Finished resched"  "scheduler"="default"
I0721 18:54:49.342113    1186 placement_manager.go:147]  "msg"="Adding toleration to pod"  "podName"="tf2-keras-cifar10-vgg16-elastic-20210721-063952-worker-0" "scheduler"="default" "toleration"={"key":"celeste/hostname","operator":"Equal","value":"gpu4","effect":"NoExecute"}
I0721 18:54:49.380614    1186 placement_manager.go:147]  "msg"="Adding toleration to pod"  "podName"="tf2-keras-cifar10-vgg16-elastic-20210721-063952-worker-1" "scheduler"="default" "toleration"={"key":"celeste/hostname","operator":"Equal","value":"gpu4","effect":"NoExecute"}
I0721 18:54:49.501109    1186 placement_manager.go:147]  "msg"="Adding toleration to pod"  "podName"="tf2-keras-cifar10-vgg16-elastic-20210721-063952-launcher" "scheduler"="default" "toleration"={"key":"celeste/hostname","operator":"Exists","effect":"NoExecute"}
I0721 18:55:00.114606    1186 placement_manager.go:147]  "msg"="Adding toleration to pod"  "podName"="tf2-keras-cifar10-inceptionv3-elastic-20210721-063900-launcher" "scheduler"="default" "toleration"={"key":"celeste/hostname","operator":"Exists","effect":"NoExecute"}
I0721 18:55:05.071168    1186 placement_manager.go:147]  "msg"="Adding toleration to pod"  "podName"="tf2-keras-cifar10-inceptionv3-elastic-20210721-063900-worker-1" "scheduler"="default" "toleration"={"key":"celeste/hostname","operator":"Equal","value":"gpu5","effect":"NoExecute"}
I0721 18:55:05.852830    1186 placement_manager.go:147]  "msg"="Adding toleration to pod"  "podName"="tf2-keras-cifar10-inceptionv3-elastic-20210721-063900-worker-0" "scheduler"="default" "toleration"={"key":"celeste/hostname","operator":"Equal","value":"gpu5","effect":"NoExecute"}
I0721 19:03:46.520295    1186 scheduler.go:559]  "msg"="Priority demoted to training job"  "job"="tf2-keras-transformer-elastic-20210721-063721" "priority"=1 "scheduler"="default"
I0721 19:03:46.520374    1186 scheduler.go:573]  "msg"="Priority changed"  "scheduler"="default"
I0721 19:03:46.520501    1186 scheduler.go:135]  "msg"="Received resched event, may be blocked because of rate limit"  "blockedUntil"="2021-07-21T18:56:49.316216278+08:00" "lastResched"="2021-07-21T18:54:49.316216278+08:00" "received"="2021-07-21T19:03:46.52038835+08:00" "scheduler"="default"
I0721 19:03:46.520559    1186 scheduler.go:159]  "msg"="Started resched"  "scheduler"="default"
I0721 19:03:46.520648    1186 scheduler.go:193]  "msg"="Updating all jobs info"  "scheduler"="default"
I0721 19:03:46.535624    1186 elastic_tiresias.go:160]  "msg"="Finished scheduling"  "algorithm"="ElasticTiresias" "compactionThreshold"=4 "freeGpu"=0 "promoteKnob"=4 "queueNum"=2 "result"={"tf2-keras-cifar10-inceptionv3-elastic-20210721-063448":0,"tf2-keras-cifar10-inceptionv3-elastic-20210721-063539":0,"tf2-keras-cifar10-inceptionv3-elastic-20210721-063756":2,"tf2-keras-cifar10-inceptionv3-elastic-20210721-063900":2,"tf2-keras-cifar10-inceptionv3-elastic-20210721-064117":0,"tf2-keras-cifar10-inceptionv3-elastic-20210721-064215":0,"tf2-keras-cifar10-resnet50-elastic-20210721-063511":0,"tf2-keras-cifar10-resnet50-elastic-20210721-063833":2,"tf2-keras-cifar10-resnet50-elastic-20210721-064048":0,"tf2-keras-cifar10-resnet50-elastic-20210721-064237":0,"tf2-keras-cifar10-resnet50-elastic-20210721-064451":0,"tf2-keras-cifar10-resnet50-elastic-20210721-064517":0,"tf2-keras-cifar10-vgg16-elastic-20210721-063631":0,"tf2-keras-cifar10-vgg16-elastic-20210721-063952":2,"tf2-keras-cifar10-vgg16-elastic-20210721-064019":2,"tf2-keras-cifar10-vgg16-elastic-20210721-064310":0,"tf2-keras-cifar10-vgg16-elastic-20210721-064412":0,"tf2-keras-transformer-elastic-20210721-063654":0,"tf2-keras-transformer-elastic-20210721-063721":0,"tf2-keras-transformer-elastic-20210721-063927":2,"tf2-keras-transformer-elastic-20210721-064152":0,"tf2-keras-transformer-elastic-20210721-064332":0,"tf2-keras-transformer-elastic-20210721-064545":0} "scheduler"="default" "thresholds"=
I0721 19:03:46.535909    1186 scheduler.go:384]  "msg"="Trying to delete multiple training jobs"  "jobs"=["tf2-keras-transformer-elastic-20210721-063721"] "scheduler"="default"
I0721 19:03:46.547866    1186 scheduler.go:342]  "msg"="Trying to scale multiple training jobs"  "jobs"=[] "scheduler"="default"
I0721 19:03:46.548103    1186 scheduler.go:292]  "msg"="Trying to start multiple training jobs"  "jobs"=["tf2-keras-cifar10-vgg16-elastic-20210721-064019"] "scheduler"="default"
I0721 19:03:46.564827    1186 scheduler.go:342]  "msg"="Trying to scale multiple training jobs"  "jobs"=[] "scheduler"="default"
I0721 19:03:46.567697    1186 placement_manager.go:166]  "msg"="Started job placements adjustment"  "scheduler"="default"
I0721 19:03:46.567771    1186 placement_manager.go:192]  "msg"="Releasing slots"  "jobs"={"tf2-keras-cifar10-inceptionv3-elastic-20210721-063756":{},"tf2-keras-cifar10-inceptionv3-elastic-20210721-063900":{},"tf2-keras-cifar10-resnet50-elastic-20210721-063833":{},"tf2-keras-cifar10-vgg16-elastic-20210721-063952":{},"tf2-keras-transformer-elastic-20210721-063721":{},"tf2-keras-transformer-elastic-20210721-063927":{}} "nodes"={"gpu3":{},"gpu4":{},"gpu5":{}} "scheduler"="default"
I0721 19:03:46.567831    1186 placement_manager.go:250]  "msg"="Released slots"  "jobs"={"tf2-keras-cifar10-inceptionv3-elastic-20210721-063756":{},"tf2-keras-cifar10-inceptionv3-elastic-20210721-063900":{},"tf2-keras-cifar10-resnet50-elastic-20210721-063833":{},"tf2-keras-cifar10-vgg16-elastic-20210721-063952":{},"tf2-keras-transformer-elastic-20210721-063721":{},"tf2-keras-transformer-elastic-20210721-063927":{}} "nodes"={"gpu3":{},"gpu4":{},"gpu5":{}} "scheduler"="default"
I0721 19:03:46.568231    1186 placement_manager.go:305]  "msg"="Found best-fit"  "crossNode"=0 "nodes"=[{},{},{}] "requests"=[{},{},{},{},{},{},{},{},{},{},{},{},{},{},{},{},{},{},{},{},{},{},{},{},{},{},{},{},{},{},{},{},{},{},{},{},{},{},{},{},{},{},{},{},{},{}] "scheduler"="default"
I0721 19:03:46.568500    1186 placement_manager.go:339]  "msg"="nodeStates updated"  "new"={"gpu3":{},"gpu4":{},"gpu5":{}} "old"={"gpu3":{},"gpu4":{},"gpu5":{}} "scheduler"="default" "score"=6
I0721 19:03:46.568761    1186 placement_manager.go:387]  "msg"="jobStates updated"  "new"={"tf2-keras-cifar10-inceptionv3-elastic-20210721-063756":{},"tf2-keras-cifar10-inceptionv3-elastic-20210721-063900":{},"tf2-keras-cifar10-resnet50-elastic-20210721-063833":{},"tf2-keras-cifar10-vgg16-elastic-20210721-063952":{},"tf2-keras-cifar10-vgg16-elastic-20210721-064019":{},"tf2-keras-transformer-elastic-20210721-063927":{}} "old"={"tf2-keras-cifar10-inceptionv3-elastic-20210721-063756":{},"tf2-keras-cifar10-inceptionv3-elastic-20210721-063900":{},"tf2-keras-cifar10-resnet50-elastic-20210721-063833":{},"tf2-keras-cifar10-vgg16-elastic-20210721-063952":{},"tf2-keras-transformer-elastic-20210721-063721":{},"tf2-keras-transformer-elastic-20210721-063927":{}} "scheduler"="default"
I0721 19:03:46.569098    1186 placement_manager.go:434]  "msg"="podNodeName updated"  "launchersToDelete"=2 "new"={"tf2-keras-cifar10-inceptionv3-elastic-20210721-063756-worker-0":"gpu5","tf2-keras-cifar10-inceptionv3-elastic-20210721-063756-worker-1":"gpu5","tf2-keras-cifar10-inceptionv3-elastic-20210721-063900-worker-0":"gpu5","tf2-keras-cifar10-inceptionv3-elastic-20210721-063900-worker-1":"gpu5","tf2-keras-cifar10-resnet50-elastic-20210721-063833-worker-0":"gpu4","tf2-keras-cifar10-resnet50-elastic-20210721-063833-worker-1":"gpu4","tf2-keras-cifar10-vgg16-elastic-20210721-063952-worker-0":"gpu4","tf2-keras-cifar10-vgg16-elastic-20210721-063952-worker-1":"gpu4","tf2-keras-cifar10-vgg16-elastic-20210721-064019-worker-0":"gpu3","tf2-keras-cifar10-vgg16-elastic-20210721-064019-worker-1":"gpu3","tf2-keras-transformer-elastic-20210721-063927-worker-0":"gpu3","tf2-keras-transformer-elastic-20210721-063927-worker-1":"gpu3"} "old"={"tf2-keras-cifar10-inceptionv3-elastic-20210721-063756-worker-0":"gpu3","tf2-keras-cifar10-inceptionv3-elastic-20210721-063756-worker-1":"gpu3","tf2-keras-cifar10-inceptionv3-elastic-20210721-063900-worker-0":"gpu5","tf2-keras-cifar10-inceptionv3-elastic-20210721-063900-worker-1":"gpu5","tf2-keras-cifar10-resnet50-elastic-20210721-063833-worker-0":"gpu5","tf2-keras-cifar10-resnet50-elastic-20210721-063833-worker-1":"gpu5","tf2-keras-cifar10-vgg16-elastic-20210721-063952-worker-0":"gpu4","tf2-keras-cifar10-vgg16-elastic-20210721-063952-worker-1":"gpu4","tf2-keras-transformer-elastic-20210721-063721-worker-0":"gpu4","tf2-keras-transformer-elastic-20210721-063721-worker-1":"gpu4","tf2-keras-transformer-elastic-20210721-063927-worker-0":"gpu3","tf2-keras-transformer-elastic-20210721-063927-worker-1":"gpu3"} "scheduler"="default" "workersToDelete"=4
I0721 19:03:46.569368    1186 placement_manager.go:451]  "msg"="Deleting pod that need migration"  "podName"="tf2-keras-cifar10-resnet50-elastic-20210721-063833-worker-0" "scheduler"="default"
I0721 19:03:46.573552    1186 placement_manager.go:451]  "msg"="Deleting pod that need migration"  "podName"="tf2-keras-cifar10-resnet50-elastic-20210721-063833-worker-1" "scheduler"="default"
I0721 19:03:46.577266    1186 placement_manager.go:451]  "msg"="Deleting pod that need migration"  "podName"="tf2-keras-cifar10-resnet50-elastic-20210721-063833-launcher" "scheduler"="default"
I0721 19:03:46.586757    1186 placement_manager.go:451]  "msg"="Deleting pod that need migration"  "podName"="tf2-keras-cifar10-inceptionv3-elastic-20210721-063756-worker-0" "scheduler"="default"
I0721 19:03:46.591092    1186 placement_manager.go:451]  "msg"="Deleting pod that need migration"  "podName"="tf2-keras-cifar10-inceptionv3-elastic-20210721-063756-worker-1" "scheduler"="default"
I0721 19:03:46.594578    1186 placement_manager.go:451]  "msg"="Deleting pod that need migration"  "podName"="tf2-keras-cifar10-inceptionv3-elastic-20210721-063756-launcher" "scheduler"="default"
I0721 19:03:46.599464    1186 placement_manager.go:183]  "msg"="Finished job placements adjustment"  "scheduler"="default"
I0721 19:03:46.599726    1186 scheduler.go:182]  "msg"="Finished resched"  "scheduler"="default"
I0721 19:03:46.626203    1186 placement_manager.go:147]  "msg"="Adding toleration to pod"  "podName"="tf2-keras-cifar10-vgg16-elastic-20210721-064019-worker-0" "scheduler"="default" "toleration"={"key":"celeste/hostname","operator":"Equal","value":"gpu3","effect":"NoExecute"}
I0721 19:03:46.771400    1186 placement_manager.go:147]  "msg"="Adding toleration to pod"  "podName"="tf2-keras-cifar10-vgg16-elastic-20210721-064019-worker-1" "scheduler"="default" "toleration"={"key":"celeste/hostname","operator":"Equal","value":"gpu3","effect":"NoExecute"}
I0721 19:03:47.376491    1186 placement_manager.go:147]  "msg"="Adding toleration to pod"  "podName"="tf2-keras-cifar10-vgg16-elastic-20210721-064019-launcher" "scheduler"="default" "toleration"={"key":"celeste/hostname","operator":"Exists","effect":"NoExecute"}
I0721 19:03:56.074037    1186 placement_manager.go:147]  "msg"="Adding toleration to pod"  "podName"="tf2-keras-cifar10-resnet50-elastic-20210721-063833-worker-1" "scheduler"="default" "toleration"={"key":"celeste/hostname","operator":"Equal","value":"gpu4","effect":"NoExecute"}
I0721 19:03:56.114844    1186 placement_manager.go:147]  "msg"="Adding toleration to pod"  "podName"="tf2-keras-cifar10-inceptionv3-elastic-20210721-063756-launcher" "scheduler"="default" "toleration"={"key":"celeste/hostname","operator":"Exists","effect":"NoExecute"}
I0721 19:03:56.125469    1186 placement_manager.go:147]  "msg"="Adding toleration to pod"  "podName"="tf2-keras-cifar10-resnet50-elastic-20210721-063833-launcher" "scheduler"="default" "toleration"={"key":"celeste/hostname","operator":"Exists","effect":"NoExecute"}
I0721 19:03:56.228363    1186 placement_manager.go:147]  "msg"="Adding toleration to pod"  "podName"="tf2-keras-cifar10-resnet50-elastic-20210721-063833-worker-0" "scheduler"="default" "toleration"={"key":"celeste/hostname","operator":"Equal","value":"gpu4","effect":"NoExecute"}
I0721 19:03:59.275053    1186 placement_manager.go:147]  "msg"="Adding toleration to pod"  "podName"="tf2-keras-cifar10-inceptionv3-elastic-20210721-063756-worker-0" "scheduler"="default" "toleration"={"key":"celeste/hostname","operator":"Equal","value":"gpu5","effect":"NoExecute"}
I0721 19:03:59.312742    1186 placement_manager.go:147]  "msg"="Adding toleration to pod"  "podName"="tf2-keras-cifar10-inceptionv3-elastic-20210721-063756-worker-1" "scheduler"="default" "toleration"={"key":"celeste/hostname","operator":"Equal","value":"gpu5","effect":"NoExecute"}
I0721 19:05:18.382574    1186 scheduler.go:474]  "msg"="Training job completed"  "elaspedTotalSeconds"=1603.162299209 "gpuTotalSeconds"=1740.065533528 "job"="tf2-keras-cifar10-resnet50-elastic-20210721-063833" "ranTotalSeconds"=870.032766764 "scheduler"="default" "waitedTotalSeconds"=733.129532445
I0721 19:05:18.382738    1186 scheduler.go:135]  "msg"="Received resched event, may be blocked because of rate limit"  "blockedUntil"="2021-07-21T19:05:46.599943688+08:00" "lastResched"="2021-07-21T19:03:46.599943688+08:00" "received"="2021-07-21T19:05:18.382613516+08:00" "scheduler"="default"
I0721 19:05:46.524781    1186 scheduler.go:559]  "msg"="Priority demoted to training job"  "job"="tf2-keras-cifar10-inceptionv3-elastic-20210721-063756" "priority"=1 "scheduler"="default"
I0721 19:05:46.524838    1186 scheduler.go:573]  "msg"="Priority changed"  "scheduler"="default"
I0721 19:05:46.599999    1186 scheduler.go:159]  "msg"="Started resched"  "scheduler"="default"
I0721 19:05:46.600047    1186 scheduler.go:193]  "msg"="Updating all jobs info"  "scheduler"="default"
I0721 19:05:46.610982    1186 elastic_tiresias.go:160]  "msg"="Finished scheduling"  "algorithm"="ElasticTiresias" "compactionThreshold"=4 "freeGpu"=0 "promoteKnob"=4 "queueNum"=2 "result"={"tf2-keras-cifar10-inceptionv3-elastic-20210721-063448":0,"tf2-keras-cifar10-inceptionv3-elastic-20210721-063539":0,"tf2-keras-cifar10-inceptionv3-elastic-20210721-063756":0,"tf2-keras-cifar10-inceptionv3-elastic-20210721-063900":2,"tf2-keras-cifar10-inceptionv3-elastic-20210721-064117":2,"tf2-keras-cifar10-inceptionv3-elastic-20210721-064215":0,"tf2-keras-cifar10-resnet50-elastic-20210721-063511":0,"tf2-keras-cifar10-resnet50-elastic-20210721-064048":2,"tf2-keras-cifar10-resnet50-elastic-20210721-064237":0,"tf2-keras-cifar10-resnet50-elastic-20210721-064451":0,"tf2-keras-cifar10-resnet50-elastic-20210721-064517":0,"tf2-keras-cifar10-vgg16-elastic-20210721-063631":0,"tf2-keras-cifar10-vgg16-elastic-20210721-063952":2,"tf2-keras-cifar10-vgg16-elastic-20210721-064019":2,"tf2-keras-cifar10-vgg16-elastic-20210721-064310":0,"tf2-keras-cifar10-vgg16-elastic-20210721-064412":0,"tf2-keras-transformer-elastic-20210721-063654":0,"tf2-keras-transformer-elastic-20210721-063721":0,"tf2-keras-transformer-elastic-20210721-063927":2,"tf2-keras-transformer-elastic-20210721-064152":0,"tf2-keras-transformer-elastic-20210721-064332":0,"tf2-keras-transformer-elastic-20210721-064545":0} "scheduler"="default" "thresholds"=
I0721 19:05:46.611563    1186 scheduler.go:384]  "msg"="Trying to delete multiple training jobs"  "jobs"=["tf2-keras-cifar10-inceptionv3-elastic-20210721-063756"] "scheduler"="default"
I0721 19:05:46.620546    1186 scheduler.go:342]  "msg"="Trying to scale multiple training jobs"  "jobs"=[] "scheduler"="default"
I0721 19:05:46.620880    1186 scheduler.go:292]  "msg"="Trying to start multiple training jobs"  "jobs"=["tf2-keras-cifar10-inceptionv3-elastic-20210721-064117","tf2-keras-cifar10-resnet50-elastic-20210721-064048"] "scheduler"="default"
I0721 19:05:46.642233    1186 scheduler.go:342]  "msg"="Trying to scale multiple training jobs"  "jobs"=[] "scheduler"="default"
I0721 19:05:46.646041    1186 placement_manager.go:166]  "msg"="Started job placements adjustment"  "scheduler"="default"
I0721 19:05:46.646118    1186 placement_manager.go:192]  "msg"="Releasing slots"  "jobs"={"tf2-keras-cifar10-inceptionv3-elastic-20210721-063756":{},"tf2-keras-cifar10-inceptionv3-elastic-20210721-063900":{},"tf2-keras-cifar10-resnet50-elastic-20210721-063833":{},"tf2-keras-cifar10-vgg16-elastic-20210721-063952":{},"tf2-keras-cifar10-vgg16-elastic-20210721-064019":{},"tf2-keras-transformer-elastic-20210721-063927":{}} "nodes"={"gpu3":{},"gpu4":{},"gpu5":{}} "scheduler"="default"
I0721 19:05:46.646180    1186 placement_manager.go:250]  "msg"="Released slots"  "jobs"={"tf2-keras-cifar10-inceptionv3-elastic-20210721-063756":{},"tf2-keras-cifar10-inceptionv3-elastic-20210721-063900":{},"tf2-keras-cifar10-resnet50-elastic-20210721-063833":{},"tf2-keras-cifar10-vgg16-elastic-20210721-063952":{},"tf2-keras-cifar10-vgg16-elastic-20210721-064019":{},"tf2-keras-transformer-elastic-20210721-063927":{}} "nodes"={"gpu3":{},"gpu4":{},"gpu5":{}} "scheduler"="default"
I0721 19:05:46.646724    1186 placement_manager.go:305]  "msg"="Found best-fit"  "crossNode"=0 "nodes"=[{},{},{}] "requests"=[{},{},{},{},{},{},{},{},{},{},{},{},{},{},{},{},{},{},{},{},{},{},{},{},{},{},{},{},{},{},{},{},{},{},{},{},{},{},{},{},{},{},{},{}] "scheduler"="default"
I0721 19:05:46.647112    1186 placement_manager.go:339]  "msg"="nodeStates updated"  "new"={"gpu3":{},"gpu4":{},"gpu5":{}} "old"={"gpu3":{},"gpu4":{},"gpu5":{}} "scheduler"="default" "score"=4
I0721 19:05:46.647415    1186 placement_manager.go:387]  "msg"="jobStates updated"  "new"={"tf2-keras-cifar10-inceptionv3-elastic-20210721-063900":{},"tf2-keras-cifar10-inceptionv3-elastic-20210721-064117":{},"tf2-keras-cifar10-resnet50-elastic-20210721-064048":{},"tf2-keras-cifar10-vgg16-elastic-20210721-063952":{},"tf2-keras-cifar10-vgg16-elastic-20210721-064019":{},"tf2-keras-transformer-elastic-20210721-063927":{}} "old"={"tf2-keras-cifar10-inceptionv3-elastic-20210721-063756":{},"tf2-keras-cifar10-inceptionv3-elastic-20210721-063900":{},"tf2-keras-cifar10-resnet50-elastic-20210721-063833":{},"tf2-keras-cifar10-vgg16-elastic-20210721-063952":{},"tf2-keras-cifar10-vgg16-elastic-20210721-064019":{},"tf2-keras-transformer-elastic-20210721-063927":{}} "scheduler"="default"
I0721 19:05:46.647830    1186 placement_manager.go:434]  "msg"="podNodeName updated"  "launchersToDelete"=2 "new"={"tf2-keras-cifar10-inceptionv3-elastic-20210721-063900-worker-0":"gpu3","tf2-keras-cifar10-inceptionv3-elastic-20210721-063900-worker-1":"gpu3","tf2-keras-cifar10-inceptionv3-elastic-20210721-064117-worker-0":"gpu5","tf2-keras-cifar10-inceptionv3-elastic-20210721-064117-worker-1":"gpu5","tf2-keras-cifar10-resnet50-elastic-20210721-064048-worker-0":"gpu5","tf2-keras-cifar10-resnet50-elastic-20210721-064048-worker-1":"gpu5","tf2-keras-cifar10-vgg16-elastic-20210721-063952-worker-0":"gpu4","tf2-keras-cifar10-vgg16-elastic-20210721-063952-worker-1":"gpu4","tf2-keras-cifar10-vgg16-elastic-20210721-064019-worker-0":"gpu3","tf2-keras-cifar10-vgg16-elastic-20210721-064019-worker-1":"gpu3","tf2-keras-transformer-elastic-20210721-063927-worker-0":"gpu4","tf2-keras-transformer-elastic-20210721-063927-worker-1":"gpu4"} "old"={"tf2-keras-cifar10-inceptionv3-elastic-20210721-063756-worker-0":"gpu5","tf2-keras-cifar10-inceptionv3-elastic-20210721-063756-worker-1":"gpu5","tf2-keras-cifar10-inceptionv3-elastic-20210721-063900-worker-0":"gpu5","tf2-keras-cifar10-inceptionv3-elastic-20210721-063900-worker-1":"gpu5","tf2-keras-cifar10-resnet50-elastic-20210721-063833-worker-0":"gpu4","tf2-keras-cifar10-resnet50-elastic-20210721-063833-worker-1":"gpu4","tf2-keras-cifar10-vgg16-elastic-20210721-063952-worker-0":"gpu4","tf2-keras-cifar10-vgg16-elastic-20210721-063952-worker-1":"gpu4","tf2-keras-cifar10-vgg16-elastic-20210721-064019-worker-0":"gpu3","tf2-keras-cifar10-vgg16-elastic-20210721-064019-worker-1":"gpu3","tf2-keras-transformer-elastic-20210721-063927-worker-0":"gpu3","tf2-keras-transformer-elastic-20210721-063927-worker-1":"gpu3"} "scheduler"="default" "workersToDelete"=4
I0721 19:05:46.648175    1186 placement_manager.go:451]  "msg"="Deleting pod that need migration"  "podName"="tf2-keras-transformer-elastic-20210721-063927-worker-0" "scheduler"="default"
I0721 19:05:46.652355    1186 placement_manager.go:451]  "msg"="Deleting pod that need migration"  "podName"="tf2-keras-transformer-elastic-20210721-063927-worker-1" "scheduler"="default"
I0721 19:05:46.657593    1186 placement_manager.go:451]  "msg"="Deleting pod that need migration"  "podName"="tf2-keras-transformer-elastic-20210721-063927-launcher" "scheduler"="default"
I0721 19:05:46.662916    1186 placement_manager.go:451]  "msg"="Deleting pod that need migration"  "podName"="tf2-keras-cifar10-inceptionv3-elastic-20210721-063900-worker-0" "scheduler"="default"
I0721 19:05:46.667602    1186 placement_manager.go:451]  "msg"="Deleting pod that need migration"  "podName"="tf2-keras-cifar10-inceptionv3-elastic-20210721-063900-worker-1" "scheduler"="default"
I0721 19:05:46.671855    1186 placement_manager.go:451]  "msg"="Deleting pod that need migration"  "podName"="tf2-keras-cifar10-inceptionv3-elastic-20210721-063900-launcher" "scheduler"="default"
I0721 19:05:46.681872    1186 placement_manager.go:183]  "msg"="Finished job placements adjustment"  "scheduler"="default"
I0721 19:05:46.682194    1186 scheduler.go:182]  "msg"="Finished resched"  "scheduler"="default"
I0721 19:05:46.845513    1186 placement_manager.go:147]  "msg"="Adding toleration to pod"  "podName"="tf2-keras-cifar10-inceptionv3-elastic-20210721-064117-worker-0" "scheduler"="default" "toleration"={"key":"celeste/hostname","operator":"Equal","value":"gpu5","effect":"NoExecute"}
I0721 19:05:47.043097    1186 placement_manager.go:147]  "msg"="Adding toleration to pod"  "podName"="tf2-keras-cifar10-resnet50-elastic-20210721-064048-worker-0" "scheduler"="default" "toleration"={"key":"celeste/hostname","operator":"Equal","value":"gpu5","effect":"NoExecute"}
I0721 19:05:47.456330    1186 placement_manager.go:147]  "msg"="Adding toleration to pod"  "podName"="tf2-keras-cifar10-inceptionv3-elastic-20210721-064117-worker-1" "scheduler"="default" "toleration"={"key":"celeste/hostname","operator":"Equal","value":"gpu5","effect":"NoExecute"}
I0721 19:05:47.861392    1186 placement_manager.go:147]  "msg"="Adding toleration to pod"  "podName"="tf2-keras-cifar10-resnet50-elastic-20210721-064048-worker-1" "scheduler"="default" "toleration"={"key":"celeste/hostname","operator":"Equal","value":"gpu5","effect":"NoExecute"}
I0721 19:05:48.255518    1186 placement_manager.go:147]  "msg"="Adding toleration to pod"  "podName"="tf2-keras-cifar10-inceptionv3-elastic-20210721-064117-launcher" "scheduler"="default" "toleration"={"key":"celeste/hostname","operator":"Exists","effect":"NoExecute"}
I0721 19:05:48.664987    1186 placement_manager.go:147]  "msg"="Adding toleration to pod"  "podName"="tf2-keras-cifar10-resnet50-elastic-20210721-064048-launcher" "scheduler"="default" "toleration"={"key":"celeste/hostname","operator":"Exists","effect":"NoExecute"}
I0721 19:05:55.587074    1186 placement_manager.go:147]  "msg"="Adding toleration to pod"  "podName"="tf2-keras-transformer-elastic-20210721-063927-worker-0" "scheduler"="default" "toleration"={"key":"celeste/hostname","operator":"Equal","value":"gpu4","effect":"NoExecute"}
I0721 19:05:55.620125    1186 placement_manager.go:147]  "msg"="Adding toleration to pod"  "podName"="tf2-keras-transformer-elastic-20210721-063927-worker-1" "scheduler"="default" "toleration"={"key":"celeste/hostname","operator":"Equal","value":"gpu4","effect":"NoExecute"}
I0721 19:05:59.778848    1186 placement_manager.go:147]  "msg"="Adding toleration to pod"  "podName"="tf2-keras-cifar10-inceptionv3-elastic-20210721-063900-worker-0" "scheduler"="default" "toleration"={"key":"celeste/hostname","operator":"Equal","value":"gpu3","effect":"NoExecute"}
I0721 19:05:59.818479    1186 placement_manager.go:147]  "msg"="Adding toleration to pod"  "podName"="tf2-keras-cifar10-inceptionv3-elastic-20210721-063900-launcher" "scheduler"="default" "toleration"={"key":"celeste/hostname","operator":"Exists","effect":"NoExecute"}
I0721 19:05:59.830179    1186 placement_manager.go:147]  "msg"="Adding toleration to pod"  "podName"="tf2-keras-cifar10-inceptionv3-elastic-20210721-063900-worker-1" "scheduler"="default" "toleration"={"key":"celeste/hostname","operator":"Equal","value":"gpu3","effect":"NoExecute"}
I0721 19:06:00.537055    1186 placement_manager.go:147]  "msg"="Adding toleration to pod"  "podName"="tf2-keras-transformer-elastic-20210721-063927-launcher" "scheduler"="default" "toleration"={"key":"celeste/hostname","operator":"Exists","effect":"NoExecute"}
I0721 19:07:46.529287    1186 scheduler.go:559]  "msg"="Priority demoted to training job"  "job"="tf2-keras-cifar10-inceptionv3-elastic-20210721-063900" "priority"=1 "scheduler"="default"
I0721 19:07:46.529392    1186 scheduler.go:559]  "msg"="Priority demoted to training job"  "job"="tf2-keras-transformer-elastic-20210721-063927" "priority"=1 "scheduler"="default"
I0721 19:07:46.529428    1186 scheduler.go:573]  "msg"="Priority changed"  "scheduler"="default"
I0721 19:07:46.529520    1186 scheduler.go:135]  "msg"="Received resched event, may be blocked because of rate limit"  "blockedUntil"="2021-07-21T19:07:46.682461233+08:00" "lastResched"="2021-07-21T19:05:46.682461233+08:00" "received"="2021-07-21T19:07:46.529436138+08:00" "scheduler"="default"
I0721 19:07:46.682504    1186 scheduler.go:159]  "msg"="Started resched"  "scheduler"="default"
I0721 19:07:46.682539    1186 scheduler.go:193]  "msg"="Updating all jobs info"  "scheduler"="default"
I0721 19:07:46.697430    1186 elastic_tiresias.go:160]  "msg"="Finished scheduling"  "algorithm"="ElasticTiresias" "compactionThreshold"=4 "freeGpu"=0 "promoteKnob"=4 "queueNum"=2 "result"={"tf2-keras-cifar10-inceptionv3-elastic-20210721-063448":0,"tf2-keras-cifar10-inceptionv3-elastic-20210721-063539":0,"tf2-keras-cifar10-inceptionv3-elastic-20210721-063756":0,"tf2-keras-cifar10-inceptionv3-elastic-20210721-063900":0,"tf2-keras-cifar10-inceptionv3-elastic-20210721-064117":2,"tf2-keras-cifar10-inceptionv3-elastic-20210721-064215":2,"tf2-keras-cifar10-resnet50-elastic-20210721-063511":0,"tf2-keras-cifar10-resnet50-elastic-20210721-064048":2,"tf2-keras-cifar10-resnet50-elastic-20210721-064237":0,"tf2-keras-cifar10-resnet50-elastic-20210721-064451":0,"tf2-keras-cifar10-resnet50-elastic-20210721-064517":0,"tf2-keras-cifar10-vgg16-elastic-20210721-063631":0,"tf2-keras-cifar10-vgg16-elastic-20210721-063952":2,"tf2-keras-cifar10-vgg16-elastic-20210721-064019":2,"tf2-keras-cifar10-vgg16-elastic-20210721-064310":0,"tf2-keras-cifar10-vgg16-elastic-20210721-064412":0,"tf2-keras-transformer-elastic-20210721-063654":0,"tf2-keras-transformer-elastic-20210721-063721":0,"tf2-keras-transformer-elastic-20210721-063927":0,"tf2-keras-transformer-elastic-20210721-064152":2,"tf2-keras-transformer-elastic-20210721-064332":0,"tf2-keras-transformer-elastic-20210721-064545":0} "scheduler"="default" "thresholds"=
I0721 19:07:46.697861    1186 scheduler.go:384]  "msg"="Trying to delete multiple training jobs"  "jobs"=["tf2-keras-cifar10-inceptionv3-elastic-20210721-063900","tf2-keras-transformer-elastic-20210721-063927"] "scheduler"="default"
I0721 19:07:46.715928    1186 scheduler.go:342]  "msg"="Trying to scale multiple training jobs"  "jobs"=[] "scheduler"="default"
I0721 19:07:46.716251    1186 scheduler.go:292]  "msg"="Trying to start multiple training jobs"  "jobs"=["tf2-keras-transformer-elastic-20210721-064152","tf2-keras-cifar10-inceptionv3-elastic-20210721-064215"] "scheduler"="default"
I0721 19:07:46.731150    1186 scheduler.go:342]  "msg"="Trying to scale multiple training jobs"  "jobs"=[] "scheduler"="default"
I0721 19:07:46.733898    1186 placement_manager.go:166]  "msg"="Started job placements adjustment"  "scheduler"="default"
I0721 19:07:46.733947    1186 placement_manager.go:192]  "msg"="Releasing slots"  "jobs"={"tf2-keras-cifar10-inceptionv3-elastic-20210721-063900":{},"tf2-keras-cifar10-inceptionv3-elastic-20210721-064117":{},"tf2-keras-cifar10-resnet50-elastic-20210721-064048":{},"tf2-keras-cifar10-vgg16-elastic-20210721-063952":{},"tf2-keras-cifar10-vgg16-elastic-20210721-064019":{},"tf2-keras-transformer-elastic-20210721-063927":{}} "nodes"={"gpu3":{},"gpu4":{},"gpu5":{}} "scheduler"="default"
I0721 19:07:46.733997    1186 placement_manager.go:250]  "msg"="Released slots"  "jobs"={"tf2-keras-cifar10-inceptionv3-elastic-20210721-063900":{},"tf2-keras-cifar10-inceptionv3-elastic-20210721-064117":{},"tf2-keras-cifar10-resnet50-elastic-20210721-064048":{},"tf2-keras-cifar10-vgg16-elastic-20210721-063952":{},"tf2-keras-cifar10-vgg16-elastic-20210721-064019":{},"tf2-keras-transformer-elastic-20210721-063927":{}} "nodes"={"gpu3":{},"gpu4":{},"gpu5":{}} "scheduler"="default"
I0721 19:07:46.734413    1186 placement_manager.go:305]  "msg"="Found best-fit"  "crossNode"=0 "nodes"=[{},{},{}] "requests"=[{},{},{},{},{},{},{},{},{},{},{},{},{},{},{},{},{},{},{},{},{},{},{},{},{},{},{},{},{},{},{},{},{},{},{},{},{},{},{},{},{},{},{},{}] "scheduler"="default"
I0721 19:07:46.734693    1186 placement_manager.go:339]  "msg"="nodeStates updated"  "new"={"gpu3":{},"gpu4":{},"gpu5":{}} "old"={"gpu3":{},"gpu4":{},"gpu5":{}} "scheduler"="default" "score"=6
I0721 19:07:46.734960    1186 placement_manager.go:387]  "msg"="jobStates updated"  "new"={"tf2-keras-cifar10-inceptionv3-elastic-20210721-064117":{},"tf2-keras-cifar10-inceptionv3-elastic-20210721-064215":{},"tf2-keras-cifar10-resnet50-elastic-20210721-064048":{},"tf2-keras-cifar10-vgg16-elastic-20210721-063952":{},"tf2-keras-cifar10-vgg16-elastic-20210721-064019":{},"tf2-keras-transformer-elastic-20210721-064152":{}} "old"={"tf2-keras-cifar10-inceptionv3-elastic-20210721-063900":{},"tf2-keras-cifar10-inceptionv3-elastic-20210721-064117":{},"tf2-keras-cifar10-resnet50-elastic-20210721-064048":{},"tf2-keras-cifar10-vgg16-elastic-20210721-063952":{},"tf2-keras-cifar10-vgg16-elastic-20210721-064019":{},"tf2-keras-transformer-elastic-20210721-063927":{}} "scheduler"="default"
I0721 19:07:46.735326    1186 placement_manager.go:434]  "msg"="podNodeName updated"  "launchersToDelete"=1 "new"={"tf2-keras-cifar10-inceptionv3-elastic-20210721-064117-worker-0":"gpu3","tf2-keras-cifar10-inceptionv3-elastic-20210721-064117-worker-1":"gpu3","tf2-keras-cifar10-inceptionv3-elastic-20210721-064215-worker-0":"gpu5","tf2-keras-cifar10-inceptionv3-elastic-20210721-064215-worker-1":"gpu5","tf2-keras-cifar10-resnet50-elastic-20210721-064048-worker-0":"gpu5","tf2-keras-cifar10-resnet50-elastic-20210721-064048-worker-1":"gpu5","tf2-keras-cifar10-vgg16-elastic-20210721-063952-worker-0":"gpu4","tf2-keras-cifar10-vgg16-elastic-20210721-063952-worker-1":"gpu4","tf2-keras-cifar10-vgg16-elastic-20210721-064019-worker-0":"gpu3","tf2-keras-cifar10-vgg16-elastic-20210721-064019-worker-1":"gpu3","tf2-keras-transformer-elastic-20210721-064152-worker-0":"gpu4","tf2-keras-transformer-elastic-20210721-064152-worker-1":"gpu4"} "old"={"tf2-keras-cifar10-inceptionv3-elastic-20210721-063900-worker-0":"gpu3","tf2-keras-cifar10-inceptionv3-elastic-20210721-063900-worker-1":"gpu3","tf2-keras-cifar10-inceptionv3-elastic-20210721-064117-worker-0":"gpu5","tf2-keras-cifar10-inceptionv3-elastic-20210721-064117-worker-1":"gpu5","tf2-keras-cifar10-resnet50-elastic-20210721-064048-worker-0":"gpu5","tf2-keras-cifar10-resnet50-elastic-20210721-064048-worker-1":"gpu5","tf2-keras-cifar10-vgg16-elastic-20210721-063952-worker-0":"gpu4","tf2-keras-cifar10-vgg16-elastic-20210721-063952-worker-1":"gpu4","tf2-keras-cifar10-vgg16-elastic-20210721-064019-worker-0":"gpu3","tf2-keras-cifar10-vgg16-elastic-20210721-064019-worker-1":"gpu3","tf2-keras-transformer-elastic-20210721-063927-worker-0":"gpu4","tf2-keras-transformer-elastic-20210721-063927-worker-1":"gpu4"} "scheduler"="default" "workersToDelete"=2
I0721 19:07:46.735598    1186 placement_manager.go:451]  "msg"="Deleting pod that need migration"  "podName"="tf2-keras-cifar10-inceptionv3-elastic-20210721-064117-worker-0" "scheduler"="default"
I0721 19:07:46.741003    1186 placement_manager.go:451]  "msg"="Deleting pod that need migration"  "podName"="tf2-keras-cifar10-inceptionv3-elastic-20210721-064117-worker-1" "scheduler"="default"
I0721 19:07:46.745248    1186 placement_manager.go:451]  "msg"="Deleting pod that need migration"  "podName"="tf2-keras-cifar10-inceptionv3-elastic-20210721-064117-launcher" "scheduler"="default"
I0721 19:07:46.750038    1186 placement_manager.go:183]  "msg"="Finished job placements adjustment"  "scheduler"="default"
I0721 19:07:46.750291    1186 scheduler.go:182]  "msg"="Finished resched"  "scheduler"="default"
I0721 19:07:46.933997    1186 placement_manager.go:147]  "msg"="Adding toleration to pod"  "podName"="tf2-keras-transformer-elastic-20210721-064152-worker-0" "scheduler"="default" "toleration"={"key":"celeste/hostname","operator":"Equal","value":"gpu4","effect":"NoExecute"}
I0721 19:07:47.132030    1186 placement_manager.go:147]  "msg"="Adding toleration to pod"  "podName"="tf2-keras-cifar10-inceptionv3-elastic-20210721-064215-worker-0" "scheduler"="default" "toleration"={"key":"celeste/hostname","operator":"Equal","value":"gpu5","effect":"NoExecute"}
I0721 19:07:47.337583    1186 placement_manager.go:147]  "msg"="Adding toleration to pod"  "podName"="tf2-keras-transformer-elastic-20210721-064152-worker-1" "scheduler"="default" "toleration"={"key":"celeste/hostname","operator":"Equal","value":"gpu4","effect":"NoExecute"}
I0721 19:07:47.531886    1186 placement_manager.go:147]  "msg"="Adding toleration to pod"  "podName"="tf2-keras-cifar10-inceptionv3-elastic-20210721-064215-worker-1" "scheduler"="default" "toleration"={"key":"celeste/hostname","operator":"Equal","value":"gpu5","effect":"NoExecute"}
I0721 19:07:48.144527    1186 placement_manager.go:147]  "msg"="Adding toleration to pod"  "podName"="tf2-keras-transformer-elastic-20210721-064152-launcher" "scheduler"="default" "toleration"={"key":"celeste/hostname","operator":"Exists","effect":"NoExecute"}
I0721 19:07:48.544551    1186 placement_manager.go:147]  "msg"="Adding toleration to pod"  "podName"="tf2-keras-cifar10-inceptionv3-elastic-20210721-064215-launcher" "scheduler"="default" "toleration"={"key":"celeste/hostname","operator":"Exists","effect":"NoExecute"}
I0721 19:07:49.355576    1186 scheduler.go:474]  "msg"="Training job completed"  "elaspedTotalSeconds"=1674.375663333 "gpuTotalSeconds"=1560.05948738 "job"="tf2-keras-cifar10-vgg16-elastic-20210721-063952" "ranTotalSeconds"=780.02974369 "scheduler"="default" "waitedTotalSeconds"=894.345919643
I0721 19:07:49.355725    1186 scheduler.go:135]  "msg"="Received resched event, may be blocked because of rate limit"  "blockedUntil"="2021-07-21T19:09:46.750558537+08:00" "lastResched"="2021-07-21T19:07:46.750558537+08:00" "received"="2021-07-21T19:07:49.355607648+08:00" "scheduler"="default"
I0721 19:08:00.079974    1186 placement_manager.go:147]  "msg"="Adding toleration to pod"  "podName"="tf2-keras-cifar10-inceptionv3-elastic-20210721-064117-worker-0" "scheduler"="default" "toleration"={"key":"celeste/hostname","operator":"Equal","value":"gpu3","effect":"NoExecute"}
I0721 19:08:00.466673    1186 placement_manager.go:147]  "msg"="Adding toleration to pod"  "podName"="tf2-keras-cifar10-inceptionv3-elastic-20210721-064117-launcher" "scheduler"="default" "toleration"={"key":"celeste/hostname","operator":"Exists","effect":"NoExecute"}
I0721 19:08:00.865096    1186 placement_manager.go:147]  "msg"="Adding toleration to pod"  "podName"="tf2-keras-cifar10-inceptionv3-elastic-20210721-064117-worker-1" "scheduler"="default" "toleration"={"key":"celeste/hostname","operator":"Equal","value":"gpu3","effect":"NoExecute"}
I0721 19:09:46.750666    1186 scheduler.go:159]  "msg"="Started resched"  "scheduler"="default"
I0721 19:09:46.750739    1186 scheduler.go:193]  "msg"="Updating all jobs info"  "scheduler"="default"
I0721 19:09:46.763886    1186 elastic_tiresias.go:160]  "msg"="Finished scheduling"  "algorithm"="ElasticTiresias" "compactionThreshold"=4 "freeGpu"=0 "promoteKnob"=4 "queueNum"=2 "result"={"tf2-keras-cifar10-inceptionv3-elastic-20210721-063448":0,"tf2-keras-cifar10-inceptionv3-elastic-20210721-063539":0,"tf2-keras-cifar10-inceptionv3-elastic-20210721-063756":0,"tf2-keras-cifar10-inceptionv3-elastic-20210721-063900":0,"tf2-keras-cifar10-inceptionv3-elastic-20210721-064117":2,"tf2-keras-cifar10-inceptionv3-elastic-20210721-064215":2,"tf2-keras-cifar10-resnet50-elastic-20210721-063511":0,"tf2-keras-cifar10-resnet50-elastic-20210721-064048":2,"tf2-keras-cifar10-resnet50-elastic-20210721-064237":2,"tf2-keras-cifar10-resnet50-elastic-20210721-064451":0,"tf2-keras-cifar10-resnet50-elastic-20210721-064517":0,"tf2-keras-cifar10-vgg16-elastic-20210721-063631":0,"tf2-keras-cifar10-vgg16-elastic-20210721-064019":2,"tf2-keras-cifar10-vgg16-elastic-20210721-064310":0,"tf2-keras-cifar10-vgg16-elastic-20210721-064412":0,"tf2-keras-transformer-elastic-20210721-063654":0,"tf2-keras-transformer-elastic-20210721-063721":0,"tf2-keras-transformer-elastic-20210721-063927":0,"tf2-keras-transformer-elastic-20210721-064152":2,"tf2-keras-transformer-elastic-20210721-064332":0,"tf2-keras-transformer-elastic-20210721-064545":0} "scheduler"="default" "thresholds"=
I0721 19:09:46.764287    1186 scheduler.go:384]  "msg"="Trying to delete multiple training jobs"  "jobs"=[] "scheduler"="default"
I0721 19:09:46.764533    1186 scheduler.go:342]  "msg"="Trying to scale multiple training jobs"  "jobs"=[] "scheduler"="default"
I0721 19:09:46.764749    1186 scheduler.go:292]  "msg"="Trying to start multiple training jobs"  "jobs"=["tf2-keras-cifar10-resnet50-elastic-20210721-064237"] "scheduler"="default"
I0721 19:09:46.776597    1186 scheduler.go:342]  "msg"="Trying to scale multiple training jobs"  "jobs"=[] "scheduler"="default"
I0721 19:09:46.780283    1186 placement_manager.go:166]  "msg"="Started job placements adjustment"  "scheduler"="default"
I0721 19:09:46.780376    1186 placement_manager.go:192]  "msg"="Releasing slots"  "jobs"={"tf2-keras-cifar10-inceptionv3-elastic-20210721-064117":{},"tf2-keras-cifar10-inceptionv3-elastic-20210721-064215":{},"tf2-keras-cifar10-resnet50-elastic-20210721-064048":{},"tf2-keras-cifar10-vgg16-elastic-20210721-063952":{},"tf2-keras-cifar10-vgg16-elastic-20210721-064019":{},"tf2-keras-transformer-elastic-20210721-064152":{}} "nodes"={"gpu3":{},"gpu4":{},"gpu5":{}} "scheduler"="default"
I0721 19:09:46.780444    1186 placement_manager.go:250]  "msg"="Released slots"  "jobs"={"tf2-keras-cifar10-inceptionv3-elastic-20210721-064117":{},"tf2-keras-cifar10-inceptionv3-elastic-20210721-064215":{},"tf2-keras-cifar10-resnet50-elastic-20210721-064048":{},"tf2-keras-cifar10-vgg16-elastic-20210721-063952":{},"tf2-keras-cifar10-vgg16-elastic-20210721-064019":{},"tf2-keras-transformer-elastic-20210721-064152":{}} "nodes"={"gpu3":{},"gpu4":{},"gpu5":{}} "scheduler"="default"
I0721 19:09:46.780950    1186 placement_manager.go:305]  "msg"="Found best-fit"  "crossNode"=0 "nodes"=[{},{},{}] "requests"=[{},{},{},{},{},{},{},{},{},{},{},{},{},{},{},{},{},{},{},{},{},{},{},{},{},{},{},{},{},{},{},{},{},{},{},{},{},{},{},{},{},{}] "scheduler"="default"
I0721 19:09:46.781305    1186 placement_manager.go:339]  "msg"="nodeStates updated"  "new"={"gpu3":{},"gpu4":{},"gpu5":{}} "old"={"gpu3":{},"gpu4":{},"gpu5":{}} "scheduler"="default" "score"=8
I0721 19:09:46.781627    1186 placement_manager.go:387]  "msg"="jobStates updated"  "new"={"tf2-keras-cifar10-inceptionv3-elastic-20210721-064117":{},"tf2-keras-cifar10-inceptionv3-elastic-20210721-064215":{},"tf2-keras-cifar10-resnet50-elastic-20210721-064048":{},"tf2-keras-cifar10-resnet50-elastic-20210721-064237":{},"tf2-keras-cifar10-vgg16-elastic-20210721-064019":{},"tf2-keras-transformer-elastic-20210721-064152":{}} "old"={"tf2-keras-cifar10-inceptionv3-elastic-20210721-064117":{},"tf2-keras-cifar10-inceptionv3-elastic-20210721-064215":{},"tf2-keras-cifar10-resnet50-elastic-20210721-064048":{},"tf2-keras-cifar10-vgg16-elastic-20210721-063952":{},"tf2-keras-cifar10-vgg16-elastic-20210721-064019":{},"tf2-keras-transformer-elastic-20210721-064152":{}} "scheduler"="default"
I0721 19:09:46.782131    1186 placement_manager.go:434]  "msg"="podNodeName updated"  "launchersToDelete"=1 "new"={"tf2-keras-cifar10-inceptionv3-elastic-20210721-064117-worker-0":"gpu3","tf2-keras-cifar10-inceptionv3-elastic-20210721-064117-worker-1":"gpu3","tf2-keras-cifar10-inceptionv3-elastic-20210721-064215-worker-0":"gpu4","tf2-keras-cifar10-inceptionv3-elastic-20210721-064215-worker-1":"gpu4","tf2-keras-cifar10-resnet50-elastic-20210721-064048-worker-0":"gpu5","tf2-keras-cifar10-resnet50-elastic-20210721-064048-worker-1":"gpu5","tf2-keras-cifar10-resnet50-elastic-20210721-064237-worker-0":"gpu5","tf2-keras-cifar10-resnet50-elastic-20210721-064237-worker-1":"gpu5","tf2-keras-cifar10-vgg16-elastic-20210721-064019-worker-0":"gpu3","tf2-keras-cifar10-vgg16-elastic-20210721-064019-worker-1":"gpu3","tf2-keras-transformer-elastic-20210721-064152-worker-0":"gpu4","tf2-keras-transformer-elastic-20210721-064152-worker-1":"gpu4"} "old"={"tf2-keras-cifar10-inceptionv3-elastic-20210721-064117-worker-0":"gpu3","tf2-keras-cifar10-inceptionv3-elastic-20210721-064117-worker-1":"gpu3","tf2-keras-cifar10-inceptionv3-elastic-20210721-064215-worker-0":"gpu5","tf2-keras-cifar10-inceptionv3-elastic-20210721-064215-worker-1":"gpu5","tf2-keras-cifar10-resnet50-elastic-20210721-064048-worker-0":"gpu5","tf2-keras-cifar10-resnet50-elastic-20210721-064048-worker-1":"gpu5","tf2-keras-cifar10-vgg16-elastic-20210721-063952-worker-0":"gpu4","tf2-keras-cifar10-vgg16-elastic-20210721-063952-worker-1":"gpu4","tf2-keras-cifar10-vgg16-elastic-20210721-064019-worker-0":"gpu3","tf2-keras-cifar10-vgg16-elastic-20210721-064019-worker-1":"gpu3","tf2-keras-transformer-elastic-20210721-064152-worker-0":"gpu4","tf2-keras-transformer-elastic-20210721-064152-worker-1":"gpu4"} "scheduler"="default" "workersToDelete"=2
I0721 19:09:46.782461    1186 placement_manager.go:451]  "msg"="Deleting pod that need migration"  "podName"="tf2-keras-cifar10-inceptionv3-elastic-20210721-064215-worker-0" "scheduler"="default"
I0721 19:09:46.787013    1186 placement_manager.go:451]  "msg"="Deleting pod that need migration"  "podName"="tf2-keras-cifar10-inceptionv3-elastic-20210721-064215-worker-1" "scheduler"="default"
I0721 19:09:46.791305    1186 placement_manager.go:451]  "msg"="Deleting pod that need migration"  "podName"="tf2-keras-cifar10-inceptionv3-elastic-20210721-064215-launcher" "scheduler"="default"
I0721 19:09:46.798034    1186 placement_manager.go:183]  "msg"="Finished job placements adjustment"  "scheduler"="default"
I0721 19:09:46.798264    1186 scheduler.go:182]  "msg"="Finished resched"  "scheduler"="default"
I0721 19:09:46.826226    1186 placement_manager.go:147]  "msg"="Adding toleration to pod"  "podName"="tf2-keras-cifar10-resnet50-elastic-20210721-064237-worker-0" "scheduler"="default" "toleration"={"key":"celeste/hostname","operator":"Equal","value":"gpu5","effect":"NoExecute"}
I0721 19:09:46.859499    1186 placement_manager.go:147]  "msg"="Adding toleration to pod"  "podName"="tf2-keras-cifar10-resnet50-elastic-20210721-064237-worker-1" "scheduler"="default" "toleration"={"key":"celeste/hostname","operator":"Equal","value":"gpu5","effect":"NoExecute"}
I0721 19:09:46.869155    1186 placement_manager.go:147]  "msg"="Adding toleration to pod"  "podName"="tf2-keras-cifar10-resnet50-elastic-20210721-064237-launcher" "scheduler"="default" "toleration"={"key":"celeste/hostname","operator":"Exists","effect":"NoExecute"}
I0721 19:09:59.782222    1186 placement_manager.go:147]  "msg"="Adding toleration to pod"  "podName"="tf2-keras-cifar10-inceptionv3-elastic-20210721-064215-worker-0" "scheduler"="default" "toleration"={"key":"celeste/hostname","operator":"Equal","value":"gpu4","effect":"NoExecute"}
I0721 19:10:00.175163    1186 placement_manager.go:147]  "msg"="Adding toleration to pod"  "podName"="tf2-keras-cifar10-inceptionv3-elastic-20210721-064215-worker-1" "scheduler"="default" "toleration"={"key":"celeste/hostname","operator":"Equal","value":"gpu4","effect":"NoExecute"}
I0721 19:10:00.572485    1186 placement_manager.go:147]  "msg"="Adding toleration to pod"  "podName"="tf2-keras-cifar10-inceptionv3-elastic-20210721-064215-launcher" "scheduler"="default" "toleration"={"key":"celeste/hostname","operator":"Exists","effect":"NoExecute"}
I0721 19:16:14.269850    1186 scheduler.go:474]  "msg"="Training job completed"  "elaspedTotalSeconds"=2152.381726417 "gpuTotalSeconds"=1490.054528846 "job"="tf2-keras-cifar10-vgg16-elastic-20210721-064019" "ranTotalSeconds"=745.027264423 "scheduler"="default" "waitedTotalSeconds"=1407.354461994
I0721 19:16:14.269982    1186 scheduler.go:135]  "msg"="Received resched event, may be blocked because of rate limit"  "blockedUntil"="2021-07-21T19:11:46.798403525+08:00" "lastResched"="2021-07-21T19:09:46.798403525+08:00" "received"="2021-07-21T19:16:14.269885442+08:00" "scheduler"="default"
I0721 19:16:14.270464    1186 scheduler.go:159]  "msg"="Started resched"  "scheduler"="default"
I0721 19:16:14.270545    1186 scheduler.go:193]  "msg"="Updating all jobs info"  "scheduler"="default"
I0721 19:16:14.281305    1186 elastic_tiresias.go:160]  "msg"="Finished scheduling"  "algorithm"="ElasticTiresias" "compactionThreshold"=4 "freeGpu"=0 "promoteKnob"=4 "queueNum"=2 "result"={"tf2-keras-cifar10-inceptionv3-elastic-20210721-063448":0,"tf2-keras-cifar10-inceptionv3-elastic-20210721-063539":0,"tf2-keras-cifar10-inceptionv3-elastic-20210721-063756":0,"tf2-keras-cifar10-inceptionv3-elastic-20210721-063900":0,"tf2-keras-cifar10-inceptionv3-elastic-20210721-064117":2,"tf2-keras-cifar10-inceptionv3-elastic-20210721-064215":2,"tf2-keras-cifar10-resnet50-elastic-20210721-063511":0,"tf2-keras-cifar10-resnet50-elastic-20210721-064048":2,"tf2-keras-cifar10-resnet50-elastic-20210721-064237":2,"tf2-keras-cifar10-resnet50-elastic-20210721-064451":0,"tf2-keras-cifar10-resnet50-elastic-20210721-064517":0,"tf2-keras-cifar10-vgg16-elastic-20210721-063631":0,"tf2-keras-cifar10-vgg16-elastic-20210721-064310":2,"tf2-keras-cifar10-vgg16-elastic-20210721-064412":0,"tf2-keras-transformer-elastic-20210721-063654":0,"tf2-keras-transformer-elastic-20210721-063721":0,"tf2-keras-transformer-elastic-20210721-063927":0,"tf2-keras-transformer-elastic-20210721-064152":2,"tf2-keras-transformer-elastic-20210721-064332":0,"tf2-keras-transformer-elastic-20210721-064545":0} "scheduler"="default" "thresholds"=
I0721 19:16:14.281592    1186 scheduler.go:384]  "msg"="Trying to delete multiple training jobs"  "jobs"=[] "scheduler"="default"
I0721 19:16:14.281785    1186 scheduler.go:342]  "msg"="Trying to scale multiple training jobs"  "jobs"=[] "scheduler"="default"
I0721 19:16:14.281948    1186 scheduler.go:292]  "msg"="Trying to start multiple training jobs"  "jobs"=["tf2-keras-cifar10-vgg16-elastic-20210721-064310"] "scheduler"="default"
I0721 19:16:14.339574    1186 scheduler.go:342]  "msg"="Trying to scale multiple training jobs"  "jobs"=[] "scheduler"="default"
I0721 19:16:14.342883    1186 placement_manager.go:166]  "msg"="Started job placements adjustment"  "scheduler"="default"
I0721 19:16:14.342975    1186 placement_manager.go:192]  "msg"="Releasing slots"  "jobs"={"tf2-keras-cifar10-inceptionv3-elastic-20210721-064117":{},"tf2-keras-cifar10-inceptionv3-elastic-20210721-064215":{},"tf2-keras-cifar10-resnet50-elastic-20210721-064048":{},"tf2-keras-cifar10-resnet50-elastic-20210721-064237":{},"tf2-keras-cifar10-vgg16-elastic-20210721-064019":{},"tf2-keras-transformer-elastic-20210721-064152":{}} "nodes"={"gpu3":{},"gpu4":{},"gpu5":{}} "scheduler"="default"
I0721 19:16:14.343047    1186 placement_manager.go:250]  "msg"="Released slots"  "jobs"={"tf2-keras-cifar10-inceptionv3-elastic-20210721-064117":{},"tf2-keras-cifar10-inceptionv3-elastic-20210721-064215":{},"tf2-keras-cifar10-resnet50-elastic-20210721-064048":{},"tf2-keras-cifar10-resnet50-elastic-20210721-064237":{},"tf2-keras-cifar10-vgg16-elastic-20210721-064019":{},"tf2-keras-transformer-elastic-20210721-064152":{}} "nodes"={"gpu3":{},"gpu4":{},"gpu5":{}} "scheduler"="default"
I0721 19:16:14.343484    1186 placement_manager.go:305]  "msg"="Found best-fit"  "crossNode"=0 "nodes"=[{},{},{}] "requests"=[{},{},{},{},{},{},{},{},{},{},{},{},{},{},{},{},{},{},{},{},{},{},{},{},{},{},{},{},{},{},{},{},{},{},{},{},{},{},{},{}] "scheduler"="default"
I0721 19:16:14.343859    1186 placement_manager.go:339]  "msg"="nodeStates updated"  "new"={"gpu3":{},"gpu4":{},"gpu5":{}} "old"={"gpu3":{},"gpu4":{},"gpu5":{}} "scheduler"="default" "score"=6
I0721 19:16:14.344179    1186 placement_manager.go:387]  "msg"="jobStates updated"  "new"={"tf2-keras-cifar10-inceptionv3-elastic-20210721-064117":{},"tf2-keras-cifar10-inceptionv3-elastic-20210721-064215":{},"tf2-keras-cifar10-resnet50-elastic-20210721-064048":{},"tf2-keras-cifar10-resnet50-elastic-20210721-064237":{},"tf2-keras-cifar10-vgg16-elastic-20210721-064310":{},"tf2-keras-transformer-elastic-20210721-064152":{}} "old"={"tf2-keras-cifar10-inceptionv3-elastic-20210721-064117":{},"tf2-keras-cifar10-inceptionv3-elastic-20210721-064215":{},"tf2-keras-cifar10-resnet50-elastic-20210721-064048":{},"tf2-keras-cifar10-resnet50-elastic-20210721-064237":{},"tf2-keras-cifar10-vgg16-elastic-20210721-064019":{},"tf2-keras-transformer-elastic-20210721-064152":{}} "scheduler"="default"
I0721 19:16:14.344648    1186 placement_manager.go:434]  "msg"="podNodeName updated"  "launchersToDelete"=2 "new"={"tf2-keras-cifar10-inceptionv3-elastic-20210721-064117-worker-0":"gpu3","tf2-keras-cifar10-inceptionv3-elastic-20210721-064117-worker-1":"gpu3","tf2-keras-cifar10-inceptionv3-elastic-20210721-064215-worker-0":"gpu4","tf2-keras-cifar10-inceptionv3-elastic-20210721-064215-worker-1":"gpu4","tf2-keras-cifar10-resnet50-elastic-20210721-064048-worker-0":"gpu5","tf2-keras-cifar10-resnet50-elastic-20210721-064048-worker-1":"gpu5","tf2-keras-cifar10-resnet50-elastic-20210721-064237-worker-0":"gpu4","tf2-keras-cifar10-resnet50-elastic-20210721-064237-worker-1":"gpu4","tf2-keras-cifar10-vgg16-elastic-20210721-064310-worker-0":"gpu5","tf2-keras-cifar10-vgg16-elastic-20210721-064310-worker-1":"gpu5","tf2-keras-transformer-elastic-20210721-064152-worker-0":"gpu3","tf2-keras-transformer-elastic-20210721-064152-worker-1":"gpu3"} "old"={"tf2-keras-cifar10-inceptionv3-elastic-20210721-064117-worker-0":"gpu3","tf2-keras-cifar10-inceptionv3-elastic-20210721-064117-worker-1":"gpu3","tf2-keras-cifar10-inceptionv3-elastic-20210721-064215-worker-0":"gpu4","tf2-keras-cifar10-inceptionv3-elastic-20210721-064215-worker-1":"gpu4","tf2-keras-cifar10-resnet50-elastic-20210721-064048-worker-0":"gpu5","tf2-keras-cifar10-resnet50-elastic-20210721-064048-worker-1":"gpu5","tf2-keras-cifar10-resnet50-elastic-20210721-064237-worker-0":"gpu5","tf2-keras-cifar10-resnet50-elastic-20210721-064237-worker-1":"gpu5","tf2-keras-cifar10-vgg16-elastic-20210721-064019-worker-0":"gpu3","tf2-keras-cifar10-vgg16-elastic-20210721-064019-worker-1":"gpu3","tf2-keras-transformer-elastic-20210721-064152-worker-0":"gpu4","tf2-keras-transformer-elastic-20210721-064152-worker-1":"gpu4"} "scheduler"="default" "workersToDelete"=4
I0721 19:16:14.345025    1186 placement_manager.go:451]  "msg"="Deleting pod that need migration"  "podName"="tf2-keras-cifar10-resnet50-elastic-20210721-064237-worker-0" "scheduler"="default"
I0721 19:16:14.361443    1186 placement_manager.go:451]  "msg"="Deleting pod that need migration"  "podName"="tf2-keras-cifar10-resnet50-elastic-20210721-064237-worker-1" "scheduler"="default"
I0721 19:16:14.379205    1186 placement_manager.go:451]  "msg"="Deleting pod that need migration"  "podName"="tf2-keras-cifar10-resnet50-elastic-20210721-064237-launcher" "scheduler"="default"
I0721 19:16:14.405003    1186 placement_manager.go:451]  "msg"="Deleting pod that need migration"  "podName"="tf2-keras-transformer-elastic-20210721-064152-worker-0" "scheduler"="default"
I0721 19:16:14.411758    1186 placement_manager.go:451]  "msg"="Deleting pod that need migration"  "podName"="tf2-keras-transformer-elastic-20210721-064152-worker-1" "scheduler"="default"
I0721 19:16:14.437649    1186 placement_manager.go:451]  "msg"="Deleting pod that need migration"  "podName"="tf2-keras-transformer-elastic-20210721-064152-launcher" "scheduler"="default"
I0721 19:16:14.459111    1186 placement_manager.go:183]  "msg"="Finished job placements adjustment"  "scheduler"="default"
I0721 19:16:14.459369    1186 scheduler.go:182]  "msg"="Finished resched"  "scheduler"="default"
I0721 19:16:15.068244    1186 placement_manager.go:147]  "msg"="Adding toleration to pod"  "podName"="tf2-keras-cifar10-vgg16-elastic-20210721-064310-worker-0" "scheduler"="default" "toleration"={"key":"celeste/hostname","operator":"Equal","value":"gpu5","effect":"NoExecute"}
I0721 19:16:15.466153    1186 placement_manager.go:147]  "msg"="Adding toleration to pod"  "podName"="tf2-keras-cifar10-vgg16-elastic-20210721-064310-worker-1" "scheduler"="default" "toleration"={"key":"celeste/hostname","operator":"Equal","value":"gpu5","effect":"NoExecute"}
I0721 19:16:15.868533    1186 placement_manager.go:147]  "msg"="Adding toleration to pod"  "podName"="tf2-keras-cifar10-vgg16-elastic-20210721-064310-launcher" "scheduler"="default" "toleration"={"key":"celeste/hostname","operator":"Exists","effect":"NoExecute"}
I0721 19:16:24.169568    1186 placement_manager.go:147]  "msg"="Adding toleration to pod"  "podName"="tf2-keras-cifar10-resnet50-elastic-20210721-064237-launcher" "scheduler"="default" "toleration"={"key":"celeste/hostname","operator":"Exists","effect":"NoExecute"}
I0721 19:16:24.241452    1186 placement_manager.go:147]  "msg"="Adding toleration to pod"  "podName"="tf2-keras-cifar10-resnet50-elastic-20210721-064237-worker-1" "scheduler"="default" "toleration"={"key":"celeste/hostname","operator":"Equal","value":"gpu4","effect":"NoExecute"}
I0721 19:16:24.252935    1186 placement_manager.go:147]  "msg"="Adding toleration to pod"  "podName"="tf2-keras-transformer-elastic-20210721-064152-launcher" "scheduler"="default" "toleration"={"key":"celeste/hostname","operator":"Exists","effect":"NoExecute"}
I0721 19:16:24.889707    1186 placement_manager.go:147]  "msg"="Adding toleration to pod"  "podName"="tf2-keras-transformer-elastic-20210721-064152-worker-0" "scheduler"="default" "toleration"={"key":"celeste/hostname","operator":"Equal","value":"gpu3","effect":"NoExecute"}
I0721 19:16:25.290437    1186 placement_manager.go:147]  "msg"="Adding toleration to pod"  "podName"="tf2-keras-transformer-elastic-20210721-064152-worker-1" "scheduler"="default" "toleration"={"key":"celeste/hostname","operator":"Equal","value":"gpu3","effect":"NoExecute"}
I0721 19:16:31.523693    1186 placement_manager.go:147]  "msg"="Adding toleration to pod"  "podName"="tf2-keras-cifar10-resnet50-elastic-20210721-064237-worker-0" "scheduler"="default" "toleration"={"key":"celeste/hostname","operator":"Equal","value":"gpu4","effect":"NoExecute"}
I0721 19:19:54.142075    1186 scheduler.go:474]  "msg"="Training job completed"  "elaspedTotalSeconds"=2343.476163493 "gpuTotalSeconds"=1690.06026671 "job"="tf2-keras-cifar10-resnet50-elastic-20210721-064048" "ranTotalSeconds"=845.030133355 "scheduler"="default" "waitedTotalSeconds"=1498.446030138
I0721 19:19:54.142224    1186 scheduler.go:135]  "msg"="Received resched event, may be blocked because of rate limit"  "blockedUntil"="2021-07-21T19:18:14.459588125+08:00" "lastResched"="2021-07-21T19:16:14.459588125+08:00" "received"="2021-07-21T19:19:54.142122275+08:00" "scheduler"="default"
I0721 19:19:54.142655    1186 scheduler.go:159]  "msg"="Started resched"  "scheduler"="default"
I0721 19:19:54.142711    1186 scheduler.go:193]  "msg"="Updating all jobs info"  "scheduler"="default"
I0721 19:19:54.152885    1186 elastic_tiresias.go:160]  "msg"="Finished scheduling"  "algorithm"="ElasticTiresias" "compactionThreshold"=4 "freeGpu"=0 "promoteKnob"=4 "queueNum"=2 "result"={"tf2-keras-cifar10-inceptionv3-elastic-20210721-063448":0,"tf2-keras-cifar10-inceptionv3-elastic-20210721-063539":0,"tf2-keras-cifar10-inceptionv3-elastic-20210721-063756":0,"tf2-keras-cifar10-inceptionv3-elastic-20210721-063900":0,"tf2-keras-cifar10-inceptionv3-elastic-20210721-064117":2,"tf2-keras-cifar10-inceptionv3-elastic-20210721-064215":2,"tf2-keras-cifar10-resnet50-elastic-20210721-063511":0,"tf2-keras-cifar10-resnet50-elastic-20210721-064237":2,"tf2-keras-cifar10-resnet50-elastic-20210721-064451":0,"tf2-keras-cifar10-resnet50-elastic-20210721-064517":0,"tf2-keras-cifar10-vgg16-elastic-20210721-063631":0,"tf2-keras-cifar10-vgg16-elastic-20210721-064310":2,"tf2-keras-cifar10-vgg16-elastic-20210721-064412":0,"tf2-keras-transformer-elastic-20210721-063654":0,"tf2-keras-transformer-elastic-20210721-063721":0,"tf2-keras-transformer-elastic-20210721-063927":0,"tf2-keras-transformer-elastic-20210721-064152":2,"tf2-keras-transformer-elastic-20210721-064332":2,"tf2-keras-transformer-elastic-20210721-064545":0} "scheduler"="default" "thresholds"=
I0721 19:19:54.153215    1186 scheduler.go:384]  "msg"="Trying to delete multiple training jobs"  "jobs"=[] "scheduler"="default"
I0721 19:19:54.153489    1186 scheduler.go:342]  "msg"="Trying to scale multiple training jobs"  "jobs"=[] "scheduler"="default"
I0721 19:19:54.153749    1186 scheduler.go:292]  "msg"="Trying to start multiple training jobs"  "jobs"=["tf2-keras-transformer-elastic-20210721-064332"] "scheduler"="default"
I0721 19:19:54.163387    1186 scheduler.go:342]  "msg"="Trying to scale multiple training jobs"  "jobs"=[] "scheduler"="default"
I0721 19:19:54.166065    1186 placement_manager.go:166]  "msg"="Started job placements adjustment"  "scheduler"="default"
I0721 19:19:54.166123    1186 placement_manager.go:192]  "msg"="Releasing slots"  "jobs"={"tf2-keras-cifar10-inceptionv3-elastic-20210721-064117":{},"tf2-keras-cifar10-inceptionv3-elastic-20210721-064215":{},"tf2-keras-cifar10-resnet50-elastic-20210721-064048":{},"tf2-keras-cifar10-resnet50-elastic-20210721-064237":{},"tf2-keras-cifar10-vgg16-elastic-20210721-064310":{},"tf2-keras-transformer-elastic-20210721-064152":{}} "nodes"={"gpu3":{},"gpu4":{},"gpu5":{}} "scheduler"="default"
I0721 19:19:54.166170    1186 placement_manager.go:250]  "msg"="Released slots"  "jobs"={"tf2-keras-cifar10-inceptionv3-elastic-20210721-064117":{},"tf2-keras-cifar10-inceptionv3-elastic-20210721-064215":{},"tf2-keras-cifar10-resnet50-elastic-20210721-064048":{},"tf2-keras-cifar10-resnet50-elastic-20210721-064237":{},"tf2-keras-cifar10-vgg16-elastic-20210721-064310":{},"tf2-keras-transformer-elastic-20210721-064152":{}} "nodes"={"gpu3":{},"gpu4":{},"gpu5":{}} "scheduler"="default"
I0721 19:19:54.166614    1186 placement_manager.go:305]  "msg"="Found best-fit"  "crossNode"=0 "nodes"=[{},{},{}] "requests"=[{},{},{},{},{},{},{},{},{},{},{},{},{},{},{},{},{},{},{},{},{},{},{},{},{},{},{},{},{},{},{},{},{},{},{},{},{},{}] "scheduler"="default"
I0721 19:19:54.166847    1186 placement_manager.go:339]  "msg"="nodeStates updated"  "new"={"gpu3":{},"gpu4":{},"gpu5":{}} "old"={"gpu3":{},"gpu4":{},"gpu5":{}} "scheduler"="default" "score"=6
I0721 19:19:54.167082    1186 placement_manager.go:387]  "msg"="jobStates updated"  "new"={"tf2-keras-cifar10-inceptionv3-elastic-20210721-064117":{},"tf2-keras-cifar10-inceptionv3-elastic-20210721-064215":{},"tf2-keras-cifar10-resnet50-elastic-20210721-064237":{},"tf2-keras-cifar10-vgg16-elastic-20210721-064310":{},"tf2-keras-transformer-elastic-20210721-064152":{},"tf2-keras-transformer-elastic-20210721-064332":{}} "old"={"tf2-keras-cifar10-inceptionv3-elastic-20210721-064117":{},"tf2-keras-cifar10-inceptionv3-elastic-20210721-064215":{},"tf2-keras-cifar10-resnet50-elastic-20210721-064048":{},"tf2-keras-cifar10-resnet50-elastic-20210721-064237":{},"tf2-keras-cifar10-vgg16-elastic-20210721-064310":{},"tf2-keras-transformer-elastic-20210721-064152":{}} "scheduler"="default"
I0721 19:19:54.167439    1186 placement_manager.go:434]  "msg"="podNodeName updated"  "launchersToDelete"=2 "new"={"tf2-keras-cifar10-inceptionv3-elastic-20210721-064117-worker-0":"gpu4","tf2-keras-cifar10-inceptionv3-elastic-20210721-064117-worker-1":"gpu4","tf2-keras-cifar10-inceptionv3-elastic-20210721-064215-worker-0":"gpu3","tf2-keras-cifar10-inceptionv3-elastic-20210721-064215-worker-1":"gpu3","tf2-keras-cifar10-resnet50-elastic-20210721-064237-worker-0":"gpu4","tf2-keras-cifar10-resnet50-elastic-20210721-064237-worker-1":"gpu4","tf2-keras-cifar10-vgg16-elastic-20210721-064310-worker-0":"gpu5","tf2-keras-cifar10-vgg16-elastic-20210721-064310-worker-1":"gpu5","tf2-keras-transformer-elastic-20210721-064152-worker-0":"gpu3","tf2-keras-transformer-elastic-20210721-064152-worker-1":"gpu3","tf2-keras-transformer-elastic-20210721-064332-worker-0":"gpu5","tf2-keras-transformer-elastic-20210721-064332-worker-1":"gpu5"} "old"={"tf2-keras-cifar10-inceptionv3-elastic-20210721-064117-worker-0":"gpu3","tf2-keras-cifar10-inceptionv3-elastic-20210721-064117-worker-1":"gpu3","tf2-keras-cifar10-inceptionv3-elastic-20210721-064215-worker-0":"gpu4","tf2-keras-cifar10-inceptionv3-elastic-20210721-064215-worker-1":"gpu4","tf2-keras-cifar10-resnet50-elastic-20210721-064048-worker-0":"gpu5","tf2-keras-cifar10-resnet50-elastic-20210721-064048-worker-1":"gpu5","tf2-keras-cifar10-resnet50-elastic-20210721-064237-worker-0":"gpu4","tf2-keras-cifar10-resnet50-elastic-20210721-064237-worker-1":"gpu4","tf2-keras-cifar10-vgg16-elastic-20210721-064310-worker-0":"gpu5","tf2-keras-cifar10-vgg16-elastic-20210721-064310-worker-1":"gpu5","tf2-keras-transformer-elastic-20210721-064152-worker-0":"gpu3","tf2-keras-transformer-elastic-20210721-064152-worker-1":"gpu3"} "scheduler"="default" "workersToDelete"=4
I0721 19:19:54.167729    1186 placement_manager.go:451]  "msg"="Deleting pod that need migration"  "podName"="tf2-keras-cifar10-inceptionv3-elastic-20210721-064215-worker-0" "scheduler"="default"
I0721 19:19:54.171708    1186 placement_manager.go:451]  "msg"="Deleting pod that need migration"  "podName"="tf2-keras-cifar10-inceptionv3-elastic-20210721-064215-worker-1" "scheduler"="default"
I0721 19:19:54.177249    1186 placement_manager.go:451]  "msg"="Deleting pod that need migration"  "podName"="tf2-keras-cifar10-inceptionv3-elastic-20210721-064215-launcher" "scheduler"="default"
I0721 19:19:54.184882    1186 placement_manager.go:451]  "msg"="Deleting pod that need migration"  "podName"="tf2-keras-cifar10-inceptionv3-elastic-20210721-064117-worker-0" "scheduler"="default"
I0721 19:19:54.199764    1186 placement_manager.go:451]  "msg"="Deleting pod that need migration"  "podName"="tf2-keras-cifar10-inceptionv3-elastic-20210721-064117-worker-1" "scheduler"="default"
I0721 19:19:54.211773    1186 placement_manager.go:451]  "msg"="Deleting pod that need migration"  "podName"="tf2-keras-cifar10-inceptionv3-elastic-20210721-064117-launcher" "scheduler"="default"
I0721 19:19:54.216219    1186 placement_manager.go:183]  "msg"="Finished job placements adjustment"  "scheduler"="default"
I0721 19:19:54.216463    1186 scheduler.go:182]  "msg"="Finished resched"  "scheduler"="default"
I0721 19:19:54.938866    1186 placement_manager.go:147]  "msg"="Adding toleration to pod"  "podName"="tf2-keras-transformer-elastic-20210721-064332-worker-0" "scheduler"="default" "toleration"={"key":"celeste/hostname","operator":"Equal","value":"gpu5","effect":"NoExecute"}
I0721 19:19:55.336632    1186 placement_manager.go:147]  "msg"="Adding toleration to pod"  "podName"="tf2-keras-transformer-elastic-20210721-064332-worker-1" "scheduler"="default" "toleration"={"key":"celeste/hostname","operator":"Equal","value":"gpu5","effect":"NoExecute"}
I0721 19:19:55.739251    1186 placement_manager.go:147]  "msg"="Adding toleration to pod"  "podName"="tf2-keras-transformer-elastic-20210721-064332-launcher" "scheduler"="default" "toleration"={"key":"celeste/hostname","operator":"Exists","effect":"NoExecute"}
I0721 19:20:01.638932    1186 placement_manager.go:147]  "msg"="Adding toleration to pod"  "podName"="tf2-keras-cifar10-inceptionv3-elastic-20210721-064117-worker-0" "scheduler"="default" "toleration"={"key":"celeste/hostname","operator":"Equal","value":"gpu4","effect":"NoExecute"}
I0721 19:20:01.681482    1186 placement_manager.go:147]  "msg"="Adding toleration to pod"  "podName"="tf2-keras-cifar10-inceptionv3-elastic-20210721-064117-worker-1" "scheduler"="default" "toleration"={"key":"celeste/hostname","operator":"Equal","value":"gpu4","effect":"NoExecute"}
I0721 19:20:03.034594    1186 placement_manager.go:147]  "msg"="Adding toleration to pod"  "podName"="tf2-keras-cifar10-inceptionv3-elastic-20210721-064215-worker-0" "scheduler"="default" "toleration"={"key":"celeste/hostname","operator":"Equal","value":"gpu3","effect":"NoExecute"}
I0721 19:20:03.834644    1186 placement_manager.go:147]  "msg"="Adding toleration to pod"  "podName"="tf2-keras-cifar10-inceptionv3-elastic-20210721-064215-launcher" "scheduler"="default" "toleration"={"key":"celeste/hostname","operator":"Exists","effect":"NoExecute"}
I0721 19:20:05.240163    1186 placement_manager.go:147]  "msg"="Adding toleration to pod"  "podName"="tf2-keras-cifar10-inceptionv3-elastic-20210721-064215-worker-1" "scheduler"="default" "toleration"={"key":"celeste/hostname","operator":"Equal","value":"gpu3","effect":"NoExecute"}
I0721 19:20:10.020876    1186 placement_manager.go:147]  "msg"="Adding toleration to pod"  "podName"="tf2-keras-cifar10-inceptionv3-elastic-20210721-064117-launcher" "scheduler"="default" "toleration"={"key":"celeste/hostname","operator":"Exists","effect":"NoExecute"}
I0721 19:20:46.557052    1186 scheduler.go:559]  "msg"="Priority demoted to training job"  "job"="tf2-keras-cifar10-inceptionv3-elastic-20210721-064117" "priority"=1 "scheduler"="default"
I0721 19:20:46.557151    1186 scheduler.go:573]  "msg"="Priority changed"  "scheduler"="default"
I0721 19:20:46.557235    1186 scheduler.go:135]  "msg"="Received resched event, may be blocked because of rate limit"  "blockedUntil"="2021-07-21T19:21:54.216655599+08:00" "lastResched"="2021-07-21T19:19:54.216655599+08:00" "received"="2021-07-21T19:20:46.55716042+08:00" "scheduler"="default"
I0721 19:21:54.216742    1186 scheduler.go:159]  "msg"="Started resched"  "scheduler"="default"
I0721 19:21:54.216809    1186 scheduler.go:193]  "msg"="Updating all jobs info"  "scheduler"="default"
I0721 19:21:54.229024    1186 elastic_tiresias.go:160]  "msg"="Finished scheduling"  "algorithm"="ElasticTiresias" "compactionThreshold"=4 "freeGpu"=0 "promoteKnob"=4 "queueNum"=2 "result"={"tf2-keras-cifar10-inceptionv3-elastic-20210721-063448":0,"tf2-keras-cifar10-inceptionv3-elastic-20210721-063539":0,"tf2-keras-cifar10-inceptionv3-elastic-20210721-063756":0,"tf2-keras-cifar10-inceptionv3-elastic-20210721-063900":0,"tf2-keras-cifar10-inceptionv3-elastic-20210721-064117":0,"tf2-keras-cifar10-inceptionv3-elastic-20210721-064215":2,"tf2-keras-cifar10-resnet50-elastic-20210721-063511":0,"tf2-keras-cifar10-resnet50-elastic-20210721-064237":2,"tf2-keras-cifar10-resnet50-elastic-20210721-064451":0,"tf2-keras-cifar10-resnet50-elastic-20210721-064517":0,"tf2-keras-cifar10-vgg16-elastic-20210721-063631":0,"tf2-keras-cifar10-vgg16-elastic-20210721-064310":2,"tf2-keras-cifar10-vgg16-elastic-20210721-064412":2,"tf2-keras-transformer-elastic-20210721-063654":0,"tf2-keras-transformer-elastic-20210721-063721":0,"tf2-keras-transformer-elastic-20210721-063927":0,"tf2-keras-transformer-elastic-20210721-064152":2,"tf2-keras-transformer-elastic-20210721-064332":2,"tf2-keras-transformer-elastic-20210721-064545":0} "scheduler"="default" "thresholds"=
I0721 19:21:54.229462    1186 scheduler.go:384]  "msg"="Trying to delete multiple training jobs"  "jobs"=["tf2-keras-cifar10-inceptionv3-elastic-20210721-064117"] "scheduler"="default"
I0721 19:21:54.240587    1186 scheduler.go:342]  "msg"="Trying to scale multiple training jobs"  "jobs"=[] "scheduler"="default"
I0721 19:21:54.240853    1186 scheduler.go:292]  "msg"="Trying to start multiple training jobs"  "jobs"=["tf2-keras-cifar10-vgg16-elastic-20210721-064412"] "scheduler"="default"
I0721 19:21:54.266764    1186 scheduler.go:342]  "msg"="Trying to scale multiple training jobs"  "jobs"=[] "scheduler"="default"
I0721 19:21:54.269852    1186 placement_manager.go:166]  "msg"="Started job placements adjustment"  "scheduler"="default"
I0721 19:21:54.269929    1186 placement_manager.go:192]  "msg"="Releasing slots"  "jobs"={"tf2-keras-cifar10-inceptionv3-elastic-20210721-064117":{},"tf2-keras-cifar10-inceptionv3-elastic-20210721-064215":{},"tf2-keras-cifar10-resnet50-elastic-20210721-064237":{},"tf2-keras-cifar10-vgg16-elastic-20210721-064310":{},"tf2-keras-transformer-elastic-20210721-064152":{},"tf2-keras-transformer-elastic-20210721-064332":{}} "nodes"={"gpu3":{},"gpu4":{},"gpu5":{}} "scheduler"="default"
I0721 19:21:54.270005    1186 placement_manager.go:250]  "msg"="Released slots"  "jobs"={"tf2-keras-cifar10-inceptionv3-elastic-20210721-064117":{},"tf2-keras-cifar10-inceptionv3-elastic-20210721-064215":{},"tf2-keras-cifar10-resnet50-elastic-20210721-064237":{},"tf2-keras-cifar10-vgg16-elastic-20210721-064310":{},"tf2-keras-transformer-elastic-20210721-064152":{},"tf2-keras-transformer-elastic-20210721-064332":{}} "nodes"={"gpu3":{},"gpu4":{},"gpu5":{}} "scheduler"="default"
I0721 19:21:54.270363    1186 placement_manager.go:305]  "msg"="Found best-fit"  "crossNode"=0 "nodes"=[{},{},{}] "requests"=[{},{},{},{},{},{},{},{},{},{},{},{},{},{},{},{},{},{},{},{},{},{},{},{},{},{},{},{},{},{},{},{},{},{},{},{},{},{}] "scheduler"="default"
I0721 19:21:54.270695    1186 placement_manager.go:339]  "msg"="nodeStates updated"  "new"={"gpu3":{},"gpu4":{},"gpu5":{}} "old"={"gpu3":{},"gpu4":{},"gpu5":{}} "scheduler"="default" "score"=6
I0721 19:21:54.271071    1186 placement_manager.go:387]  "msg"="jobStates updated"  "new"={"tf2-keras-cifar10-inceptionv3-elastic-20210721-064215":{},"tf2-keras-cifar10-resnet50-elastic-20210721-064237":{},"tf2-keras-cifar10-vgg16-elastic-20210721-064310":{},"tf2-keras-cifar10-vgg16-elastic-20210721-064412":{},"tf2-keras-transformer-elastic-20210721-064152":{},"tf2-keras-transformer-elastic-20210721-064332":{}} "old"={"tf2-keras-cifar10-inceptionv3-elastic-20210721-064117":{},"tf2-keras-cifar10-inceptionv3-elastic-20210721-064215":{},"tf2-keras-cifar10-resnet50-elastic-20210721-064237":{},"tf2-keras-cifar10-vgg16-elastic-20210721-064310":{},"tf2-keras-transformer-elastic-20210721-064152":{},"tf2-keras-transformer-elastic-20210721-064332":{}} "scheduler"="default"
I0721 19:21:54.271619    1186 placement_manager.go:434]  "msg"="podNodeName updated"  "launchersToDelete"=2 "new"={"tf2-keras-cifar10-inceptionv3-elastic-20210721-064215-worker-0":"gpu4","tf2-keras-cifar10-inceptionv3-elastic-20210721-064215-worker-1":"gpu4","tf2-keras-cifar10-resnet50-elastic-20210721-064237-worker-0":"gpu4","tf2-keras-cifar10-resnet50-elastic-20210721-064237-worker-1":"gpu4","tf2-keras-cifar10-vgg16-elastic-20210721-064310-worker-0":"gpu5","tf2-keras-cifar10-vgg16-elastic-20210721-064310-worker-1":"gpu5","tf2-keras-cifar10-vgg16-elastic-20210721-064412-worker-0":"gpu5","tf2-keras-cifar10-vgg16-elastic-20210721-064412-worker-1":"gpu5","tf2-keras-transformer-elastic-20210721-064152-worker-0":"gpu3","tf2-keras-transformer-elastic-20210721-064152-worker-1":"gpu3","tf2-keras-transformer-elastic-20210721-064332-worker-0":"gpu3","tf2-keras-transformer-elastic-20210721-064332-worker-1":"gpu3"} "old"={"tf2-keras-cifar10-inceptionv3-elastic-20210721-064117-worker-0":"gpu4","tf2-keras-cifar10-inceptionv3-elastic-20210721-064117-worker-1":"gpu4","tf2-keras-cifar10-inceptionv3-elastic-20210721-064215-worker-0":"gpu3","tf2-keras-cifar10-inceptionv3-elastic-20210721-064215-worker-1":"gpu3","tf2-keras-cifar10-resnet50-elastic-20210721-064237-worker-0":"gpu4","tf2-keras-cifar10-resnet50-elastic-20210721-064237-worker-1":"gpu4","tf2-keras-cifar10-vgg16-elastic-20210721-064310-worker-0":"gpu5","tf2-keras-cifar10-vgg16-elastic-20210721-064310-worker-1":"gpu5","tf2-keras-transformer-elastic-20210721-064152-worker-0":"gpu3","tf2-keras-transformer-elastic-20210721-064152-worker-1":"gpu3","tf2-keras-transformer-elastic-20210721-064332-worker-0":"gpu5","tf2-keras-transformer-elastic-20210721-064332-worker-1":"gpu5"} "scheduler"="default" "workersToDelete"=4
I0721 19:21:54.271912    1186 placement_manager.go:451]  "msg"="Deleting pod that need migration"  "podName"="tf2-keras-cifar10-inceptionv3-elastic-20210721-064215-worker-0" "scheduler"="default"
I0721 19:21:54.278283    1186 placement_manager.go:451]  "msg"="Deleting pod that need migration"  "podName"="tf2-keras-cifar10-inceptionv3-elastic-20210721-064215-worker-1" "scheduler"="default"
I0721 19:21:54.282687    1186 placement_manager.go:451]  "msg"="Deleting pod that need migration"  "podName"="tf2-keras-cifar10-inceptionv3-elastic-20210721-064215-launcher" "scheduler"="default"
I0721 19:21:54.292176    1186 placement_manager.go:451]  "msg"="Deleting pod that need migration"  "podName"="tf2-keras-transformer-elastic-20210721-064332-worker-0" "scheduler"="default"
I0721 19:21:54.299203    1186 placement_manager.go:451]  "msg"="Deleting pod that need migration"  "podName"="tf2-keras-transformer-elastic-20210721-064332-worker-1" "scheduler"="default"
I0721 19:21:54.307808    1186 placement_manager.go:451]  "msg"="Deleting pod that need migration"  "podName"="tf2-keras-transformer-elastic-20210721-064332-launcher" "scheduler"="default"
I0721 19:21:54.312612    1186 placement_manager.go:183]  "msg"="Finished job placements adjustment"  "scheduler"="default"
I0721 19:21:54.313012    1186 scheduler.go:182]  "msg"="Finished resched"  "scheduler"="default"
I0721 19:21:54.475155    1186 placement_manager.go:147]  "msg"="Adding toleration to pod"  "podName"="tf2-keras-cifar10-vgg16-elastic-20210721-064412-worker-0" "scheduler"="default" "toleration"={"key":"celeste/hostname","operator":"Equal","value":"gpu5","effect":"NoExecute"}
I0721 19:21:54.675044    1186 placement_manager.go:147]  "msg"="Adding toleration to pod"  "podName"="tf2-keras-cifar10-vgg16-elastic-20210721-064412-worker-1" "scheduler"="default" "toleration"={"key":"celeste/hostname","operator":"Equal","value":"gpu5","effect":"NoExecute"}
I0721 19:21:54.872541    1186 placement_manager.go:147]  "msg"="Adding toleration to pod"  "podName"="tf2-keras-cifar10-vgg16-elastic-20210721-064412-launcher" "scheduler"="default" "toleration"={"key":"celeste/hostname","operator":"Exists","effect":"NoExecute"}
I0721 19:22:01.919590    1186 placement_manager.go:147]  "msg"="Adding toleration to pod"  "podName"="tf2-keras-cifar10-inceptionv3-elastic-20210721-064215-worker-0" "scheduler"="default" "toleration"={"key":"celeste/hostname","operator":"Equal","value":"gpu4","effect":"NoExecute"}
I0721 19:22:01.956478    1186 placement_manager.go:147]  "msg"="Adding toleration to pod"  "podName"="tf2-keras-cifar10-inceptionv3-elastic-20210721-064215-launcher" "scheduler"="default" "toleration"={"key":"celeste/hostname","operator":"Exists","effect":"NoExecute"}
I0721 19:22:01.968708    1186 placement_manager.go:147]  "msg"="Adding toleration to pod"  "podName"="tf2-keras-cifar10-inceptionv3-elastic-20210721-064215-worker-1" "scheduler"="default" "toleration"={"key":"celeste/hostname","operator":"Equal","value":"gpu4","effect":"NoExecute"}
I0721 19:22:02.403612    1186 placement_manager.go:147]  "msg"="Adding toleration to pod"  "podName"="tf2-keras-transformer-elastic-20210721-064332-worker-1" "scheduler"="default" "toleration"={"key":"celeste/hostname","operator":"Equal","value":"gpu3","effect":"NoExecute"}
I0721 19:22:03.207215    1186 placement_manager.go:147]  "msg"="Adding toleration to pod"  "podName"="tf2-keras-transformer-elastic-20210721-064332-launcher" "scheduler"="default" "toleration"={"key":"celeste/hostname","operator":"Exists","effect":"NoExecute"}
I0721 19:22:10.405844    1186 placement_manager.go:147]  "msg"="Adding toleration to pod"  "podName"="tf2-keras-transformer-elastic-20210721-064332-worker-0" "scheduler"="default" "toleration"={"key":"celeste/hostname","operator":"Equal","value":"gpu3","effect":"NoExecute"}
I0721 19:22:46.560784    1186 scheduler.go:559]  "msg"="Priority demoted to training job"  "job"="tf2-keras-transformer-elastic-20210721-064152" "priority"=1 "scheduler"="default"
I0721 19:22:46.560842    1186 scheduler.go:559]  "msg"="Priority demoted to training job"  "job"="tf2-keras-cifar10-inceptionv3-elastic-20210721-064215" "priority"=1 "scheduler"="default"
I0721 19:22:46.560876    1186 scheduler.go:573]  "msg"="Priority changed"  "scheduler"="default"
I0721 19:22:46.560946    1186 scheduler.go:135]  "msg"="Received resched event, may be blocked because of rate limit"  "blockedUntil"="2021-07-21T19:23:54.313339723+08:00" "lastResched"="2021-07-21T19:21:54.313339723+08:00" "received"="2021-07-21T19:22:46.560883657+08:00" "scheduler"="default"
I0721 19:23:54.313487    1186 scheduler.go:159]  "msg"="Started resched"  "scheduler"="default"
I0721 19:23:54.313580    1186 scheduler.go:193]  "msg"="Updating all jobs info"  "scheduler"="default"
I0721 19:23:54.324246    1186 elastic_tiresias.go:160]  "msg"="Finished scheduling"  "algorithm"="ElasticTiresias" "compactionThreshold"=4 "freeGpu"=0 "promoteKnob"=4 "queueNum"=2 "result"={"tf2-keras-cifar10-inceptionv3-elastic-20210721-063448":0,"tf2-keras-cifar10-inceptionv3-elastic-20210721-063539":0,"tf2-keras-cifar10-inceptionv3-elastic-20210721-063756":0,"tf2-keras-cifar10-inceptionv3-elastic-20210721-063900":0,"tf2-keras-cifar10-inceptionv3-elastic-20210721-064117":0,"tf2-keras-cifar10-inceptionv3-elastic-20210721-064215":0,"tf2-keras-cifar10-resnet50-elastic-20210721-063511":0,"tf2-keras-cifar10-resnet50-elastic-20210721-064237":2,"tf2-keras-cifar10-resnet50-elastic-20210721-064451":2,"tf2-keras-cifar10-resnet50-elastic-20210721-064517":2,"tf2-keras-cifar10-vgg16-elastic-20210721-063631":0,"tf2-keras-cifar10-vgg16-elastic-20210721-064310":2,"tf2-keras-cifar10-vgg16-elastic-20210721-064412":2,"tf2-keras-transformer-elastic-20210721-063654":0,"tf2-keras-transformer-elastic-20210721-063721":0,"tf2-keras-transformer-elastic-20210721-063927":0,"tf2-keras-transformer-elastic-20210721-064152":0,"tf2-keras-transformer-elastic-20210721-064332":2,"tf2-keras-transformer-elastic-20210721-064545":0} "scheduler"="default" "thresholds"=
I0721 19:23:54.324632    1186 scheduler.go:384]  "msg"="Trying to delete multiple training jobs"  "jobs"=["tf2-keras-transformer-elastic-20210721-064152","tf2-keras-cifar10-inceptionv3-elastic-20210721-064215"] "scheduler"="default"
I0721 19:23:54.345598    1186 scheduler.go:342]  "msg"="Trying to scale multiple training jobs"  "jobs"=[] "scheduler"="default"
I0721 19:23:54.346013    1186 scheduler.go:292]  "msg"="Trying to start multiple training jobs"  "jobs"=["tf2-keras-cifar10-resnet50-elastic-20210721-064517","tf2-keras-cifar10-resnet50-elastic-20210721-064451"] "scheduler"="default"
I0721 19:23:54.367549    1186 scheduler.go:342]  "msg"="Trying to scale multiple training jobs"  "jobs"=[] "scheduler"="default"
I0721 19:23:54.370564    1186 placement_manager.go:166]  "msg"="Started job placements adjustment"  "scheduler"="default"
I0721 19:23:54.370630    1186 placement_manager.go:192]  "msg"="Releasing slots"  "jobs"={"tf2-keras-cifar10-inceptionv3-elastic-20210721-064215":{},"tf2-keras-cifar10-resnet50-elastic-20210721-064237":{},"tf2-keras-cifar10-vgg16-elastic-20210721-064310":{},"tf2-keras-cifar10-vgg16-elastic-20210721-064412":{},"tf2-keras-transformer-elastic-20210721-064152":{},"tf2-keras-transformer-elastic-20210721-064332":{}} "nodes"={"gpu3":{},"gpu4":{},"gpu5":{}} "scheduler"="default"
I0721 19:23:54.370688    1186 placement_manager.go:250]  "msg"="Released slots"  "jobs"={"tf2-keras-cifar10-inceptionv3-elastic-20210721-064215":{},"tf2-keras-cifar10-resnet50-elastic-20210721-064237":{},"tf2-keras-cifar10-vgg16-elastic-20210721-064310":{},"tf2-keras-cifar10-vgg16-elastic-20210721-064412":{},"tf2-keras-transformer-elastic-20210721-064152":{},"tf2-keras-transformer-elastic-20210721-064332":{}} "nodes"={"gpu3":{},"gpu4":{},"gpu5":{}} "scheduler"="default"
I0721 19:23:54.371027    1186 placement_manager.go:305]  "msg"="Found best-fit"  "crossNode"=0 "nodes"=[{},{},{}] "requests"=[{},{},{},{},{},{},{},{},{},{},{},{},{},{},{},{},{},{},{},{},{},{},{},{},{},{},{},{},{},{},{},{},{},{},{},{},{},{}] "scheduler"="default"
I0721 19:23:54.371305    1186 placement_manager.go:339]  "msg"="nodeStates updated"  "new"={"gpu3":{},"gpu4":{},"gpu5":{}} "old"={"gpu3":{},"gpu4":{},"gpu5":{}} "scheduler"="default" "score"=6
I0721 19:23:54.371580    1186 placement_manager.go:387]  "msg"="jobStates updated"  "new"={"tf2-keras-cifar10-resnet50-elastic-20210721-064237":{},"tf2-keras-cifar10-resnet50-elastic-20210721-064451":{},"tf2-keras-cifar10-resnet50-elastic-20210721-064517":{},"tf2-keras-cifar10-vgg16-elastic-20210721-064310":{},"tf2-keras-cifar10-vgg16-elastic-20210721-064412":{},"tf2-keras-transformer-elastic-20210721-064332":{}} "old"={"tf2-keras-cifar10-inceptionv3-elastic-20210721-064215":{},"tf2-keras-cifar10-resnet50-elastic-20210721-064237":{},"tf2-keras-cifar10-vgg16-elastic-20210721-064310":{},"tf2-keras-cifar10-vgg16-elastic-20210721-064412":{},"tf2-keras-transformer-elastic-20210721-064152":{},"tf2-keras-transformer-elastic-20210721-064332":{}} "scheduler"="default"
I0721 19:23:54.371913    1186 placement_manager.go:434]  "msg"="podNodeName updated"  "launchersToDelete"=1 "new"={"tf2-keras-cifar10-resnet50-elastic-20210721-064237-worker-0":"gpu4","tf2-keras-cifar10-resnet50-elastic-20210721-064237-worker-1":"gpu4","tf2-keras-cifar10-resnet50-elastic-20210721-064451-worker-0":"gpu3","tf2-keras-cifar10-resnet50-elastic-20210721-064451-worker-1":"gpu3","tf2-keras-cifar10-resnet50-elastic-20210721-064517-worker-0":"gpu5","tf2-keras-cifar10-resnet50-elastic-20210721-064517-worker-1":"gpu5","tf2-keras-cifar10-vgg16-elastic-20210721-064310-worker-0":"gpu4","tf2-keras-cifar10-vgg16-elastic-20210721-064310-worker-1":"gpu4","tf2-keras-cifar10-vgg16-elastic-20210721-064412-worker-0":"gpu5","tf2-keras-cifar10-vgg16-elastic-20210721-064412-worker-1":"gpu5","tf2-keras-transformer-elastic-20210721-064332-worker-0":"gpu3","tf2-keras-transformer-elastic-20210721-064332-worker-1":"gpu3"} "old"={"tf2-keras-cifar10-inceptionv3-elastic-20210721-064215-worker-0":"gpu4","tf2-keras-cifar10-inceptionv3-elastic-20210721-064215-worker-1":"gpu4","tf2-keras-cifar10-resnet50-elastic-20210721-064237-worker-0":"gpu4","tf2-keras-cifar10-resnet50-elastic-20210721-064237-worker-1":"gpu4","tf2-keras-cifar10-vgg16-elastic-20210721-064310-worker-0":"gpu5","tf2-keras-cifar10-vgg16-elastic-20210721-064310-worker-1":"gpu5","tf2-keras-cifar10-vgg16-elastic-20210721-064412-worker-0":"gpu5","tf2-keras-cifar10-vgg16-elastic-20210721-064412-worker-1":"gpu5","tf2-keras-transformer-elastic-20210721-064152-worker-0":"gpu3","tf2-keras-transformer-elastic-20210721-064152-worker-1":"gpu3","tf2-keras-transformer-elastic-20210721-064332-worker-0":"gpu3","tf2-keras-transformer-elastic-20210721-064332-worker-1":"gpu3"} "scheduler"="default" "workersToDelete"=2
I0721 19:23:54.372170    1186 placement_manager.go:451]  "msg"="Deleting pod that need migration"  "podName"="tf2-keras-cifar10-vgg16-elastic-20210721-064310-worker-0" "scheduler"="default"
I0721 19:23:54.376891    1186 placement_manager.go:451]  "msg"="Deleting pod that need migration"  "podName"="tf2-keras-cifar10-vgg16-elastic-20210721-064310-worker-1" "scheduler"="default"
I0721 19:23:54.381080    1186 placement_manager.go:451]  "msg"="Deleting pod that need migration"  "podName"="tf2-keras-cifar10-vgg16-elastic-20210721-064310-launcher" "scheduler"="default"
I0721 19:23:54.386539    1186 placement_manager.go:183]  "msg"="Finished job placements adjustment"  "scheduler"="default"
I0721 19:23:54.386776    1186 scheduler.go:182]  "msg"="Finished resched"  "scheduler"="default"
I0721 19:23:54.570983    1186 placement_manager.go:147]  "msg"="Adding toleration to pod"  "podName"="tf2-keras-cifar10-resnet50-elastic-20210721-064517-worker-0" "scheduler"="default" "toleration"={"key":"celeste/hostname","operator":"Equal","value":"gpu5","effect":"NoExecute"}
I0721 19:23:54.768049    1186 placement_manager.go:147]  "msg"="Adding toleration to pod"  "podName"="tf2-keras-cifar10-resnet50-elastic-20210721-064451-worker-0" "scheduler"="default" "toleration"={"key":"celeste/hostname","operator":"Equal","value":"gpu3","effect":"NoExecute"}
I0721 19:23:54.969694    1186 placement_manager.go:147]  "msg"="Adding toleration to pod"  "podName"="tf2-keras-cifar10-resnet50-elastic-20210721-064517-worker-1" "scheduler"="default" "toleration"={"key":"celeste/hostname","operator":"Equal","value":"gpu5","effect":"NoExecute"}
I0721 19:23:55.381397    1186 placement_manager.go:147]  "msg"="Adding toleration to pod"  "podName"="tf2-keras-cifar10-resnet50-elastic-20210721-064451-worker-1" "scheduler"="default" "toleration"={"key":"celeste/hostname","operator":"Equal","value":"gpu3","effect":"NoExecute"}
I0721 19:23:55.779808    1186 placement_manager.go:147]  "msg"="Adding toleration to pod"  "podName"="tf2-keras-cifar10-resnet50-elastic-20210721-064517-launcher" "scheduler"="default" "toleration"={"key":"celeste/hostname","operator":"Exists","effect":"NoExecute"}
I0721 19:23:56.183604    1186 placement_manager.go:147]  "msg"="Adding toleration to pod"  "podName"="tf2-keras-cifar10-resnet50-elastic-20210721-064451-launcher" "scheduler"="default" "toleration"={"key":"celeste/hostname","operator":"Exists","effect":"NoExecute"}
I0721 19:24:09.750530    1186 placement_manager.go:147]  "msg"="Adding toleration to pod"  "podName"="tf2-keras-cifar10-vgg16-elastic-20210721-064310-worker-0" "scheduler"="default" "toleration"={"key":"celeste/hostname","operator":"Equal","value":"gpu4","effect":"NoExecute"}
I0721 19:24:09.796615    1186 placement_manager.go:147]  "msg"="Adding toleration to pod"  "podName"="tf2-keras-cifar10-vgg16-elastic-20210721-064310-worker-1" "scheduler"="default" "toleration"={"key":"celeste/hostname","operator":"Equal","value":"gpu4","effect":"NoExecute"}
I0721 19:24:09.809877    1186 placement_manager.go:147]  "msg"="Adding toleration to pod"  "podName"="tf2-keras-cifar10-vgg16-elastic-20210721-064310-launcher" "scheduler"="default" "toleration"={"key":"celeste/hostname","operator":"Exists","effect":"NoExecute"}
I0721 19:24:36.974008    1186 scheduler.go:474]  "msg"="Training job completed"  "elaspedTotalSeconds"=2518.656687591 "gpuTotalSeconds"=1780.061365276 "job"="tf2-keras-cifar10-resnet50-elastic-20210721-064237" "ranTotalSeconds"=890.030682638 "scheduler"="default" "waitedTotalSeconds"=1628.626004953
I0721 19:24:36.974214    1186 scheduler.go:135]  "msg"="Received resched event, may be blocked because of rate limit"  "blockedUntil"="2021-07-21T19:25:54.386945426+08:00" "lastResched"="2021-07-21T19:23:54.386945426+08:00" "received"="2021-07-21T19:24:36.97404814+08:00" "scheduler"="default"
I0721 19:25:54.387038    1186 scheduler.go:159]  "msg"="Started resched"  "scheduler"="default"
I0721 19:25:54.387119    1186 scheduler.go:193]  "msg"="Updating all jobs info"  "scheduler"="default"
I0721 19:25:54.399597    1186 elastic_tiresias.go:160]  "msg"="Finished scheduling"  "algorithm"="ElasticTiresias" "compactionThreshold"=4 "freeGpu"=0 "promoteKnob"=4 "queueNum"=2 "result"={"tf2-keras-cifar10-inceptionv3-elastic-20210721-063448":0,"tf2-keras-cifar10-inceptionv3-elastic-20210721-063539":0,"tf2-keras-cifar10-inceptionv3-elastic-20210721-063756":0,"tf2-keras-cifar10-inceptionv3-elastic-20210721-063900":0,"tf2-keras-cifar10-inceptionv3-elastic-20210721-064117":0,"tf2-keras-cifar10-inceptionv3-elastic-20210721-064215":0,"tf2-keras-cifar10-resnet50-elastic-20210721-063511":0,"tf2-keras-cifar10-resnet50-elastic-20210721-064451":2,"tf2-keras-cifar10-resnet50-elastic-20210721-064517":2,"tf2-keras-cifar10-vgg16-elastic-20210721-063631":0,"tf2-keras-cifar10-vgg16-elastic-20210721-064310":2,"tf2-keras-cifar10-vgg16-elastic-20210721-064412":2,"tf2-keras-transformer-elastic-20210721-063654":0,"tf2-keras-transformer-elastic-20210721-063721":0,"tf2-keras-transformer-elastic-20210721-063927":0,"tf2-keras-transformer-elastic-20210721-064152":0,"tf2-keras-transformer-elastic-20210721-064332":2,"tf2-keras-transformer-elastic-20210721-064545":2} "scheduler"="default" "thresholds"=
I0721 19:25:54.399944    1186 scheduler.go:384]  "msg"="Trying to delete multiple training jobs"  "jobs"=[] "scheduler"="default"
I0721 19:25:54.400170    1186 scheduler.go:342]  "msg"="Trying to scale multiple training jobs"  "jobs"=[] "scheduler"="default"
I0721 19:25:54.400397    1186 scheduler.go:292]  "msg"="Trying to start multiple training jobs"  "jobs"=["tf2-keras-transformer-elastic-20210721-064545"] "scheduler"="default"
I0721 19:25:54.410285    1186 scheduler.go:342]  "msg"="Trying to scale multiple training jobs"  "jobs"=[] "scheduler"="default"
I0721 19:25:54.412458    1186 placement_manager.go:166]  "msg"="Started job placements adjustment"  "scheduler"="default"
I0721 19:25:54.412548    1186 placement_manager.go:192]  "msg"="Releasing slots"  "jobs"={"tf2-keras-cifar10-resnet50-elastic-20210721-064237":{},"tf2-keras-cifar10-resnet50-elastic-20210721-064451":{},"tf2-keras-cifar10-resnet50-elastic-20210721-064517":{},"tf2-keras-cifar10-vgg16-elastic-20210721-064310":{},"tf2-keras-cifar10-vgg16-elastic-20210721-064412":{},"tf2-keras-transformer-elastic-20210721-064332":{}} "nodes"={"gpu3":{},"gpu4":{},"gpu5":{}} "scheduler"="default"
I0721 19:25:54.412626    1186 placement_manager.go:250]  "msg"="Released slots"  "jobs"={"tf2-keras-cifar10-resnet50-elastic-20210721-064237":{},"tf2-keras-cifar10-resnet50-elastic-20210721-064451":{},"tf2-keras-cifar10-resnet50-elastic-20210721-064517":{},"tf2-keras-cifar10-vgg16-elastic-20210721-064310":{},"tf2-keras-cifar10-vgg16-elastic-20210721-064412":{},"tf2-keras-transformer-elastic-20210721-064332":{}} "nodes"={"gpu3":{},"gpu4":{},"gpu5":{}} "scheduler"="default"
I0721 19:25:54.413036    1186 placement_manager.go:305]  "msg"="Found best-fit"  "crossNode"=0 "nodes"=[{},{},{}] "requests"=[{},{},{},{},{},{},{},{},{},{},{},{},{},{},{},{},{},{},{},{},{},{},{},{},{},{},{},{},{},{},{},{},{},{},{},{}] "scheduler"="default"
I0721 19:25:54.413346    1186 placement_manager.go:339]  "msg"="nodeStates updated"  "new"={"gpu3":{},"gpu4":{},"gpu5":{}} "old"={"gpu3":{},"gpu4":{},"gpu5":{}} "scheduler"="default" "score"=8
I0721 19:25:54.413697    1186 placement_manager.go:387]  "msg"="jobStates updated"  "new"={"tf2-keras-cifar10-resnet50-elastic-20210721-064451":{},"tf2-keras-cifar10-resnet50-elastic-20210721-064517":{},"tf2-keras-cifar10-vgg16-elastic-20210721-064310":{},"tf2-keras-cifar10-vgg16-elastic-20210721-064412":{},"tf2-keras-transformer-elastic-20210721-064332":{},"tf2-keras-transformer-elastic-20210721-064545":{}} "old"={"tf2-keras-cifar10-resnet50-elastic-20210721-064237":{},"tf2-keras-cifar10-resnet50-elastic-20210721-064451":{},"tf2-keras-cifar10-resnet50-elastic-20210721-064517":{},"tf2-keras-cifar10-vgg16-elastic-20210721-064310":{},"tf2-keras-cifar10-vgg16-elastic-20210721-064412":{},"tf2-keras-transformer-elastic-20210721-064332":{}} "scheduler"="default"
I0721 19:25:54.414181    1186 placement_manager.go:434]  "msg"="podNodeName updated"  "launchersToDelete"=1 "new"={"tf2-keras-cifar10-resnet50-elastic-20210721-064451-worker-0":"gpu3","tf2-keras-cifar10-resnet50-elastic-20210721-064451-worker-1":"gpu3","tf2-keras-cifar10-resnet50-elastic-20210721-064517-worker-0":"gpu4","tf2-keras-cifar10-resnet50-elastic-20210721-064517-worker-1":"gpu4","tf2-keras-cifar10-vgg16-elastic-20210721-064310-worker-0":"gpu4","tf2-keras-cifar10-vgg16-elastic-20210721-064310-worker-1":"gpu4","tf2-keras-cifar10-vgg16-elastic-20210721-064412-worker-0":"gpu5","tf2-keras-cifar10-vgg16-elastic-20210721-064412-worker-1":"gpu5","tf2-keras-transformer-elastic-20210721-064332-worker-0":"gpu3","tf2-keras-transformer-elastic-20210721-064332-worker-1":"gpu3","tf2-keras-transformer-elastic-20210721-064545-worker-0":"gpu5","tf2-keras-transformer-elastic-20210721-064545-worker-1":"gpu5"} "old"={"tf2-keras-cifar10-resnet50-elastic-20210721-064237-worker-0":"gpu4","tf2-keras-cifar10-resnet50-elastic-20210721-064237-worker-1":"gpu4","tf2-keras-cifar10-resnet50-elastic-20210721-064451-worker-0":"gpu3","tf2-keras-cifar10-resnet50-elastic-20210721-064451-worker-1":"gpu3","tf2-keras-cifar10-resnet50-elastic-20210721-064517-worker-0":"gpu5","tf2-keras-cifar10-resnet50-elastic-20210721-064517-worker-1":"gpu5","tf2-keras-cifar10-vgg16-elastic-20210721-064310-worker-0":"gpu4","tf2-keras-cifar10-vgg16-elastic-20210721-064310-worker-1":"gpu4","tf2-keras-cifar10-vgg16-elastic-20210721-064412-worker-0":"gpu5","tf2-keras-cifar10-vgg16-elastic-20210721-064412-worker-1":"gpu5","tf2-keras-transformer-elastic-20210721-064332-worker-0":"gpu3","tf2-keras-transformer-elastic-20210721-064332-worker-1":"gpu3"} "scheduler"="default" "workersToDelete"=2
I0721 19:25:54.414515    1186 placement_manager.go:451]  "msg"="Deleting pod that need migration"  "podName"="tf2-keras-cifar10-resnet50-elastic-20210721-064517-worker-0" "scheduler"="default"
I0721 19:25:54.426068    1186 placement_manager.go:451]  "msg"="Deleting pod that need migration"  "podName"="tf2-keras-cifar10-resnet50-elastic-20210721-064517-worker-1" "scheduler"="default"
I0721 19:25:54.434007    1186 placement_manager.go:451]  "msg"="Deleting pod that need migration"  "podName"="tf2-keras-cifar10-resnet50-elastic-20210721-064517-launcher" "scheduler"="default"
I0721 19:25:54.457818    1186 placement_manager.go:183]  "msg"="Finished job placements adjustment"  "scheduler"="default"
I0721 19:25:54.458082    1186 scheduler.go:182]  "msg"="Finished resched"  "scheduler"="default"
I0721 19:25:54.493973    1186 placement_manager.go:147]  "msg"="Adding toleration to pod"  "podName"="tf2-keras-transformer-elastic-20210721-064545-worker-0" "scheduler"="default" "toleration"={"key":"celeste/hostname","operator":"Equal","value":"gpu5","effect":"NoExecute"}
I0721 19:25:54.525269    1186 placement_manager.go:147]  "msg"="Adding toleration to pod"  "podName"="tf2-keras-transformer-elastic-20210721-064545-worker-1" "scheduler"="default" "toleration"={"key":"celeste/hostname","operator":"Equal","value":"gpu5","effect":"NoExecute"}
I0721 19:25:54.617811    1186 placement_manager.go:147]  "msg"="Adding toleration to pod"  "podName"="tf2-keras-transformer-elastic-20210721-064545-launcher" "scheduler"="default" "toleration"={"key":"celeste/hostname","operator":"Exists","effect":"NoExecute"}
I0721 19:26:09.755438    1186 placement_manager.go:147]  "msg"="Adding toleration to pod"  "podName"="tf2-keras-cifar10-resnet50-elastic-20210721-064517-worker-1" "scheduler"="default" "toleration"={"key":"celeste/hostname","operator":"Equal","value":"gpu4","effect":"NoExecute"}
I0721 19:26:09.909870    1186 placement_manager.go:147]  "msg"="Adding toleration to pod"  "podName"="tf2-keras-cifar10-resnet50-elastic-20210721-064517-worker-0" "scheduler"="default" "toleration"={"key":"celeste/hostname","operator":"Equal","value":"gpu4","effect":"NoExecute"}
I0721 19:26:09.922034    1186 placement_manager.go:147]  "msg"="Adding toleration to pod"  "podName"="tf2-keras-cifar10-resnet50-elastic-20210721-064517-launcher" "scheduler"="default" "toleration"={"key":"celeste/hostname","operator":"Exists","effect":"NoExecute"}
I0721 19:31:11.577755    1186 scheduler.go:559]  "msg"="Priority demoted to training job"  "job"="tf2-keras-cifar10-vgg16-elastic-20210721-064310" "priority"=1 "scheduler"="default"
I0721 19:31:11.577814    1186 scheduler.go:573]  "msg"="Priority changed"  "scheduler"="default"
I0721 19:31:11.577931    1186 scheduler.go:135]  "msg"="Received resched event, may be blocked because of rate limit"  "blockedUntil"="2021-07-21T19:27:54.458269584+08:00" "lastResched"="2021-07-21T19:25:54.458269584+08:00" "received"="2021-07-21T19:31:11.577820538+08:00" "scheduler"="default"
I0721 19:31:11.577975    1186 scheduler.go:159]  "msg"="Started resched"  "scheduler"="default"
I0721 19:31:11.578038    1186 scheduler.go:193]  "msg"="Updating all jobs info"  "scheduler"="default"
I0721 19:31:11.588388    1186 elastic_tiresias.go:160]  "msg"="Finished scheduling"  "algorithm"="ElasticTiresias" "compactionThreshold"=4 "freeGpu"=0 "promoteKnob"=4 "queueNum"=2 "result"={"tf2-keras-cifar10-inceptionv3-elastic-20210721-063448":1,"tf2-keras-cifar10-inceptionv3-elastic-20210721-063539":0,"tf2-keras-cifar10-inceptionv3-elastic-20210721-063756":0,"tf2-keras-cifar10-inceptionv3-elastic-20210721-063900":0,"tf2-keras-cifar10-inceptionv3-elastic-20210721-064117":0,"tf2-keras-cifar10-inceptionv3-elastic-20210721-064215":0,"tf2-keras-cifar10-resnet50-elastic-20210721-063511":1,"tf2-keras-cifar10-resnet50-elastic-20210721-064451":2,"tf2-keras-cifar10-resnet50-elastic-20210721-064517":2,"tf2-keras-cifar10-vgg16-elastic-20210721-063631":0,"tf2-keras-cifar10-vgg16-elastic-20210721-064310":0,"tf2-keras-cifar10-vgg16-elastic-20210721-064412":2,"tf2-keras-transformer-elastic-20210721-063654":0,"tf2-keras-transformer-elastic-20210721-063721":0,"tf2-keras-transformer-elastic-20210721-063927":0,"tf2-keras-transformer-elastic-20210721-064152":0,"tf2-keras-transformer-elastic-20210721-064332":2,"tf2-keras-transformer-elastic-20210721-064545":2} "scheduler"="default" "thresholds"=
I0721 19:31:11.588714    1186 scheduler.go:384]  "msg"="Trying to delete multiple training jobs"  "jobs"=["tf2-keras-cifar10-vgg16-elastic-20210721-064310"] "scheduler"="default"
I0721 19:31:11.600134    1186 scheduler.go:342]  "msg"="Trying to scale multiple training jobs"  "jobs"=[] "scheduler"="default"
I0721 19:31:11.600396    1186 scheduler.go:292]  "msg"="Trying to start multiple training jobs"  "jobs"=["tf2-keras-cifar10-inceptionv3-elastic-20210721-063448","tf2-keras-cifar10-resnet50-elastic-20210721-063511"] "scheduler"="default"
I0721 19:31:11.635846    1186 scheduler.go:342]  "msg"="Trying to scale multiple training jobs"  "jobs"=[] "scheduler"="default"
I0721 19:31:11.639640    1186 placement_manager.go:166]  "msg"="Started job placements adjustment"  "scheduler"="default"
I0721 19:31:11.639708    1186 placement_manager.go:192]  "msg"="Releasing slots"  "jobs"={"tf2-keras-cifar10-resnet50-elastic-20210721-064451":{},"tf2-keras-cifar10-resnet50-elastic-20210721-064517":{},"tf2-keras-cifar10-vgg16-elastic-20210721-064310":{},"tf2-keras-cifar10-vgg16-elastic-20210721-064412":{},"tf2-keras-transformer-elastic-20210721-064332":{},"tf2-keras-transformer-elastic-20210721-064545":{}} "nodes"={"gpu3":{},"gpu4":{},"gpu5":{}} "scheduler"="default"
I0721 19:31:11.639774    1186 placement_manager.go:250]  "msg"="Released slots"  "jobs"={"tf2-keras-cifar10-resnet50-elastic-20210721-064451":{},"tf2-keras-cifar10-resnet50-elastic-20210721-064517":{},"tf2-keras-cifar10-vgg16-elastic-20210721-064310":{},"tf2-keras-cifar10-vgg16-elastic-20210721-064412":{},"tf2-keras-transformer-elastic-20210721-064332":{},"tf2-keras-transformer-elastic-20210721-064545":{}} "nodes"={"gpu3":{},"gpu4":{},"gpu5":{}} "scheduler"="default"
I0721 19:31:11.640246    1186 placement_manager.go:305]  "msg"="Found best-fit"  "crossNode"=0 "nodes"=[{},{},{}] "requests"=[{},{},{},{},{},{},{},{},{},{},{},{},{},{},{},{},{},{},{},{},{},{},{},{},{},{},{},{},{},{},{},{},{},{},{},{}] "scheduler"="default"
I0721 19:31:11.640517    1186 placement_manager.go:339]  "msg"="nodeStates updated"  "new"={"gpu3":{},"gpu4":{},"gpu5":{}} "old"={"gpu3":{},"gpu4":{},"gpu5":{}} "scheduler"="default" "score"=6
I0721 19:31:11.640766    1186 placement_manager.go:387]  "msg"="jobStates updated"  "new"={"tf2-keras-cifar10-inceptionv3-elastic-20210721-063448":{},"tf2-keras-cifar10-resnet50-elastic-20210721-063511":{},"tf2-keras-cifar10-resnet50-elastic-20210721-064451":{},"tf2-keras-cifar10-resnet50-elastic-20210721-064517":{},"tf2-keras-cifar10-vgg16-elastic-20210721-064412":{},"tf2-keras-transformer-elastic-20210721-064332":{},"tf2-keras-transformer-elastic-20210721-064545":{}} "old"={"tf2-keras-cifar10-resnet50-elastic-20210721-064451":{},"tf2-keras-cifar10-resnet50-elastic-20210721-064517":{},"tf2-keras-cifar10-vgg16-elastic-20210721-064310":{},"tf2-keras-cifar10-vgg16-elastic-20210721-064412":{},"tf2-keras-transformer-elastic-20210721-064332":{},"tf2-keras-transformer-elastic-20210721-064545":{}} "scheduler"="default"
I0721 19:31:11.641048    1186 placement_manager.go:434]  "msg"="podNodeName updated"  "launchersToDelete"=2 "new"={"tf2-keras-cifar10-inceptionv3-elastic-20210721-063448-worker-0":"gpu4","tf2-keras-cifar10-resnet50-elastic-20210721-063511-worker-0":"gpu4","tf2-keras-cifar10-resnet50-elastic-20210721-064451-worker-0":"gpu5","tf2-keras-cifar10-resnet50-elastic-20210721-064451-worker-1":"gpu5","tf2-keras-cifar10-resnet50-elastic-20210721-064517-worker-0":"gpu4","tf2-keras-cifar10-resnet50-elastic-20210721-064517-worker-1":"gpu4","tf2-keras-cifar10-vgg16-elastic-20210721-064412-worker-0":"gpu5","tf2-keras-cifar10-vgg16-elastic-20210721-064412-worker-1":"gpu5","tf2-keras-transformer-elastic-20210721-064332-worker-0":"gpu3","tf2-keras-transformer-elastic-20210721-064332-worker-1":"gpu3","tf2-keras-transformer-elastic-20210721-064545-worker-0":"gpu3","tf2-keras-transformer-elastic-20210721-064545-worker-1":"gpu3"} "old"={"tf2-keras-cifar10-resnet50-elastic-20210721-064451-worker-0":"gpu3","tf2-keras-cifar10-resnet50-elastic-20210721-064451-worker-1":"gpu3","tf2-keras-cifar10-resnet50-elastic-20210721-064517-worker-0":"gpu4","tf2-keras-cifar10-resnet50-elastic-20210721-064517-worker-1":"gpu4","tf2-keras-cifar10-vgg16-elastic-20210721-064310-worker-0":"gpu4","tf2-keras-cifar10-vgg16-elastic-20210721-064310-worker-1":"gpu4","tf2-keras-cifar10-vgg16-elastic-20210721-064412-worker-0":"gpu5","tf2-keras-cifar10-vgg16-elastic-20210721-064412-worker-1":"gpu5","tf2-keras-transformer-elastic-20210721-064332-worker-0":"gpu3","tf2-keras-transformer-elastic-20210721-064332-worker-1":"gpu3","tf2-keras-transformer-elastic-20210721-064545-worker-0":"gpu5","tf2-keras-transformer-elastic-20210721-064545-worker-1":"gpu5"} "scheduler"="default" "workersToDelete"=4
I0721 19:31:11.641309    1186 placement_manager.go:451]  "msg"="Deleting pod that need migration"  "podName"="tf2-keras-transformer-elastic-20210721-064545-worker-0" "scheduler"="default"
I0721 19:31:11.664776    1186 placement_manager.go:451]  "msg"="Deleting pod that need migration"  "podName"="tf2-keras-transformer-elastic-20210721-064545-worker-1" "scheduler"="default"
I0721 19:31:11.669245    1186 placement_manager.go:451]  "msg"="Deleting pod that need migration"  "podName"="tf2-keras-transformer-elastic-20210721-064545-launcher" "scheduler"="default"
I0721 19:31:11.674785    1186 placement_manager.go:451]  "msg"="Deleting pod that need migration"  "podName"="tf2-keras-cifar10-resnet50-elastic-20210721-064451-worker-0" "scheduler"="default"
I0721 19:31:11.681329    1186 placement_manager.go:451]  "msg"="Deleting pod that need migration"  "podName"="tf2-keras-cifar10-resnet50-elastic-20210721-064451-worker-1" "scheduler"="default"
I0721 19:31:11.690113    1186 placement_manager.go:451]  "msg"="Deleting pod that need migration"  "podName"="tf2-keras-cifar10-resnet50-elastic-20210721-064451-launcher" "scheduler"="default"
I0721 19:31:11.695806    1186 placement_manager.go:183]  "msg"="Finished job placements adjustment"  "scheduler"="default"
I0721 19:31:11.696073    1186 scheduler.go:182]  "msg"="Finished resched"  "scheduler"="default"
I0721 19:31:11.826385    1186 placement_manager.go:147]  "msg"="Adding toleration to pod"  "podName"="tf2-keras-cifar10-inceptionv3-elastic-20210721-063448-worker-0" "scheduler"="default" "toleration"={"key":"celeste/hostname","operator":"Equal","value":"gpu4","effect":"NoExecute"}
I0721 19:31:12.028112    1186 placement_manager.go:147]  "msg"="Adding toleration to pod"  "podName"="tf2-keras-cifar10-resnet50-elastic-20210721-063511-worker-0" "scheduler"="default" "toleration"={"key":"celeste/hostname","operator":"Equal","value":"gpu4","effect":"NoExecute"}
I0721 19:31:12.446845    1186 placement_manager.go:147]  "msg"="Adding toleration to pod"  "podName"="tf2-keras-cifar10-inceptionv3-elastic-20210721-063448-launcher" "scheduler"="default" "toleration"={"key":"celeste/hostname","operator":"Exists","effect":"NoExecute"}
I0721 19:31:12.854367    1186 placement_manager.go:147]  "msg"="Adding toleration to pod"  "podName"="tf2-keras-cifar10-resnet50-elastic-20210721-063511-launcher" "scheduler"="default" "toleration"={"key":"celeste/hostname","operator":"Exists","effect":"NoExecute"}
I0721 19:31:16.578057    1186 scheduler.go:565]  "msg"="Priority promoted to training job"  "job"="tf2-keras-cifar10-resnet50-elastic-20210721-063511" "priority"=0 "scheduler"="default"
I0721 19:31:16.578151    1186 scheduler.go:565]  "msg"="Priority promoted to training job"  "job"="tf2-keras-cifar10-inceptionv3-elastic-20210721-063448" "priority"=0 "scheduler"="default"
I0721 19:31:16.578187    1186 scheduler.go:573]  "msg"="Priority changed"  "scheduler"="default"
I0721 19:31:16.578307    1186 scheduler.go:135]  "msg"="Received resched event, may be blocked because of rate limit"  "blockedUntil"="2021-07-21T19:33:11.696352887+08:00" "lastResched"="2021-07-21T19:31:11.696352887+08:00" "received"="2021-07-21T19:31:16.578195246+08:00" "scheduler"="default"
I0721 19:31:24.607143    1186 placement_manager.go:147]  "msg"="Adding toleration to pod"  "podName"="tf2-keras-cifar10-resnet50-elastic-20210721-064451-launcher" "scheduler"="default" "toleration"={"key":"celeste/hostname","operator":"Exists","effect":"NoExecute"}
I0721 19:31:24.648814    1186 placement_manager.go:147]  "msg"="Adding toleration to pod"  "podName"="tf2-keras-transformer-elastic-20210721-064545-launcher" "scheduler"="default" "toleration"={"key":"celeste/hostname","operator":"Exists","effect":"NoExecute"}
I0721 19:31:29.266180    1186 placement_manager.go:147]  "msg"="Adding toleration to pod"  "podName"="tf2-keras-cifar10-resnet50-elastic-20210721-064451-worker-0" "scheduler"="default" "toleration"={"key":"celeste/hostname","operator":"Equal","value":"gpu5","effect":"NoExecute"}
I0721 19:31:29.290096    1186 placement_manager.go:147]  "msg"="Adding toleration to pod"  "podName"="tf2-keras-cifar10-resnet50-elastic-20210721-064451-worker-1" "scheduler"="default" "toleration"={"key":"celeste/hostname","operator":"Equal","value":"gpu5","effect":"NoExecute"}
I0721 19:31:30.875123    1186 placement_manager.go:147]  "msg"="Adding toleration to pod"  "podName"="tf2-keras-transformer-elastic-20210721-064545-worker-0" "scheduler"="default" "toleration"={"key":"celeste/hostname","operator":"Equal","value":"gpu3","effect":"NoExecute"}
I0721 19:31:31.675982    1186 placement_manager.go:147]  "msg"="Adding toleration to pod"  "podName"="tf2-keras-transformer-elastic-20210721-064545-worker-1" "scheduler"="default" "toleration"={"key":"celeste/hostname","operator":"Equal","value":"gpu3","effect":"NoExecute"}
I0721 19:33:11.696427    1186 scheduler.go:159]  "msg"="Started resched"  "scheduler"="default"
I0721 19:33:11.696499    1186 scheduler.go:193]  "msg"="Updating all jobs info"  "scheduler"="default"
I0721 19:33:11.708194    1186 elastic_tiresias.go:160]  "msg"="Finished scheduling"  "algorithm"="ElasticTiresias" "compactionThreshold"=4 "freeGpu"=0 "promoteKnob"=4 "queueNum"=2 "result"={"tf2-keras-cifar10-inceptionv3-elastic-20210721-063448":2,"tf2-keras-cifar10-inceptionv3-elastic-20210721-063539":0,"tf2-keras-cifar10-inceptionv3-elastic-20210721-063756":0,"tf2-keras-cifar10-inceptionv3-elastic-20210721-063900":0,"tf2-keras-cifar10-inceptionv3-elastic-20210721-064117":0,"tf2-keras-cifar10-inceptionv3-elastic-20210721-064215":0,"tf2-keras-cifar10-resnet50-elastic-20210721-063511":2,"tf2-keras-cifar10-resnet50-elastic-20210721-064451":2,"tf2-keras-cifar10-resnet50-elastic-20210721-064517":2,"tf2-keras-cifar10-vgg16-elastic-20210721-063631":0,"tf2-keras-cifar10-vgg16-elastic-20210721-064310":0,"tf2-keras-cifar10-vgg16-elastic-20210721-064412":2,"tf2-keras-transformer-elastic-20210721-063654":0,"tf2-keras-transformer-elastic-20210721-063721":0,"tf2-keras-transformer-elastic-20210721-063927":0,"tf2-keras-transformer-elastic-20210721-064152":0,"tf2-keras-transformer-elastic-20210721-064332":2,"tf2-keras-transformer-elastic-20210721-064545":0} "scheduler"="default" "thresholds"=
I0721 19:33:11.708518    1186 scheduler.go:384]  "msg"="Trying to delete multiple training jobs"  "jobs"=["tf2-keras-transformer-elastic-20210721-064545"] "scheduler"="default"
I0721 19:33:11.719277    1186 scheduler.go:342]  "msg"="Trying to scale multiple training jobs"  "jobs"=[] "scheduler"="default"
I0721 19:33:11.719529    1186 scheduler.go:292]  "msg"="Trying to start multiple training jobs"  "jobs"=[] "scheduler"="default"
I0721 19:33:11.719780    1186 scheduler.go:342]  "msg"="Trying to scale multiple training jobs"  "jobs"=["tf2-keras-cifar10-inceptionv3-elastic-20210721-063448","tf2-keras-cifar10-resnet50-elastic-20210721-063511"] "scheduler"="default"
I0721 19:33:11.763775    1186 placement_manager.go:166]  "msg"="Started job placements adjustment"  "scheduler"="default"
I0721 19:33:11.763896    1186 placement_manager.go:192]  "msg"="Releasing slots"  "jobs"={"tf2-keras-cifar10-inceptionv3-elastic-20210721-063448":{},"tf2-keras-cifar10-resnet50-elastic-20210721-063511":{},"tf2-keras-cifar10-resnet50-elastic-20210721-064451":{},"tf2-keras-cifar10-resnet50-elastic-20210721-064517":{},"tf2-keras-cifar10-vgg16-elastic-20210721-064412":{},"tf2-keras-transformer-elastic-20210721-064332":{},"tf2-keras-transformer-elastic-20210721-064545":{}} "nodes"={"gpu3":{},"gpu4":{},"gpu5":{}} "scheduler"="default"
I0721 19:33:11.763962    1186 placement_manager.go:250]  "msg"="Released slots"  "jobs"={"tf2-keras-cifar10-inceptionv3-elastic-20210721-063448":{},"tf2-keras-cifar10-resnet50-elastic-20210721-063511":{},"tf2-keras-cifar10-resnet50-elastic-20210721-064451":{},"tf2-keras-cifar10-resnet50-elastic-20210721-064517":{},"tf2-keras-cifar10-vgg16-elastic-20210721-064412":{},"tf2-keras-transformer-elastic-20210721-064332":{},"tf2-keras-transformer-elastic-20210721-064545":{}} "nodes"={"gpu3":{},"gpu4":{},"gpu5":{}} "scheduler"="default"
I0721 19:33:11.764445    1186 placement_manager.go:305]  "msg"="Found best-fit"  "crossNode"=0 "nodes"=[{},{},{}] "requests"=[{},{},{},{},{},{},{},{},{},{},{},{},{},{},{},{},{},{},{},{},{},{},{},{},{},{},{},{},{},{},{},{},{},{},{},{}] "scheduler"="default"
I0721 19:33:11.764796    1186 placement_manager.go:339]  "msg"="nodeStates updated"  "new"={"gpu3":{},"gpu4":{},"gpu5":{}} "old"={"gpu3":{},"gpu4":{},"gpu5":{}} "scheduler"="default" "score"=6
I0721 19:33:11.765225    1186 placement_manager.go:387]  "msg"="jobStates updated"  "new"={"tf2-keras-cifar10-inceptionv3-elastic-20210721-063448":{},"tf2-keras-cifar10-resnet50-elastic-20210721-063511":{},"tf2-keras-cifar10-resnet50-elastic-20210721-064451":{},"tf2-keras-cifar10-resnet50-elastic-20210721-064517":{},"tf2-keras-cifar10-vgg16-elastic-20210721-064412":{},"tf2-keras-transformer-elastic-20210721-064332":{}} "old"={"tf2-keras-cifar10-inceptionv3-elastic-20210721-063448":{},"tf2-keras-cifar10-resnet50-elastic-20210721-063511":{},"tf2-keras-cifar10-resnet50-elastic-20210721-064451":{},"tf2-keras-cifar10-resnet50-elastic-20210721-064517":{},"tf2-keras-cifar10-vgg16-elastic-20210721-064412":{},"tf2-keras-transformer-elastic-20210721-064332":{},"tf2-keras-transformer-elastic-20210721-064545":{}} "scheduler"="default"
I0721 19:33:11.765646    1186 placement_manager.go:434]  "msg"="podNodeName updated"  "launchersToDelete"=1 "new"={"tf2-keras-cifar10-inceptionv3-elastic-20210721-063448-worker-0":"gpu3","tf2-keras-cifar10-inceptionv3-elastic-20210721-063448-worker-1":"gpu3","tf2-keras-cifar10-resnet50-elastic-20210721-063511-worker-0":"gpu5","tf2-keras-cifar10-resnet50-elastic-20210721-063511-worker-1":"gpu5","tf2-keras-cifar10-resnet50-elastic-20210721-064451-worker-0":"gpu4","tf2-keras-cifar10-resnet50-elastic-20210721-064451-worker-1":"gpu4","tf2-keras-cifar10-resnet50-elastic-20210721-064517-worker-0":"gpu4","tf2-keras-cifar10-resnet50-elastic-20210721-064517-worker-1":"gpu4","tf2-keras-cifar10-vgg16-elastic-20210721-064412-worker-0":"gpu5","tf2-keras-cifar10-vgg16-elastic-20210721-064412-worker-1":"gpu5","tf2-keras-transformer-elastic-20210721-064332-worker-0":"gpu3","tf2-keras-transformer-elastic-20210721-064332-worker-1":"gpu3"} "old"={"tf2-keras-cifar10-inceptionv3-elastic-20210721-063448-worker-0":"gpu4","tf2-keras-cifar10-resnet50-elastic-20210721-063511-worker-0":"gpu4","tf2-keras-cifar10-resnet50-elastic-20210721-064451-worker-0":"gpu5","tf2-keras-cifar10-resnet50-elastic-20210721-064451-worker-1":"gpu5","tf2-keras-cifar10-resnet50-elastic-20210721-064517-worker-0":"gpu4","tf2-keras-cifar10-resnet50-elastic-20210721-064517-worker-1":"gpu4","tf2-keras-cifar10-vgg16-elastic-20210721-064412-worker-0":"gpu5","tf2-keras-cifar10-vgg16-elastic-20210721-064412-worker-1":"gpu5","tf2-keras-transformer-elastic-20210721-064332-worker-0":"gpu3","tf2-keras-transformer-elastic-20210721-064332-worker-1":"gpu3","tf2-keras-transformer-elastic-20210721-064545-worker-0":"gpu3","tf2-keras-transformer-elastic-20210721-064545-worker-1":"gpu3"} "scheduler"="default" "workersToDelete"=4
I0721 19:33:11.765997    1186 placement_manager.go:451]  "msg"="Deleting pod that need migration"  "podName"="tf2-keras-cifar10-resnet50-elastic-20210721-064451-worker-0" "scheduler"="default"
I0721 19:33:11.770238    1186 placement_manager.go:451]  "msg"="Deleting pod that need migration"  "podName"="tf2-keras-cifar10-resnet50-elastic-20210721-064451-worker-1" "scheduler"="default"
I0721 19:33:11.775357    1186 placement_manager.go:451]  "msg"="Deleting pod that need migration"  "podName"="tf2-keras-cifar10-resnet50-elastic-20210721-064451-launcher" "scheduler"="default"
I0721 19:33:11.783345    1186 placement_manager.go:451]  "msg"="Deleting pod that need migration"  "podName"="tf2-keras-cifar10-inceptionv3-elastic-20210721-063448-worker-0" "scheduler"="default"
I0721 19:33:11.785187    1186 placement_manager.go:147]  "msg"="Adding toleration to pod"  "podName"="tf2-keras-cifar10-inceptionv3-elastic-20210721-063448-worker-1" "scheduler"="default" "toleration"={"key":"celeste/hostname","operator":"Equal","value":"gpu3","effect":"NoExecute"}
I0721 19:33:11.796100    1186 placement_manager.go:451]  "msg"="Deleting pod that need migration"  "podName"="tf2-keras-cifar10-resnet50-elastic-20210721-063511-worker-0" "scheduler"="default"
I0721 19:33:11.801188    1186 placement_manager.go:183]  "msg"="Finished job placements adjustment"  "scheduler"="default"
I0721 19:33:11.801523    1186 scheduler.go:182]  "msg"="Finished resched"  "scheduler"="default"
I0721 19:33:11.820384    1186 placement_manager.go:147]  "msg"="Adding toleration to pod"  "podName"="tf2-keras-cifar10-resnet50-elastic-20210721-063511-worker-1" "scheduler"="default" "toleration"={"key":"celeste/hostname","operator":"Equal","value":"gpu5","effect":"NoExecute"}
I0721 19:33:18.796755    1186 placement_manager.go:147]  "msg"="Adding toleration to pod"  "podName"="tf2-keras-cifar10-resnet50-elastic-20210721-063511-worker-0" "scheduler"="default" "toleration"={"key":"celeste/hostname","operator":"Equal","value":"gpu5","effect":"NoExecute"}
I0721 19:33:18.828964    1186 placement_manager.go:147]  "msg"="Adding toleration to pod"  "podName"="tf2-keras-cifar10-inceptionv3-elastic-20210721-063448-worker-0" "scheduler"="default" "toleration"={"key":"celeste/hostname","operator":"Equal","value":"gpu3","effect":"NoExecute"}
I0721 19:33:21.194604    1186 placement_manager.go:147]  "msg"="Adding toleration to pod"  "podName"="tf2-keras-cifar10-resnet50-elastic-20210721-064451-launcher" "scheduler"="default" "toleration"={"key":"celeste/hostname","operator":"Exists","effect":"NoExecute"}
I0721 19:33:22.380482    1186 placement_manager.go:147]  "msg"="Adding toleration to pod"  "podName"="tf2-keras-cifar10-resnet50-elastic-20210721-064451-worker-0" "scheduler"="default" "toleration"={"key":"celeste/hostname","operator":"Equal","value":"gpu4","effect":"NoExecute"}
I0721 19:33:23.181020    1186 placement_manager.go:147]  "msg"="Adding toleration to pod"  "podName"="tf2-keras-cifar10-resnet50-elastic-20210721-064451-worker-1" "scheduler"="default" "toleration"={"key":"celeste/hostname","operator":"Equal","value":"gpu4","effect":"NoExecute"}
I0721 19:34:41.326464    1186 scheduler.go:474]  "msg"="Training job completed"  "elaspedTotalSeconds"=3023.748444878 "gpuTotalSeconds"=1530.050635072 "job"="tf2-keras-cifar10-vgg16-elastic-20210721-064412" "ranTotalSeconds"=765.025317536 "scheduler"="default" "waitedTotalSeconds"=2258.723127342
I0721 19:34:41.326609    1186 scheduler.go:135]  "msg"="Received resched event, may be blocked because of rate limit"  "blockedUntil"="2021-07-21T19:35:11.801830739+08:00" "lastResched"="2021-07-21T19:33:11.801830739+08:00" "received"="2021-07-21T19:34:41.326520739+08:00" "scheduler"="default"
I0721 19:34:51.584835    1186 scheduler.go:559]  "msg"="Priority demoted to training job"  "job"="tf2-keras-transformer-elastic-20210721-064332" "priority"=1 "scheduler"="default"
I0721 19:34:51.584922    1186 scheduler.go:573]  "msg"="Priority changed"  "scheduler"="default"
I0721 19:35:11.801880    1186 scheduler.go:159]  "msg"="Started resched"  "scheduler"="default"
I0721 19:35:11.801927    1186 scheduler.go:193]  "msg"="Updating all jobs info"  "scheduler"="default"
I0721 19:35:11.811966    1186 elastic_tiresias.go:160]  "msg"="Finished scheduling"  "algorithm"="ElasticTiresias" "compactionThreshold"=4 "freeGpu"=0 "promoteKnob"=4 "queueNum"=2 "result"={"tf2-keras-cifar10-inceptionv3-elastic-20210721-063448":2,"tf2-keras-cifar10-inceptionv3-elastic-20210721-063539":1,"tf2-keras-cifar10-inceptionv3-elastic-20210721-063756":0,"tf2-keras-cifar10-inceptionv3-elastic-20210721-063900":0,"tf2-keras-cifar10-inceptionv3-elastic-20210721-064117":0,"tf2-keras-cifar10-inceptionv3-elastic-20210721-064215":0,"tf2-keras-cifar10-resnet50-elastic-20210721-063511":2,"tf2-keras-cifar10-resnet50-elastic-20210721-064451":2,"tf2-keras-cifar10-resnet50-elastic-20210721-064517":2,"tf2-keras-cifar10-vgg16-elastic-20210721-063631":1,"tf2-keras-cifar10-vgg16-elastic-20210721-064310":0,"tf2-keras-transformer-elastic-20210721-063654":0,"tf2-keras-transformer-elastic-20210721-063721":0,"tf2-keras-transformer-elastic-20210721-063927":0,"tf2-keras-transformer-elastic-20210721-064152":0,"tf2-keras-transformer-elastic-20210721-064332":0,"tf2-keras-transformer-elastic-20210721-064545":2} "scheduler"="default" "thresholds"=
I0721 19:35:11.812348    1186 scheduler.go:384]  "msg"="Trying to delete multiple training jobs"  "jobs"=["tf2-keras-transformer-elastic-20210721-064332"] "scheduler"="default"
I0721 19:35:11.821923    1186 scheduler.go:342]  "msg"="Trying to scale multiple training jobs"  "jobs"=[] "scheduler"="default"
I0721 19:35:11.822227    1186 scheduler.go:292]  "msg"="Trying to start multiple training jobs"  "jobs"=["tf2-keras-cifar10-vgg16-elastic-20210721-063631","tf2-keras-transformer-elastic-20210721-064545","tf2-keras-cifar10-inceptionv3-elastic-20210721-063539"] "scheduler"="default"
I0721 19:35:11.864436    1186 scheduler.go:342]  "msg"="Trying to scale multiple training jobs"  "jobs"=[] "scheduler"="default"
I0721 19:35:11.866940    1186 placement_manager.go:166]  "msg"="Started job placements adjustment"  "scheduler"="default"
I0721 19:35:11.866986    1186 placement_manager.go:192]  "msg"="Releasing slots"  "jobs"={"tf2-keras-cifar10-inceptionv3-elastic-20210721-063448":{},"tf2-keras-cifar10-resnet50-elastic-20210721-063511":{},"tf2-keras-cifar10-resnet50-elastic-20210721-064451":{},"tf2-keras-cifar10-resnet50-elastic-20210721-064517":{},"tf2-keras-cifar10-vgg16-elastic-20210721-064412":{},"tf2-keras-transformer-elastic-20210721-064332":{}} "nodes"={"gpu3":{},"gpu4":{},"gpu5":{}} "scheduler"="default"
I0721 19:35:11.867033    1186 placement_manager.go:250]  "msg"="Released slots"  "jobs"={"tf2-keras-cifar10-inceptionv3-elastic-20210721-063448":{},"tf2-keras-cifar10-resnet50-elastic-20210721-063511":{},"tf2-keras-cifar10-resnet50-elastic-20210721-064451":{},"tf2-keras-cifar10-resnet50-elastic-20210721-064517":{},"tf2-keras-cifar10-vgg16-elastic-20210721-064412":{},"tf2-keras-transformer-elastic-20210721-064332":{}} "nodes"={"gpu3":{},"gpu4":{},"gpu5":{}} "scheduler"="default"
I0721 19:35:11.867420    1186 placement_manager.go:305]  "msg"="Found best-fit"  "crossNode"=0 "nodes"=[{},{},{}] "requests"=[{},{},{},{},{},{},{},{},{},{},{},{},{},{},{},{},{},{},{},{},{},{},{},{},{},{},{},{},{},{},{},{},{},{}] "scheduler"="default"
I0721 19:35:11.867639    1186 placement_manager.go:339]  "msg"="nodeStates updated"  "new"={"gpu3":{},"gpu4":{},"gpu5":{}} "old"={"gpu3":{},"gpu4":{},"gpu5":{}} "scheduler"="default" "score"=6
I0721 19:35:11.867879    1186 placement_manager.go:387]  "msg"="jobStates updated"  "new"={"tf2-keras-cifar10-inceptionv3-elastic-20210721-063448":{},"tf2-keras-cifar10-inceptionv3-elastic-20210721-063539":{},"tf2-keras-cifar10-resnet50-elastic-20210721-063511":{},"tf2-keras-cifar10-resnet50-elastic-20210721-064451":{},"tf2-keras-cifar10-resnet50-elastic-20210721-064517":{},"tf2-keras-cifar10-vgg16-elastic-20210721-063631":{},"tf2-keras-transformer-elastic-20210721-064545":{}} "old"={"tf2-keras-cifar10-inceptionv3-elastic-20210721-063448":{},"tf2-keras-cifar10-resnet50-elastic-20210721-063511":{},"tf2-keras-cifar10-resnet50-elastic-20210721-064451":{},"tf2-keras-cifar10-resnet50-elastic-20210721-064517":{},"tf2-keras-cifar10-vgg16-elastic-20210721-064412":{},"tf2-keras-transformer-elastic-20210721-064332":{}} "scheduler"="default"
I0721 19:35:11.868155    1186 placement_manager.go:434]  "msg"="podNodeName updated"  "launchersToDelete"=1 "new"={"tf2-keras-cifar10-inceptionv3-elastic-20210721-063448-worker-0":"gpu3","tf2-keras-cifar10-inceptionv3-elastic-20210721-063448-worker-1":"gpu3","tf2-keras-cifar10-inceptionv3-elastic-20210721-063539-worker-0":"gpu3","tf2-keras-cifar10-resnet50-elastic-20210721-063511-worker-0":"gpu5","tf2-keras-cifar10-resnet50-elastic-20210721-063511-worker-1":"gpu5","tf2-keras-cifar10-resnet50-elastic-20210721-064451-worker-0":"gpu5","tf2-keras-cifar10-resnet50-elastic-20210721-064451-worker-1":"gpu5","tf2-keras-cifar10-resnet50-elastic-20210721-064517-worker-0":"gpu4","tf2-keras-cifar10-resnet50-elastic-20210721-064517-worker-1":"gpu4","tf2-keras-cifar10-vgg16-elastic-20210721-063631-worker-0":"gpu3","tf2-keras-transformer-elastic-20210721-064545-worker-0":"gpu4","tf2-keras-transformer-elastic-20210721-064545-worker-1":"gpu4"} "old"={"tf2-keras-cifar10-inceptionv3-elastic-20210721-063448-worker-0":"gpu3","tf2-keras-cifar10-inceptionv3-elastic-20210721-063448-worker-1":"gpu3","tf2-keras-cifar10-resnet50-elastic-20210721-063511-worker-0":"gpu5","tf2-keras-cifar10-resnet50-elastic-20210721-063511-worker-1":"gpu5","tf2-keras-cifar10-resnet50-elastic-20210721-064451-worker-0":"gpu4","tf2-keras-cifar10-resnet50-elastic-20210721-064451-worker-1":"gpu4","tf2-keras-cifar10-resnet50-elastic-20210721-064517-worker-0":"gpu4","tf2-keras-cifar10-resnet50-elastic-20210721-064517-worker-1":"gpu4","tf2-keras-cifar10-vgg16-elastic-20210721-064412-worker-0":"gpu5","tf2-keras-cifar10-vgg16-elastic-20210721-064412-worker-1":"gpu5","tf2-keras-transformer-elastic-20210721-064332-worker-0":"gpu3","tf2-keras-transformer-elastic-20210721-064332-worker-1":"gpu3"} "scheduler"="default" "workersToDelete"=2
I0721 19:35:11.868392    1186 placement_manager.go:451]  "msg"="Deleting pod that need migration"  "podName"="tf2-keras-cifar10-resnet50-elastic-20210721-064451-worker-0" "scheduler"="default"
I0721 19:35:11.872626    1186 placement_manager.go:451]  "msg"="Deleting pod that need migration"  "podName"="tf2-keras-cifar10-resnet50-elastic-20210721-064451-worker-1" "scheduler"="default"
I0721 19:35:11.877544    1186 placement_manager.go:451]  "msg"="Deleting pod that need migration"  "podName"="tf2-keras-cifar10-resnet50-elastic-20210721-064451-launcher" "scheduler"="default"
I0721 19:35:11.882371    1186 placement_manager.go:183]  "msg"="Finished job placements adjustment"  "scheduler"="default"
I0721 19:35:11.882587    1186 scheduler.go:182]  "msg"="Finished resched"  "scheduler"="default"
I0721 19:35:12.255061    1186 placement_manager.go:147]  "msg"="Adding toleration to pod"  "podName"="tf2-keras-cifar10-vgg16-elastic-20210721-063631-worker-0" "scheduler"="default" "toleration"={"key":"celeste/hostname","operator":"Equal","value":"gpu3","effect":"NoExecute"}
I0721 19:35:12.453680    1186 placement_manager.go:147]  "msg"="Adding toleration to pod"  "podName"="tf2-keras-transformer-elastic-20210721-064545-worker-0" "scheduler"="default" "toleration"={"key":"celeste/hostname","operator":"Equal","value":"gpu4","effect":"NoExecute"}
I0721 19:35:12.653750    1186 placement_manager.go:147]  "msg"="Adding toleration to pod"  "podName"="tf2-keras-cifar10-vgg16-elastic-20210721-063631-launcher" "scheduler"="default" "toleration"={"key":"celeste/hostname","operator":"Exists","effect":"NoExecute"}
I0721 19:35:12.855944    1186 placement_manager.go:147]  "msg"="Adding toleration to pod"  "podName"="tf2-keras-transformer-elastic-20210721-064545-worker-1" "scheduler"="default" "toleration"={"key":"celeste/hostname","operator":"Equal","value":"gpu4","effect":"NoExecute"}
I0721 19:35:13.276177    1186 placement_manager.go:147]  "msg"="Adding toleration to pod"  "podName"="tf2-keras-transformer-elastic-20210721-064545-launcher" "scheduler"="default" "toleration"={"key":"celeste/hostname","operator":"Exists","effect":"NoExecute"}
I0721 19:35:14.260188    1186 placement_manager.go:147]  "msg"="Adding toleration to pod"  "podName"="tf2-keras-cifar10-inceptionv3-elastic-20210721-063539-worker-0" "scheduler"="default" "toleration"={"key":"celeste/hostname","operator":"Equal","value":"gpu3","effect":"NoExecute"}
I0721 19:35:14.474468    1186 placement_manager.go:147]  "msg"="Adding toleration to pod"  "podName"="tf2-keras-cifar10-inceptionv3-elastic-20210721-063539-launcher" "scheduler"="default" "toleration"={"key":"celeste/hostname","operator":"Exists","effect":"NoExecute"}
I0721 19:35:16.585640    1186 scheduler.go:565]  "msg"="Priority promoted to training job"  "job"="tf2-keras-cifar10-vgg16-elastic-20210721-063631" "priority"=0 "scheduler"="default"
I0721 19:35:16.585759    1186 scheduler.go:565]  "msg"="Priority promoted to training job"  "job"="tf2-keras-cifar10-inceptionv3-elastic-20210721-063539" "priority"=0 "scheduler"="default"
I0721 19:35:16.585838    1186 scheduler.go:573]  "msg"="Priority changed"  "scheduler"="default"
I0721 19:35:16.585951    1186 scheduler.go:135]  "msg"="Received resched event, may be blocked because of rate limit"  "blockedUntil"="2021-07-21T19:37:11.882780864+08:00" "lastResched"="2021-07-21T19:35:11.882780864+08:00" "received"="2021-07-21T19:35:16.585853829+08:00" "scheduler"="default"
I0721 19:35:21.670953    1186 placement_manager.go:147]  "msg"="Adding toleration to pod"  "podName"="tf2-keras-cifar10-resnet50-elastic-20210721-064451-worker-1" "scheduler"="default" "toleration"={"key":"celeste/hostname","operator":"Equal","value":"gpu5","effect":"NoExecute"}
I0721 19:35:22.695665    1186 placement_manager.go:147]  "msg"="Adding toleration to pod"  "podName"="tf2-keras-cifar10-resnet50-elastic-20210721-064451-worker-0" "scheduler"="default" "toleration"={"key":"celeste/hostname","operator":"Equal","value":"gpu5","effect":"NoExecute"}
I0721 19:35:29.745748    1186 placement_manager.go:147]  "msg"="Adding toleration to pod"  "podName"="tf2-keras-cifar10-resnet50-elastic-20210721-064451-launcher" "scheduler"="default" "toleration"={"key":"celeste/hostname","operator":"Exists","effect":"NoExecute"}
I0721 19:37:11.882848    1186 scheduler.go:159]  "msg"="Started resched"  "scheduler"="default"
I0721 19:37:11.882908    1186 scheduler.go:193]  "msg"="Updating all jobs info"  "scheduler"="default"
I0721 19:37:11.891405    1186 elastic_tiresias.go:160]  "msg"="Finished scheduling"  "algorithm"="ElasticTiresias" "compactionThreshold"=4 "freeGpu"=0 "promoteKnob"=4 "queueNum"=2 "result"={"tf2-keras-cifar10-inceptionv3-elastic-20210721-063448":2,"tf2-keras-cifar10-inceptionv3-elastic-20210721-063539":2,"tf2-keras-cifar10-inceptionv3-elastic-20210721-063756":0,"tf2-keras-cifar10-inceptionv3-elastic-20210721-063900":0,"tf2-keras-cifar10-inceptionv3-elastic-20210721-064117":0,"tf2-keras-cifar10-inceptionv3-elastic-20210721-064215":0,"tf2-keras-cifar10-resnet50-elastic-20210721-063511":2,"tf2-keras-cifar10-resnet50-elastic-20210721-064451":2,"tf2-keras-cifar10-resnet50-elastic-20210721-064517":2,"tf2-keras-cifar10-vgg16-elastic-20210721-063631":2,"tf2-keras-cifar10-vgg16-elastic-20210721-064310":0,"tf2-keras-transformer-elastic-20210721-063654":0,"tf2-keras-transformer-elastic-20210721-063721":0,"tf2-keras-transformer-elastic-20210721-063927":0,"tf2-keras-transformer-elastic-20210721-064152":0,"tf2-keras-transformer-elastic-20210721-064332":0,"tf2-keras-transformer-elastic-20210721-064545":0} "scheduler"="default" "thresholds"=
I0721 19:37:11.891680    1186 scheduler.go:384]  "msg"="Trying to delete multiple training jobs"  "jobs"=["tf2-keras-transformer-elastic-20210721-064545"] "scheduler"="default"
I0721 19:37:11.903344    1186 scheduler.go:342]  "msg"="Trying to scale multiple training jobs"  "jobs"=[] "scheduler"="default"
I0721 19:37:11.903657    1186 scheduler.go:292]  "msg"="Trying to start multiple training jobs"  "jobs"=[] "scheduler"="default"
I0721 19:37:11.903949    1186 scheduler.go:342]  "msg"="Trying to scale multiple training jobs"  "jobs"=["tf2-keras-cifar10-inceptionv3-elastic-20210721-063539","tf2-keras-cifar10-vgg16-elastic-20210721-063631"] "scheduler"="default"
I0721 19:37:11.946099    1186 placement_manager.go:166]  "msg"="Started job placements adjustment"  "scheduler"="default"
I0721 19:37:11.946184    1186 placement_manager.go:192]  "msg"="Releasing slots"  "jobs"={"tf2-keras-cifar10-inceptionv3-elastic-20210721-063448":{},"tf2-keras-cifar10-inceptionv3-elastic-20210721-063539":{},"tf2-keras-cifar10-resnet50-elastic-20210721-063511":{},"tf2-keras-cifar10-resnet50-elastic-20210721-064451":{},"tf2-keras-cifar10-resnet50-elastic-20210721-064517":{},"tf2-keras-cifar10-vgg16-elastic-20210721-063631":{},"tf2-keras-transformer-elastic-20210721-064545":{}} "nodes"={"gpu3":{},"gpu4":{},"gpu5":{}} "scheduler"="default"
I0721 19:37:11.946248    1186 placement_manager.go:250]  "msg"="Released slots"  "jobs"={"tf2-keras-cifar10-inceptionv3-elastic-20210721-063448":{},"tf2-keras-cifar10-inceptionv3-elastic-20210721-063539":{},"tf2-keras-cifar10-resnet50-elastic-20210721-063511":{},"tf2-keras-cifar10-resnet50-elastic-20210721-064451":{},"tf2-keras-cifar10-resnet50-elastic-20210721-064517":{},"tf2-keras-cifar10-vgg16-elastic-20210721-063631":{},"tf2-keras-transformer-elastic-20210721-064545":{}} "nodes"={"gpu3":{},"gpu4":{},"gpu5":{}} "scheduler"="default"
I0721 19:37:11.946701    1186 placement_manager.go:305]  "msg"="Found best-fit"  "crossNode"=0 "nodes"=[{},{},{}] "requests"=[{},{},{},{},{},{},{},{},{},{},{},{},{},{},{},{},{},{},{},{},{},{},{},{},{},{},{},{},{},{},{},{},{},{}] "scheduler"="default"
I0721 19:37:11.946961    1186 placement_manager.go:339]  "msg"="nodeStates updated"  "new"={"gpu3":{},"gpu4":{},"gpu5":{}} "old"={"gpu3":{},"gpu4":{},"gpu5":{}} "scheduler"="default" "score"=6
I0721 19:37:11.947264    1186 placement_manager.go:387]  "msg"="jobStates updated"  "new"={"tf2-keras-cifar10-inceptionv3-elastic-20210721-063448":{},"tf2-keras-cifar10-inceptionv3-elastic-20210721-063539":{},"tf2-keras-cifar10-resnet50-elastic-20210721-063511":{},"tf2-keras-cifar10-resnet50-elastic-20210721-064451":{},"tf2-keras-cifar10-resnet50-elastic-20210721-064517":{},"tf2-keras-cifar10-vgg16-elastic-20210721-063631":{}} "old"={"tf2-keras-cifar10-inceptionv3-elastic-20210721-063448":{},"tf2-keras-cifar10-inceptionv3-elastic-20210721-063539":{},"tf2-keras-cifar10-resnet50-elastic-20210721-063511":{},"tf2-keras-cifar10-resnet50-elastic-20210721-064451":{},"tf2-keras-cifar10-resnet50-elastic-20210721-064517":{},"tf2-keras-cifar10-vgg16-elastic-20210721-063631":{},"tf2-keras-transformer-elastic-20210721-064545":{}} "scheduler"="default"
I0721 19:37:11.947601    1186 placement_manager.go:434]  "msg"="podNodeName updated"  "launchersToDelete"=2 "new"={"tf2-keras-cifar10-inceptionv3-elastic-20210721-063448-worker-0":"gpu5","tf2-keras-cifar10-inceptionv3-elastic-20210721-063448-worker-1":"gpu5","tf2-keras-cifar10-inceptionv3-elastic-20210721-063539-worker-0":"gpu3","tf2-keras-cifar10-inceptionv3-elastic-20210721-063539-worker-1":"gpu3","tf2-keras-cifar10-resnet50-elastic-20210721-063511-worker-0":"gpu4","tf2-keras-cifar10-resnet50-elastic-20210721-063511-worker-1":"gpu4","tf2-keras-cifar10-resnet50-elastic-20210721-064451-worker-0":"gpu5","tf2-keras-cifar10-resnet50-elastic-20210721-064451-worker-1":"gpu5","tf2-keras-cifar10-resnet50-elastic-20210721-064517-worker-0":"gpu4","tf2-keras-cifar10-resnet50-elastic-20210721-064517-worker-1":"gpu4","tf2-keras-cifar10-vgg16-elastic-20210721-063631-worker-0":"gpu3","tf2-keras-cifar10-vgg16-elastic-20210721-063631-worker-1":"gpu3"} "old"={"tf2-keras-cifar10-inceptionv3-elastic-20210721-063448-worker-0":"gpu3","tf2-keras-cifar10-inceptionv3-elastic-20210721-063448-worker-1":"gpu3","tf2-keras-cifar10-inceptionv3-elastic-20210721-063539-worker-0":"gpu3","tf2-keras-cifar10-resnet50-elastic-20210721-063511-worker-0":"gpu5","tf2-keras-cifar10-resnet50-elastic-20210721-063511-worker-1":"gpu5","tf2-keras-cifar10-resnet50-elastic-20210721-064451-worker-0":"gpu5","tf2-keras-cifar10-resnet50-elastic-20210721-064451-worker-1":"gpu5","tf2-keras-cifar10-resnet50-elastic-20210721-064517-worker-0":"gpu4","tf2-keras-cifar10-resnet50-elastic-20210721-064517-worker-1":"gpu4","tf2-keras-cifar10-vgg16-elastic-20210721-063631-worker-0":"gpu3","tf2-keras-transformer-elastic-20210721-064545-worker-0":"gpu4","tf2-keras-transformer-elastic-20210721-064545-worker-1":"gpu4"} "scheduler"="default" "workersToDelete"=4
I0721 19:37:11.947865    1186 placement_manager.go:451]  "msg"="Deleting pod that need migration"  "podName"="tf2-keras-cifar10-inceptionv3-elastic-20210721-063448-worker-0" "scheduler"="default"
I0721 19:37:11.951873    1186 placement_manager.go:451]  "msg"="Deleting pod that need migration"  "podName"="tf2-keras-cifar10-inceptionv3-elastic-20210721-063448-worker-1" "scheduler"="default"
I0721 19:37:11.955983    1186 placement_manager.go:451]  "msg"="Deleting pod that need migration"  "podName"="tf2-keras-cifar10-inceptionv3-elastic-20210721-063448-launcher" "scheduler"="default"
I0721 19:37:11.960654    1186 placement_manager.go:451]  "msg"="Deleting pod that need migration"  "podName"="tf2-keras-cifar10-resnet50-elastic-20210721-063511-worker-0" "scheduler"="default"
I0721 19:37:11.963876    1186 placement_manager.go:147]  "msg"="Adding toleration to pod"  "podName"="tf2-keras-cifar10-inceptionv3-elastic-20210721-063539-worker-1" "scheduler"="default" "toleration"={"key":"celeste/hostname","operator":"Equal","value":"gpu3","effect":"NoExecute"}
I0721 19:37:11.975039    1186 placement_manager.go:451]  "msg"="Deleting pod that need migration"  "podName"="tf2-keras-cifar10-resnet50-elastic-20210721-063511-worker-1" "scheduler"="default"
I0721 19:37:11.979833    1186 placement_manager.go:451]  "msg"="Deleting pod that need migration"  "podName"="tf2-keras-cifar10-resnet50-elastic-20210721-063511-launcher" "scheduler"="default"
I0721 19:37:11.983990    1186 placement_manager.go:183]  "msg"="Finished job placements adjustment"  "scheduler"="default"
I0721 19:37:11.984376    1186 scheduler.go:182]  "msg"="Finished resched"  "scheduler"="default"
I0721 19:37:11.986407    1186 placement_manager.go:147]  "msg"="Adding toleration to pod"  "podName"="tf2-keras-cifar10-vgg16-elastic-20210721-063631-worker-1" "scheduler"="default" "toleration"={"key":"celeste/hostname","operator":"Equal","value":"gpu3","effect":"NoExecute"}
I0721 19:37:29.498877    1186 placement_manager.go:147]  "msg"="Adding toleration to pod"  "podName"="tf2-keras-cifar10-inceptionv3-elastic-20210721-063448-worker-0" "scheduler"="default" "toleration"={"key":"celeste/hostname","operator":"Equal","value":"gpu5","effect":"NoExecute"}
I0721 19:37:29.896369    1186 placement_manager.go:147]  "msg"="Adding toleration to pod"  "podName"="tf2-keras-cifar10-inceptionv3-elastic-20210721-063448-worker-1" "scheduler"="default" "toleration"={"key":"celeste/hostname","operator":"Equal","value":"gpu5","effect":"NoExecute"}
I0721 19:37:31.183859    1186 placement_manager.go:147]  "msg"="Adding toleration to pod"  "podName"="tf2-keras-cifar10-resnet50-elastic-20210721-063511-worker-1" "scheduler"="default" "toleration"={"key":"celeste/hostname","operator":"Equal","value":"gpu4","effect":"NoExecute"}
I0721 19:37:31.982532    1186 placement_manager.go:147]  "msg"="Adding toleration to pod"  "podName"="tf2-keras-cifar10-inceptionv3-elastic-20210721-063448-launcher" "scheduler"="default" "toleration"={"key":"celeste/hostname","operator":"Exists","effect":"NoExecute"}
I0721 19:37:32.980563    1186 placement_manager.go:147]  "msg"="Adding toleration to pod"  "podName"="tf2-keras-cifar10-resnet50-elastic-20210721-063511-launcher" "scheduler"="default" "toleration"={"key":"celeste/hostname","operator":"Exists","effect":"NoExecute"}
I0721 19:37:33.802278    1186 placement_manager.go:147]  "msg"="Adding toleration to pod"  "podName"="tf2-keras-cifar10-resnet50-elastic-20210721-063511-worker-0" "scheduler"="default" "toleration"={"key":"celeste/hostname","operator":"Equal","value":"gpu4","effect":"NoExecute"}
I0721 19:38:27.444946    1186 scheduler.go:474]  "msg"="Training job completed"  "elaspedTotalSeconds"=3188.77683121 "gpuTotalSeconds"=1750.057176478 "job"="tf2-keras-cifar10-resnet50-elastic-20210721-064517" "ranTotalSeconds"=875.028588239 "scheduler"="default" "waitedTotalSeconds"=2313.748242971
I0721 19:38:27.445087    1186 scheduler.go:135]  "msg"="Received resched event, may be blocked because of rate limit"  "blockedUntil"="2021-07-21T19:39:11.984622111+08:00" "lastResched"="2021-07-21T19:37:11.984622111+08:00" "received"="2021-07-21T19:38:27.4449797+08:00" "scheduler"="default"
I0721 19:38:51.592176    1186 scheduler.go:559]  "msg"="Priority demoted to training job"  "job"="tf2-keras-cifar10-resnet50-elastic-20210721-064451" "priority"=1 "scheduler"="default"
I0721 19:38:51.592265    1186 scheduler.go:573]  "msg"="Priority changed"  "scheduler"="default"
I0721 19:39:11.984668    1186 scheduler.go:159]  "msg"="Started resched"  "scheduler"="default"
I0721 19:39:11.984707    1186 scheduler.go:193]  "msg"="Updating all jobs info"  "scheduler"="default"
I0721 19:39:11.993969    1186 elastic_tiresias.go:160]  "msg"="Finished scheduling"  "algorithm"="ElasticTiresias" "compactionThreshold"=4 "freeGpu"=0 "promoteKnob"=4 "queueNum"=2 "result"={"tf2-keras-cifar10-inceptionv3-elastic-20210721-063448":2,"tf2-keras-cifar10-inceptionv3-elastic-20210721-063539":3,"tf2-keras-cifar10-inceptionv3-elastic-20210721-063756":0,"tf2-keras-cifar10-inceptionv3-elastic-20210721-063900":0,"tf2-keras-cifar10-inceptionv3-elastic-20210721-064117":0,"tf2-keras-cifar10-inceptionv3-elastic-20210721-064215":0,"tf2-keras-cifar10-resnet50-elastic-20210721-063511":2,"tf2-keras-cifar10-resnet50-elastic-20210721-064451":0,"tf2-keras-cifar10-vgg16-elastic-20210721-063631":2,"tf2-keras-cifar10-vgg16-elastic-20210721-064310":0,"tf2-keras-transformer-elastic-20210721-063654":1,"tf2-keras-transformer-elastic-20210721-063721":0,"tf2-keras-transformer-elastic-20210721-063927":0,"tf2-keras-transformer-elastic-20210721-064152":0,"tf2-keras-transformer-elastic-20210721-064332":0,"tf2-keras-transformer-elastic-20210721-064545":2} "scheduler"="default" "thresholds"=
I0721 19:39:11.994373    1186 scheduler.go:384]  "msg"="Trying to delete multiple training jobs"  "jobs"=["tf2-keras-cifar10-resnet50-elastic-20210721-064451"] "scheduler"="default"
I0721 19:39:12.004324    1186 scheduler.go:342]  "msg"="Trying to scale multiple training jobs"  "jobs"=[] "scheduler"="default"
I0721 19:39:12.004635    1186 scheduler.go:292]  "msg"="Trying to start multiple training jobs"  "jobs"=["tf2-keras-transformer-elastic-20210721-063654","tf2-keras-transformer-elastic-20210721-064545"] "scheduler"="default"
I0721 19:39:12.035784    1186 scheduler.go:342]  "msg"="Trying to scale multiple training jobs"  "jobs"=["tf2-keras-cifar10-inceptionv3-elastic-20210721-063539"] "scheduler"="default"
I0721 19:39:12.053920    1186 placement_manager.go:166]  "msg"="Started job placements adjustment"  "scheduler"="default"
I0721 19:39:12.054044    1186 placement_manager.go:192]  "msg"="Releasing slots"  "jobs"={"tf2-keras-cifar10-inceptionv3-elastic-20210721-063448":{},"tf2-keras-cifar10-inceptionv3-elastic-20210721-063539":{},"tf2-keras-cifar10-resnet50-elastic-20210721-063511":{},"tf2-keras-cifar10-resnet50-elastic-20210721-064451":{},"tf2-keras-cifar10-resnet50-elastic-20210721-064517":{},"tf2-keras-cifar10-vgg16-elastic-20210721-063631":{}} "nodes"={"gpu3":{},"gpu4":{},"gpu5":{}} "scheduler"="default"
I0721 19:39:12.054118    1186 placement_manager.go:250]  "msg"="Released slots"  "jobs"={"tf2-keras-cifar10-inceptionv3-elastic-20210721-063448":{},"tf2-keras-cifar10-inceptionv3-elastic-20210721-063539":{},"tf2-keras-cifar10-resnet50-elastic-20210721-063511":{},"tf2-keras-cifar10-resnet50-elastic-20210721-064451":{},"tf2-keras-cifar10-resnet50-elastic-20210721-064517":{},"tf2-keras-cifar10-vgg16-elastic-20210721-063631":{}} "nodes"={"gpu3":{},"gpu4":{},"gpu5":{}} "scheduler"="default"
I0721 19:39:12.054566    1186 placement_manager.go:305]  "msg"="Found best-fit"  "crossNode"=0 "nodes"=[{},{},{}] "requests"=[{},{},{},{},{},{},{},{},{},{},{},{},{},{},{},{},{},{},{},{},{},{},{},{},{},{},{},{},{},{},{},{}] "scheduler"="default"
I0721 19:39:12.054934    1186 placement_manager.go:339]  "msg"="nodeStates updated"  "new"={"gpu3":{},"gpu4":{},"gpu5":{}} "old"={"gpu3":{},"gpu4":{},"gpu5":{}} "scheduler"="default" "score"=4
I0721 19:39:12.055236    1186 placement_manager.go:387]  "msg"="jobStates updated"  "new"={"tf2-keras-cifar10-inceptionv3-elastic-20210721-063448":{},"tf2-keras-cifar10-inceptionv3-elastic-20210721-063539":{},"tf2-keras-cifar10-resnet50-elastic-20210721-063511":{},"tf2-keras-cifar10-vgg16-elastic-20210721-063631":{},"tf2-keras-transformer-elastic-20210721-063654":{},"tf2-keras-transformer-elastic-20210721-064545":{}} "old"={"tf2-keras-cifar10-inceptionv3-elastic-20210721-063448":{},"tf2-keras-cifar10-inceptionv3-elastic-20210721-063539":{},"tf2-keras-cifar10-resnet50-elastic-20210721-063511":{},"tf2-keras-cifar10-resnet50-elastic-20210721-064451":{},"tf2-keras-cifar10-resnet50-elastic-20210721-064517":{},"tf2-keras-cifar10-vgg16-elastic-20210721-063631":{}} "scheduler"="default"
I0721 19:39:12.055630    1186 placement_manager.go:434]  "msg"="podNodeName updated"  "launchersToDelete"=2 "new"={"tf2-keras-cifar10-inceptionv3-elastic-20210721-063448-worker-0":"gpu4","tf2-keras-cifar10-inceptionv3-elastic-20210721-063448-worker-1":"gpu4","tf2-keras-cifar10-inceptionv3-elastic-20210721-063539-worker-0":"gpu3","tf2-keras-cifar10-inceptionv3-elastic-20210721-063539-worker-1":"gpu3","tf2-keras-cifar10-inceptionv3-elastic-20210721-063539-worker-2":"gpu3","tf2-keras-cifar10-resnet50-elastic-20210721-063511-worker-0":"gpu4","tf2-keras-cifar10-resnet50-elastic-20210721-063511-worker-1":"gpu4","tf2-keras-cifar10-vgg16-elastic-20210721-063631-worker-0":"gpu5","tf2-keras-cifar10-vgg16-elastic-20210721-063631-worker-1":"gpu5","tf2-keras-transformer-elastic-20210721-063654-worker-0":"gpu3","tf2-keras-transformer-elastic-20210721-064545-worker-0":"gpu5","tf2-keras-transformer-elastic-20210721-064545-worker-1":"gpu5"} "old"={"tf2-keras-cifar10-inceptionv3-elastic-20210721-063448-worker-0":"gpu5","tf2-keras-cifar10-inceptionv3-elastic-20210721-063448-worker-1":"gpu5","tf2-keras-cifar10-inceptionv3-elastic-20210721-063539-worker-0":"gpu3","tf2-keras-cifar10-inceptionv3-elastic-20210721-063539-worker-1":"gpu3","tf2-keras-cifar10-resnet50-elastic-20210721-063511-worker-0":"gpu4","tf2-keras-cifar10-resnet50-elastic-20210721-063511-worker-1":"gpu4","tf2-keras-cifar10-resnet50-elastic-20210721-064451-worker-0":"gpu5","tf2-keras-cifar10-resnet50-elastic-20210721-064451-worker-1":"gpu5","tf2-keras-cifar10-resnet50-elastic-20210721-064517-worker-0":"gpu4","tf2-keras-cifar10-resnet50-elastic-20210721-064517-worker-1":"gpu4","tf2-keras-cifar10-vgg16-elastic-20210721-063631-worker-0":"gpu3","tf2-keras-cifar10-vgg16-elastic-20210721-063631-worker-1":"gpu3"} "scheduler"="default" "workersToDelete"=4
I0721 19:39:12.055879    1186 placement_manager.go:451]  "msg"="Deleting pod that need migration"  "podName"="tf2-keras-cifar10-vgg16-elastic-20210721-063631-worker-0" "scheduler"="default"
I0721 19:39:12.059688    1186 placement_manager.go:451]  "msg"="Deleting pod that need migration"  "podName"="tf2-keras-cifar10-vgg16-elastic-20210721-063631-worker-1" "scheduler"="default"
I0721 19:39:12.063771    1186 placement_manager.go:451]  "msg"="Deleting pod that need migration"  "podName"="tf2-keras-cifar10-vgg16-elastic-20210721-063631-launcher" "scheduler"="default"
I0721 19:39:12.071873    1186 placement_manager.go:451]  "msg"="Deleting pod that need migration"  "podName"="tf2-keras-cifar10-inceptionv3-elastic-20210721-063448-worker-0" "scheduler"="default"
I0721 19:39:12.076152    1186 placement_manager.go:451]  "msg"="Deleting pod that need migration"  "podName"="tf2-keras-cifar10-inceptionv3-elastic-20210721-063448-worker-1" "scheduler"="default"
I0721 19:39:12.080759    1186 placement_manager.go:451]  "msg"="Deleting pod that need migration"  "podName"="tf2-keras-cifar10-inceptionv3-elastic-20210721-063448-launcher" "scheduler"="default"
I0721 19:39:12.085595    1186 placement_manager.go:183]  "msg"="Finished job placements adjustment"  "scheduler"="default"
I0721 19:39:12.085948    1186 scheduler.go:182]  "msg"="Finished resched"  "scheduler"="default"
I0721 19:39:12.235736    1186 placement_manager.go:147]  "msg"="Adding toleration to pod"  "podName"="tf2-keras-transformer-elastic-20210721-064545-worker-0" "scheduler"="default" "toleration"={"key":"celeste/hostname","operator":"Equal","value":"gpu5","effect":"NoExecute"}
I0721 19:39:12.434762    1186 placement_manager.go:147]  "msg"="Adding toleration to pod"  "podName"="tf2-keras-transformer-elastic-20210721-063654-worker-0" "scheduler"="default" "toleration"={"key":"celeste/hostname","operator":"Equal","value":"gpu3","effect":"NoExecute"}
I0721 19:39:12.863383    1186 placement_manager.go:147]  "msg"="Adding toleration to pod"  "podName"="tf2-keras-transformer-elastic-20210721-064545-worker-1" "scheduler"="default" "toleration"={"key":"celeste/hostname","operator":"Equal","value":"gpu5","effect":"NoExecute"}
I0721 19:39:13.263622    1186 placement_manager.go:147]  "msg"="Adding toleration to pod"  "podName"="tf2-keras-transformer-elastic-20210721-063654-launcher" "scheduler"="default" "toleration"={"key":"celeste/hostname","operator":"Exists","effect":"NoExecute"}
I0721 19:39:13.663019    1186 placement_manager.go:147]  "msg"="Adding toleration to pod"  "podName"="tf2-keras-transformer-elastic-20210721-064545-launcher" "scheduler"="default" "toleration"={"key":"celeste/hostname","operator":"Exists","effect":"NoExecute"}
I0721 19:39:14.065608    1186 placement_manager.go:147]  "msg"="Adding toleration to pod"  "podName"="tf2-keras-cifar10-inceptionv3-elastic-20210721-063539-worker-2" "scheduler"="default" "toleration"={"key":"celeste/hostname","operator":"Equal","value":"gpu3","effect":"NoExecute"}
I0721 19:39:16.593090    1186 scheduler.go:565]  "msg"="Priority promoted to training job"  "job"="tf2-keras-transformer-elastic-20210721-063654" "priority"=0 "scheduler"="default"
I0721 19:39:16.593171    1186 scheduler.go:573]  "msg"="Priority changed"  "scheduler"="default"
I0721 19:39:16.593254    1186 scheduler.go:135]  "msg"="Received resched event, may be blocked because of rate limit"  "blockedUntil"="2021-07-21T19:41:12.086182926+08:00" "lastResched"="2021-07-21T19:39:12.086182926+08:00" "received"="2021-07-21T19:39:16.593179192+08:00" "scheduler"="default"
I0721 19:39:19.012562    1186 placement_manager.go:147]  "msg"="Adding toleration to pod"  "podName"="tf2-keras-cifar10-vgg16-elastic-20210721-063631-launcher" "scheduler"="default" "toleration"={"key":"celeste/hostname","operator":"Exists","effect":"NoExecute"}
I0721 19:39:22.604334    1186 placement_manager.go:147]  "msg"="Adding toleration to pod"  "podName"="tf2-keras-cifar10-inceptionv3-elastic-20210721-063448-launcher" "scheduler"="default" "toleration"={"key":"celeste/hostname","operator":"Exists","effect":"NoExecute"}
I0721 19:39:25.202329    1186 placement_manager.go:147]  "msg"="Adding toleration to pod"  "podName"="tf2-keras-cifar10-inceptionv3-elastic-20210721-063448-worker-0" "scheduler"="default" "toleration"={"key":"celeste/hostname","operator":"Equal","value":"gpu4","effect":"NoExecute"}
I0721 19:39:29.265839    1186 placement_manager.go:147]  "msg"="Adding toleration to pod"  "podName"="tf2-keras-cifar10-vgg16-elastic-20210721-063631-worker-0" "scheduler"="default" "toleration"={"key":"celeste/hostname","operator":"Equal","value":"gpu5","effect":"NoExecute"}
I0721 19:39:29.302459    1186 placement_manager.go:147]  "msg"="Adding toleration to pod"  "podName"="tf2-keras-cifar10-vgg16-elastic-20210721-063631-worker-1" "scheduler"="default" "toleration"={"key":"celeste/hostname","operator":"Equal","value":"gpu5","effect":"NoExecute"}
I0721 19:39:33.211571    1186 placement_manager.go:147]  "msg"="Adding toleration to pod"  "podName"="tf2-keras-cifar10-inceptionv3-elastic-20210721-063448-worker-1" "scheduler"="default" "toleration"={"key":"celeste/hostname","operator":"Equal","value":"gpu4","effect":"NoExecute"}
I0721 19:40:54.690914    1186 scheduler.go:474]  "msg"="Training job completed"  "elaspedTotalSeconds"=3939.930203534 "gpuTotalSeconds"=2960.096025893 "job"="tf2-keras-cifar10-resnet50-elastic-20210721-063511" "ranTotalSeconds"=1540.049819532 "scheduler"="default" "waitedTotalSeconds"=2399.880384002
I0721 19:41:12.086238    1186 scheduler.go:159]  "msg"="Started resched"  "scheduler"="default"
I0721 19:41:12.086301    1186 scheduler.go:193]  "msg"="Updating all jobs info"  "scheduler"="default"
I0721 19:41:12.096312    1186 elastic_tiresias.go:160]  "msg"="Finished scheduling"  "algorithm"="ElasticTiresias" "compactionThreshold"=4 "freeGpu"=0 "promoteKnob"=4 "queueNum"=2 "result"={"tf2-keras-cifar10-inceptionv3-elastic-20210721-063448":2,"tf2-keras-cifar10-inceptionv3-elastic-20210721-063539":3,"tf2-keras-cifar10-inceptionv3-elastic-20210721-063756":0,"tf2-keras-cifar10-inceptionv3-elastic-20210721-063900":0,"tf2-keras-cifar10-inceptionv3-elastic-20210721-064117":0,"tf2-keras-cifar10-inceptionv3-elastic-20210721-064215":0,"tf2-keras-cifar10-resnet50-elastic-20210721-064451":0,"tf2-keras-cifar10-vgg16-elastic-20210721-063631":2,"tf2-keras-cifar10-vgg16-elastic-20210721-064310":0,"tf2-keras-transformer-elastic-20210721-063654":2,"tf2-keras-transformer-elastic-20210721-063721":1,"tf2-keras-transformer-elastic-20210721-063927":0,"tf2-keras-transformer-elastic-20210721-064152":0,"tf2-keras-transformer-elastic-20210721-064332":0,"tf2-keras-transformer-elastic-20210721-064545":2} "scheduler"="default" "thresholds"=
I0721 19:41:12.096688    1186 scheduler.go:384]  "msg"="Trying to delete multiple training jobs"  "jobs"=[] "scheduler"="default"
I0721 19:41:12.096981    1186 scheduler.go:342]  "msg"="Trying to scale multiple training jobs"  "jobs"=[] "scheduler"="default"
I0721 19:41:12.097240    1186 scheduler.go:292]  "msg"="Trying to start multiple training jobs"  "jobs"=["tf2-keras-transformer-elastic-20210721-063721"] "scheduler"="default"
I0721 19:41:12.111671    1186 scheduler.go:342]  "msg"="Trying to scale multiple training jobs"  "jobs"=["tf2-keras-transformer-elastic-20210721-063654"] "scheduler"="default"
I0721 19:41:12.139419    1186 placement_manager.go:166]  "msg"="Started job placements adjustment"  "scheduler"="default"
I0721 19:41:12.139498    1186 placement_manager.go:192]  "msg"="Releasing slots"  "jobs"={"tf2-keras-cifar10-inceptionv3-elastic-20210721-063448":{},"tf2-keras-cifar10-inceptionv3-elastic-20210721-063539":{},"tf2-keras-cifar10-resnet50-elastic-20210721-063511":{},"tf2-keras-cifar10-vgg16-elastic-20210721-063631":{},"tf2-keras-transformer-elastic-20210721-063654":{},"tf2-keras-transformer-elastic-20210721-064545":{}} "nodes"={"gpu3":{},"gpu4":{},"gpu5":{}} "scheduler"="default"
I0721 19:41:12.139575    1186 placement_manager.go:250]  "msg"="Released slots"  "jobs"={"tf2-keras-cifar10-inceptionv3-elastic-20210721-063448":{},"tf2-keras-cifar10-inceptionv3-elastic-20210721-063539":{},"tf2-keras-cifar10-resnet50-elastic-20210721-063511":{},"tf2-keras-cifar10-vgg16-elastic-20210721-063631":{},"tf2-keras-transformer-elastic-20210721-063654":{},"tf2-keras-transformer-elastic-20210721-064545":{}} "nodes"={"gpu3":{},"gpu4":{},"gpu5":{}} "scheduler"="default"
I0721 19:41:12.140020    1186 placement_manager.go:305]  "msg"="Found best-fit"  "crossNode"=0 "nodes"=[{},{},{}] "requests"=[{},{},{},{},{},{},{},{},{},{},{},{},{},{},{},{},{},{},{},{},{},{},{},{},{},{},{},{},{},{}] "scheduler"="default"
I0721 19:41:12.140304    1186 placement_manager.go:339]  "msg"="nodeStates updated"  "new"={"gpu3":{},"gpu4":{},"gpu5":{}} "old"={"gpu3":{},"gpu4":{},"gpu5":{}} "scheduler"="default" "score"=9
I0721 19:41:12.140641    1186 placement_manager.go:387]  "msg"="jobStates updated"  "new"={"tf2-keras-cifar10-inceptionv3-elastic-20210721-063448":{},"tf2-keras-cifar10-inceptionv3-elastic-20210721-063539":{},"tf2-keras-cifar10-vgg16-elastic-20210721-063631":{},"tf2-keras-transformer-elastic-20210721-063654":{},"tf2-keras-transformer-elastic-20210721-063721":{},"tf2-keras-transformer-elastic-20210721-064545":{}} "old"={"tf2-keras-cifar10-inceptionv3-elastic-20210721-063448":{},"tf2-keras-cifar10-inceptionv3-elastic-20210721-063539":{},"tf2-keras-cifar10-resnet50-elastic-20210721-063511":{},"tf2-keras-cifar10-vgg16-elastic-20210721-063631":{},"tf2-keras-transformer-elastic-20210721-063654":{},"tf2-keras-transformer-elastic-20210721-064545":{}} "scheduler"="default"
I0721 19:41:12.141083    1186 placement_manager.go:434]  "msg"="podNodeName updated"  "launchersToDelete"=0 "new"={"tf2-keras-cifar10-inceptionv3-elastic-20210721-063448-worker-0":"gpu4","tf2-keras-cifar10-inceptionv3-elastic-20210721-063448-worker-1":"gpu4","tf2-keras-cifar10-inceptionv3-elastic-20210721-063539-worker-0":"gpu3","tf2-keras-cifar10-inceptionv3-elastic-20210721-063539-worker-1":"gpu3","tf2-keras-cifar10-inceptionv3-elastic-20210721-063539-worker-2":"gpu3","tf2-keras-cifar10-vgg16-elastic-20210721-063631-worker-0":"gpu5","tf2-keras-cifar10-vgg16-elastic-20210721-063631-worker-1":"gpu5","tf2-keras-transformer-elastic-20210721-063654-worker-0":"gpu4","tf2-keras-transformer-elastic-20210721-063654-worker-1":"gpu4","tf2-keras-transformer-elastic-20210721-063721-worker-0":"gpu3","tf2-keras-transformer-elastic-20210721-064545-worker-0":"gpu5","tf2-keras-transformer-elastic-20210721-064545-worker-1":"gpu5"} "old"={"tf2-keras-cifar10-inceptionv3-elastic-20210721-063448-worker-0":"gpu4","tf2-keras-cifar10-inceptionv3-elastic-20210721-063448-worker-1":"gpu4","tf2-keras-cifar10-inceptionv3-elastic-20210721-063539-worker-0":"gpu3","tf2-keras-cifar10-inceptionv3-elastic-20210721-063539-worker-1":"gpu3","tf2-keras-cifar10-inceptionv3-elastic-20210721-063539-worker-2":"gpu3","tf2-keras-cifar10-resnet50-elastic-20210721-063511-worker-0":"gpu4","tf2-keras-cifar10-resnet50-elastic-20210721-063511-worker-1":"gpu4","tf2-keras-cifar10-vgg16-elastic-20210721-063631-worker-0":"gpu5","tf2-keras-cifar10-vgg16-elastic-20210721-063631-worker-1":"gpu5","tf2-keras-transformer-elastic-20210721-063654-worker-0":"gpu3","tf2-keras-transformer-elastic-20210721-064545-worker-0":"gpu5","tf2-keras-transformer-elastic-20210721-064545-worker-1":"gpu5"} "scheduler"="default" "workersToDelete"=1
I0721 19:41:12.141395    1186 placement_manager.go:451]  "msg"="Deleting pod that need migration"  "podName"="tf2-keras-transformer-elastic-20210721-063654-worker-0" "scheduler"="default"
I0721 19:41:12.147985    1186 placement_manager.go:183]  "msg"="Finished job placements adjustment"  "scheduler"="default"
I0721 19:41:12.148229    1186 scheduler.go:182]  "msg"="Finished resched"  "scheduler"="default"
I0721 19:41:12.162583    1186 placement_manager.go:147]  "msg"="Adding toleration to pod"  "podName"="tf2-keras-transformer-elastic-20210721-063654-worker-1" "scheduler"="default" "toleration"={"key":"celeste/hostname","operator":"Equal","value":"gpu4","effect":"NoExecute"}
I0721 19:41:12.318972    1186 placement_manager.go:147]  "msg"="Adding toleration to pod"  "podName"="tf2-keras-transformer-elastic-20210721-063721-worker-0" "scheduler"="default" "toleration"={"key":"celeste/hostname","operator":"Equal","value":"gpu3","effect":"NoExecute"}
I0721 19:41:12.518989    1186 placement_manager.go:147]  "msg"="Adding toleration to pod"  "podName"="tf2-keras-transformer-elastic-20210721-063721-launcher" "scheduler"="default" "toleration"={"key":"celeste/hostname","operator":"Exists","effect":"NoExecute"}
I0721 19:41:16.596661    1186 scheduler.go:565]  "msg"="Priority promoted to training job"  "job"="tf2-keras-transformer-elastic-20210721-063721" "priority"=0 "scheduler"="default"
I0721 19:41:16.596733    1186 scheduler.go:573]  "msg"="Priority changed"  "scheduler"="default"
I0721 19:41:16.596805    1186 scheduler.go:135]  "msg"="Received resched event, may be blocked because of rate limit"  "blockedUntil"="2021-07-21T19:43:12.148396875+08:00" "lastResched"="2021-07-21T19:41:12.148396875+08:00" "received"="2021-07-21T19:41:16.596742653+08:00" "scheduler"="default"
I0721 19:41:19.582880    1186 placement_manager.go:147]  "msg"="Adding toleration to pod"  "podName"="tf2-keras-transformer-elastic-20210721-063654-worker-0" "scheduler"="default" "toleration"={"key":"celeste/hostname","operator":"Equal","value":"gpu4","effect":"NoExecute"}
I0721 19:42:24.390602    1186 scheduler.go:474]  "msg"="Training job completed"  "elaspedTotalSeconds"=3950.106792654 "gpuTotalSeconds"=2660.086270089 "job"="tf2-keras-cifar10-vgg16-elastic-20210721-063631" "ranTotalSeconds"=1390.044857986 "scheduler"="default" "waitedTotalSeconds"=2560.061934668
I0721 19:43:12.148558    1186 scheduler.go:159]  "msg"="Started resched"  "scheduler"="default"
I0721 19:43:12.148665    1186 scheduler.go:193]  "msg"="Updating all jobs info"  "scheduler"="default"
I0721 19:43:12.156415    1186 elastic_tiresias.go:160]  "msg"="Finished scheduling"  "algorithm"="ElasticTiresias" "compactionThreshold"=4 "freeGpu"=0 "promoteKnob"=4 "queueNum"=2 "result"={"tf2-keras-cifar10-inceptionv3-elastic-20210721-063448":2,"tf2-keras-cifar10-inceptionv3-elastic-20210721-063539":2,"tf2-keras-cifar10-inceptionv3-elastic-20210721-063756":1,"tf2-keras-cifar10-inceptionv3-elastic-20210721-063900":1,"tf2-keras-cifar10-inceptionv3-elastic-20210721-064117":0,"tf2-keras-cifar10-inceptionv3-elastic-20210721-064215":0,"tf2-keras-cifar10-resnet50-elastic-20210721-064451":0,"tf2-keras-cifar10-vgg16-elastic-20210721-064310":0,"tf2-keras-transformer-elastic-20210721-063654":2,"tf2-keras-transformer-elastic-20210721-063721":2,"tf2-keras-transformer-elastic-20210721-063927":0,"tf2-keras-transformer-elastic-20210721-064152":0,"tf2-keras-transformer-elastic-20210721-064332":0,"tf2-keras-transformer-elastic-20210721-064545":2} "scheduler"="default" "thresholds"=
I0721 19:43:12.156776    1186 scheduler.go:384]  "msg"="Trying to delete multiple training jobs"  "jobs"=[] "scheduler"="default"
I0721 19:43:12.156981    1186 scheduler.go:342]  "msg"="Trying to scale multiple training jobs"  "jobs"=["tf2-keras-cifar10-inceptionv3-elastic-20210721-063539"] "scheduler"="default"
I0721 19:43:12.177318    1186 scheduler.go:292]  "msg"="Trying to start multiple training jobs"  "jobs"=["tf2-keras-cifar10-inceptionv3-elastic-20210721-063756","tf2-keras-cifar10-inceptionv3-elastic-20210721-063900"] "scheduler"="default"
I0721 19:43:12.194519    1186 scheduler.go:342]  "msg"="Trying to scale multiple training jobs"  "jobs"=["tf2-keras-transformer-elastic-20210721-063721"] "scheduler"="default"
I0721 19:43:12.226007    1186 placement_manager.go:166]  "msg"="Started job placements adjustment"  "scheduler"="default"
I0721 19:43:12.226094    1186 placement_manager.go:192]  "msg"="Releasing slots"  "jobs"={"tf2-keras-cifar10-inceptionv3-elastic-20210721-063448":{},"tf2-keras-cifar10-inceptionv3-elastic-20210721-063539":{},"tf2-keras-cifar10-vgg16-elastic-20210721-063631":{},"tf2-keras-transformer-elastic-20210721-063654":{},"tf2-keras-transformer-elastic-20210721-063721":{},"tf2-keras-transformer-elastic-20210721-064545":{}} "nodes"={"gpu3":{},"gpu4":{},"gpu5":{}} "scheduler"="default"
I0721 19:43:12.226159    1186 placement_manager.go:250]  "msg"="Released slots"  "jobs"={"tf2-keras-cifar10-inceptionv3-elastic-20210721-063448":{},"tf2-keras-cifar10-inceptionv3-elastic-20210721-063539":{},"tf2-keras-cifar10-vgg16-elastic-20210721-063631":{},"tf2-keras-transformer-elastic-20210721-063654":{},"tf2-keras-transformer-elastic-20210721-063721":{},"tf2-keras-transformer-elastic-20210721-064545":{}} "nodes"={"gpu3":{},"gpu4":{},"gpu5":{}} "scheduler"="default"
I0721 19:43:12.226675    1186 placement_manager.go:305]  "msg"="Found best-fit"  "crossNode"=0 "nodes"=[{},{},{}] "requests"=[{},{},{},{},{},{},{},{},{},{},{},{},{},{},{},{},{},{},{},{},{},{},{},{},{},{},{},{}] "scheduler"="default"
I0721 19:43:12.227036    1186 placement_manager.go:339]  "msg"="nodeStates updated"  "new"={"gpu3":{},"gpu4":{},"gpu5":{}} "old"={"gpu3":{},"gpu4":{},"gpu5":{}} "scheduler"="default" "score"=7
I0721 19:43:12.227344    1186 placement_manager.go:387]  "msg"="jobStates updated"  "new"={"tf2-keras-cifar10-inceptionv3-elastic-20210721-063448":{},"tf2-keras-cifar10-inceptionv3-elastic-20210721-063539":{},"tf2-keras-cifar10-inceptionv3-elastic-20210721-063756":{},"tf2-keras-cifar10-inceptionv3-elastic-20210721-063900":{},"tf2-keras-transformer-elastic-20210721-063654":{},"tf2-keras-transformer-elastic-20210721-063721":{},"tf2-keras-transformer-elastic-20210721-064545":{}} "old"={"tf2-keras-cifar10-inceptionv3-elastic-20210721-063448":{},"tf2-keras-cifar10-inceptionv3-elastic-20210721-063539":{},"tf2-keras-cifar10-vgg16-elastic-20210721-063631":{},"tf2-keras-transformer-elastic-20210721-063654":{},"tf2-keras-transformer-elastic-20210721-063721":{},"tf2-keras-transformer-elastic-20210721-064545":{}} "scheduler"="default"
I0721 19:43:12.227688    1186 placement_manager.go:434]  "msg"="podNodeName updated"  "launchersToDelete"=1 "new"={"tf2-keras-cifar10-inceptionv3-elastic-20210721-063448-worker-0":"gpu4","tf2-keras-cifar10-inceptionv3-elastic-20210721-063448-worker-1":"gpu4","tf2-keras-cifar10-inceptionv3-elastic-20210721-063539-worker-0":"gpu5","tf2-keras-cifar10-inceptionv3-elastic-20210721-063539-worker-1":"gpu5","tf2-keras-cifar10-inceptionv3-elastic-20210721-063756-worker-0":"gpu3","tf2-keras-cifar10-inceptionv3-elastic-20210721-063900-worker-0":"gpu3","tf2-keras-transformer-elastic-20210721-063654-worker-0":"gpu4","tf2-keras-transformer-elastic-20210721-063654-worker-1":"gpu4","tf2-keras-transformer-elastic-20210721-063721-worker-0":"gpu3","tf2-keras-transformer-elastic-20210721-063721-worker-1":"gpu3","tf2-keras-transformer-elastic-20210721-064545-worker-0":"gpu5","tf2-keras-transformer-elastic-20210721-064545-worker-1":"gpu5"} "old"={"tf2-keras-cifar10-inceptionv3-elastic-20210721-063448-worker-0":"gpu4","tf2-keras-cifar10-inceptionv3-elastic-20210721-063448-worker-1":"gpu4","tf2-keras-cifar10-inceptionv3-elastic-20210721-063539-worker-0":"gpu3","tf2-keras-cifar10-inceptionv3-elastic-20210721-063539-worker-1":"gpu3","tf2-keras-cifar10-inceptionv3-elastic-20210721-063539-worker-2":"gpu3","tf2-keras-cifar10-vgg16-elastic-20210721-063631-worker-0":"gpu5","tf2-keras-cifar10-vgg16-elastic-20210721-063631-worker-1":"gpu5","tf2-keras-transformer-elastic-20210721-063654-worker-0":"gpu4","tf2-keras-transformer-elastic-20210721-063654-worker-1":"gpu4","tf2-keras-transformer-elastic-20210721-063721-worker-0":"gpu3","tf2-keras-transformer-elastic-20210721-064545-worker-0":"gpu5","tf2-keras-transformer-elastic-20210721-064545-worker-1":"gpu5"} "scheduler"="default" "workersToDelete"=2
I0721 19:43:12.227992    1186 placement_manager.go:451]  "msg"="Deleting pod that need migration"  "podName"="tf2-keras-cifar10-inceptionv3-elastic-20210721-063539-worker-0" "scheduler"="default"
I0721 19:43:12.231170    1186 placement_manager.go:451]  "msg"="Deleting pod that need migration"  "podName"="tf2-keras-cifar10-inceptionv3-elastic-20210721-063539-worker-1" "scheduler"="default"
I0721 19:43:12.234781    1186 placement_manager.go:451]  "msg"="Deleting pod that need migration"  "podName"="tf2-keras-cifar10-inceptionv3-elastic-20210721-063539-launcher" "scheduler"="default"
I0721 19:43:12.239837    1186 placement_manager.go:183]  "msg"="Finished job placements adjustment"  "scheduler"="default"
I0721 19:43:12.240095    1186 scheduler.go:182]  "msg"="Finished resched"  "scheduler"="default"
I0721 19:43:12.591973    1186 placement_manager.go:147]  "msg"="Adding toleration to pod"  "podName"="tf2-keras-cifar10-inceptionv3-elastic-20210721-063756-worker-0" "scheduler"="default" "toleration"={"key":"celeste/hostname","operator":"Equal","value":"gpu3","effect":"NoExecute"}
I0721 19:43:12.989574    1186 placement_manager.go:147]  "msg"="Adding toleration to pod"  "podName"="tf2-keras-cifar10-inceptionv3-elastic-20210721-063756-launcher" "scheduler"="default" "toleration"={"key":"celeste/hostname","operator":"Exists","effect":"NoExecute"}
I0721 19:43:13.991817    1186 placement_manager.go:147]  "msg"="Adding toleration to pod"  "podName"="tf2-keras-cifar10-inceptionv3-elastic-20210721-063900-worker-0" "scheduler"="default" "toleration"={"key":"celeste/hostname","operator":"Equal","value":"gpu3","effect":"NoExecute"}
I0721 19:43:14.194443    1186 placement_manager.go:147]  "msg"="Adding toleration to pod"  "podName"="tf2-keras-transformer-elastic-20210721-063721-worker-1" "scheduler"="default" "toleration"={"key":"celeste/hostname","operator":"Equal","value":"gpu3","effect":"NoExecute"}
I0721 19:43:14.392987    1186 placement_manager.go:147]  "msg"="Adding toleration to pod"  "podName"="tf2-keras-cifar10-inceptionv3-elastic-20210721-063900-launcher" "scheduler"="default" "toleration"={"key":"celeste/hostname","operator":"Exists","effect":"NoExecute"}
I0721 19:43:16.599994    1186 scheduler.go:565]  "msg"="Priority promoted to training job"  "job"="tf2-keras-cifar10-inceptionv3-elastic-20210721-063900" "priority"=0 "scheduler"="default"
I0721 19:43:16.600078    1186 scheduler.go:565]  "msg"="Priority promoted to training job"  "job"="tf2-keras-cifar10-inceptionv3-elastic-20210721-063756" "priority"=0 "scheduler"="default"
I0721 19:43:16.600113    1186 scheduler.go:573]  "msg"="Priority changed"  "scheduler"="default"
I0721 19:43:16.600209    1186 scheduler.go:135]  "msg"="Received resched event, may be blocked because of rate limit"  "blockedUntil"="2021-07-21T19:45:12.240302086+08:00" "lastResched"="2021-07-21T19:43:12.240302086+08:00" "received"="2021-07-21T19:43:16.600121481+08:00" "scheduler"="default"
I0721 19:43:29.753067    1186 placement_manager.go:147]  "msg"="Adding toleration to pod"  "podName"="tf2-keras-cifar10-inceptionv3-elastic-20210721-063539-launcher" "scheduler"="default" "toleration"={"key":"celeste/hostname","operator":"Exists","effect":"NoExecute"}
I0721 19:43:29.997587    1186 placement_manager.go:147]  "msg"="Adding toleration to pod"  "podName"="tf2-keras-cifar10-inceptionv3-elastic-20210721-063539-worker-1" "scheduler"="default" "toleration"={"key":"celeste/hostname","operator":"Equal","value":"gpu5","effect":"NoExecute"}
I0721 19:43:31.601748    1186 placement_manager.go:147]  "msg"="Adding toleration to pod"  "podName"="tf2-keras-cifar10-inceptionv3-elastic-20210721-063539-worker-0" "scheduler"="default" "toleration"={"key":"celeste/hostname","operator":"Equal","value":"gpu5","effect":"NoExecute"}
I0721 19:45:12.240398    1186 scheduler.go:159]  "msg"="Started resched"  "scheduler"="default"
I0721 19:45:12.240479    1186 scheduler.go:193]  "msg"="Updating all jobs info"  "scheduler"="default"
I0721 19:45:12.248839    1186 elastic_tiresias.go:160]  "msg"="Finished scheduling"  "algorithm"="ElasticTiresias" "compactionThreshold"=4 "freeGpu"=0 "promoteKnob"=4 "queueNum"=2 "result"={"tf2-keras-cifar10-inceptionv3-elastic-20210721-063448":2,"tf2-keras-cifar10-inceptionv3-elastic-20210721-063539":2,"tf2-keras-cifar10-inceptionv3-elastic-20210721-063756":2,"tf2-keras-cifar10-inceptionv3-elastic-20210721-063900":2,"tf2-keras-cifar10-inceptionv3-elastic-20210721-064117":0,"tf2-keras-cifar10-inceptionv3-elastic-20210721-064215":0,"tf2-keras-cifar10-resnet50-elastic-20210721-064451":0,"tf2-keras-cifar10-vgg16-elastic-20210721-064310":0,"tf2-keras-transformer-elastic-20210721-063654":2,"tf2-keras-transformer-elastic-20210721-063721":2,"tf2-keras-transformer-elastic-20210721-063927":0,"tf2-keras-transformer-elastic-20210721-064152":0,"tf2-keras-transformer-elastic-20210721-064332":0,"tf2-keras-transformer-elastic-20210721-064545":0} "scheduler"="default" "thresholds"=
I0721 19:45:12.249049    1186 scheduler.go:384]  "msg"="Trying to delete multiple training jobs"  "jobs"=["tf2-keras-transformer-elastic-20210721-064545"] "scheduler"="default"
I0721 19:45:12.260157    1186 scheduler.go:342]  "msg"="Trying to scale multiple training jobs"  "jobs"=[] "scheduler"="default"
I0721 19:45:12.260456    1186 scheduler.go:292]  "msg"="Trying to start multiple training jobs"  "jobs"=[] "scheduler"="default"
I0721 19:45:12.260769    1186 scheduler.go:342]  "msg"="Trying to scale multiple training jobs"  "jobs"=["tf2-keras-cifar10-inceptionv3-elastic-20210721-063900","tf2-keras-cifar10-inceptionv3-elastic-20210721-063756"] "scheduler"="default"
I0721 19:45:12.296346    1186 placement_manager.go:166]  "msg"="Started job placements adjustment"  "scheduler"="default"
I0721 19:45:12.296433    1186 placement_manager.go:192]  "msg"="Releasing slots"  "jobs"={"tf2-keras-cifar10-inceptionv3-elastic-20210721-063448":{},"tf2-keras-cifar10-inceptionv3-elastic-20210721-063539":{},"tf2-keras-cifar10-inceptionv3-elastic-20210721-063756":{},"tf2-keras-cifar10-inceptionv3-elastic-20210721-063900":{},"tf2-keras-transformer-elastic-20210721-063654":{},"tf2-keras-transformer-elastic-20210721-063721":{},"tf2-keras-transformer-elastic-20210721-064545":{}} "nodes"={"gpu3":{},"gpu4":{},"gpu5":{}} "scheduler"="default"
I0721 19:45:12.296488    1186 placement_manager.go:250]  "msg"="Released slots"  "jobs"={"tf2-keras-cifar10-inceptionv3-elastic-20210721-063448":{},"tf2-keras-cifar10-inceptionv3-elastic-20210721-063539":{},"tf2-keras-cifar10-inceptionv3-elastic-20210721-063756":{},"tf2-keras-cifar10-inceptionv3-elastic-20210721-063900":{},"tf2-keras-transformer-elastic-20210721-063654":{},"tf2-keras-transformer-elastic-20210721-063721":{},"tf2-keras-transformer-elastic-20210721-064545":{}} "nodes"={"gpu3":{},"gpu4":{},"gpu5":{}} "scheduler"="default"
I0721 19:45:12.296885    1186 placement_manager.go:305]  "msg"="Found best-fit"  "crossNode"=0 "nodes"=[{},{},{}] "requests"=[{},{},{},{},{},{},{},{},{},{},{},{},{},{},{},{},{},{},{},{},{},{},{},{},{},{},{},{}] "scheduler"="default"
I0721 19:45:12.297135    1186 placement_manager.go:339]  "msg"="nodeStates updated"  "new"={"gpu3":{},"gpu4":{},"gpu5":{}} "old"={"gpu3":{},"gpu4":{},"gpu5":{}} "scheduler"="default" "score"=9
I0721 19:45:12.297509    1186 placement_manager.go:387]  "msg"="jobStates updated"  "new"={"tf2-keras-cifar10-inceptionv3-elastic-20210721-063448":{},"tf2-keras-cifar10-inceptionv3-elastic-20210721-063539":{},"tf2-keras-cifar10-inceptionv3-elastic-20210721-063756":{},"tf2-keras-cifar10-inceptionv3-elastic-20210721-063900":{},"tf2-keras-transformer-elastic-20210721-063654":{},"tf2-keras-transformer-elastic-20210721-063721":{}} "old"={"tf2-keras-cifar10-inceptionv3-elastic-20210721-063448":{},"tf2-keras-cifar10-inceptionv3-elastic-20210721-063539":{},"tf2-keras-cifar10-inceptionv3-elastic-20210721-063756":{},"tf2-keras-cifar10-inceptionv3-elastic-20210721-063900":{},"tf2-keras-transformer-elastic-20210721-063654":{},"tf2-keras-transformer-elastic-20210721-063721":{},"tf2-keras-transformer-elastic-20210721-064545":{}} "scheduler"="default"
I0721 19:45:12.298087    1186 placement_manager.go:434]  "msg"="podNodeName updated"  "launchersToDelete"=0 "new"={"tf2-keras-cifar10-inceptionv3-elastic-20210721-063448-worker-0":"gpu4","tf2-keras-cifar10-inceptionv3-elastic-20210721-063448-worker-1":"gpu4","tf2-keras-cifar10-inceptionv3-elastic-20210721-063539-worker-0":"gpu5","tf2-keras-cifar10-inceptionv3-elastic-20210721-063539-worker-1":"gpu5","tf2-keras-cifar10-inceptionv3-elastic-20210721-063756-worker-0":"gpu3","tf2-keras-cifar10-inceptionv3-elastic-20210721-063756-worker-1":"gpu3","tf2-keras-cifar10-inceptionv3-elastic-20210721-063900-worker-0":"gpu5","tf2-keras-cifar10-inceptionv3-elastic-20210721-063900-worker-1":"gpu5","tf2-keras-transformer-elastic-20210721-063654-worker-0":"gpu4","tf2-keras-transformer-elastic-20210721-063654-worker-1":"gpu4","tf2-keras-transformer-elastic-20210721-063721-worker-0":"gpu3","tf2-keras-transformer-elastic-20210721-063721-worker-1":"gpu3"} "old"={"tf2-keras-cifar10-inceptionv3-elastic-20210721-063448-worker-0":"gpu4","tf2-keras-cifar10-inceptionv3-elastic-20210721-063448-worker-1":"gpu4","tf2-keras-cifar10-inceptionv3-elastic-20210721-063539-worker-0":"gpu5","tf2-keras-cifar10-inceptionv3-elastic-20210721-063539-worker-1":"gpu5","tf2-keras-cifar10-inceptionv3-elastic-20210721-063756-worker-0":"gpu3","tf2-keras-cifar10-inceptionv3-elastic-20210721-063900-worker-0":"gpu3","tf2-keras-transformer-elastic-20210721-063654-worker-0":"gpu4","tf2-keras-transformer-elastic-20210721-063654-worker-1":"gpu4","tf2-keras-transformer-elastic-20210721-063721-worker-0":"gpu3","tf2-keras-transformer-elastic-20210721-063721-worker-1":"gpu3","tf2-keras-transformer-elastic-20210721-064545-worker-0":"gpu5","tf2-keras-transformer-elastic-20210721-064545-worker-1":"gpu5"} "scheduler"="default" "workersToDelete"=1
I0721 19:45:12.298491    1186 placement_manager.go:451]  "msg"="Deleting pod that need migration"  "podName"="tf2-keras-cifar10-inceptionv3-elastic-20210721-063900-worker-0" "scheduler"="default"
I0721 19:45:12.302726    1186 placement_manager.go:183]  "msg"="Finished job placements adjustment"  "scheduler"="default"
I0721 19:45:12.302984    1186 scheduler.go:182]  "msg"="Finished resched"  "scheduler"="default"
I0721 19:45:12.310569    1186 placement_manager.go:147]  "msg"="Adding toleration to pod"  "podName"="tf2-keras-cifar10-inceptionv3-elastic-20210721-063900-worker-1" "scheduler"="default" "toleration"={"key":"celeste/hostname","operator":"Equal","value":"gpu5","effect":"NoExecute"}
I0721 19:45:12.340961    1186 placement_manager.go:147]  "msg"="Adding toleration to pod"  "podName"="tf2-keras-cifar10-inceptionv3-elastic-20210721-063756-worker-1" "scheduler"="default" "toleration"={"key":"celeste/hostname","operator":"Equal","value":"gpu3","effect":"NoExecute"}
I0721 19:45:19.679475    1186 placement_manager.go:147]  "msg"="Adding toleration to pod"  "podName"="tf2-keras-cifar10-inceptionv3-elastic-20210721-063900-worker-0" "scheduler"="default" "toleration"={"key":"celeste/hostname","operator":"Equal","value":"gpu5","effect":"NoExecute"}
I0721 19:47:11.607222    1186 scheduler.go:559]  "msg"="Priority demoted to training job"  "job"="tf2-keras-cifar10-inceptionv3-elastic-20210721-063448" "priority"=1 "scheduler"="default"
I0721 19:47:11.607276    1186 scheduler.go:573]  "msg"="Priority changed"  "scheduler"="default"
I0721 19:47:11.607353    1186 scheduler.go:135]  "msg"="Received resched event, may be blocked because of rate limit"  "blockedUntil"="2021-07-21T19:47:12.303214428+08:00" "lastResched"="2021-07-21T19:45:12.303214428+08:00" "received"="2021-07-21T19:47:11.607284565+08:00" "scheduler"="default"
I0721 19:47:12.303274    1186 scheduler.go:159]  "msg"="Started resched"  "scheduler"="default"
I0721 19:47:12.303318    1186 scheduler.go:193]  "msg"="Updating all jobs info"  "scheduler"="default"
I0721 19:47:12.312781    1186 elastic_tiresias.go:160]  "msg"="Finished scheduling"  "algorithm"="ElasticTiresias" "compactionThreshold"=4 "freeGpu"=0 "promoteKnob"=4 "queueNum"=2 "result"={"tf2-keras-cifar10-inceptionv3-elastic-20210721-063448":0,"tf2-keras-cifar10-inceptionv3-elastic-20210721-063539":2,"tf2-keras-cifar10-inceptionv3-elastic-20210721-063756":2,"tf2-keras-cifar10-inceptionv3-elastic-20210721-063900":2,"tf2-keras-cifar10-inceptionv3-elastic-20210721-064117":0,"tf2-keras-cifar10-inceptionv3-elastic-20210721-064215":0,"tf2-keras-cifar10-resnet50-elastic-20210721-064451":0,"tf2-keras-cifar10-vgg16-elastic-20210721-064310":0,"tf2-keras-transformer-elastic-20210721-063654":2,"tf2-keras-transformer-elastic-20210721-063721":2,"tf2-keras-transformer-elastic-20210721-063927":0,"tf2-keras-transformer-elastic-20210721-064152":0,"tf2-keras-transformer-elastic-20210721-064332":0,"tf2-keras-transformer-elastic-20210721-064545":2} "scheduler"="default" "thresholds"=
I0721 19:47:12.313059    1186 scheduler.go:384]  "msg"="Trying to delete multiple training jobs"  "jobs"=["tf2-keras-cifar10-inceptionv3-elastic-20210721-063448"] "scheduler"="default"
I0721 19:47:12.322263    1186 scheduler.go:342]  "msg"="Trying to scale multiple training jobs"  "jobs"=[] "scheduler"="default"
I0721 19:47:12.322479    1186 scheduler.go:292]  "msg"="Trying to start multiple training jobs"  "jobs"=["tf2-keras-transformer-elastic-20210721-064545"] "scheduler"="default"
I0721 19:47:12.335793    1186 scheduler.go:342]  "msg"="Trying to scale multiple training jobs"  "jobs"=[] "scheduler"="default"
I0721 19:47:12.338926    1186 placement_manager.go:166]  "msg"="Started job placements adjustment"  "scheduler"="default"
I0721 19:47:12.338990    1186 placement_manager.go:192]  "msg"="Releasing slots"  "jobs"={"tf2-keras-cifar10-inceptionv3-elastic-20210721-063448":{},"tf2-keras-cifar10-inceptionv3-elastic-20210721-063539":{},"tf2-keras-cifar10-inceptionv3-elastic-20210721-063756":{},"tf2-keras-cifar10-inceptionv3-elastic-20210721-063900":{},"tf2-keras-transformer-elastic-20210721-063654":{},"tf2-keras-transformer-elastic-20210721-063721":{}} "nodes"={"gpu3":{},"gpu4":{},"gpu5":{}} "scheduler"="default"
I0721 19:47:12.339073    1186 placement_manager.go:250]  "msg"="Released slots"  "jobs"={"tf2-keras-cifar10-inceptionv3-elastic-20210721-063448":{},"tf2-keras-cifar10-inceptionv3-elastic-20210721-063539":{},"tf2-keras-cifar10-inceptionv3-elastic-20210721-063756":{},"tf2-keras-cifar10-inceptionv3-elastic-20210721-063900":{},"tf2-keras-transformer-elastic-20210721-063654":{},"tf2-keras-transformer-elastic-20210721-063721":{}} "nodes"={"gpu3":{},"gpu4":{},"gpu5":{}} "scheduler"="default"
I0721 19:47:12.339526    1186 placement_manager.go:305]  "msg"="Found best-fit"  "crossNode"=0 "nodes"=[{},{},{}] "requests"=[{},{},{},{},{},{},{},{},{},{},{},{},{},{},{},{},{},{},{},{},{},{},{},{},{},{},{},{}] "scheduler"="default"
I0721 19:47:12.339844    1186 placement_manager.go:339]  "msg"="nodeStates updated"  "new"={"gpu3":{},"gpu4":{},"gpu5":{}} "old"={"gpu3":{},"gpu4":{},"gpu5":{}} "scheduler"="default" "score"=8
I0721 19:47:12.340140    1186 placement_manager.go:387]  "msg"="jobStates updated"  "new"={"tf2-keras-cifar10-inceptionv3-elastic-20210721-063539":{},"tf2-keras-cifar10-inceptionv3-elastic-20210721-063756":{},"tf2-keras-cifar10-inceptionv3-elastic-20210721-063900":{},"tf2-keras-transformer-elastic-20210721-063654":{},"tf2-keras-transformer-elastic-20210721-063721":{},"tf2-keras-transformer-elastic-20210721-064545":{}} "old"={"tf2-keras-cifar10-inceptionv3-elastic-20210721-063448":{},"tf2-keras-cifar10-inceptionv3-elastic-20210721-063539":{},"tf2-keras-cifar10-inceptionv3-elastic-20210721-063756":{},"tf2-keras-cifar10-inceptionv3-elastic-20210721-063900":{},"tf2-keras-transformer-elastic-20210721-063654":{},"tf2-keras-transformer-elastic-20210721-063721":{}} "scheduler"="default"
I0721 19:47:12.340509    1186 placement_manager.go:434]  "msg"="podNodeName updated"  "launchersToDelete"=1 "new"={"tf2-keras-cifar10-inceptionv3-elastic-20210721-063539-worker-0":"gpu5","tf2-keras-cifar10-inceptionv3-elastic-20210721-063539-worker-1":"gpu5","tf2-keras-cifar10-inceptionv3-elastic-20210721-063756-worker-0":"gpu4","tf2-keras-cifar10-inceptionv3-elastic-20210721-063756-worker-1":"gpu4","tf2-keras-cifar10-inceptionv3-elastic-20210721-063900-worker-0":"gpu5","tf2-keras-cifar10-inceptionv3-elastic-20210721-063900-worker-1":"gpu5","tf2-keras-transformer-elastic-20210721-063654-worker-0":"gpu4","tf2-keras-transformer-elastic-20210721-063654-worker-1":"gpu4","tf2-keras-transformer-elastic-20210721-063721-worker-0":"gpu3","tf2-keras-transformer-elastic-20210721-063721-worker-1":"gpu3","tf2-keras-transformer-elastic-20210721-064545-worker-0":"gpu3","tf2-keras-transformer-elastic-20210721-064545-worker-1":"gpu3"} "old"={"tf2-keras-cifar10-inceptionv3-elastic-20210721-063448-worker-0":"gpu4","tf2-keras-cifar10-inceptionv3-elastic-20210721-063448-worker-1":"gpu4","tf2-keras-cifar10-inceptionv3-elastic-20210721-063539-worker-0":"gpu5","tf2-keras-cifar10-inceptionv3-elastic-20210721-063539-worker-1":"gpu5","tf2-keras-cifar10-inceptionv3-elastic-20210721-063756-worker-0":"gpu3","tf2-keras-cifar10-inceptionv3-elastic-20210721-063756-worker-1":"gpu3","tf2-keras-cifar10-inceptionv3-elastic-20210721-063900-worker-0":"gpu5","tf2-keras-cifar10-inceptionv3-elastic-20210721-063900-worker-1":"gpu5","tf2-keras-transformer-elastic-20210721-063654-worker-0":"gpu4","tf2-keras-transformer-elastic-20210721-063654-worker-1":"gpu4","tf2-keras-transformer-elastic-20210721-063721-worker-0":"gpu3","tf2-keras-transformer-elastic-20210721-063721-worker-1":"gpu3"} "scheduler"="default" "workersToDelete"=2
I0721 19:47:12.340816    1186 placement_manager.go:451]  "msg"="Deleting pod that need migration"  "podName"="tf2-keras-cifar10-inceptionv3-elastic-20210721-063756-worker-0" "scheduler"="default"
I0721 19:47:12.346643    1186 placement_manager.go:451]  "msg"="Deleting pod that need migration"  "podName"="tf2-keras-cifar10-inceptionv3-elastic-20210721-063756-worker-1" "scheduler"="default"
I0721 19:47:12.352066    1186 placement_manager.go:451]  "msg"="Deleting pod that need migration"  "podName"="tf2-keras-cifar10-inceptionv3-elastic-20210721-063756-launcher" "scheduler"="default"
I0721 19:47:12.361150    1186 placement_manager.go:183]  "msg"="Finished job placements adjustment"  "scheduler"="default"
I0721 19:47:12.361443    1186 scheduler.go:182]  "msg"="Finished resched"  "scheduler"="default"
I0721 19:47:12.385950    1186 placement_manager.go:147]  "msg"="Adding toleration to pod"  "podName"="tf2-keras-transformer-elastic-20210721-064545-worker-0" "scheduler"="default" "toleration"={"key":"celeste/hostname","operator":"Equal","value":"gpu3","effect":"NoExecute"}
I0721 19:47:12.416601    1186 placement_manager.go:147]  "msg"="Adding toleration to pod"  "podName"="tf2-keras-transformer-elastic-20210721-064545-worker-1" "scheduler"="default" "toleration"={"key":"celeste/hostname","operator":"Equal","value":"gpu3","effect":"NoExecute"}
I0721 19:47:12.425613    1186 placement_manager.go:147]  "msg"="Adding toleration to pod"  "podName"="tf2-keras-transformer-elastic-20210721-064545-launcher" "scheduler"="default" "toleration"={"key":"celeste/hostname","operator":"Exists","effect":"NoExecute"}
I0721 19:47:19.836936    1186 placement_manager.go:147]  "msg"="Adding toleration to pod"  "podName"="tf2-keras-cifar10-inceptionv3-elastic-20210721-063756-worker-1" "scheduler"="default" "toleration"={"key":"celeste/hostname","operator":"Equal","value":"gpu4","effect":"NoExecute"}
I0721 19:47:25.258158    1186 placement_manager.go:147]  "msg"="Adding toleration to pod"  "podName"="tf2-keras-cifar10-inceptionv3-elastic-20210721-063756-launcher" "scheduler"="default" "toleration"={"key":"celeste/hostname","operator":"Exists","effect":"NoExecute"}
I0721 19:47:30.023027    1186 placement_manager.go:147]  "msg"="Adding toleration to pod"  "podName"="tf2-keras-cifar10-inceptionv3-elastic-20210721-063756-worker-0" "scheduler"="default" "toleration"={"key":"celeste/hostname","operator":"Equal","value":"gpu4","effect":"NoExecute"}
I0721 19:49:11.611760    1186 scheduler.go:559]  "msg"="Priority demoted to training job"  "job"="tf2-keras-cifar10-inceptionv3-elastic-20210721-063539" "priority"=1 "scheduler"="default"
I0721 19:49:11.611804    1186 scheduler.go:573]  "msg"="Priority changed"  "scheduler"="default"
I0721 19:49:11.611855    1186 scheduler.go:135]  "msg"="Received resched event, may be blocked because of rate limit"  "blockedUntil"="2021-07-21T19:49:12.361720608+08:00" "lastResched"="2021-07-21T19:47:12.361720608+08:00" "received"="2021-07-21T19:49:11.611807314+08:00" "scheduler"="default"
I0721 19:49:12.361856    1186 scheduler.go:159]  "msg"="Started resched"  "scheduler"="default"
I0721 19:49:12.361960    1186 scheduler.go:193]  "msg"="Updating all jobs info"  "scheduler"="default"
I0721 19:49:12.371501    1186 elastic_tiresias.go:160]  "msg"="Finished scheduling"  "algorithm"="ElasticTiresias" "compactionThreshold"=4 "freeGpu"=0 "promoteKnob"=4 "queueNum"=2 "result"={"tf2-keras-cifar10-inceptionv3-elastic-20210721-063448":1,"tf2-keras-cifar10-inceptionv3-elastic-20210721-063539":0,"tf2-keras-cifar10-inceptionv3-elastic-20210721-063756":3,"tf2-keras-cifar10-inceptionv3-elastic-20210721-063900":2,"tf2-keras-cifar10-inceptionv3-elastic-20210721-064117":0,"tf2-keras-cifar10-inceptionv3-elastic-20210721-064215":0,"tf2-keras-cifar10-resnet50-elastic-20210721-064451":0,"tf2-keras-cifar10-vgg16-elastic-20210721-064310":0,"tf2-keras-transformer-elastic-20210721-063654":2,"tf2-keras-transformer-elastic-20210721-063721":2,"tf2-keras-transformer-elastic-20210721-063927":0,"tf2-keras-transformer-elastic-20210721-064152":0,"tf2-keras-transformer-elastic-20210721-064332":0,"tf2-keras-transformer-elastic-20210721-064545":2} "scheduler"="default" "thresholds"=
I0721 19:49:12.371799    1186 scheduler.go:384]  "msg"="Trying to delete multiple training jobs"  "jobs"=["tf2-keras-cifar10-inceptionv3-elastic-20210721-063539"] "scheduler"="default"
I0721 19:49:12.383737    1186 scheduler.go:342]  "msg"="Trying to scale multiple training jobs"  "jobs"=[] "scheduler"="default"
I0721 19:49:12.384005    1186 scheduler.go:292]  "msg"="Trying to start multiple training jobs"  "jobs"=["tf2-keras-cifar10-inceptionv3-elastic-20210721-063448"] "scheduler"="default"
I0721 19:49:12.399655    1186 scheduler.go:342]  "msg"="Trying to scale multiple training jobs"  "jobs"=["tf2-keras-cifar10-inceptionv3-elastic-20210721-063756"] "scheduler"="default"
I0721 19:49:12.444130    1186 placement_manager.go:166]  "msg"="Started job placements adjustment"  "scheduler"="default"
I0721 19:49:12.444218    1186 placement_manager.go:192]  "msg"="Releasing slots"  "jobs"={"tf2-keras-cifar10-inceptionv3-elastic-20210721-063539":{},"tf2-keras-cifar10-inceptionv3-elastic-20210721-063756":{},"tf2-keras-cifar10-inceptionv3-elastic-20210721-063900":{},"tf2-keras-transformer-elastic-20210721-063654":{},"tf2-keras-transformer-elastic-20210721-063721":{},"tf2-keras-transformer-elastic-20210721-064545":{}} "nodes"={"gpu3":{},"gpu4":{},"gpu5":{}} "scheduler"="default"
I0721 19:49:12.444318    1186 placement_manager.go:250]  "msg"="Released slots"  "jobs"={"tf2-keras-cifar10-inceptionv3-elastic-20210721-063539":{},"tf2-keras-cifar10-inceptionv3-elastic-20210721-063756":{},"tf2-keras-cifar10-inceptionv3-elastic-20210721-063900":{},"tf2-keras-transformer-elastic-20210721-063654":{},"tf2-keras-transformer-elastic-20210721-063721":{},"tf2-keras-transformer-elastic-20210721-064545":{}} "nodes"={"gpu3":{},"gpu4":{},"gpu5":{}} "scheduler"="default"
I0721 19:49:12.444821    1186 placement_manager.go:305]  "msg"="Found best-fit"  "crossNode"=0 "nodes"=[{},{},{}] "requests"=[{},{},{},{},{},{},{},{},{},{},{},{},{},{},{},{},{},{},{},{},{},{},{},{},{},{},{},{}] "scheduler"="default"
I0721 19:49:12.445158    1186 placement_manager.go:339]  "msg"="nodeStates updated"  "new"={"gpu3":{},"gpu4":{},"gpu5":{}} "old"={"gpu3":{},"gpu4":{},"gpu5":{}} "scheduler"="default" "score"=6
I0721 19:49:12.445497    1186 placement_manager.go:387]  "msg"="jobStates updated"  "new"={"tf2-keras-cifar10-inceptionv3-elastic-20210721-063448":{},"tf2-keras-cifar10-inceptionv3-elastic-20210721-063756":{},"tf2-keras-cifar10-inceptionv3-elastic-20210721-063900":{},"tf2-keras-transformer-elastic-20210721-063654":{},"tf2-keras-transformer-elastic-20210721-063721":{},"tf2-keras-transformer-elastic-20210721-064545":{}} "old"={"tf2-keras-cifar10-inceptionv3-elastic-20210721-063539":{},"tf2-keras-cifar10-inceptionv3-elastic-20210721-063756":{},"tf2-keras-cifar10-inceptionv3-elastic-20210721-063900":{},"tf2-keras-transformer-elastic-20210721-063654":{},"tf2-keras-transformer-elastic-20210721-063721":{},"tf2-keras-transformer-elastic-20210721-064545":{}} "scheduler"="default"
I0721 19:49:12.445953    1186 placement_manager.go:434]  "msg"="podNodeName updated"  "launchersToDelete"=2 "new"={"tf2-keras-cifar10-inceptionv3-elastic-20210721-063448-worker-0":"gpu4","tf2-keras-cifar10-inceptionv3-elastic-20210721-063756-worker-0":"gpu4","tf2-keras-cifar10-inceptionv3-elastic-20210721-063756-worker-1":"gpu4","tf2-keras-cifar10-inceptionv3-elastic-20210721-063756-worker-2":"gpu4","tf2-keras-cifar10-inceptionv3-elastic-20210721-063900-worker-0":"gpu5","tf2-keras-cifar10-inceptionv3-elastic-20210721-063900-worker-1":"gpu5","tf2-keras-transformer-elastic-20210721-063654-worker-0":"gpu3","tf2-keras-transformer-elastic-20210721-063654-worker-1":"gpu3","tf2-keras-transformer-elastic-20210721-063721-worker-0":"gpu5","tf2-keras-transformer-elastic-20210721-063721-worker-1":"gpu5","tf2-keras-transformer-elastic-20210721-064545-worker-0":"gpu3","tf2-keras-transformer-elastic-20210721-064545-worker-1":"gpu3"} "old"={"tf2-keras-cifar10-inceptionv3-elastic-20210721-063539-worker-0":"gpu5","tf2-keras-cifar10-inceptionv3-elastic-20210721-063539-worker-1":"gpu5","tf2-keras-cifar10-inceptionv3-elastic-20210721-063756-worker-0":"gpu4","tf2-keras-cifar10-inceptionv3-elastic-20210721-063756-worker-1":"gpu4","tf2-keras-cifar10-inceptionv3-elastic-20210721-063900-worker-0":"gpu5","tf2-keras-cifar10-inceptionv3-elastic-20210721-063900-worker-1":"gpu5","tf2-keras-transformer-elastic-20210721-063654-worker-0":"gpu4","tf2-keras-transformer-elastic-20210721-063654-worker-1":"gpu4","tf2-keras-transformer-elastic-20210721-063721-worker-0":"gpu3","tf2-keras-transformer-elastic-20210721-063721-worker-1":"gpu3","tf2-keras-transformer-elastic-20210721-064545-worker-0":"gpu3","tf2-keras-transformer-elastic-20210721-064545-worker-1":"gpu3"} "scheduler"="default" "workersToDelete"=4
I0721 19:49:12.446282    1186 placement_manager.go:451]  "msg"="Deleting pod that need migration"  "podName"="tf2-keras-transformer-elastic-20210721-063654-worker-0" "scheduler"="default"
I0721 19:49:12.449998    1186 placement_manager.go:451]  "msg"="Deleting pod that need migration"  "podName"="tf2-keras-transformer-elastic-20210721-063654-worker-1" "scheduler"="default"
I0721 19:49:12.452932    1186 placement_manager.go:451]  "msg"="Deleting pod that need migration"  "podName"="tf2-keras-transformer-elastic-20210721-063654-launcher" "scheduler"="default"
I0721 19:49:12.455964    1186 placement_manager.go:451]  "msg"="Deleting pod that need migration"  "podName"="tf2-keras-transformer-elastic-20210721-063721-worker-0" "scheduler"="default"
I0721 19:49:12.471725    1186 placement_manager.go:451]  "msg"="Deleting pod that need migration"  "podName"="tf2-keras-transformer-elastic-20210721-063721-worker-1" "scheduler"="default"
I0721 19:49:12.473052    1186 placement_manager.go:147]  "msg"="Adding toleration to pod"  "podName"="tf2-keras-cifar10-inceptionv3-elastic-20210721-063448-worker-0" "scheduler"="default" "toleration"={"key":"celeste/hostname","operator":"Equal","value":"gpu4","effect":"NoExecute"}
I0721 19:49:12.475267    1186 placement_manager.go:451]  "msg"="Deleting pod that need migration"  "podName"="tf2-keras-transformer-elastic-20210721-063721-launcher" "scheduler"="default"
I0721 19:49:12.481966    1186 placement_manager.go:183]  "msg"="Finished job placements adjustment"  "scheduler"="default"
I0721 19:49:12.482303    1186 scheduler.go:182]  "msg"="Finished resched"  "scheduler"="default"
I0721 19:49:12.501215    1186 placement_manager.go:147]  "msg"="Adding toleration to pod"  "podName"="tf2-keras-cifar10-inceptionv3-elastic-20210721-063756-worker-2" "scheduler"="default" "toleration"={"key":"celeste/hostname","operator":"Equal","value":"gpu4","effect":"NoExecute"}
I0721 19:49:12.855371    1186 placement_manager.go:147]  "msg"="Adding toleration to pod"  "podName"="tf2-keras-cifar10-inceptionv3-elastic-20210721-063448-launcher" "scheduler"="default" "toleration"={"key":"celeste/hostname","operator":"Exists","effect":"NoExecute"}
I0721 19:49:16.612028    1186 scheduler.go:565]  "msg"="Priority promoted to training job"  "job"="tf2-keras-cifar10-inceptionv3-elastic-20210721-063448" "priority"=0 "scheduler"="default"
I0721 19:49:16.612105    1186 scheduler.go:573]  "msg"="Priority changed"  "scheduler"="default"
I0721 19:49:16.612181    1186 scheduler.go:135]  "msg"="Received resched event, may be blocked because of rate limit"  "blockedUntil"="2021-07-21T19:51:12.482627582+08:00" "lastResched"="2021-07-21T19:49:12.482627582+08:00" "received"="2021-07-21T19:49:16.612114083+08:00" "scheduler"="default"
I0721 19:49:19.809643    1186 placement_manager.go:147]  "msg"="Adding toleration to pod"  "podName"="tf2-keras-transformer-elastic-20210721-063721-worker-0" "scheduler"="default" "toleration"={"key":"celeste/hostname","operator":"Equal","value":"gpu5","effect":"NoExecute"}
I0721 19:49:20.715475    1186 placement_manager.go:147]  "msg"="Adding toleration to pod"  "podName"="tf2-keras-transformer-elastic-20210721-063721-launcher" "scheduler"="default" "toleration"={"key":"celeste/hostname","operator":"Exists","effect":"NoExecute"}
I0721 19:49:24.600605    1186 placement_manager.go:147]  "msg"="Adding toleration to pod"  "podName"="tf2-keras-transformer-elastic-20210721-063654-worker-0" "scheduler"="default" "toleration"={"key":"celeste/hostname","operator":"Equal","value":"gpu3","effect":"NoExecute"}
I0721 19:49:24.631932    1186 placement_manager.go:147]  "msg"="Adding toleration to pod"  "podName"="tf2-keras-transformer-elastic-20210721-063654-worker-1" "scheduler"="default" "toleration"={"key":"celeste/hostname","operator":"Equal","value":"gpu3","effect":"NoExecute"}
I0721 19:49:29.266192    1186 placement_manager.go:147]  "msg"="Adding toleration to pod"  "podName"="tf2-keras-transformer-elastic-20210721-063721-worker-1" "scheduler"="default" "toleration"={"key":"celeste/hostname","operator":"Equal","value":"gpu5","effect":"NoExecute"}
I0721 19:49:32.091984    1186 placement_manager.go:147]  "msg"="Adding toleration to pod"  "podName"="tf2-keras-transformer-elastic-20210721-063654-launcher" "scheduler"="default" "toleration"={"key":"celeste/hostname","operator":"Exists","effect":"NoExecute"}
I0721 19:51:12.482710    1186 scheduler.go:159]  "msg"="Started resched"  "scheduler"="default"
I0721 19:51:12.482812    1186 scheduler.go:193]  "msg"="Updating all jobs info"  "scheduler"="default"
I0721 19:51:12.493196    1186 elastic_tiresias.go:160]  "msg"="Finished scheduling"  "algorithm"="ElasticTiresias" "compactionThreshold"=4 "freeGpu"=0 "promoteKnob"=4 "queueNum"=2 "result"={"tf2-keras-cifar10-inceptionv3-elastic-20210721-063448":2,"tf2-keras-cifar10-inceptionv3-elastic-20210721-063539":0,"tf2-keras-cifar10-inceptionv3-elastic-20210721-063756":2,"tf2-keras-cifar10-inceptionv3-elastic-20210721-063900":2,"tf2-keras-cifar10-inceptionv3-elastic-20210721-064117":0,"tf2-keras-cifar10-inceptionv3-elastic-20210721-064215":0,"tf2-keras-cifar10-resnet50-elastic-20210721-064451":0,"tf2-keras-cifar10-vgg16-elastic-20210721-064310":0,"tf2-keras-transformer-elastic-20210721-063654":2,"tf2-keras-transformer-elastic-20210721-063721":2,"tf2-keras-transformer-elastic-20210721-063927":0,"tf2-keras-transformer-elastic-20210721-064152":0,"tf2-keras-transformer-elastic-20210721-064332":0,"tf2-keras-transformer-elastic-20210721-064545":2} "scheduler"="default" "thresholds"=
I0721 19:51:12.493459    1186 scheduler.go:384]  "msg"="Trying to delete multiple training jobs"  "jobs"=[] "scheduler"="default"
I0721 19:51:12.493723    1186 scheduler.go:342]  "msg"="Trying to scale multiple training jobs"  "jobs"=["tf2-keras-cifar10-inceptionv3-elastic-20210721-063756"] "scheduler"="default"
I0721 19:51:12.513078    1186 scheduler.go:292]  "msg"="Trying to start multiple training jobs"  "jobs"=[] "scheduler"="default"
I0721 19:51:12.513438    1186 scheduler.go:342]  "msg"="Trying to scale multiple training jobs"  "jobs"=["tf2-keras-cifar10-inceptionv3-elastic-20210721-063448"] "scheduler"="default"
I0721 19:51:12.540841    1186 placement_manager.go:166]  "msg"="Started job placements adjustment"  "scheduler"="default"
I0721 19:51:12.540967    1186 placement_manager.go:192]  "msg"="Releasing slots"  "jobs"={"tf2-keras-cifar10-inceptionv3-elastic-20210721-063448":{},"tf2-keras-cifar10-inceptionv3-elastic-20210721-063756":{},"tf2-keras-cifar10-inceptionv3-elastic-20210721-063900":{},"tf2-keras-transformer-elastic-20210721-063654":{},"tf2-keras-transformer-elastic-20210721-063721":{},"tf2-keras-transformer-elastic-20210721-064545":{}} "nodes"={"gpu3":{},"gpu4":{},"gpu5":{}} "scheduler"="default"
I0721 19:51:12.541036    1186 placement_manager.go:250]  "msg"="Released slots"  "jobs"={"tf2-keras-cifar10-inceptionv3-elastic-20210721-063448":{},"tf2-keras-cifar10-inceptionv3-elastic-20210721-063756":{},"tf2-keras-cifar10-inceptionv3-elastic-20210721-063900":{},"tf2-keras-transformer-elastic-20210721-063654":{},"tf2-keras-transformer-elastic-20210721-063721":{},"tf2-keras-transformer-elastic-20210721-064545":{}} "nodes"={"gpu3":{},"gpu4":{},"gpu5":{}} "scheduler"="default"
I0721 19:51:12.541629    1186 placement_manager.go:305]  "msg"="Found best-fit"  "crossNode"=0 "nodes"=[{},{},{}] "requests"=[{},{},{},{},{},{},{},{},{},{},{},{},{},{},{},{},{},{},{},{},{},{},{},{},{},{},{},{}] "scheduler"="default"
I0721 19:51:12.541963    1186 placement_manager.go:339]  "msg"="nodeStates updated"  "new"={"gpu3":{},"gpu4":{},"gpu5":{}} "old"={"gpu3":{},"gpu4":{},"gpu5":{}} "scheduler"="default" "score"=6
I0721 19:51:12.542326    1186 placement_manager.go:387]  "msg"="jobStates updated"  "new"={"tf2-keras-cifar10-inceptionv3-elastic-20210721-063448":{},"tf2-keras-cifar10-inceptionv3-elastic-20210721-063756":{},"tf2-keras-cifar10-inceptionv3-elastic-20210721-063900":{},"tf2-keras-transformer-elastic-20210721-063654":{},"tf2-keras-transformer-elastic-20210721-063721":{},"tf2-keras-transformer-elastic-20210721-064545":{}} "old"={"tf2-keras-cifar10-inceptionv3-elastic-20210721-063448":{},"tf2-keras-cifar10-inceptionv3-elastic-20210721-063756":{},"tf2-keras-cifar10-inceptionv3-elastic-20210721-063900":{},"tf2-keras-transformer-elastic-20210721-063654":{},"tf2-keras-transformer-elastic-20210721-063721":{},"tf2-keras-transformer-elastic-20210721-064545":{}} "scheduler"="default"
I0721 19:51:12.542783    1186 placement_manager.go:434]  "msg"="podNodeName updated"  "launchersToDelete"=2 "new"={"tf2-keras-cifar10-inceptionv3-elastic-20210721-063448-worker-0":"gpu3","tf2-keras-cifar10-inceptionv3-elastic-20210721-063448-worker-1":"gpu3","tf2-keras-cifar10-inceptionv3-elastic-20210721-063756-worker-0":"gpu4","tf2-keras-cifar10-inceptionv3-elastic-20210721-063756-worker-1":"gpu4","tf2-keras-cifar10-inceptionv3-elastic-20210721-063900-worker-0":"gpu5","tf2-keras-cifar10-inceptionv3-elastic-20210721-063900-worker-1":"gpu5","tf2-keras-transformer-elastic-20210721-063654-worker-0":"gpu5","tf2-keras-transformer-elastic-20210721-063654-worker-1":"gpu5","tf2-keras-transformer-elastic-20210721-063721-worker-0":"gpu4","tf2-keras-transformer-elastic-20210721-063721-worker-1":"gpu4","tf2-keras-transformer-elastic-20210721-064545-worker-0":"gpu3","tf2-keras-transformer-elastic-20210721-064545-worker-1":"gpu3"} "old"={"tf2-keras-cifar10-inceptionv3-elastic-20210721-063448-worker-0":"gpu4","tf2-keras-cifar10-inceptionv3-elastic-20210721-063756-worker-0":"gpu4","tf2-keras-cifar10-inceptionv3-elastic-20210721-063756-worker-1":"gpu4","tf2-keras-cifar10-inceptionv3-elastic-20210721-063756-worker-2":"gpu4","tf2-keras-cifar10-inceptionv3-elastic-20210721-063900-worker-0":"gpu5","tf2-keras-cifar10-inceptionv3-elastic-20210721-063900-worker-1":"gpu5","tf2-keras-transformer-elastic-20210721-063654-worker-0":"gpu3","tf2-keras-transformer-elastic-20210721-063654-worker-1":"gpu3","tf2-keras-transformer-elastic-20210721-063721-worker-0":"gpu5","tf2-keras-transformer-elastic-20210721-063721-worker-1":"gpu5","tf2-keras-transformer-elastic-20210721-064545-worker-0":"gpu3","tf2-keras-transformer-elastic-20210721-064545-worker-1":"gpu3"} "scheduler"="default" "workersToDelete"=5
I0721 19:51:12.543177    1186 placement_manager.go:451]  "msg"="Deleting pod that need migration"  "podName"="tf2-keras-cifar10-inceptionv3-elastic-20210721-063448-worker-0" "scheduler"="default"
I0721 19:51:12.550800    1186 placement_manager.go:451]  "msg"="Deleting pod that need migration"  "podName"="tf2-keras-transformer-elastic-20210721-063654-worker-0" "scheduler"="default"
I0721 19:51:12.554151    1186 placement_manager.go:451]  "msg"="Deleting pod that need migration"  "podName"="tf2-keras-transformer-elastic-20210721-063654-worker-1" "scheduler"="default"
I0721 19:51:12.567983    1186 placement_manager.go:451]  "msg"="Deleting pod that need migration"  "podName"="tf2-keras-transformer-elastic-20210721-063654-launcher" "scheduler"="default"
I0721 19:51:12.575262    1186 placement_manager.go:451]  "msg"="Deleting pod that need migration"  "podName"="tf2-keras-transformer-elastic-20210721-063721-worker-0" "scheduler"="default"
I0721 19:51:12.582426    1186 placement_manager.go:147]  "msg"="Adding toleration to pod"  "podName"="tf2-keras-cifar10-inceptionv3-elastic-20210721-063448-worker-1" "scheduler"="default" "toleration"={"key":"celeste/hostname","operator":"Equal","value":"gpu3","effect":"NoExecute"}
I0721 19:51:12.584036    1186 placement_manager.go:451]  "msg"="Deleting pod that need migration"  "podName"="tf2-keras-transformer-elastic-20210721-063721-worker-1" "scheduler"="default"
I0721 19:51:12.596721    1186 placement_manager.go:451]  "msg"="Deleting pod that need migration"  "podName"="tf2-keras-transformer-elastic-20210721-063721-launcher" "scheduler"="default"
I0721 19:51:12.603829    1186 placement_manager.go:183]  "msg"="Finished job placements adjustment"  "scheduler"="default"
I0721 19:51:12.604037    1186 scheduler.go:182]  "msg"="Finished resched"  "scheduler"="default"
I0721 19:51:19.347650    1186 placement_manager.go:147]  "msg"="Adding toleration to pod"  "podName"="tf2-keras-transformer-elastic-20210721-063654-launcher" "scheduler"="default" "toleration"={"key":"celeste/hostname","operator":"Exists","effect":"NoExecute"}
I0721 19:51:20.753370    1186 placement_manager.go:147]  "msg"="Adding toleration to pod"  "podName"="tf2-keras-transformer-elastic-20210721-063721-worker-1" "scheduler"="default" "toleration"={"key":"celeste/hostname","operator":"Equal","value":"gpu4","effect":"NoExecute"}
I0721 19:51:24.600635    1186 placement_manager.go:147]  "msg"="Adding toleration to pod"  "podName"="tf2-keras-cifar10-inceptionv3-elastic-20210721-063448-worker-0" "scheduler"="default" "toleration"={"key":"celeste/hostname","operator":"Equal","value":"gpu3","effect":"NoExecute"}
I0721 19:51:24.749618    1186 placement_manager.go:147]  "msg"="Adding toleration to pod"  "podName"="tf2-keras-transformer-elastic-20210721-063721-launcher" "scheduler"="default" "toleration"={"key":"celeste/hostname","operator":"Exists","effect":"NoExecute"}
I0721 19:51:29.769978    1186 placement_manager.go:147]  "msg"="Adding toleration to pod"  "podName"="tf2-keras-transformer-elastic-20210721-063721-worker-0" "scheduler"="default" "toleration"={"key":"celeste/hostname","operator":"Equal","value":"gpu4","effect":"NoExecute"}
I0721 19:51:29.866606    1186 placement_manager.go:147]  "msg"="Adding toleration to pod"  "podName"="tf2-keras-transformer-elastic-20210721-063654-worker-0" "scheduler"="default" "toleration"={"key":"celeste/hostname","operator":"Equal","value":"gpu5","effect":"NoExecute"}
I0721 19:51:30.671478    1186 placement_manager.go:147]  "msg"="Adding toleration to pod"  "podName"="tf2-keras-transformer-elastic-20210721-063654-worker-1" "scheduler"="default" "toleration"={"key":"celeste/hostname","operator":"Equal","value":"gpu5","effect":"NoExecute"}
I0721 19:54:33.588685    1186 scheduler.go:474]  "msg"="Training job completed"  "elaspedTotalSeconds"=4630.100419629 "gpuTotalSeconds"=3280.11513333 "job"="tf2-keras-transformer-elastic-20210721-063721" "ranTotalSeconds"=1700.059221995 "scheduler"="default" "waitedTotalSeconds"=2930.041197634
I0721 19:54:33.588860    1186 scheduler.go:135]  "msg"="Received resched event, may be blocked because of rate limit"  "blockedUntil"="2021-07-21T19:53:12.604192429+08:00" "lastResched"="2021-07-21T19:51:12.604192429+08:00" "received"="2021-07-21T19:54:33.588727925+08:00" "scheduler"="default"
I0721 19:54:33.589355    1186 scheduler.go:159]  "msg"="Started resched"  "scheduler"="default"
I0721 19:54:33.589424    1186 scheduler.go:193]  "msg"="Updating all jobs info"  "scheduler"="default"
I0721 19:54:33.598394    1186 elastic_tiresias.go:160]  "msg"="Finished scheduling"  "algorithm"="ElasticTiresias" "compactionThreshold"=4 "freeGpu"=0 "promoteKnob"=4 "queueNum"=2 "result"={"tf2-keras-cifar10-inceptionv3-elastic-20210721-063448":2,"tf2-keras-cifar10-inceptionv3-elastic-20210721-063539":1,"tf2-keras-cifar10-inceptionv3-elastic-20210721-063756":3,"tf2-keras-cifar10-inceptionv3-elastic-20210721-063900":2,"tf2-keras-cifar10-inceptionv3-elastic-20210721-064117":0,"tf2-keras-cifar10-inceptionv3-elastic-20210721-064215":0,"tf2-keras-cifar10-resnet50-elastic-20210721-064451":0,"tf2-keras-cifar10-vgg16-elastic-20210721-064310":0,"tf2-keras-transformer-elastic-20210721-063654":2,"tf2-keras-transformer-elastic-20210721-063927":0,"tf2-keras-transformer-elastic-20210721-064152":0,"tf2-keras-transformer-elastic-20210721-064332":0,"tf2-keras-transformer-elastic-20210721-064545":2} "scheduler"="default" "thresholds"=
I0721 19:54:33.598797    1186 scheduler.go:384]  "msg"="Trying to delete multiple training jobs"  "jobs"=[] "scheduler"="default"
I0721 19:54:33.599101    1186 scheduler.go:342]  "msg"="Trying to scale multiple training jobs"  "jobs"=[] "scheduler"="default"
I0721 19:54:33.599401    1186 scheduler.go:292]  "msg"="Trying to start multiple training jobs"  "jobs"=["tf2-keras-cifar10-inceptionv3-elastic-20210721-063539"] "scheduler"="default"
I0721 19:54:33.610450    1186 scheduler.go:342]  "msg"="Trying to scale multiple training jobs"  "jobs"=["tf2-keras-cifar10-inceptionv3-elastic-20210721-063756"] "scheduler"="default"
I0721 19:54:33.627148    1186 placement_manager.go:166]  "msg"="Started job placements adjustment"  "scheduler"="default"
I0721 19:54:33.627215    1186 placement_manager.go:192]  "msg"="Releasing slots"  "jobs"={"tf2-keras-cifar10-inceptionv3-elastic-20210721-063448":{},"tf2-keras-cifar10-inceptionv3-elastic-20210721-063756":{},"tf2-keras-cifar10-inceptionv3-elastic-20210721-063900":{},"tf2-keras-transformer-elastic-20210721-063654":{},"tf2-keras-transformer-elastic-20210721-063721":{},"tf2-keras-transformer-elastic-20210721-064545":{}} "nodes"={"gpu3":{},"gpu4":{},"gpu5":{}} "scheduler"="default"
I0721 19:54:33.627284    1186 placement_manager.go:250]  "msg"="Released slots"  "jobs"={"tf2-keras-cifar10-inceptionv3-elastic-20210721-063448":{},"tf2-keras-cifar10-inceptionv3-elastic-20210721-063756":{},"tf2-keras-cifar10-inceptionv3-elastic-20210721-063900":{},"tf2-keras-transformer-elastic-20210721-063654":{},"tf2-keras-transformer-elastic-20210721-063721":{},"tf2-keras-transformer-elastic-20210721-064545":{}} "nodes"={"gpu3":{},"gpu4":{},"gpu5":{}} "scheduler"="default"
I0721 19:54:33.627659    1186 placement_manager.go:305]  "msg"="Found best-fit"  "crossNode"=0 "nodes"=[{},{},{}] "requests"=[{},{},{},{},{},{},{},{},{},{},{},{},{},{},{},{},{},{},{},{},{},{},{},{},{},{}] "scheduler"="default"
I0721 19:54:33.627964    1186 placement_manager.go:339]  "msg"="nodeStates updated"  "new"={"gpu3":{},"gpu4":{},"gpu5":{}} "old"={"gpu3":{},"gpu4":{},"gpu5":{}} "scheduler"="default" "score"=6
I0721 19:54:33.628243    1186 placement_manager.go:387]  "msg"="jobStates updated"  "new"={"tf2-keras-cifar10-inceptionv3-elastic-20210721-063448":{},"tf2-keras-cifar10-inceptionv3-elastic-20210721-063539":{},"tf2-keras-cifar10-inceptionv3-elastic-20210721-063756":{},"tf2-keras-cifar10-inceptionv3-elastic-20210721-063900":{},"tf2-keras-transformer-elastic-20210721-063654":{},"tf2-keras-transformer-elastic-20210721-064545":{}} "old"={"tf2-keras-cifar10-inceptionv3-elastic-20210721-063448":{},"tf2-keras-cifar10-inceptionv3-elastic-20210721-063756":{},"tf2-keras-cifar10-inceptionv3-elastic-20210721-063900":{},"tf2-keras-transformer-elastic-20210721-063654":{},"tf2-keras-transformer-elastic-20210721-063721":{},"tf2-keras-transformer-elastic-20210721-064545":{}} "scheduler"="default"
I0721 19:54:33.628667    1186 placement_manager.go:434]  "msg"="podNodeName updated"  "launchersToDelete"=2 "new"={"tf2-keras-cifar10-inceptionv3-elastic-20210721-063448-worker-0":"gpu3","tf2-keras-cifar10-inceptionv3-elastic-20210721-063448-worker-1":"gpu3","tf2-keras-cifar10-inceptionv3-elastic-20210721-063539-worker-0":"gpu4","tf2-keras-cifar10-inceptionv3-elastic-20210721-063756-worker-0":"gpu4","tf2-keras-cifar10-inceptionv3-elastic-20210721-063756-worker-1":"gpu4","tf2-keras-cifar10-inceptionv3-elastic-20210721-063756-worker-2":"gpu4","tf2-keras-cifar10-inceptionv3-elastic-20210721-063900-worker-0":"gpu3","tf2-keras-cifar10-inceptionv3-elastic-20210721-063900-worker-1":"gpu3","tf2-keras-transformer-elastic-20210721-063654-worker-0":"gpu5","tf2-keras-transformer-elastic-20210721-063654-worker-1":"gpu5","tf2-keras-transformer-elastic-20210721-064545-worker-0":"gpu5","tf2-keras-transformer-elastic-20210721-064545-worker-1":"gpu5"} "old"={"tf2-keras-cifar10-inceptionv3-elastic-20210721-063448-worker-0":"gpu3","tf2-keras-cifar10-inceptionv3-elastic-20210721-063448-worker-1":"gpu3","tf2-keras-cifar10-inceptionv3-elastic-20210721-063756-worker-0":"gpu4","tf2-keras-cifar10-inceptionv3-elastic-20210721-063756-worker-1":"gpu4","tf2-keras-cifar10-inceptionv3-elastic-20210721-063900-worker-0":"gpu5","tf2-keras-cifar10-inceptionv3-elastic-20210721-063900-worker-1":"gpu5","tf2-keras-transformer-elastic-20210721-063654-worker-0":"gpu5","tf2-keras-transformer-elastic-20210721-063654-worker-1":"gpu5","tf2-keras-transformer-elastic-20210721-063721-worker-0":"gpu4","tf2-keras-transformer-elastic-20210721-063721-worker-1":"gpu4","tf2-keras-transformer-elastic-20210721-064545-worker-0":"gpu3","tf2-keras-transformer-elastic-20210721-064545-worker-1":"gpu3"} "scheduler"="default" "workersToDelete"=4
I0721 19:54:33.628905    1186 placement_manager.go:451]  "msg"="Deleting pod that need migration"  "podName"="tf2-keras-cifar10-inceptionv3-elastic-20210721-063900-worker-0" "scheduler"="default"
I0721 19:54:33.640185    1186 placement_manager.go:451]  "msg"="Deleting pod that need migration"  "podName"="tf2-keras-cifar10-inceptionv3-elastic-20210721-063900-worker-1" "scheduler"="default"
I0721 19:54:33.643894    1186 placement_manager.go:451]  "msg"="Deleting pod that need migration"  "podName"="tf2-keras-cifar10-inceptionv3-elastic-20210721-063900-launcher" "scheduler"="default"
I0721 19:54:33.653033    1186 placement_manager.go:451]  "msg"="Deleting pod that need migration"  "podName"="tf2-keras-transformer-elastic-20210721-064545-worker-0" "scheduler"="default"
I0721 19:54:33.657971    1186 placement_manager.go:451]  "msg"="Deleting pod that need migration"  "podName"="tf2-keras-transformer-elastic-20210721-064545-worker-1" "scheduler"="default"
I0721 19:54:33.661210    1186 placement_manager.go:451]  "msg"="Deleting pod that need migration"  "podName"="tf2-keras-transformer-elastic-20210721-064545-launcher" "scheduler"="default"
I0721 19:54:33.667575    1186 placement_manager.go:183]  "msg"="Finished job placements adjustment"  "scheduler"="default"
I0721 19:54:33.667811    1186 scheduler.go:182]  "msg"="Finished resched"  "scheduler"="default"
I0721 19:54:33.981898    1186 placement_manager.go:147]  "msg"="Adding toleration to pod"  "podName"="tf2-keras-cifar10-inceptionv3-elastic-20210721-063539-worker-0" "scheduler"="default" "toleration"={"key":"celeste/hostname","operator":"Equal","value":"gpu4","effect":"NoExecute"}
I0721 19:54:34.384128    1186 placement_manager.go:147]  "msg"="Adding toleration to pod"  "podName"="tf2-keras-cifar10-inceptionv3-elastic-20210721-063539-launcher" "scheduler"="default" "toleration"={"key":"celeste/hostname","operator":"Exists","effect":"NoExecute"}
I0721 19:54:34.580757    1186 placement_manager.go:147]  "msg"="Adding toleration to pod"  "podName"="tf2-keras-cifar10-inceptionv3-elastic-20210721-063756-worker-2" "scheduler"="default" "toleration"={"key":"celeste/hostname","operator":"Equal","value":"gpu4","effect":"NoExecute"}
I0721 19:54:36.622674    1186 scheduler.go:565]  "msg"="Priority promoted to training job"  "job"="tf2-keras-cifar10-inceptionv3-elastic-20210721-063539" "priority"=0 "scheduler"="default"
I0721 19:54:36.622743    1186 scheduler.go:573]  "msg"="Priority changed"  "scheduler"="default"
I0721 19:54:36.622874    1186 scheduler.go:135]  "msg"="Received resched event, may be blocked because of rate limit"  "blockedUntil"="2021-07-21T19:56:33.667993835+08:00" "lastResched"="2021-07-21T19:54:33.667993835+08:00" "received"="2021-07-21T19:54:36.622752618+08:00" "scheduler"="default"
I0721 19:54:40.634960    1186 placement_manager.go:147]  "msg"="Adding toleration to pod"  "podName"="tf2-keras-cifar10-inceptionv3-elastic-20210721-063900-launcher" "scheduler"="default" "toleration"={"key":"celeste/hostname","operator":"Exists","effect":"NoExecute"}
I0721 19:54:44.597876    1186 placement_manager.go:147]  "msg"="Adding toleration to pod"  "podName"="tf2-keras-transformer-elastic-20210721-064545-launcher" "scheduler"="default" "toleration"={"key":"celeste/hostname","operator":"Exists","effect":"NoExecute"}
I0721 19:54:49.270785    1186 placement_manager.go:147]  "msg"="Adding toleration to pod"  "podName"="tf2-keras-transformer-elastic-20210721-064545-worker-0" "scheduler"="default" "toleration"={"key":"celeste/hostname","operator":"Equal","value":"gpu5","effect":"NoExecute"}
I0721 19:54:49.302212    1186 placement_manager.go:147]  "msg"="Adding toleration to pod"  "podName"="tf2-keras-transformer-elastic-20210721-064545-worker-1" "scheduler"="default" "toleration"={"key":"celeste/hostname","operator":"Equal","value":"gpu5","effect":"NoExecute"}
I0721 19:54:50.527672    1186 placement_manager.go:147]  "msg"="Adding toleration to pod"  "podName"="tf2-keras-cifar10-inceptionv3-elastic-20210721-063900-worker-0" "scheduler"="default" "toleration"={"key":"celeste/hostname","operator":"Equal","value":"gpu3","effect":"NoExecute"}
I0721 19:54:51.331562    1186 placement_manager.go:147]  "msg"="Adding toleration to pod"  "podName"="tf2-keras-cifar10-inceptionv3-elastic-20210721-063900-worker-1" "scheduler"="default" "toleration"={"key":"celeste/hostname","operator":"Equal","value":"gpu3","effect":"NoExecute"}
I0721 19:55:11.623749    1186 scheduler.go:559]  "msg"="Priority demoted to training job"  "job"="tf2-keras-transformer-elastic-20210721-063654" "priority"=1 "scheduler"="default"
I0721 19:55:11.623811    1186 scheduler.go:573]  "msg"="Priority changed"  "scheduler"="default"
I0721 19:55:12.434572    1186 scheduler.go:474]  "msg"="Training job completed"  "elaspedTotalSeconds"=4696.963048346 "gpuTotalSeconds"=3720.123344443 "job"="tf2-keras-transformer-elastic-20210721-063654" "ranTotalSeconds"=1920.063460924 "scheduler"="default" "waitedTotalSeconds"=2776.899587422
I0721 19:56:33.668072    1186 scheduler.go:159]  "msg"="Started resched"  "scheduler"="default"
I0721 19:56:33.668129    1186 scheduler.go:193]  "msg"="Updating all jobs info"  "scheduler"="default"
I0721 19:56:33.676913    1186 elastic_tiresias.go:160]  "msg"="Finished scheduling"  "algorithm"="ElasticTiresias" "compactionThreshold"=4 "freeGpu"=0 "promoteKnob"=4 "queueNum"=2 "result"={"tf2-keras-cifar10-inceptionv3-elastic-20210721-063448":2,"tf2-keras-cifar10-inceptionv3-elastic-20210721-063539":2,"tf2-keras-cifar10-inceptionv3-elastic-20210721-063756":3,"tf2-keras-cifar10-inceptionv3-elastic-20210721-063900":2,"tf2-keras-cifar10-inceptionv3-elastic-20210721-064117":0,"tf2-keras-cifar10-inceptionv3-elastic-20210721-064215":0,"tf2-keras-cifar10-resnet50-elastic-20210721-064451":0,"tf2-keras-cifar10-vgg16-elastic-20210721-064310":0,"tf2-keras-transformer-elastic-20210721-063927":1,"tf2-keras-transformer-elastic-20210721-064152":0,"tf2-keras-transformer-elastic-20210721-064332":0,"tf2-keras-transformer-elastic-20210721-064545":2} "scheduler"="default" "thresholds"=
I0721 19:56:33.677263    1186 scheduler.go:384]  "msg"="Trying to delete multiple training jobs"  "jobs"=[] "scheduler"="default"
I0721 19:56:33.677491    1186 scheduler.go:342]  "msg"="Trying to scale multiple training jobs"  "jobs"=[] "scheduler"="default"
I0721 19:56:33.677803    1186 scheduler.go:292]  "msg"="Trying to start multiple training jobs"  "jobs"=["tf2-keras-transformer-elastic-20210721-063927"] "scheduler"="default"
I0721 19:56:33.687327    1186 scheduler.go:342]  "msg"="Trying to scale multiple training jobs"  "jobs"=["tf2-keras-cifar10-inceptionv3-elastic-20210721-063539"] "scheduler"="default"
I0721 19:56:33.704417    1186 placement_manager.go:166]  "msg"="Started job placements adjustment"  "scheduler"="default"
I0721 19:56:33.704506    1186 placement_manager.go:192]  "msg"="Releasing slots"  "jobs"={"tf2-keras-cifar10-inceptionv3-elastic-20210721-063448":{},"tf2-keras-cifar10-inceptionv3-elastic-20210721-063539":{},"tf2-keras-cifar10-inceptionv3-elastic-20210721-063756":{},"tf2-keras-cifar10-inceptionv3-elastic-20210721-063900":{},"tf2-keras-transformer-elastic-20210721-063654":{},"tf2-keras-transformer-elastic-20210721-064545":{}} "nodes"={"gpu3":{},"gpu4":{},"gpu5":{}} "scheduler"="default"
I0721 19:56:33.704578    1186 placement_manager.go:250]  "msg"="Released slots"  "jobs"={"tf2-keras-cifar10-inceptionv3-elastic-20210721-063448":{},"tf2-keras-cifar10-inceptionv3-elastic-20210721-063539":{},"tf2-keras-cifar10-inceptionv3-elastic-20210721-063756":{},"tf2-keras-cifar10-inceptionv3-elastic-20210721-063900":{},"tf2-keras-transformer-elastic-20210721-063654":{},"tf2-keras-transformer-elastic-20210721-064545":{}} "nodes"={"gpu3":{},"gpu4":{},"gpu5":{}} "scheduler"="default"
I0721 19:56:33.704952    1186 placement_manager.go:305]  "msg"="Found best-fit"  "crossNode"=0 "nodes"=[{},{},{}] "requests"=[{},{},{},{},{},{},{},{},{},{},{},{},{},{},{},{},{},{},{},{},{},{},{},{}] "scheduler"="default"
I0721 19:56:33.705301    1186 placement_manager.go:339]  "msg"="nodeStates updated"  "new"={"gpu3":{},"gpu4":{},"gpu5":{}} "old"={"gpu3":{},"gpu4":{},"gpu5":{}} "scheduler"="default" "score"=7
I0721 19:56:33.705579    1186 placement_manager.go:387]  "msg"="jobStates updated"  "new"={"tf2-keras-cifar10-inceptionv3-elastic-20210721-063448":{},"tf2-keras-cifar10-inceptionv3-elastic-20210721-063539":{},"tf2-keras-cifar10-inceptionv3-elastic-20210721-063756":{},"tf2-keras-cifar10-inceptionv3-elastic-20210721-063900":{},"tf2-keras-transformer-elastic-20210721-063927":{},"tf2-keras-transformer-elastic-20210721-064545":{}} "old"={"tf2-keras-cifar10-inceptionv3-elastic-20210721-063448":{},"tf2-keras-cifar10-inceptionv3-elastic-20210721-063539":{},"tf2-keras-cifar10-inceptionv3-elastic-20210721-063756":{},"tf2-keras-cifar10-inceptionv3-elastic-20210721-063900":{},"tf2-keras-transformer-elastic-20210721-063654":{},"tf2-keras-transformer-elastic-20210721-064545":{}} "scheduler"="default"
I0721 19:56:33.706106    1186 placement_manager.go:434]  "msg"="podNodeName updated"  "launchersToDelete"=1 "new"={"tf2-keras-cifar10-inceptionv3-elastic-20210721-063448-worker-0":"gpu3","tf2-keras-cifar10-inceptionv3-elastic-20210721-063448-worker-1":"gpu3","tf2-keras-cifar10-inceptionv3-elastic-20210721-063539-worker-0":"gpu3","tf2-keras-cifar10-inceptionv3-elastic-20210721-063539-worker-1":"gpu3","tf2-keras-cifar10-inceptionv3-elastic-20210721-063756-worker-0":"gpu4","tf2-keras-cifar10-inceptionv3-elastic-20210721-063756-worker-1":"gpu4","tf2-keras-cifar10-inceptionv3-elastic-20210721-063756-worker-2":"gpu4","tf2-keras-cifar10-inceptionv3-elastic-20210721-063900-worker-0":"gpu5","tf2-keras-cifar10-inceptionv3-elastic-20210721-063900-worker-1":"gpu5","tf2-keras-transformer-elastic-20210721-063927-worker-0":"gpu4","tf2-keras-transformer-elastic-20210721-064545-worker-0":"gpu5","tf2-keras-transformer-elastic-20210721-064545-worker-1":"gpu5"} "old"={"tf2-keras-cifar10-inceptionv3-elastic-20210721-063448-worker-0":"gpu3","tf2-keras-cifar10-inceptionv3-elastic-20210721-063448-worker-1":"gpu3","tf2-keras-cifar10-inceptionv3-elastic-20210721-063539-worker-0":"gpu4","tf2-keras-cifar10-inceptionv3-elastic-20210721-063756-worker-0":"gpu4","tf2-keras-cifar10-inceptionv3-elastic-20210721-063756-worker-1":"gpu4","tf2-keras-cifar10-inceptionv3-elastic-20210721-063756-worker-2":"gpu4","tf2-keras-cifar10-inceptionv3-elastic-20210721-063900-worker-0":"gpu3","tf2-keras-cifar10-inceptionv3-elastic-20210721-063900-worker-1":"gpu3","tf2-keras-transformer-elastic-20210721-063654-worker-0":"gpu5","tf2-keras-transformer-elastic-20210721-063654-worker-1":"gpu5","tf2-keras-transformer-elastic-20210721-064545-worker-0":"gpu5","tf2-keras-transformer-elastic-20210721-064545-worker-1":"gpu5"} "scheduler"="default" "workersToDelete"=3
I0721 19:56:33.706542    1186 placement_manager.go:451]  "msg"="Deleting pod that need migration"  "podName"="tf2-keras-cifar10-inceptionv3-elastic-20210721-063539-worker-0" "scheduler"="default"
I0721 19:56:33.720528    1186 placement_manager.go:451]  "msg"="Deleting pod that need migration"  "podName"="tf2-keras-cifar10-inceptionv3-elastic-20210721-063900-worker-0" "scheduler"="default"
I0721 19:56:33.726681    1186 placement_manager.go:451]  "msg"="Deleting pod that need migration"  "podName"="tf2-keras-cifar10-inceptionv3-elastic-20210721-063900-worker-1" "scheduler"="default"
I0721 19:56:33.734938    1186 placement_manager.go:451]  "msg"="Deleting pod that need migration"  "podName"="tf2-keras-cifar10-inceptionv3-elastic-20210721-063900-launcher" "scheduler"="default"
I0721 19:56:33.738881    1186 placement_manager.go:147]  "msg"="Adding toleration to pod"  "podName"="tf2-keras-cifar10-inceptionv3-elastic-20210721-063539-worker-1" "scheduler"="default" "toleration"={"key":"celeste/hostname","operator":"Equal","value":"gpu3","effect":"NoExecute"}
I0721 19:56:33.748080    1186 placement_manager.go:183]  "msg"="Finished job placements adjustment"  "scheduler"="default"
I0721 19:56:33.748357    1186 scheduler.go:182]  "msg"="Finished resched"  "scheduler"="default"
I0721 19:56:34.095500    1186 placement_manager.go:147]  "msg"="Adding toleration to pod"  "podName"="tf2-keras-transformer-elastic-20210721-063927-worker-0" "scheduler"="default" "toleration"={"key":"celeste/hostname","operator":"Equal","value":"gpu4","effect":"NoExecute"}
I0721 19:56:34.498317    1186 placement_manager.go:147]  "msg"="Adding toleration to pod"  "podName"="tf2-keras-transformer-elastic-20210721-063927-launcher" "scheduler"="default" "toleration"={"key":"celeste/hostname","operator":"Exists","effect":"NoExecute"}
I0721 19:56:36.626048    1186 scheduler.go:565]  "msg"="Priority promoted to training job"  "job"="tf2-keras-transformer-elastic-20210721-063927" "priority"=0 "scheduler"="default"
I0721 19:56:36.626135    1186 scheduler.go:573]  "msg"="Priority changed"  "scheduler"="default"
I0721 19:56:36.626227    1186 scheduler.go:135]  "msg"="Received resched event, may be blocked because of rate limit"  "blockedUntil"="2021-07-21T19:58:33.748626865+08:00" "lastResched"="2021-07-21T19:56:33.748626865+08:00" "received"="2021-07-21T19:56:36.626148973+08:00" "scheduler"="default"
I0721 19:56:41.964735    1186 placement_manager.go:147]  "msg"="Adding toleration to pod"  "podName"="tf2-keras-cifar10-inceptionv3-elastic-20210721-063539-worker-0" "scheduler"="default" "toleration"={"key":"celeste/hostname","operator":"Equal","value":"gpu3","effect":"NoExecute"}
I0721 19:56:49.526175    1186 placement_manager.go:147]  "msg"="Adding toleration to pod"  "podName"="tf2-keras-cifar10-inceptionv3-elastic-20210721-063900-worker-1" "scheduler"="default" "toleration"={"key":"celeste/hostname","operator":"Equal","value":"gpu5","effect":"NoExecute"}
I0721 19:56:49.916668    1186 placement_manager.go:147]  "msg"="Adding toleration to pod"  "podName"="tf2-keras-cifar10-inceptionv3-elastic-20210721-063900-worker-0" "scheduler"="default" "toleration"={"key":"celeste/hostname","operator":"Equal","value":"gpu5","effect":"NoExecute"}
I0721 19:56:49.999707    1186 placement_manager.go:147]  "msg"="Adding toleration to pod"  "podName"="tf2-keras-cifar10-inceptionv3-elastic-20210721-063900-launcher" "scheduler"="default" "toleration"={"key":"celeste/hostname","operator":"Exists","effect":"NoExecute"}
I0721 19:57:01.626862    1186 scheduler.go:559]  "msg"="Priority demoted to training job"  "job"="tf2-keras-cifar10-inceptionv3-elastic-20210721-063756" "priority"=1 "scheduler"="default"
I0721 19:57:01.626945    1186 scheduler.go:573]  "msg"="Priority changed"  "scheduler"="default"
I0721 19:58:33.748732    1186 scheduler.go:159]  "msg"="Started resched"  "scheduler"="default"
I0721 19:58:33.748795    1186 scheduler.go:193]  "msg"="Updating all jobs info"  "scheduler"="default"
I0721 19:58:33.757151    1186 elastic_tiresias.go:160]  "msg"="Finished scheduling"  "algorithm"="ElasticTiresias" "compactionThreshold"=4 "freeGpu"=0 "promoteKnob"=4 "queueNum"=2 "result"={"tf2-keras-cifar10-inceptionv3-elastic-20210721-063448":2,"tf2-keras-cifar10-inceptionv3-elastic-20210721-063539":2,"tf2-keras-cifar10-inceptionv3-elastic-20210721-063756":1,"tf2-keras-cifar10-inceptionv3-elastic-20210721-063900":2,"tf2-keras-cifar10-inceptionv3-elastic-20210721-064117":1,"tf2-keras-cifar10-inceptionv3-elastic-20210721-064215":0,"tf2-keras-cifar10-resnet50-elastic-20210721-064451":0,"tf2-keras-cifar10-vgg16-elastic-20210721-064310":0,"tf2-keras-transformer-elastic-20210721-063927":2,"tf2-keras-transformer-elastic-20210721-064152":0,"tf2-keras-transformer-elastic-20210721-064332":0,"tf2-keras-transformer-elastic-20210721-064545":2} "scheduler"="default" "thresholds"=
I0721 19:58:33.757452    1186 scheduler.go:384]  "msg"="Trying to delete multiple training jobs"  "jobs"=[] "scheduler"="default"
I0721 19:58:33.757737    1186 scheduler.go:342]  "msg"="Trying to scale multiple training jobs"  "jobs"=["tf2-keras-cifar10-inceptionv3-elastic-20210721-063756"] "scheduler"="default"
I0721 19:58:33.777107    1186 scheduler.go:292]  "msg"="Trying to start multiple training jobs"  "jobs"=["tf2-keras-cifar10-inceptionv3-elastic-20210721-064117"] "scheduler"="default"
I0721 19:58:33.784964    1186 scheduler.go:342]  "msg"="Trying to scale multiple training jobs"  "jobs"=["tf2-keras-transformer-elastic-20210721-063927"] "scheduler"="default"
I0721 19:58:33.814677    1186 placement_manager.go:166]  "msg"="Started job placements adjustment"  "scheduler"="default"
I0721 19:58:33.814746    1186 placement_manager.go:192]  "msg"="Releasing slots"  "jobs"={"tf2-keras-cifar10-inceptionv3-elastic-20210721-063448":{},"tf2-keras-cifar10-inceptionv3-elastic-20210721-063539":{},"tf2-keras-cifar10-inceptionv3-elastic-20210721-063756":{},"tf2-keras-cifar10-inceptionv3-elastic-20210721-063900":{},"tf2-keras-transformer-elastic-20210721-063927":{},"tf2-keras-transformer-elastic-20210721-064545":{}} "nodes"={"gpu3":{},"gpu4":{},"gpu5":{}} "scheduler"="default"
I0721 19:58:33.814810    1186 placement_manager.go:250]  "msg"="Released slots"  "jobs"={"tf2-keras-cifar10-inceptionv3-elastic-20210721-063448":{},"tf2-keras-cifar10-inceptionv3-elastic-20210721-063539":{},"tf2-keras-cifar10-inceptionv3-elastic-20210721-063756":{},"tf2-keras-cifar10-inceptionv3-elastic-20210721-063900":{},"tf2-keras-transformer-elastic-20210721-063927":{},"tf2-keras-transformer-elastic-20210721-064545":{}} "nodes"={"gpu3":{},"gpu4":{},"gpu5":{}} "scheduler"="default"
I0721 19:58:33.815286    1186 placement_manager.go:305]  "msg"="Found best-fit"  "crossNode"=0 "nodes"=[{},{},{}] "requests"=[{},{},{},{},{},{},{},{},{},{},{},{},{},{},{},{},{},{},{},{},{},{},{},{}] "scheduler"="default"
I0721 19:58:33.815622    1186 placement_manager.go:339]  "msg"="nodeStates updated"  "new"={"gpu3":{},"gpu4":{},"gpu5":{}} "old"={"gpu3":{},"gpu4":{},"gpu5":{}} "scheduler"="default" "score"=6
I0721 19:58:33.815895    1186 placement_manager.go:387]  "msg"="jobStates updated"  "new"={"tf2-keras-cifar10-inceptionv3-elastic-20210721-063448":{},"tf2-keras-cifar10-inceptionv3-elastic-20210721-063539":{},"tf2-keras-cifar10-inceptionv3-elastic-20210721-063756":{},"tf2-keras-cifar10-inceptionv3-elastic-20210721-063900":{},"tf2-keras-cifar10-inceptionv3-elastic-20210721-064117":{},"tf2-keras-transformer-elastic-20210721-063927":{},"tf2-keras-transformer-elastic-20210721-064545":{}} "old"={"tf2-keras-cifar10-inceptionv3-elastic-20210721-063448":{},"tf2-keras-cifar10-inceptionv3-elastic-20210721-063539":{},"tf2-keras-cifar10-inceptionv3-elastic-20210721-063756":{},"tf2-keras-cifar10-inceptionv3-elastic-20210721-063900":{},"tf2-keras-transformer-elastic-20210721-063927":{},"tf2-keras-transformer-elastic-20210721-064545":{}} "scheduler"="default"
I0721 19:58:33.816303    1186 placement_manager.go:434]  "msg"="podNodeName updated"  "launchersToDelete"=2 "new"={"tf2-keras-cifar10-inceptionv3-elastic-20210721-063448-worker-0":"gpu5","tf2-keras-cifar10-inceptionv3-elastic-20210721-063448-worker-1":"gpu5","tf2-keras-cifar10-inceptionv3-elastic-20210721-063539-worker-0":"gpu3","tf2-keras-cifar10-inceptionv3-elastic-20210721-063539-worker-1":"gpu3","tf2-keras-cifar10-inceptionv3-elastic-20210721-063756-worker-0":"gpu4","tf2-keras-cifar10-inceptionv3-elastic-20210721-063900-worker-0":"gpu5","tf2-keras-cifar10-inceptionv3-elastic-20210721-063900-worker-1":"gpu5","tf2-keras-cifar10-inceptionv3-elastic-20210721-064117-worker-0":"gpu4","tf2-keras-transformer-elastic-20210721-063927-worker-0":"gpu4","tf2-keras-transformer-elastic-20210721-063927-worker-1":"gpu4","tf2-keras-transformer-elastic-20210721-064545-worker-0":"gpu3","tf2-keras-transformer-elastic-20210721-064545-worker-1":"gpu3"} "old"={"tf2-keras-cifar10-inceptionv3-elastic-20210721-063448-worker-0":"gpu3","tf2-keras-cifar10-inceptionv3-elastic-20210721-063448-worker-1":"gpu3","tf2-keras-cifar10-inceptionv3-elastic-20210721-063539-worker-0":"gpu3","tf2-keras-cifar10-inceptionv3-elastic-20210721-063539-worker-1":"gpu3","tf2-keras-cifar10-inceptionv3-elastic-20210721-063756-worker-0":"gpu4","tf2-keras-cifar10-inceptionv3-elastic-20210721-063756-worker-1":"gpu4","tf2-keras-cifar10-inceptionv3-elastic-20210721-063756-worker-2":"gpu4","tf2-keras-cifar10-inceptionv3-elastic-20210721-063900-worker-0":"gpu5","tf2-keras-cifar10-inceptionv3-elastic-20210721-063900-worker-1":"gpu5","tf2-keras-transformer-elastic-20210721-063927-worker-0":"gpu4","tf2-keras-transformer-elastic-20210721-064545-worker-0":"gpu5","tf2-keras-transformer-elastic-20210721-064545-worker-1":"gpu5"} "scheduler"="default" "workersToDelete"=4
I0721 19:58:33.816556    1186 placement_manager.go:451]  "msg"="Deleting pod that need migration"  "podName"="tf2-keras-transformer-elastic-20210721-064545-worker-0" "scheduler"="default"
I0721 19:58:33.819803    1186 placement_manager.go:451]  "msg"="Deleting pod that need migration"  "podName"="tf2-keras-transformer-elastic-20210721-064545-worker-1" "scheduler"="default"
I0721 19:58:33.823051    1186 placement_manager.go:451]  "msg"="Deleting pod that need migration"  "podName"="tf2-keras-transformer-elastic-20210721-064545-launcher" "scheduler"="default"
I0721 19:58:33.835541    1186 placement_manager.go:451]  "msg"="Deleting pod that need migration"  "podName"="tf2-keras-cifar10-inceptionv3-elastic-20210721-063448-worker-0" "scheduler"="default"
I0721 19:58:33.839523    1186 placement_manager.go:451]  "msg"="Deleting pod that need migration"  "podName"="tf2-keras-cifar10-inceptionv3-elastic-20210721-063448-worker-1" "scheduler"="default"
I0721 19:58:33.844296    1186 placement_manager.go:451]  "msg"="Deleting pod that need migration"  "podName"="tf2-keras-cifar10-inceptionv3-elastic-20210721-063448-launcher" "scheduler"="default"
I0721 19:58:33.856286    1186 placement_manager.go:183]  "msg"="Finished job placements adjustment"  "scheduler"="default"
I0721 19:58:33.856500    1186 scheduler.go:182]  "msg"="Finished resched"  "scheduler"="default"
I0721 19:58:33.990284    1186 placement_manager.go:147]  "msg"="Adding toleration to pod"  "podName"="tf2-keras-cifar10-inceptionv3-elastic-20210721-064117-worker-0" "scheduler"="default" "toleration"={"key":"celeste/hostname","operator":"Equal","value":"gpu4","effect":"NoExecute"}
I0721 19:58:34.391913    1186 placement_manager.go:147]  "msg"="Adding toleration to pod"  "podName"="tf2-keras-cifar10-inceptionv3-elastic-20210721-064117-launcher" "scheduler"="default" "toleration"={"key":"celeste/hostname","operator":"Exists","effect":"NoExecute"}
I0721 19:58:35.194376    1186 placement_manager.go:147]  "msg"="Adding toleration to pod"  "podName"="tf2-keras-transformer-elastic-20210721-063927-worker-1" "scheduler"="default" "toleration"={"key":"celeste/hostname","operator":"Equal","value":"gpu4","effect":"NoExecute"}
I0721 19:58:36.629604    1186 scheduler.go:565]  "msg"="Priority promoted to training job"  "job"="tf2-keras-cifar10-inceptionv3-elastic-20210721-064117" "priority"=0 "scheduler"="default"
I0721 19:58:36.629677    1186 scheduler.go:573]  "msg"="Priority changed"  "scheduler"="default"
I0721 19:58:36.629793    1186 scheduler.go:135]  "msg"="Received resched event, may be blocked because of rate limit"  "blockedUntil"="2021-07-21T20:00:33.856695932+08:00" "lastResched"="2021-07-21T19:58:33.856695932+08:00" "received"="2021-07-21T19:58:36.629683885+08:00" "scheduler"="default"
I0721 19:58:43.883223    1186 placement_manager.go:147]  "msg"="Adding toleration to pod"  "podName"="tf2-keras-cifar10-inceptionv3-elastic-20210721-063448-worker-0" "scheduler"="default" "toleration"={"key":"celeste/hostname","operator":"Equal","value":"gpu5","effect":"NoExecute"}
I0721 19:58:44.589760    1186 placement_manager.go:147]  "msg"="Adding toleration to pod"  "podName"="tf2-keras-transformer-elastic-20210721-064545-launcher" "scheduler"="default" "toleration"={"key":"celeste/hostname","operator":"Exists","effect":"NoExecute"}
I0721 19:58:49.256870    1186 placement_manager.go:147]  "msg"="Adding toleration to pod"  "podName"="tf2-keras-cifar10-inceptionv3-elastic-20210721-063448-worker-1" "scheduler"="default" "toleration"={"key":"celeste/hostname","operator":"Equal","value":"gpu5","effect":"NoExecute"}
I0721 19:58:50.519586    1186 placement_manager.go:147]  "msg"="Adding toleration to pod"  "podName"="tf2-keras-cifar10-inceptionv3-elastic-20210721-063448-launcher" "scheduler"="default" "toleration"={"key":"celeste/hostname","operator":"Exists","effect":"NoExecute"}
I0721 19:58:51.305951    1186 placement_manager.go:147]  "msg"="Adding toleration to pod"  "podName"="tf2-keras-transformer-elastic-20210721-064545-worker-0" "scheduler"="default" "toleration"={"key":"celeste/hostname","operator":"Equal","value":"gpu3","effect":"NoExecute"}
I0721 19:58:51.901384    1186 placement_manager.go:147]  "msg"="Adding toleration to pod"  "podName"="tf2-keras-transformer-elastic-20210721-064545-worker-1" "scheduler"="default" "toleration"={"key":"celeste/hostname","operator":"Equal","value":"gpu3","effect":"NoExecute"}
I0721 19:59:11.630671    1186 scheduler.go:559]  "msg"="Priority demoted to training job"  "job"="tf2-keras-cifar10-inceptionv3-elastic-20210721-063900" "priority"=1 "scheduler"="default"
I0721 19:59:11.630722    1186 scheduler.go:573]  "msg"="Priority changed"  "scheduler"="default"
I0721 20:00:33.856830    1186 scheduler.go:159]  "msg"="Started resched"  "scheduler"="default"
I0721 20:00:33.856978    1186 scheduler.go:193]  "msg"="Updating all jobs info"  "scheduler"="default"
I0721 20:00:33.866899    1186 elastic_tiresias.go:160]  "msg"="Finished scheduling"  "algorithm"="ElasticTiresias" "compactionThreshold"=4 "freeGpu"=0 "promoteKnob"=4 "queueNum"=2 "result"={"tf2-keras-cifar10-inceptionv3-elastic-20210721-063448":2,"tf2-keras-cifar10-inceptionv3-elastic-20210721-063539":2,"tf2-keras-cifar10-inceptionv3-elastic-20210721-063756":1,"tf2-keras-cifar10-inceptionv3-elastic-20210721-063900":0,"tf2-keras-cifar10-inceptionv3-elastic-20210721-064117":3,"tf2-keras-cifar10-inceptionv3-elastic-20210721-064215":0,"tf2-keras-cifar10-resnet50-elastic-20210721-064451":0,"tf2-keras-cifar10-vgg16-elastic-20210721-064310":0,"tf2-keras-transformer-elastic-20210721-063927":2,"tf2-keras-transformer-elastic-20210721-064152":0,"tf2-keras-transformer-elastic-20210721-064332":0,"tf2-keras-transformer-elastic-20210721-064545":2} "scheduler"="default" "thresholds"=
I0721 20:00:33.867205    1186 scheduler.go:384]  "msg"="Trying to delete multiple training jobs"  "jobs"=["tf2-keras-cifar10-inceptionv3-elastic-20210721-063900"] "scheduler"="default"
I0721 20:00:33.878529    1186 scheduler.go:342]  "msg"="Trying to scale multiple training jobs"  "jobs"=[] "scheduler"="default"
I0721 20:00:33.878777    1186 scheduler.go:292]  "msg"="Trying to start multiple training jobs"  "jobs"=[] "scheduler"="default"
I0721 20:00:33.879003    1186 scheduler.go:342]  "msg"="Trying to scale multiple training jobs"  "jobs"=["tf2-keras-cifar10-inceptionv3-elastic-20210721-064117"] "scheduler"="default"
I0721 20:00:33.912560    1186 placement_manager.go:166]  "msg"="Started job placements adjustment"  "scheduler"="default"
I0721 20:00:33.912687    1186 placement_manager.go:192]  "msg"="Releasing slots"  "jobs"={"tf2-keras-cifar10-inceptionv3-elastic-20210721-063448":{},"tf2-keras-cifar10-inceptionv3-elastic-20210721-063539":{},"tf2-keras-cifar10-inceptionv3-elastic-20210721-063756":{},"tf2-keras-cifar10-inceptionv3-elastic-20210721-063900":{},"tf2-keras-cifar10-inceptionv3-elastic-20210721-064117":{},"tf2-keras-transformer-elastic-20210721-063927":{},"tf2-keras-transformer-elastic-20210721-064545":{}} "nodes"={"gpu3":{},"gpu4":{},"gpu5":{}} "scheduler"="default"
I0721 20:00:33.912769    1186 placement_manager.go:250]  "msg"="Released slots"  "jobs"={"tf2-keras-cifar10-inceptionv3-elastic-20210721-063448":{},"tf2-keras-cifar10-inceptionv3-elastic-20210721-063539":{},"tf2-keras-cifar10-inceptionv3-elastic-20210721-063756":{},"tf2-keras-cifar10-inceptionv3-elastic-20210721-063900":{},"tf2-keras-cifar10-inceptionv3-elastic-20210721-064117":{},"tf2-keras-transformer-elastic-20210721-063927":{},"tf2-keras-transformer-elastic-20210721-064545":{}} "nodes"={"gpu3":{},"gpu4":{},"gpu5":{}} "scheduler"="default"
I0721 20:00:33.913343    1186 placement_manager.go:305]  "msg"="Found best-fit"  "crossNode"=0 "nodes"=[{},{},{}] "requests"=[{},{},{},{},{},{},{},{},{},{},{},{},{},{},{},{},{},{},{},{},{},{},{},{}] "scheduler"="default"
I0721 20:00:33.913711    1186 placement_manager.go:339]  "msg"="nodeStates updated"  "new"={"gpu3":{},"gpu4":{},"gpu5":{}} "old"={"gpu3":{},"gpu4":{},"gpu5":{}} "scheduler"="default" "score"=8
I0721 20:00:33.914051    1186 placement_manager.go:387]  "msg"="jobStates updated"  "new"={"tf2-keras-cifar10-inceptionv3-elastic-20210721-063448":{},"tf2-keras-cifar10-inceptionv3-elastic-20210721-063539":{},"tf2-keras-cifar10-inceptionv3-elastic-20210721-063756":{},"tf2-keras-cifar10-inceptionv3-elastic-20210721-064117":{},"tf2-keras-transformer-elastic-20210721-063927":{},"tf2-keras-transformer-elastic-20210721-064545":{}} "old"={"tf2-keras-cifar10-inceptionv3-elastic-20210721-063448":{},"tf2-keras-cifar10-inceptionv3-elastic-20210721-063539":{},"tf2-keras-cifar10-inceptionv3-elastic-20210721-063756":{},"tf2-keras-cifar10-inceptionv3-elastic-20210721-063900":{},"tf2-keras-cifar10-inceptionv3-elastic-20210721-064117":{},"tf2-keras-transformer-elastic-20210721-063927":{},"tf2-keras-transformer-elastic-20210721-064545":{}} "scheduler"="default"
I0721 20:00:33.914481    1186 placement_manager.go:434]  "msg"="podNodeName updated"  "launchersToDelete"=1 "new"={"tf2-keras-cifar10-inceptionv3-elastic-20210721-063448-worker-0":"gpu5","tf2-keras-cifar10-inceptionv3-elastic-20210721-063448-worker-1":"gpu5","tf2-keras-cifar10-inceptionv3-elastic-20210721-063539-worker-0":"gpu3","tf2-keras-cifar10-inceptionv3-elastic-20210721-063539-worker-1":"gpu3","tf2-keras-cifar10-inceptionv3-elastic-20210721-063756-worker-0":"gpu4","tf2-keras-cifar10-inceptionv3-elastic-20210721-064117-worker-0":"gpu4","tf2-keras-cifar10-inceptionv3-elastic-20210721-064117-worker-1":"gpu4","tf2-keras-cifar10-inceptionv3-elastic-20210721-064117-worker-2":"gpu4","tf2-keras-transformer-elastic-20210721-063927-worker-0":"gpu5","tf2-keras-transformer-elastic-20210721-063927-worker-1":"gpu5","tf2-keras-transformer-elastic-20210721-064545-worker-0":"gpu3","tf2-keras-transformer-elastic-20210721-064545-worker-1":"gpu3"} "old"={"tf2-keras-cifar10-inceptionv3-elastic-20210721-063448-worker-0":"gpu5","tf2-keras-cifar10-inceptionv3-elastic-20210721-063448-worker-1":"gpu5","tf2-keras-cifar10-inceptionv3-elastic-20210721-063539-worker-0":"gpu3","tf2-keras-cifar10-inceptionv3-elastic-20210721-063539-worker-1":"gpu3","tf2-keras-cifar10-inceptionv3-elastic-20210721-063756-worker-0":"gpu4","tf2-keras-cifar10-inceptionv3-elastic-20210721-063900-worker-0":"gpu5","tf2-keras-cifar10-inceptionv3-elastic-20210721-063900-worker-1":"gpu5","tf2-keras-cifar10-inceptionv3-elastic-20210721-064117-worker-0":"gpu4","tf2-keras-transformer-elastic-20210721-063927-worker-0":"gpu4","tf2-keras-transformer-elastic-20210721-063927-worker-1":"gpu4","tf2-keras-transformer-elastic-20210721-064545-worker-0":"gpu3","tf2-keras-transformer-elastic-20210721-064545-worker-1":"gpu3"} "scheduler"="default" "workersToDelete"=2
I0721 20:00:33.914830    1186 placement_manager.go:451]  "msg"="Deleting pod that need migration"  "podName"="tf2-keras-transformer-elastic-20210721-063927-worker-0" "scheduler"="default"
I0721 20:00:33.926149    1186 placement_manager.go:451]  "msg"="Deleting pod that need migration"  "podName"="tf2-keras-transformer-elastic-20210721-063927-worker-1" "scheduler"="default"
I0721 20:00:33.929884    1186 placement_manager.go:451]  "msg"="Deleting pod that need migration"  "podName"="tf2-keras-transformer-elastic-20210721-063927-launcher" "scheduler"="default"
I0721 20:00:33.934857    1186 placement_manager.go:183]  "msg"="Finished job placements adjustment"  "scheduler"="default"
I0721 20:00:33.935110    1186 scheduler.go:182]  "msg"="Finished resched"  "scheduler"="default"
I0721 20:00:33.945256    1186 placement_manager.go:147]  "msg"="Adding toleration to pod"  "podName"="tf2-keras-cifar10-inceptionv3-elastic-20210721-064117-worker-1" "scheduler"="default" "toleration"={"key":"celeste/hostname","operator":"Equal","value":"gpu4","effect":"NoExecute"}
I0721 20:00:33.977589    1186 placement_manager.go:147]  "msg"="Adding toleration to pod"  "podName"="tf2-keras-cifar10-inceptionv3-elastic-20210721-064117-worker-2" "scheduler"="default" "toleration"={"key":"celeste/hostname","operator":"Equal","value":"gpu4","effect":"NoExecute"}
I0721 20:00:41.859445    1186 placement_manager.go:147]  "msg"="Adding toleration to pod"  "podName"="tf2-keras-transformer-elastic-20210721-063927-worker-0" "scheduler"="default" "toleration"={"key":"celeste/hostname","operator":"Equal","value":"gpu5","effect":"NoExecute"}
I0721 20:00:42.917450    1186 placement_manager.go:147]  "msg"="Adding toleration to pod"  "podName"="tf2-keras-transformer-elastic-20210721-063927-worker-1" "scheduler"="default" "toleration"={"key":"celeste/hostname","operator":"Equal","value":"gpu5","effect":"NoExecute"}
I0721 20:00:51.242742    1186 placement_manager.go:147]  "msg"="Adding toleration to pod"  "podName"="tf2-keras-transformer-elastic-20210721-063927-launcher" "scheduler"="default" "toleration"={"key":"celeste/hostname","operator":"Exists","effect":"NoExecute"}
I0721 20:02:11.636785    1186 scheduler.go:559]  "msg"="Priority demoted to training job"  "job"="tf2-keras-transformer-elastic-20210721-064545" "priority"=1 "scheduler"="default"
I0721 20:02:11.636876    1186 scheduler.go:573]  "msg"="Priority changed"  "scheduler"="default"
I0721 20:02:11.636949    1186 scheduler.go:135]  "msg"="Received resched event, may be blocked because of rate limit"  "blockedUntil"="2021-07-21T20:02:33.93529272+08:00" "lastResched"="2021-07-21T20:00:33.93529272+08:00" "received"="2021-07-21T20:02:11.636886888+08:00" "scheduler"="default"
I0721 20:02:33.935410    1186 scheduler.go:159]  "msg"="Started resched"  "scheduler"="default"
I0721 20:02:33.935484    1186 scheduler.go:193]  "msg"="Updating all jobs info"  "scheduler"="default"
I0721 20:02:33.943988    1186 elastic_tiresias.go:160]  "msg"="Finished scheduling"  "algorithm"="ElasticTiresias" "compactionThreshold"=4 "freeGpu"=0 "promoteKnob"=4 "queueNum"=2 "result"={"tf2-keras-cifar10-inceptionv3-elastic-20210721-063448":2,"tf2-keras-cifar10-inceptionv3-elastic-20210721-063539":2,"tf2-keras-cifar10-inceptionv3-elastic-20210721-063756":1,"tf2-keras-cifar10-inceptionv3-elastic-20210721-063900":1,"tf2-keras-cifar10-inceptionv3-elastic-20210721-064117":3,"tf2-keras-cifar10-inceptionv3-elastic-20210721-064215":0,"tf2-keras-cifar10-resnet50-elastic-20210721-064451":0,"tf2-keras-cifar10-vgg16-elastic-20210721-064310":0,"tf2-keras-transformer-elastic-20210721-063927":2,"tf2-keras-transformer-elastic-20210721-064152":1,"tf2-keras-transformer-elastic-20210721-064332":0,"tf2-keras-transformer-elastic-20210721-064545":0} "scheduler"="default" "thresholds"=
I0721 20:02:33.944421    1186 scheduler.go:384]  "msg"="Trying to delete multiple training jobs"  "jobs"=["tf2-keras-transformer-elastic-20210721-064545"] "scheduler"="default"
I0721 20:02:33.957452    1186 scheduler.go:342]  "msg"="Trying to scale multiple training jobs"  "jobs"=[] "scheduler"="default"
I0721 20:02:33.957762    1186 scheduler.go:292]  "msg"="Trying to start multiple training jobs"  "jobs"=["tf2-keras-cifar10-inceptionv3-elastic-20210721-063900","tf2-keras-transformer-elastic-20210721-064152"] "scheduler"="default"
I0721 20:02:33.985027    1186 scheduler.go:342]  "msg"="Trying to scale multiple training jobs"  "jobs"=[] "scheduler"="default"
I0721 20:02:33.988084    1186 placement_manager.go:166]  "msg"="Started job placements adjustment"  "scheduler"="default"
I0721 20:02:33.988181    1186 placement_manager.go:192]  "msg"="Releasing slots"  "jobs"={"tf2-keras-cifar10-inceptionv3-elastic-20210721-063448":{},"tf2-keras-cifar10-inceptionv3-elastic-20210721-063539":{},"tf2-keras-cifar10-inceptionv3-elastic-20210721-063756":{},"tf2-keras-cifar10-inceptionv3-elastic-20210721-064117":{},"tf2-keras-transformer-elastic-20210721-063927":{},"tf2-keras-transformer-elastic-20210721-064545":{}} "nodes"={"gpu3":{},"gpu4":{},"gpu5":{}} "scheduler"="default"
I0721 20:02:33.988248    1186 placement_manager.go:250]  "msg"="Released slots"  "jobs"={"tf2-keras-cifar10-inceptionv3-elastic-20210721-063448":{},"tf2-keras-cifar10-inceptionv3-elastic-20210721-063539":{},"tf2-keras-cifar10-inceptionv3-elastic-20210721-063756":{},"tf2-keras-cifar10-inceptionv3-elastic-20210721-064117":{},"tf2-keras-transformer-elastic-20210721-063927":{},"tf2-keras-transformer-elastic-20210721-064545":{}} "nodes"={"gpu3":{},"gpu4":{},"gpu5":{}} "scheduler"="default"
I0721 20:02:33.988794    1186 placement_manager.go:305]  "msg"="Found best-fit"  "crossNode"=0 "nodes"=[{},{},{}] "requests"=[{},{},{},{},{},{},{},{},{},{},{},{},{},{},{},{},{},{},{},{},{},{},{},{}] "scheduler"="default"
I0721 20:02:33.989239    1186 placement_manager.go:339]  "msg"="nodeStates updated"  "new"={"gpu3":{},"gpu4":{},"gpu5":{}} "old"={"gpu3":{},"gpu4":{},"gpu5":{}} "scheduler"="default" "score"=7
I0721 20:02:33.989558    1186 placement_manager.go:387]  "msg"="jobStates updated"  "new"={"tf2-keras-cifar10-inceptionv3-elastic-20210721-063448":{},"tf2-keras-cifar10-inceptionv3-elastic-20210721-063539":{},"tf2-keras-cifar10-inceptionv3-elastic-20210721-063756":{},"tf2-keras-cifar10-inceptionv3-elastic-20210721-063900":{},"tf2-keras-cifar10-inceptionv3-elastic-20210721-064117":{},"tf2-keras-transformer-elastic-20210721-063927":{},"tf2-keras-transformer-elastic-20210721-064152":{}} "old"={"tf2-keras-cifar10-inceptionv3-elastic-20210721-063448":{},"tf2-keras-cifar10-inceptionv3-elastic-20210721-063539":{},"tf2-keras-cifar10-inceptionv3-elastic-20210721-063756":{},"tf2-keras-cifar10-inceptionv3-elastic-20210721-064117":{},"tf2-keras-transformer-elastic-20210721-063927":{},"tf2-keras-transformer-elastic-20210721-064545":{}} "scheduler"="default"
I0721 20:02:33.989870    1186 placement_manager.go:434]  "msg"="podNodeName updated"  "launchersToDelete"=2 "new"={"tf2-keras-cifar10-inceptionv3-elastic-20210721-063448-worker-0":"gpu3","tf2-keras-cifar10-inceptionv3-elastic-20210721-063448-worker-1":"gpu3","tf2-keras-cifar10-inceptionv3-elastic-20210721-063539-worker-0":"gpu3","tf2-keras-cifar10-inceptionv3-elastic-20210721-063539-worker-1":"gpu3","tf2-keras-cifar10-inceptionv3-elastic-20210721-063756-worker-0":"gpu5","tf2-keras-cifar10-inceptionv3-elastic-20210721-063900-worker-0":"gpu5","tf2-keras-cifar10-inceptionv3-elastic-20210721-064117-worker-0":"gpu4","tf2-keras-cifar10-inceptionv3-elastic-20210721-064117-worker-1":"gpu4","tf2-keras-cifar10-inceptionv3-elastic-20210721-064117-worker-2":"gpu4","tf2-keras-transformer-elastic-20210721-063927-worker-0":"gpu5","tf2-keras-transformer-elastic-20210721-063927-worker-1":"gpu5","tf2-keras-transformer-elastic-20210721-064152-worker-0":"gpu4"} "old"={"tf2-keras-cifar10-inceptionv3-elastic-20210721-063448-worker-0":"gpu5","tf2-keras-cifar10-inceptionv3-elastic-20210721-063448-worker-1":"gpu5","tf2-keras-cifar10-inceptionv3-elastic-20210721-063539-worker-0":"gpu3","tf2-keras-cifar10-inceptionv3-elastic-20210721-063539-worker-1":"gpu3","tf2-keras-cifar10-inceptionv3-elastic-20210721-063756-worker-0":"gpu4","tf2-keras-cifar10-inceptionv3-elastic-20210721-064117-worker-0":"gpu4","tf2-keras-cifar10-inceptionv3-elastic-20210721-064117-worker-1":"gpu4","tf2-keras-cifar10-inceptionv3-elastic-20210721-064117-worker-2":"gpu4","tf2-keras-transformer-elastic-20210721-063927-worker-0":"gpu5","tf2-keras-transformer-elastic-20210721-063927-worker-1":"gpu5","tf2-keras-transformer-elastic-20210721-064545-worker-0":"gpu3","tf2-keras-transformer-elastic-20210721-064545-worker-1":"gpu3"} "scheduler"="default" "workersToDelete"=3
I0721 20:02:33.990152    1186 placement_manager.go:451]  "msg"="Deleting pod that need migration"  "podName"="tf2-keras-cifar10-inceptionv3-elastic-20210721-063448-worker-0" "scheduler"="default"
I0721 20:02:33.996320    1186 placement_manager.go:451]  "msg"="Deleting pod that need migration"  "podName"="tf2-keras-cifar10-inceptionv3-elastic-20210721-063448-worker-1" "scheduler"="default"
I0721 20:02:34.001474    1186 placement_manager.go:451]  "msg"="Deleting pod that need migration"  "podName"="tf2-keras-cifar10-inceptionv3-elastic-20210721-063448-launcher" "scheduler"="default"
I0721 20:02:34.012655    1186 placement_manager.go:451]  "msg"="Deleting pod that need migration"  "podName"="tf2-keras-cifar10-inceptionv3-elastic-20210721-063756-worker-0" "scheduler"="default"
I0721 20:02:34.020141    1186 placement_manager.go:451]  "msg"="Deleting pod that need migration"  "podName"="tf2-keras-cifar10-inceptionv3-elastic-20210721-063756-launcher" "scheduler"="default"
I0721 20:02:34.025297    1186 placement_manager.go:183]  "msg"="Finished job placements adjustment"  "scheduler"="default"
I0721 20:02:34.025608    1186 scheduler.go:182]  "msg"="Finished resched"  "scheduler"="default"
I0721 20:02:34.184723    1186 placement_manager.go:147]  "msg"="Adding toleration to pod"  "podName"="tf2-keras-transformer-elastic-20210721-064152-worker-0" "scheduler"="default" "toleration"={"key":"celeste/hostname","operator":"Equal","value":"gpu4","effect":"NoExecute"}
I0721 20:02:34.384708    1186 placement_manager.go:147]  "msg"="Adding toleration to pod"  "podName"="tf2-keras-cifar10-inceptionv3-elastic-20210721-063900-worker-0" "scheduler"="default" "toleration"={"key":"celeste/hostname","operator":"Equal","value":"gpu5","effect":"NoExecute"}
I0721 20:02:34.597890    1186 placement_manager.go:147]  "msg"="Adding toleration to pod"  "podName"="tf2-keras-transformer-elastic-20210721-064152-launcher" "scheduler"="default" "toleration"={"key":"celeste/hostname","operator":"Exists","effect":"NoExecute"}
I0721 20:02:35.000403    1186 placement_manager.go:147]  "msg"="Adding toleration to pod"  "podName"="tf2-keras-cifar10-inceptionv3-elastic-20210721-063900-launcher" "scheduler"="default" "toleration"={"key":"celeste/hostname","operator":"Exists","effect":"NoExecute"}
I0721 20:02:36.637820    1186 scheduler.go:565]  "msg"="Priority promoted to training job"  "job"="tf2-keras-cifar10-inceptionv3-elastic-20210721-063900" "priority"=0 "scheduler"="default"
I0721 20:02:36.637900    1186 scheduler.go:565]  "msg"="Priority promoted to training job"  "job"="tf2-keras-transformer-elastic-20210721-064152" "priority"=0 "scheduler"="default"
I0721 20:02:36.637939    1186 scheduler.go:573]  "msg"="Priority changed"  "scheduler"="default"
I0721 20:02:36.638007    1186 scheduler.go:135]  "msg"="Received resched event, may be blocked because of rate limit"  "blockedUntil"="2021-07-21T20:04:34.025897873+08:00" "lastResched"="2021-07-21T20:02:34.025897873+08:00" "received"="2021-07-21T20:02:36.637947764+08:00" "scheduler"="default"
I0721 20:02:40.730875    1186 placement_manager.go:147]  "msg"="Adding toleration to pod"  "podName"="tf2-keras-cifar10-inceptionv3-elastic-20210721-063756-launcher" "scheduler"="default" "toleration"={"key":"celeste/hostname","operator":"Exists","effect":"NoExecute"}
I0721 20:02:41.857834    1186 placement_manager.go:147]  "msg"="Adding toleration to pod"  "podName"="tf2-keras-cifar10-inceptionv3-elastic-20210721-063448-worker-1" "scheduler"="default" "toleration"={"key":"celeste/hostname","operator":"Equal","value":"gpu3","effect":"NoExecute"}
I0721 20:02:42.128550    1186 placement_manager.go:147]  "msg"="Adding toleration to pod"  "podName"="tf2-keras-cifar10-inceptionv3-elastic-20210721-063448-launcher" "scheduler"="default" "toleration"={"key":"celeste/hostname","operator":"Exists","effect":"NoExecute"}
I0721 20:02:44.583987    1186 placement_manager.go:147]  "msg"="Adding toleration to pod"  "podName"="tf2-keras-cifar10-inceptionv3-elastic-20210721-063756-worker-0" "scheduler"="default" "toleration"={"key":"celeste/hostname","operator":"Equal","value":"gpu5","effect":"NoExecute"}
I0721 20:02:51.991561    1186 placement_manager.go:147]  "msg"="Adding toleration to pod"  "podName"="tf2-keras-cifar10-inceptionv3-elastic-20210721-063448-worker-0" "scheduler"="default" "toleration"={"key":"celeste/hostname","operator":"Equal","value":"gpu3","effect":"NoExecute"}
I0721 20:04:34.026024    1186 scheduler.go:159]  "msg"="Started resched"  "scheduler"="default"
I0721 20:04:34.026149    1186 scheduler.go:193]  "msg"="Updating all jobs info"  "scheduler"="default"
I0721 20:04:34.035137    1186 elastic_tiresias.go:160]  "msg"="Finished scheduling"  "algorithm"="ElasticTiresias" "compactionThreshold"=4 "freeGpu"=0 "promoteKnob"=4 "queueNum"=2 "result"={"tf2-keras-cifar10-inceptionv3-elastic-20210721-063448":2,"tf2-keras-cifar10-inceptionv3-elastic-20210721-063539":2,"tf2-keras-cifar10-inceptionv3-elastic-20210721-063756":0,"tf2-keras-cifar10-inceptionv3-elastic-20210721-063900":2,"tf2-keras-cifar10-inceptionv3-elastic-20210721-064117":2,"tf2-keras-cifar10-inceptionv3-elastic-20210721-064215":0,"tf2-keras-cifar10-resnet50-elastic-20210721-064451":0,"tf2-keras-cifar10-vgg16-elastic-20210721-064310":0,"tf2-keras-transformer-elastic-20210721-063927":2,"tf2-keras-transformer-elastic-20210721-064152":2,"tf2-keras-transformer-elastic-20210721-064332":0,"tf2-keras-transformer-elastic-20210721-064545":0} "scheduler"="default" "thresholds"=
I0721 20:04:34.035420    1186 scheduler.go:384]  "msg"="Trying to delete multiple training jobs"  "jobs"=["tf2-keras-cifar10-inceptionv3-elastic-20210721-063756"] "scheduler"="default"
I0721 20:04:34.047120    1186 scheduler.go:342]  "msg"="Trying to scale multiple training jobs"  "jobs"=["tf2-keras-cifar10-inceptionv3-elastic-20210721-064117"] "scheduler"="default"
I0721 20:04:34.082811    1186 scheduler.go:292]  "msg"="Trying to start multiple training jobs"  "jobs"=[] "scheduler"="default"
I0721 20:04:34.083116    1186 scheduler.go:342]  "msg"="Trying to scale multiple training jobs"  "jobs"=["tf2-keras-transformer-elastic-20210721-064152","tf2-keras-cifar10-inceptionv3-elastic-20210721-063900"] "scheduler"="default"
I0721 20:04:34.115375    1186 placement_manager.go:166]  "msg"="Started job placements adjustment"  "scheduler"="default"
I0721 20:04:34.115429    1186 placement_manager.go:192]  "msg"="Releasing slots"  "jobs"={"tf2-keras-cifar10-inceptionv3-elastic-20210721-063448":{},"tf2-keras-cifar10-inceptionv3-elastic-20210721-063539":{},"tf2-keras-cifar10-inceptionv3-elastic-20210721-063756":{},"tf2-keras-cifar10-inceptionv3-elastic-20210721-063900":{},"tf2-keras-cifar10-inceptionv3-elastic-20210721-064117":{},"tf2-keras-transformer-elastic-20210721-063927":{},"tf2-keras-transformer-elastic-20210721-064152":{}} "nodes"={"gpu3":{},"gpu4":{},"gpu5":{}} "scheduler"="default"
I0721 20:04:34.115464    1186 placement_manager.go:250]  "msg"="Released slots"  "jobs"={"tf2-keras-cifar10-inceptionv3-elastic-20210721-063448":{},"tf2-keras-cifar10-inceptionv3-elastic-20210721-063539":{},"tf2-keras-cifar10-inceptionv3-elastic-20210721-063756":{},"tf2-keras-cifar10-inceptionv3-elastic-20210721-063900":{},"tf2-keras-cifar10-inceptionv3-elastic-20210721-064117":{},"tf2-keras-transformer-elastic-20210721-063927":{},"tf2-keras-transformer-elastic-20210721-064152":{}} "nodes"={"gpu3":{},"gpu4":{},"gpu5":{}} "scheduler"="default"
I0721 20:04:34.115871    1186 placement_manager.go:305]  "msg"="Found best-fit"  "crossNode"=0 "nodes"=[{},{},{}] "requests"=[{},{},{},{},{},{},{},{},{},{},{},{},{},{},{},{},{},{},{},{},{},{},{},{}] "scheduler"="default"
I0721 20:04:34.116093    1186 placement_manager.go:339]  "msg"="nodeStates updated"  "new"={"gpu3":{},"gpu4":{},"gpu5":{}} "old"={"gpu3":{},"gpu4":{},"gpu5":{}} "scheduler"="default" "score"=10
I0721 20:04:34.116302    1186 placement_manager.go:387]  "msg"="jobStates updated"  "new"={"tf2-keras-cifar10-inceptionv3-elastic-20210721-063448":{},"tf2-keras-cifar10-inceptionv3-elastic-20210721-063539":{},"tf2-keras-cifar10-inceptionv3-elastic-20210721-063900":{},"tf2-keras-cifar10-inceptionv3-elastic-20210721-064117":{},"tf2-keras-transformer-elastic-20210721-063927":{},"tf2-keras-transformer-elastic-20210721-064152":{}} "old"={"tf2-keras-cifar10-inceptionv3-elastic-20210721-063448":{},"tf2-keras-cifar10-inceptionv3-elastic-20210721-063539":{},"tf2-keras-cifar10-inceptionv3-elastic-20210721-063756":{},"tf2-keras-cifar10-inceptionv3-elastic-20210721-063900":{},"tf2-keras-cifar10-inceptionv3-elastic-20210721-064117":{},"tf2-keras-transformer-elastic-20210721-063927":{},"tf2-keras-transformer-elastic-20210721-064152":{}} "scheduler"="default"
I0721 20:04:34.116572    1186 placement_manager.go:434]  "msg"="podNodeName updated"  "launchersToDelete"=0 "new"={"tf2-keras-cifar10-inceptionv3-elastic-20210721-063448-worker-0":"gpu3","tf2-keras-cifar10-inceptionv3-elastic-20210721-063448-worker-1":"gpu3","tf2-keras-cifar10-inceptionv3-elastic-20210721-063539-worker-0":"gpu3","tf2-keras-cifar10-inceptionv3-elastic-20210721-063539-worker-1":"gpu3","tf2-keras-cifar10-inceptionv3-elastic-20210721-063900-worker-0":"gpu5","tf2-keras-cifar10-inceptionv3-elastic-20210721-063900-worker-1":"gpu5","tf2-keras-cifar10-inceptionv3-elastic-20210721-064117-worker-0":"gpu4","tf2-keras-cifar10-inceptionv3-elastic-20210721-064117-worker-1":"gpu4","tf2-keras-transformer-elastic-20210721-063927-worker-0":"gpu5","tf2-keras-transformer-elastic-20210721-063927-worker-1":"gpu5","tf2-keras-transformer-elastic-20210721-064152-worker-0":"gpu4","tf2-keras-transformer-elastic-20210721-064152-worker-1":"gpu4"} "old"={"tf2-keras-cifar10-inceptionv3-elastic-20210721-063448-worker-0":"gpu3","tf2-keras-cifar10-inceptionv3-elastic-20210721-063448-worker-1":"gpu3","tf2-keras-cifar10-inceptionv3-elastic-20210721-063539-worker-0":"gpu3","tf2-keras-cifar10-inceptionv3-elastic-20210721-063539-worker-1":"gpu3","tf2-keras-cifar10-inceptionv3-elastic-20210721-063756-worker-0":"gpu5","tf2-keras-cifar10-inceptionv3-elastic-20210721-063900-worker-0":"gpu5","tf2-keras-cifar10-inceptionv3-elastic-20210721-064117-worker-0":"gpu4","tf2-keras-cifar10-inceptionv3-elastic-20210721-064117-worker-1":"gpu4","tf2-keras-cifar10-inceptionv3-elastic-20210721-064117-worker-2":"gpu4","tf2-keras-transformer-elastic-20210721-063927-worker-0":"gpu5","tf2-keras-transformer-elastic-20210721-063927-worker-1":"gpu5","tf2-keras-transformer-elastic-20210721-064152-worker-0":"gpu4"} "scheduler"="default" "workersToDelete"=0
I0721 20:04:34.116800    1186 placement_manager.go:183]  "msg"="Finished job placements adjustment"  "scheduler"="default"
I0721 20:04:34.117014    1186 scheduler.go:182]  "msg"="Finished resched"  "scheduler"="default"
I0721 20:04:34.126710    1186 placement_manager.go:147]  "msg"="Adding toleration to pod"  "podName"="tf2-keras-transformer-elastic-20210721-064152-worker-1" "scheduler"="default" "toleration"={"key":"celeste/hostname","operator":"Equal","value":"gpu4","effect":"NoExecute"}
I0721 20:04:34.694758    1186 placement_manager.go:147]  "msg"="Adding toleration to pod"  "podName"="tf2-keras-cifar10-inceptionv3-elastic-20210721-063900-worker-1" "scheduler"="default" "toleration"={"key":"celeste/hostname","operator":"Equal","value":"gpu5","effect":"NoExecute"}
I0721 20:05:11.642352    1186 scheduler.go:559]  "msg"="Priority demoted to training job"  "job"="tf2-keras-cifar10-inceptionv3-elastic-20210721-063448" "priority"=1 "scheduler"="default"
I0721 20:05:11.642424    1186 scheduler.go:573]  "msg"="Priority changed"  "scheduler"="default"
I0721 20:05:11.642512    1186 scheduler.go:135]  "msg"="Received resched event, may be blocked because of rate limit"  "blockedUntil"="2021-07-21T20:06:34.117247319+08:00" "lastResched"="2021-07-21T20:04:34.117247319+08:00" "received"="2021-07-21T20:05:11.642430296+08:00" "scheduler"="default"
I0721 20:06:34.117321    1186 scheduler.go:159]  "msg"="Started resched"  "scheduler"="default"
I0721 20:06:34.117387    1186 scheduler.go:193]  "msg"="Updating all jobs info"  "scheduler"="default"
I0721 20:06:34.122791    1186 elastic_tiresias.go:160]  "msg"="Finished scheduling"  "algorithm"="ElasticTiresias" "compactionThreshold"=4 "freeGpu"=0 "promoteKnob"=4 "queueNum"=2 "result"={"tf2-keras-cifar10-inceptionv3-elastic-20210721-063448":1,"tf2-keras-cifar10-inceptionv3-elastic-20210721-063539":2,"tf2-keras-cifar10-inceptionv3-elastic-20210721-063756":0,"tf2-keras-cifar10-inceptionv3-elastic-20210721-063900":3,"tf2-keras-cifar10-inceptionv3-elastic-20210721-064117":2,"tf2-keras-cifar10-inceptionv3-elastic-20210721-064215":0,"tf2-keras-cifar10-resnet50-elastic-20210721-064451":0,"tf2-keras-cifar10-vgg16-elastic-20210721-064310":0,"tf2-keras-transformer-elastic-20210721-063927":2,"tf2-keras-transformer-elastic-20210721-064152":2,"tf2-keras-transformer-elastic-20210721-064332":0,"tf2-keras-transformer-elastic-20210721-064545":0} "scheduler"="default" "thresholds"=
I0721 20:06:34.123011    1186 scheduler.go:384]  "msg"="Trying to delete multiple training jobs"  "jobs"=[] "scheduler"="default"
I0721 20:06:34.123252    1186 scheduler.go:342]  "msg"="Trying to scale multiple training jobs"  "jobs"=["tf2-keras-cifar10-inceptionv3-elastic-20210721-063448"] "scheduler"="default"
I0721 20:06:34.140318    1186 scheduler.go:292]  "msg"="Trying to start multiple training jobs"  "jobs"=[] "scheduler"="default"
I0721 20:06:34.140555    1186 scheduler.go:342]  "msg"="Trying to scale multiple training jobs"  "jobs"=["tf2-keras-cifar10-inceptionv3-elastic-20210721-063900"] "scheduler"="default"
I0721 20:06:34.157057    1186 placement_manager.go:166]  "msg"="Started job placements adjustment"  "scheduler"="default"
I0721 20:06:34.157129    1186 placement_manager.go:192]  "msg"="Releasing slots"  "jobs"={"tf2-keras-cifar10-inceptionv3-elastic-20210721-063448":{},"tf2-keras-cifar10-inceptionv3-elastic-20210721-063539":{},"tf2-keras-cifar10-inceptionv3-elastic-20210721-063900":{},"tf2-keras-cifar10-inceptionv3-elastic-20210721-064117":{},"tf2-keras-transformer-elastic-20210721-063927":{},"tf2-keras-transformer-elastic-20210721-064152":{}} "nodes"={"gpu3":{},"gpu4":{},"gpu5":{}} "scheduler"="default"
I0721 20:06:34.157193    1186 placement_manager.go:250]  "msg"="Released slots"  "jobs"={"tf2-keras-cifar10-inceptionv3-elastic-20210721-063448":{},"tf2-keras-cifar10-inceptionv3-elastic-20210721-063539":{},"tf2-keras-cifar10-inceptionv3-elastic-20210721-063900":{},"tf2-keras-cifar10-inceptionv3-elastic-20210721-064117":{},"tf2-keras-transformer-elastic-20210721-063927":{},"tf2-keras-transformer-elastic-20210721-064152":{}} "nodes"={"gpu3":{},"gpu4":{},"gpu5":{}} "scheduler"="default"
I0721 20:06:34.157551    1186 placement_manager.go:305]  "msg"="Found best-fit"  "crossNode"=0 "nodes"=[{},{},{}] "requests"=[{},{},{},{},{},{},{},{},{},{},{},{},{},{},{},{},{},{},{},{},{},{},{},{}] "scheduler"="default"
I0721 20:06:34.157847    1186 placement_manager.go:339]  "msg"="nodeStates updated"  "new"={"gpu3":{},"gpu4":{},"gpu5":{}} "old"={"gpu3":{},"gpu4":{},"gpu5":{}} "scheduler"="default" "score"=8
I0721 20:06:34.158099    1186 placement_manager.go:387]  "msg"="jobStates updated"  "new"={"tf2-keras-cifar10-inceptionv3-elastic-20210721-063448":{},"tf2-keras-cifar10-inceptionv3-elastic-20210721-063539":{},"tf2-keras-cifar10-inceptionv3-elastic-20210721-063900":{},"tf2-keras-cifar10-inceptionv3-elastic-20210721-064117":{},"tf2-keras-transformer-elastic-20210721-063927":{},"tf2-keras-transformer-elastic-20210721-064152":{}} "old"={"tf2-keras-cifar10-inceptionv3-elastic-20210721-063448":{},"tf2-keras-cifar10-inceptionv3-elastic-20210721-063539":{},"tf2-keras-cifar10-inceptionv3-elastic-20210721-063900":{},"tf2-keras-cifar10-inceptionv3-elastic-20210721-064117":{},"tf2-keras-transformer-elastic-20210721-063927":{},"tf2-keras-transformer-elastic-20210721-064152":{}} "scheduler"="default"
I0721 20:06:34.158391    1186 placement_manager.go:434]  "msg"="podNodeName updated"  "launchersToDelete"=2 "new"={"tf2-keras-cifar10-inceptionv3-elastic-20210721-063448-worker-0":"gpu5","tf2-keras-cifar10-inceptionv3-elastic-20210721-063539-worker-0":"gpu3","tf2-keras-cifar10-inceptionv3-elastic-20210721-063539-worker-1":"gpu3","tf2-keras-cifar10-inceptionv3-elastic-20210721-063900-worker-0":"gpu5","tf2-keras-cifar10-inceptionv3-elastic-20210721-063900-worker-1":"gpu5","tf2-keras-cifar10-inceptionv3-elastic-20210721-063900-worker-2":"gpu5","tf2-keras-cifar10-inceptionv3-elastic-20210721-064117-worker-0":"gpu4","tf2-keras-cifar10-inceptionv3-elastic-20210721-064117-worker-1":"gpu4","tf2-keras-transformer-elastic-20210721-063927-worker-0":"gpu3","tf2-keras-transformer-elastic-20210721-063927-worker-1":"gpu3","tf2-keras-transformer-elastic-20210721-064152-worker-0":"gpu4","tf2-keras-transformer-elastic-20210721-064152-worker-1":"gpu4"} "old"={"tf2-keras-cifar10-inceptionv3-elastic-20210721-063448-worker-0":"gpu3","tf2-keras-cifar10-inceptionv3-elastic-20210721-063448-worker-1":"gpu3","tf2-keras-cifar10-inceptionv3-elastic-20210721-063539-worker-0":"gpu3","tf2-keras-cifar10-inceptionv3-elastic-20210721-063539-worker-1":"gpu3","tf2-keras-cifar10-inceptionv3-elastic-20210721-063900-worker-0":"gpu5","tf2-keras-cifar10-inceptionv3-elastic-20210721-063900-worker-1":"gpu5","tf2-keras-cifar10-inceptionv3-elastic-20210721-064117-worker-0":"gpu4","tf2-keras-cifar10-inceptionv3-elastic-20210721-064117-worker-1":"gpu4","tf2-keras-transformer-elastic-20210721-063927-worker-0":"gpu5","tf2-keras-transformer-elastic-20210721-063927-worker-1":"gpu5","tf2-keras-transformer-elastic-20210721-064152-worker-0":"gpu4","tf2-keras-transformer-elastic-20210721-064152-worker-1":"gpu4"} "scheduler"="default" "workersToDelete"=3
I0721 20:06:34.158672    1186 placement_manager.go:451]  "msg"="Deleting pod that need migration"  "podName"="tf2-keras-cifar10-inceptionv3-elastic-20210721-063448-worker-0" "scheduler"="default"
I0721 20:06:34.163834    1186 placement_manager.go:451]  "msg"="Deleting pod that need migration"  "podName"="tf2-keras-cifar10-inceptionv3-elastic-20210721-063448-launcher" "scheduler"="default"
I0721 20:06:34.171207    1186 placement_manager.go:451]  "msg"="Deleting pod that need migration"  "podName"="tf2-keras-transformer-elastic-20210721-063927-worker-0" "scheduler"="default"
I0721 20:06:34.177196    1186 placement_manager.go:451]  "msg"="Deleting pod that need migration"  "podName"="tf2-keras-transformer-elastic-20210721-063927-worker-1" "scheduler"="default"
I0721 20:06:34.187458    1186 placement_manager.go:451]  "msg"="Deleting pod that need migration"  "podName"="tf2-keras-transformer-elastic-20210721-063927-launcher" "scheduler"="default"
I0721 20:06:34.195911    1186 placement_manager.go:183]  "msg"="Finished job placements adjustment"  "scheduler"="default"
I0721 20:06:34.196176    1186 scheduler.go:182]  "msg"="Finished resched"  "scheduler"="default"
I0721 20:06:34.199406    1186 placement_manager.go:147]  "msg"="Adding toleration to pod"  "podName"="tf2-keras-cifar10-inceptionv3-elastic-20210721-063900-worker-2" "scheduler"="default" "toleration"={"key":"celeste/hostname","operator":"Equal","value":"gpu5","effect":"NoExecute"}
I0721 20:06:41.848710    1186 placement_manager.go:147]  "msg"="Adding toleration to pod"  "podName"="tf2-keras-cifar10-inceptionv3-elastic-20210721-063448-worker-0" "scheduler"="default" "toleration"={"key":"celeste/hostname","operator":"Equal","value":"gpu5","effect":"NoExecute"}
I0721 20:06:41.894740    1186 placement_manager.go:147]  "msg"="Adding toleration to pod"  "podName"="tf2-keras-cifar10-inceptionv3-elastic-20210721-063448-launcher" "scheduler"="default" "toleration"={"key":"celeste/hostname","operator":"Exists","effect":"NoExecute"}
I0721 20:06:42.734064    1186 placement_manager.go:147]  "msg"="Adding toleration to pod"  "podName"="tf2-keras-transformer-elastic-20210721-063927-worker-1" "scheduler"="default" "toleration"={"key":"celeste/hostname","operator":"Equal","value":"gpu3","effect":"NoExecute"}
I0721 20:06:43.536423    1186 placement_manager.go:147]  "msg"="Adding toleration to pod"  "podName"="tf2-keras-transformer-elastic-20210721-063927-launcher" "scheduler"="default" "toleration"={"key":"celeste/hostname","operator":"Exists","effect":"NoExecute"}
I0721 20:06:50.553773    1186 placement_manager.go:147]  "msg"="Adding toleration to pod"  "podName"="tf2-keras-transformer-elastic-20210721-063927-worker-0" "scheduler"="default" "toleration"={"key":"celeste/hostname","operator":"Equal","value":"gpu3","effect":"NoExecute"}
I0721 20:10:31.653122    1186 scheduler.go:559]  "msg"="Priority demoted to training job"  "job"="tf2-keras-cifar10-inceptionv3-elastic-20210721-063539" "priority"=1 "scheduler"="default"
I0721 20:10:31.653176    1186 scheduler.go:573]  "msg"="Priority changed"  "scheduler"="default"
I0721 20:10:31.653234    1186 scheduler.go:135]  "msg"="Received resched event, may be blocked because of rate limit"  "blockedUntil"="2021-07-21T20:08:34.196420596+08:00" "lastResched"="2021-07-21T20:06:34.196420596+08:00" "received"="2021-07-21T20:10:31.653181948+08:00" "scheduler"="default"
I0721 20:10:31.653251    1186 scheduler.go:159]  "msg"="Started resched"  "scheduler"="default"
I0721 20:10:31.653267    1186 scheduler.go:193]  "msg"="Updating all jobs info"  "scheduler"="default"
I0721 20:10:31.661649    1186 elastic_tiresias.go:160]  "msg"="Finished scheduling"  "algorithm"="ElasticTiresias" "compactionThreshold"=4 "freeGpu"=0 "promoteKnob"=4 "queueNum"=2 "result"={"tf2-keras-cifar10-inceptionv3-elastic-20210721-063448":1,"tf2-keras-cifar10-inceptionv3-elastic-20210721-063539":2,"tf2-keras-cifar10-inceptionv3-elastic-20210721-063756":1,"tf2-keras-cifar10-inceptionv3-elastic-20210721-063900":2,"tf2-keras-cifar10-inceptionv3-elastic-20210721-064117":2,"tf2-keras-cifar10-inceptionv3-elastic-20210721-064215":0,"tf2-keras-cifar10-resnet50-elastic-20210721-064451":0,"tf2-keras-cifar10-vgg16-elastic-20210721-064310":0,"tf2-keras-transformer-elastic-20210721-063927":2,"tf2-keras-transformer-elastic-20210721-064152":2,"tf2-keras-transformer-elastic-20210721-064332":0,"tf2-keras-transformer-elastic-20210721-064545":0} "scheduler"="default" "thresholds"=
I0721 20:10:31.661930    1186 scheduler.go:384]  "msg"="Trying to delete multiple training jobs"  "jobs"=[] "scheduler"="default"
I0721 20:10:31.662176    1186 scheduler.go:342]  "msg"="Trying to scale multiple training jobs"  "jobs"=["tf2-keras-cifar10-inceptionv3-elastic-20210721-063900"] "scheduler"="default"
I0721 20:10:31.678540    1186 scheduler.go:292]  "msg"="Trying to start multiple training jobs"  "jobs"=["tf2-keras-cifar10-inceptionv3-elastic-20210721-063756"] "scheduler"="default"
I0721 20:10:31.688436    1186 scheduler.go:342]  "msg"="Trying to scale multiple training jobs"  "jobs"=[] "scheduler"="default"
I0721 20:10:31.691925    1186 placement_manager.go:166]  "msg"="Started job placements adjustment"  "scheduler"="default"
I0721 20:10:31.691989    1186 placement_manager.go:192]  "msg"="Releasing slots"  "jobs"={"tf2-keras-cifar10-inceptionv3-elastic-20210721-063448":{},"tf2-keras-cifar10-inceptionv3-elastic-20210721-063539":{},"tf2-keras-cifar10-inceptionv3-elastic-20210721-063900":{},"tf2-keras-cifar10-inceptionv3-elastic-20210721-064117":{},"tf2-keras-transformer-elastic-20210721-063927":{},"tf2-keras-transformer-elastic-20210721-064152":{}} "nodes"={"gpu3":{},"gpu4":{},"gpu5":{}} "scheduler"="default"
I0721 20:10:31.692049    1186 placement_manager.go:250]  "msg"="Released slots"  "jobs"={"tf2-keras-cifar10-inceptionv3-elastic-20210721-063448":{},"tf2-keras-cifar10-inceptionv3-elastic-20210721-063539":{},"tf2-keras-cifar10-inceptionv3-elastic-20210721-063900":{},"tf2-keras-cifar10-inceptionv3-elastic-20210721-064117":{},"tf2-keras-transformer-elastic-20210721-063927":{},"tf2-keras-transformer-elastic-20210721-064152":{}} "nodes"={"gpu3":{},"gpu4":{},"gpu5":{}} "scheduler"="default"
I0721 20:10:31.692565    1186 placement_manager.go:305]  "msg"="Found best-fit"  "crossNode"=0 "nodes"=[{},{},{}] "requests"=[{},{},{},{},{},{},{},{},{},{},{},{},{},{},{},{},{},{},{},{},{},{},{},{}] "scheduler"="default"
I0721 20:10:31.692857    1186 placement_manager.go:339]  "msg"="nodeStates updated"  "new"={"gpu3":{},"gpu4":{},"gpu5":{}} "old"={"gpu3":{},"gpu4":{},"gpu5":{}} "scheduler"="default" "score"=6
I0721 20:10:31.693108    1186 placement_manager.go:387]  "msg"="jobStates updated"  "new"={"tf2-keras-cifar10-inceptionv3-elastic-20210721-063448":{},"tf2-keras-cifar10-inceptionv3-elastic-20210721-063539":{},"tf2-keras-cifar10-inceptionv3-elastic-20210721-063756":{},"tf2-keras-cifar10-inceptionv3-elastic-20210721-063900":{},"tf2-keras-cifar10-inceptionv3-elastic-20210721-064117":{},"tf2-keras-transformer-elastic-20210721-063927":{},"tf2-keras-transformer-elastic-20210721-064152":{}} "old"={"tf2-keras-cifar10-inceptionv3-elastic-20210721-063448":{},"tf2-keras-cifar10-inceptionv3-elastic-20210721-063539":{},"tf2-keras-cifar10-inceptionv3-elastic-20210721-063900":{},"tf2-keras-cifar10-inceptionv3-elastic-20210721-064117":{},"tf2-keras-transformer-elastic-20210721-063927":{},"tf2-keras-transformer-elastic-20210721-064152":{}} "scheduler"="default"
I0721 20:10:31.693495    1186 placement_manager.go:434]  "msg"="podNodeName updated"  "launchersToDelete"=3 "new"={"tf2-keras-cifar10-inceptionv3-elastic-20210721-063448-worker-0":"gpu4","tf2-keras-cifar10-inceptionv3-elastic-20210721-063539-worker-0":"gpu3","tf2-keras-cifar10-inceptionv3-elastic-20210721-063539-worker-1":"gpu3","tf2-keras-cifar10-inceptionv3-elastic-20210721-063756-worker-0":"gpu4","tf2-keras-cifar10-inceptionv3-elastic-20210721-063900-worker-0":"gpu5","tf2-keras-cifar10-inceptionv3-elastic-20210721-063900-worker-1":"gpu5","tf2-keras-cifar10-inceptionv3-elastic-20210721-064117-worker-0":"gpu4","tf2-keras-cifar10-inceptionv3-elastic-20210721-064117-worker-1":"gpu4","tf2-keras-transformer-elastic-20210721-063927-worker-0":"gpu5","tf2-keras-transformer-elastic-20210721-063927-worker-1":"gpu5","tf2-keras-transformer-elastic-20210721-064152-worker-0":"gpu3","tf2-keras-transformer-elastic-20210721-064152-worker-1":"gpu3"} "old"={"tf2-keras-cifar10-inceptionv3-elastic-20210721-063448-worker-0":"gpu5","tf2-keras-cifar10-inceptionv3-elastic-20210721-063539-worker-0":"gpu3","tf2-keras-cifar10-inceptionv3-elastic-20210721-063539-worker-1":"gpu3","tf2-keras-cifar10-inceptionv3-elastic-20210721-063900-worker-0":"gpu5","tf2-keras-cifar10-inceptionv3-elastic-20210721-063900-worker-1":"gpu5","tf2-keras-cifar10-inceptionv3-elastic-20210721-063900-worker-2":"gpu5","tf2-keras-cifar10-inceptionv3-elastic-20210721-064117-worker-0":"gpu4","tf2-keras-cifar10-inceptionv3-elastic-20210721-064117-worker-1":"gpu4","tf2-keras-transformer-elastic-20210721-063927-worker-0":"gpu3","tf2-keras-transformer-elastic-20210721-063927-worker-1":"gpu3","tf2-keras-transformer-elastic-20210721-064152-worker-0":"gpu4","tf2-keras-transformer-elastic-20210721-064152-worker-1":"gpu4"} "scheduler"="default" "workersToDelete"=5
I0721 20:10:31.693802    1186 placement_manager.go:451]  "msg"="Deleting pod that need migration"  "podName"="tf2-keras-cifar10-inceptionv3-elastic-20210721-063448-worker-0" "scheduler"="default"
I0721 20:10:31.698943    1186 placement_manager.go:451]  "msg"="Deleting pod that need migration"  "podName"="tf2-keras-cifar10-inceptionv3-elastic-20210721-063448-launcher" "scheduler"="default"
I0721 20:10:31.707549    1186 placement_manager.go:451]  "msg"="Deleting pod that need migration"  "podName"="tf2-keras-transformer-elastic-20210721-064152-worker-0" "scheduler"="default"
I0721 20:10:31.711425    1186 placement_manager.go:451]  "msg"="Deleting pod that need migration"  "podName"="tf2-keras-transformer-elastic-20210721-064152-worker-1" "scheduler"="default"
I0721 20:10:31.718217    1186 placement_manager.go:451]  "msg"="Deleting pod that need migration"  "podName"="tf2-keras-transformer-elastic-20210721-064152-launcher" "scheduler"="default"
I0721 20:10:31.729435    1186 placement_manager.go:451]  "msg"="Deleting pod that need migration"  "podName"="tf2-keras-transformer-elastic-20210721-063927-worker-0" "scheduler"="default"
I0721 20:10:31.734410    1186 placement_manager.go:451]  "msg"="Deleting pod that need migration"  "podName"="tf2-keras-transformer-elastic-20210721-063927-worker-1" "scheduler"="default"
I0721 20:10:31.739847    1186 placement_manager.go:451]  "msg"="Deleting pod that need migration"  "podName"="tf2-keras-transformer-elastic-20210721-063927-launcher" "scheduler"="default"
I0721 20:10:31.749563    1186 placement_manager.go:183]  "msg"="Finished job placements adjustment"  "scheduler"="default"
I0721 20:10:31.749872    1186 scheduler.go:182]  "msg"="Finished resched"  "scheduler"="default"
I0721 20:10:32.298541    1186 placement_manager.go:147]  "msg"="Adding toleration to pod"  "podName"="tf2-keras-cifar10-inceptionv3-elastic-20210721-063756-worker-0" "scheduler"="default" "toleration"={"key":"celeste/hostname","operator":"Equal","value":"gpu4","effect":"NoExecute"}
I0721 20:10:32.694220    1186 placement_manager.go:147]  "msg"="Adding toleration to pod"  "podName"="tf2-keras-cifar10-inceptionv3-elastic-20210721-063756-launcher" "scheduler"="default" "toleration"={"key":"celeste/hostname","operator":"Exists","effect":"NoExecute"}
I0721 20:10:36.653440    1186 scheduler.go:565]  "msg"="Priority promoted to training job"  "job"="tf2-keras-cifar10-inceptionv3-elastic-20210721-063756" "priority"=0 "scheduler"="default"
I0721 20:10:36.653513    1186 scheduler.go:573]  "msg"="Priority changed"  "scheduler"="default"
I0721 20:10:36.653602    1186 scheduler.go:135]  "msg"="Received resched event, may be blocked because of rate limit"  "blockedUntil"="2021-07-21T20:12:31.750125297+08:00" "lastResched"="2021-07-21T20:10:31.750125297+08:00" "received"="2021-07-21T20:10:36.653522956+08:00" "scheduler"="default"
I0721 20:10:40.143567    1186 placement_manager.go:147]  "msg"="Adding toleration to pod"  "podName"="tf2-keras-cifar10-inceptionv3-elastic-20210721-063448-worker-0" "scheduler"="default" "toleration"={"key":"celeste/hostname","operator":"Equal","value":"gpu4","effect":"NoExecute"}
I0721 20:10:40.179337    1186 placement_manager.go:147]  "msg"="Adding toleration to pod"  "podName"="tf2-keras-cifar10-inceptionv3-elastic-20210721-063448-launcher" "scheduler"="default" "toleration"={"key":"celeste/hostname","operator":"Exists","effect":"NoExecute"}
I0721 20:10:45.323706    1186 placement_manager.go:147]  "msg"="Adding toleration to pod"  "podName"="tf2-keras-transformer-elastic-20210721-064152-worker-0" "scheduler"="default" "toleration"={"key":"celeste/hostname","operator":"Equal","value":"gpu3","effect":"NoExecute"}
I0721 20:10:46.112688    1186 placement_manager.go:147]  "msg"="Adding toleration to pod"  "podName"="tf2-keras-transformer-elastic-20210721-064152-worker-1" "scheduler"="default" "toleration"={"key":"celeste/hostname","operator":"Equal","value":"gpu3","effect":"NoExecute"}
I0721 20:10:49.746385    1186 placement_manager.go:147]  "msg"="Adding toleration to pod"  "podName"="tf2-keras-transformer-elastic-20210721-064152-launcher" "scheduler"="default" "toleration"={"key":"celeste/hostname","operator":"Exists","effect":"NoExecute"}
I0721 20:10:49.984661    1186 placement_manager.go:147]  "msg"="Adding toleration to pod"  "podName"="tf2-keras-transformer-elastic-20210721-063927-worker-1" "scheduler"="default" "toleration"={"key":"celeste/hostname","operator":"Equal","value":"gpu5","effect":"NoExecute"}
I0721 20:10:51.000253    1186 placement_manager.go:147]  "msg"="Adding toleration to pod"  "podName"="tf2-keras-transformer-elastic-20210721-063927-worker-0" "scheduler"="default" "toleration"={"key":"celeste/hostname","operator":"Equal","value":"gpu5","effect":"NoExecute"}
I0721 20:10:51.790853    1186 placement_manager.go:147]  "msg"="Adding toleration to pod"  "podName"="tf2-keras-transformer-elastic-20210721-063927-launcher" "scheduler"="default" "toleration"={"key":"celeste/hostname","operator":"Exists","effect":"NoExecute"}
I0721 20:10:53.549961    1186 scheduler.go:474]  "msg"="Training job completed"  "elaspedTotalSeconds"=5711.959454524 "gpuTotalSeconds"=5440.172884215 "job"="tf2-keras-cifar10-inceptionv3-elastic-20210721-063539" "ranTotalSeconds"=2660.084833276 "scheduler"="default" "waitedTotalSeconds"=3051.874621248
I0721 20:12:31.656716    1186 scheduler.go:559]  "msg"="Priority demoted to training job"  "job"="tf2-keras-cifar10-inceptionv3-elastic-20210721-064117" "priority"=1 "scheduler"="default"
I0721 20:12:31.656850    1186 scheduler.go:559]  "msg"="Priority demoted to training job"  "job"="tf2-keras-transformer-elastic-20210721-063927" "priority"=1 "scheduler"="default"
I0721 20:12:31.656916    1186 scheduler.go:573]  "msg"="Priority changed"  "scheduler"="default"
I0721 20:12:31.750233    1186 scheduler.go:159]  "msg"="Started resched"  "scheduler"="default"
I0721 20:12:31.750305    1186 scheduler.go:193]  "msg"="Updating all jobs info"  "scheduler"="default"
I0721 20:12:31.757480    1186 elastic_tiresias.go:160]  "msg"="Finished scheduling"  "algorithm"="ElasticTiresias" "compactionThreshold"=4 "freeGpu"=0 "promoteKnob"=4 "queueNum"=2 "result"={"tf2-keras-cifar10-inceptionv3-elastic-20210721-063448":1,"tf2-keras-cifar10-inceptionv3-elastic-20210721-063756":2,"tf2-keras-cifar10-inceptionv3-elastic-20210721-063900":2,"tf2-keras-cifar10-inceptionv3-elastic-20210721-064117":1,"tf2-keras-cifar10-inceptionv3-elastic-20210721-064215":1,"tf2-keras-cifar10-resnet50-elastic-20210721-064451":0,"tf2-keras-cifar10-vgg16-elastic-20210721-064310":1,"tf2-keras-transformer-elastic-20210721-063927":1,"tf2-keras-transformer-elastic-20210721-064152":2,"tf2-keras-transformer-elastic-20210721-064332":1,"tf2-keras-transformer-elastic-20210721-064545":0} "scheduler"="default" "thresholds"=
I0721 20:12:31.757794    1186 scheduler.go:384]  "msg"="Trying to delete multiple training jobs"  "jobs"=[] "scheduler"="default"
I0721 20:12:31.758062    1186 scheduler.go:342]  "msg"="Trying to scale multiple training jobs"  "jobs"=["tf2-keras-transformer-elastic-20210721-063927","tf2-keras-cifar10-inceptionv3-elastic-20210721-064117"] "scheduler"="default"
I0721 20:12:31.809219    1186 scheduler.go:292]  "msg"="Trying to start multiple training jobs"  "jobs"=["tf2-keras-transformer-elastic-20210721-064332","tf2-keras-cifar10-vgg16-elastic-20210721-064310","tf2-keras-cifar10-inceptionv3-elastic-20210721-064215"] "scheduler"="default"
I0721 20:12:31.831424    1186 scheduler.go:342]  "msg"="Trying to scale multiple training jobs"  "jobs"=["tf2-keras-cifar10-inceptionv3-elastic-20210721-063756"] "scheduler"="default"
I0721 20:12:31.853034    1186 placement_manager.go:166]  "msg"="Started job placements adjustment"  "scheduler"="default"
I0721 20:12:31.853114    1186 placement_manager.go:192]  "msg"="Releasing slots"  "jobs"={"tf2-keras-cifar10-inceptionv3-elastic-20210721-063448":{},"tf2-keras-cifar10-inceptionv3-elastic-20210721-063539":{},"tf2-keras-cifar10-inceptionv3-elastic-20210721-063756":{},"tf2-keras-cifar10-inceptionv3-elastic-20210721-063900":{},"tf2-keras-cifar10-inceptionv3-elastic-20210721-064117":{},"tf2-keras-transformer-elastic-20210721-063927":{},"tf2-keras-transformer-elastic-20210721-064152":{}} "nodes"={"gpu3":{},"gpu4":{},"gpu5":{}} "scheduler"="default"
I0721 20:12:31.853211    1186 placement_manager.go:250]  "msg"="Released slots"  "jobs"={"tf2-keras-cifar10-inceptionv3-elastic-20210721-063448":{},"tf2-keras-cifar10-inceptionv3-elastic-20210721-063539":{},"tf2-keras-cifar10-inceptionv3-elastic-20210721-063756":{},"tf2-keras-cifar10-inceptionv3-elastic-20210721-063900":{},"tf2-keras-cifar10-inceptionv3-elastic-20210721-064117":{},"tf2-keras-transformer-elastic-20210721-063927":{},"tf2-keras-transformer-elastic-20210721-064152":{}} "nodes"={"gpu3":{},"gpu4":{},"gpu5":{}} "scheduler"="default"
I0721 20:12:31.853655    1186 placement_manager.go:305]  "msg"="Found best-fit"  "crossNode"=0 "nodes"=[{},{},{}] "requests"=[{},{},{},{},{},{},{},{},{},{},{},{},{},{},{},{},{},{},{},{},{},{}] "scheduler"="default"
I0721 20:12:31.853933    1186 placement_manager.go:339]  "msg"="nodeStates updated"  "new"={"gpu3":{},"gpu4":{},"gpu5":{}} "old"={"gpu3":{},"gpu4":{},"gpu5":{}} "scheduler"="default" "score"=5
I0721 20:12:31.854158    1186 placement_manager.go:387]  "msg"="jobStates updated"  "new"={"tf2-keras-cifar10-inceptionv3-elastic-20210721-063448":{},"tf2-keras-cifar10-inceptionv3-elastic-20210721-063756":{},"tf2-keras-cifar10-inceptionv3-elastic-20210721-063900":{},"tf2-keras-cifar10-inceptionv3-elastic-20210721-064117":{},"tf2-keras-cifar10-inceptionv3-elastic-20210721-064215":{},"tf2-keras-cifar10-vgg16-elastic-20210721-064310":{},"tf2-keras-transformer-elastic-20210721-063927":{},"tf2-keras-transformer-elastic-20210721-064152":{},"tf2-keras-transformer-elastic-20210721-064332":{}} "old"={"tf2-keras-cifar10-inceptionv3-elastic-20210721-063448":{},"tf2-keras-cifar10-inceptionv3-elastic-20210721-063539":{},"tf2-keras-cifar10-inceptionv3-elastic-20210721-063756":{},"tf2-keras-cifar10-inceptionv3-elastic-20210721-063900":{},"tf2-keras-cifar10-inceptionv3-elastic-20210721-064117":{},"tf2-keras-transformer-elastic-20210721-063927":{},"tf2-keras-transformer-elastic-20210721-064152":{}} "scheduler"="default"
I0721 20:12:31.854476    1186 placement_manager.go:434]  "msg"="podNodeName updated"  "launchersToDelete"=2 "new"={"tf2-keras-cifar10-inceptionv3-elastic-20210721-063448-worker-0":"gpu4","tf2-keras-cifar10-inceptionv3-elastic-20210721-063756-worker-0":"gpu5","tf2-keras-cifar10-inceptionv3-elastic-20210721-063756-worker-1":"gpu5","tf2-keras-cifar10-inceptionv3-elastic-20210721-063900-worker-0":"gpu5","tf2-keras-cifar10-inceptionv3-elastic-20210721-063900-worker-1":"gpu5","tf2-keras-cifar10-inceptionv3-elastic-20210721-064117-worker-0":"gpu3","tf2-keras-cifar10-inceptionv3-elastic-20210721-064215-worker-0":"gpu3","tf2-keras-cifar10-vgg16-elastic-20210721-064310-worker-0":"gpu4","tf2-keras-transformer-elastic-20210721-063927-worker-0":"gpu4","tf2-keras-transformer-elastic-20210721-064152-worker-0":"gpu3","tf2-keras-transformer-elastic-20210721-064152-worker-1":"gpu3","tf2-keras-transformer-elastic-20210721-064332-worker-0":"gpu4"} "old"={"tf2-keras-cifar10-inceptionv3-elastic-20210721-063448-worker-0":"gpu4","tf2-keras-cifar10-inceptionv3-elastic-20210721-063539-worker-0":"gpu3","tf2-keras-cifar10-inceptionv3-elastic-20210721-063539-worker-1":"gpu3","tf2-keras-cifar10-inceptionv3-elastic-20210721-063756-worker-0":"gpu4","tf2-keras-cifar10-inceptionv3-elastic-20210721-063900-worker-0":"gpu5","tf2-keras-cifar10-inceptionv3-elastic-20210721-063900-worker-1":"gpu5","tf2-keras-cifar10-inceptionv3-elastic-20210721-064117-worker-0":"gpu4","tf2-keras-cifar10-inceptionv3-elastic-20210721-064117-worker-1":"gpu4","tf2-keras-transformer-elastic-20210721-063927-worker-0":"gpu5","tf2-keras-transformer-elastic-20210721-063927-worker-1":"gpu5","tf2-keras-transformer-elastic-20210721-064152-worker-0":"gpu3","tf2-keras-transformer-elastic-20210721-064152-worker-1":"gpu3"} "scheduler"="default" "workersToDelete"=3
I0721 20:12:31.854771    1186 placement_manager.go:451]  "msg"="Deleting pod that need migration"  "podName"="tf2-keras-transformer-elastic-20210721-063927-worker-0" "scheduler"="default"
I0721 20:12:31.859364    1186 placement_manager.go:451]  "msg"="Deleting pod that need migration"  "podName"="tf2-keras-transformer-elastic-20210721-063927-launcher" "scheduler"="default"
I0721 20:12:31.863649    1186 placement_manager.go:451]  "msg"="Deleting pod that need migration"  "podName"="tf2-keras-cifar10-inceptionv3-elastic-20210721-064117-worker-0" "scheduler"="default"
I0721 20:12:31.867489    1186 placement_manager.go:451]  "msg"="Deleting pod that need migration"  "podName"="tf2-keras-cifar10-inceptionv3-elastic-20210721-064117-launcher" "scheduler"="default"
I0721 20:12:31.872130    1186 placement_manager.go:451]  "msg"="Deleting pod that need migration"  "podName"="tf2-keras-cifar10-inceptionv3-elastic-20210721-063756-worker-0" "scheduler"="default"
I0721 20:12:31.876476    1186 placement_manager.go:183]  "msg"="Finished job placements adjustment"  "scheduler"="default"
I0721 20:12:31.876815    1186 scheduler.go:182]  "msg"="Finished resched"  "scheduler"="default"
I0721 20:12:33.601735    1186 placement_manager.go:147]  "msg"="Adding toleration to pod"  "podName"="tf2-keras-transformer-elastic-20210721-064332-worker-0" "scheduler"="default" "toleration"={"key":"celeste/hostname","operator":"Equal","value":"gpu4","effect":"NoExecute"}
I0721 20:12:33.999717    1186 placement_manager.go:147]  "msg"="Adding toleration to pod"  "podName"="tf2-keras-transformer-elastic-20210721-064332-launcher" "scheduler"="default" "toleration"={"key":"celeste/hostname","operator":"Exists","effect":"NoExecute"}
I0721 20:12:34.198013    1186 placement_manager.go:147]  "msg"="Adding toleration to pod"  "podName"="tf2-keras-cifar10-vgg16-elastic-20210721-064310-worker-0" "scheduler"="default" "toleration"={"key":"celeste/hostname","operator":"Equal","value":"gpu4","effect":"NoExecute"}
I0721 20:12:34.599654    1186 placement_manager.go:147]  "msg"="Adding toleration to pod"  "podName"="tf2-keras-cifar10-vgg16-elastic-20210721-064310-launcher" "scheduler"="default" "toleration"={"key":"celeste/hostname","operator":"Exists","effect":"NoExecute"}
I0721 20:12:36.597918    1186 placement_manager.go:147]  "msg"="Adding toleration to pod"  "podName"="tf2-keras-cifar10-inceptionv3-elastic-20210721-063756-worker-1" "scheduler"="default" "toleration"={"key":"celeste/hostname","operator":"Equal","value":"gpu5","effect":"NoExecute"}
I0721 20:12:36.657129    1186 scheduler.go:565]  "msg"="Priority promoted to training job"  "job"="tf2-keras-cifar10-vgg16-elastic-20210721-064310" "priority"=0 "scheduler"="default"
I0721 20:12:36.657204    1186 scheduler.go:565]  "msg"="Priority promoted to training job"  "job"="tf2-keras-transformer-elastic-20210721-064332" "priority"=0 "scheduler"="default"
I0721 20:12:36.657250    1186 scheduler.go:565]  "msg"="Priority promoted to training job"  "job"="tf2-keras-cifar10-inceptionv3-elastic-20210721-064215" "priority"=0 "scheduler"="default"
I0721 20:12:36.657281    1186 scheduler.go:573]  "msg"="Priority changed"  "scheduler"="default"
I0721 20:12:36.657356    1186 scheduler.go:135]  "msg"="Received resched event, may be blocked because of rate limit"  "blockedUntil"="2021-07-21T20:14:31.877062964+08:00" "lastResched"="2021-07-21T20:12:31.877062964+08:00" "received"="2021-07-21T20:12:36.657288112+08:00" "scheduler"="default"
I0721 20:12:36.798034    1186 placement_manager.go:147]  "msg"="Adding toleration to pod"  "podName"="tf2-keras-cifar10-inceptionv3-elastic-20210721-064215-worker-0" "scheduler"="default" "toleration"={"key":"celeste/hostname","operator":"Equal","value":"gpu3","effect":"NoExecute"}
I0721 20:12:36.998865    1186 placement_manager.go:147]  "msg"="Adding toleration to pod"  "podName"="tf2-keras-cifar10-inceptionv3-elastic-20210721-064215-launcher" "scheduler"="default" "toleration"={"key":"celeste/hostname","operator":"Exists","effect":"NoExecute"}
I0721 20:12:39.798148    1186 placement_manager.go:147]  "msg"="Adding toleration to pod"  "podName"="tf2-keras-cifar10-inceptionv3-elastic-20210721-064117-worker-0" "scheduler"="default" "toleration"={"key":"celeste/hostname","operator":"Equal","value":"gpu3","effect":"NoExecute"}
I0721 20:12:39.997587    1186 placement_manager.go:147]  "msg"="Adding toleration to pod"  "podName"="tf2-keras-cifar10-inceptionv3-elastic-20210721-063756-worker-0" "scheduler"="default" "toleration"={"key":"celeste/hostname","operator":"Equal","value":"gpu5","effect":"NoExecute"}
I0721 20:12:49.761750    1186 placement_manager.go:147]  "msg"="Adding toleration to pod"  "podName"="tf2-keras-cifar10-inceptionv3-elastic-20210721-064117-launcher" "scheduler"="default" "toleration"={"key":"celeste/hostname","operator":"Exists","effect":"NoExecute"}
I0721 20:12:49.808182    1186 placement_manager.go:147]  "msg"="Adding toleration to pod"  "podName"="tf2-keras-transformer-elastic-20210721-063927-worker-0" "scheduler"="default" "toleration"={"key":"celeste/hostname","operator":"Equal","value":"gpu4","effect":"NoExecute"}
I0721 20:12:49.983802    1186 placement_manager.go:147]  "msg"="Adding toleration to pod"  "podName"="tf2-keras-transformer-elastic-20210721-063927-launcher" "scheduler"="default" "toleration"={"key":"celeste/hostname","operator":"Exists","effect":"NoExecute"}
I0721 20:13:03.332187    1186 scheduler.go:474]  "msg"="Training job completed"  "elaspedTotalSeconds"=5892.934434941 "gpuTotalSeconds"=6181.142328036 "job"="tf2-keras-cifar10-inceptionv3-elastic-20210721-063448" "ranTotalSeconds"=3227.839013648 "scheduler"="default" "waitedTotalSeconds"=2665.095421293
I0721 20:14:31.877155    1186 scheduler.go:159]  "msg"="Started resched"  "scheduler"="default"
I0721 20:14:31.877264    1186 scheduler.go:193]  "msg"="Updating all jobs info"  "scheduler"="default"
I0721 20:14:31.882826    1186 elastic_tiresias.go:160]  "msg"="Finished scheduling"  "algorithm"="ElasticTiresias" "compactionThreshold"=4 "freeGpu"=0 "promoteKnob"=4 "queueNum"=2 "result"={"tf2-keras-cifar10-inceptionv3-elastic-20210721-063756":2,"tf2-keras-cifar10-inceptionv3-elastic-20210721-063900":2,"tf2-keras-cifar10-inceptionv3-elastic-20210721-064117":0,"tf2-keras-cifar10-inceptionv3-elastic-20210721-064215":2,"tf2-keras-cifar10-resnet50-elastic-20210721-064451":0,"tf2-keras-cifar10-vgg16-elastic-20210721-064310":2,"tf2-keras-transformer-elastic-20210721-063927":0,"tf2-keras-transformer-elastic-20210721-064152":2,"tf2-keras-transformer-elastic-20210721-064332":2,"tf2-keras-transformer-elastic-20210721-064545":0} "scheduler"="default" "thresholds"=
I0721 20:14:31.883134    1186 scheduler.go:384]  "msg"="Trying to delete multiple training jobs"  "jobs"=["tf2-keras-cifar10-inceptionv3-elastic-20210721-064117","tf2-keras-transformer-elastic-20210721-063927"] "scheduler"="default"
I0721 20:14:31.902191    1186 scheduler.go:342]  "msg"="Trying to scale multiple training jobs"  "jobs"=[] "scheduler"="default"
I0721 20:14:31.902680    1186 scheduler.go:292]  "msg"="Trying to start multiple training jobs"  "jobs"=[] "scheduler"="default"
I0721 20:14:31.903068    1186 scheduler.go:342]  "msg"="Trying to scale multiple training jobs"  "jobs"=["tf2-keras-cifar10-inceptionv3-elastic-20210721-064215","tf2-keras-cifar10-vgg16-elastic-20210721-064310","tf2-keras-transformer-elastic-20210721-064332"] "scheduler"="default"
I0721 20:14:31.963684    1186 placement_manager.go:166]  "msg"="Started job placements adjustment"  "scheduler"="default"
I0721 20:14:31.963799    1186 placement_manager.go:192]  "msg"="Releasing slots"  "jobs"={"tf2-keras-cifar10-inceptionv3-elastic-20210721-063448":{},"tf2-keras-cifar10-inceptionv3-elastic-20210721-063756":{},"tf2-keras-cifar10-inceptionv3-elastic-20210721-063900":{},"tf2-keras-cifar10-inceptionv3-elastic-20210721-064117":{},"tf2-keras-cifar10-inceptionv3-elastic-20210721-064215":{},"tf2-keras-cifar10-vgg16-elastic-20210721-064310":{},"tf2-keras-transformer-elastic-20210721-063927":{},"tf2-keras-transformer-elastic-20210721-064152":{},"tf2-keras-transformer-elastic-20210721-064332":{}} "nodes"={"gpu3":{},"gpu4":{},"gpu5":{}} "scheduler"="default"
I0721 20:14:31.963873    1186 placement_manager.go:250]  "msg"="Released slots"  "jobs"={"tf2-keras-cifar10-inceptionv3-elastic-20210721-063448":{},"tf2-keras-cifar10-inceptionv3-elastic-20210721-063756":{},"tf2-keras-cifar10-inceptionv3-elastic-20210721-063900":{},"tf2-keras-cifar10-inceptionv3-elastic-20210721-064117":{},"tf2-keras-cifar10-inceptionv3-elastic-20210721-064215":{},"tf2-keras-cifar10-vgg16-elastic-20210721-064310":{},"tf2-keras-transformer-elastic-20210721-063927":{},"tf2-keras-transformer-elastic-20210721-064152":{},"tf2-keras-transformer-elastic-20210721-064332":{}} "nodes"={"gpu3":{},"gpu4":{},"gpu5":{}} "scheduler"="default"
I0721 20:14:31.964411    1186 placement_manager.go:305]  "msg"="Found best-fit"  "crossNode"=0 "nodes"=[{},{},{}] "requests"=[{},{},{},{},{},{},{},{},{},{},{},{},{},{},{},{},{},{},{},{}] "scheduler"="default"
I0721 20:14:31.964807    1186 placement_manager.go:339]  "msg"="nodeStates updated"  "new"={"gpu3":{},"gpu4":{},"gpu5":{}} "old"={"gpu3":{},"gpu4":{},"gpu5":{}} "scheduler"="default" "score"=6
I0721 20:14:31.965311    1186 placement_manager.go:387]  "msg"="jobStates updated"  "new"={"tf2-keras-cifar10-inceptionv3-elastic-20210721-063756":{},"tf2-keras-cifar10-inceptionv3-elastic-20210721-063900":{},"tf2-keras-cifar10-inceptionv3-elastic-20210721-064215":{},"tf2-keras-cifar10-vgg16-elastic-20210721-064310":{},"tf2-keras-transformer-elastic-20210721-064152":{},"tf2-keras-transformer-elastic-20210721-064332":{}} "old"={"tf2-keras-cifar10-inceptionv3-elastic-20210721-063448":{},"tf2-keras-cifar10-inceptionv3-elastic-20210721-063756":{},"tf2-keras-cifar10-inceptionv3-elastic-20210721-063900":{},"tf2-keras-cifar10-inceptionv3-elastic-20210721-064117":{},"tf2-keras-cifar10-inceptionv3-elastic-20210721-064215":{},"tf2-keras-cifar10-vgg16-elastic-20210721-064310":{},"tf2-keras-transformer-elastic-20210721-063927":{},"tf2-keras-transformer-elastic-20210721-064152":{},"tf2-keras-transformer-elastic-20210721-064332":{}} "scheduler"="default"
I0721 20:14:31.965902    1186 placement_manager.go:434]  "msg"="podNodeName updated"  "launchersToDelete"=1 "new"={"tf2-keras-cifar10-inceptionv3-elastic-20210721-063756-worker-0":"gpu3","tf2-keras-cifar10-inceptionv3-elastic-20210721-063756-worker-1":"gpu3","tf2-keras-cifar10-inceptionv3-elastic-20210721-063900-worker-0":"gpu5","tf2-keras-cifar10-inceptionv3-elastic-20210721-063900-worker-1":"gpu5","tf2-keras-cifar10-inceptionv3-elastic-20210721-064215-worker-0":"gpu5","tf2-keras-cifar10-inceptionv3-elastic-20210721-064215-worker-1":"gpu5","tf2-keras-cifar10-vgg16-elastic-20210721-064310-worker-0":"gpu4","tf2-keras-cifar10-vgg16-elastic-20210721-064310-worker-1":"gpu4","tf2-keras-transformer-elastic-20210721-064152-worker-0":"gpu3","tf2-keras-transformer-elastic-20210721-064152-worker-1":"gpu3","tf2-keras-transformer-elastic-20210721-064332-worker-0":"gpu4","tf2-keras-transformer-elastic-20210721-064332-worker-1":"gpu4"} "old"={"tf2-keras-cifar10-inceptionv3-elastic-20210721-063448-worker-0":"gpu4","tf2-keras-cifar10-inceptionv3-elastic-20210721-063756-worker-0":"gpu5","tf2-keras-cifar10-inceptionv3-elastic-20210721-063756-worker-1":"gpu5","tf2-keras-cifar10-inceptionv3-elastic-20210721-063900-worker-0":"gpu5","tf2-keras-cifar10-inceptionv3-elastic-20210721-063900-worker-1":"gpu5","tf2-keras-cifar10-inceptionv3-elastic-20210721-064117-worker-0":"gpu3","tf2-keras-cifar10-inceptionv3-elastic-20210721-064215-worker-0":"gpu3","tf2-keras-cifar10-vgg16-elastic-20210721-064310-worker-0":"gpu4","tf2-keras-transformer-elastic-20210721-063927-worker-0":"gpu4","tf2-keras-transformer-elastic-20210721-064152-worker-0":"gpu3","tf2-keras-transformer-elastic-20210721-064152-worker-1":"gpu3","tf2-keras-transformer-elastic-20210721-064332-worker-0":"gpu4"} "scheduler"="default" "workersToDelete"=3
I0721 20:14:31.966361    1186 placement_manager.go:451]  "msg"="Deleting pod that need migration"  "podName"="tf2-keras-cifar10-inceptionv3-elastic-20210721-064215-worker-0" "scheduler"="default"
I0721 20:14:31.968590    1186 placement_manager.go:147]  "msg"="Adding toleration to pod"  "podName"="tf2-keras-cifar10-inceptionv3-elastic-20210721-064215-worker-1" "scheduler"="default" "toleration"={"key":"celeste/hostname","operator":"Equal","value":"gpu5","effect":"NoExecute"}
I0721 20:14:31.972413    1186 placement_manager.go:451]  "msg"="Deleting pod that need migration"  "podName"="tf2-keras-cifar10-inceptionv3-elastic-20210721-063756-worker-0" "scheduler"="default"
I0721 20:14:31.977042    1186 placement_manager.go:451]  "msg"="Deleting pod that need migration"  "podName"="tf2-keras-cifar10-inceptionv3-elastic-20210721-063756-worker-1" "scheduler"="default"
I0721 20:14:31.981962    1186 placement_manager.go:451]  "msg"="Deleting pod that need migration"  "podName"="tf2-keras-cifar10-inceptionv3-elastic-20210721-063756-launcher" "scheduler"="default"
I0721 20:14:31.986496    1186 placement_manager.go:183]  "msg"="Finished job placements adjustment"  "scheduler"="default"
I0721 20:14:31.986741    1186 scheduler.go:182]  "msg"="Finished resched"  "scheduler"="default"
I0721 20:14:32.000558    1186 placement_manager.go:147]  "msg"="Adding toleration to pod"  "podName"="tf2-keras-cifar10-vgg16-elastic-20210721-064310-worker-1" "scheduler"="default" "toleration"={"key":"celeste/hostname","operator":"Equal","value":"gpu4","effect":"NoExecute"}
I0721 20:14:32.010755    1186 placement_manager.go:147]  "msg"="Adding toleration to pod"  "podName"="tf2-keras-transformer-elastic-20210721-064332-worker-1" "scheduler"="default" "toleration"={"key":"celeste/hostname","operator":"Equal","value":"gpu4","effect":"NoExecute"}
I0721 20:14:39.089233    1186 placement_manager.go:147]  "msg"="Adding toleration to pod"  "podName"="tf2-keras-cifar10-inceptionv3-elastic-20210721-063756-launcher" "scheduler"="default" "toleration"={"key":"celeste/hostname","operator":"Exists","effect":"NoExecute"}
I0721 20:14:42.018667    1186 placement_manager.go:147]  "msg"="Adding toleration to pod"  "podName"="tf2-keras-cifar10-inceptionv3-elastic-20210721-064215-worker-0" "scheduler"="default" "toleration"={"key":"celeste/hostname","operator":"Equal","value":"gpu5","effect":"NoExecute"}
I0721 20:14:42.254982    1186 placement_manager.go:147]  "msg"="Adding toleration to pod"  "podName"="tf2-keras-cifar10-inceptionv3-elastic-20210721-063756-worker-1" "scheduler"="default" "toleration"={"key":"celeste/hostname","operator":"Equal","value":"gpu3","effect":"NoExecute"}
I0721 20:14:49.749955    1186 placement_manager.go:147]  "msg"="Adding toleration to pod"  "podName"="tf2-keras-cifar10-inceptionv3-elastic-20210721-063756-worker-0" "scheduler"="default" "toleration"={"key":"celeste/hostname","operator":"Equal","value":"gpu3","effect":"NoExecute"}
I0721 20:16:13.665861    1186 scheduler.go:474]  "msg"="Training job completed"  "elaspedTotalSeconds"=5580.752455301 "gpuTotalSeconds"=2120.07040372 "job"="tf2-keras-cifar10-vgg16-elastic-20210721-064310" "ranTotalSeconds"=1120.036871627 "scheduler"="default" "waitedTotalSeconds"=4460.715583674
I0721 20:16:13.666079    1186 scheduler.go:135]  "msg"="Received resched event, may be blocked because of rate limit"  "blockedUntil"="2021-07-21T20:16:31.986905396+08:00" "lastResched"="2021-07-21T20:14:31.986905396+08:00" "received"="2021-07-21T20:16:13.665941558+08:00" "scheduler"="default"
I0721 20:16:31.664635    1186 scheduler.go:559]  "msg"="Priority demoted to training job"  "job"="tf2-keras-cifar10-inceptionv3-elastic-20210721-063900" "priority"=1 "scheduler"="default"
I0721 20:16:31.664704    1186 scheduler.go:573]  "msg"="Priority changed"  "scheduler"="default"
I0721 20:16:31.986941    1186 scheduler.go:159]  "msg"="Started resched"  "scheduler"="default"
I0721 20:16:31.986980    1186 scheduler.go:193]  "msg"="Updating all jobs info"  "scheduler"="default"
I0721 20:16:31.992691    1186 elastic_tiresias.go:160]  "msg"="Finished scheduling"  "algorithm"="ElasticTiresias" "compactionThreshold"=4 "freeGpu"=0 "promoteKnob"=4 "queueNum"=2 "result"={"tf2-keras-cifar10-inceptionv3-elastic-20210721-063756":2,"tf2-keras-cifar10-inceptionv3-elastic-20210721-063900":2,"tf2-keras-cifar10-inceptionv3-elastic-20210721-064117":0,"tf2-keras-cifar10-inceptionv3-elastic-20210721-064215":2,"tf2-keras-cifar10-resnet50-elastic-20210721-064451":0,"tf2-keras-transformer-elastic-20210721-063927":2,"tf2-keras-transformer-elastic-20210721-064152":2,"tf2-keras-transformer-elastic-20210721-064332":2,"tf2-keras-transformer-elastic-20210721-064545":0} "scheduler"="default" "thresholds"=
I0721 20:16:31.993082    1186 scheduler.go:384]  "msg"="Trying to delete multiple training jobs"  "jobs"=[] "scheduler"="default"
I0721 20:16:31.993332    1186 scheduler.go:342]  "msg"="Trying to scale multiple training jobs"  "jobs"=[] "scheduler"="default"
I0721 20:16:31.993637    1186 scheduler.go:292]  "msg"="Trying to start multiple training jobs"  "jobs"=["tf2-keras-transformer-elastic-20210721-063927"] "scheduler"="default"
I0721 20:16:32.008652    1186 scheduler.go:342]  "msg"="Trying to scale multiple training jobs"  "jobs"=[] "scheduler"="default"
I0721 20:16:32.012431    1186 placement_manager.go:166]  "msg"="Started job placements adjustment"  "scheduler"="default"
I0721 20:16:32.012497    1186 placement_manager.go:192]  "msg"="Releasing slots"  "jobs"={"tf2-keras-cifar10-inceptionv3-elastic-20210721-063756":{},"tf2-keras-cifar10-inceptionv3-elastic-20210721-063900":{},"tf2-keras-cifar10-inceptionv3-elastic-20210721-064215":{},"tf2-keras-cifar10-vgg16-elastic-20210721-064310":{},"tf2-keras-transformer-elastic-20210721-064152":{},"tf2-keras-transformer-elastic-20210721-064332":{}} "nodes"={"gpu3":{},"gpu4":{},"gpu5":{}} "scheduler"="default"
I0721 20:16:32.012550    1186 placement_manager.go:250]  "msg"="Released slots"  "jobs"={"tf2-keras-cifar10-inceptionv3-elastic-20210721-063756":{},"tf2-keras-cifar10-inceptionv3-elastic-20210721-063900":{},"tf2-keras-cifar10-inceptionv3-elastic-20210721-064215":{},"tf2-keras-cifar10-vgg16-elastic-20210721-064310":{},"tf2-keras-transformer-elastic-20210721-064152":{},"tf2-keras-transformer-elastic-20210721-064332":{}} "nodes"={"gpu3":{},"gpu4":{},"gpu5":{}} "scheduler"="default"
I0721 20:16:32.013116    1186 placement_manager.go:305]  "msg"="Found best-fit"  "crossNode"=0 "nodes"=[{},{},{}] "requests"=[{},{},{},{},{},{},{},{},{},{},{},{},{},{},{},{},{},{}] "scheduler"="default"
I0721 20:16:32.013485    1186 placement_manager.go:339]  "msg"="nodeStates updated"  "new"={"gpu3":{},"gpu4":{},"gpu5":{}} "old"={"gpu3":{},"gpu4":{},"gpu5":{}} "scheduler"="default" "score"=6
I0721 20:16:32.013848    1186 placement_manager.go:387]  "msg"="jobStates updated"  "new"={"tf2-keras-cifar10-inceptionv3-elastic-20210721-063756":{},"tf2-keras-cifar10-inceptionv3-elastic-20210721-063900":{},"tf2-keras-cifar10-inceptionv3-elastic-20210721-064215":{},"tf2-keras-transformer-elastic-20210721-063927":{},"tf2-keras-transformer-elastic-20210721-064152":{},"tf2-keras-transformer-elastic-20210721-064332":{}} "old"={"tf2-keras-cifar10-inceptionv3-elastic-20210721-063756":{},"tf2-keras-cifar10-inceptionv3-elastic-20210721-063900":{},"tf2-keras-cifar10-inceptionv3-elastic-20210721-064215":{},"tf2-keras-cifar10-vgg16-elastic-20210721-064310":{},"tf2-keras-transformer-elastic-20210721-064152":{},"tf2-keras-transformer-elastic-20210721-064332":{}} "scheduler"="default"
I0721 20:16:32.014317    1186 placement_manager.go:434]  "msg"="podNodeName updated"  "launchersToDelete"=2 "new"={"tf2-keras-cifar10-inceptionv3-elastic-20210721-063756-worker-0":"gpu5","tf2-keras-cifar10-inceptionv3-elastic-20210721-063756-worker-1":"gpu5","tf2-keras-cifar10-inceptionv3-elastic-20210721-063900-worker-0":"gpu5","tf2-keras-cifar10-inceptionv3-elastic-20210721-063900-worker-1":"gpu5","tf2-keras-cifar10-inceptionv3-elastic-20210721-064215-worker-0":"gpu3","tf2-keras-cifar10-inceptionv3-elastic-20210721-064215-worker-1":"gpu3","tf2-keras-transformer-elastic-20210721-063927-worker-0":"gpu4","tf2-keras-transformer-elastic-20210721-063927-worker-1":"gpu4","tf2-keras-transformer-elastic-20210721-064152-worker-0":"gpu3","tf2-keras-transformer-elastic-20210721-064152-worker-1":"gpu3","tf2-keras-transformer-elastic-20210721-064332-worker-0":"gpu4","tf2-keras-transformer-elastic-20210721-064332-worker-1":"gpu4"} "old"={"tf2-keras-cifar10-inceptionv3-elastic-20210721-063756-worker-0":"gpu3","tf2-keras-cifar10-inceptionv3-elastic-20210721-063756-worker-1":"gpu3","tf2-keras-cifar10-inceptionv3-elastic-20210721-063900-worker-0":"gpu5","tf2-keras-cifar10-inceptionv3-elastic-20210721-063900-worker-1":"gpu5","tf2-keras-cifar10-inceptionv3-elastic-20210721-064215-worker-0":"gpu5","tf2-keras-cifar10-inceptionv3-elastic-20210721-064215-worker-1":"gpu5","tf2-keras-cifar10-vgg16-elastic-20210721-064310-worker-0":"gpu4","tf2-keras-cifar10-vgg16-elastic-20210721-064310-worker-1":"gpu4","tf2-keras-transformer-elastic-20210721-064152-worker-0":"gpu3","tf2-keras-transformer-elastic-20210721-064152-worker-1":"gpu3","tf2-keras-transformer-elastic-20210721-064332-worker-0":"gpu4","tf2-keras-transformer-elastic-20210721-064332-worker-1":"gpu4"} "scheduler"="default" "workersToDelete"=4
I0721 20:16:32.014752    1186 placement_manager.go:451]  "msg"="Deleting pod that need migration"  "podName"="tf2-keras-cifar10-inceptionv3-elastic-20210721-064215-worker-0" "scheduler"="default"
I0721 20:16:32.022567    1186 placement_manager.go:451]  "msg"="Deleting pod that need migration"  "podName"="tf2-keras-cifar10-inceptionv3-elastic-20210721-064215-worker-1" "scheduler"="default"
I0721 20:16:32.028873    1186 placement_manager.go:451]  "msg"="Deleting pod that need migration"  "podName"="tf2-keras-cifar10-inceptionv3-elastic-20210721-064215-launcher" "scheduler"="default"
I0721 20:16:32.060877    1186 placement_manager.go:451]  "msg"="Deleting pod that need migration"  "podName"="tf2-keras-cifar10-inceptionv3-elastic-20210721-063756-worker-0" "scheduler"="default"
I0721 20:16:32.064681    1186 placement_manager.go:451]  "msg"="Deleting pod that need migration"  "podName"="tf2-keras-cifar10-inceptionv3-elastic-20210721-063756-worker-1" "scheduler"="default"
I0721 20:16:32.076462    1186 placement_manager.go:451]  "msg"="Deleting pod that need migration"  "podName"="tf2-keras-cifar10-inceptionv3-elastic-20210721-063756-launcher" "scheduler"="default"
I0721 20:16:32.084443    1186 placement_manager.go:183]  "msg"="Finished job placements adjustment"  "scheduler"="default"
I0721 20:16:32.084663    1186 scheduler.go:182]  "msg"="Finished resched"  "scheduler"="default"
I0721 20:16:32.093895    1186 placement_manager.go:147]  "msg"="Adding toleration to pod"  "podName"="tf2-keras-transformer-elastic-20210721-063927-worker-0" "scheduler"="default" "toleration"={"key":"celeste/hostname","operator":"Equal","value":"gpu4","effect":"NoExecute"}
I0721 20:16:32.215460    1186 placement_manager.go:147]  "msg"="Adding toleration to pod"  "podName"="tf2-keras-transformer-elastic-20210721-063927-worker-1" "scheduler"="default" "toleration"={"key":"celeste/hostname","operator":"Equal","value":"gpu4","effect":"NoExecute"}
I0721 20:16:32.616504    1186 placement_manager.go:147]  "msg"="Adding toleration to pod"  "podName"="tf2-keras-transformer-elastic-20210721-063927-launcher" "scheduler"="default" "toleration"={"key":"celeste/hostname","operator":"Exists","effect":"NoExecute"}
I0721 20:16:36.665012    1186 scheduler.go:565]  "msg"="Priority promoted to training job"  "job"="tf2-keras-transformer-elastic-20210721-063927" "priority"=0 "scheduler"="default"
I0721 20:16:36.665092    1186 scheduler.go:573]  "msg"="Priority changed"  "scheduler"="default"
I0721 20:16:36.665197    1186 scheduler.go:135]  "msg"="Received resched event, may be blocked because of rate limit"  "blockedUntil"="2021-07-21T20:18:32.084858743+08:00" "lastResched"="2021-07-21T20:16:32.084858743+08:00" "received"="2021-07-21T20:16:36.665105491+08:00" "scheduler"="default"
I0721 20:16:39.751613    1186 placement_manager.go:147]  "msg"="Adding toleration to pod"  "podName"="tf2-keras-cifar10-inceptionv3-elastic-20210721-064215-launcher" "scheduler"="default" "toleration"={"key":"celeste/hostname","operator":"Exists","effect":"NoExecute"}
I0721 20:16:41.788564    1186 placement_manager.go:147]  "msg"="Adding toleration to pod"  "podName"="tf2-keras-cifar10-inceptionv3-elastic-20210721-063756-worker-0" "scheduler"="default" "toleration"={"key":"celeste/hostname","operator":"Equal","value":"gpu5","effect":"NoExecute"}
I0721 20:16:41.819432    1186 placement_manager.go:147]  "msg"="Adding toleration to pod"  "podName"="tf2-keras-cifar10-inceptionv3-elastic-20210721-063756-worker-1" "scheduler"="default" "toleration"={"key":"celeste/hostname","operator":"Equal","value":"gpu5","effect":"NoExecute"}
I0721 20:16:49.761579    1186 placement_manager.go:147]  "msg"="Adding toleration to pod"  "podName"="tf2-keras-cifar10-inceptionv3-elastic-20210721-064215-worker-1" "scheduler"="default" "toleration"={"key":"celeste/hostname","operator":"Equal","value":"gpu3","effect":"NoExecute"}
I0721 20:16:49.866130    1186 placement_manager.go:147]  "msg"="Adding toleration to pod"  "podName"="tf2-keras-cifar10-inceptionv3-elastic-20210721-064215-worker-0" "scheduler"="default" "toleration"={"key":"celeste/hostname","operator":"Equal","value":"gpu3","effect":"NoExecute"}
I0721 20:16:50.264192    1186 placement_manager.go:147]  "msg"="Adding toleration to pod"  "podName"="tf2-keras-cifar10-inceptionv3-elastic-20210721-063756-launcher" "scheduler"="default" "toleration"={"key":"celeste/hostname","operator":"Exists","effect":"NoExecute"}
I0721 20:18:08.578434    1186 scheduler.go:474]  "msg"="Training job completed"  "elaspedTotalSeconds"=5773.698912792 "gpuTotalSeconds"=3680.123264479 "job"="tf2-keras-transformer-elastic-20210721-064152" "ranTotalSeconds"=1900.063272852 "scheduler"="default" "waitedTotalSeconds"=3873.63563994
I0721 20:18:31.610108    1186 scheduler.go:474]  "msg"="Training job completed"  "elaspedTotalSeconds"=5939.447561439 "gpuTotalSeconds"=3950.137389615 "job"="tf2-keras-transformer-elastic-20210721-063927" "ranTotalSeconds"=2095.072148747 "scheduler"="default" "waitedTotalSeconds"=3844.375412692
I0721 20:18:32.084912    1186 scheduler.go:159]  "msg"="Started resched"  "scheduler"="default"
I0721 20:18:32.084959    1186 scheduler.go:193]  "msg"="Updating all jobs info"  "scheduler"="default"
I0721 20:18:32.090849    1186 elastic_tiresias.go:160]  "msg"="Finished scheduling"  "algorithm"="ElasticTiresias" "compactionThreshold"=4 "freeGpu"=0 "promoteKnob"=4 "queueNum"=2 "result"={"tf2-keras-cifar10-inceptionv3-elastic-20210721-063756":2,"tf2-keras-cifar10-inceptionv3-elastic-20210721-063900":2,"tf2-keras-cifar10-inceptionv3-elastic-20210721-064117":2,"tf2-keras-cifar10-inceptionv3-elastic-20210721-064215":2,"tf2-keras-cifar10-resnet50-elastic-20210721-064451":2,"tf2-keras-transformer-elastic-20210721-064332":2,"tf2-keras-transformer-elastic-20210721-064545":0} "scheduler"="default" "thresholds"=
I0721 20:18:32.091275    1186 scheduler.go:384]  "msg"="Trying to delete multiple training jobs"  "jobs"=[] "scheduler"="default"
I0721 20:18:32.091635    1186 scheduler.go:342]  "msg"="Trying to scale multiple training jobs"  "jobs"=[] "scheduler"="default"
I0721 20:18:32.091959    1186 scheduler.go:292]  "msg"="Trying to start multiple training jobs"  "jobs"=["tf2-keras-cifar10-inceptionv3-elastic-20210721-064117","tf2-keras-cifar10-resnet50-elastic-20210721-064451"] "scheduler"="default"
I0721 20:18:32.112145    1186 scheduler.go:342]  "msg"="Trying to scale multiple training jobs"  "jobs"=[] "scheduler"="default"
I0721 20:18:32.115395    1186 placement_manager.go:166]  "msg"="Started job placements adjustment"  "scheduler"="default"
I0721 20:18:32.115476    1186 placement_manager.go:192]  "msg"="Releasing slots"  "jobs"={"tf2-keras-cifar10-inceptionv3-elastic-20210721-063756":{},"tf2-keras-cifar10-inceptionv3-elastic-20210721-063900":{},"tf2-keras-cifar10-inceptionv3-elastic-20210721-064215":{},"tf2-keras-transformer-elastic-20210721-063927":{},"tf2-keras-transformer-elastic-20210721-064152":{},"tf2-keras-transformer-elastic-20210721-064332":{}} "nodes"={"gpu3":{},"gpu4":{},"gpu5":{}} "scheduler"="default"
I0721 20:18:32.115544    1186 placement_manager.go:250]  "msg"="Released slots"  "jobs"={"tf2-keras-cifar10-inceptionv3-elastic-20210721-063756":{},"tf2-keras-cifar10-inceptionv3-elastic-20210721-063900":{},"tf2-keras-cifar10-inceptionv3-elastic-20210721-064215":{},"tf2-keras-transformer-elastic-20210721-063927":{},"tf2-keras-transformer-elastic-20210721-064152":{},"tf2-keras-transformer-elastic-20210721-064332":{}} "nodes"={"gpu3":{},"gpu4":{},"gpu5":{}} "scheduler"="default"
I0721 20:18:32.115976    1186 placement_manager.go:305]  "msg"="Found best-fit"  "crossNode"=0 "nodes"=[{},{},{}] "requests"=[{},{},{},{},{},{},{},{},{},{},{},{},{},{}] "scheduler"="default"
I0721 20:18:32.116382    1186 placement_manager.go:339]  "msg"="nodeStates updated"  "new"={"gpu3":{},"gpu4":{},"gpu5":{}} "old"={"gpu3":{},"gpu4":{},"gpu5":{}} "scheduler"="default" "score"=8
I0721 20:18:32.116709    1186 placement_manager.go:387]  "msg"="jobStates updated"  "new"={"tf2-keras-cifar10-inceptionv3-elastic-20210721-063756":{},"tf2-keras-cifar10-inceptionv3-elastic-20210721-063900":{},"tf2-keras-cifar10-inceptionv3-elastic-20210721-064117":{},"tf2-keras-cifar10-inceptionv3-elastic-20210721-064215":{},"tf2-keras-cifar10-resnet50-elastic-20210721-064451":{},"tf2-keras-transformer-elastic-20210721-064332":{}} "old"={"tf2-keras-cifar10-inceptionv3-elastic-20210721-063756":{},"tf2-keras-cifar10-inceptionv3-elastic-20210721-063900":{},"tf2-keras-cifar10-inceptionv3-elastic-20210721-064215":{},"tf2-keras-transformer-elastic-20210721-063927":{},"tf2-keras-transformer-elastic-20210721-064152":{},"tf2-keras-transformer-elastic-20210721-064332":{}} "scheduler"="default"
