Log file created at: 2021/07/21 16:24:04
Running on machine: gpu4
Binary: Built with gc go1.13.15 for linux/amd64
Log line format: [IWEF]mmdd hh:mm:ss.uuuuuu threadid file:line] msg
I0721 16:24:04.913154   31979 main.go:19]  "msg"="Celeste - DLT jobs scheduler"  "version"="0.0.1"
I0721 16:24:04.914043   31979 main.go:20]  "msg"="Starting service"  
I0721 16:24:04.919678   31979 placement_manager.go:65]  "msg"="Starting placement manager"  "scheduler"="default"
I0721 16:24:04.920860   31979 placement_manager.go:95]  "msg"="Started placement manager"  "nodes"={"gpu3":{},"gpu4":{},"gpu5":{}} "scheduler"="default"
I0721 16:24:04.921275   31979 jobmaster.go:82]  "msg"="Starting scheduler"  "gpuType"="default"
I0721 16:24:04.921380   31979 scheduler.go:124]  "msg"="Starting scheduler"  "scheduler"="default"
I0721 16:24:04.953782   31979 scheduler.go:432]  "msg"="Start watching mpijob"  "scheduler"="default"
I0721 16:24:59.626539   31979 jobmaster.go:155]  "msg"="Training job created"  "job"="tf2-keras-cifar10-inceptionv3-elastic-20210721-042459"
I0721 16:24:59.626692   31979 scheduler.go:135]  "msg"="Received resched event, may be blocked because of rate limit"  "blockedUntil"="2021-07-21T16:24:04.921240891+08:00" "lastResched"="2021-07-21T16:24:04.921241174+08:00" "received"="2021-07-21T16:24:59.625870965+08:00" "scheduler"="default"
I0721 16:24:59.627134   31979 scheduler.go:159]  "msg"="Started resched"  "scheduler"="default"
I0721 16:24:59.627206   31979 scheduler.go:193]  "msg"="Updating all jobs info"  "scheduler"="default"
I0721 16:24:59.628680   31979 elastic_fifo.go:73]  "msg"="Finished scheduling"  "algorithm"="ElasticFIFO" "freeGpu"=8 "result"={"tf2-keras-cifar10-inceptionv3-elastic-20210721-042459":4} "scheduler"="default"
I0721 16:24:59.628952   31979 scheduler.go:384]  "msg"="Trying to delete multiple training jobs"  "jobs"=[] "scheduler"="default"
I0721 16:24:59.629274   31979 scheduler.go:342]  "msg"="Trying to scale multiple training jobs"  "jobs"=[] "scheduler"="default"
I0721 16:24:59.629503   31979 scheduler.go:292]  "msg"="Trying to start multiple training jobs"  "jobs"=["tf2-keras-cifar10-inceptionv3-elastic-20210721-042459"] "scheduler"="default"
I0721 16:24:59.655448   31979 scheduler.go:342]  "msg"="Trying to scale multiple training jobs"  "jobs"=[] "scheduler"="default"
I0721 16:24:59.657382   31979 placement_manager.go:166]  "msg"="Started job placements adjustment"  "scheduler"="default"
I0721 16:24:59.657521   31979 placement_manager.go:192]  "msg"="Releasing slots"  "jobs"={} "nodes"={"gpu3":{},"gpu4":{},"gpu5":{}} "scheduler"="default"
I0721 16:24:59.657570   31979 placement_manager.go:250]  "msg"="Released slots"  "jobs"={} "nodes"={"gpu3":{},"gpu4":{},"gpu5":{}} "scheduler"="default"
I0721 16:24:59.657934   31979 placement_manager.go:305]  "msg"="Found best-fit"  "crossNode"=0 "nodes"=[{},{},{}] "requests"=[{},{}] "scheduler"="default"
I0721 16:24:59.658235   31979 placement_manager.go:339]  "msg"="nodeStates updated"  "new"={"gpu3":{},"gpu4":{},"gpu5":{}} "old"={"gpu3":{},"gpu4":{},"gpu5":{}} "scheduler"="default" "score"=0
I0721 16:24:59.658561   31979 placement_manager.go:387]  "msg"="jobStates updated"  "new"={"tf2-keras-cifar10-inceptionv3-elastic-20210721-042459":{}} "old"={} "scheduler"="default"
I0721 16:24:59.658958   31979 placement_manager.go:434]  "msg"="podNodeName updated"  "launchersToDelete"=0 "new"={"tf2-keras-cifar10-inceptionv3-elastic-20210721-042459-worker-0":"gpu3","tf2-keras-cifar10-inceptionv3-elastic-20210721-042459-worker-1":"gpu3","tf2-keras-cifar10-inceptionv3-elastic-20210721-042459-worker-2":"gpu3","tf2-keras-cifar10-inceptionv3-elastic-20210721-042459-worker-3":"gpu3"} "old"={} "scheduler"="default" "workersToDelete"=0
I0721 16:24:59.659206   31979 placement_manager.go:183]  "msg"="Finished job placements adjustment"  "scheduler"="default"
I0721 16:24:59.659406   31979 scheduler.go:182]  "msg"="Finished resched"  "scheduler"="default"
I0721 16:24:59.734661   31979 placement_manager.go:147]  "msg"="Adding toleration to pod"  "podName"="tf2-keras-cifar10-inceptionv3-elastic-20210721-042459-worker-0" "scheduler"="default" "toleration"={"key":"celeste/hostname","operator":"Equal","value":"gpu3","effect":"NoExecute"}
I0721 16:24:59.769456   31979 placement_manager.go:147]  "msg"="Adding toleration to pod"  "podName"="tf2-keras-cifar10-inceptionv3-elastic-20210721-042459-worker-1" "scheduler"="default" "toleration"={"key":"celeste/hostname","operator":"Equal","value":"gpu3","effect":"NoExecute"}
I0721 16:24:59.779367   31979 placement_manager.go:147]  "msg"="Adding toleration to pod"  "podName"="tf2-keras-cifar10-inceptionv3-elastic-20210721-042459-worker-2" "scheduler"="default" "toleration"={"key":"celeste/hostname","operator":"Equal","value":"gpu3","effect":"NoExecute"}
I0721 16:24:59.791296   31979 placement_manager.go:147]  "msg"="Adding toleration to pod"  "podName"="tf2-keras-cifar10-inceptionv3-elastic-20210721-042459-worker-3" "scheduler"="default" "toleration"={"key":"celeste/hostname","operator":"Equal","value":"gpu3","effect":"NoExecute"}
I0721 16:24:59.800052   31979 placement_manager.go:147]  "msg"="Adding toleration to pod"  "podName"="tf2-keras-cifar10-inceptionv3-elastic-20210721-042459-launcher" "scheduler"="default" "toleration"={"key":"celeste/hostname","operator":"Exists","effect":"NoExecute"}
I0721 16:25:22.612204   31979 jobmaster.go:155]  "msg"="Training job created"  "job"="tf2-keras-cifar10-resnet50-elastic-20210721-042522"
I0721 16:25:22.612328   31979 scheduler.go:135]  "msg"="Received resched event, may be blocked because of rate limit"  "blockedUntil"="2021-07-21T16:26:59.659590939+08:00" "lastResched"="2021-07-21T16:24:59.659590939+08:00" "received"="2021-07-21T16:25:22.611543248+08:00" "scheduler"="default"
I0721 16:25:50.538852   31979 jobmaster.go:155]  "msg"="Training job created"  "job"="tf2-keras-cifar10-inceptionv3-elastic-20210721-042550"
I0721 16:26:20.471628   31979 jobmaster.go:155]  "msg"="Training job created"  "job"="tf2-keras-cifar10-vgg16-elastic-20210721-042620"
I0721 16:26:42.434505   31979 jobmaster.go:155]  "msg"="Training job created"  "job"="tf2-keras-cifar10-vgg16-elastic-20210721-042642"
I0721 16:26:59.659742   31979 scheduler.go:159]  "msg"="Started resched"  "scheduler"="default"
I0721 16:26:59.659872   31979 scheduler.go:193]  "msg"="Updating all jobs info"  "scheduler"="default"
I0721 16:26:59.663384   31979 elastic_fifo.go:73]  "msg"="Finished scheduling"  "algorithm"="ElasticFIFO" "freeGpu"=0 "result"={"tf2-keras-cifar10-inceptionv3-elastic-20210721-042459":3,"tf2-keras-cifar10-inceptionv3-elastic-20210721-042550":2,"tf2-keras-cifar10-resnet50-elastic-20210721-042522":3,"tf2-keras-cifar10-vgg16-elastic-20210721-042620":2,"tf2-keras-cifar10-vgg16-elastic-20210721-042642":2} "scheduler"="default"
I0721 16:26:59.663813   31979 scheduler.go:384]  "msg"="Trying to delete multiple training jobs"  "jobs"=[] "scheduler"="default"
I0721 16:26:59.664279   31979 scheduler.go:342]  "msg"="Trying to scale multiple training jobs"  "jobs"=["tf2-keras-cifar10-inceptionv3-elastic-20210721-042459"] "scheduler"="default"
I0721 16:26:59.683657   31979 scheduler.go:292]  "msg"="Trying to start multiple training jobs"  "jobs"=["tf2-keras-cifar10-resnet50-elastic-20210721-042522","tf2-keras-cifar10-inceptionv3-elastic-20210721-042550","tf2-keras-cifar10-vgg16-elastic-20210721-042620","tf2-keras-cifar10-vgg16-elastic-20210721-042642"] "scheduler"="default"
I0721 16:26:59.732800   31979 scheduler.go:342]  "msg"="Trying to scale multiple training jobs"  "jobs"=[] "scheduler"="default"
I0721 16:26:59.736769   31979 placement_manager.go:166]  "msg"="Started job placements adjustment"  "scheduler"="default"
I0721 16:26:59.736855   31979 placement_manager.go:192]  "msg"="Releasing slots"  "jobs"={"tf2-keras-cifar10-inceptionv3-elastic-20210721-042459":{}} "nodes"={"gpu3":{},"gpu4":{},"gpu5":{}} "scheduler"="default"
I0721 16:26:59.736969   31979 placement_manager.go:250]  "msg"="Released slots"  "jobs"={"tf2-keras-cifar10-inceptionv3-elastic-20210721-042459":{}} "nodes"={"gpu3":{},"gpu4":{},"gpu5":{}} "scheduler"="default"
I0721 16:26:59.737565   31979 placement_manager.go:305]  "msg"="Found best-fit"  "crossNode"=0 "nodes"=[{},{},{}] "requests"=[{},{},{},{},{},{},{},{},{},{}] "scheduler"="default"
I0721 16:26:59.738060   31979 placement_manager.go:339]  "msg"="nodeStates updated"  "new"={"gpu3":{},"gpu4":{},"gpu5":{}} "old"={"gpu3":{},"gpu4":{},"gpu5":{}} "scheduler"="default" "score"=3
I0721 16:26:59.738478   31979 placement_manager.go:387]  "msg"="jobStates updated"  "new"={"tf2-keras-cifar10-inceptionv3-elastic-20210721-042459":{},"tf2-keras-cifar10-inceptionv3-elastic-20210721-042550":{},"tf2-keras-cifar10-resnet50-elastic-20210721-042522":{},"tf2-keras-cifar10-vgg16-elastic-20210721-042620":{},"tf2-keras-cifar10-vgg16-elastic-20210721-042642":{}} "old"={"tf2-keras-cifar10-inceptionv3-elastic-20210721-042459":{}} "scheduler"="default"
I0721 16:26:59.739100   31979 placement_manager.go:434]  "msg"="podNodeName updated"  "launchersToDelete"=0 "new"={"tf2-keras-cifar10-inceptionv3-elastic-20210721-042459-worker-0":"gpu3","tf2-keras-cifar10-inceptionv3-elastic-20210721-042459-worker-1":"gpu3","tf2-keras-cifar10-inceptionv3-elastic-20210721-042459-worker-2":"gpu3","tf2-keras-cifar10-inceptionv3-elastic-20210721-042550-worker-0":"gpu5","tf2-keras-cifar10-inceptionv3-elastic-20210721-042550-worker-1":"gpu5","tf2-keras-cifar10-resnet50-elastic-20210721-042522-worker-0":"gpu4","tf2-keras-cifar10-resnet50-elastic-20210721-042522-worker-1":"gpu4","tf2-keras-cifar10-resnet50-elastic-20210721-042522-worker-2":"gpu4","tf2-keras-cifar10-vgg16-elastic-20210721-042620-worker-0":"gpu5","tf2-keras-cifar10-vgg16-elastic-20210721-042620-worker-1":"gpu5","tf2-keras-cifar10-vgg16-elastic-20210721-042642-worker-0":"gpu3","tf2-keras-cifar10-vgg16-elastic-20210721-042642-worker-1":"gpu4","tf2-keras-cifar10-vgg16-elastic-20210721-042642-worker-2":"gpu4"} "old"={"tf2-keras-cifar10-inceptionv3-elastic-20210721-042459-worker-0":"gpu3","tf2-keras-cifar10-inceptionv3-elastic-20210721-042459-worker-1":"gpu3","tf2-keras-cifar10-inceptionv3-elastic-20210721-042459-worker-2":"gpu3","tf2-keras-cifar10-inceptionv3-elastic-20210721-042459-worker-3":"gpu3"} "scheduler"="default" "workersToDelete"=0
I0721 16:26:59.739665   31979 placement_manager.go:183]  "msg"="Finished job placements adjustment"  "scheduler"="default"
I0721 16:26:59.740050   31979 scheduler.go:182]  "msg"="Finished resched"  "scheduler"="default"
I0721 16:27:00.499388   31979 placement_manager.go:147]  "msg"="Adding toleration to pod"  "podName"="tf2-keras-cifar10-resnet50-elastic-20210721-042522-worker-0" "scheduler"="default" "toleration"={"key":"celeste/hostname","operator":"Equal","value":"gpu4","effect":"NoExecute"}
I0721 16:27:00.895447   31979 placement_manager.go:147]  "msg"="Adding toleration to pod"  "podName"="tf2-keras-cifar10-resnet50-elastic-20210721-042522-worker-1" "scheduler"="default" "toleration"={"key":"celeste/hostname","operator":"Equal","value":"gpu4","effect":"NoExecute"}
I0721 16:27:01.296532   31979 placement_manager.go:147]  "msg"="Adding toleration to pod"  "podName"="tf2-keras-cifar10-resnet50-elastic-20210721-042522-worker-2" "scheduler"="default" "toleration"={"key":"celeste/hostname","operator":"Equal","value":"gpu4","effect":"NoExecute"}
I0721 16:27:01.698297   31979 placement_manager.go:147]  "msg"="Adding toleration to pod"  "podName"="tf2-keras-cifar10-resnet50-elastic-20210721-042522-launcher" "scheduler"="default" "toleration"={"key":"celeste/hostname","operator":"Exists","effect":"NoExecute"}
I0721 16:27:01.896880   31979 placement_manager.go:147]  "msg"="Adding toleration to pod"  "podName"="tf2-keras-cifar10-inceptionv3-elastic-20210721-042550-worker-0" "scheduler"="default" "toleration"={"key":"celeste/hostname","operator":"Equal","value":"gpu5","effect":"NoExecute"}
I0721 16:27:02.506236   31979 placement_manager.go:147]  "msg"="Adding toleration to pod"  "podName"="tf2-keras-cifar10-inceptionv3-elastic-20210721-042550-worker-1" "scheduler"="default" "toleration"={"key":"celeste/hostname","operator":"Equal","value":"gpu5","effect":"NoExecute"}
I0721 16:27:02.906007   31979 placement_manager.go:147]  "msg"="Adding toleration to pod"  "podName"="tf2-keras-cifar10-inceptionv3-elastic-20210721-042550-launcher" "scheduler"="default" "toleration"={"key":"celeste/hostname","operator":"Exists","effect":"NoExecute"}
I0721 16:27:03.695270   31979 placement_manager.go:147]  "msg"="Adding toleration to pod"  "podName"="tf2-keras-cifar10-vgg16-elastic-20210721-042620-worker-0" "scheduler"="default" "toleration"={"key":"celeste/hostname","operator":"Equal","value":"gpu5","effect":"NoExecute"}
I0721 16:27:04.108227   31979 placement_manager.go:147]  "msg"="Adding toleration to pod"  "podName"="tf2-keras-cifar10-vgg16-elastic-20210721-042620-worker-1" "scheduler"="default" "toleration"={"key":"celeste/hostname","operator":"Equal","value":"gpu5","effect":"NoExecute"}
I0721 16:27:04.510016   31979 placement_manager.go:147]  "msg"="Adding toleration to pod"  "podName"="tf2-keras-cifar10-vgg16-elastic-20210721-042620-launcher" "scheduler"="default" "toleration"={"key":"celeste/hostname","operator":"Exists","effect":"NoExecute"}
I0721 16:27:04.909048   31979 placement_manager.go:147]  "msg"="Adding toleration to pod"  "podName"="tf2-keras-cifar10-vgg16-elastic-20210721-042642-worker-0" "scheduler"="default" "toleration"={"key":"celeste/hostname","operator":"Equal","value":"gpu3","effect":"NoExecute"}
I0721 16:27:05.307959   31979 placement_manager.go:147]  "msg"="Adding toleration to pod"  "podName"="tf2-keras-cifar10-vgg16-elastic-20210721-042642-worker-1" "scheduler"="default" "toleration"={"key":"celeste/hostname","operator":"Equal","value":"gpu4","effect":"NoExecute"}
I0721 16:27:05.356750   31979 jobmaster.go:155]  "msg"="Training job created"  "job"="tf2-keras-transformer-elastic-20210721-042705"
I0721 16:27:05.356888   31979 scheduler.go:135]  "msg"="Received resched event, may be blocked because of rate limit"  "blockedUntil"="2021-07-21T16:28:59.740372658+08:00" "lastResched"="2021-07-21T16:26:59.740372658+08:00" "received"="2021-07-21T16:27:05.356096522+08:00" "scheduler"="default"
I0721 16:27:05.707393   31979 placement_manager.go:147]  "msg"="Adding toleration to pod"  "podName"="tf2-keras-cifar10-vgg16-elastic-20210721-042642-launcher" "scheduler"="default" "toleration"={"key":"celeste/hostname","operator":"Exists","effect":"NoExecute"}
I0721 16:27:32.234091   31979 jobmaster.go:155]  "msg"="Training job created"  "job"="tf2-keras-transformer-elastic-20210721-042732"
I0721 16:28:07.138697   31979 jobmaster.go:155]  "msg"="Training job created"  "job"="tf2-keras-cifar10-inceptionv3-elastic-20210721-042807"
I0721 16:28:44.013653   31979 jobmaster.go:155]  "msg"="Training job created"  "job"="tf2-keras-cifar10-resnet50-elastic-20210721-042844"
I0721 16:28:59.740485   31979 scheduler.go:159]  "msg"="Started resched"  "scheduler"="default"
I0721 16:28:59.740564   31979 scheduler.go:193]  "msg"="Updating all jobs info"  "scheduler"="default"
I0721 16:28:59.747087   31979 elastic_fifo.go:73]  "msg"="Finished scheduling"  "algorithm"="ElasticFIFO" "freeGpu"=0 "result"={"tf2-keras-cifar10-inceptionv3-elastic-20210721-042459":2,"tf2-keras-cifar10-inceptionv3-elastic-20210721-042550":2,"tf2-keras-cifar10-inceptionv3-elastic-20210721-042807":1,"tf2-keras-cifar10-resnet50-elastic-20210721-042522":2,"tf2-keras-cifar10-resnet50-elastic-20210721-042844":1,"tf2-keras-cifar10-vgg16-elastic-20210721-042620":1,"tf2-keras-cifar10-vgg16-elastic-20210721-042642":1,"tf2-keras-transformer-elastic-20210721-042705":1,"tf2-keras-transformer-elastic-20210721-042732":1} "scheduler"="default"
I0721 16:28:59.747576   31979 scheduler.go:384]  "msg"="Trying to delete multiple training jobs"  "jobs"=[] "scheduler"="default"
I0721 16:28:59.747893   31979 scheduler.go:342]  "msg"="Trying to scale multiple training jobs"  "jobs"=["tf2-keras-cifar10-resnet50-elastic-20210721-042522","tf2-keras-cifar10-vgg16-elastic-20210721-042620","tf2-keras-cifar10-vgg16-elastic-20210721-042642","tf2-keras-cifar10-inceptionv3-elastic-20210721-042459"] "scheduler"="default"
I0721 16:28:59.823543   31979 scheduler.go:292]  "msg"="Trying to start multiple training jobs"  "jobs"=["tf2-keras-transformer-elastic-20210721-042705","tf2-keras-transformer-elastic-20210721-042732","tf2-keras-cifar10-resnet50-elastic-20210721-042844","tf2-keras-cifar10-inceptionv3-elastic-20210721-042807"] "scheduler"="default"
I0721 16:29:00.157800   31979 scheduler.go:342]  "msg"="Trying to scale multiple training jobs"  "jobs"=[] "scheduler"="default"
I0721 16:29:00.162732   31979 placement_manager.go:166]  "msg"="Started job placements adjustment"  "scheduler"="default"
I0721 16:29:00.162830   31979 placement_manager.go:192]  "msg"="Releasing slots"  "jobs"={"tf2-keras-cifar10-inceptionv3-elastic-20210721-042459":{},"tf2-keras-cifar10-inceptionv3-elastic-20210721-042550":{},"tf2-keras-cifar10-resnet50-elastic-20210721-042522":{},"tf2-keras-cifar10-vgg16-elastic-20210721-042620":{},"tf2-keras-cifar10-vgg16-elastic-20210721-042642":{}} "nodes"={"gpu3":{},"gpu4":{},"gpu5":{}} "scheduler"="default"
I0721 16:29:00.162886   31979 placement_manager.go:250]  "msg"="Released slots"  "jobs"={"tf2-keras-cifar10-inceptionv3-elastic-20210721-042459":{},"tf2-keras-cifar10-inceptionv3-elastic-20210721-042550":{},"tf2-keras-cifar10-resnet50-elastic-20210721-042522":{},"tf2-keras-cifar10-vgg16-elastic-20210721-042620":{},"tf2-keras-cifar10-vgg16-elastic-20210721-042642":{}} "nodes"={"gpu3":{},"gpu4":{},"gpu5":{}} "scheduler"="default"
I0721 16:29:00.163310   31979 placement_manager.go:305]  "msg"="Found best-fit"  "crossNode"=0 "nodes"=[{},{},{}] "requests"=[{},{},{},{},{},{},{},{},{},{},{},{},{},{},{},{},{},{}] "scheduler"="default"
I0721 16:29:00.163540   31979 placement_manager.go:339]  "msg"="nodeStates updated"  "new"={"gpu3":{},"gpu4":{},"gpu5":{}} "old"={"gpu3":{},"gpu4":{},"gpu5":{}} "scheduler"="default" "score"=5
I0721 16:29:00.163906   31979 placement_manager.go:387]  "msg"="jobStates updated"  "new"={"tf2-keras-cifar10-inceptionv3-elastic-20210721-042459":{},"tf2-keras-cifar10-inceptionv3-elastic-20210721-042550":{},"tf2-keras-cifar10-inceptionv3-elastic-20210721-042807":{},"tf2-keras-cifar10-resnet50-elastic-20210721-042522":{},"tf2-keras-cifar10-resnet50-elastic-20210721-042844":{},"tf2-keras-cifar10-vgg16-elastic-20210721-042620":{},"tf2-keras-cifar10-vgg16-elastic-20210721-042642":{},"tf2-keras-transformer-elastic-20210721-042705":{},"tf2-keras-transformer-elastic-20210721-042732":{}} "old"={"tf2-keras-cifar10-inceptionv3-elastic-20210721-042459":{},"tf2-keras-cifar10-inceptionv3-elastic-20210721-042550":{},"tf2-keras-cifar10-resnet50-elastic-20210721-042522":{},"tf2-keras-cifar10-vgg16-elastic-20210721-042620":{},"tf2-keras-cifar10-vgg16-elastic-20210721-042642":{}} "scheduler"="default"
I0721 16:29:00.164479   31979 placement_manager.go:434]  "msg"="podNodeName updated"  "launchersToDelete"=2 "new"={"tf2-keras-cifar10-inceptionv3-elastic-20210721-042459-worker-0":"gpu3","tf2-keras-cifar10-inceptionv3-elastic-20210721-042459-worker-1":"gpu3","tf2-keras-cifar10-inceptionv3-elastic-20210721-042550-worker-0":"gpu4","tf2-keras-cifar10-inceptionv3-elastic-20210721-042550-worker-1":"gpu4","tf2-keras-cifar10-inceptionv3-elastic-20210721-042807-worker-0":"gpu3","tf2-keras-cifar10-resnet50-elastic-20210721-042522-worker-0":"gpu4","tf2-keras-cifar10-resnet50-elastic-20210721-042522-worker-1":"gpu4","tf2-keras-cifar10-resnet50-elastic-20210721-042844-worker-0":"gpu5","tf2-keras-cifar10-vgg16-elastic-20210721-042620-worker-0":"gpu5","tf2-keras-cifar10-vgg16-elastic-20210721-042642-worker-0":"gpu5","tf2-keras-transformer-elastic-20210721-042705-worker-0":"gpu3","tf2-keras-transformer-elastic-20210721-042732-worker-0":"gpu5"} "old"={"tf2-keras-cifar10-inceptionv3-elastic-20210721-042459-worker-0":"gpu3","tf2-keras-cifar10-inceptionv3-elastic-20210721-042459-worker-1":"gpu3","tf2-keras-cifar10-inceptionv3-elastic-20210721-042459-worker-2":"gpu3","tf2-keras-cifar10-inceptionv3-elastic-20210721-042550-worker-0":"gpu5","tf2-keras-cifar10-inceptionv3-elastic-20210721-042550-worker-1":"gpu5","tf2-keras-cifar10-resnet50-elastic-20210721-042522-worker-0":"gpu4","tf2-keras-cifar10-resnet50-elastic-20210721-042522-worker-1":"gpu4","tf2-keras-cifar10-resnet50-elastic-20210721-042522-worker-2":"gpu4","tf2-keras-cifar10-vgg16-elastic-20210721-042620-worker-0":"gpu5","tf2-keras-cifar10-vgg16-elastic-20210721-042620-worker-1":"gpu5","tf2-keras-cifar10-vgg16-elastic-20210721-042642-worker-0":"gpu3","tf2-keras-cifar10-vgg16-elastic-20210721-042642-worker-1":"gpu4","tf2-keras-cifar10-vgg16-elastic-20210721-042642-worker-2":"gpu4"} "scheduler"="default" "workersToDelete"=3
I0721 16:29:00.164884   31979 placement_manager.go:451]  "msg"="Deleting pod that need migration"  "podName"="tf2-keras-cifar10-vgg16-elastic-20210721-042642-worker-0" "scheduler"="default"
I0721 16:29:00.170070   31979 placement_manager.go:451]  "msg"="Deleting pod that need migration"  "podName"="tf2-keras-cifar10-vgg16-elastic-20210721-042642-launcher" "scheduler"="default"
I0721 16:29:00.175071   31979 placement_manager.go:451]  "msg"="Deleting pod that need migration"  "podName"="tf2-keras-cifar10-inceptionv3-elastic-20210721-042550-worker-0" "scheduler"="default"
I0721 16:29:00.184778   31979 placement_manager.go:451]  "msg"="Deleting pod that need migration"  "podName"="tf2-keras-cifar10-inceptionv3-elastic-20210721-042550-worker-1" "scheduler"="default"
I0721 16:29:00.189125   31979 placement_manager.go:451]  "msg"="Deleting pod that need migration"  "podName"="tf2-keras-cifar10-inceptionv3-elastic-20210721-042550-launcher" "scheduler"="default"
I0721 16:29:00.195306   31979 placement_manager.go:183]  "msg"="Finished job placements adjustment"  "scheduler"="default"
I0721 16:29:00.195617   31979 scheduler.go:182]  "msg"="Finished resched"  "scheduler"="default"
I0721 16:29:03.382271   31979 placement_manager.go:147]  "msg"="Adding toleration to pod"  "podName"="tf2-keras-transformer-elastic-20210721-042705-worker-0" "scheduler"="default" "toleration"={"key":"celeste/hostname","operator":"Equal","value":"gpu3","effect":"NoExecute"}
I0721 16:29:03.978541   31979 placement_manager.go:147]  "msg"="Adding toleration to pod"  "podName"="tf2-keras-transformer-elastic-20210721-042705-launcher" "scheduler"="default" "toleration"={"key":"celeste/hostname","operator":"Exists","effect":"NoExecute"}
I0721 16:29:05.177846   31979 placement_manager.go:147]  "msg"="Adding toleration to pod"  "podName"="tf2-keras-transformer-elastic-20210721-042732-worker-0" "scheduler"="default" "toleration"={"key":"celeste/hostname","operator":"Equal","value":"gpu5","effect":"NoExecute"}
I0721 16:29:05.579775   31979 placement_manager.go:147]  "msg"="Adding toleration to pod"  "podName"="tf2-keras-transformer-elastic-20210721-042732-launcher" "scheduler"="default" "toleration"={"key":"celeste/hostname","operator":"Exists","effect":"NoExecute"}
I0721 16:29:06.177693   31979 placement_manager.go:147]  "msg"="Adding toleration to pod"  "podName"="tf2-keras-cifar10-resnet50-elastic-20210721-042844-worker-0" "scheduler"="default" "toleration"={"key":"celeste/hostname","operator":"Equal","value":"gpu5","effect":"NoExecute"}
I0721 16:29:06.578354   31979 placement_manager.go:147]  "msg"="Adding toleration to pod"  "podName"="tf2-keras-cifar10-resnet50-elastic-20210721-042844-launcher" "scheduler"="default" "toleration"={"key":"celeste/hostname","operator":"Exists","effect":"NoExecute"}
I0721 16:29:07.579805   31979 placement_manager.go:147]  "msg"="Adding toleration to pod"  "podName"="tf2-keras-cifar10-inceptionv3-elastic-20210721-042807-worker-0" "scheduler"="default" "toleration"={"key":"celeste/hostname","operator":"Equal","value":"gpu3","effect":"NoExecute"}
I0721 16:29:07.779470   31979 placement_manager.go:147]  "msg"="Adding toleration to pod"  "podName"="tf2-keras-cifar10-vgg16-elastic-20210721-042642-worker-0" "scheduler"="default" "toleration"={"key":"celeste/hostname","operator":"Equal","value":"gpu5","effect":"NoExecute"}
I0721 16:29:07.986440   31979 placement_manager.go:147]  "msg"="Adding toleration to pod"  "podName"="tf2-keras-cifar10-inceptionv3-elastic-20210721-042807-launcher" "scheduler"="default" "toleration"={"key":"celeste/hostname","operator":"Exists","effect":"NoExecute"}
I0721 16:29:09.780773   31979 placement_manager.go:147]  "msg"="Adding toleration to pod"  "podName"="tf2-keras-cifar10-vgg16-elastic-20210721-042642-launcher" "scheduler"="default" "toleration"={"key":"celeste/hostname","operator":"Exists","effect":"NoExecute"}
I0721 16:29:10.964867   31979 jobmaster.go:155]  "msg"="Training job created"  "job"="tf2-keras-cifar10-inceptionv3-elastic-20210721-042910"
I0721 16:29:10.965019   31979 scheduler.go:135]  "msg"="Received resched event, may be blocked because of rate limit"  "blockedUntil"="2021-07-21T16:31:00.195883829+08:00" "lastResched"="2021-07-21T16:29:00.195883829+08:00" "received"="2021-07-21T16:29:10.964311292+08:00" "scheduler"="default"
I0721 16:29:14.649206   31979 placement_manager.go:147]  "msg"="Adding toleration to pod"  "podName"="tf2-keras-cifar10-inceptionv3-elastic-20210721-042550-launcher" "scheduler"="default" "toleration"={"key":"celeste/hostname","operator":"Exists","effect":"NoExecute"}
I0721 16:29:22.276767   31979 placement_manager.go:147]  "msg"="Adding toleration to pod"  "podName"="tf2-keras-cifar10-inceptionv3-elastic-20210721-042550-worker-0" "scheduler"="default" "toleration"={"key":"celeste/hostname","operator":"Equal","value":"gpu4","effect":"NoExecute"}
I0721 16:29:23.062064   31979 placement_manager.go:147]  "msg"="Adding toleration to pod"  "podName"="tf2-keras-cifar10-inceptionv3-elastic-20210721-042550-worker-1" "scheduler"="default" "toleration"={"key":"celeste/hostname","operator":"Equal","value":"gpu4","effect":"NoExecute"}
I0721 16:29:37.870762   31979 jobmaster.go:155]  "msg"="Training job created"  "job"="tf2-keras-transformer-elastic-20210721-042937"
I0721 16:30:02.791572   31979 jobmaster.go:155]  "msg"="Training job created"  "job"="tf2-keras-cifar10-vgg16-elastic-20210721-043002"
I0721 16:30:29.727205   31979 jobmaster.go:155]  "msg"="Training job created"  "job"="tf2-keras-cifar10-vgg16-elastic-20210721-043029"
I0721 16:30:58.696142   31979 jobmaster.go:155]  "msg"="Training job created"  "job"="tf2-keras-cifar10-resnet50-elastic-20210721-043058"
I0721 16:31:00.195976   31979 scheduler.go:159]  "msg"="Started resched"  "scheduler"="default"
I0721 16:31:00.196065   31979 scheduler.go:193]  "msg"="Updating all jobs info"  "scheduler"="default"
I0721 16:31:00.207081   31979 elastic_fifo.go:73]  "msg"="Finished scheduling"  "algorithm"="ElasticFIFO" "freeGpu"=0 "result"={"tf2-keras-cifar10-inceptionv3-elastic-20210721-042459":1,"tf2-keras-cifar10-inceptionv3-elastic-20210721-042550":1,"tf2-keras-cifar10-inceptionv3-elastic-20210721-042807":1,"tf2-keras-cifar10-inceptionv3-elastic-20210721-042910":1,"tf2-keras-cifar10-resnet50-elastic-20210721-042522":1,"tf2-keras-cifar10-resnet50-elastic-20210721-042844":1,"tf2-keras-cifar10-resnet50-elastic-20210721-043058":0,"tf2-keras-cifar10-vgg16-elastic-20210721-042620":1,"tf2-keras-cifar10-vgg16-elastic-20210721-042642":1,"tf2-keras-cifar10-vgg16-elastic-20210721-043002":1,"tf2-keras-cifar10-vgg16-elastic-20210721-043029":0,"tf2-keras-transformer-elastic-20210721-042705":1,"tf2-keras-transformer-elastic-20210721-042732":1,"tf2-keras-transformer-elastic-20210721-042937":1} "scheduler"="default"
I0721 16:31:00.207402   31979 scheduler.go:384]  "msg"="Trying to delete multiple training jobs"  "jobs"=[] "scheduler"="default"
I0721 16:31:00.207775   31979 scheduler.go:342]  "msg"="Trying to scale multiple training jobs"  "jobs"=["tf2-keras-cifar10-inceptionv3-elastic-20210721-042550","tf2-keras-cifar10-inceptionv3-elastic-20210721-042459","tf2-keras-cifar10-resnet50-elastic-20210721-042522"] "scheduler"="default"
I0721 16:31:00.256799   31979 scheduler.go:292]  "msg"="Trying to start multiple training jobs"  "jobs"=["tf2-keras-cifar10-vgg16-elastic-20210721-043002","tf2-keras-cifar10-inceptionv3-elastic-20210721-042910","tf2-keras-transformer-elastic-20210721-042937"] "scheduler"="default"
I0721 16:31:00.280454   31979 scheduler.go:342]  "msg"="Trying to scale multiple training jobs"  "jobs"=[] "scheduler"="default"
I0721 16:31:00.287632   31979 placement_manager.go:166]  "msg"="Started job placements adjustment"  "scheduler"="default"
I0721 16:31:00.287749   31979 placement_manager.go:192]  "msg"="Releasing slots"  "jobs"={"tf2-keras-cifar10-inceptionv3-elastic-20210721-042459":{},"tf2-keras-cifar10-inceptionv3-elastic-20210721-042550":{},"tf2-keras-cifar10-inceptionv3-elastic-20210721-042807":{},"tf2-keras-cifar10-resnet50-elastic-20210721-042522":{},"tf2-keras-cifar10-resnet50-elastic-20210721-042844":{},"tf2-keras-cifar10-vgg16-elastic-20210721-042620":{},"tf2-keras-cifar10-vgg16-elastic-20210721-042642":{},"tf2-keras-transformer-elastic-20210721-042705":{},"tf2-keras-transformer-elastic-20210721-042732":{}} "nodes"={"gpu3":{},"gpu4":{},"gpu5":{}} "scheduler"="default"
I0721 16:31:00.287824   31979 placement_manager.go:250]  "msg"="Released slots"  "jobs"={"tf2-keras-cifar10-inceptionv3-elastic-20210721-042459":{},"tf2-keras-cifar10-inceptionv3-elastic-20210721-042550":{},"tf2-keras-cifar10-inceptionv3-elastic-20210721-042807":{},"tf2-keras-cifar10-resnet50-elastic-20210721-042522":{},"tf2-keras-cifar10-resnet50-elastic-20210721-042844":{},"tf2-keras-cifar10-vgg16-elastic-20210721-042620":{},"tf2-keras-cifar10-vgg16-elastic-20210721-042642":{},"tf2-keras-transformer-elastic-20210721-042705":{},"tf2-keras-transformer-elastic-20210721-042732":{}} "nodes"={"gpu3":{},"gpu4":{},"gpu5":{}} "scheduler"="default"
I0721 16:31:00.288274   31979 placement_manager.go:305]  "msg"="Found best-fit"  "crossNode"=0 "nodes"=[{},{},{}] "requests"=[{},{},{},{},{},{},{},{},{},{},{},{},{},{},{},{},{},{},{},{},{},{},{},{},{},{},{},{}] "scheduler"="default"
I0721 16:31:00.288709   31979 placement_manager.go:339]  "msg"="nodeStates updated"  "new"={"gpu3":{},"gpu4":{},"gpu5":{}} "old"={"gpu3":{},"gpu4":{},"gpu5":{}} "scheduler"="default" "score"=5
I0721 16:31:00.289121   31979 placement_manager.go:387]  "msg"="jobStates updated"  "new"={"tf2-keras-cifar10-inceptionv3-elastic-20210721-042459":{},"tf2-keras-cifar10-inceptionv3-elastic-20210721-042550":{},"tf2-keras-cifar10-inceptionv3-elastic-20210721-042807":{},"tf2-keras-cifar10-inceptionv3-elastic-20210721-042910":{},"tf2-keras-cifar10-resnet50-elastic-20210721-042522":{},"tf2-keras-cifar10-resnet50-elastic-20210721-042844":{},"tf2-keras-cifar10-vgg16-elastic-20210721-042620":{},"tf2-keras-cifar10-vgg16-elastic-20210721-042642":{},"tf2-keras-cifar10-vgg16-elastic-20210721-043002":{},"tf2-keras-transformer-elastic-20210721-042705":{},"tf2-keras-transformer-elastic-20210721-042732":{},"tf2-keras-transformer-elastic-20210721-042937":{}} "old"={"tf2-keras-cifar10-inceptionv3-elastic-20210721-042459":{},"tf2-keras-cifar10-inceptionv3-elastic-20210721-042550":{},"tf2-keras-cifar10-inceptionv3-elastic-20210721-042807":{},"tf2-keras-cifar10-resnet50-elastic-20210721-042522":{},"tf2-keras-cifar10-resnet50-elastic-20210721-042844":{},"tf2-keras-cifar10-vgg16-elastic-20210721-042620":{},"tf2-keras-cifar10-vgg16-elastic-20210721-042642":{},"tf2-keras-transformer-elastic-20210721-042705":{},"tf2-keras-transformer-elastic-20210721-042732":{}} "scheduler"="default"
I0721 16:31:00.289533   31979 placement_manager.go:434]  "msg"="podNodeName updated"  "launchersToDelete"=4 "new"={"tf2-keras-cifar10-inceptionv3-elastic-20210721-042459-worker-0":"gpu3","tf2-keras-cifar10-inceptionv3-elastic-20210721-042550-worker-0":"gpu4","tf2-keras-cifar10-inceptionv3-elastic-20210721-042807-worker-0":"gpu5","tf2-keras-cifar10-inceptionv3-elastic-20210721-042910-worker-0":"gpu5","tf2-keras-cifar10-resnet50-elastic-20210721-042522-worker-0":"gpu4","tf2-keras-cifar10-resnet50-elastic-20210721-042844-worker-0":"gpu4","tf2-keras-cifar10-vgg16-elastic-20210721-042620-worker-0":"gpu3","tf2-keras-cifar10-vgg16-elastic-20210721-042642-worker-0":"gpu5","tf2-keras-cifar10-vgg16-elastic-20210721-043002-worker-0":"gpu5","tf2-keras-transformer-elastic-20210721-042705-worker-0":"gpu3","tf2-keras-transformer-elastic-20210721-042732-worker-0":"gpu4","tf2-keras-transformer-elastic-20210721-042937-worker-0":"gpu3"} "old"={"tf2-keras-cifar10-inceptionv3-elastic-20210721-042459-worker-0":"gpu3","tf2-keras-cifar10-inceptionv3-elastic-20210721-042459-worker-1":"gpu3","tf2-keras-cifar10-inceptionv3-elastic-20210721-042550-worker-0":"gpu4","tf2-keras-cifar10-inceptionv3-elastic-20210721-042550-worker-1":"gpu4","tf2-keras-cifar10-inceptionv3-elastic-20210721-042807-worker-0":"gpu3","tf2-keras-cifar10-resnet50-elastic-20210721-042522-worker-0":"gpu4","tf2-keras-cifar10-resnet50-elastic-20210721-042522-worker-1":"gpu4","tf2-keras-cifar10-resnet50-elastic-20210721-042844-worker-0":"gpu5","tf2-keras-cifar10-vgg16-elastic-20210721-042620-worker-0":"gpu5","tf2-keras-cifar10-vgg16-elastic-20210721-042642-worker-0":"gpu5","tf2-keras-transformer-elastic-20210721-042705-worker-0":"gpu3","tf2-keras-transformer-elastic-20210721-042732-worker-0":"gpu5"} "scheduler"="default" "workersToDelete"=4
I0721 16:31:00.289874   31979 placement_manager.go:451]  "msg"="Deleting pod that need migration"  "podName"="tf2-keras-cifar10-vgg16-elastic-20210721-042620-worker-0" "scheduler"="default"
I0721 16:31:00.294131   31979 placement_manager.go:451]  "msg"="Deleting pod that need migration"  "podName"="tf2-keras-cifar10-vgg16-elastic-20210721-042620-launcher" "scheduler"="default"
I0721 16:31:00.298422   31979 placement_manager.go:451]  "msg"="Deleting pod that need migration"  "podName"="tf2-keras-cifar10-inceptionv3-elastic-20210721-042807-worker-0" "scheduler"="default"
I0721 16:31:00.302663   31979 placement_manager.go:451]  "msg"="Deleting pod that need migration"  "podName"="tf2-keras-cifar10-inceptionv3-elastic-20210721-042807-launcher" "scheduler"="default"
I0721 16:31:00.306742   31979 placement_manager.go:451]  "msg"="Deleting pod that need migration"  "podName"="tf2-keras-transformer-elastic-20210721-042732-worker-0" "scheduler"="default"
I0721 16:31:00.310925   31979 placement_manager.go:451]  "msg"="Deleting pod that need migration"  "podName"="tf2-keras-transformer-elastic-20210721-042732-launcher" "scheduler"="default"
I0721 16:31:00.314864   31979 placement_manager.go:451]  "msg"="Deleting pod that need migration"  "podName"="tf2-keras-cifar10-resnet50-elastic-20210721-042844-worker-0" "scheduler"="default"
I0721 16:31:00.323259   31979 placement_manager.go:451]  "msg"="Deleting pod that need migration"  "podName"="tf2-keras-cifar10-resnet50-elastic-20210721-042844-launcher" "scheduler"="default"
I0721 16:31:00.328224   31979 placement_manager.go:183]  "msg"="Finished job placements adjustment"  "scheduler"="default"
I0721 16:31:00.328532   31979 scheduler.go:182]  "msg"="Finished resched"  "scheduler"="default"
I0721 16:31:02.841440   31979 placement_manager.go:147]  "msg"="Adding toleration to pod"  "podName"="tf2-keras-cifar10-vgg16-elastic-20210721-043002-worker-0" "scheduler"="default" "toleration"={"key":"celeste/hostname","operator":"Equal","value":"gpu5","effect":"NoExecute"}
I0721 16:31:03.238607   31979 placement_manager.go:147]  "msg"="Adding toleration to pod"  "podName"="tf2-keras-cifar10-vgg16-elastic-20210721-043002-launcher" "scheduler"="default" "toleration"={"key":"celeste/hostname","operator":"Exists","effect":"NoExecute"}
I0721 16:31:04.440686   31979 placement_manager.go:147]  "msg"="Adding toleration to pod"  "podName"="tf2-keras-cifar10-inceptionv3-elastic-20210721-042910-worker-0" "scheduler"="default" "toleration"={"key":"celeste/hostname","operator":"Equal","value":"gpu5","effect":"NoExecute"}
I0721 16:31:04.840121   31979 placement_manager.go:147]  "msg"="Adding toleration to pod"  "podName"="tf2-keras-cifar10-inceptionv3-elastic-20210721-042910-launcher" "scheduler"="default" "toleration"={"key":"celeste/hostname","operator":"Exists","effect":"NoExecute"}
I0721 16:31:06.039296   31979 placement_manager.go:147]  "msg"="Adding toleration to pod"  "podName"="tf2-keras-transformer-elastic-20210721-042937-worker-0" "scheduler"="default" "toleration"={"key":"celeste/hostname","operator":"Equal","value":"gpu3","effect":"NoExecute"}
I0721 16:31:06.438811   31979 placement_manager.go:147]  "msg"="Adding toleration to pod"  "podName"="tf2-keras-transformer-elastic-20210721-042937-launcher" "scheduler"="default" "toleration"={"key":"celeste/hostname","operator":"Exists","effect":"NoExecute"}
I0721 16:31:10.040242   31979 placement_manager.go:147]  "msg"="Adding toleration to pod"  "podName"="tf2-keras-cifar10-resnet50-elastic-20210721-042844-worker-0" "scheduler"="default" "toleration"={"key":"celeste/hostname","operator":"Equal","value":"gpu4","effect":"NoExecute"}
I0721 16:31:10.241201   31979 placement_manager.go:147]  "msg"="Adding toleration to pod"  "podName"="tf2-keras-transformer-elastic-20210721-042732-launcher" "scheduler"="default" "toleration"={"key":"celeste/hostname","operator":"Exists","effect":"NoExecute"}
I0721 16:31:10.839921   31979 placement_manager.go:147]  "msg"="Adding toleration to pod"  "podName"="tf2-keras-cifar10-vgg16-elastic-20210721-042620-worker-0" "scheduler"="default" "toleration"={"key":"celeste/hostname","operator":"Equal","value":"gpu3","effect":"NoExecute"}
I0721 16:31:11.239078   31979 placement_manager.go:147]  "msg"="Adding toleration to pod"  "podName"="tf2-keras-transformer-elastic-20210721-042732-worker-0" "scheduler"="default" "toleration"={"key":"celeste/hostname","operator":"Equal","value":"gpu4","effect":"NoExecute"}
I0721 16:31:12.919907   31979 placement_manager.go:147]  "msg"="Adding toleration to pod"  "podName"="tf2-keras-cifar10-vgg16-elastic-20210721-042620-launcher" "scheduler"="default" "toleration"={"key":"celeste/hostname","operator":"Exists","effect":"NoExecute"}
I0721 16:31:16.124733   31979 placement_manager.go:147]  "msg"="Adding toleration to pod"  "podName"="tf2-keras-cifar10-resnet50-elastic-20210721-042844-launcher" "scheduler"="default" "toleration"={"key":"celeste/hostname","operator":"Exists","effect":"NoExecute"}
I0721 16:31:20.502223   31979 placement_manager.go:147]  "msg"="Adding toleration to pod"  "podName"="tf2-keras-cifar10-inceptionv3-elastic-20210721-042807-worker-0" "scheduler"="default" "toleration"={"key":"celeste/hostname","operator":"Equal","value":"gpu5","effect":"NoExecute"}
I0721 16:31:20.903230   31979 placement_manager.go:147]  "msg"="Adding toleration to pod"  "podName"="tf2-keras-cifar10-inceptionv3-elastic-20210721-042807-launcher" "scheduler"="default" "toleration"={"key":"celeste/hostname","operator":"Exists","effect":"NoExecute"}
I0721 16:31:27.640075   31979 jobmaster.go:155]  "msg"="Training job created"  "job"="tf2-keras-cifar10-inceptionv3-elastic-20210721-043127"
I0721 16:31:27.640181   31979 scheduler.go:135]  "msg"="Received resched event, may be blocked because of rate limit"  "blockedUntil"="2021-07-21T16:33:00.328832542+08:00" "lastResched"="2021-07-21T16:31:00.328832542+08:00" "received"="2021-07-21T16:31:27.639614097+08:00" "scheduler"="default"
I0721 16:32:03.581525   31979 jobmaster.go:155]  "msg"="Training job created"  "job"="tf2-keras-transformer-elastic-20210721-043203"
I0721 16:32:26.471733   31979 jobmaster.go:155]  "msg"="Training job created"  "job"="tf2-keras-cifar10-inceptionv3-elastic-20210721-043226"
I0721 16:32:48.354865   31979 jobmaster.go:155]  "msg"="Training job created"  "job"="tf2-keras-cifar10-resnet50-elastic-20210721-043248"
I0721 16:33:00.328915   31979 scheduler.go:159]  "msg"="Started resched"  "scheduler"="default"
I0721 16:33:00.329009   31979 scheduler.go:193]  "msg"="Updating all jobs info"  "scheduler"="default"
I0721 16:33:00.340397   31979 elastic_fifo.go:73]  "msg"="Finished scheduling"  "algorithm"="ElasticFIFO" "freeGpu"=0 "result"={"tf2-keras-cifar10-inceptionv3-elastic-20210721-042459":1,"tf2-keras-cifar10-inceptionv3-elastic-20210721-042550":1,"tf2-keras-cifar10-inceptionv3-elastic-20210721-042807":1,"tf2-keras-cifar10-inceptionv3-elastic-20210721-042910":1,"tf2-keras-cifar10-inceptionv3-elastic-20210721-043127":0,"tf2-keras-cifar10-inceptionv3-elastic-20210721-043226":0,"tf2-keras-cifar10-resnet50-elastic-20210721-042522":1,"tf2-keras-cifar10-resnet50-elastic-20210721-042844":1,"tf2-keras-cifar10-resnet50-elastic-20210721-043058":0,"tf2-keras-cifar10-resnet50-elastic-20210721-043248":0,"tf2-keras-cifar10-vgg16-elastic-20210721-042620":1,"tf2-keras-cifar10-vgg16-elastic-20210721-042642":1,"tf2-keras-cifar10-vgg16-elastic-20210721-043002":1,"tf2-keras-cifar10-vgg16-elastic-20210721-043029":0,"tf2-keras-transformer-elastic-20210721-042705":1,"tf2-keras-transformer-elastic-20210721-042732":1,"tf2-keras-transformer-elastic-20210721-042937":1,"tf2-keras-transformer-elastic-20210721-043203":0} "scheduler"="default"
I0721 16:33:00.340680   31979 scheduler.go:384]  "msg"="Trying to delete multiple training jobs"  "jobs"=[] "scheduler"="default"
I0721 16:33:00.340891   31979 scheduler.go:342]  "msg"="Trying to scale multiple training jobs"  "jobs"=[] "scheduler"="default"
I0721 16:33:00.341086   31979 scheduler.go:292]  "msg"="Trying to start multiple training jobs"  "jobs"=[] "scheduler"="default"
I0721 16:33:00.341273   31979 scheduler.go:342]  "msg"="Trying to scale multiple training jobs"  "jobs"=[] "scheduler"="default"
I0721 16:33:00.341469   31979 scheduler.go:180]  "msg"="Nothing changed, skipped ajust placements"  "scheduler"="default"
I0721 16:33:00.341494   31979 scheduler.go:182]  "msg"="Finished resched"  "scheduler"="default"
I0721 16:33:21.249273   31979 jobmaster.go:155]  "msg"="Training job created"  "job"="tf2-keras-cifar10-vgg16-elastic-20210721-043321"
I0721 16:33:21.249388   31979 scheduler.go:135]  "msg"="Received resched event, may be blocked because of rate limit"  "blockedUntil"="2021-07-21T16:35:00.341638843+08:00" "lastResched"="2021-07-21T16:33:00.341638843+08:00" "received"="2021-07-21T16:33:21.248786165+08:00" "scheduler"="default"
I0721 16:33:43.099387   31979 jobmaster.go:155]  "msg"="Training job created"  "job"="tf2-keras-transformer-elastic-20210721-043343"
I0721 16:34:23.022183   31979 jobmaster.go:155]  "msg"="Training job created"  "job"="tf2-keras-cifar10-vgg16-elastic-20210721-043423"
I0721 16:35:00.341791   31979 scheduler.go:159]  "msg"="Started resched"  "scheduler"="default"
I0721 16:35:00.341868   31979 scheduler.go:193]  "msg"="Updating all jobs info"  "scheduler"="default"
I0721 16:35:00.356015   31979 elastic_fifo.go:73]  "msg"="Finished scheduling"  "algorithm"="ElasticFIFO" "freeGpu"=0 "result"={"tf2-keras-cifar10-inceptionv3-elastic-20210721-042459":1,"tf2-keras-cifar10-inceptionv3-elastic-20210721-042550":1,"tf2-keras-cifar10-inceptionv3-elastic-20210721-042807":1,"tf2-keras-cifar10-inceptionv3-elastic-20210721-042910":1,"tf2-keras-cifar10-inceptionv3-elastic-20210721-043127":0,"tf2-keras-cifar10-inceptionv3-elastic-20210721-043226":0,"tf2-keras-cifar10-resnet50-elastic-20210721-042522":1,"tf2-keras-cifar10-resnet50-elastic-20210721-042844":1,"tf2-keras-cifar10-resnet50-elastic-20210721-043058":0,"tf2-keras-cifar10-resnet50-elastic-20210721-043248":0,"tf2-keras-cifar10-vgg16-elastic-20210721-042620":1,"tf2-keras-cifar10-vgg16-elastic-20210721-042642":1,"tf2-keras-cifar10-vgg16-elastic-20210721-043002":1,"tf2-keras-cifar10-vgg16-elastic-20210721-043029":0,"tf2-keras-cifar10-vgg16-elastic-20210721-043321":0,"tf2-keras-cifar10-vgg16-elastic-20210721-043423":0,"tf2-keras-transformer-elastic-20210721-042705":1,"tf2-keras-transformer-elastic-20210721-042732":1,"tf2-keras-transformer-elastic-20210721-042937":1,"tf2-keras-transformer-elastic-20210721-043203":0,"tf2-keras-transformer-elastic-20210721-043343":0} "scheduler"="default"
I0721 16:35:00.356383   31979 scheduler.go:384]  "msg"="Trying to delete multiple training jobs"  "jobs"=[] "scheduler"="default"
I0721 16:35:00.356749   31979 scheduler.go:342]  "msg"="Trying to scale multiple training jobs"  "jobs"=[] "scheduler"="default"
I0721 16:35:00.357033   31979 scheduler.go:292]  "msg"="Trying to start multiple training jobs"  "jobs"=[] "scheduler"="default"
I0721 16:35:00.357262   31979 scheduler.go:342]  "msg"="Trying to scale multiple training jobs"  "jobs"=[] "scheduler"="default"
I0721 16:35:00.357496   31979 scheduler.go:180]  "msg"="Nothing changed, skipped ajust placements"  "scheduler"="default"
I0721 16:35:00.357522   31979 scheduler.go:182]  "msg"="Finished resched"  "scheduler"="default"
I0721 16:35:01.886215   31979 jobmaster.go:155]  "msg"="Training job created"  "job"="tf2-keras-cifar10-resnet50-elastic-20210721-043501"
I0721 16:35:01.886414   31979 scheduler.go:135]  "msg"="Received resched event, may be blocked because of rate limit"  "blockedUntil"="2021-07-21T16:37:00.357730053+08:00" "lastResched"="2021-07-21T16:35:00.357730053+08:00" "received"="2021-07-21T16:35:01.885615985+08:00" "scheduler"="default"
I0721 16:35:27.786368   31979 jobmaster.go:155]  "msg"="Training job created"  "job"="tf2-keras-cifar10-resnet50-elastic-20210721-043527"
I0721 16:35:55.705759   31979 jobmaster.go:155]  "msg"="Training job created"  "job"="tf2-keras-transformer-elastic-20210721-043555"
I0721 16:37:00.357813   31979 scheduler.go:159]  "msg"="Started resched"  "scheduler"="default"
I0721 16:37:00.357868   31979 scheduler.go:193]  "msg"="Updating all jobs info"  "scheduler"="default"
I0721 16:37:00.371864   31979 elastic_fifo.go:73]  "msg"="Finished scheduling"  "algorithm"="ElasticFIFO" "freeGpu"=0 "result"={"tf2-keras-cifar10-inceptionv3-elastic-20210721-042459":1,"tf2-keras-cifar10-inceptionv3-elastic-20210721-042550":1,"tf2-keras-cifar10-inceptionv3-elastic-20210721-042807":1,"tf2-keras-cifar10-inceptionv3-elastic-20210721-042910":1,"tf2-keras-cifar10-inceptionv3-elastic-20210721-043127":0,"tf2-keras-cifar10-inceptionv3-elastic-20210721-043226":0,"tf2-keras-cifar10-resnet50-elastic-20210721-042522":1,"tf2-keras-cifar10-resnet50-elastic-20210721-042844":1,"tf2-keras-cifar10-resnet50-elastic-20210721-043058":0,"tf2-keras-cifar10-resnet50-elastic-20210721-043248":0,"tf2-keras-cifar10-resnet50-elastic-20210721-043501":0,"tf2-keras-cifar10-resnet50-elastic-20210721-043527":0,"tf2-keras-cifar10-vgg16-elastic-20210721-042620":1,"tf2-keras-cifar10-vgg16-elastic-20210721-042642":1,"tf2-keras-cifar10-vgg16-elastic-20210721-043002":1,"tf2-keras-cifar10-vgg16-elastic-20210721-043029":0,"tf2-keras-cifar10-vgg16-elastic-20210721-043321":0,"tf2-keras-cifar10-vgg16-elastic-20210721-043423":0,"tf2-keras-transformer-elastic-20210721-042705":1,"tf2-keras-transformer-elastic-20210721-042732":1,"tf2-keras-transformer-elastic-20210721-042937":1,"tf2-keras-transformer-elastic-20210721-043203":0,"tf2-keras-transformer-elastic-20210721-043343":0,"tf2-keras-transformer-elastic-20210721-043555":0} "scheduler"="default"
I0721 16:37:00.372240   31979 scheduler.go:384]  "msg"="Trying to delete multiple training jobs"  "jobs"=[] "scheduler"="default"
I0721 16:37:00.372540   31979 scheduler.go:342]  "msg"="Trying to scale multiple training jobs"  "jobs"=[] "scheduler"="default"
I0721 16:37:00.372853   31979 scheduler.go:292]  "msg"="Trying to start multiple training jobs"  "jobs"=[] "scheduler"="default"
I0721 16:37:00.373156   31979 scheduler.go:342]  "msg"="Trying to scale multiple training jobs"  "jobs"=[] "scheduler"="default"
I0721 16:37:00.373430   31979 scheduler.go:180]  "msg"="Nothing changed, skipped ajust placements"  "scheduler"="default"
I0721 16:37:00.373485   31979 scheduler.go:182]  "msg"="Finished resched"  "scheduler"="default"
I0721 16:49:22.464185   31979 scheduler.go:474]  "msg"="Training job completed"  "elaspedTotalSeconds"=1437.787659681 "gpuTotalSeconds"=1705.748403586 "job"="tf2-keras-cifar10-resnet50-elastic-20210721-042522" "ranTotalSeconds"=1345.472936464 "scheduler"="default" "waitedTotalSeconds"=92.314723217
I0721 16:49:22.464408   31979 scheduler.go:135]  "msg"="Received resched event, may be blocked because of rate limit"  "blockedUntil"="2021-07-21T16:39:00.373719794+08:00" "lastResched"="2021-07-21T16:37:00.373719794+08:00" "received"="2021-07-21T16:49:22.464215586+08:00" "scheduler"="default"
I0721 16:49:22.464863   31979 scheduler.go:159]  "msg"="Started resched"  "scheduler"="default"
I0721 16:49:22.464966   31979 scheduler.go:193]  "msg"="Updating all jobs info"  "scheduler"="default"
I0721 16:49:22.478223   31979 elastic_fifo.go:73]  "msg"="Finished scheduling"  "algorithm"="ElasticFIFO" "freeGpu"=0 "result"={"tf2-keras-cifar10-inceptionv3-elastic-20210721-042459":1,"tf2-keras-cifar10-inceptionv3-elastic-20210721-042550":1,"tf2-keras-cifar10-inceptionv3-elastic-20210721-042807":1,"tf2-keras-cifar10-inceptionv3-elastic-20210721-042910":1,"tf2-keras-cifar10-inceptionv3-elastic-20210721-043127":0,"tf2-keras-cifar10-inceptionv3-elastic-20210721-043226":0,"tf2-keras-cifar10-resnet50-elastic-20210721-042844":1,"tf2-keras-cifar10-resnet50-elastic-20210721-043058":0,"tf2-keras-cifar10-resnet50-elastic-20210721-043248":0,"tf2-keras-cifar10-resnet50-elastic-20210721-043501":0,"tf2-keras-cifar10-resnet50-elastic-20210721-043527":0,"tf2-keras-cifar10-vgg16-elastic-20210721-042620":1,"tf2-keras-cifar10-vgg16-elastic-20210721-042642":1,"tf2-keras-cifar10-vgg16-elastic-20210721-043002":1,"tf2-keras-cifar10-vgg16-elastic-20210721-043029":1,"tf2-keras-cifar10-vgg16-elastic-20210721-043321":0,"tf2-keras-cifar10-vgg16-elastic-20210721-043423":0,"tf2-keras-transformer-elastic-20210721-042705":1,"tf2-keras-transformer-elastic-20210721-042732":1,"tf2-keras-transformer-elastic-20210721-042937":1,"tf2-keras-transformer-elastic-20210721-043203":0,"tf2-keras-transformer-elastic-20210721-043343":0,"tf2-keras-transformer-elastic-20210721-043555":0} "scheduler"="default"
I0721 16:49:22.478542   31979 scheduler.go:384]  "msg"="Trying to delete multiple training jobs"  "jobs"=[] "scheduler"="default"
I0721 16:49:22.478755   31979 scheduler.go:342]  "msg"="Trying to scale multiple training jobs"  "jobs"=[] "scheduler"="default"
I0721 16:49:22.479066   31979 scheduler.go:292]  "msg"="Trying to start multiple training jobs"  "jobs"=["tf2-keras-cifar10-vgg16-elastic-20210721-043029"] "scheduler"="default"
I0721 16:49:22.488484   31979 scheduler.go:342]  "msg"="Trying to scale multiple training jobs"  "jobs"=[] "scheduler"="default"
I0721 16:49:22.492724   31979 placement_manager.go:166]  "msg"="Started job placements adjustment"  "scheduler"="default"
I0721 16:49:22.492871   31979 placement_manager.go:192]  "msg"="Releasing slots"  "jobs"={"tf2-keras-cifar10-inceptionv3-elastic-20210721-042459":{},"tf2-keras-cifar10-inceptionv3-elastic-20210721-042550":{},"tf2-keras-cifar10-inceptionv3-elastic-20210721-042807":{},"tf2-keras-cifar10-inceptionv3-elastic-20210721-042910":{},"tf2-keras-cifar10-resnet50-elastic-20210721-042522":{},"tf2-keras-cifar10-resnet50-elastic-20210721-042844":{},"tf2-keras-cifar10-vgg16-elastic-20210721-042620":{},"tf2-keras-cifar10-vgg16-elastic-20210721-042642":{},"tf2-keras-cifar10-vgg16-elastic-20210721-043002":{},"tf2-keras-transformer-elastic-20210721-042705":{},"tf2-keras-transformer-elastic-20210721-042732":{},"tf2-keras-transformer-elastic-20210721-042937":{}} "nodes"={"gpu3":{},"gpu4":{},"gpu5":{}} "scheduler"="default"
I0721 16:49:22.492953   31979 placement_manager.go:250]  "msg"="Released slots"  "jobs"={"tf2-keras-cifar10-inceptionv3-elastic-20210721-042459":{},"tf2-keras-cifar10-inceptionv3-elastic-20210721-042550":{},"tf2-keras-cifar10-inceptionv3-elastic-20210721-042807":{},"tf2-keras-cifar10-inceptionv3-elastic-20210721-042910":{},"tf2-keras-cifar10-resnet50-elastic-20210721-042522":{},"tf2-keras-cifar10-resnet50-elastic-20210721-042844":{},"tf2-keras-cifar10-vgg16-elastic-20210721-042620":{},"tf2-keras-cifar10-vgg16-elastic-20210721-042642":{},"tf2-keras-cifar10-vgg16-elastic-20210721-043002":{},"tf2-keras-transformer-elastic-20210721-042705":{},"tf2-keras-transformer-elastic-20210721-042732":{},"tf2-keras-transformer-elastic-20210721-042937":{}} "nodes"={"gpu3":{},"gpu4":{},"gpu5":{}} "scheduler"="default"
I0721 16:49:22.493390   31979 placement_manager.go:305]  "msg"="Found best-fit"  "crossNode"=0 "nodes"=[{},{},{}] "requests"=[{},{},{},{},{},{},{},{},{},{},{},{},{},{},{},{},{},{},{},{},{},{},{},{},{},{},{},{},{},{},{},{},{},{},{},{},{},{},{},{},{},{},{},{},{},{}] "scheduler"="default"
I0721 16:49:22.493718   31979 placement_manager.go:339]  "msg"="nodeStates updated"  "new"={"gpu3":{},"gpu4":{},"gpu5":{}} "old"={"gpu3":{},"gpu4":{},"gpu5":{}} "scheduler"="default" "score"=5
I0721 16:49:22.494022   31979 placement_manager.go:387]  "msg"="jobStates updated"  "new"={"tf2-keras-cifar10-inceptionv3-elastic-20210721-042459":{},"tf2-keras-cifar10-inceptionv3-elastic-20210721-042550":{},"tf2-keras-cifar10-inceptionv3-elastic-20210721-042807":{},"tf2-keras-cifar10-inceptionv3-elastic-20210721-042910":{},"tf2-keras-cifar10-resnet50-elastic-20210721-042844":{},"tf2-keras-cifar10-vgg16-elastic-20210721-042620":{},"tf2-keras-cifar10-vgg16-elastic-20210721-042642":{},"tf2-keras-cifar10-vgg16-elastic-20210721-043002":{},"tf2-keras-cifar10-vgg16-elastic-20210721-043029":{},"tf2-keras-transformer-elastic-20210721-042705":{},"tf2-keras-transformer-elastic-20210721-042732":{},"tf2-keras-transformer-elastic-20210721-042937":{}} "old"={"tf2-keras-cifar10-inceptionv3-elastic-20210721-042459":{},"tf2-keras-cifar10-inceptionv3-elastic-20210721-042550":{},"tf2-keras-cifar10-inceptionv3-elastic-20210721-042807":{},"tf2-keras-cifar10-inceptionv3-elastic-20210721-042910":{},"tf2-keras-cifar10-resnet50-elastic-20210721-042522":{},"tf2-keras-cifar10-resnet50-elastic-20210721-042844":{},"tf2-keras-cifar10-vgg16-elastic-20210721-042620":{},"tf2-keras-cifar10-vgg16-elastic-20210721-042642":{},"tf2-keras-cifar10-vgg16-elastic-20210721-043002":{},"tf2-keras-transformer-elastic-20210721-042705":{},"tf2-keras-transformer-elastic-20210721-042732":{},"tf2-keras-transformer-elastic-20210721-042937":{}} "scheduler"="default"
I0721 16:49:22.494512   31979 placement_manager.go:434]  "msg"="podNodeName updated"  "launchersToDelete"=6 "new"={"tf2-keras-cifar10-inceptionv3-elastic-20210721-042459-worker-0":"gpu3","tf2-keras-cifar10-inceptionv3-elastic-20210721-042550-worker-0":"gpu4","tf2-keras-cifar10-inceptionv3-elastic-20210721-042807-worker-0":"gpu4","tf2-keras-cifar10-inceptionv3-elastic-20210721-042910-worker-0":"gpu5","tf2-keras-cifar10-resnet50-elastic-20210721-042844-worker-0":"gpu3","tf2-keras-cifar10-vgg16-elastic-20210721-042620-worker-0":"gpu4","tf2-keras-cifar10-vgg16-elastic-20210721-042642-worker-0":"gpu5","tf2-keras-cifar10-vgg16-elastic-20210721-043002-worker-0":"gpu3","tf2-keras-cifar10-vgg16-elastic-20210721-043029-worker-0":"gpu5","tf2-keras-transformer-elastic-20210721-042705-worker-0":"gpu4","tf2-keras-transformer-elastic-20210721-042732-worker-0":"gpu5","tf2-keras-transformer-elastic-20210721-042937-worker-0":"gpu3"} "old"={"tf2-keras-cifar10-inceptionv3-elastic-20210721-042459-worker-0":"gpu3","tf2-keras-cifar10-inceptionv3-elastic-20210721-042550-worker-0":"gpu4","tf2-keras-cifar10-inceptionv3-elastic-20210721-042807-worker-0":"gpu5","tf2-keras-cifar10-inceptionv3-elastic-20210721-042910-worker-0":"gpu5","tf2-keras-cifar10-resnet50-elastic-20210721-042522-worker-0":"gpu4","tf2-keras-cifar10-resnet50-elastic-20210721-042844-worker-0":"gpu4","tf2-keras-cifar10-vgg16-elastic-20210721-042620-worker-0":"gpu3","tf2-keras-cifar10-vgg16-elastic-20210721-042642-worker-0":"gpu5","tf2-keras-cifar10-vgg16-elastic-20210721-043002-worker-0":"gpu5","tf2-keras-transformer-elastic-20210721-042705-worker-0":"gpu3","tf2-keras-transformer-elastic-20210721-042732-worker-0":"gpu4","tf2-keras-transformer-elastic-20210721-042937-worker-0":"gpu3"} "scheduler"="default" "workersToDelete"=6
I0721 16:49:22.494748   31979 placement_manager.go:451]  "msg"="Deleting pod that need migration"  "podName"="tf2-keras-transformer-elastic-20210721-042705-worker-0" "scheduler"="default"
I0721 16:49:22.501335   31979 placement_manager.go:451]  "msg"="Deleting pod that need migration"  "podName"="tf2-keras-transformer-elastic-20210721-042705-launcher" "scheduler"="default"
I0721 16:49:22.510718   31979 placement_manager.go:451]  "msg"="Deleting pod that need migration"  "podName"="tf2-keras-cifar10-vgg16-elastic-20210721-042620-worker-0" "scheduler"="default"
I0721 16:49:22.515378   31979 placement_manager.go:451]  "msg"="Deleting pod that need migration"  "podName"="tf2-keras-cifar10-vgg16-elastic-20210721-042620-launcher" "scheduler"="default"
I0721 16:49:22.519725   31979 placement_manager.go:451]  "msg"="Deleting pod that need migration"  "podName"="tf2-keras-cifar10-vgg16-elastic-20210721-043002-worker-0" "scheduler"="default"
I0721 16:49:22.523893   31979 placement_manager.go:451]  "msg"="Deleting pod that need migration"  "podName"="tf2-keras-cifar10-vgg16-elastic-20210721-043002-launcher" "scheduler"="default"
I0721 16:49:22.527575   31979 placement_manager.go:451]  "msg"="Deleting pod that need migration"  "podName"="tf2-keras-cifar10-resnet50-elastic-20210721-042844-worker-0" "scheduler"="default"
I0721 16:49:22.531645   31979 placement_manager.go:451]  "msg"="Deleting pod that need migration"  "podName"="tf2-keras-cifar10-resnet50-elastic-20210721-042844-launcher" "scheduler"="default"
I0721 16:49:22.535238   31979 placement_manager.go:451]  "msg"="Deleting pod that need migration"  "podName"="tf2-keras-cifar10-inceptionv3-elastic-20210721-042807-worker-0" "scheduler"="default"
I0721 16:49:22.538369   31979 placement_manager.go:451]  "msg"="Deleting pod that need migration"  "podName"="tf2-keras-cifar10-inceptionv3-elastic-20210721-042807-launcher" "scheduler"="default"
I0721 16:49:22.542306   31979 placement_manager.go:451]  "msg"="Deleting pod that need migration"  "podName"="tf2-keras-transformer-elastic-20210721-042732-worker-0" "scheduler"="default"
I0721 16:49:22.699807   31979 placement_manager.go:451]  "msg"="Deleting pod that need migration"  "podName"="tf2-keras-transformer-elastic-20210721-042732-launcher" "scheduler"="default"
I0721 16:49:22.860243   31979 placement_manager.go:147]  "msg"="Adding toleration to pod"  "podName"="tf2-keras-cifar10-vgg16-elastic-20210721-043029-worker-0" "scheduler"="default" "toleration"={"key":"celeste/hostname","operator":"Equal","value":"gpu5","effect":"NoExecute"}
I0721 16:49:22.901213   31979 placement_manager.go:183]  "msg"="Finished job placements adjustment"  "scheduler"="default"
I0721 16:49:22.901507   31979 scheduler.go:182]  "msg"="Finished resched"  "scheduler"="default"
I0721 16:49:23.302203   31979 placement_manager.go:147]  "msg"="Adding toleration to pod"  "podName"="tf2-keras-cifar10-vgg16-elastic-20210721-043029-launcher" "scheduler"="default" "toleration"={"key":"celeste/hostname","operator":"Exists","effect":"NoExecute"}
I0721 16:49:31.966013   31979 placement_manager.go:147]  "msg"="Adding toleration to pod"  "podName"="tf2-keras-cifar10-vgg16-elastic-20210721-043002-launcher" "scheduler"="default" "toleration"={"key":"celeste/hostname","operator":"Exists","effect":"NoExecute"}
I0721 16:49:32.006476   31979 placement_manager.go:147]  "msg"="Adding toleration to pod"  "podName"="tf2-keras-cifar10-vgg16-elastic-20210721-043002-worker-0" "scheduler"="default" "toleration"={"key":"celeste/hostname","operator":"Equal","value":"gpu3","effect":"NoExecute"}
I0721 16:49:32.095837   31979 placement_manager.go:147]  "msg"="Adding toleration to pod"  "podName"="tf2-keras-cifar10-inceptionv3-elastic-20210721-042807-launcher" "scheduler"="default" "toleration"={"key":"celeste/hostname","operator":"Exists","effect":"NoExecute"}
I0721 16:49:33.297426   31979 placement_manager.go:147]  "msg"="Adding toleration to pod"  "podName"="tf2-keras-transformer-elastic-20210721-042705-launcher" "scheduler"="default" "toleration"={"key":"celeste/hostname","operator":"Exists","effect":"NoExecute"}
I0721 16:49:33.693891   31979 placement_manager.go:147]  "msg"="Adding toleration to pod"  "podName"="tf2-keras-cifar10-inceptionv3-elastic-20210721-042807-worker-0" "scheduler"="default" "toleration"={"key":"celeste/hostname","operator":"Equal","value":"gpu4","effect":"NoExecute"}
I0721 16:49:36.167804   31979 placement_manager.go:147]  "msg"="Adding toleration to pod"  "podName"="tf2-keras-transformer-elastic-20210721-042732-launcher" "scheduler"="default" "toleration"={"key":"celeste/hostname","operator":"Exists","effect":"NoExecute"}
I0721 16:49:36.974125   31979 placement_manager.go:147]  "msg"="Adding toleration to pod"  "podName"="tf2-keras-transformer-elastic-20210721-042732-worker-0" "scheduler"="default" "toleration"={"key":"celeste/hostname","operator":"Equal","value":"gpu5","effect":"NoExecute"}
I0721 16:49:37.759197   31979 placement_manager.go:147]  "msg"="Adding toleration to pod"  "podName"="tf2-keras-cifar10-resnet50-elastic-20210721-042844-launcher" "scheduler"="default" "toleration"={"key":"celeste/hostname","operator":"Exists","effect":"NoExecute"}
I0721 16:49:38.560136   31979 placement_manager.go:147]  "msg"="Adding toleration to pod"  "podName"="tf2-keras-cifar10-resnet50-elastic-20210721-042844-worker-0" "scheduler"="default" "toleration"={"key":"celeste/hostname","operator":"Equal","value":"gpu3","effect":"NoExecute"}
I0721 16:49:40.242937   31979 placement_manager.go:147]  "msg"="Adding toleration to pod"  "podName"="tf2-keras-transformer-elastic-20210721-042705-worker-0" "scheduler"="default" "toleration"={"key":"celeste/hostname","operator":"Equal","value":"gpu4","effect":"NoExecute"}
I0721 16:49:41.055612   31979 placement_manager.go:147]  "msg"="Adding toleration to pod"  "podName"="tf2-keras-cifar10-vgg16-elastic-20210721-042620-launcher" "scheduler"="default" "toleration"={"key":"celeste/hostname","operator":"Exists","effect":"NoExecute"}
I0721 16:49:41.837759   31979 placement_manager.go:147]  "msg"="Adding toleration to pod"  "podName"="tf2-keras-cifar10-vgg16-elastic-20210721-042620-worker-0" "scheduler"="default" "toleration"={"key":"celeste/hostname","operator":"Equal","value":"gpu4","effect":"NoExecute"}
I0721 16:50:23.293848   31979 scheduler.go:474]  "msg"="Training job completed"  "elaspedTotalSeconds"=1417.967923587 "gpuTotalSeconds"=1525.479198103 "job"="tf2-keras-cifar10-vgg16-elastic-20210721-042642" "ranTotalSeconds"=1405.475436935 "scheduler"="default" "waitedTotalSeconds"=12.492486652
I0721 16:50:23.294138   31979 scheduler.go:135]  "msg"="Received resched event, may be blocked because of rate limit"  "blockedUntil"="2021-07-21T16:51:22.901760795+08:00" "lastResched"="2021-07-21T16:49:22.901760795+08:00" "received"="2021-07-21T16:50:23.293897642+08:00" "scheduler"="default"
I0721 16:51:22.901896   31979 scheduler.go:159]  "msg"="Started resched"  "scheduler"="default"
I0721 16:51:22.902109   31979 scheduler.go:193]  "msg"="Updating all jobs info"  "scheduler"="default"
I0721 16:51:22.912801   31979 elastic_fifo.go:73]  "msg"="Finished scheduling"  "algorithm"="ElasticFIFO" "freeGpu"=0 "result"={"tf2-keras-cifar10-inceptionv3-elastic-20210721-042459":1,"tf2-keras-cifar10-inceptionv3-elastic-20210721-042550":1,"tf2-keras-cifar10-inceptionv3-elastic-20210721-042807":1,"tf2-keras-cifar10-inceptionv3-elastic-20210721-042910":1,"tf2-keras-cifar10-inceptionv3-elastic-20210721-043127":0,"tf2-keras-cifar10-inceptionv3-elastic-20210721-043226":0,"tf2-keras-cifar10-resnet50-elastic-20210721-042844":1,"tf2-keras-cifar10-resnet50-elastic-20210721-043058":1,"tf2-keras-cifar10-resnet50-elastic-20210721-043248":0,"tf2-keras-cifar10-resnet50-elastic-20210721-043501":0,"tf2-keras-cifar10-resnet50-elastic-20210721-043527":0,"tf2-keras-cifar10-vgg16-elastic-20210721-042620":1,"tf2-keras-cifar10-vgg16-elastic-20210721-043002":1,"tf2-keras-cifar10-vgg16-elastic-20210721-043029":1,"tf2-keras-cifar10-vgg16-elastic-20210721-043321":0,"tf2-keras-cifar10-vgg16-elastic-20210721-043423":0,"tf2-keras-transformer-elastic-20210721-042705":1,"tf2-keras-transformer-elastic-20210721-042732":1,"tf2-keras-transformer-elastic-20210721-042937":1,"tf2-keras-transformer-elastic-20210721-043203":0,"tf2-keras-transformer-elastic-20210721-043343":0,"tf2-keras-transformer-elastic-20210721-043555":0} "scheduler"="default"
I0721 16:51:22.913121   31979 scheduler.go:384]  "msg"="Trying to delete multiple training jobs"  "jobs"=[] "scheduler"="default"
I0721 16:51:22.913396   31979 scheduler.go:342]  "msg"="Trying to scale multiple training jobs"  "jobs"=[] "scheduler"="default"
I0721 16:51:22.913612   31979 scheduler.go:292]  "msg"="Trying to start multiple training jobs"  "jobs"=["tf2-keras-cifar10-resnet50-elastic-20210721-043058"] "scheduler"="default"
I0721 16:51:22.925879   31979 scheduler.go:342]  "msg"="Trying to scale multiple training jobs"  "jobs"=[] "scheduler"="default"
I0721 16:51:22.930531   31979 placement_manager.go:166]  "msg"="Started job placements adjustment"  "scheduler"="default"
I0721 16:51:22.930640   31979 placement_manager.go:192]  "msg"="Releasing slots"  "jobs"={"tf2-keras-cifar10-inceptionv3-elastic-20210721-042459":{},"tf2-keras-cifar10-inceptionv3-elastic-20210721-042550":{},"tf2-keras-cifar10-inceptionv3-elastic-20210721-042807":{},"tf2-keras-cifar10-inceptionv3-elastic-20210721-042910":{},"tf2-keras-cifar10-resnet50-elastic-20210721-042844":{},"tf2-keras-cifar10-vgg16-elastic-20210721-042620":{},"tf2-keras-cifar10-vgg16-elastic-20210721-042642":{},"tf2-keras-cifar10-vgg16-elastic-20210721-043002":{},"tf2-keras-cifar10-vgg16-elastic-20210721-043029":{},"tf2-keras-transformer-elastic-20210721-042705":{},"tf2-keras-transformer-elastic-20210721-042732":{},"tf2-keras-transformer-elastic-20210721-042937":{}} "nodes"={"gpu3":{},"gpu4":{},"gpu5":{}} "scheduler"="default"
I0721 16:51:22.930701   31979 placement_manager.go:250]  "msg"="Released slots"  "jobs"={"tf2-keras-cifar10-inceptionv3-elastic-20210721-042459":{},"tf2-keras-cifar10-inceptionv3-elastic-20210721-042550":{},"tf2-keras-cifar10-inceptionv3-elastic-20210721-042807":{},"tf2-keras-cifar10-inceptionv3-elastic-20210721-042910":{},"tf2-keras-cifar10-resnet50-elastic-20210721-042844":{},"tf2-keras-cifar10-vgg16-elastic-20210721-042620":{},"tf2-keras-cifar10-vgg16-elastic-20210721-042642":{},"tf2-keras-cifar10-vgg16-elastic-20210721-043002":{},"tf2-keras-cifar10-vgg16-elastic-20210721-043029":{},"tf2-keras-transformer-elastic-20210721-042705":{},"tf2-keras-transformer-elastic-20210721-042732":{},"tf2-keras-transformer-elastic-20210721-042937":{}} "nodes"={"gpu3":{},"gpu4":{},"gpu5":{}} "scheduler"="default"
I0721 16:51:22.931132   31979 placement_manager.go:305]  "msg"="Found best-fit"  "crossNode"=0 "nodes"=[{},{},{}] "requests"=[{},{},{},{},{},{},{},{},{},{},{},{},{},{},{},{},{},{},{},{},{},{},{},{},{},{},{},{},{},{},{},{},{},{},{},{},{},{},{},{},{},{},{},{}] "scheduler"="default"
I0721 16:51:22.931477   31979 placement_manager.go:339]  "msg"="nodeStates updated"  "new"={"gpu3":{},"gpu4":{},"gpu5":{}} "old"={"gpu3":{},"gpu4":{},"gpu5":{}} "scheduler"="default" "score"=8
I0721 16:51:22.931830   31979 placement_manager.go:387]  "msg"="jobStates updated"  "new"={"tf2-keras-cifar10-inceptionv3-elastic-20210721-042459":{},"tf2-keras-cifar10-inceptionv3-elastic-20210721-042550":{},"tf2-keras-cifar10-inceptionv3-elastic-20210721-042807":{},"tf2-keras-cifar10-inceptionv3-elastic-20210721-042910":{},"tf2-keras-cifar10-resnet50-elastic-20210721-042844":{},"tf2-keras-cifar10-resnet50-elastic-20210721-043058":{},"tf2-keras-cifar10-vgg16-elastic-20210721-042620":{},"tf2-keras-cifar10-vgg16-elastic-20210721-043002":{},"tf2-keras-cifar10-vgg16-elastic-20210721-043029":{},"tf2-keras-transformer-elastic-20210721-042705":{},"tf2-keras-transformer-elastic-20210721-042732":{},"tf2-keras-transformer-elastic-20210721-042937":{}} "old"={"tf2-keras-cifar10-inceptionv3-elastic-20210721-042459":{},"tf2-keras-cifar10-inceptionv3-elastic-20210721-042550":{},"tf2-keras-cifar10-inceptionv3-elastic-20210721-042807":{},"tf2-keras-cifar10-inceptionv3-elastic-20210721-042910":{},"tf2-keras-cifar10-resnet50-elastic-20210721-042844":{},"tf2-keras-cifar10-vgg16-elastic-20210721-042620":{},"tf2-keras-cifar10-vgg16-elastic-20210721-042642":{},"tf2-keras-cifar10-vgg16-elastic-20210721-043002":{},"tf2-keras-cifar10-vgg16-elastic-20210721-043029":{},"tf2-keras-transformer-elastic-20210721-042705":{},"tf2-keras-transformer-elastic-20210721-042732":{},"tf2-keras-transformer-elastic-20210721-042937":{}} "scheduler"="default"
I0721 16:51:22.932239   31979 placement_manager.go:434]  "msg"="podNodeName updated"  "launchersToDelete"=3 "new"={"tf2-keras-cifar10-inceptionv3-elastic-20210721-042459-worker-0":"gpu5","tf2-keras-cifar10-inceptionv3-elastic-20210721-042550-worker-0":"gpu4","tf2-keras-cifar10-inceptionv3-elastic-20210721-042807-worker-0":"gpu4","tf2-keras-cifar10-inceptionv3-elastic-20210721-042910-worker-0":"gpu5","tf2-keras-cifar10-resnet50-elastic-20210721-042844-worker-0":"gpu5","tf2-keras-cifar10-resnet50-elastic-20210721-043058-worker-0":"gpu3","tf2-keras-cifar10-vgg16-elastic-20210721-042620-worker-0":"gpu4","tf2-keras-cifar10-vgg16-elastic-20210721-043002-worker-0":"gpu3","tf2-keras-cifar10-vgg16-elastic-20210721-043029-worker-0":"gpu3","tf2-keras-transformer-elastic-20210721-042705-worker-0":"gpu4","tf2-keras-transformer-elastic-20210721-042732-worker-0":"gpu5","tf2-keras-transformer-elastic-20210721-042937-worker-0":"gpu3"} "old"={"tf2-keras-cifar10-inceptionv3-elastic-20210721-042459-worker-0":"gpu3","tf2-keras-cifar10-inceptionv3-elastic-20210721-042550-worker-0":"gpu4","tf2-keras-cifar10-inceptionv3-elastic-20210721-042807-worker-0":"gpu4","tf2-keras-cifar10-inceptionv3-elastic-20210721-042910-worker-0":"gpu5","tf2-keras-cifar10-resnet50-elastic-20210721-042844-worker-0":"gpu3","tf2-keras-cifar10-vgg16-elastic-20210721-042620-worker-0":"gpu4","tf2-keras-cifar10-vgg16-elastic-20210721-042642-worker-0":"gpu5","tf2-keras-cifar10-vgg16-elastic-20210721-043002-worker-0":"gpu3","tf2-keras-cifar10-vgg16-elastic-20210721-043029-worker-0":"gpu5","tf2-keras-transformer-elastic-20210721-042705-worker-0":"gpu4","tf2-keras-transformer-elastic-20210721-042732-worker-0":"gpu5","tf2-keras-transformer-elastic-20210721-042937-worker-0":"gpu3"} "scheduler"="default" "workersToDelete"=3
I0721 16:51:22.932539   31979 placement_manager.go:451]  "msg"="Deleting pod that need migration"  "podName"="tf2-keras-cifar10-vgg16-elastic-20210721-043029-worker-0" "scheduler"="default"
I0721 16:51:22.937685   31979 placement_manager.go:451]  "msg"="Deleting pod that need migration"  "podName"="tf2-keras-cifar10-vgg16-elastic-20210721-043029-launcher" "scheduler"="default"
I0721 16:51:22.945135   31979 placement_manager.go:451]  "msg"="Deleting pod that need migration"  "podName"="tf2-keras-cifar10-inceptionv3-elastic-20210721-042459-worker-0" "scheduler"="default"
I0721 16:51:22.955605   31979 placement_manager.go:451]  "msg"="Deleting pod that need migration"  "podName"="tf2-keras-cifar10-inceptionv3-elastic-20210721-042459-launcher" "scheduler"="default"
I0721 16:51:22.960621   31979 placement_manager.go:451]  "msg"="Deleting pod that need migration"  "podName"="tf2-keras-cifar10-resnet50-elastic-20210721-042844-worker-0" "scheduler"="default"
I0721 16:51:22.965496   31979 placement_manager.go:451]  "msg"="Deleting pod that need migration"  "podName"="tf2-keras-cifar10-resnet50-elastic-20210721-042844-launcher" "scheduler"="default"
I0721 16:51:22.971234   31979 placement_manager.go:183]  "msg"="Finished job placements adjustment"  "scheduler"="default"
I0721 16:51:22.971514   31979 scheduler.go:182]  "msg"="Finished resched"  "scheduler"="default"
I0721 16:51:23.132548   31979 placement_manager.go:147]  "msg"="Adding toleration to pod"  "podName"="tf2-keras-cifar10-resnet50-elastic-20210721-043058-worker-0" "scheduler"="default" "toleration"={"key":"celeste/hostname","operator":"Equal","value":"gpu3","effect":"NoExecute"}
I0721 16:51:23.332666   31979 placement_manager.go:147]  "msg"="Adding toleration to pod"  "podName"="tf2-keras-cifar10-resnet50-elastic-20210721-043058-launcher" "scheduler"="default" "toleration"={"key":"celeste/hostname","operator":"Exists","effect":"NoExecute"}
I0721 16:51:31.879146   31979 placement_manager.go:147]  "msg"="Adding toleration to pod"  "podName"="tf2-keras-cifar10-resnet50-elastic-20210721-042844-launcher" "scheduler"="default" "toleration"={"key":"celeste/hostname","operator":"Exists","effect":"NoExecute"}
I0721 16:51:31.927295   31979 placement_manager.go:147]  "msg"="Adding toleration to pod"  "podName"="tf2-keras-cifar10-vgg16-elastic-20210721-043029-worker-0" "scheduler"="default" "toleration"={"key":"celeste/hostname","operator":"Equal","value":"gpu3","effect":"NoExecute"}
I0721 16:51:39.931461   31979 placement_manager.go:147]  "msg"="Adding toleration to pod"  "podName"="tf2-keras-cifar10-vgg16-elastic-20210721-043029-launcher" "scheduler"="default" "toleration"={"key":"celeste/hostname","operator":"Exists","effect":"NoExecute"}
I0721 16:51:40.924893   31979 placement_manager.go:147]  "msg"="Adding toleration to pod"  "podName"="tf2-keras-cifar10-inceptionv3-elastic-20210721-042459-worker-0" "scheduler"="default" "toleration"={"key":"celeste/hostname","operator":"Equal","value":"gpu5","effect":"NoExecute"}
I0721 16:51:41.527978   31979 placement_manager.go:147]  "msg"="Adding toleration to pod"  "podName"="tf2-keras-cifar10-inceptionv3-elastic-20210721-042459-launcher" "scheduler"="default" "toleration"={"key":"celeste/hostname","operator":"Exists","effect":"NoExecute"}
I0721 16:51:41.924422   31979 placement_manager.go:147]  "msg"="Adding toleration to pod"  "podName"="tf2-keras-cifar10-resnet50-elastic-20210721-042844-worker-0" "scheduler"="default" "toleration"={"key":"celeste/hostname","operator":"Equal","value":"gpu5","effect":"NoExecute"}
I0721 16:54:06.857773   31979 scheduler.go:474]  "msg"="Training job completed"  "elaspedTotalSeconds"=1664.938386393 "gpuTotalSeconds"=1750.486788435 "job"="tf2-keras-cifar10-vgg16-elastic-20210721-042620" "ranTotalSeconds"=1630.483034469 "scheduler"="default" "waitedTotalSeconds"=34.455351924
I0721 16:54:06.857942   31979 scheduler.go:135]  "msg"="Received resched event, may be blocked because of rate limit"  "blockedUntil"="2021-07-21T16:53:22.971701256+08:00" "lastResched"="2021-07-21T16:51:22.971701256+08:00" "received"="2021-07-21T16:54:06.857825787+08:00" "scheduler"="default"
I0721 16:54:06.858467   31979 scheduler.go:159]  "msg"="Started resched"  "scheduler"="default"
I0721 16:54:06.858531   31979 scheduler.go:193]  "msg"="Updating all jobs info"  "scheduler"="default"
I0721 16:54:06.870264   31979 elastic_fifo.go:73]  "msg"="Finished scheduling"  "algorithm"="ElasticFIFO" "freeGpu"=0 "result"={"tf2-keras-cifar10-inceptionv3-elastic-20210721-042459":1,"tf2-keras-cifar10-inceptionv3-elastic-20210721-042550":1,"tf2-keras-cifar10-inceptionv3-elastic-20210721-042807":1,"tf2-keras-cifar10-inceptionv3-elastic-20210721-042910":1,"tf2-keras-cifar10-inceptionv3-elastic-20210721-043127":1,"tf2-keras-cifar10-inceptionv3-elastic-20210721-043226":0,"tf2-keras-cifar10-resnet50-elastic-20210721-042844":1,"tf2-keras-cifar10-resnet50-elastic-20210721-043058":1,"tf2-keras-cifar10-resnet50-elastic-20210721-043248":0,"tf2-keras-cifar10-resnet50-elastic-20210721-043501":0,"tf2-keras-cifar10-resnet50-elastic-20210721-043527":0,"tf2-keras-cifar10-vgg16-elastic-20210721-043002":1,"tf2-keras-cifar10-vgg16-elastic-20210721-043029":1,"tf2-keras-cifar10-vgg16-elastic-20210721-043321":0,"tf2-keras-cifar10-vgg16-elastic-20210721-043423":0,"tf2-keras-transformer-elastic-20210721-042705":1,"tf2-keras-transformer-elastic-20210721-042732":1,"tf2-keras-transformer-elastic-20210721-042937":1,"tf2-keras-transformer-elastic-20210721-043203":0,"tf2-keras-transformer-elastic-20210721-043343":0,"tf2-keras-transformer-elastic-20210721-043555":0} "scheduler"="default"
I0721 16:54:06.870600   31979 scheduler.go:384]  "msg"="Trying to delete multiple training jobs"  "jobs"=[] "scheduler"="default"
I0721 16:54:06.870862   31979 scheduler.go:342]  "msg"="Trying to scale multiple training jobs"  "jobs"=[] "scheduler"="default"
I0721 16:54:06.871082   31979 scheduler.go:292]  "msg"="Trying to start multiple training jobs"  "jobs"=["tf2-keras-cifar10-inceptionv3-elastic-20210721-043127"] "scheduler"="default"
I0721 16:54:06.881369   31979 scheduler.go:342]  "msg"="Trying to scale multiple training jobs"  "jobs"=[] "scheduler"="default"
I0721 16:54:06.885707   31979 placement_manager.go:166]  "msg"="Started job placements adjustment"  "scheduler"="default"
I0721 16:54:06.885802   31979 placement_manager.go:192]  "msg"="Releasing slots"  "jobs"={"tf2-keras-cifar10-inceptionv3-elastic-20210721-042459":{},"tf2-keras-cifar10-inceptionv3-elastic-20210721-042550":{},"tf2-keras-cifar10-inceptionv3-elastic-20210721-042807":{},"tf2-keras-cifar10-inceptionv3-elastic-20210721-042910":{},"tf2-keras-cifar10-resnet50-elastic-20210721-042844":{},"tf2-keras-cifar10-resnet50-elastic-20210721-043058":{},"tf2-keras-cifar10-vgg16-elastic-20210721-042620":{},"tf2-keras-cifar10-vgg16-elastic-20210721-043002":{},"tf2-keras-cifar10-vgg16-elastic-20210721-043029":{},"tf2-keras-transformer-elastic-20210721-042705":{},"tf2-keras-transformer-elastic-20210721-042732":{},"tf2-keras-transformer-elastic-20210721-042937":{}} "nodes"={"gpu3":{},"gpu4":{},"gpu5":{}} "scheduler"="default"
I0721 16:54:06.885895   31979 placement_manager.go:250]  "msg"="Released slots"  "jobs"={"tf2-keras-cifar10-inceptionv3-elastic-20210721-042459":{},"tf2-keras-cifar10-inceptionv3-elastic-20210721-042550":{},"tf2-keras-cifar10-inceptionv3-elastic-20210721-042807":{},"tf2-keras-cifar10-inceptionv3-elastic-20210721-042910":{},"tf2-keras-cifar10-resnet50-elastic-20210721-042844":{},"tf2-keras-cifar10-resnet50-elastic-20210721-043058":{},"tf2-keras-cifar10-vgg16-elastic-20210721-042620":{},"tf2-keras-cifar10-vgg16-elastic-20210721-043002":{},"tf2-keras-cifar10-vgg16-elastic-20210721-043029":{},"tf2-keras-transformer-elastic-20210721-042705":{},"tf2-keras-transformer-elastic-20210721-042732":{},"tf2-keras-transformer-elastic-20210721-042937":{}} "nodes"={"gpu3":{},"gpu4":{},"gpu5":{}} "scheduler"="default"
I0721 16:54:06.886431   31979 placement_manager.go:305]  "msg"="Found best-fit"  "crossNode"=0 "nodes"=[{},{},{}] "requests"=[{},{},{},{},{},{},{},{},{},{},{},{},{},{},{},{},{},{},{},{},{},{},{},{},{},{},{},{},{},{},{},{},{},{},{},{},{},{},{},{},{},{}] "scheduler"="default"
I0721 16:54:06.886808   31979 placement_manager.go:339]  "msg"="nodeStates updated"  "new"={"gpu3":{},"gpu4":{},"gpu5":{}} "old"={"gpu3":{},"gpu4":{},"gpu5":{}} "scheduler"="default" "score"=5
I0721 16:54:06.887159   31979 placement_manager.go:387]  "msg"="jobStates updated"  "new"={"tf2-keras-cifar10-inceptionv3-elastic-20210721-042459":{},"tf2-keras-cifar10-inceptionv3-elastic-20210721-042550":{},"tf2-keras-cifar10-inceptionv3-elastic-20210721-042807":{},"tf2-keras-cifar10-inceptionv3-elastic-20210721-042910":{},"tf2-keras-cifar10-inceptionv3-elastic-20210721-043127":{},"tf2-keras-cifar10-resnet50-elastic-20210721-042844":{},"tf2-keras-cifar10-resnet50-elastic-20210721-043058":{},"tf2-keras-cifar10-vgg16-elastic-20210721-043002":{},"tf2-keras-cifar10-vgg16-elastic-20210721-043029":{},"tf2-keras-transformer-elastic-20210721-042705":{},"tf2-keras-transformer-elastic-20210721-042732":{},"tf2-keras-transformer-elastic-20210721-042937":{}} "old"={"tf2-keras-cifar10-inceptionv3-elastic-20210721-042459":{},"tf2-keras-cifar10-inceptionv3-elastic-20210721-042550":{},"tf2-keras-cifar10-inceptionv3-elastic-20210721-042807":{},"tf2-keras-cifar10-inceptionv3-elastic-20210721-042910":{},"tf2-keras-cifar10-resnet50-elastic-20210721-042844":{},"tf2-keras-cifar10-resnet50-elastic-20210721-043058":{},"tf2-keras-cifar10-vgg16-elastic-20210721-042620":{},"tf2-keras-cifar10-vgg16-elastic-20210721-043002":{},"tf2-keras-cifar10-vgg16-elastic-20210721-043029":{},"tf2-keras-transformer-elastic-20210721-042705":{},"tf2-keras-transformer-elastic-20210721-042732":{},"tf2-keras-transformer-elastic-20210721-042937":{}} "scheduler"="default"
I0721 16:54:06.887589   31979 placement_manager.go:434]  "msg"="podNodeName updated"  "launchersToDelete"=6 "new"={"tf2-keras-cifar10-inceptionv3-elastic-20210721-042459-worker-0":"gpu5","tf2-keras-cifar10-inceptionv3-elastic-20210721-042550-worker-0":"gpu3","tf2-keras-cifar10-inceptionv3-elastic-20210721-042807-worker-0":"gpu4","tf2-keras-cifar10-inceptionv3-elastic-20210721-042910-worker-0":"gpu3","tf2-keras-cifar10-inceptionv3-elastic-20210721-043127-worker-0":"gpu5","tf2-keras-cifar10-resnet50-elastic-20210721-042844-worker-0":"gpu4","tf2-keras-cifar10-resnet50-elastic-20210721-043058-worker-0":"gpu3","tf2-keras-cifar10-vgg16-elastic-20210721-043002-worker-0":"gpu5","tf2-keras-cifar10-vgg16-elastic-20210721-043029-worker-0":"gpu3","tf2-keras-transformer-elastic-20210721-042705-worker-0":"gpu4","tf2-keras-transformer-elastic-20210721-042732-worker-0":"gpu4","tf2-keras-transformer-elastic-20210721-042937-worker-0":"gpu5"} "old"={"tf2-keras-cifar10-inceptionv3-elastic-20210721-042459-worker-0":"gpu5","tf2-keras-cifar10-inceptionv3-elastic-20210721-042550-worker-0":"gpu4","tf2-keras-cifar10-inceptionv3-elastic-20210721-042807-worker-0":"gpu4","tf2-keras-cifar10-inceptionv3-elastic-20210721-042910-worker-0":"gpu5","tf2-keras-cifar10-resnet50-elastic-20210721-042844-worker-0":"gpu5","tf2-keras-cifar10-resnet50-elastic-20210721-043058-worker-0":"gpu3","tf2-keras-cifar10-vgg16-elastic-20210721-042620-worker-0":"gpu4","tf2-keras-cifar10-vgg16-elastic-20210721-043002-worker-0":"gpu3","tf2-keras-cifar10-vgg16-elastic-20210721-043029-worker-0":"gpu3","tf2-keras-transformer-elastic-20210721-042705-worker-0":"gpu4","tf2-keras-transformer-elastic-20210721-042732-worker-0":"gpu5","tf2-keras-transformer-elastic-20210721-042937-worker-0":"gpu3"} "scheduler"="default" "workersToDelete"=6
I0721 16:54:06.887961   31979 placement_manager.go:451]  "msg"="Deleting pod that need migration"  "podName"="tf2-keras-cifar10-vgg16-elastic-20210721-043002-worker-0" "scheduler"="default"
I0721 16:54:06.892678   31979 placement_manager.go:451]  "msg"="Deleting pod that need migration"  "podName"="tf2-keras-cifar10-vgg16-elastic-20210721-043002-launcher" "scheduler"="default"
I0721 16:54:06.897256   31979 placement_manager.go:451]  "msg"="Deleting pod that need migration"  "podName"="tf2-keras-cifar10-resnet50-elastic-20210721-042844-worker-0" "scheduler"="default"
I0721 16:54:06.907964   31979 placement_manager.go:451]  "msg"="Deleting pod that need migration"  "podName"="tf2-keras-cifar10-resnet50-elastic-20210721-042844-launcher" "scheduler"="default"
I0721 16:54:06.911717   31979 placement_manager.go:451]  "msg"="Deleting pod that need migration"  "podName"="tf2-keras-cifar10-inceptionv3-elastic-20210721-042910-worker-0" "scheduler"="default"
I0721 16:54:06.916165   31979 placement_manager.go:451]  "msg"="Deleting pod that need migration"  "podName"="tf2-keras-cifar10-inceptionv3-elastic-20210721-042910-launcher" "scheduler"="default"
I0721 16:54:06.920382   31979 placement_manager.go:451]  "msg"="Deleting pod that need migration"  "podName"="tf2-keras-transformer-elastic-20210721-042937-worker-0" "scheduler"="default"
I0721 16:54:06.923890   31979 placement_manager.go:451]  "msg"="Deleting pod that need migration"  "podName"="tf2-keras-transformer-elastic-20210721-042937-launcher" "scheduler"="default"
I0721 16:54:06.928478   31979 placement_manager.go:451]  "msg"="Deleting pod that need migration"  "podName"="tf2-keras-transformer-elastic-20210721-042732-worker-0" "scheduler"="default"
I0721 16:54:06.932377   31979 placement_manager.go:451]  "msg"="Deleting pod that need migration"  "podName"="tf2-keras-transformer-elastic-20210721-042732-launcher" "scheduler"="default"
I0721 16:54:06.936384   31979 placement_manager.go:451]  "msg"="Deleting pod that need migration"  "podName"="tf2-keras-cifar10-inceptionv3-elastic-20210721-042550-worker-0" "scheduler"="default"
I0721 16:54:07.092272   31979 placement_manager.go:451]  "msg"="Deleting pod that need migration"  "podName"="tf2-keras-cifar10-inceptionv3-elastic-20210721-042550-launcher" "scheduler"="default"
I0721 16:54:07.294144   31979 placement_manager.go:183]  "msg"="Finished job placements adjustment"  "scheduler"="default"
I0721 16:54:07.294394   31979 scheduler.go:182]  "msg"="Finished resched"  "scheduler"="default"
I0721 16:54:07.450496   31979 placement_manager.go:147]  "msg"="Adding toleration to pod"  "podName"="tf2-keras-cifar10-inceptionv3-elastic-20210721-043127-worker-0" "scheduler"="default" "toleration"={"key":"celeste/hostname","operator":"Equal","value":"gpu5","effect":"NoExecute"}
I0721 16:54:07.850999   31979 placement_manager.go:147]  "msg"="Adding toleration to pod"  "podName"="tf2-keras-cifar10-inceptionv3-elastic-20210721-043127-launcher" "scheduler"="default" "toleration"={"key":"celeste/hostname","operator":"Exists","effect":"NoExecute"}
I0721 16:54:13.971709   31979 placement_manager.go:147]  "msg"="Adding toleration to pod"  "podName"="tf2-keras-cifar10-inceptionv3-elastic-20210721-042910-launcher" "scheduler"="default" "toleration"={"key":"celeste/hostname","operator":"Exists","effect":"NoExecute"}
I0721 16:54:16.031679   31979 placement_manager.go:147]  "msg"="Adding toleration to pod"  "podName"="tf2-keras-cifar10-vgg16-elastic-20210721-043002-worker-0" "scheduler"="default" "toleration"={"key":"celeste/hostname","operator":"Equal","value":"gpu5","effect":"NoExecute"}
I0721 16:54:16.070214   31979 placement_manager.go:147]  "msg"="Adding toleration to pod"  "podName"="tf2-keras-transformer-elastic-20210721-042937-worker-0" "scheduler"="default" "toleration"={"key":"celeste/hostname","operator":"Equal","value":"gpu5","effect":"NoExecute"}
I0721 16:54:18.236013   31979 placement_manager.go:147]  "msg"="Adding toleration to pod"  "podName"="tf2-keras-transformer-elastic-20210721-042732-worker-0" "scheduler"="default" "toleration"={"key":"celeste/hostname","operator":"Equal","value":"gpu4","effect":"NoExecute"}
I0721 16:54:19.036749   31979 placement_manager.go:147]  "msg"="Adding toleration to pod"  "podName"="tf2-keras-transformer-elastic-20210721-042937-launcher" "scheduler"="default" "toleration"={"key":"celeste/hostname","operator":"Exists","effect":"NoExecute"}
I0721 16:54:20.623952   31979 placement_manager.go:147]  "msg"="Adding toleration to pod"  "podName"="tf2-keras-cifar10-vgg16-elastic-20210721-043002-launcher" "scheduler"="default" "toleration"={"key":"celeste/hostname","operator":"Exists","effect":"NoExecute"}
I0721 16:54:24.025436   31979 placement_manager.go:147]  "msg"="Adding toleration to pod"  "podName"="tf2-keras-cifar10-resnet50-elastic-20210721-042844-launcher" "scheduler"="default" "toleration"={"key":"celeste/hostname","operator":"Exists","effect":"NoExecute"}
I0721 16:54:24.896226   31979 placement_manager.go:147]  "msg"="Adding toleration to pod"  "podName"="tf2-keras-cifar10-inceptionv3-elastic-20210721-042550-worker-0" "scheduler"="default" "toleration"={"key":"celeste/hostname","operator":"Equal","value":"gpu3","effect":"NoExecute"}
I0721 16:54:25.222769   31979 placement_manager.go:147]  "msg"="Adding toleration to pod"  "podName"="tf2-keras-cifar10-inceptionv3-elastic-20210721-042910-worker-0" "scheduler"="default" "toleration"={"key":"celeste/hostname","operator":"Equal","value":"gpu3","effect":"NoExecute"}
I0721 16:54:26.023204   31979 placement_manager.go:147]  "msg"="Adding toleration to pod"  "podName"="tf2-keras-cifar10-resnet50-elastic-20210721-042844-worker-0" "scheduler"="default" "toleration"={"key":"celeste/hostname","operator":"Equal","value":"gpu4","effect":"NoExecute"}
I0721 16:54:26.104462   31979 placement_manager.go:147]  "msg"="Adding toleration to pod"  "podName"="tf2-keras-cifar10-inceptionv3-elastic-20210721-042550-launcher" "scheduler"="default" "toleration"={"key":"celeste/hostname","operator":"Exists","effect":"NoExecute"}
I0721 16:54:26.823115   31979 placement_manager.go:147]  "msg"="Adding toleration to pod"  "podName"="tf2-keras-transformer-elastic-20210721-042732-launcher" "scheduler"="default" "toleration"={"key":"celeste/hostname","operator":"Exists","effect":"NoExecute"}
I0721 16:55:20.686177   31979 scheduler.go:474]  "msg"="Training job completed"  "elaspedTotalSeconds"=1517.621519269 "gpuTotalSeconds"=1465.214380007 "job"="tf2-keras-cifar10-vgg16-elastic-20210721-043002" "ranTotalSeconds"=1465.214380007 "scheduler"="default" "waitedTotalSeconds"=52.407139262
I0721 16:55:20.686320   31979 scheduler.go:135]  "msg"="Received resched event, may be blocked because of rate limit"  "blockedUntil"="2021-07-21T16:56:07.294687387+08:00" "lastResched"="2021-07-21T16:54:07.294687387+08:00" "received"="2021-07-21T16:55:20.686204682+08:00" "scheduler"="default"
I0721 16:56:07.294758   31979 scheduler.go:159]  "msg"="Started resched"  "scheduler"="default"
I0721 16:56:07.294868   31979 scheduler.go:193]  "msg"="Updating all jobs info"  "scheduler"="default"
I0721 16:56:07.306411   31979 elastic_fifo.go:73]  "msg"="Finished scheduling"  "algorithm"="ElasticFIFO" "freeGpu"=0 "result"={"tf2-keras-cifar10-inceptionv3-elastic-20210721-042459":1,"tf2-keras-cifar10-inceptionv3-elastic-20210721-042550":1,"tf2-keras-cifar10-inceptionv3-elastic-20210721-042807":1,"tf2-keras-cifar10-inceptionv3-elastic-20210721-042910":1,"tf2-keras-cifar10-inceptionv3-elastic-20210721-043127":1,"tf2-keras-cifar10-inceptionv3-elastic-20210721-043226":0,"tf2-keras-cifar10-resnet50-elastic-20210721-042844":1,"tf2-keras-cifar10-resnet50-elastic-20210721-043058":1,"tf2-keras-cifar10-resnet50-elastic-20210721-043248":0,"tf2-keras-cifar10-resnet50-elastic-20210721-043501":0,"tf2-keras-cifar10-resnet50-elastic-20210721-043527":0,"tf2-keras-cifar10-vgg16-elastic-20210721-043029":1,"tf2-keras-cifar10-vgg16-elastic-20210721-043321":0,"tf2-keras-cifar10-vgg16-elastic-20210721-043423":0,"tf2-keras-transformer-elastic-20210721-042705":1,"tf2-keras-transformer-elastic-20210721-042732":1,"tf2-keras-transformer-elastic-20210721-042937":1,"tf2-keras-transformer-elastic-20210721-043203":1,"tf2-keras-transformer-elastic-20210721-043343":0,"tf2-keras-transformer-elastic-20210721-043555":0} "scheduler"="default"
I0721 16:56:07.306838   31979 scheduler.go:384]  "msg"="Trying to delete multiple training jobs"  "jobs"=[] "scheduler"="default"
I0721 16:56:07.307149   31979 scheduler.go:342]  "msg"="Trying to scale multiple training jobs"  "jobs"=[] "scheduler"="default"
I0721 16:56:07.307453   31979 scheduler.go:292]  "msg"="Trying to start multiple training jobs"  "jobs"=["tf2-keras-transformer-elastic-20210721-043203"] "scheduler"="default"
I0721 16:56:07.319872   31979 scheduler.go:342]  "msg"="Trying to scale multiple training jobs"  "jobs"=[] "scheduler"="default"
I0721 16:56:07.323666   31979 placement_manager.go:166]  "msg"="Started job placements adjustment"  "scheduler"="default"
I0721 16:56:07.323731   31979 placement_manager.go:192]  "msg"="Releasing slots"  "jobs"={"tf2-keras-cifar10-inceptionv3-elastic-20210721-042459":{},"tf2-keras-cifar10-inceptionv3-elastic-20210721-042550":{},"tf2-keras-cifar10-inceptionv3-elastic-20210721-042807":{},"tf2-keras-cifar10-inceptionv3-elastic-20210721-042910":{},"tf2-keras-cifar10-inceptionv3-elastic-20210721-043127":{},"tf2-keras-cifar10-resnet50-elastic-20210721-042844":{},"tf2-keras-cifar10-resnet50-elastic-20210721-043058":{},"tf2-keras-cifar10-vgg16-elastic-20210721-043002":{},"tf2-keras-cifar10-vgg16-elastic-20210721-043029":{},"tf2-keras-transformer-elastic-20210721-042705":{},"tf2-keras-transformer-elastic-20210721-042732":{},"tf2-keras-transformer-elastic-20210721-042937":{}} "nodes"={"gpu3":{},"gpu4":{},"gpu5":{}} "scheduler"="default"
I0721 16:56:07.323835   31979 placement_manager.go:250]  "msg"="Released slots"  "jobs"={"tf2-keras-cifar10-inceptionv3-elastic-20210721-042459":{},"tf2-keras-cifar10-inceptionv3-elastic-20210721-042550":{},"tf2-keras-cifar10-inceptionv3-elastic-20210721-042807":{},"tf2-keras-cifar10-inceptionv3-elastic-20210721-042910":{},"tf2-keras-cifar10-inceptionv3-elastic-20210721-043127":{},"tf2-keras-cifar10-resnet50-elastic-20210721-042844":{},"tf2-keras-cifar10-resnet50-elastic-20210721-043058":{},"tf2-keras-cifar10-vgg16-elastic-20210721-043002":{},"tf2-keras-cifar10-vgg16-elastic-20210721-043029":{},"tf2-keras-transformer-elastic-20210721-042705":{},"tf2-keras-transformer-elastic-20210721-042732":{},"tf2-keras-transformer-elastic-20210721-042937":{}} "nodes"={"gpu3":{},"gpu4":{},"gpu5":{}} "scheduler"="default"
I0721 16:56:07.324335   31979 placement_manager.go:305]  "msg"="Found best-fit"  "crossNode"=0 "nodes"=[{},{},{}] "requests"=[{},{},{},{},{},{},{},{},{},{},{},{},{},{},{},{},{},{},{},{},{},{},{},{},{},{},{},{},{},{},{},{},{},{},{},{},{},{},{},{}] "scheduler"="default"
I0721 16:56:07.324648   31979 placement_manager.go:339]  "msg"="nodeStates updated"  "new"={"gpu3":{},"gpu4":{},"gpu5":{}} "old"={"gpu3":{},"gpu4":{},"gpu5":{}} "scheduler"="default" "score"=8
I0721 16:56:07.324925   31979 placement_manager.go:387]  "msg"="jobStates updated"  "new"={"tf2-keras-cifar10-inceptionv3-elastic-20210721-042459":{},"tf2-keras-cifar10-inceptionv3-elastic-20210721-042550":{},"tf2-keras-cifar10-inceptionv3-elastic-20210721-042807":{},"tf2-keras-cifar10-inceptionv3-elastic-20210721-042910":{},"tf2-keras-cifar10-inceptionv3-elastic-20210721-043127":{},"tf2-keras-cifar10-resnet50-elastic-20210721-042844":{},"tf2-keras-cifar10-resnet50-elastic-20210721-043058":{},"tf2-keras-cifar10-vgg16-elastic-20210721-043029":{},"tf2-keras-transformer-elastic-20210721-042705":{},"tf2-keras-transformer-elastic-20210721-042732":{},"tf2-keras-transformer-elastic-20210721-042937":{},"tf2-keras-transformer-elastic-20210721-043203":{}} "old"={"tf2-keras-cifar10-inceptionv3-elastic-20210721-042459":{},"tf2-keras-cifar10-inceptionv3-elastic-20210721-042550":{},"tf2-keras-cifar10-inceptionv3-elastic-20210721-042807":{},"tf2-keras-cifar10-inceptionv3-elastic-20210721-042910":{},"tf2-keras-cifar10-inceptionv3-elastic-20210721-043127":{},"tf2-keras-cifar10-resnet50-elastic-20210721-042844":{},"tf2-keras-cifar10-resnet50-elastic-20210721-043058":{},"tf2-keras-cifar10-vgg16-elastic-20210721-043002":{},"tf2-keras-cifar10-vgg16-elastic-20210721-043029":{},"tf2-keras-transformer-elastic-20210721-042705":{},"tf2-keras-transformer-elastic-20210721-042732":{},"tf2-keras-transformer-elastic-20210721-042937":{}} "scheduler"="default"
I0721 16:56:07.325208   31979 placement_manager.go:434]  "msg"="podNodeName updated"  "launchersToDelete"=3 "new"={"tf2-keras-cifar10-inceptionv3-elastic-20210721-042459-worker-0":"gpu5","tf2-keras-cifar10-inceptionv3-elastic-20210721-042550-worker-0":"gpu4","tf2-keras-cifar10-inceptionv3-elastic-20210721-042807-worker-0":"gpu4","tf2-keras-cifar10-inceptionv3-elastic-20210721-042910-worker-0":"gpu3","tf2-keras-cifar10-inceptionv3-elastic-20210721-043127-worker-0":"gpu5","tf2-keras-cifar10-resnet50-elastic-20210721-042844-worker-0":"gpu4","tf2-keras-cifar10-resnet50-elastic-20210721-043058-worker-0":"gpu3","tf2-keras-cifar10-vgg16-elastic-20210721-043029-worker-0":"gpu5","tf2-keras-transformer-elastic-20210721-042705-worker-0":"gpu3","tf2-keras-transformer-elastic-20210721-042732-worker-0":"gpu4","tf2-keras-transformer-elastic-20210721-042937-worker-0":"gpu5","tf2-keras-transformer-elastic-20210721-043203-worker-0":"gpu3"} "old"={"tf2-keras-cifar10-inceptionv3-elastic-20210721-042459-worker-0":"gpu5","tf2-keras-cifar10-inceptionv3-elastic-20210721-042550-worker-0":"gpu3","tf2-keras-cifar10-inceptionv3-elastic-20210721-042807-worker-0":"gpu4","tf2-keras-cifar10-inceptionv3-elastic-20210721-042910-worker-0":"gpu3","tf2-keras-cifar10-inceptionv3-elastic-20210721-043127-worker-0":"gpu5","tf2-keras-cifar10-resnet50-elastic-20210721-042844-worker-0":"gpu4","tf2-keras-cifar10-resnet50-elastic-20210721-043058-worker-0":"gpu3","tf2-keras-cifar10-vgg16-elastic-20210721-043002-worker-0":"gpu5","tf2-keras-cifar10-vgg16-elastic-20210721-043029-worker-0":"gpu3","tf2-keras-transformer-elastic-20210721-042705-worker-0":"gpu4","tf2-keras-transformer-elastic-20210721-042732-worker-0":"gpu4","tf2-keras-transformer-elastic-20210721-042937-worker-0":"gpu5"} "scheduler"="default" "workersToDelete"=3
I0721 16:56:07.325401   31979 placement_manager.go:451]  "msg"="Deleting pod that need migration"  "podName"="tf2-keras-transformer-elastic-20210721-042705-worker-0" "scheduler"="default"
I0721 16:56:07.334918   31979 placement_manager.go:451]  "msg"="Deleting pod that need migration"  "podName"="tf2-keras-transformer-elastic-20210721-042705-launcher" "scheduler"="default"
I0721 16:56:07.340058   31979 placement_manager.go:451]  "msg"="Deleting pod that need migration"  "podName"="tf2-keras-cifar10-vgg16-elastic-20210721-043029-worker-0" "scheduler"="default"
I0721 16:56:07.362106   31979 placement_manager.go:451]  "msg"="Deleting pod that need migration"  "podName"="tf2-keras-cifar10-vgg16-elastic-20210721-043029-launcher" "scheduler"="default"
I0721 16:56:07.368557   31979 placement_manager.go:451]  "msg"="Deleting pod that need migration"  "podName"="tf2-keras-cifar10-inceptionv3-elastic-20210721-042550-worker-0" "scheduler"="default"
I0721 16:56:07.376182   31979 placement_manager.go:451]  "msg"="Deleting pod that need migration"  "podName"="tf2-keras-cifar10-inceptionv3-elastic-20210721-042550-launcher" "scheduler"="default"
I0721 16:56:07.382238   31979 placement_manager.go:183]  "msg"="Finished job placements adjustment"  "scheduler"="default"
I0721 16:56:07.382538   31979 scheduler.go:182]  "msg"="Finished resched"  "scheduler"="default"
I0721 16:56:07.526370   31979 placement_manager.go:147]  "msg"="Adding toleration to pod"  "podName"="tf2-keras-transformer-elastic-20210721-043203-worker-0" "scheduler"="default" "toleration"={"key":"celeste/hostname","operator":"Equal","value":"gpu3","effect":"NoExecute"}
I0721 16:56:07.929619   31979 placement_manager.go:147]  "msg"="Adding toleration to pod"  "podName"="tf2-keras-transformer-elastic-20210721-043203-launcher" "scheduler"="default" "toleration"={"key":"celeste/hostname","operator":"Exists","effect":"NoExecute"}
I0721 16:56:19.276821   31979 placement_manager.go:147]  "msg"="Adding toleration to pod"  "podName"="tf2-keras-cifar10-vgg16-elastic-20210721-043029-worker-0" "scheduler"="default" "toleration"={"key":"celeste/hostname","operator":"Equal","value":"gpu5","effect":"NoExecute"}
I0721 16:56:19.311204   31979 placement_manager.go:147]  "msg"="Adding toleration to pod"  "podName"="tf2-keras-cifar10-vgg16-elastic-20210721-043029-launcher" "scheduler"="default" "toleration"={"key":"celeste/hostname","operator":"Exists","effect":"NoExecute"}
I0721 16:56:19.322359   31979 placement_manager.go:147]  "msg"="Adding toleration to pod"  "podName"="tf2-keras-cifar10-inceptionv3-elastic-20210721-042550-worker-0" "scheduler"="default" "toleration"={"key":"celeste/hostname","operator":"Equal","value":"gpu4","effect":"NoExecute"}
I0721 16:56:19.604103   31979 placement_manager.go:147]  "msg"="Adding toleration to pod"  "podName"="tf2-keras-cifar10-inceptionv3-elastic-20210721-042550-launcher" "scheduler"="default" "toleration"={"key":"celeste/hostname","operator":"Exists","effect":"NoExecute"}
I0721 16:56:25.363204   31979 placement_manager.go:147]  "msg"="Adding toleration to pod"  "podName"="tf2-keras-transformer-elastic-20210721-042705-launcher" "scheduler"="default" "toleration"={"key":"celeste/hostname","operator":"Exists","effect":"NoExecute"}
I0721 16:56:26.158569   31979 placement_manager.go:147]  "msg"="Adding toleration to pod"  "podName"="tf2-keras-transformer-elastic-20210721-042705-worker-0" "scheduler"="default" "toleration"={"key":"celeste/hostname","operator":"Equal","value":"gpu3","effect":"NoExecute"}
I0721 16:58:06.300873   31979 scheduler.go:474]  "msg"="Training job completed"  "elaspedTotalSeconds"=1761.405073417 "gpuTotalSeconds"=1750.487934644 "job"="tf2-keras-cifar10-resnet50-elastic-20210721-042844" "ranTotalSeconds"=1750.487934644 "scheduler"="default" "waitedTotalSeconds"=10.917138773
I0721 16:58:06.301002   31979 scheduler.go:135]  "msg"="Received resched event, may be blocked because of rate limit"  "blockedUntil"="2021-07-21T16:58:07.382772647+08:00" "lastResched"="2021-07-21T16:56:07.382772647+08:00" "received"="2021-07-21T16:58:06.300899307+08:00" "scheduler"="default"
I0721 16:58:07.382832   31979 scheduler.go:159]  "msg"="Started resched"  "scheduler"="default"
I0721 16:58:07.382896   31979 scheduler.go:193]  "msg"="Updating all jobs info"  "scheduler"="default"
I0721 16:58:07.392628   31979 elastic_fifo.go:73]  "msg"="Finished scheduling"  "algorithm"="ElasticFIFO" "freeGpu"=0 "result"={"tf2-keras-cifar10-inceptionv3-elastic-20210721-042459":1,"tf2-keras-cifar10-inceptionv3-elastic-20210721-042550":1,"tf2-keras-cifar10-inceptionv3-elastic-20210721-042807":1,"tf2-keras-cifar10-inceptionv3-elastic-20210721-042910":1,"tf2-keras-cifar10-inceptionv3-elastic-20210721-043127":1,"tf2-keras-cifar10-inceptionv3-elastic-20210721-043226":1,"tf2-keras-cifar10-resnet50-elastic-20210721-043058":1,"tf2-keras-cifar10-resnet50-elastic-20210721-043248":0,"tf2-keras-cifar10-resnet50-elastic-20210721-043501":0,"tf2-keras-cifar10-resnet50-elastic-20210721-043527":0,"tf2-keras-cifar10-vgg16-elastic-20210721-043029":1,"tf2-keras-cifar10-vgg16-elastic-20210721-043321":0,"tf2-keras-cifar10-vgg16-elastic-20210721-043423":0,"tf2-keras-transformer-elastic-20210721-042705":1,"tf2-keras-transformer-elastic-20210721-042732":1,"tf2-keras-transformer-elastic-20210721-042937":1,"tf2-keras-transformer-elastic-20210721-043203":1,"tf2-keras-transformer-elastic-20210721-043343":0,"tf2-keras-transformer-elastic-20210721-043555":0} "scheduler"="default"
I0721 16:58:07.392932   31979 scheduler.go:384]  "msg"="Trying to delete multiple training jobs"  "jobs"=[] "scheduler"="default"
I0721 16:58:07.393185   31979 scheduler.go:342]  "msg"="Trying to scale multiple training jobs"  "jobs"=[] "scheduler"="default"
I0721 16:58:07.393415   31979 scheduler.go:292]  "msg"="Trying to start multiple training jobs"  "jobs"=["tf2-keras-cifar10-inceptionv3-elastic-20210721-043226"] "scheduler"="default"
I0721 16:58:07.403194   31979 scheduler.go:342]  "msg"="Trying to scale multiple training jobs"  "jobs"=[] "scheduler"="default"
I0721 16:58:07.408001   31979 placement_manager.go:166]  "msg"="Started job placements adjustment"  "scheduler"="default"
I0721 16:58:07.408093   31979 placement_manager.go:192]  "msg"="Releasing slots"  "jobs"={"tf2-keras-cifar10-inceptionv3-elastic-20210721-042459":{},"tf2-keras-cifar10-inceptionv3-elastic-20210721-042550":{},"tf2-keras-cifar10-inceptionv3-elastic-20210721-042807":{},"tf2-keras-cifar10-inceptionv3-elastic-20210721-042910":{},"tf2-keras-cifar10-inceptionv3-elastic-20210721-043127":{},"tf2-keras-cifar10-resnet50-elastic-20210721-042844":{},"tf2-keras-cifar10-resnet50-elastic-20210721-043058":{},"tf2-keras-cifar10-vgg16-elastic-20210721-043029":{},"tf2-keras-transformer-elastic-20210721-042705":{},"tf2-keras-transformer-elastic-20210721-042732":{},"tf2-keras-transformer-elastic-20210721-042937":{},"tf2-keras-transformer-elastic-20210721-043203":{}} "nodes"={"gpu3":{},"gpu4":{},"gpu5":{}} "scheduler"="default"
I0721 16:58:07.408169   31979 placement_manager.go:250]  "msg"="Released slots"  "jobs"={"tf2-keras-cifar10-inceptionv3-elastic-20210721-042459":{},"tf2-keras-cifar10-inceptionv3-elastic-20210721-042550":{},"tf2-keras-cifar10-inceptionv3-elastic-20210721-042807":{},"tf2-keras-cifar10-inceptionv3-elastic-20210721-042910":{},"tf2-keras-cifar10-inceptionv3-elastic-20210721-043127":{},"tf2-keras-cifar10-resnet50-elastic-20210721-042844":{},"tf2-keras-cifar10-resnet50-elastic-20210721-043058":{},"tf2-keras-cifar10-vgg16-elastic-20210721-043029":{},"tf2-keras-transformer-elastic-20210721-042705":{},"tf2-keras-transformer-elastic-20210721-042732":{},"tf2-keras-transformer-elastic-20210721-042937":{},"tf2-keras-transformer-elastic-20210721-043203":{}} "nodes"={"gpu3":{},"gpu4":{},"gpu5":{}} "scheduler"="default"
I0721 16:58:07.408574   31979 placement_manager.go:305]  "msg"="Found best-fit"  "crossNode"=0 "nodes"=[{},{},{}] "requests"=[{},{},{},{},{},{},{},{},{},{},{},{},{},{},{},{},{},{},{},{},{},{},{},{},{},{},{},{},{},{},{},{},{},{},{},{},{},{}] "scheduler"="default"
I0721 16:58:07.408876   31979 placement_manager.go:339]  "msg"="nodeStates updated"  "new"={"gpu3":{},"gpu4":{},"gpu5":{}} "old"={"gpu3":{},"gpu4":{},"gpu5":{}} "scheduler"="default" "score"=6
I0721 16:58:07.409211   31979 placement_manager.go:387]  "msg"="jobStates updated"  "new"={"tf2-keras-cifar10-inceptionv3-elastic-20210721-042459":{},"tf2-keras-cifar10-inceptionv3-elastic-20210721-042550":{},"tf2-keras-cifar10-inceptionv3-elastic-20210721-042807":{},"tf2-keras-cifar10-inceptionv3-elastic-20210721-042910":{},"tf2-keras-cifar10-inceptionv3-elastic-20210721-043127":{},"tf2-keras-cifar10-inceptionv3-elastic-20210721-043226":{},"tf2-keras-cifar10-resnet50-elastic-20210721-043058":{},"tf2-keras-cifar10-vgg16-elastic-20210721-043029":{},"tf2-keras-transformer-elastic-20210721-042705":{},"tf2-keras-transformer-elastic-20210721-042732":{},"tf2-keras-transformer-elastic-20210721-042937":{},"tf2-keras-transformer-elastic-20210721-043203":{}} "old"={"tf2-keras-cifar10-inceptionv3-elastic-20210721-042459":{},"tf2-keras-cifar10-inceptionv3-elastic-20210721-042550":{},"tf2-keras-cifar10-inceptionv3-elastic-20210721-042807":{},"tf2-keras-cifar10-inceptionv3-elastic-20210721-042910":{},"tf2-keras-cifar10-inceptionv3-elastic-20210721-043127":{},"tf2-keras-cifar10-resnet50-elastic-20210721-042844":{},"tf2-keras-cifar10-resnet50-elastic-20210721-043058":{},"tf2-keras-cifar10-vgg16-elastic-20210721-043029":{},"tf2-keras-transformer-elastic-20210721-042705":{},"tf2-keras-transformer-elastic-20210721-042732":{},"tf2-keras-transformer-elastic-20210721-042937":{},"tf2-keras-transformer-elastic-20210721-043203":{}} "scheduler"="default"
I0721 16:58:07.409623   31979 placement_manager.go:434]  "msg"="podNodeName updated"  "launchersToDelete"=5 "new"={"tf2-keras-cifar10-inceptionv3-elastic-20210721-042459-worker-0":"gpu5","tf2-keras-cifar10-inceptionv3-elastic-20210721-042550-worker-0":"gpu4","tf2-keras-cifar10-inceptionv3-elastic-20210721-042807-worker-0":"gpu5","tf2-keras-cifar10-inceptionv3-elastic-20210721-042910-worker-0":"gpu4","tf2-keras-cifar10-inceptionv3-elastic-20210721-043127-worker-0":"gpu4","tf2-keras-cifar10-inceptionv3-elastic-20210721-043226-worker-0":"gpu3","tf2-keras-cifar10-resnet50-elastic-20210721-043058-worker-0":"gpu3","tf2-keras-cifar10-vgg16-elastic-20210721-043029-worker-0":"gpu5","tf2-keras-transformer-elastic-20210721-042705-worker-0":"gpu5","tf2-keras-transformer-elastic-20210721-042732-worker-0":"gpu4","tf2-keras-transformer-elastic-20210721-042937-worker-0":"gpu3","tf2-keras-transformer-elastic-20210721-043203-worker-0":"gpu3"} "old"={"tf2-keras-cifar10-inceptionv3-elastic-20210721-042459-worker-0":"gpu5","tf2-keras-cifar10-inceptionv3-elastic-20210721-042550-worker-0":"gpu4","tf2-keras-cifar10-inceptionv3-elastic-20210721-042807-worker-0":"gpu4","tf2-keras-cifar10-inceptionv3-elastic-20210721-042910-worker-0":"gpu3","tf2-keras-cifar10-inceptionv3-elastic-20210721-043127-worker-0":"gpu5","tf2-keras-cifar10-resnet50-elastic-20210721-042844-worker-0":"gpu4","tf2-keras-cifar10-resnet50-elastic-20210721-043058-worker-0":"gpu3","tf2-keras-cifar10-vgg16-elastic-20210721-043029-worker-0":"gpu5","tf2-keras-transformer-elastic-20210721-042705-worker-0":"gpu3","tf2-keras-transformer-elastic-20210721-042732-worker-0":"gpu4","tf2-keras-transformer-elastic-20210721-042937-worker-0":"gpu5","tf2-keras-transformer-elastic-20210721-043203-worker-0":"gpu3"} "scheduler"="default" "workersToDelete"=5
I0721 16:58:07.409966   31979 placement_manager.go:451]  "msg"="Deleting pod that need migration"  "podName"="tf2-keras-cifar10-inceptionv3-elastic-20210721-042910-worker-0" "scheduler"="default"
I0721 16:58:07.416376   31979 placement_manager.go:451]  "msg"="Deleting pod that need migration"  "podName"="tf2-keras-cifar10-inceptionv3-elastic-20210721-042910-launcher" "scheduler"="default"
I0721 16:58:07.421262   31979 placement_manager.go:451]  "msg"="Deleting pod that need migration"  "podName"="tf2-keras-cifar10-inceptionv3-elastic-20210721-043127-worker-0" "scheduler"="default"
I0721 16:58:07.433180   31979 placement_manager.go:451]  "msg"="Deleting pod that need migration"  "podName"="tf2-keras-cifar10-inceptionv3-elastic-20210721-043127-launcher" "scheduler"="default"
I0721 16:58:07.437973   31979 placement_manager.go:451]  "msg"="Deleting pod that need migration"  "podName"="tf2-keras-transformer-elastic-20210721-042937-worker-0" "scheduler"="default"
I0721 16:58:07.441226   31979 placement_manager.go:451]  "msg"="Deleting pod that need migration"  "podName"="tf2-keras-transformer-elastic-20210721-042937-launcher" "scheduler"="default"
I0721 16:58:07.445862   31979 placement_manager.go:451]  "msg"="Deleting pod that need migration"  "podName"="tf2-keras-transformer-elastic-20210721-042705-worker-0" "scheduler"="default"
I0721 16:58:07.449234   31979 placement_manager.go:451]  "msg"="Deleting pod that need migration"  "podName"="tf2-keras-transformer-elastic-20210721-042705-launcher" "scheduler"="default"
I0721 16:58:07.453296   31979 placement_manager.go:451]  "msg"="Deleting pod that need migration"  "podName"="tf2-keras-cifar10-inceptionv3-elastic-20210721-042807-worker-0" "scheduler"="default"
I0721 16:58:07.457363   31979 placement_manager.go:147]  "msg"="Adding toleration to pod"  "podName"="tf2-keras-cifar10-inceptionv3-elastic-20210721-043226-worker-0" "scheduler"="default" "toleration"={"key":"celeste/hostname","operator":"Equal","value":"gpu3","effect":"NoExecute"}
I0721 16:58:07.460004   31979 placement_manager.go:451]  "msg"="Deleting pod that need migration"  "podName"="tf2-keras-cifar10-inceptionv3-elastic-20210721-042807-launcher" "scheduler"="default"
I0721 16:58:07.616416   31979 placement_manager.go:183]  "msg"="Finished job placements adjustment"  "scheduler"="default"
I0721 16:58:07.616683   31979 scheduler.go:182]  "msg"="Finished resched"  "scheduler"="default"
I0721 16:58:08.217694   31979 placement_manager.go:147]  "msg"="Adding toleration to pod"  "podName"="tf2-keras-cifar10-inceptionv3-elastic-20210721-043226-launcher" "scheduler"="default" "toleration"={"key":"celeste/hostname","operator":"Exists","effect":"NoExecute"}
I0721 16:58:15.825814   31979 placement_manager.go:147]  "msg"="Adding toleration to pod"  "podName"="tf2-keras-transformer-elastic-20210721-042937-worker-0" "scheduler"="default" "toleration"={"key":"celeste/hostname","operator":"Equal","value":"gpu3","effect":"NoExecute"}
I0721 16:58:15.870535   31979 placement_manager.go:147]  "msg"="Adding toleration to pod"  "podName"="tf2-keras-cifar10-inceptionv3-elastic-20210721-043127-worker-0" "scheduler"="default" "toleration"={"key":"celeste/hostname","operator":"Equal","value":"gpu4","effect":"NoExecute"}
I0721 16:58:15.878102   31979 placement_manager.go:147]  "msg"="Adding toleration to pod"  "podName"="tf2-keras-cifar10-inceptionv3-elastic-20210721-042910-launcher" "scheduler"="default" "toleration"={"key":"celeste/hostname","operator":"Exists","effect":"NoExecute"}
I0721 16:58:16.782432   31979 placement_manager.go:147]  "msg"="Adding toleration to pod"  "podName"="tf2-keras-transformer-elastic-20210721-042937-launcher" "scheduler"="default" "toleration"={"key":"celeste/hostname","operator":"Exists","effect":"NoExecute"}
I0721 16:58:20.307891   31979 placement_manager.go:147]  "msg"="Adding toleration to pod"  "podName"="tf2-keras-cifar10-inceptionv3-elastic-20210721-042910-worker-0" "scheduler"="default" "toleration"={"key":"celeste/hostname","operator":"Equal","value":"gpu4","effect":"NoExecute"}
I0721 16:58:20.707751   31979 placement_manager.go:147]  "msg"="Adding toleration to pod"  "podName"="tf2-keras-transformer-elastic-20210721-042705-worker-0" "scheduler"="default" "toleration"={"key":"celeste/hostname","operator":"Equal","value":"gpu5","effect":"NoExecute"}
I0721 16:58:21.501641   31979 placement_manager.go:147]  "msg"="Adding toleration to pod"  "podName"="tf2-keras-transformer-elastic-20210721-042705-launcher" "scheduler"="default" "toleration"={"key":"celeste/hostname","operator":"Exists","effect":"NoExecute"}
I0721 16:58:24.597213   31979 placement_manager.go:147]  "msg"="Adding toleration to pod"  "podName"="tf2-keras-cifar10-inceptionv3-elastic-20210721-042807-launcher" "scheduler"="default" "toleration"={"key":"celeste/hostname","operator":"Exists","effect":"NoExecute"}
I0721 16:58:24.642800   31979 placement_manager.go:147]  "msg"="Adding toleration to pod"  "podName"="tf2-keras-cifar10-inceptionv3-elastic-20210721-042807-worker-0" "scheduler"="default" "toleration"={"key":"celeste/hostname","operator":"Equal","value":"gpu5","effect":"NoExecute"}
I0721 16:58:25.792499   31979 placement_manager.go:147]  "msg"="Adding toleration to pod"  "podName"="tf2-keras-cifar10-inceptionv3-elastic-20210721-043127-launcher" "scheduler"="default" "toleration"={"key":"celeste/hostname","operator":"Exists","effect":"NoExecute"}
I0721 17:12:39.349127   31979 scheduler.go:474]  "msg"="Training job completed"  "elaspedTotalSeconds"=2703.216593015 "gpuTotalSeconds"=2620.519912464 "job"="tf2-keras-transformer-elastic-20210721-042732" "ranTotalSeconds"=2620.519912464 "scheduler"="default" "waitedTotalSeconds"=82.696680551
I0721 17:12:39.349265   31979 scheduler.go:135]  "msg"="Received resched event, may be blocked because of rate limit"  "blockedUntil"="2021-07-21T17:00:07.616891909+08:00" "lastResched"="2021-07-21T16:58:07.616891909+08:00" "received"="2021-07-21T17:12:39.34916023+08:00" "scheduler"="default"
I0721 17:12:39.349682   31979 scheduler.go:159]  "msg"="Started resched"  "scheduler"="default"
I0721 17:12:39.349749   31979 scheduler.go:193]  "msg"="Updating all jobs info"  "scheduler"="default"
I0721 17:12:39.361742   31979 elastic_fifo.go:73]  "msg"="Finished scheduling"  "algorithm"="ElasticFIFO" "freeGpu"=0 "result"={"tf2-keras-cifar10-inceptionv3-elastic-20210721-042459":1,"tf2-keras-cifar10-inceptionv3-elastic-20210721-042550":1,"tf2-keras-cifar10-inceptionv3-elastic-20210721-042807":1,"tf2-keras-cifar10-inceptionv3-elastic-20210721-042910":1,"tf2-keras-cifar10-inceptionv3-elastic-20210721-043127":1,"tf2-keras-cifar10-inceptionv3-elastic-20210721-043226":1,"tf2-keras-cifar10-resnet50-elastic-20210721-043058":1,"tf2-keras-cifar10-resnet50-elastic-20210721-043248":1,"tf2-keras-cifar10-resnet50-elastic-20210721-043501":0,"tf2-keras-cifar10-resnet50-elastic-20210721-043527":0,"tf2-keras-cifar10-vgg16-elastic-20210721-043029":1,"tf2-keras-cifar10-vgg16-elastic-20210721-043321":0,"tf2-keras-cifar10-vgg16-elastic-20210721-043423":0,"tf2-keras-transformer-elastic-20210721-042705":1,"tf2-keras-transformer-elastic-20210721-042937":1,"tf2-keras-transformer-elastic-20210721-043203":1,"tf2-keras-transformer-elastic-20210721-043343":0,"tf2-keras-transformer-elastic-20210721-043555":0} "scheduler"="default"
I0721 17:12:39.362115   31979 scheduler.go:384]  "msg"="Trying to delete multiple training jobs"  "jobs"=[] "scheduler"="default"
I0721 17:12:39.362335   31979 scheduler.go:342]  "msg"="Trying to scale multiple training jobs"  "jobs"=[] "scheduler"="default"
I0721 17:12:39.362550   31979 scheduler.go:292]  "msg"="Trying to start multiple training jobs"  "jobs"=["tf2-keras-cifar10-resnet50-elastic-20210721-043248"] "scheduler"="default"
I0721 17:12:39.371901   31979 scheduler.go:342]  "msg"="Trying to scale multiple training jobs"  "jobs"=[] "scheduler"="default"
I0721 17:12:39.375615   31979 placement_manager.go:166]  "msg"="Started job placements adjustment"  "scheduler"="default"
I0721 17:12:39.375699   31979 placement_manager.go:192]  "msg"="Releasing slots"  "jobs"={"tf2-keras-cifar10-inceptionv3-elastic-20210721-042459":{},"tf2-keras-cifar10-inceptionv3-elastic-20210721-042550":{},"tf2-keras-cifar10-inceptionv3-elastic-20210721-042807":{},"tf2-keras-cifar10-inceptionv3-elastic-20210721-042910":{},"tf2-keras-cifar10-inceptionv3-elastic-20210721-043127":{},"tf2-keras-cifar10-inceptionv3-elastic-20210721-043226":{},"tf2-keras-cifar10-resnet50-elastic-20210721-043058":{},"tf2-keras-cifar10-vgg16-elastic-20210721-043029":{},"tf2-keras-transformer-elastic-20210721-042705":{},"tf2-keras-transformer-elastic-20210721-042732":{},"tf2-keras-transformer-elastic-20210721-042937":{},"tf2-keras-transformer-elastic-20210721-043203":{}} "nodes"={"gpu3":{},"gpu4":{},"gpu5":{}} "scheduler"="default"
I0721 17:12:39.375784   31979 placement_manager.go:250]  "msg"="Released slots"  "jobs"={"tf2-keras-cifar10-inceptionv3-elastic-20210721-042459":{},"tf2-keras-cifar10-inceptionv3-elastic-20210721-042550":{},"tf2-keras-cifar10-inceptionv3-elastic-20210721-042807":{},"tf2-keras-cifar10-inceptionv3-elastic-20210721-042910":{},"tf2-keras-cifar10-inceptionv3-elastic-20210721-043127":{},"tf2-keras-cifar10-inceptionv3-elastic-20210721-043226":{},"tf2-keras-cifar10-resnet50-elastic-20210721-043058":{},"tf2-keras-cifar10-vgg16-elastic-20210721-043029":{},"tf2-keras-transformer-elastic-20210721-042705":{},"tf2-keras-transformer-elastic-20210721-042732":{},"tf2-keras-transformer-elastic-20210721-042937":{},"tf2-keras-transformer-elastic-20210721-043203":{}} "nodes"={"gpu3":{},"gpu4":{},"gpu5":{}} "scheduler"="default"
I0721 17:12:39.376295   31979 placement_manager.go:305]  "msg"="Found best-fit"  "crossNode"=0 "nodes"=[{},{},{}] "requests"=[{},{},{},{},{},{},{},{},{},{},{},{},{},{},{},{},{},{},{},{},{},{},{},{},{},{},{},{},{},{},{},{},{},{},{},{}] "scheduler"="default"
I0721 17:12:39.376618   31979 placement_manager.go:339]  "msg"="nodeStates updated"  "new"={"gpu3":{},"gpu4":{},"gpu5":{}} "old"={"gpu3":{},"gpu4":{},"gpu5":{}} "scheduler"="default" "score"=5
I0721 17:12:39.377006   31979 placement_manager.go:387]  "msg"="jobStates updated"  "new"={"tf2-keras-cifar10-inceptionv3-elastic-20210721-042459":{},"tf2-keras-cifar10-inceptionv3-elastic-20210721-042550":{},"tf2-keras-cifar10-inceptionv3-elastic-20210721-042807":{},"tf2-keras-cifar10-inceptionv3-elastic-20210721-042910":{},"tf2-keras-cifar10-inceptionv3-elastic-20210721-043127":{},"tf2-keras-cifar10-inceptionv3-elastic-20210721-043226":{},"tf2-keras-cifar10-resnet50-elastic-20210721-043058":{},"tf2-keras-cifar10-resnet50-elastic-20210721-043248":{},"tf2-keras-cifar10-vgg16-elastic-20210721-043029":{},"tf2-keras-transformer-elastic-20210721-042705":{},"tf2-keras-transformer-elastic-20210721-042937":{},"tf2-keras-transformer-elastic-20210721-043203":{}} "old"={"tf2-keras-cifar10-inceptionv3-elastic-20210721-042459":{},"tf2-keras-cifar10-inceptionv3-elastic-20210721-042550":{},"tf2-keras-cifar10-inceptionv3-elastic-20210721-042807":{},"tf2-keras-cifar10-inceptionv3-elastic-20210721-042910":{},"tf2-keras-cifar10-inceptionv3-elastic-20210721-043127":{},"tf2-keras-cifar10-inceptionv3-elastic-20210721-043226":{},"tf2-keras-cifar10-resnet50-elastic-20210721-043058":{},"tf2-keras-cifar10-vgg16-elastic-20210721-043029":{},"tf2-keras-transformer-elastic-20210721-042705":{},"tf2-keras-transformer-elastic-20210721-042732":{},"tf2-keras-transformer-elastic-20210721-042937":{},"tf2-keras-transformer-elastic-20210721-043203":{}} "scheduler"="default"
I0721 17:12:39.377550   31979 placement_manager.go:434]  "msg"="podNodeName updated"  "launchersToDelete"=6 "new"={"tf2-keras-cifar10-inceptionv3-elastic-20210721-042459-worker-0":"gpu5","tf2-keras-cifar10-inceptionv3-elastic-20210721-042550-worker-0":"gpu3","tf2-keras-cifar10-inceptionv3-elastic-20210721-042807-worker-0":"gpu4","tf2-keras-cifar10-inceptionv3-elastic-20210721-042910-worker-0":"gpu4","tf2-keras-cifar10-inceptionv3-elastic-20210721-043127-worker-0":"gpu5","tf2-keras-cifar10-inceptionv3-elastic-20210721-043226-worker-0":"gpu5","tf2-keras-cifar10-resnet50-elastic-20210721-043058-worker-0":"gpu3","tf2-keras-cifar10-resnet50-elastic-20210721-043248-worker-0":"gpu4","tf2-keras-cifar10-vgg16-elastic-20210721-043029-worker-0":"gpu3","tf2-keras-transformer-elastic-20210721-042705-worker-0":"gpu5","tf2-keras-transformer-elastic-20210721-042937-worker-0":"gpu4","tf2-keras-transformer-elastic-20210721-043203-worker-0":"gpu3"} "old"={"tf2-keras-cifar10-inceptionv3-elastic-20210721-042459-worker-0":"gpu5","tf2-keras-cifar10-inceptionv3-elastic-20210721-042550-worker-0":"gpu4","tf2-keras-cifar10-inceptionv3-elastic-20210721-042807-worker-0":"gpu5","tf2-keras-cifar10-inceptionv3-elastic-20210721-042910-worker-0":"gpu4","tf2-keras-cifar10-inceptionv3-elastic-20210721-043127-worker-0":"gpu4","tf2-keras-cifar10-inceptionv3-elastic-20210721-043226-worker-0":"gpu3","tf2-keras-cifar10-resnet50-elastic-20210721-043058-worker-0":"gpu3","tf2-keras-cifar10-vgg16-elastic-20210721-043029-worker-0":"gpu5","tf2-keras-transformer-elastic-20210721-042705-worker-0":"gpu5","tf2-keras-transformer-elastic-20210721-042732-worker-0":"gpu4","tf2-keras-transformer-elastic-20210721-042937-worker-0":"gpu3","tf2-keras-transformer-elastic-20210721-043203-worker-0":"gpu3"} "scheduler"="default" "workersToDelete"=6
I0721 17:12:39.377924   31979 placement_manager.go:451]  "msg"="Deleting pod that need migration"  "podName"="tf2-keras-cifar10-inceptionv3-elastic-20210721-042550-worker-0" "scheduler"="default"
I0721 17:12:39.381763   31979 placement_manager.go:451]  "msg"="Deleting pod that need migration"  "podName"="tf2-keras-cifar10-inceptionv3-elastic-20210721-042550-launcher" "scheduler"="default"
I0721 17:12:39.386184   31979 placement_manager.go:451]  "msg"="Deleting pod that need migration"  "podName"="tf2-keras-cifar10-vgg16-elastic-20210721-043029-worker-0" "scheduler"="default"
I0721 17:12:39.389770   31979 placement_manager.go:451]  "msg"="Deleting pod that need migration"  "podName"="tf2-keras-cifar10-vgg16-elastic-20210721-043029-launcher" "scheduler"="default"
I0721 17:12:39.393763   31979 placement_manager.go:451]  "msg"="Deleting pod that need migration"  "podName"="tf2-keras-cifar10-inceptionv3-elastic-20210721-043127-worker-0" "scheduler"="default"
I0721 17:12:39.397245   31979 placement_manager.go:451]  "msg"="Deleting pod that need migration"  "podName"="tf2-keras-cifar10-inceptionv3-elastic-20210721-043127-launcher" "scheduler"="default"
I0721 17:12:39.401282   31979 placement_manager.go:451]  "msg"="Deleting pod that need migration"  "podName"="tf2-keras-cifar10-inceptionv3-elastic-20210721-043226-worker-0" "scheduler"="default"
I0721 17:12:39.404778   31979 placement_manager.go:451]  "msg"="Deleting pod that need migration"  "podName"="tf2-keras-cifar10-inceptionv3-elastic-20210721-043226-launcher" "scheduler"="default"
I0721 17:12:39.408913   31979 placement_manager.go:451]  "msg"="Deleting pod that need migration"  "podName"="tf2-keras-cifar10-inceptionv3-elastic-20210721-042807-worker-0" "scheduler"="default"
I0721 17:12:39.412390   31979 placement_manager.go:451]  "msg"="Deleting pod that need migration"  "podName"="tf2-keras-cifar10-inceptionv3-elastic-20210721-042807-launcher" "scheduler"="default"
I0721 17:12:39.417259   31979 placement_manager.go:451]  "msg"="Deleting pod that need migration"  "podName"="tf2-keras-transformer-elastic-20210721-042937-worker-0" "scheduler"="default"
I0721 17:12:39.583190   31979 placement_manager.go:451]  "msg"="Deleting pod that need migration"  "podName"="tf2-keras-transformer-elastic-20210721-042937-launcher" "scheduler"="default"
I0721 17:12:39.739058   31979 placement_manager.go:147]  "msg"="Adding toleration to pod"  "podName"="tf2-keras-cifar10-resnet50-elastic-20210721-043248-worker-0" "scheduler"="default" "toleration"={"key":"celeste/hostname","operator":"Equal","value":"gpu4","effect":"NoExecute"}
I0721 17:12:39.783762   31979 placement_manager.go:183]  "msg"="Finished job placements adjustment"  "scheduler"="default"
I0721 17:12:39.784110   31979 scheduler.go:182]  "msg"="Finished resched"  "scheduler"="default"
I0721 17:12:40.185709   31979 placement_manager.go:147]  "msg"="Adding toleration to pod"  "podName"="tf2-keras-cifar10-resnet50-elastic-20210721-043248-launcher" "scheduler"="default" "toleration"={"key":"celeste/hostname","operator":"Exists","effect":"NoExecute"}
I0721 17:12:40.573997   31979 scheduler.go:474]  "msg"="Training job completed"  "elaspedTotalSeconds"=2582.580195754 "gpuTotalSeconds"=2505.252181069 "job"="tf2-keras-transformer-elastic-20210721-042937" "ranTotalSeconds"=2505.252181069 "scheduler"="default" "waitedTotalSeconds"=77.328014685
I0721 17:12:40.574117   31979 scheduler.go:135]  "msg"="Received resched event, may be blocked because of rate limit"  "blockedUntil"="2021-07-21T17:14:39.784368886+08:00" "lastResched"="2021-07-21T17:12:39.784368886+08:00" "received"="2021-07-21T17:12:40.574033546+08:00" "scheduler"="default"
I0721 17:12:46.515787   31979 placement_manager.go:147]  "msg"="Adding toleration to pod"  "podName"="tf2-keras-cifar10-vgg16-elastic-20210721-043029-worker-0" "scheduler"="default" "toleration"={"key":"celeste/hostname","operator":"Equal","value":"gpu3","effect":"NoExecute"}
I0721 17:12:46.552536   31979 placement_manager.go:147]  "msg"="Adding toleration to pod"  "podName"="tf2-keras-cifar10-inceptionv3-elastic-20210721-042807-worker-0" "scheduler"="default" "toleration"={"key":"celeste/hostname","operator":"Equal","value":"gpu4","effect":"NoExecute"}
I0721 17:12:46.562703   31979 placement_manager.go:147]  "msg"="Adding toleration to pod"  "podName"="tf2-keras-cifar10-vgg16-elastic-20210721-043029-launcher" "scheduler"="default" "toleration"={"key":"celeste/hostname","operator":"Exists","effect":"NoExecute"}
I0721 17:12:49.288153   31979 placement_manager.go:147]  "msg"="Adding toleration to pod"  "podName"="tf2-keras-cifar10-inceptionv3-elastic-20210721-042807-launcher" "scheduler"="default" "toleration"={"key":"celeste/hostname","operator":"Exists","effect":"NoExecute"}
I0721 17:12:55.622864   31979 placement_manager.go:147]  "msg"="Adding toleration to pod"  "podName"="tf2-keras-cifar10-inceptionv3-elastic-20210721-042550-launcher" "scheduler"="default" "toleration"={"key":"celeste/hostname","operator":"Exists","effect":"NoExecute"}
I0721 17:12:56.811144   31979 placement_manager.go:147]  "msg"="Adding toleration to pod"  "podName"="tf2-keras-cifar10-inceptionv3-elastic-20210721-043127-launcher" "scheduler"="default" "toleration"={"key":"celeste/hostname","operator":"Exists","effect":"NoExecute"}
I0721 17:12:59.223121   31979 placement_manager.go:147]  "msg"="Adding toleration to pod"  "podName"="tf2-keras-cifar10-inceptionv3-elastic-20210721-043127-worker-0" "scheduler"="default" "toleration"={"key":"celeste/hostname","operator":"Equal","value":"gpu5","effect":"NoExecute"}
I0721 17:12:59.271779   31979 placement_manager.go:147]  "msg"="Adding toleration to pod"  "podName"="tf2-keras-cifar10-inceptionv3-elastic-20210721-043226-launcher" "scheduler"="default" "toleration"={"key":"celeste/hostname","operator":"Exists","effect":"NoExecute"}
I0721 17:12:59.308104   31979 placement_manager.go:147]  "msg"="Adding toleration to pod"  "podName"="tf2-keras-cifar10-inceptionv3-elastic-20210721-043226-worker-0" "scheduler"="default" "toleration"={"key":"celeste/hostname","operator":"Equal","value":"gpu5","effect":"NoExecute"}
I0721 17:13:00.022428   31979 placement_manager.go:147]  "msg"="Adding toleration to pod"  "podName"="tf2-keras-cifar10-inceptionv3-elastic-20210721-042550-worker-0" "scheduler"="default" "toleration"={"key":"celeste/hostname","operator":"Equal","value":"gpu3","effect":"NoExecute"}
I0721 17:13:42.327376   31979 scheduler.go:474]  "msg"="Training job completed"  "elaspedTotalSeconds"=2795.095803645 "gpuTotalSeconds"=2685.521800709 "job"="tf2-keras-transformer-elastic-20210721-042705" "ranTotalSeconds"=2685.521800709 "scheduler"="default" "waitedTotalSeconds"=109.574002936
I0721 17:14:06.774396   31979 scheduler.go:474]  "msg"="Training job completed"  "elaspedTotalSeconds"=2615.725962618 "gpuTotalSeconds"=1485.053185987 "job"="tf2-keras-cifar10-vgg16-elastic-20210721-043029" "ranTotalSeconds"=1485.053185987 "scheduler"="default" "waitedTotalSeconds"=1130.672776631
I0721 17:14:39.784417   31979 scheduler.go:159]  "msg"="Started resched"  "scheduler"="default"
I0721 17:14:39.784489   31979 scheduler.go:193]  "msg"="Updating all jobs info"  "scheduler"="default"
I0721 17:14:39.793337   31979 elastic_fifo.go:73]  "msg"="Finished scheduling"  "algorithm"="ElasticFIFO" "freeGpu"=0 "result"={"tf2-keras-cifar10-inceptionv3-elastic-20210721-042459":1,"tf2-keras-cifar10-inceptionv3-elastic-20210721-042550":1,"tf2-keras-cifar10-inceptionv3-elastic-20210721-042807":1,"tf2-keras-cifar10-inceptionv3-elastic-20210721-042910":1,"tf2-keras-cifar10-inceptionv3-elastic-20210721-043127":1,"tf2-keras-cifar10-inceptionv3-elastic-20210721-043226":1,"tf2-keras-cifar10-resnet50-elastic-20210721-043058":1,"tf2-keras-cifar10-resnet50-elastic-20210721-043248":1,"tf2-keras-cifar10-resnet50-elastic-20210721-043501":0,"tf2-keras-cifar10-resnet50-elastic-20210721-043527":0,"tf2-keras-cifar10-vgg16-elastic-20210721-043321":1,"tf2-keras-cifar10-vgg16-elastic-20210721-043423":1,"tf2-keras-transformer-elastic-20210721-043203":1,"tf2-keras-transformer-elastic-20210721-043343":1,"tf2-keras-transformer-elastic-20210721-043555":0} "scheduler"="default"
I0721 17:14:39.793607   31979 scheduler.go:384]  "msg"="Trying to delete multiple training jobs"  "jobs"=[] "scheduler"="default"
I0721 17:14:39.793880   31979 scheduler.go:342]  "msg"="Trying to scale multiple training jobs"  "jobs"=[] "scheduler"="default"
I0721 17:14:39.794646   31979 scheduler.go:292]  "msg"="Trying to start multiple training jobs"  "jobs"=["tf2-keras-transformer-elastic-20210721-043343","tf2-keras-cifar10-vgg16-elastic-20210721-043321","tf2-keras-cifar10-vgg16-elastic-20210721-043423"] "scheduler"="default"
I0721 17:14:39.827495   31979 scheduler.go:342]  "msg"="Trying to scale multiple training jobs"  "jobs"=[] "scheduler"="default"
I0721 17:14:39.832156   31979 placement_manager.go:166]  "msg"="Started job placements adjustment"  "scheduler"="default"
I0721 17:14:39.832236   31979 placement_manager.go:192]  "msg"="Releasing slots"  "jobs"={"tf2-keras-cifar10-inceptionv3-elastic-20210721-042459":{},"tf2-keras-cifar10-inceptionv3-elastic-20210721-042550":{},"tf2-keras-cifar10-inceptionv3-elastic-20210721-042807":{},"tf2-keras-cifar10-inceptionv3-elastic-20210721-042910":{},"tf2-keras-cifar10-inceptionv3-elastic-20210721-043127":{},"tf2-keras-cifar10-inceptionv3-elastic-20210721-043226":{},"tf2-keras-cifar10-resnet50-elastic-20210721-043058":{},"tf2-keras-cifar10-resnet50-elastic-20210721-043248":{},"tf2-keras-cifar10-vgg16-elastic-20210721-043029":{},"tf2-keras-transformer-elastic-20210721-042705":{},"tf2-keras-transformer-elastic-20210721-042937":{},"tf2-keras-transformer-elastic-20210721-043203":{}} "nodes"={"gpu3":{},"gpu4":{},"gpu5":{}} "scheduler"="default"
I0721 17:14:39.832328   31979 placement_manager.go:250]  "msg"="Released slots"  "jobs"={"tf2-keras-cifar10-inceptionv3-elastic-20210721-042459":{},"tf2-keras-cifar10-inceptionv3-elastic-20210721-042550":{},"tf2-keras-cifar10-inceptionv3-elastic-20210721-042807":{},"tf2-keras-cifar10-inceptionv3-elastic-20210721-042910":{},"tf2-keras-cifar10-inceptionv3-elastic-20210721-043127":{},"tf2-keras-cifar10-inceptionv3-elastic-20210721-043226":{},"tf2-keras-cifar10-resnet50-elastic-20210721-043058":{},"tf2-keras-cifar10-resnet50-elastic-20210721-043248":{},"tf2-keras-cifar10-vgg16-elastic-20210721-043029":{},"tf2-keras-transformer-elastic-20210721-042705":{},"tf2-keras-transformer-elastic-20210721-042937":{},"tf2-keras-transformer-elastic-20210721-043203":{}} "nodes"={"gpu3":{},"gpu4":{},"gpu5":{}} "scheduler"="default"
I0721 17:14:39.832679   31979 placement_manager.go:305]  "msg"="Found best-fit"  "crossNode"=0 "nodes"=[{},{},{}] "requests"=[{},{},{},{},{},{},{},{},{},{},{},{},{},{},{},{},{},{},{},{},{},{},{},{},{},{},{},{},{},{}] "scheduler"="default"
I0721 17:14:39.832981   31979 placement_manager.go:339]  "msg"="nodeStates updated"  "new"={"gpu3":{},"gpu4":{},"gpu5":{}} "old"={"gpu3":{},"gpu4":{},"gpu5":{}} "scheduler"="default" "score"=6
I0721 17:14:39.833286   31979 placement_manager.go:387]  "msg"="jobStates updated"  "new"={"tf2-keras-cifar10-inceptionv3-elastic-20210721-042459":{},"tf2-keras-cifar10-inceptionv3-elastic-20210721-042550":{},"tf2-keras-cifar10-inceptionv3-elastic-20210721-042807":{},"tf2-keras-cifar10-inceptionv3-elastic-20210721-042910":{},"tf2-keras-cifar10-inceptionv3-elastic-20210721-043127":{},"tf2-keras-cifar10-inceptionv3-elastic-20210721-043226":{},"tf2-keras-cifar10-resnet50-elastic-20210721-043058":{},"tf2-keras-cifar10-resnet50-elastic-20210721-043248":{},"tf2-keras-cifar10-vgg16-elastic-20210721-043321":{},"tf2-keras-cifar10-vgg16-elastic-20210721-043423":{},"tf2-keras-transformer-elastic-20210721-043203":{},"tf2-keras-transformer-elastic-20210721-043343":{}} "old"={"tf2-keras-cifar10-inceptionv3-elastic-20210721-042459":{},"tf2-keras-cifar10-inceptionv3-elastic-20210721-042550":{},"tf2-keras-cifar10-inceptionv3-elastic-20210721-042807":{},"tf2-keras-cifar10-inceptionv3-elastic-20210721-042910":{},"tf2-keras-cifar10-inceptionv3-elastic-20210721-043127":{},"tf2-keras-cifar10-inceptionv3-elastic-20210721-043226":{},"tf2-keras-cifar10-resnet50-elastic-20210721-043058":{},"tf2-keras-cifar10-resnet50-elastic-20210721-043248":{},"tf2-keras-cifar10-vgg16-elastic-20210721-043029":{},"tf2-keras-transformer-elastic-20210721-042705":{},"tf2-keras-transformer-elastic-20210721-042937":{},"tf2-keras-transformer-elastic-20210721-043203":{}} "scheduler"="default"
I0721 17:14:39.833687   31979 placement_manager.go:434]  "msg"="podNodeName updated"  "launchersToDelete"=3 "new"={"tf2-keras-cifar10-inceptionv3-elastic-20210721-042459-worker-0":"gpu3","tf2-keras-cifar10-inceptionv3-elastic-20210721-042550-worker-0":"gpu4","tf2-keras-cifar10-inceptionv3-elastic-20210721-042807-worker-0":"gpu4","tf2-keras-cifar10-inceptionv3-elastic-20210721-042910-worker-0":"gpu3","tf2-keras-cifar10-inceptionv3-elastic-20210721-043127-worker-0":"gpu5","tf2-keras-cifar10-inceptionv3-elastic-20210721-043226-worker-0":"gpu5","tf2-keras-cifar10-resnet50-elastic-20210721-043058-worker-0":"gpu3","tf2-keras-cifar10-resnet50-elastic-20210721-043248-worker-0":"gpu4","tf2-keras-cifar10-vgg16-elastic-20210721-043321-worker-0":"gpu4","tf2-keras-cifar10-vgg16-elastic-20210721-043423-worker-0":"gpu5","tf2-keras-transformer-elastic-20210721-043203-worker-0":"gpu3","tf2-keras-transformer-elastic-20210721-043343-worker-0":"gpu5"} "old"={"tf2-keras-cifar10-inceptionv3-elastic-20210721-042459-worker-0":"gpu5","tf2-keras-cifar10-inceptionv3-elastic-20210721-042550-worker-0":"gpu3","tf2-keras-cifar10-inceptionv3-elastic-20210721-042807-worker-0":"gpu4","tf2-keras-cifar10-inceptionv3-elastic-20210721-042910-worker-0":"gpu4","tf2-keras-cifar10-inceptionv3-elastic-20210721-043127-worker-0":"gpu5","tf2-keras-cifar10-inceptionv3-elastic-20210721-043226-worker-0":"gpu5","tf2-keras-cifar10-resnet50-elastic-20210721-043058-worker-0":"gpu3","tf2-keras-cifar10-resnet50-elastic-20210721-043248-worker-0":"gpu4","tf2-keras-cifar10-vgg16-elastic-20210721-043029-worker-0":"gpu3","tf2-keras-transformer-elastic-20210721-042705-worker-0":"gpu5","tf2-keras-transformer-elastic-20210721-042937-worker-0":"gpu4","tf2-keras-transformer-elastic-20210721-043203-worker-0":"gpu3"} "scheduler"="default" "workersToDelete"=3
I0721 17:14:39.834006   31979 placement_manager.go:451]  "msg"="Deleting pod that need migration"  "podName"="tf2-keras-cifar10-inceptionv3-elastic-20210721-042459-worker-0" "scheduler"="default"
I0721 17:14:39.845717   31979 placement_manager.go:451]  "msg"="Deleting pod that need migration"  "podName"="tf2-keras-cifar10-inceptionv3-elastic-20210721-042459-launcher" "scheduler"="default"
I0721 17:14:39.850490   31979 placement_manager.go:451]  "msg"="Deleting pod that need migration"  "podName"="tf2-keras-cifar10-inceptionv3-elastic-20210721-042910-worker-0" "scheduler"="default"
I0721 17:14:39.858674   31979 placement_manager.go:451]  "msg"="Deleting pod that need migration"  "podName"="tf2-keras-cifar10-inceptionv3-elastic-20210721-042910-launcher" "scheduler"="default"
I0721 17:14:39.863457   31979 placement_manager.go:451]  "msg"="Deleting pod that need migration"  "podName"="tf2-keras-cifar10-inceptionv3-elastic-20210721-042550-worker-0" "scheduler"="default"
I0721 17:14:39.866848   31979 placement_manager.go:451]  "msg"="Deleting pod that need migration"  "podName"="tf2-keras-cifar10-inceptionv3-elastic-20210721-042550-launcher" "scheduler"="default"
I0721 17:14:39.871573   31979 placement_manager.go:183]  "msg"="Finished job placements adjustment"  "scheduler"="default"
I0721 17:14:39.871892   31979 scheduler.go:182]  "msg"="Finished resched"  "scheduler"="default"
I0721 17:14:40.217868   31979 placement_manager.go:147]  "msg"="Adding toleration to pod"  "podName"="tf2-keras-cifar10-vgg16-elastic-20210721-043321-worker-0" "scheduler"="default" "toleration"={"key":"celeste/hostname","operator":"Equal","value":"gpu4","effect":"NoExecute"}
I0721 17:14:40.415769   31979 placement_manager.go:147]  "msg"="Adding toleration to pod"  "podName"="tf2-keras-transformer-elastic-20210721-043343-worker-0" "scheduler"="default" "toleration"={"key":"celeste/hostname","operator":"Equal","value":"gpu5","effect":"NoExecute"}
I0721 17:14:40.640757   31979 placement_manager.go:147]  "msg"="Adding toleration to pod"  "podName"="tf2-keras-cifar10-vgg16-elastic-20210721-043321-launcher" "scheduler"="default" "toleration"={"key":"celeste/hostname","operator":"Exists","effect":"NoExecute"}
I0721 17:14:41.044013   31979 placement_manager.go:147]  "msg"="Adding toleration to pod"  "podName"="tf2-keras-transformer-elastic-20210721-043343-launcher" "scheduler"="default" "toleration"={"key":"celeste/hostname","operator":"Exists","effect":"NoExecute"}
I0721 17:14:42.418583   31979 placement_manager.go:147]  "msg"="Adding toleration to pod"  "podName"="tf2-keras-cifar10-vgg16-elastic-20210721-043423-worker-0" "scheduler"="default" "toleration"={"key":"celeste/hostname","operator":"Equal","value":"gpu5","effect":"NoExecute"}
I0721 17:14:42.816518   31979 placement_manager.go:147]  "msg"="Adding toleration to pod"  "podName"="tf2-keras-cifar10-vgg16-elastic-20210721-043423-launcher" "scheduler"="default" "toleration"={"key":"celeste/hostname","operator":"Exists","effect":"NoExecute"}
I0721 17:14:47.480025   31979 placement_manager.go:147]  "msg"="Adding toleration to pod"  "podName"="tf2-keras-cifar10-inceptionv3-elastic-20210721-042550-launcher" "scheduler"="default" "toleration"={"key":"celeste/hostname","operator":"Exists","effect":"NoExecute"}
I0721 17:14:47.901105   31979 placement_manager.go:147]  "msg"="Adding toleration to pod"  "podName"="tf2-keras-cifar10-inceptionv3-elastic-20210721-042550-worker-0" "scheduler"="default" "toleration"={"key":"celeste/hostname","operator":"Equal","value":"gpu4","effect":"NoExecute"}
I0721 17:14:49.068204   31979 placement_manager.go:147]  "msg"="Adding toleration to pod"  "podName"="tf2-keras-cifar10-inceptionv3-elastic-20210721-042459-launcher" "scheduler"="default" "toleration"={"key":"celeste/hostname","operator":"Exists","effect":"NoExecute"}
I0721 17:14:50.268293   31979 placement_manager.go:147]  "msg"="Adding toleration to pod"  "podName"="tf2-keras-cifar10-inceptionv3-elastic-20210721-042459-worker-0" "scheduler"="default" "toleration"={"key":"celeste/hostname","operator":"Equal","value":"gpu3","effect":"NoExecute"}
I0721 17:14:54.583822   31979 placement_manager.go:147]  "msg"="Adding toleration to pod"  "podName"="tf2-keras-cifar10-inceptionv3-elastic-20210721-042910-worker-0" "scheduler"="default" "toleration"={"key":"celeste/hostname","operator":"Equal","value":"gpu3","effect":"NoExecute"}
I0721 17:15:00.649650   31979 placement_manager.go:147]  "msg"="Adding toleration to pod"  "podName"="tf2-keras-cifar10-inceptionv3-elastic-20210721-042910-launcher" "scheduler"="default" "toleration"={"key":"celeste/hostname","operator":"Exists","effect":"NoExecute"}
I0721 17:15:04.766690   31979 scheduler.go:474]  "msg"="Training job completed"  "elaspedTotalSeconds"=2641.758456426 "gpuTotalSeconds"=1420.050239026 "job"="tf2-keras-cifar10-resnet50-elastic-20210721-043058" "ranTotalSeconds"=1420.050239026 "scheduler"="default" "waitedTotalSeconds"=1221.7082174
I0721 17:15:04.766837   31979 scheduler.go:135]  "msg"="Received resched event, may be blocked because of rate limit"  "blockedUntil"="2021-07-21T17:16:39.872151297+08:00" "lastResched"="2021-07-21T17:14:39.872151297+08:00" "received"="2021-07-21T17:15:04.766716471+08:00" "scheduler"="default"
I0721 17:16:39.872368   31979 scheduler.go:159]  "msg"="Started resched"  "scheduler"="default"
I0721 17:16:39.872513   31979 scheduler.go:193]  "msg"="Updating all jobs info"  "scheduler"="default"
I0721 17:16:39.882321   31979 elastic_fifo.go:73]  "msg"="Finished scheduling"  "algorithm"="ElasticFIFO" "freeGpu"=0 "result"={"tf2-keras-cifar10-inceptionv3-elastic-20210721-042459":1,"tf2-keras-cifar10-inceptionv3-elastic-20210721-042550":1,"tf2-keras-cifar10-inceptionv3-elastic-20210721-042807":1,"tf2-keras-cifar10-inceptionv3-elastic-20210721-042910":1,"tf2-keras-cifar10-inceptionv3-elastic-20210721-043127":1,"tf2-keras-cifar10-inceptionv3-elastic-20210721-043226":1,"tf2-keras-cifar10-resnet50-elastic-20210721-043248":1,"tf2-keras-cifar10-resnet50-elastic-20210721-043501":1,"tf2-keras-cifar10-resnet50-elastic-20210721-043527":0,"tf2-keras-cifar10-vgg16-elastic-20210721-043321":1,"tf2-keras-cifar10-vgg16-elastic-20210721-043423":1,"tf2-keras-transformer-elastic-20210721-043203":1,"tf2-keras-transformer-elastic-20210721-043343":1,"tf2-keras-transformer-elastic-20210721-043555":0} "scheduler"="default"
I0721 17:16:39.882787   31979 scheduler.go:384]  "msg"="Trying to delete multiple training jobs"  "jobs"=[] "scheduler"="default"
I0721 17:16:39.883095   31979 scheduler.go:342]  "msg"="Trying to scale multiple training jobs"  "jobs"=[] "scheduler"="default"
I0721 17:16:39.883316   31979 scheduler.go:292]  "msg"="Trying to start multiple training jobs"  "jobs"=["tf2-keras-cifar10-resnet50-elastic-20210721-043501"] "scheduler"="default"
I0721 17:16:39.893588   31979 scheduler.go:342]  "msg"="Trying to scale multiple training jobs"  "jobs"=[] "scheduler"="default"
I0721 17:16:39.899439   31979 placement_manager.go:166]  "msg"="Started job placements adjustment"  "scheduler"="default"
I0721 17:16:39.899566   31979 placement_manager.go:192]  "msg"="Releasing slots"  "jobs"={"tf2-keras-cifar10-inceptionv3-elastic-20210721-042459":{},"tf2-keras-cifar10-inceptionv3-elastic-20210721-042550":{},"tf2-keras-cifar10-inceptionv3-elastic-20210721-042807":{},"tf2-keras-cifar10-inceptionv3-elastic-20210721-042910":{},"tf2-keras-cifar10-inceptionv3-elastic-20210721-043127":{},"tf2-keras-cifar10-inceptionv3-elastic-20210721-043226":{},"tf2-keras-cifar10-resnet50-elastic-20210721-043058":{},"tf2-keras-cifar10-resnet50-elastic-20210721-043248":{},"tf2-keras-cifar10-vgg16-elastic-20210721-043321":{},"tf2-keras-cifar10-vgg16-elastic-20210721-043423":{},"tf2-keras-transformer-elastic-20210721-043203":{},"tf2-keras-transformer-elastic-20210721-043343":{}} "nodes"={"gpu3":{},"gpu4":{},"gpu5":{}} "scheduler"="default"
I0721 17:16:39.899686   31979 placement_manager.go:250]  "msg"="Released slots"  "jobs"={"tf2-keras-cifar10-inceptionv3-elastic-20210721-042459":{},"tf2-keras-cifar10-inceptionv3-elastic-20210721-042550":{},"tf2-keras-cifar10-inceptionv3-elastic-20210721-042807":{},"tf2-keras-cifar10-inceptionv3-elastic-20210721-042910":{},"tf2-keras-cifar10-inceptionv3-elastic-20210721-043127":{},"tf2-keras-cifar10-inceptionv3-elastic-20210721-043226":{},"tf2-keras-cifar10-resnet50-elastic-20210721-043058":{},"tf2-keras-cifar10-resnet50-elastic-20210721-043248":{},"tf2-keras-cifar10-vgg16-elastic-20210721-043321":{},"tf2-keras-cifar10-vgg16-elastic-20210721-043423":{},"tf2-keras-transformer-elastic-20210721-043203":{},"tf2-keras-transformer-elastic-20210721-043343":{}} "nodes"={"gpu3":{},"gpu4":{},"gpu5":{}} "scheduler"="default"
I0721 17:16:39.900244   31979 placement_manager.go:305]  "msg"="Found best-fit"  "crossNode"=0 "nodes"=[{},{},{}] "requests"=[{},{},{},{},{},{},{},{},{},{},{},{},{},{},{},{},{},{},{},{},{},{},{},{},{},{},{},{}] "scheduler"="default"
I0721 17:16:39.900714   31979 placement_manager.go:339]  "msg"="nodeStates updated"  "new"={"gpu3":{},"gpu4":{},"gpu5":{}} "old"={"gpu3":{},"gpu4":{},"gpu5":{}} "scheduler"="default" "score"=6
I0721 17:16:39.901161   31979 placement_manager.go:387]  "msg"="jobStates updated"  "new"={"tf2-keras-cifar10-inceptionv3-elastic-20210721-042459":{},"tf2-keras-cifar10-inceptionv3-elastic-20210721-042550":{},"tf2-keras-cifar10-inceptionv3-elastic-20210721-042807":{},"tf2-keras-cifar10-inceptionv3-elastic-20210721-042910":{},"tf2-keras-cifar10-inceptionv3-elastic-20210721-043127":{},"tf2-keras-cifar10-inceptionv3-elastic-20210721-043226":{},"tf2-keras-cifar10-resnet50-elastic-20210721-043248":{},"tf2-keras-cifar10-resnet50-elastic-20210721-043501":{},"tf2-keras-cifar10-vgg16-elastic-20210721-043321":{},"tf2-keras-cifar10-vgg16-elastic-20210721-043423":{},"tf2-keras-transformer-elastic-20210721-043203":{},"tf2-keras-transformer-elastic-20210721-043343":{}} "old"={"tf2-keras-cifar10-inceptionv3-elastic-20210721-042459":{},"tf2-keras-cifar10-inceptionv3-elastic-20210721-042550":{},"tf2-keras-cifar10-inceptionv3-elastic-20210721-042807":{},"tf2-keras-cifar10-inceptionv3-elastic-20210721-042910":{},"tf2-keras-cifar10-inceptionv3-elastic-20210721-043127":{},"tf2-keras-cifar10-inceptionv3-elastic-20210721-043226":{},"tf2-keras-cifar10-resnet50-elastic-20210721-043058":{},"tf2-keras-cifar10-resnet50-elastic-20210721-043248":{},"tf2-keras-cifar10-vgg16-elastic-20210721-043321":{},"tf2-keras-cifar10-vgg16-elastic-20210721-043423":{},"tf2-keras-transformer-elastic-20210721-043203":{},"tf2-keras-transformer-elastic-20210721-043343":{}} "scheduler"="default"
I0721 17:16:39.901571   31979 placement_manager.go:434]  "msg"="podNodeName updated"  "launchersToDelete"=5 "new"={"tf2-keras-cifar10-inceptionv3-elastic-20210721-042459-worker-0":"gpu3","tf2-keras-cifar10-inceptionv3-elastic-20210721-042550-worker-0":"gpu3","tf2-keras-cifar10-inceptionv3-elastic-20210721-042807-worker-0":"gpu4","tf2-keras-cifar10-inceptionv3-elastic-20210721-042910-worker-0":"gpu3","tf2-keras-cifar10-inceptionv3-elastic-20210721-043127-worker-0":"gpu5","tf2-keras-cifar10-inceptionv3-elastic-20210721-043226-worker-0":"gpu5","tf2-keras-cifar10-resnet50-elastic-20210721-043248-worker-0":"gpu4","tf2-keras-cifar10-resnet50-elastic-20210721-043501-worker-0":"gpu5","tf2-keras-cifar10-vgg16-elastic-20210721-043321-worker-0":"gpu5","tf2-keras-cifar10-vgg16-elastic-20210721-043423-worker-0":"gpu3","tf2-keras-transformer-elastic-20210721-043203-worker-0":"gpu4","tf2-keras-transformer-elastic-20210721-043343-worker-0":"gpu4"} "old"={"tf2-keras-cifar10-inceptionv3-elastic-20210721-042459-worker-0":"gpu3","tf2-keras-cifar10-inceptionv3-elastic-20210721-042550-worker-0":"gpu4","tf2-keras-cifar10-inceptionv3-elastic-20210721-042807-worker-0":"gpu4","tf2-keras-cifar10-inceptionv3-elastic-20210721-042910-worker-0":"gpu3","tf2-keras-cifar10-inceptionv3-elastic-20210721-043127-worker-0":"gpu5","tf2-keras-cifar10-inceptionv3-elastic-20210721-043226-worker-0":"gpu5","tf2-keras-cifar10-resnet50-elastic-20210721-043058-worker-0":"gpu3","tf2-keras-cifar10-resnet50-elastic-20210721-043248-worker-0":"gpu4","tf2-keras-cifar10-vgg16-elastic-20210721-043321-worker-0":"gpu4","tf2-keras-cifar10-vgg16-elastic-20210721-043423-worker-0":"gpu5","tf2-keras-transformer-elastic-20210721-043203-worker-0":"gpu3","tf2-keras-transformer-elastic-20210721-043343-worker-0":"gpu5"} "scheduler"="default" "workersToDelete"=5
I0721 17:16:39.901886   31979 placement_manager.go:451]  "msg"="Deleting pod that need migration"  "podName"="tf2-keras-cifar10-vgg16-elastic-20210721-043321-worker-0" "scheduler"="default"
I0721 17:16:39.909045   31979 placement_manager.go:451]  "msg"="Deleting pod that need migration"  "podName"="tf2-keras-cifar10-vgg16-elastic-20210721-043321-launcher" "scheduler"="default"
I0721 17:16:39.913047   31979 placement_manager.go:451]  "msg"="Deleting pod that need migration"  "podName"="tf2-keras-transformer-elastic-20210721-043203-worker-0" "scheduler"="default"
I0721 17:16:39.923277   31979 placement_manager.go:451]  "msg"="Deleting pod that need migration"  "podName"="tf2-keras-transformer-elastic-20210721-043203-launcher" "scheduler"="default"
I0721 17:16:39.927978   31979 placement_manager.go:451]  "msg"="Deleting pod that need migration"  "podName"="tf2-keras-cifar10-vgg16-elastic-20210721-043423-worker-0" "scheduler"="default"
I0721 17:16:39.932622   31979 placement_manager.go:451]  "msg"="Deleting pod that need migration"  "podName"="tf2-keras-cifar10-vgg16-elastic-20210721-043423-launcher" "scheduler"="default"
I0721 17:16:39.936807   31979 placement_manager.go:451]  "msg"="Deleting pod that need migration"  "podName"="tf2-keras-transformer-elastic-20210721-043343-worker-0" "scheduler"="default"
I0721 17:16:39.941258   31979 placement_manager.go:451]  "msg"="Deleting pod that need migration"  "podName"="tf2-keras-transformer-elastic-20210721-043343-launcher" "scheduler"="default"
I0721 17:16:39.945609   31979 placement_manager.go:451]  "msg"="Deleting pod that need migration"  "podName"="tf2-keras-cifar10-inceptionv3-elastic-20210721-042550-worker-0" "scheduler"="default"
I0721 17:16:39.948429   31979 placement_manager.go:147]  "msg"="Adding toleration to pod"  "podName"="tf2-keras-cifar10-resnet50-elastic-20210721-043501-worker-0" "scheduler"="default" "toleration"={"key":"celeste/hostname","operator":"Equal","value":"gpu5","effect":"NoExecute"}
I0721 17:16:39.949629   31979 placement_manager.go:451]  "msg"="Deleting pod that need migration"  "podName"="tf2-keras-cifar10-inceptionv3-elastic-20210721-042550-launcher" "scheduler"="default"
I0721 17:16:40.107155   31979 placement_manager.go:183]  "msg"="Finished job placements adjustment"  "scheduler"="default"
I0721 17:16:40.107430   31979 scheduler.go:182]  "msg"="Finished resched"  "scheduler"="default"
I0721 17:16:40.710638   31979 placement_manager.go:147]  "msg"="Adding toleration to pod"  "podName"="tf2-keras-cifar10-resnet50-elastic-20210721-043501-launcher" "scheduler"="default" "toleration"={"key":"celeste/hostname","operator":"Exists","effect":"NoExecute"}
I0721 17:16:49.285127   31979 placement_manager.go:147]  "msg"="Adding toleration to pod"  "podName"="tf2-keras-cifar10-inceptionv3-elastic-20210721-042550-launcher" "scheduler"="default" "toleration"={"key":"celeste/hostname","operator":"Exists","effect":"NoExecute"}
I0721 17:16:50.235912   31979 placement_manager.go:147]  "msg"="Adding toleration to pod"  "podName"="tf2-keras-cifar10-vgg16-elastic-20210721-043423-worker-0" "scheduler"="default" "toleration"={"key":"celeste/hostname","operator":"Equal","value":"gpu3","effect":"NoExecute"}
I0721 17:16:51.048199   31979 placement_manager.go:147]  "msg"="Adding toleration to pod"  "podName"="tf2-keras-transformer-elastic-20210721-043203-launcher" "scheduler"="default" "toleration"={"key":"celeste/hostname","operator":"Exists","effect":"NoExecute"}
I0721 17:16:53.033954   31979 placement_manager.go:147]  "msg"="Adding toleration to pod"  "podName"="tf2-keras-cifar10-vgg16-elastic-20210721-043423-launcher" "scheduler"="default" "toleration"={"key":"celeste/hostname","operator":"Exists","effect":"NoExecute"}
I0721 17:16:54.033292   31979 placement_manager.go:147]  "msg"="Adding toleration to pod"  "podName"="tf2-keras-transformer-elastic-20210721-043343-worker-0" "scheduler"="default" "toleration"={"key":"celeste/hostname","operator":"Equal","value":"gpu4","effect":"NoExecute"}
I0721 17:16:54.437169   31979 placement_manager.go:147]  "msg"="Adding toleration to pod"  "podName"="tf2-keras-transformer-elastic-20210721-043343-launcher" "scheduler"="default" "toleration"={"key":"celeste/hostname","operator":"Exists","effect":"NoExecute"}
I0721 17:16:56.038260   31979 placement_manager.go:147]  "msg"="Adding toleration to pod"  "podName"="tf2-keras-cifar10-vgg16-elastic-20210721-043321-launcher" "scheduler"="default" "toleration"={"key":"celeste/hostname","operator":"Exists","effect":"NoExecute"}
I0721 17:16:56.566860   31979 placement_manager.go:147]  "msg"="Adding toleration to pod"  "podName"="tf2-keras-cifar10-inceptionv3-elastic-20210721-042550-worker-0" "scheduler"="default" "toleration"={"key":"celeste/hostname","operator":"Equal","value":"gpu3","effect":"NoExecute"}
I0721 17:16:56.967618   31979 placement_manager.go:147]  "msg"="Adding toleration to pod"  "podName"="tf2-keras-cifar10-vgg16-elastic-20210721-043321-worker-0" "scheduler"="default" "toleration"={"key":"celeste/hostname","operator":"Equal","value":"gpu5","effect":"NoExecute"}
I0721 17:16:59.277598   31979 placement_manager.go:147]  "msg"="Adding toleration to pod"  "podName"="tf2-keras-transformer-elastic-20210721-043203-worker-0" "scheduler"="default" "toleration"={"key":"celeste/hostname","operator":"Equal","value":"gpu4","effect":"NoExecute"}
I0721 17:33:57.932377   31979 scheduler.go:474]  "msg"="Training job completed"  "elaspedTotalSeconds"=4135.867632988 "gpuTotalSeconds"=4842.044036773 "job"="tf2-keras-cifar10-inceptionv3-elastic-20210721-042459" "ranTotalSeconds"=4135.867632988 "scheduler"="default" "waitedTotalSeconds"=0
I0721 17:33:57.932559   31979 scheduler.go:135]  "msg"="Received resched event, may be blocked because of rate limit"  "blockedUntil"="2021-07-21T17:18:40.107649802+08:00" "lastResched"="2021-07-21T17:16:40.107649802+08:00" "received"="2021-07-21T17:33:57.93241402+08:00" "scheduler"="default"
I0721 17:33:57.932927   31979 scheduler.go:159]  "msg"="Started resched"  "scheduler"="default"
I0721 17:33:57.932989   31979 scheduler.go:193]  "msg"="Updating all jobs info"  "scheduler"="default"
I0721 17:33:57.943648   31979 elastic_fifo.go:73]  "msg"="Finished scheduling"  "algorithm"="ElasticFIFO" "freeGpu"=0 "result"={"tf2-keras-cifar10-inceptionv3-elastic-20210721-042550":1,"tf2-keras-cifar10-inceptionv3-elastic-20210721-042807":1,"tf2-keras-cifar10-inceptionv3-elastic-20210721-042910":1,"tf2-keras-cifar10-inceptionv3-elastic-20210721-043127":1,"tf2-keras-cifar10-inceptionv3-elastic-20210721-043226":1,"tf2-keras-cifar10-resnet50-elastic-20210721-043248":1,"tf2-keras-cifar10-resnet50-elastic-20210721-043501":1,"tf2-keras-cifar10-resnet50-elastic-20210721-043527":1,"tf2-keras-cifar10-vgg16-elastic-20210721-043321":1,"tf2-keras-cifar10-vgg16-elastic-20210721-043423":1,"tf2-keras-transformer-elastic-20210721-043203":1,"tf2-keras-transformer-elastic-20210721-043343":1,"tf2-keras-transformer-elastic-20210721-043555":0} "scheduler"="default"
I0721 17:33:57.943974   31979 scheduler.go:384]  "msg"="Trying to delete multiple training jobs"  "jobs"=[] "scheduler"="default"
I0721 17:33:57.944291   31979 scheduler.go:342]  "msg"="Trying to scale multiple training jobs"  "jobs"=[] "scheduler"="default"
I0721 17:33:57.944615   31979 scheduler.go:292]  "msg"="Trying to start multiple training jobs"  "jobs"=["tf2-keras-cifar10-resnet50-elastic-20210721-043527"] "scheduler"="default"
I0721 17:33:57.953890   31979 scheduler.go:342]  "msg"="Trying to scale multiple training jobs"  "jobs"=[] "scheduler"="default"
I0721 17:33:57.960768   31979 placement_manager.go:166]  "msg"="Started job placements adjustment"  "scheduler"="default"
I0721 17:33:57.960907   31979 placement_manager.go:192]  "msg"="Releasing slots"  "jobs"={"tf2-keras-cifar10-inceptionv3-elastic-20210721-042459":{},"tf2-keras-cifar10-inceptionv3-elastic-20210721-042550":{},"tf2-keras-cifar10-inceptionv3-elastic-20210721-042807":{},"tf2-keras-cifar10-inceptionv3-elastic-20210721-042910":{},"tf2-keras-cifar10-inceptionv3-elastic-20210721-043127":{},"tf2-keras-cifar10-inceptionv3-elastic-20210721-043226":{},"tf2-keras-cifar10-resnet50-elastic-20210721-043248":{},"tf2-keras-cifar10-resnet50-elastic-20210721-043501":{},"tf2-keras-cifar10-vgg16-elastic-20210721-043321":{},"tf2-keras-cifar10-vgg16-elastic-20210721-043423":{},"tf2-keras-transformer-elastic-20210721-043203":{},"tf2-keras-transformer-elastic-20210721-043343":{}} "nodes"={"gpu3":{},"gpu4":{},"gpu5":{}} "scheduler"="default"
I0721 17:33:57.961025   31979 placement_manager.go:250]  "msg"="Released slots"  "jobs"={"tf2-keras-cifar10-inceptionv3-elastic-20210721-042459":{},"tf2-keras-cifar10-inceptionv3-elastic-20210721-042550":{},"tf2-keras-cifar10-inceptionv3-elastic-20210721-042807":{},"tf2-keras-cifar10-inceptionv3-elastic-20210721-042910":{},"tf2-keras-cifar10-inceptionv3-elastic-20210721-043127":{},"tf2-keras-cifar10-inceptionv3-elastic-20210721-043226":{},"tf2-keras-cifar10-resnet50-elastic-20210721-043248":{},"tf2-keras-cifar10-resnet50-elastic-20210721-043501":{},"tf2-keras-cifar10-vgg16-elastic-20210721-043321":{},"tf2-keras-cifar10-vgg16-elastic-20210721-043423":{},"tf2-keras-transformer-elastic-20210721-043203":{},"tf2-keras-transformer-elastic-20210721-043343":{}} "nodes"={"gpu3":{},"gpu4":{},"gpu5":{}} "scheduler"="default"
I0721 17:33:57.961702   31979 placement_manager.go:305]  "msg"="Found best-fit"  "crossNode"=0 "nodes"=[{},{},{}] "requests"=[{},{},{},{},{},{},{},{},{},{},{},{},{},{},{},{},{},{},{},{},{},{},{},{},{},{}] "scheduler"="default"
I0721 17:33:57.962100   31979 placement_manager.go:339]  "msg"="nodeStates updated"  "new"={"gpu3":{},"gpu4":{},"gpu5":{}} "old"={"gpu3":{},"gpu4":{},"gpu5":{}} "scheduler"="default" "score"=5
I0721 17:33:57.962489   31979 placement_manager.go:387]  "msg"="jobStates updated"  "new"={"tf2-keras-cifar10-inceptionv3-elastic-20210721-042550":{},"tf2-keras-cifar10-inceptionv3-elastic-20210721-042807":{},"tf2-keras-cifar10-inceptionv3-elastic-20210721-042910":{},"tf2-keras-cifar10-inceptionv3-elastic-20210721-043127":{},"tf2-keras-cifar10-inceptionv3-elastic-20210721-043226":{},"tf2-keras-cifar10-resnet50-elastic-20210721-043248":{},"tf2-keras-cifar10-resnet50-elastic-20210721-043501":{},"tf2-keras-cifar10-resnet50-elastic-20210721-043527":{},"tf2-keras-cifar10-vgg16-elastic-20210721-043321":{},"tf2-keras-cifar10-vgg16-elastic-20210721-043423":{},"tf2-keras-transformer-elastic-20210721-043203":{},"tf2-keras-transformer-elastic-20210721-043343":{}} "old"={"tf2-keras-cifar10-inceptionv3-elastic-20210721-042459":{},"tf2-keras-cifar10-inceptionv3-elastic-20210721-042550":{},"tf2-keras-cifar10-inceptionv3-elastic-20210721-042807":{},"tf2-keras-cifar10-inceptionv3-elastic-20210721-042910":{},"tf2-keras-cifar10-inceptionv3-elastic-20210721-043127":{},"tf2-keras-cifar10-inceptionv3-elastic-20210721-043226":{},"tf2-keras-cifar10-resnet50-elastic-20210721-043248":{},"tf2-keras-cifar10-resnet50-elastic-20210721-043501":{},"tf2-keras-cifar10-vgg16-elastic-20210721-043321":{},"tf2-keras-cifar10-vgg16-elastic-20210721-043423":{},"tf2-keras-transformer-elastic-20210721-043203":{},"tf2-keras-transformer-elastic-20210721-043343":{}} "scheduler"="default"
I0721 17:33:57.962970   31979 placement_manager.go:434]  "msg"="podNodeName updated"  "launchersToDelete"=6 "new"={"tf2-keras-cifar10-inceptionv3-elastic-20210721-042550-worker-0":"gpu3","tf2-keras-cifar10-inceptionv3-elastic-20210721-042807-worker-0":"gpu4","tf2-keras-cifar10-inceptionv3-elastic-20210721-042910-worker-0":"gpu5","tf2-keras-cifar10-inceptionv3-elastic-20210721-043127-worker-0":"gpu5","tf2-keras-cifar10-inceptionv3-elastic-20210721-043226-worker-0":"gpu5","tf2-keras-cifar10-resnet50-elastic-20210721-043248-worker-0":"gpu5","tf2-keras-cifar10-resnet50-elastic-20210721-043501-worker-0":"gpu4","tf2-keras-cifar10-resnet50-elastic-20210721-043527-worker-0":"gpu3","tf2-keras-cifar10-vgg16-elastic-20210721-043321-worker-0":"gpu3","tf2-keras-cifar10-vgg16-elastic-20210721-043423-worker-0":"gpu4","tf2-keras-transformer-elastic-20210721-043203-worker-0":"gpu3","tf2-keras-transformer-elastic-20210721-043343-worker-0":"gpu4"} "old"={"tf2-keras-cifar10-inceptionv3-elastic-20210721-042459-worker-0":"gpu3","tf2-keras-cifar10-inceptionv3-elastic-20210721-042550-worker-0":"gpu3","tf2-keras-cifar10-inceptionv3-elastic-20210721-042807-worker-0":"gpu4","tf2-keras-cifar10-inceptionv3-elastic-20210721-042910-worker-0":"gpu3","tf2-keras-cifar10-inceptionv3-elastic-20210721-043127-worker-0":"gpu5","tf2-keras-cifar10-inceptionv3-elastic-20210721-043226-worker-0":"gpu5","tf2-keras-cifar10-resnet50-elastic-20210721-043248-worker-0":"gpu4","tf2-keras-cifar10-resnet50-elastic-20210721-043501-worker-0":"gpu5","tf2-keras-cifar10-vgg16-elastic-20210721-043321-worker-0":"gpu5","tf2-keras-cifar10-vgg16-elastic-20210721-043423-worker-0":"gpu3","tf2-keras-transformer-elastic-20210721-043203-worker-0":"gpu4","tf2-keras-transformer-elastic-20210721-043343-worker-0":"gpu4"} "scheduler"="default" "workersToDelete"=6
I0721 17:33:57.963359   31979 placement_manager.go:451]  "msg"="Deleting pod that need migration"  "podName"="tf2-keras-cifar10-resnet50-elastic-20210721-043501-worker-0" "scheduler"="default"
I0721 17:33:57.970394   31979 placement_manager.go:451]  "msg"="Deleting pod that need migration"  "podName"="tf2-keras-cifar10-resnet50-elastic-20210721-043501-launcher" "scheduler"="default"
I0721 17:33:57.987876   31979 placement_manager.go:451]  "msg"="Deleting pod that need migration"  "podName"="tf2-keras-cifar10-resnet50-elastic-20210721-043248-worker-0" "scheduler"="default"
I0721 17:33:57.992823   31979 placement_manager.go:451]  "msg"="Deleting pod that need migration"  "podName"="tf2-keras-cifar10-resnet50-elastic-20210721-043248-launcher" "scheduler"="default"
I0721 17:33:57.998641   31979 placement_manager.go:451]  "msg"="Deleting pod that need migration"  "podName"="tf2-keras-transformer-elastic-20210721-043203-worker-0" "scheduler"="default"
I0721 17:33:58.007457   31979 placement_manager.go:451]  "msg"="Deleting pod that need migration"  "podName"="tf2-keras-transformer-elastic-20210721-043203-launcher" "scheduler"="default"
I0721 17:33:58.010735   31979 placement_manager.go:451]  "msg"="Deleting pod that need migration"  "podName"="tf2-keras-cifar10-vgg16-elastic-20210721-043321-worker-0" "scheduler"="default"
I0721 17:33:58.014013   31979 placement_manager.go:451]  "msg"="Deleting pod that need migration"  "podName"="tf2-keras-cifar10-vgg16-elastic-20210721-043321-launcher" "scheduler"="default"
I0721 17:33:58.017968   31979 placement_manager.go:451]  "msg"="Deleting pod that need migration"  "podName"="tf2-keras-cifar10-vgg16-elastic-20210721-043423-worker-0" "scheduler"="default"
I0721 17:33:58.021453   31979 placement_manager.go:451]  "msg"="Deleting pod that need migration"  "podName"="tf2-keras-cifar10-vgg16-elastic-20210721-043423-launcher" "scheduler"="default"
I0721 17:33:58.025038   31979 placement_manager.go:451]  "msg"="Deleting pod that need migration"  "podName"="tf2-keras-cifar10-inceptionv3-elastic-20210721-042910-worker-0" "scheduler"="default"
I0721 17:33:58.168401   31979 placement_manager.go:451]  "msg"="Deleting pod that need migration"  "podName"="tf2-keras-cifar10-inceptionv3-elastic-20210721-042910-launcher" "scheduler"="default"
I0721 17:33:58.369132   31979 placement_manager.go:183]  "msg"="Finished job placements adjustment"  "scheduler"="default"
I0721 17:33:58.369480   31979 scheduler.go:182]  "msg"="Finished resched"  "scheduler"="default"
I0721 17:33:58.524116   31979 placement_manager.go:147]  "msg"="Adding toleration to pod"  "podName"="tf2-keras-cifar10-resnet50-elastic-20210721-043527-worker-0" "scheduler"="default" "toleration"={"key":"celeste/hostname","operator":"Equal","value":"gpu3","effect":"NoExecute"}
I0721 17:33:58.921771   31979 placement_manager.go:147]  "msg"="Adding toleration to pod"  "podName"="tf2-keras-cifar10-resnet50-elastic-20210721-043527-launcher" "scheduler"="default" "toleration"={"key":"celeste/hostname","operator":"Exists","effect":"NoExecute"}
I0721 17:34:05.423364   31979 placement_manager.go:147]  "msg"="Adding toleration to pod"  "podName"="tf2-keras-cifar10-resnet50-elastic-20210721-043501-launcher" "scheduler"="default" "toleration"={"key":"celeste/hostname","operator":"Exists","effect":"NoExecute"}
I0721 17:34:09.286843   31979 placement_manager.go:147]  "msg"="Adding toleration to pod"  "podName"="tf2-keras-cifar10-inceptionv3-elastic-20210721-042910-launcher" "scheduler"="default" "toleration"={"key":"celeste/hostname","operator":"Exists","effect":"NoExecute"}
I0721 17:34:09.329579   31979 placement_manager.go:147]  "msg"="Adding toleration to pod"  "podName"="tf2-keras-cifar10-vgg16-elastic-20210721-043423-launcher" "scheduler"="default" "toleration"={"key":"celeste/hostname","operator":"Exists","effect":"NoExecute"}
I0721 17:34:09.742374   31979 placement_manager.go:147]  "msg"="Adding toleration to pod"  "podName"="tf2-keras-cifar10-vgg16-elastic-20210721-043321-launcher" "scheduler"="default" "toleration"={"key":"celeste/hostname","operator":"Exists","effect":"NoExecute"}
I0721 17:34:09.990789   31979 placement_manager.go:147]  "msg"="Adding toleration to pod"  "podName"="tf2-keras-cifar10-resnet50-elastic-20210721-043501-worker-0" "scheduler"="default" "toleration"={"key":"celeste/hostname","operator":"Equal","value":"gpu4","effect":"NoExecute"}
I0721 17:34:10.383369   31979 placement_manager.go:147]  "msg"="Adding toleration to pod"  "podName"="tf2-keras-cifar10-vgg16-elastic-20210721-043321-worker-0" "scheduler"="default" "toleration"={"key":"celeste/hostname","operator":"Equal","value":"gpu3","effect":"NoExecute"}
I0721 17:34:14.708897   31979 placement_manager.go:147]  "msg"="Adding toleration to pod"  "podName"="tf2-keras-cifar10-resnet50-elastic-20210721-043248-worker-0" "scheduler"="default" "toleration"={"key":"celeste/hostname","operator":"Equal","value":"gpu5","effect":"NoExecute"}
I0721 17:34:15.123271   31979 placement_manager.go:147]  "msg"="Adding toleration to pod"  "podName"="tf2-keras-transformer-elastic-20210721-043203-launcher" "scheduler"="default" "toleration"={"key":"celeste/hostname","operator":"Exists","effect":"NoExecute"}
I0721 17:34:15.512271   31979 placement_manager.go:147]  "msg"="Adding toleration to pod"  "podName"="tf2-keras-transformer-elastic-20210721-043203-worker-0" "scheduler"="default" "toleration"={"key":"celeste/hostname","operator":"Equal","value":"gpu3","effect":"NoExecute"}
I0721 17:34:15.910979   31979 placement_manager.go:147]  "msg"="Adding toleration to pod"  "podName"="tf2-keras-cifar10-resnet50-elastic-20210721-043248-launcher" "scheduler"="default" "toleration"={"key":"celeste/hostname","operator":"Exists","effect":"NoExecute"}
I0721 17:34:22.064283   31979 placement_manager.go:147]  "msg"="Adding toleration to pod"  "podName"="tf2-keras-cifar10-inceptionv3-elastic-20210721-042910-worker-0" "scheduler"="default" "toleration"={"key":"celeste/hostname","operator":"Equal","value":"gpu5","effect":"NoExecute"}
I0721 17:34:23.263178   31979 placement_manager.go:147]  "msg"="Adding toleration to pod"  "podName"="tf2-keras-cifar10-vgg16-elastic-20210721-043423-worker-0" "scheduler"="default" "toleration"={"key":"celeste/hostname","operator":"Equal","value":"gpu4","effect":"NoExecute"}
I0721 17:38:12.528652   31979 scheduler.go:474]  "msg"="Training job completed"  "elaspedTotalSeconds"=3922.149037282 "gpuTotalSeconds"=1535.05302024 "job"="tf2-keras-cifar10-resnet50-elastic-20210721-043248" "ranTotalSeconds"=1535.05302024 "scheduler"="default" "waitedTotalSeconds"=2387.096017042
I0721 17:38:12.528812   31979 scheduler.go:135]  "msg"="Received resched event, may be blocked because of rate limit"  "blockedUntil"="2021-07-21T17:35:58.369715705+08:00" "lastResched"="2021-07-21T17:33:58.369715705+08:00" "received"="2021-07-21T17:38:12.528697403+08:00" "scheduler"="default"
I0721 17:38:12.529275   31979 scheduler.go:159]  "msg"="Started resched"  "scheduler"="default"
I0721 17:38:12.529351   31979 scheduler.go:193]  "msg"="Updating all jobs info"  "scheduler"="default"
I0721 17:38:12.537831   31979 elastic_fifo.go:73]  "msg"="Finished scheduling"  "algorithm"="ElasticFIFO" "freeGpu"=0 "result"={"tf2-keras-cifar10-inceptionv3-elastic-20210721-042550":1,"tf2-keras-cifar10-inceptionv3-elastic-20210721-042807":1,"tf2-keras-cifar10-inceptionv3-elastic-20210721-042910":1,"tf2-keras-cifar10-inceptionv3-elastic-20210721-043127":1,"tf2-keras-cifar10-inceptionv3-elastic-20210721-043226":1,"tf2-keras-cifar10-resnet50-elastic-20210721-043501":1,"tf2-keras-cifar10-resnet50-elastic-20210721-043527":1,"tf2-keras-cifar10-vgg16-elastic-20210721-043321":1,"tf2-keras-cifar10-vgg16-elastic-20210721-043423":1,"tf2-keras-transformer-elastic-20210721-043203":1,"tf2-keras-transformer-elastic-20210721-043343":1,"tf2-keras-transformer-elastic-20210721-043555":1} "scheduler"="default"
I0721 17:38:12.538231   31979 scheduler.go:384]  "msg"="Trying to delete multiple training jobs"  "jobs"=[] "scheduler"="default"
I0721 17:38:12.538489   31979 scheduler.go:342]  "msg"="Trying to scale multiple training jobs"  "jobs"=[] "scheduler"="default"
I0721 17:38:12.538743   31979 scheduler.go:292]  "msg"="Trying to start multiple training jobs"  "jobs"=["tf2-keras-transformer-elastic-20210721-043555"] "scheduler"="default"
I0721 17:38:12.558197   31979 scheduler.go:342]  "msg"="Trying to scale multiple training jobs"  "jobs"=[] "scheduler"="default"
I0721 17:38:12.564092   31979 placement_manager.go:166]  "msg"="Started job placements adjustment"  "scheduler"="default"
I0721 17:38:12.564183   31979 placement_manager.go:192]  "msg"="Releasing slots"  "jobs"={"tf2-keras-cifar10-inceptionv3-elastic-20210721-042550":{},"tf2-keras-cifar10-inceptionv3-elastic-20210721-042807":{},"tf2-keras-cifar10-inceptionv3-elastic-20210721-042910":{},"tf2-keras-cifar10-inceptionv3-elastic-20210721-043127":{},"tf2-keras-cifar10-inceptionv3-elastic-20210721-043226":{},"tf2-keras-cifar10-resnet50-elastic-20210721-043248":{},"tf2-keras-cifar10-resnet50-elastic-20210721-043501":{},"tf2-keras-cifar10-resnet50-elastic-20210721-043527":{},"tf2-keras-cifar10-vgg16-elastic-20210721-043321":{},"tf2-keras-cifar10-vgg16-elastic-20210721-043423":{},"tf2-keras-transformer-elastic-20210721-043203":{},"tf2-keras-transformer-elastic-20210721-043343":{}} "nodes"={"gpu3":{},"gpu4":{},"gpu5":{}} "scheduler"="default"
I0721 17:38:12.564260   31979 placement_manager.go:250]  "msg"="Released slots"  "jobs"={"tf2-keras-cifar10-inceptionv3-elastic-20210721-042550":{},"tf2-keras-cifar10-inceptionv3-elastic-20210721-042807":{},"tf2-keras-cifar10-inceptionv3-elastic-20210721-042910":{},"tf2-keras-cifar10-inceptionv3-elastic-20210721-043127":{},"tf2-keras-cifar10-inceptionv3-elastic-20210721-043226":{},"tf2-keras-cifar10-resnet50-elastic-20210721-043248":{},"tf2-keras-cifar10-resnet50-elastic-20210721-043501":{},"tf2-keras-cifar10-resnet50-elastic-20210721-043527":{},"tf2-keras-cifar10-vgg16-elastic-20210721-043321":{},"tf2-keras-cifar10-vgg16-elastic-20210721-043423":{},"tf2-keras-transformer-elastic-20210721-043203":{},"tf2-keras-transformer-elastic-20210721-043343":{}} "nodes"={"gpu3":{},"gpu4":{},"gpu5":{}} "scheduler"="default"
I0721 17:38:12.564672   31979 placement_manager.go:305]  "msg"="Found best-fit"  "crossNode"=0 "nodes"=[{},{},{}] "requests"=[{},{},{},{},{},{},{},{},{},{},{},{},{},{},{},{},{},{},{},{},{},{},{},{}] "scheduler"="default"
I0721 17:38:12.564944   31979 placement_manager.go:339]  "msg"="nodeStates updated"  "new"={"gpu3":{},"gpu4":{},"gpu5":{}} "old"={"gpu3":{},"gpu4":{},"gpu5":{}} "scheduler"="default" "score"=5
I0721 17:38:12.565212   31979 placement_manager.go:387]  "msg"="jobStates updated"  "new"={"tf2-keras-cifar10-inceptionv3-elastic-20210721-042550":{},"tf2-keras-cifar10-inceptionv3-elastic-20210721-042807":{},"tf2-keras-cifar10-inceptionv3-elastic-20210721-042910":{},"tf2-keras-cifar10-inceptionv3-elastic-20210721-043127":{},"tf2-keras-cifar10-inceptionv3-elastic-20210721-043226":{},"tf2-keras-cifar10-resnet50-elastic-20210721-043501":{},"tf2-keras-cifar10-resnet50-elastic-20210721-043527":{},"tf2-keras-cifar10-vgg16-elastic-20210721-043321":{},"tf2-keras-cifar10-vgg16-elastic-20210721-043423":{},"tf2-keras-transformer-elastic-20210721-043203":{},"tf2-keras-transformer-elastic-20210721-043343":{},"tf2-keras-transformer-elastic-20210721-043555":{}} "old"={"tf2-keras-cifar10-inceptionv3-elastic-20210721-042550":{},"tf2-keras-cifar10-inceptionv3-elastic-20210721-042807":{},"tf2-keras-cifar10-inceptionv3-elastic-20210721-042910":{},"tf2-keras-cifar10-inceptionv3-elastic-20210721-043127":{},"tf2-keras-cifar10-inceptionv3-elastic-20210721-043226":{},"tf2-keras-cifar10-resnet50-elastic-20210721-043248":{},"tf2-keras-cifar10-resnet50-elastic-20210721-043501":{},"tf2-keras-cifar10-resnet50-elastic-20210721-043527":{},"tf2-keras-cifar10-vgg16-elastic-20210721-043321":{},"tf2-keras-cifar10-vgg16-elastic-20210721-043423":{},"tf2-keras-transformer-elastic-20210721-043203":{},"tf2-keras-transformer-elastic-20210721-043343":{}} "scheduler"="default"
I0721 17:38:12.565550   31979 placement_manager.go:434]  "msg"="podNodeName updated"  "launchersToDelete"=6 "new"={"tf2-keras-cifar10-inceptionv3-elastic-20210721-042550-worker-0":"gpu4","tf2-keras-cifar10-inceptionv3-elastic-20210721-042807-worker-0":"gpu5","tf2-keras-cifar10-inceptionv3-elastic-20210721-042910-worker-0":"gpu4","tf2-keras-cifar10-inceptionv3-elastic-20210721-043127-worker-0":"gpu5","tf2-keras-cifar10-inceptionv3-elastic-20210721-043226-worker-0":"gpu3","tf2-keras-cifar10-resnet50-elastic-20210721-043501-worker-0":"gpu4","tf2-keras-cifar10-resnet50-elastic-20210721-043527-worker-0":"gpu5","tf2-keras-cifar10-vgg16-elastic-20210721-043321-worker-0":"gpu3","tf2-keras-cifar10-vgg16-elastic-20210721-043423-worker-0":"gpu4","tf2-keras-transformer-elastic-20210721-043203-worker-0":"gpu3","tf2-keras-transformer-elastic-20210721-043343-worker-0":"gpu3","tf2-keras-transformer-elastic-20210721-043555-worker-0":"gpu5"} "old"={"tf2-keras-cifar10-inceptionv3-elastic-20210721-042550-worker-0":"gpu3","tf2-keras-cifar10-inceptionv3-elastic-20210721-042807-worker-0":"gpu4","tf2-keras-cifar10-inceptionv3-elastic-20210721-042910-worker-0":"gpu5","tf2-keras-cifar10-inceptionv3-elastic-20210721-043127-worker-0":"gpu5","tf2-keras-cifar10-inceptionv3-elastic-20210721-043226-worker-0":"gpu5","tf2-keras-cifar10-resnet50-elastic-20210721-043248-worker-0":"gpu5","tf2-keras-cifar10-resnet50-elastic-20210721-043501-worker-0":"gpu4","tf2-keras-cifar10-resnet50-elastic-20210721-043527-worker-0":"gpu3","tf2-keras-cifar10-vgg16-elastic-20210721-043321-worker-0":"gpu3","tf2-keras-cifar10-vgg16-elastic-20210721-043423-worker-0":"gpu4","tf2-keras-transformer-elastic-20210721-043203-worker-0":"gpu3","tf2-keras-transformer-elastic-20210721-043343-worker-0":"gpu4"} "scheduler"="default" "workersToDelete"=6
I0721 17:38:12.565764   31979 placement_manager.go:451]  "msg"="Deleting pod that need migration"  "podName"="tf2-keras-transformer-elastic-20210721-043343-worker-0" "scheduler"="default"
I0721 17:38:12.570093   31979 placement_manager.go:451]  "msg"="Deleting pod that need migration"  "podName"="tf2-keras-transformer-elastic-20210721-043343-launcher" "scheduler"="default"
I0721 17:38:12.573272   31979 placement_manager.go:451]  "msg"="Deleting pod that need migration"  "podName"="tf2-keras-cifar10-inceptionv3-elastic-20210721-042910-worker-0" "scheduler"="default"
I0721 17:38:12.577362   31979 placement_manager.go:451]  "msg"="Deleting pod that need migration"  "podName"="tf2-keras-cifar10-inceptionv3-elastic-20210721-042910-launcher" "scheduler"="default"
I0721 17:38:12.581022   31979 placement_manager.go:451]  "msg"="Deleting pod that need migration"  "podName"="tf2-keras-cifar10-resnet50-elastic-20210721-043527-worker-0" "scheduler"="default"
I0721 17:38:12.594006   31979 placement_manager.go:451]  "msg"="Deleting pod that need migration"  "podName"="tf2-keras-cifar10-resnet50-elastic-20210721-043527-launcher" "scheduler"="default"
I0721 17:38:12.597292   31979 placement_manager.go:451]  "msg"="Deleting pod that need migration"  "podName"="tf2-keras-cifar10-inceptionv3-elastic-20210721-043226-worker-0" "scheduler"="default"
I0721 17:38:12.600072   31979 placement_manager.go:451]  "msg"="Deleting pod that need migration"  "podName"="tf2-keras-cifar10-inceptionv3-elastic-20210721-043226-launcher" "scheduler"="default"
I0721 17:38:12.603736   31979 placement_manager.go:451]  "msg"="Deleting pod that need migration"  "podName"="tf2-keras-cifar10-inceptionv3-elastic-20210721-042550-worker-0" "scheduler"="default"
I0721 17:38:12.607511   31979 placement_manager.go:451]  "msg"="Deleting pod that need migration"  "podName"="tf2-keras-cifar10-inceptionv3-elastic-20210721-042550-launcher" "scheduler"="default"
I0721 17:38:12.610941   31979 placement_manager.go:451]  "msg"="Deleting pod that need migration"  "podName"="tf2-keras-cifar10-inceptionv3-elastic-20210721-042807-worker-0" "scheduler"="default"
I0721 17:38:12.771358   31979 placement_manager.go:451]  "msg"="Deleting pod that need migration"  "podName"="tf2-keras-cifar10-inceptionv3-elastic-20210721-042807-launcher" "scheduler"="default"
I0721 17:38:12.922690   31979 placement_manager.go:147]  "msg"="Adding toleration to pod"  "podName"="tf2-keras-transformer-elastic-20210721-043555-worker-0" "scheduler"="default" "toleration"={"key":"celeste/hostname","operator":"Equal","value":"gpu5","effect":"NoExecute"}
I0721 17:38:12.971305   31979 placement_manager.go:183]  "msg"="Finished job placements adjustment"  "scheduler"="default"
I0721 17:38:12.971607   31979 scheduler.go:182]  "msg"="Finished resched"  "scheduler"="default"
I0721 17:38:13.373110   31979 placement_manager.go:147]  "msg"="Adding toleration to pod"  "podName"="tf2-keras-transformer-elastic-20210721-043555-launcher" "scheduler"="default" "toleration"={"key":"celeste/hostname","operator":"Exists","effect":"NoExecute"}
I0721 17:38:21.373428   31979 placement_manager.go:147]  "msg"="Adding toleration to pod"  "podName"="tf2-keras-transformer-elastic-20210721-043343-launcher" "scheduler"="default" "toleration"={"key":"celeste/hostname","operator":"Exists","effect":"NoExecute"}
I0721 17:38:29.290892   31979 placement_manager.go:147]  "msg"="Adding toleration to pod"  "podName"="tf2-keras-cifar10-inceptionv3-elastic-20210721-042550-worker-0" "scheduler"="default" "toleration"={"key":"celeste/hostname","operator":"Equal","value":"gpu4","effect":"NoExecute"}
I0721 17:38:29.323667   31979 placement_manager.go:147]  "msg"="Adding toleration to pod"  "podName"="tf2-keras-cifar10-resnet50-elastic-20210721-043527-worker-0" "scheduler"="default" "toleration"={"key":"celeste/hostname","operator":"Equal","value":"gpu5","effect":"NoExecute"}
I0721 17:38:29.333797   31979 placement_manager.go:147]  "msg"="Adding toleration to pod"  "podName"="tf2-keras-cifar10-inceptionv3-elastic-20210721-042550-launcher" "scheduler"="default" "toleration"={"key":"celeste/hostname","operator":"Exists","effect":"NoExecute"}
I0721 17:38:30.284060   31979 placement_manager.go:147]  "msg"="Adding toleration to pod"  "podName"="tf2-keras-cifar10-inceptionv3-elastic-20210721-042910-launcher" "scheduler"="default" "toleration"={"key":"celeste/hostname","operator":"Exists","effect":"NoExecute"}
I0721 17:38:30.669988   31979 placement_manager.go:147]  "msg"="Adding toleration to pod"  "podName"="tf2-keras-cifar10-inceptionv3-elastic-20210721-043226-launcher" "scheduler"="default" "toleration"={"key":"celeste/hostname","operator":"Exists","effect":"NoExecute"}
I0721 17:38:31.736062   31979 placement_manager.go:147]  "msg"="Adding toleration to pod"  "podName"="tf2-keras-cifar10-inceptionv3-elastic-20210721-043226-worker-0" "scheduler"="default" "toleration"={"key":"celeste/hostname","operator":"Equal","value":"gpu3","effect":"NoExecute"}
I0721 17:38:32.481608   31979 placement_manager.go:147]  "msg"="Adding toleration to pod"  "podName"="tf2-keras-cifar10-inceptionv3-elastic-20210721-042910-worker-0" "scheduler"="default" "toleration"={"key":"celeste/hostname","operator":"Equal","value":"gpu4","effect":"NoExecute"}
I0721 17:38:33.271993   31979 placement_manager.go:147]  "msg"="Adding toleration to pod"  "podName"="tf2-keras-cifar10-resnet50-elastic-20210721-043527-launcher" "scheduler"="default" "toleration"={"key":"celeste/hostname","operator":"Exists","effect":"NoExecute"}
I0721 17:38:35.355503   31979 placement_manager.go:147]  "msg"="Adding toleration to pod"  "podName"="tf2-keras-cifar10-inceptionv3-elastic-20210721-042807-launcher" "scheduler"="default" "toleration"={"key":"celeste/hostname","operator":"Exists","effect":"NoExecute"}
I0721 17:38:36.159248   31979 placement_manager.go:147]  "msg"="Adding toleration to pod"  "podName"="tf2-keras-cifar10-inceptionv3-elastic-20210721-042807-worker-0" "scheduler"="default" "toleration"={"key":"celeste/hostname","operator":"Equal","value":"gpu5","effect":"NoExecute"}
I0721 17:38:36.950755   31979 placement_manager.go:147]  "msg"="Adding toleration to pod"  "podName"="tf2-keras-transformer-elastic-20210721-043343-worker-0" "scheduler"="default" "toleration"={"key":"celeste/hostname","operator":"Equal","value":"gpu3","effect":"NoExecute"}
I0721 17:38:48.917095   31979 scheduler.go:474]  "msg"="Training job completed"  "elaspedTotalSeconds"=3862.48288543 "gpuTotalSeconds"=1450.051052437 "job"="tf2-keras-cifar10-vgg16-elastic-20210721-043423" "ranTotalSeconds"=1450.051052437 "scheduler"="default" "waitedTotalSeconds"=2412.431832993
I0721 17:38:48.917282   31979 scheduler.go:135]  "msg"="Received resched event, may be blocked because of rate limit"  "blockedUntil"="2021-07-21T17:40:12.971845285+08:00" "lastResched"="2021-07-21T17:38:12.971845285+08:00" "received"="2021-07-21T17:38:48.917135723+08:00" "scheduler"="default"
I0721 17:38:56.165597   31979 scheduler.go:474]  "msg"="Training job completed"  "elaspedTotalSeconds"=4011.923654039 "gpuTotalSeconds"=2570.090583867 "job"="tf2-keras-transformer-elastic-20210721-043203" "ranTotalSeconds"=2570.090583867 "scheduler"="default" "waitedTotalSeconds"=1441.833070172
I0721 17:39:04.255073   31979 scheduler.go:474]  "msg"="Training job completed"  "elaspedTotalSeconds"=3939.256251933 "gpuTotalSeconds"=1465.051543679 "job"="tf2-keras-cifar10-vgg16-elastic-20210721-043321" "ranTotalSeconds"=1465.051543679 "scheduler"="default" "waitedTotalSeconds"=2474.204708254
I0721 17:40:12.971929   31979 scheduler.go:159]  "msg"="Started resched"  "scheduler"="default"
I0721 17:40:12.972026   31979 scheduler.go:193]  "msg"="Updating all jobs info"  "scheduler"="default"
I0721 17:40:12.978241   31979 elastic_fifo.go:73]  "msg"="Finished scheduling"  "algorithm"="ElasticFIFO" "freeGpu"=0 "result"={"tf2-keras-cifar10-inceptionv3-elastic-20210721-042550":2,"tf2-keras-cifar10-inceptionv3-elastic-20210721-042807":2,"tf2-keras-cifar10-inceptionv3-elastic-20210721-042910":2,"tf2-keras-cifar10-inceptionv3-elastic-20210721-043127":1,"tf2-keras-cifar10-inceptionv3-elastic-20210721-043226":1,"tf2-keras-cifar10-resnet50-elastic-20210721-043501":1,"tf2-keras-cifar10-resnet50-elastic-20210721-043527":1,"tf2-keras-transformer-elastic-20210721-043343":1,"tf2-keras-transformer-elastic-20210721-043555":1} "scheduler"="default"
I0721 17:40:12.978512   31979 scheduler.go:384]  "msg"="Trying to delete multiple training jobs"  "jobs"=[] "scheduler"="default"
I0721 17:40:12.978721   31979 scheduler.go:342]  "msg"="Trying to scale multiple training jobs"  "jobs"=[] "scheduler"="default"
I0721 17:40:12.978968   31979 scheduler.go:292]  "msg"="Trying to start multiple training jobs"  "jobs"=[] "scheduler"="default"
I0721 17:40:12.979151   31979 scheduler.go:342]  "msg"="Trying to scale multiple training jobs"  "jobs"=["tf2-keras-cifar10-inceptionv3-elastic-20210721-042550","tf2-keras-cifar10-inceptionv3-elastic-20210721-042910","tf2-keras-cifar10-inceptionv3-elastic-20210721-042807"] "scheduler"="default"
I0721 17:40:13.020414   31979 placement_manager.go:166]  "msg"="Started job placements adjustment"  "scheduler"="default"
I0721 17:40:13.020535   31979 placement_manager.go:192]  "msg"="Releasing slots"  "jobs"={"tf2-keras-cifar10-inceptionv3-elastic-20210721-042550":{},"tf2-keras-cifar10-inceptionv3-elastic-20210721-042807":{},"tf2-keras-cifar10-inceptionv3-elastic-20210721-042910":{},"tf2-keras-cifar10-inceptionv3-elastic-20210721-043127":{},"tf2-keras-cifar10-inceptionv3-elastic-20210721-043226":{},"tf2-keras-cifar10-resnet50-elastic-20210721-043501":{},"tf2-keras-cifar10-resnet50-elastic-20210721-043527":{},"tf2-keras-cifar10-vgg16-elastic-20210721-043321":{},"tf2-keras-cifar10-vgg16-elastic-20210721-043423":{},"tf2-keras-transformer-elastic-20210721-043203":{},"tf2-keras-transformer-elastic-20210721-043343":{},"tf2-keras-transformer-elastic-20210721-043555":{}} "nodes"={"gpu3":{},"gpu4":{},"gpu5":{}} "scheduler"="default"
I0721 17:40:13.020603   31979 placement_manager.go:250]  "msg"="Released slots"  "jobs"={"tf2-keras-cifar10-inceptionv3-elastic-20210721-042550":{},"tf2-keras-cifar10-inceptionv3-elastic-20210721-042807":{},"tf2-keras-cifar10-inceptionv3-elastic-20210721-042910":{},"tf2-keras-cifar10-inceptionv3-elastic-20210721-043127":{},"tf2-keras-cifar10-inceptionv3-elastic-20210721-043226":{},"tf2-keras-cifar10-resnet50-elastic-20210721-043501":{},"tf2-keras-cifar10-resnet50-elastic-20210721-043527":{},"tf2-keras-cifar10-vgg16-elastic-20210721-043321":{},"tf2-keras-cifar10-vgg16-elastic-20210721-043423":{},"tf2-keras-transformer-elastic-20210721-043203":{},"tf2-keras-transformer-elastic-20210721-043343":{},"tf2-keras-transformer-elastic-20210721-043555":{}} "nodes"={"gpu3":{},"gpu4":{},"gpu5":{}} "scheduler"="default"
I0721 17:40:13.021066   31979 placement_manager.go:305]  "msg"="Found best-fit"  "crossNode"=0 "nodes"=[{},{},{}] "requests"=[{},{},{},{},{},{},{},{},{},{},{},{},{},{},{},{},{},{}] "scheduler"="default"
I0721 17:40:13.021443   31979 placement_manager.go:339]  "msg"="nodeStates updated"  "new"={"gpu3":{},"gpu4":{},"gpu5":{}} "old"={"gpu3":{},"gpu4":{},"gpu5":{}} "scheduler"="default" "score"=5
I0721 17:40:13.021835   31979 placement_manager.go:387]  "msg"="jobStates updated"  "new"={"tf2-keras-cifar10-inceptionv3-elastic-20210721-042550":{},"tf2-keras-cifar10-inceptionv3-elastic-20210721-042807":{},"tf2-keras-cifar10-inceptionv3-elastic-20210721-042910":{},"tf2-keras-cifar10-inceptionv3-elastic-20210721-043127":{},"tf2-keras-cifar10-inceptionv3-elastic-20210721-043226":{},"tf2-keras-cifar10-resnet50-elastic-20210721-043501":{},"tf2-keras-cifar10-resnet50-elastic-20210721-043527":{},"tf2-keras-transformer-elastic-20210721-043343":{},"tf2-keras-transformer-elastic-20210721-043555":{}} "old"={"tf2-keras-cifar10-inceptionv3-elastic-20210721-042550":{},"tf2-keras-cifar10-inceptionv3-elastic-20210721-042807":{},"tf2-keras-cifar10-inceptionv3-elastic-20210721-042910":{},"tf2-keras-cifar10-inceptionv3-elastic-20210721-043127":{},"tf2-keras-cifar10-inceptionv3-elastic-20210721-043226":{},"tf2-keras-cifar10-resnet50-elastic-20210721-043501":{},"tf2-keras-cifar10-resnet50-elastic-20210721-043527":{},"tf2-keras-cifar10-vgg16-elastic-20210721-043321":{},"tf2-keras-cifar10-vgg16-elastic-20210721-043423":{},"tf2-keras-transformer-elastic-20210721-043203":{},"tf2-keras-transformer-elastic-20210721-043343":{},"tf2-keras-transformer-elastic-20210721-043555":{}} "scheduler"="default"
I0721 17:40:13.022234   31979 placement_manager.go:434]  "msg"="podNodeName updated"  "launchersToDelete"=2 "new"={"tf2-keras-cifar10-inceptionv3-elastic-20210721-042550-worker-0":"gpu4","tf2-keras-cifar10-inceptionv3-elastic-20210721-042550-worker-1":"gpu4","tf2-keras-cifar10-inceptionv3-elastic-20210721-042807-worker-0":"gpu4","tf2-keras-cifar10-inceptionv3-elastic-20210721-042807-worker-1":"gpu4","tf2-keras-cifar10-inceptionv3-elastic-20210721-042910-worker-0":"gpu5","tf2-keras-cifar10-inceptionv3-elastic-20210721-042910-worker-1":"gpu5","tf2-keras-cifar10-inceptionv3-elastic-20210721-043127-worker-0":"gpu3","tf2-keras-cifar10-inceptionv3-elastic-20210721-043226-worker-0":"gpu3","tf2-keras-cifar10-resnet50-elastic-20210721-043501-worker-0":"gpu3","tf2-keras-cifar10-resnet50-elastic-20210721-043527-worker-0":"gpu5","tf2-keras-transformer-elastic-20210721-043343-worker-0":"gpu3","tf2-keras-transformer-elastic-20210721-043555-worker-0":"gpu5"} "old"={"tf2-keras-cifar10-inceptionv3-elastic-20210721-042550-worker-0":"gpu4","tf2-keras-cifar10-inceptionv3-elastic-20210721-042807-worker-0":"gpu5","tf2-keras-cifar10-inceptionv3-elastic-20210721-042910-worker-0":"gpu4","tf2-keras-cifar10-inceptionv3-elastic-20210721-043127-worker-0":"gpu5","tf2-keras-cifar10-inceptionv3-elastic-20210721-043226-worker-0":"gpu3","tf2-keras-cifar10-resnet50-elastic-20210721-043501-worker-0":"gpu4","tf2-keras-cifar10-resnet50-elastic-20210721-043527-worker-0":"gpu5","tf2-keras-cifar10-vgg16-elastic-20210721-043321-worker-0":"gpu3","tf2-keras-cifar10-vgg16-elastic-20210721-043423-worker-0":"gpu4","tf2-keras-transformer-elastic-20210721-043203-worker-0":"gpu3","tf2-keras-transformer-elastic-20210721-043343-worker-0":"gpu3","tf2-keras-transformer-elastic-20210721-043555-worker-0":"gpu5"} "scheduler"="default" "workersToDelete"=4
I0721 17:40:13.022560   31979 placement_manager.go:451]  "msg"="Deleting pod that need migration"  "podName"="tf2-keras-cifar10-inceptionv3-elastic-20210721-043127-worker-0" "scheduler"="default"
I0721 17:40:13.022655   31979 placement_manager.go:147]  "msg"="Adding toleration to pod"  "podName"="tf2-keras-cifar10-inceptionv3-elastic-20210721-042550-worker-1" "scheduler"="default" "toleration"={"key":"celeste/hostname","operator":"Equal","value":"gpu4","effect":"NoExecute"}
I0721 17:40:13.030619   31979 placement_manager.go:451]  "msg"="Deleting pod that need migration"  "podName"="tf2-keras-cifar10-inceptionv3-elastic-20210721-043127-launcher" "scheduler"="default"
I0721 17:40:13.035808   31979 placement_manager.go:451]  "msg"="Deleting pod that need migration"  "podName"="tf2-keras-cifar10-inceptionv3-elastic-20210721-042807-worker-0" "scheduler"="default"
I0721 17:40:13.040511   31979 placement_manager.go:451]  "msg"="Deleting pod that need migration"  "podName"="tf2-keras-cifar10-inceptionv3-elastic-20210721-042910-worker-0" "scheduler"="default"
I0721 17:40:13.043696   31979 placement_manager.go:451]  "msg"="Deleting pod that need migration"  "podName"="tf2-keras-cifar10-resnet50-elastic-20210721-043501-worker-0" "scheduler"="default"
I0721 17:40:13.046848   31979 placement_manager.go:451]  "msg"="Deleting pod that need migration"  "podName"="tf2-keras-cifar10-resnet50-elastic-20210721-043501-launcher" "scheduler"="default"
I0721 17:40:13.051033   31979 placement_manager.go:183]  "msg"="Finished job placements adjustment"  "scheduler"="default"
I0721 17:40:13.051311   31979 scheduler.go:182]  "msg"="Finished resched"  "scheduler"="default"
I0721 17:40:13.054852   31979 placement_manager.go:147]  "msg"="Adding toleration to pod"  "podName"="tf2-keras-cifar10-inceptionv3-elastic-20210721-042910-worker-1" "scheduler"="default" "toleration"={"key":"celeste/hostname","operator":"Equal","value":"gpu5","effect":"NoExecute"}
I0721 17:40:13.428327   31979 placement_manager.go:147]  "msg"="Adding toleration to pod"  "podName"="tf2-keras-cifar10-inceptionv3-elastic-20210721-042807-worker-1" "scheduler"="default" "toleration"={"key":"celeste/hostname","operator":"Equal","value":"gpu4","effect":"NoExecute"}
I0721 17:40:20.084107   31979 placement_manager.go:147]  "msg"="Adding toleration to pod"  "podName"="tf2-keras-cifar10-resnet50-elastic-20210721-043501-launcher" "scheduler"="default" "toleration"={"key":"celeste/hostname","operator":"Exists","effect":"NoExecute"}
I0721 17:40:25.267171   31979 placement_manager.go:147]  "msg"="Adding toleration to pod"  "podName"="tf2-keras-cifar10-resnet50-elastic-20210721-043501-worker-0" "scheduler"="default" "toleration"={"key":"celeste/hostname","operator":"Equal","value":"gpu3","effect":"NoExecute"}
I0721 17:40:29.750248   31979 placement_manager.go:147]  "msg"="Adding toleration to pod"  "podName"="tf2-keras-cifar10-inceptionv3-elastic-20210721-043127-worker-0" "scheduler"="default" "toleration"={"key":"celeste/hostname","operator":"Equal","value":"gpu3","effect":"NoExecute"}
I0721 17:40:29.788446   31979 placement_manager.go:147]  "msg"="Adding toleration to pod"  "podName"="tf2-keras-cifar10-inceptionv3-elastic-20210721-042807-worker-0" "scheduler"="default" "toleration"={"key":"celeste/hostname","operator":"Equal","value":"gpu4","effect":"NoExecute"}
I0721 17:40:34.586665   31979 placement_manager.go:147]  "msg"="Adding toleration to pod"  "podName"="tf2-keras-cifar10-inceptionv3-elastic-20210721-042910-worker-0" "scheduler"="default" "toleration"={"key":"celeste/hostname","operator":"Equal","value":"gpu5","effect":"NoExecute"}
I0721 17:40:34.846944   31979 placement_manager.go:147]  "msg"="Adding toleration to pod"  "podName"="tf2-keras-cifar10-inceptionv3-elastic-20210721-043127-launcher" "scheduler"="default" "toleration"={"key":"celeste/hostname","operator":"Exists","effect":"NoExecute"}
I0721 17:42:07.176452   31979 scheduler.go:474]  "msg"="Training job completed"  "elaspedTotalSeconds"=4023.625291469 "gpuTotalSeconds"=1530.054361067 "job"="tf2-keras-cifar10-resnet50-elastic-20210721-043501" "ranTotalSeconds"=1530.054361067 "scheduler"="default" "waitedTotalSeconds"=2493.570930402
I0721 17:42:07.176605   31979 scheduler.go:135]  "msg"="Received resched event, may be blocked because of rate limit"  "blockedUntil"="2021-07-21T17:42:13.051516718+08:00" "lastResched"="2021-07-21T17:40:13.051516718+08:00" "received"="2021-07-21T17:42:07.176483069+08:00" "scheduler"="default"
I0721 17:42:13.051578   31979 scheduler.go:159]  "msg"="Started resched"  "scheduler"="default"
I0721 17:42:13.051652   31979 scheduler.go:193]  "msg"="Updating all jobs info"  "scheduler"="default"
I0721 17:42:13.056411   31979 elastic_fifo.go:73]  "msg"="Finished scheduling"  "algorithm"="ElasticFIFO" "freeGpu"=0 "result"={"tf2-keras-cifar10-inceptionv3-elastic-20210721-042550":2,"tf2-keras-cifar10-inceptionv3-elastic-20210721-042807":2,"tf2-keras-cifar10-inceptionv3-elastic-20210721-042910":2,"tf2-keras-cifar10-inceptionv3-elastic-20210721-043127":2,"tf2-keras-cifar10-inceptionv3-elastic-20210721-043226":1,"tf2-keras-cifar10-resnet50-elastic-20210721-043527":1,"tf2-keras-transformer-elastic-20210721-043343":1,"tf2-keras-transformer-elastic-20210721-043555":1} "scheduler"="default"
I0721 17:42:13.056661   31979 scheduler.go:384]  "msg"="Trying to delete multiple training jobs"  "jobs"=[] "scheduler"="default"
I0721 17:42:13.056962   31979 scheduler.go:342]  "msg"="Trying to scale multiple training jobs"  "jobs"=[] "scheduler"="default"
I0721 17:42:13.057323   31979 scheduler.go:292]  "msg"="Trying to start multiple training jobs"  "jobs"=[] "scheduler"="default"
I0721 17:42:13.057598   31979 scheduler.go:342]  "msg"="Trying to scale multiple training jobs"  "jobs"=["tf2-keras-cifar10-inceptionv3-elastic-20210721-043127"] "scheduler"="default"
I0721 17:42:13.076057   31979 placement_manager.go:166]  "msg"="Started job placements adjustment"  "scheduler"="default"
I0721 17:42:13.076148   31979 placement_manager.go:192]  "msg"="Releasing slots"  "jobs"={"tf2-keras-cifar10-inceptionv3-elastic-20210721-042550":{},"tf2-keras-cifar10-inceptionv3-elastic-20210721-042807":{},"tf2-keras-cifar10-inceptionv3-elastic-20210721-042910":{},"tf2-keras-cifar10-inceptionv3-elastic-20210721-043127":{},"tf2-keras-cifar10-inceptionv3-elastic-20210721-043226":{},"tf2-keras-cifar10-resnet50-elastic-20210721-043501":{},"tf2-keras-cifar10-resnet50-elastic-20210721-043527":{},"tf2-keras-transformer-elastic-20210721-043343":{},"tf2-keras-transformer-elastic-20210721-043555":{}} "nodes"={"gpu3":{},"gpu4":{},"gpu5":{}} "scheduler"="default"
I0721 17:42:13.076216   31979 placement_manager.go:250]  "msg"="Released slots"  "jobs"={"tf2-keras-cifar10-inceptionv3-elastic-20210721-042550":{},"tf2-keras-cifar10-inceptionv3-elastic-20210721-042807":{},"tf2-keras-cifar10-inceptionv3-elastic-20210721-042910":{},"tf2-keras-cifar10-inceptionv3-elastic-20210721-043127":{},"tf2-keras-cifar10-inceptionv3-elastic-20210721-043226":{},"tf2-keras-cifar10-resnet50-elastic-20210721-043501":{},"tf2-keras-cifar10-resnet50-elastic-20210721-043527":{},"tf2-keras-transformer-elastic-20210721-043343":{},"tf2-keras-transformer-elastic-20210721-043555":{}} "nodes"={"gpu3":{},"gpu4":{},"gpu5":{}} "scheduler"="default"
I0721 17:42:13.076581   31979 placement_manager.go:305]  "msg"="Found best-fit"  "crossNode"=0 "nodes"=[{},{},{}] "requests"=[{},{},{},{},{},{},{},{},{},{},{},{},{},{},{},{}] "scheduler"="default"
I0721 17:42:13.076835   31979 placement_manager.go:339]  "msg"="nodeStates updated"  "new"={"gpu3":{},"gpu4":{},"gpu5":{}} "old"={"gpu3":{},"gpu4":{},"gpu5":{}} "scheduler"="default" "score"=8
I0721 17:42:13.077182   31979 placement_manager.go:387]  "msg"="jobStates updated"  "new"={"tf2-keras-cifar10-inceptionv3-elastic-20210721-042550":{},"tf2-keras-cifar10-inceptionv3-elastic-20210721-042807":{},"tf2-keras-cifar10-inceptionv3-elastic-20210721-042910":{},"tf2-keras-cifar10-inceptionv3-elastic-20210721-043127":{},"tf2-keras-cifar10-inceptionv3-elastic-20210721-043226":{},"tf2-keras-cifar10-resnet50-elastic-20210721-043527":{},"tf2-keras-transformer-elastic-20210721-043343":{},"tf2-keras-transformer-elastic-20210721-043555":{}} "old"={"tf2-keras-cifar10-inceptionv3-elastic-20210721-042550":{},"tf2-keras-cifar10-inceptionv3-elastic-20210721-042807":{},"tf2-keras-cifar10-inceptionv3-elastic-20210721-042910":{},"tf2-keras-cifar10-inceptionv3-elastic-20210721-043127":{},"tf2-keras-cifar10-inceptionv3-elastic-20210721-043226":{},"tf2-keras-cifar10-resnet50-elastic-20210721-043501":{},"tf2-keras-cifar10-resnet50-elastic-20210721-043527":{},"tf2-keras-transformer-elastic-20210721-043343":{},"tf2-keras-transformer-elastic-20210721-043555":{}} "scheduler"="default"
I0721 17:42:13.077704   31979 placement_manager.go:434]  "msg"="podNodeName updated"  "launchersToDelete"=2 "new"={"tf2-keras-cifar10-inceptionv3-elastic-20210721-042550-worker-0":"gpu4","tf2-keras-cifar10-inceptionv3-elastic-20210721-042550-worker-1":"gpu4","tf2-keras-cifar10-inceptionv3-elastic-20210721-042807-worker-0":"gpu4","tf2-keras-cifar10-inceptionv3-elastic-20210721-042807-worker-1":"gpu4","tf2-keras-cifar10-inceptionv3-elastic-20210721-042910-worker-0":"gpu5","tf2-keras-cifar10-inceptionv3-elastic-20210721-042910-worker-1":"gpu5","tf2-keras-cifar10-inceptionv3-elastic-20210721-043127-worker-0":"gpu5","tf2-keras-cifar10-inceptionv3-elastic-20210721-043127-worker-1":"gpu5","tf2-keras-cifar10-inceptionv3-elastic-20210721-043226-worker-0":"gpu3","tf2-keras-cifar10-resnet50-elastic-20210721-043527-worker-0":"gpu3","tf2-keras-transformer-elastic-20210721-043343-worker-0":"gpu3","tf2-keras-transformer-elastic-20210721-043555-worker-0":"gpu3"} "old"={"tf2-keras-cifar10-inceptionv3-elastic-20210721-042550-worker-0":"gpu4","tf2-keras-cifar10-inceptionv3-elastic-20210721-042550-worker-1":"gpu4","tf2-keras-cifar10-inceptionv3-elastic-20210721-042807-worker-0":"gpu4","tf2-keras-cifar10-inceptionv3-elastic-20210721-042807-worker-1":"gpu4","tf2-keras-cifar10-inceptionv3-elastic-20210721-042910-worker-0":"gpu5","tf2-keras-cifar10-inceptionv3-elastic-20210721-042910-worker-1":"gpu5","tf2-keras-cifar10-inceptionv3-elastic-20210721-043127-worker-0":"gpu3","tf2-keras-cifar10-inceptionv3-elastic-20210721-043226-worker-0":"gpu3","tf2-keras-cifar10-resnet50-elastic-20210721-043501-worker-0":"gpu3","tf2-keras-cifar10-resnet50-elastic-20210721-043527-worker-0":"gpu5","tf2-keras-transformer-elastic-20210721-043343-worker-0":"gpu3","tf2-keras-transformer-elastic-20210721-043555-worker-0":"gpu5"} "scheduler"="default" "workersToDelete"=3
I0721 17:42:13.078136   31979 placement_manager.go:451]  "msg"="Deleting pod that need migration"  "podName"="tf2-keras-cifar10-inceptionv3-elastic-20210721-043127-worker-0" "scheduler"="default"
I0721 17:42:13.082431   31979 placement_manager.go:451]  "msg"="Deleting pod that need migration"  "podName"="tf2-keras-cifar10-resnet50-elastic-20210721-043527-worker-0" "scheduler"="default"
I0721 17:42:13.087057   31979 placement_manager.go:451]  "msg"="Deleting pod that need migration"  "podName"="tf2-keras-cifar10-resnet50-elastic-20210721-043527-launcher" "scheduler"="default"
I0721 17:42:13.094756   31979 placement_manager.go:451]  "msg"="Deleting pod that need migration"  "podName"="tf2-keras-transformer-elastic-20210721-043555-worker-0" "scheduler"="default"
I0721 17:42:13.101941   31979 placement_manager.go:451]  "msg"="Deleting pod that need migration"  "podName"="tf2-keras-transformer-elastic-20210721-043555-launcher" "scheduler"="default"
I0721 17:42:13.111752   31979 placement_manager.go:183]  "msg"="Finished job placements adjustment"  "scheduler"="default"
I0721 17:42:13.112014   31979 scheduler.go:182]  "msg"="Finished resched"  "scheduler"="default"
I0721 17:42:13.116915   31979 placement_manager.go:147]  "msg"="Adding toleration to pod"  "podName"="tf2-keras-cifar10-inceptionv3-elastic-20210721-043127-worker-1" "scheduler"="default" "toleration"={"key":"celeste/hostname","operator":"Equal","value":"gpu5","effect":"NoExecute"}
I0721 17:42:20.534687   31979 placement_manager.go:147]  "msg"="Adding toleration to pod"  "podName"="tf2-keras-cifar10-resnet50-elastic-20210721-043527-launcher" "scheduler"="default" "toleration"={"key":"celeste/hostname","operator":"Exists","effect":"NoExecute"}
I0721 17:42:20.572880   31979 placement_manager.go:147]  "msg"="Adding toleration to pod"  "podName"="tf2-keras-transformer-elastic-20210721-043555-worker-0" "scheduler"="default" "toleration"={"key":"celeste/hostname","operator":"Equal","value":"gpu3","effect":"NoExecute"}
I0721 17:42:24.603193   31979 placement_manager.go:147]  "msg"="Adding toleration to pod"  "podName"="tf2-keras-transformer-elastic-20210721-043555-launcher" "scheduler"="default" "toleration"={"key":"celeste/hostname","operator":"Exists","effect":"NoExecute"}
I0721 17:42:29.738156   31979 placement_manager.go:147]  "msg"="Adding toleration to pod"  "podName"="tf2-keras-cifar10-resnet50-elastic-20210721-043527-worker-0" "scheduler"="default" "toleration"={"key":"celeste/hostname","operator":"Equal","value":"gpu3","effect":"NoExecute"}
I0721 17:42:30.025397   31979 placement_manager.go:147]  "msg"="Adding toleration to pod"  "podName"="tf2-keras-cifar10-inceptionv3-elastic-20210721-043127-worker-0" "scheduler"="default" "toleration"={"key":"celeste/hostname","operator":"Equal","value":"gpu5","effect":"NoExecute"}
I0721 17:44:15.373342   31979 scheduler.go:474]  "msg"="Training job completed"  "elaspedTotalSeconds"=4563.376893268 "gpuTotalSeconds"=4755.593017909 "job"="tf2-keras-cifar10-inceptionv3-elastic-20210721-042807" "ranTotalSeconds"=4515.584825318 "scheduler"="default" "waitedTotalSeconds"=47.79206795
I0721 17:44:15.373495   31979 scheduler.go:135]  "msg"="Received resched event, may be blocked because of rate limit"  "blockedUntil"="2021-07-21T17:44:13.112219856+08:00" "lastResched"="2021-07-21T17:42:13.112219856+08:00" "received"="2021-07-21T17:44:15.373381773+08:00" "scheduler"="default"
I0721 17:44:15.373941   31979 scheduler.go:159]  "msg"="Started resched"  "scheduler"="default"
I0721 17:44:15.373972   31979 scheduler.go:193]  "msg"="Updating all jobs info"  "scheduler"="default"
I0721 17:44:15.378900   31979 elastic_fifo.go:73]  "msg"="Finished scheduling"  "algorithm"="ElasticFIFO" "freeGpu"=0 "result"={"tf2-keras-cifar10-inceptionv3-elastic-20210721-042550":2,"tf2-keras-cifar10-inceptionv3-elastic-20210721-042910":2,"tf2-keras-cifar10-inceptionv3-elastic-20210721-043127":2,"tf2-keras-cifar10-inceptionv3-elastic-20210721-043226":2,"tf2-keras-cifar10-resnet50-elastic-20210721-043527":1,"tf2-keras-transformer-elastic-20210721-043343":2,"tf2-keras-transformer-elastic-20210721-043555":1} "scheduler"="default"
I0721 17:44:15.379214   31979 scheduler.go:384]  "msg"="Trying to delete multiple training jobs"  "jobs"=[] "scheduler"="default"
I0721 17:44:15.379464   31979 scheduler.go:342]  "msg"="Trying to scale multiple training jobs"  "jobs"=[] "scheduler"="default"
I0721 17:44:15.379749   31979 scheduler.go:292]  "msg"="Trying to start multiple training jobs"  "jobs"=[] "scheduler"="default"
I0721 17:44:15.379989   31979 scheduler.go:342]  "msg"="Trying to scale multiple training jobs"  "jobs"=["tf2-keras-cifar10-inceptionv3-elastic-20210721-043226","tf2-keras-transformer-elastic-20210721-043343"] "scheduler"="default"
I0721 17:44:15.409345   31979 placement_manager.go:166]  "msg"="Started job placements adjustment"  "scheduler"="default"
I0721 17:44:15.409427   31979 placement_manager.go:192]  "msg"="Releasing slots"  "jobs"={"tf2-keras-cifar10-inceptionv3-elastic-20210721-042550":{},"tf2-keras-cifar10-inceptionv3-elastic-20210721-042807":{},"tf2-keras-cifar10-inceptionv3-elastic-20210721-042910":{},"tf2-keras-cifar10-inceptionv3-elastic-20210721-043127":{},"tf2-keras-cifar10-inceptionv3-elastic-20210721-043226":{},"tf2-keras-cifar10-resnet50-elastic-20210721-043527":{},"tf2-keras-transformer-elastic-20210721-043343":{},"tf2-keras-transformer-elastic-20210721-043555":{}} "nodes"={"gpu3":{},"gpu4":{},"gpu5":{}} "scheduler"="default"
I0721 17:44:15.409493   31979 placement_manager.go:250]  "msg"="Released slots"  "jobs"={"tf2-keras-cifar10-inceptionv3-elastic-20210721-042550":{},"tf2-keras-cifar10-inceptionv3-elastic-20210721-042807":{},"tf2-keras-cifar10-inceptionv3-elastic-20210721-042910":{},"tf2-keras-cifar10-inceptionv3-elastic-20210721-043127":{},"tf2-keras-cifar10-inceptionv3-elastic-20210721-043226":{},"tf2-keras-cifar10-resnet50-elastic-20210721-043527":{},"tf2-keras-transformer-elastic-20210721-043343":{},"tf2-keras-transformer-elastic-20210721-043555":{}} "nodes"={"gpu3":{},"gpu4":{},"gpu5":{}} "scheduler"="default"
I0721 17:44:15.410005   31979 placement_manager.go:305]  "msg"="Found best-fit"  "crossNode"=0 "nodes"=[{},{},{}] "requests"=[{},{},{},{},{},{},{},{},{},{},{},{},{},{}] "scheduler"="default"
I0721 17:44:15.410382   31979 placement_manager.go:339]  "msg"="nodeStates updated"  "new"={"gpu3":{},"gpu4":{},"gpu5":{}} "old"={"gpu3":{},"gpu4":{},"gpu5":{}} "scheduler"="default" "score"=7
I0721 17:44:15.410748   31979 placement_manager.go:387]  "msg"="jobStates updated"  "new"={"tf2-keras-cifar10-inceptionv3-elastic-20210721-042550":{},"tf2-keras-cifar10-inceptionv3-elastic-20210721-042910":{},"tf2-keras-cifar10-inceptionv3-elastic-20210721-043127":{},"tf2-keras-cifar10-inceptionv3-elastic-20210721-043226":{},"tf2-keras-cifar10-resnet50-elastic-20210721-043527":{},"tf2-keras-transformer-elastic-20210721-043343":{},"tf2-keras-transformer-elastic-20210721-043555":{}} "old"={"tf2-keras-cifar10-inceptionv3-elastic-20210721-042550":{},"tf2-keras-cifar10-inceptionv3-elastic-20210721-042807":{},"tf2-keras-cifar10-inceptionv3-elastic-20210721-042910":{},"tf2-keras-cifar10-inceptionv3-elastic-20210721-043127":{},"tf2-keras-cifar10-inceptionv3-elastic-20210721-043226":{},"tf2-keras-cifar10-resnet50-elastic-20210721-043527":{},"tf2-keras-transformer-elastic-20210721-043343":{},"tf2-keras-transformer-elastic-20210721-043555":{}} "scheduler"="default"
I0721 17:44:15.411172   31979 placement_manager.go:434]  "msg"="podNodeName updated"  "launchersToDelete"=1 "new"={"tf2-keras-cifar10-inceptionv3-elastic-20210721-042550-worker-0":"gpu4","tf2-keras-cifar10-inceptionv3-elastic-20210721-042550-worker-1":"gpu4","tf2-keras-cifar10-inceptionv3-elastic-20210721-042910-worker-0":"gpu4","tf2-keras-cifar10-inceptionv3-elastic-20210721-042910-worker-1":"gpu4","tf2-keras-cifar10-inceptionv3-elastic-20210721-043127-worker-0":"gpu5","tf2-keras-cifar10-inceptionv3-elastic-20210721-043127-worker-1":"gpu5","tf2-keras-cifar10-inceptionv3-elastic-20210721-043226-worker-0":"gpu5","tf2-keras-cifar10-inceptionv3-elastic-20210721-043226-worker-1":"gpu5","tf2-keras-cifar10-resnet50-elastic-20210721-043527-worker-0":"gpu3","tf2-keras-transformer-elastic-20210721-043343-worker-0":"gpu3","tf2-keras-transformer-elastic-20210721-043343-worker-1":"gpu3","tf2-keras-transformer-elastic-20210721-043555-worker-0":"gpu3"} "old"={"tf2-keras-cifar10-inceptionv3-elastic-20210721-042550-worker-0":"gpu4","tf2-keras-cifar10-inceptionv3-elastic-20210721-042550-worker-1":"gpu4","tf2-keras-cifar10-inceptionv3-elastic-20210721-042807-worker-0":"gpu4","tf2-keras-cifar10-inceptionv3-elastic-20210721-042807-worker-1":"gpu4","tf2-keras-cifar10-inceptionv3-elastic-20210721-042910-worker-0":"gpu5","tf2-keras-cifar10-inceptionv3-elastic-20210721-042910-worker-1":"gpu5","tf2-keras-cifar10-inceptionv3-elastic-20210721-043127-worker-0":"gpu5","tf2-keras-cifar10-inceptionv3-elastic-20210721-043127-worker-1":"gpu5","tf2-keras-cifar10-inceptionv3-elastic-20210721-043226-worker-0":"gpu3","tf2-keras-cifar10-resnet50-elastic-20210721-043527-worker-0":"gpu3","tf2-keras-transformer-elastic-20210721-043343-worker-0":"gpu3","tf2-keras-transformer-elastic-20210721-043555-worker-0":"gpu3"} "scheduler"="default" "workersToDelete"=3
I0721 17:44:15.411664   31979 placement_manager.go:451]  "msg"="Deleting pod that need migration"  "podName"="tf2-keras-cifar10-inceptionv3-elastic-20210721-043226-worker-0" "scheduler"="default"
I0721 17:44:15.415840   31979 placement_manager.go:451]  "msg"="Deleting pod that need migration"  "podName"="tf2-keras-cifar10-inceptionv3-elastic-20210721-042910-worker-0" "scheduler"="default"
I0721 17:44:15.418574   31979 placement_manager.go:147]  "msg"="Adding toleration to pod"  "podName"="tf2-keras-cifar10-inceptionv3-elastic-20210721-043226-worker-1" "scheduler"="default" "toleration"={"key":"celeste/hostname","operator":"Equal","value":"gpu5","effect":"NoExecute"}
I0721 17:44:15.419834   31979 placement_manager.go:451]  "msg"="Deleting pod that need migration"  "podName"="tf2-keras-cifar10-inceptionv3-elastic-20210721-042910-worker-1" "scheduler"="default"
I0721 17:44:15.429569   31979 placement_manager.go:451]  "msg"="Deleting pod that need migration"  "podName"="tf2-keras-cifar10-inceptionv3-elastic-20210721-042910-launcher" "scheduler"="default"
I0721 17:44:15.435741   31979 placement_manager.go:183]  "msg"="Finished job placements adjustment"  "scheduler"="default"
I0721 17:44:15.436059   31979 scheduler.go:182]  "msg"="Finished resched"  "scheduler"="default"
I0721 17:44:15.763625   31979 placement_manager.go:147]  "msg"="Adding toleration to pod"  "podName"="tf2-keras-transformer-elastic-20210721-043343-worker-1" "scheduler"="default" "toleration"={"key":"celeste/hostname","operator":"Equal","value":"gpu3","effect":"NoExecute"}
I0721 17:44:22.521512   31979 placement_manager.go:147]  "msg"="Adding toleration to pod"  "podName"="tf2-keras-cifar10-inceptionv3-elastic-20210721-042910-worker-0" "scheduler"="default" "toleration"={"key":"celeste/hostname","operator":"Equal","value":"gpu4","effect":"NoExecute"}
I0721 17:44:22.563603   31979 placement_manager.go:147]  "msg"="Adding toleration to pod"  "podName"="tf2-keras-cifar10-inceptionv3-elastic-20210721-042910-worker-1" "scheduler"="default" "toleration"={"key":"celeste/hostname","operator":"Equal","value":"gpu4","effect":"NoExecute"}
I0721 17:44:29.280200   31979 placement_manager.go:147]  "msg"="Adding toleration to pod"  "podName"="tf2-keras-cifar10-inceptionv3-elastic-20210721-043226-worker-0" "scheduler"="default" "toleration"={"key":"celeste/hostname","operator":"Equal","value":"gpu5","effect":"NoExecute"}
I0721 17:44:29.324632   31979 placement_manager.go:147]  "msg"="Adding toleration to pod"  "podName"="tf2-keras-cifar10-inceptionv3-elastic-20210721-042910-launcher" "scheduler"="default" "toleration"={"key":"celeste/hostname","operator":"Exists","effect":"NoExecute"}
I0721 17:44:32.631515   31979 scheduler.go:474]  "msg"="Training job completed"  "elaspedTotalSeconds"=4719.977622705 "gpuTotalSeconds"=5155.870263117 "job"="tf2-keras-cifar10-inceptionv3-elastic-20210721-042550" "ranTotalSeconds"=4655.589518508 "scheduler"="default" "waitedTotalSeconds"=64.388104197
I0721 17:44:32.631686   31979 scheduler.go:135]  "msg"="Received resched event, may be blocked because of rate limit"  "blockedUntil"="2021-07-21T17:46:15.436346551+08:00" "lastResched"="2021-07-21T17:44:15.436346551+08:00" "received"="2021-07-21T17:44:32.631572764+08:00" "scheduler"="default"
I0721 17:46:09.968577   31979 scheduler.go:474]  "msg"="Training job completed"  "elaspedTotalSeconds"=4614.553858102 "gpuTotalSeconds"=4865.331304406 "job"="tf2-keras-cifar10-inceptionv3-elastic-20210721-042910" "ranTotalSeconds"=4510.320008074 "scheduler"="default" "waitedTotalSeconds"=104.233850028
I0721 17:46:15.436435   31979 scheduler.go:159]  "msg"="Started resched"  "scheduler"="default"
I0721 17:46:15.436524   31979 scheduler.go:193]  "msg"="Updating all jobs info"  "scheduler"="default"
I0721 17:46:15.440769   31979 elastic_fifo.go:73]  "msg"="Finished scheduling"  "algorithm"="ElasticFIFO" "freeGpu"=0 "result"={"tf2-keras-cifar10-inceptionv3-elastic-20210721-043127":3,"tf2-keras-cifar10-inceptionv3-elastic-20210721-043226":3,"tf2-keras-cifar10-resnet50-elastic-20210721-043527":2,"tf2-keras-transformer-elastic-20210721-043343":2,"tf2-keras-transformer-elastic-20210721-043555":2} "scheduler"="default"
I0721 17:46:15.441123   31979 scheduler.go:384]  "msg"="Trying to delete multiple training jobs"  "jobs"=[] "scheduler"="default"
I0721 17:46:15.441358   31979 scheduler.go:342]  "msg"="Trying to scale multiple training jobs"  "jobs"=[] "scheduler"="default"
I0721 17:46:15.441522   31979 scheduler.go:292]  "msg"="Trying to start multiple training jobs"  "jobs"=[] "scheduler"="default"
I0721 17:46:15.441741   31979 scheduler.go:342]  "msg"="Trying to scale multiple training jobs"  "jobs"=["tf2-keras-cifar10-inceptionv3-elastic-20210721-043127","tf2-keras-cifar10-inceptionv3-elastic-20210721-043226","tf2-keras-cifar10-resnet50-elastic-20210721-043527","tf2-keras-transformer-elastic-20210721-043555"] "scheduler"="default"
I0721 17:46:15.500717   31979 placement_manager.go:166]  "msg"="Started job placements adjustment"  "scheduler"="default"
I0721 17:46:15.500872   31979 placement_manager.go:192]  "msg"="Releasing slots"  "jobs"={"tf2-keras-cifar10-inceptionv3-elastic-20210721-042550":{},"tf2-keras-cifar10-inceptionv3-elastic-20210721-042910":{},"tf2-keras-cifar10-inceptionv3-elastic-20210721-043127":{},"tf2-keras-cifar10-inceptionv3-elastic-20210721-043226":{},"tf2-keras-cifar10-resnet50-elastic-20210721-043527":{},"tf2-keras-transformer-elastic-20210721-043343":{},"tf2-keras-transformer-elastic-20210721-043555":{}} "nodes"={"gpu3":{},"gpu4":{},"gpu5":{}} "scheduler"="default"
I0721 17:46:15.500954   31979 placement_manager.go:250]  "msg"="Released slots"  "jobs"={"tf2-keras-cifar10-inceptionv3-elastic-20210721-042550":{},"tf2-keras-cifar10-inceptionv3-elastic-20210721-042910":{},"tf2-keras-cifar10-inceptionv3-elastic-20210721-043127":{},"tf2-keras-cifar10-inceptionv3-elastic-20210721-043226":{},"tf2-keras-cifar10-resnet50-elastic-20210721-043527":{},"tf2-keras-transformer-elastic-20210721-043343":{},"tf2-keras-transformer-elastic-20210721-043555":{}} "nodes"={"gpu3":{},"gpu4":{},"gpu5":{}} "scheduler"="default"
I0721 17:46:15.501430   31979 placement_manager.go:305]  "msg"="Found best-fit"  "crossNode"=0 "nodes"=[{},{},{}] "requests"=[{},{},{},{},{},{},{},{},{},{}] "scheduler"="default"
I0721 17:46:15.501878   31979 placement_manager.go:339]  "msg"="nodeStates updated"  "new"={"gpu3":{},"gpu4":{},"gpu5":{}} "old"={"gpu3":{},"gpu4":{},"gpu5":{}} "scheduler"="default" "score"=5
I0721 17:46:15.502364   31979 placement_manager.go:387]  "msg"="jobStates updated"  "new"={"tf2-keras-cifar10-inceptionv3-elastic-20210721-043127":{},"tf2-keras-cifar10-inceptionv3-elastic-20210721-043226":{},"tf2-keras-cifar10-resnet50-elastic-20210721-043527":{},"tf2-keras-transformer-elastic-20210721-043343":{},"tf2-keras-transformer-elastic-20210721-043555":{}} "old"={"tf2-keras-cifar10-inceptionv3-elastic-20210721-042550":{},"tf2-keras-cifar10-inceptionv3-elastic-20210721-042910":{},"tf2-keras-cifar10-inceptionv3-elastic-20210721-043127":{},"tf2-keras-cifar10-inceptionv3-elastic-20210721-043226":{},"tf2-keras-cifar10-resnet50-elastic-20210721-043527":{},"tf2-keras-transformer-elastic-20210721-043343":{},"tf2-keras-transformer-elastic-20210721-043555":{}} "scheduler"="default"
I0721 17:46:15.503032   31979 placement_manager.go:434]  "msg"="podNodeName updated"  "launchersToDelete"=0 "new"={"tf2-keras-cifar10-inceptionv3-elastic-20210721-043127-worker-0":"gpu4","tf2-keras-cifar10-inceptionv3-elastic-20210721-043127-worker-1":"gpu4","tf2-keras-cifar10-inceptionv3-elastic-20210721-043127-worker-2":"gpu4","tf2-keras-cifar10-inceptionv3-elastic-20210721-043226-worker-0":"gpu5","tf2-keras-cifar10-inceptionv3-elastic-20210721-043226-worker-1":"gpu5","tf2-keras-cifar10-inceptionv3-elastic-20210721-043226-worker-2":"gpu5","tf2-keras-cifar10-resnet50-elastic-20210721-043527-worker-0":"gpu3","tf2-keras-cifar10-resnet50-elastic-20210721-043527-worker-1":"gpu3","tf2-keras-transformer-elastic-20210721-043343-worker-0":"gpu3","tf2-keras-transformer-elastic-20210721-043343-worker-1":"gpu3","tf2-keras-transformer-elastic-20210721-043555-worker-0":"gpu5","tf2-keras-transformer-elastic-20210721-043555-worker-1":"gpu4","tf2-keras-transformer-elastic-20210721-043555-worker-2":"gpu4"} "old"={"tf2-keras-cifar10-inceptionv3-elastic-20210721-042550-worker-0":"gpu4","tf2-keras-cifar10-inceptionv3-elastic-20210721-042550-worker-1":"gpu4","tf2-keras-cifar10-inceptionv3-elastic-20210721-042910-worker-0":"gpu4","tf2-keras-cifar10-inceptionv3-elastic-20210721-042910-worker-1":"gpu4","tf2-keras-cifar10-inceptionv3-elastic-20210721-043127-worker-0":"gpu5","tf2-keras-cifar10-inceptionv3-elastic-20210721-043127-worker-1":"gpu5","tf2-keras-cifar10-inceptionv3-elastic-20210721-043226-worker-0":"gpu5","tf2-keras-cifar10-inceptionv3-elastic-20210721-043226-worker-1":"gpu5","tf2-keras-cifar10-resnet50-elastic-20210721-043527-worker-0":"gpu3","tf2-keras-transformer-elastic-20210721-043343-worker-0":"gpu3","tf2-keras-transformer-elastic-20210721-043343-worker-1":"gpu3","tf2-keras-transformer-elastic-20210721-043555-worker-0":"gpu3"} "scheduler"="default" "workersToDelete"=3
I0721 17:46:15.503557   31979 placement_manager.go:451]  "msg"="Deleting pod that need migration"  "podName"="tf2-keras-cifar10-inceptionv3-elastic-20210721-043127-worker-0" "scheduler"="default"
I0721 17:46:15.503650   31979 placement_manager.go:147]  "msg"="Adding toleration to pod"  "podName"="tf2-keras-cifar10-inceptionv3-elastic-20210721-043226-worker-2" "scheduler"="default" "toleration"={"key":"celeste/hostname","operator":"Equal","value":"gpu5","effect":"NoExecute"}
I0721 17:46:15.507871   31979 placement_manager.go:451]  "msg"="Deleting pod that need migration"  "podName"="tf2-keras-cifar10-inceptionv3-elastic-20210721-043127-worker-1" "scheduler"="default"
I0721 17:46:15.513577   31979 placement_manager.go:451]  "msg"="Deleting pod that need migration"  "podName"="tf2-keras-transformer-elastic-20210721-043555-worker-0" "scheduler"="default"
I0721 17:46:15.517645   31979 placement_manager.go:183]  "msg"="Finished job placements adjustment"  "scheduler"="default"
I0721 17:46:15.517943   31979 scheduler.go:182]  "msg"="Finished resched"  "scheduler"="default"
I0721 17:46:15.530934   31979 placement_manager.go:147]  "msg"="Adding toleration to pod"  "podName"="tf2-keras-cifar10-resnet50-elastic-20210721-043527-worker-1" "scheduler"="default" "toleration"={"key":"celeste/hostname","operator":"Equal","value":"gpu3","effect":"NoExecute"}
I0721 17:46:16.872608   31979 placement_manager.go:147]  "msg"="Adding toleration to pod"  "podName"="tf2-keras-transformer-elastic-20210721-043555-worker-1" "scheduler"="default" "toleration"={"key":"celeste/hostname","operator":"Equal","value":"gpu4","effect":"NoExecute"}
I0721 17:46:29.785375   31979 placement_manager.go:147]  "msg"="Adding toleration to pod"  "podName"="tf2-keras-transformer-elastic-20210721-043555-worker-0" "scheduler"="default" "toleration"={"key":"celeste/hostname","operator":"Equal","value":"gpu5","effect":"NoExecute"}
I0721 17:46:30.581524   31979 placement_manager.go:147]  "msg"="Adding toleration to pod"  "podName"="tf2-keras-cifar10-inceptionv3-elastic-20210721-043127-worker-1" "scheduler"="default" "toleration"={"key":"celeste/hostname","operator":"Equal","value":"gpu4","effect":"NoExecute"}
I0721 17:46:31.373072   31979 placement_manager.go:147]  "msg"="Adding toleration to pod"  "podName"="tf2-keras-cifar10-inceptionv3-elastic-20210721-043127-worker-0" "scheduler"="default" "toleration"={"key":"celeste/hostname","operator":"Equal","value":"gpu4","effect":"NoExecute"}
I0721 17:52:42.626590   31979 scheduler.go:474]  "msg"="Training job completed"  "elaspedTotalSeconds"=4737.433833825 "gpuTotalSeconds"=2795.096696289 "job"="tf2-keras-transformer-elastic-20210721-043343" "ranTotalSeconds"=2285.079214157 "scheduler"="default" "waitedTotalSeconds"=2452.354619668
I0721 17:52:42.626744   31979 scheduler.go:135]  "msg"="Received resched event, may be blocked because of rate limit"  "blockedUntil"="2021-07-21T17:48:15.518211272+08:00" "lastResched"="2021-07-21T17:46:15.518211272+08:00" "received"="2021-07-21T17:52:42.626626121+08:00" "scheduler"="default"
I0721 17:52:42.627140   31979 scheduler.go:159]  "msg"="Started resched"  "scheduler"="default"
I0721 17:52:42.627211   31979 scheduler.go:193]  "msg"="Updating all jobs info"  "scheduler"="default"
I0721 17:52:42.630507   31979 elastic_fifo.go:73]  "msg"="Finished scheduling"  "algorithm"="ElasticFIFO" "freeGpu"=0 "result"={"tf2-keras-cifar10-inceptionv3-elastic-20210721-043127":3,"tf2-keras-cifar10-inceptionv3-elastic-20210721-043226":3,"tf2-keras-cifar10-resnet50-elastic-20210721-043527":3,"tf2-keras-transformer-elastic-20210721-043555":3} "scheduler"="default"
I0721 17:52:42.630790   31979 scheduler.go:384]  "msg"="Trying to delete multiple training jobs"  "jobs"=[] "scheduler"="default"
I0721 17:52:42.631054   31979 scheduler.go:342]  "msg"="Trying to scale multiple training jobs"  "jobs"=[] "scheduler"="default"
I0721 17:52:42.631287   31979 scheduler.go:292]  "msg"="Trying to start multiple training jobs"  "jobs"=[] "scheduler"="default"
I0721 17:52:42.631492   31979 scheduler.go:342]  "msg"="Trying to scale multiple training jobs"  "jobs"=["tf2-keras-cifar10-resnet50-elastic-20210721-043527","tf2-keras-transformer-elastic-20210721-043555"] "scheduler"="default"
I0721 17:52:42.669815   31979 placement_manager.go:166]  "msg"="Started job placements adjustment"  "scheduler"="default"
I0721 17:52:42.669910   31979 placement_manager.go:192]  "msg"="Releasing slots"  "jobs"={"tf2-keras-cifar10-inceptionv3-elastic-20210721-043127":{},"tf2-keras-cifar10-inceptionv3-elastic-20210721-043226":{},"tf2-keras-cifar10-resnet50-elastic-20210721-043527":{},"tf2-keras-transformer-elastic-20210721-043343":{},"tf2-keras-transformer-elastic-20210721-043555":{}} "nodes"={"gpu3":{},"gpu4":{},"gpu5":{}} "scheduler"="default"
I0721 17:52:42.670001   31979 placement_manager.go:250]  "msg"="Released slots"  "jobs"={"tf2-keras-cifar10-inceptionv3-elastic-20210721-043127":{},"tf2-keras-cifar10-inceptionv3-elastic-20210721-043226":{},"tf2-keras-cifar10-resnet50-elastic-20210721-043527":{},"tf2-keras-transformer-elastic-20210721-043343":{},"tf2-keras-transformer-elastic-20210721-043555":{}} "nodes"={"gpu3":{},"gpu4":{},"gpu5":{}} "scheduler"="default"
I0721 17:52:42.670401   31979 placement_manager.go:305]  "msg"="Found best-fit"  "crossNode"=0 "nodes"=[{},{},{}] "requests"=[{},{},{},{},{},{},{},{}] "scheduler"="default"
I0721 17:52:42.670721   31979 placement_manager.go:339]  "msg"="nodeStates updated"  "new"={"gpu3":{},"gpu4":{},"gpu5":{}} "old"={"gpu3":{},"gpu4":{},"gpu5":{}} "scheduler"="default" "score"=10
I0721 17:52:42.671012   31979 placement_manager.go:387]  "msg"="jobStates updated"  "new"={"tf2-keras-cifar10-inceptionv3-elastic-20210721-043127":{},"tf2-keras-cifar10-inceptionv3-elastic-20210721-043226":{},"tf2-keras-cifar10-resnet50-elastic-20210721-043527":{},"tf2-keras-transformer-elastic-20210721-043555":{}} "old"={"tf2-keras-cifar10-inceptionv3-elastic-20210721-043127":{},"tf2-keras-cifar10-inceptionv3-elastic-20210721-043226":{},"tf2-keras-cifar10-resnet50-elastic-20210721-043527":{},"tf2-keras-transformer-elastic-20210721-043343":{},"tf2-keras-transformer-elastic-20210721-043555":{}} "scheduler"="default"
I0721 17:52:42.671467   31979 placement_manager.go:434]  "msg"="podNodeName updated"  "launchersToDelete"=0 "new"={"tf2-keras-cifar10-inceptionv3-elastic-20210721-043127-worker-0":"gpu4","tf2-keras-cifar10-inceptionv3-elastic-20210721-043127-worker-1":"gpu4","tf2-keras-cifar10-inceptionv3-elastic-20210721-043127-worker-2":"gpu4","tf2-keras-cifar10-inceptionv3-elastic-20210721-043226-worker-0":"gpu5","tf2-keras-cifar10-inceptionv3-elastic-20210721-043226-worker-1":"gpu5","tf2-keras-cifar10-inceptionv3-elastic-20210721-043226-worker-2":"gpu5","tf2-keras-cifar10-resnet50-elastic-20210721-043527-worker-0":"gpu3","tf2-keras-cifar10-resnet50-elastic-20210721-043527-worker-1":"gpu3","tf2-keras-cifar10-resnet50-elastic-20210721-043527-worker-2":"gpu3","tf2-keras-transformer-elastic-20210721-043555-worker-0":"gpu4","tf2-keras-transformer-elastic-20210721-043555-worker-1":"gpu5","tf2-keras-transformer-elastic-20210721-043555-worker-2":"gpu3","tf2-keras-transformer-elastic-20210721-043555-worker-3":"gpu3","tf2-keras-transformer-elastic-20210721-043555-worker-4":"gpu3"} "old"={"tf2-keras-cifar10-inceptionv3-elastic-20210721-043127-worker-0":"gpu4","tf2-keras-cifar10-inceptionv3-elastic-20210721-043127-worker-1":"gpu4","tf2-keras-cifar10-inceptionv3-elastic-20210721-043127-worker-2":"gpu4","tf2-keras-cifar10-inceptionv3-elastic-20210721-043226-worker-0":"gpu5","tf2-keras-cifar10-inceptionv3-elastic-20210721-043226-worker-1":"gpu5","tf2-keras-cifar10-inceptionv3-elastic-20210721-043226-worker-2":"gpu5","tf2-keras-cifar10-resnet50-elastic-20210721-043527-worker-0":"gpu3","tf2-keras-cifar10-resnet50-elastic-20210721-043527-worker-1":"gpu3","tf2-keras-transformer-elastic-20210721-043343-worker-0":"gpu3","tf2-keras-transformer-elastic-20210721-043343-worker-1":"gpu3","tf2-keras-transformer-elastic-20210721-043555-worker-0":"gpu5","tf2-keras-transformer-elastic-20210721-043555-worker-1":"gpu4","tf2-keras-transformer-elastic-20210721-043555-worker-2":"gpu4"} "scheduler"="default" "workersToDelete"=3
I0721 17:52:42.671854   31979 placement_manager.go:451]  "msg"="Deleting pod that need migration"  "podName"="tf2-keras-transformer-elastic-20210721-043555-worker-0" "scheduler"="default"
I0721 17:52:42.676076   31979 placement_manager.go:451]  "msg"="Deleting pod that need migration"  "podName"="tf2-keras-transformer-elastic-20210721-043555-worker-1" "scheduler"="default"
I0721 17:52:42.679745   31979 placement_manager.go:147]  "msg"="Adding toleration to pod"  "podName"="tf2-keras-cifar10-resnet50-elastic-20210721-043527-worker-2" "scheduler"="default" "toleration"={"key":"celeste/hostname","operator":"Equal","value":"gpu3","effect":"NoExecute"}
I0721 17:52:42.680720   31979 placement_manager.go:451]  "msg"="Deleting pod that need migration"  "podName"="tf2-keras-transformer-elastic-20210721-043555-worker-2" "scheduler"="default"
E0721 17:52:42.697868   31979 placement_manager.go:455]  "msg"="Failed to delete pod" "error"="pods \"tf2-keras-transformer-elastic-20210721-043555-worker-2\" not found"  "podName"="tf2-keras-transformer-elastic-20210721-043555-worker-2" "scheduler"="default"
I0721 17:52:42.698328   31979 placement_manager.go:183]  "msg"="Finished job placements adjustment"  "scheduler"="default"
I0721 17:52:42.698536   31979 scheduler.go:182]  "msg"="Finished resched"  "scheduler"="default"
I0721 17:52:43.217872   31979 placement_manager.go:147]  "msg"="Adding toleration to pod"  "podName"="tf2-keras-transformer-elastic-20210721-043555-worker-2" "scheduler"="default" "toleration"={"key":"celeste/hostname","operator":"Equal","value":"gpu3","effect":"NoExecute"}
I0721 17:52:49.801721   31979 placement_manager.go:147]  "msg"="Adding toleration to pod"  "podName"="tf2-keras-transformer-elastic-20210721-043555-worker-0" "scheduler"="default" "toleration"={"key":"celeste/hostname","operator":"Equal","value":"gpu4","effect":"NoExecute"}
I0721 17:52:55.246793   31979 placement_manager.go:147]  "msg"="Adding toleration to pod"  "podName"="tf2-keras-transformer-elastic-20210721-043555-worker-1" "scheduler"="default" "toleration"={"key":"celeste/hostname","operator":"Equal","value":"gpu5","effect":"NoExecute"}
I0721 17:55:17.884809   31979 scheduler.go:474]  "msg"="Training job completed"  "elaspedTotalSeconds"=4969.067140027 "gpuTotalSeconds"=4640.163047678 "job"="tf2-keras-cifar10-inceptionv3-elastic-20210721-043226" "ranTotalSeconds"=3430.119856338 "scheduler"="default" "waitedTotalSeconds"=1538.947283689
I0721 17:55:17.884958   31979 scheduler.go:135]  "msg"="Received resched event, may be blocked because of rate limit"  "blockedUntil"="2021-07-21T17:54:42.698850285+08:00" "lastResched"="2021-07-21T17:52:42.698850285+08:00" "received"="2021-07-21T17:55:17.884848964+08:00" "scheduler"="default"
I0721 17:55:17.885673   31979 scheduler.go:159]  "msg"="Started resched"  "scheduler"="default"
I0721 17:55:17.885718   31979 scheduler.go:193]  "msg"="Updating all jobs info"  "scheduler"="default"
I0721 17:55:17.888279   31979 elastic_fifo.go:73]  "msg"="Finished scheduling"  "algorithm"="ElasticFIFO" "freeGpu"=0 "result"={"tf2-keras-cifar10-inceptionv3-elastic-20210721-043127":4,"tf2-keras-cifar10-resnet50-elastic-20210721-043527":4,"tf2-keras-transformer-elastic-20210721-043555":4} "scheduler"="default"
I0721 17:55:17.888564   31979 scheduler.go:384]  "msg"="Trying to delete multiple training jobs"  "jobs"=[] "scheduler"="default"
I0721 17:55:17.888739   31979 scheduler.go:342]  "msg"="Trying to scale multiple training jobs"  "jobs"=[] "scheduler"="default"
I0721 17:55:17.888943   31979 scheduler.go:292]  "msg"="Trying to start multiple training jobs"  "jobs"=[] "scheduler"="default"
I0721 17:55:17.889191   31979 scheduler.go:342]  "msg"="Trying to scale multiple training jobs"  "jobs"=["tf2-keras-cifar10-resnet50-elastic-20210721-043527","tf2-keras-transformer-elastic-20210721-043555","tf2-keras-cifar10-inceptionv3-elastic-20210721-043127"] "scheduler"="default"
I0721 17:55:17.931786   31979 placement_manager.go:166]  "msg"="Started job placements adjustment"  "scheduler"="default"
I0721 17:55:17.931850   31979 placement_manager.go:192]  "msg"="Releasing slots"  "jobs"={"tf2-keras-cifar10-inceptionv3-elastic-20210721-043127":{},"tf2-keras-cifar10-inceptionv3-elastic-20210721-043226":{},"tf2-keras-cifar10-resnet50-elastic-20210721-043527":{},"tf2-keras-transformer-elastic-20210721-043555":{}} "nodes"={"gpu3":{},"gpu4":{},"gpu5":{}} "scheduler"="default"
I0721 17:55:17.931884   31979 placement_manager.go:250]  "msg"="Released slots"  "jobs"={"tf2-keras-cifar10-inceptionv3-elastic-20210721-043127":{},"tf2-keras-cifar10-inceptionv3-elastic-20210721-043226":{},"tf2-keras-cifar10-resnet50-elastic-20210721-043527":{},"tf2-keras-transformer-elastic-20210721-043555":{}} "nodes"={"gpu3":{},"gpu4":{},"gpu5":{}} "scheduler"="default"
I0721 17:55:17.932476   31979 placement_manager.go:305]  "msg"="Found best-fit"  "crossNode"=0 "nodes"=[{},{},{}] "requests"=[{},{},{},{},{},{}] "scheduler"="default"
I0721 17:55:17.932826   31979 placement_manager.go:339]  "msg"="nodeStates updated"  "new"={"gpu3":{},"gpu4":{},"gpu5":{}} "old"={"gpu3":{},"gpu4":{},"gpu5":{}} "scheduler"="default" "score"=7
I0721 17:55:17.933122   31979 placement_manager.go:387]  "msg"="jobStates updated"  "new"={"tf2-keras-cifar10-inceptionv3-elastic-20210721-043127":{},"tf2-keras-cifar10-resnet50-elastic-20210721-043527":{},"tf2-keras-transformer-elastic-20210721-043555":{}} "old"={"tf2-keras-cifar10-inceptionv3-elastic-20210721-043127":{},"tf2-keras-cifar10-inceptionv3-elastic-20210721-043226":{},"tf2-keras-cifar10-resnet50-elastic-20210721-043527":{},"tf2-keras-transformer-elastic-20210721-043555":{}} "scheduler"="default"
I0721 17:55:17.933602   31979 placement_manager.go:434]  "msg"="podNodeName updated"  "launchersToDelete"=0 "new"={"tf2-keras-cifar10-inceptionv3-elastic-20210721-043127-worker-0":"gpu4","tf2-keras-cifar10-inceptionv3-elastic-20210721-043127-worker-1":"gpu4","tf2-keras-cifar10-inceptionv3-elastic-20210721-043127-worker-2":"gpu4","tf2-keras-cifar10-inceptionv3-elastic-20210721-043127-worker-3":"gpu4","tf2-keras-cifar10-resnet50-elastic-20210721-043527-worker-0":"gpu3","tf2-keras-cifar10-resnet50-elastic-20210721-043527-worker-1":"gpu3","tf2-keras-cifar10-resnet50-elastic-20210721-043527-worker-2":"gpu3","tf2-keras-cifar10-resnet50-elastic-20210721-043527-worker-3":"gpu3","tf2-keras-transformer-elastic-20210721-043555-worker-0":"gpu5","tf2-keras-transformer-elastic-20210721-043555-worker-1":"gpu5","tf2-keras-transformer-elastic-20210721-043555-worker-2":"gpu5","tf2-keras-transformer-elastic-20210721-043555-worker-3":"gpu5"} "old"={"tf2-keras-cifar10-inceptionv3-elastic-20210721-043127-worker-0":"gpu4","tf2-keras-cifar10-inceptionv3-elastic-20210721-043127-worker-1":"gpu4","tf2-keras-cifar10-inceptionv3-elastic-20210721-043127-worker-2":"gpu4","tf2-keras-cifar10-inceptionv3-elastic-20210721-043226-worker-0":"gpu5","tf2-keras-cifar10-inceptionv3-elastic-20210721-043226-worker-1":"gpu5","tf2-keras-cifar10-inceptionv3-elastic-20210721-043226-worker-2":"gpu5","tf2-keras-cifar10-resnet50-elastic-20210721-043527-worker-0":"gpu3","tf2-keras-cifar10-resnet50-elastic-20210721-043527-worker-1":"gpu3","tf2-keras-cifar10-resnet50-elastic-20210721-043527-worker-2":"gpu3","tf2-keras-transformer-elastic-20210721-043555-worker-0":"gpu4","tf2-keras-transformer-elastic-20210721-043555-worker-1":"gpu5","tf2-keras-transformer-elastic-20210721-043555-worker-2":"gpu3","tf2-keras-transformer-elastic-20210721-043555-worker-3":"gpu3","tf2-keras-transformer-elastic-20210721-043555-worker-4":"gpu3"} "scheduler"="default" "workersToDelete"=3
I0721 17:55:17.934057   31979 placement_manager.go:451]  "msg"="Deleting pod that need migration"  "podName"="tf2-keras-transformer-elastic-20210721-043555-worker-0" "scheduler"="default"
I0721 17:55:17.938442   31979 placement_manager.go:451]  "msg"="Deleting pod that need migration"  "podName"="tf2-keras-transformer-elastic-20210721-043555-worker-2" "scheduler"="default"
I0721 17:55:17.942529   31979 placement_manager.go:451]  "msg"="Deleting pod that need migration"  "podName"="tf2-keras-transformer-elastic-20210721-043555-worker-3" "scheduler"="default"
E0721 17:55:17.944482   31979 placement_manager.go:455]  "msg"="Failed to delete pod" "error"="pods \"tf2-keras-transformer-elastic-20210721-043555-worker-3\" not found"  "podName"="tf2-keras-transformer-elastic-20210721-043555-worker-3" "scheduler"="default"
I0721 17:55:17.944896   31979 placement_manager.go:183]  "msg"="Finished job placements adjustment"  "scheduler"="default"
I0721 17:55:17.945146   31979 scheduler.go:182]  "msg"="Finished resched"  "scheduler"="default"
I0721 17:55:18.872136   31979 placement_manager.go:147]  "msg"="Adding toleration to pod"  "podName"="tf2-keras-transformer-elastic-20210721-043555-worker-3" "scheduler"="default" "toleration"={"key":"celeste/hostname","operator":"Equal","value":"gpu5","effect":"NoExecute"}
I0721 17:55:19.071524   31979 placement_manager.go:147]  "msg"="Adding toleration to pod"  "podName"="tf2-keras-cifar10-inceptionv3-elastic-20210721-043127-worker-3" "scheduler"="default" "toleration"={"key":"celeste/hostname","operator":"Equal","value":"gpu4","effect":"NoExecute"}
I0721 17:55:20.969902   31979 scheduler.go:474]  "msg"="Training job completed"  "elaspedTotalSeconds"=4792.752880733 "gpuTotalSeconds"=2000.071031362 "job"="tf2-keras-cifar10-resnet50-elastic-20210721-043527" "ranTotalSeconds"=1285.044728672 "scheduler"="default" "waitedTotalSeconds"=3507.708152061
I0721 17:55:20.970028   31979 scheduler.go:135]  "msg"="Received resched event, may be blocked because of rate limit"  "blockedUntil"="2021-07-21T17:57:17.945385353+08:00" "lastResched"="2021-07-21T17:55:17.945385353+08:00" "received"="2021-07-21T17:55:20.969933593+08:00" "scheduler"="default"
I0721 17:55:29.289725   31979 placement_manager.go:147]  "msg"="Adding toleration to pod"  "podName"="tf2-keras-transformer-elastic-20210721-043555-worker-2" "scheduler"="default" "toleration"={"key":"celeste/hostname","operator":"Equal","value":"gpu5","effect":"NoExecute"}
I0721 17:55:34.601125   31979 placement_manager.go:147]  "msg"="Adding toleration to pod"  "podName"="tf2-keras-transformer-elastic-20210721-043555-worker-0" "scheduler"="default" "toleration"={"key":"celeste/hostname","operator":"Equal","value":"gpu5","effect":"NoExecute"}
I0721 17:57:17.945474   31979 scheduler.go:159]  "msg"="Started resched"  "scheduler"="default"
I0721 17:57:17.945547   31979 scheduler.go:193]  "msg"="Updating all jobs info"  "scheduler"="default"
I0721 17:57:17.948196   31979 elastic_fifo.go:73]  "msg"="Finished scheduling"  "algorithm"="ElasticFIFO" "freeGpu"=4 "result"={"tf2-keras-cifar10-inceptionv3-elastic-20210721-043127":4,"tf2-keras-transformer-elastic-20210721-043555":4} "scheduler"="default"
I0721 17:57:17.948491   31979 scheduler.go:384]  "msg"="Trying to delete multiple training jobs"  "jobs"=[] "scheduler"="default"
I0721 17:57:17.948771   31979 scheduler.go:342]  "msg"="Trying to scale multiple training jobs"  "jobs"=[] "scheduler"="default"
I0721 17:57:17.949016   31979 scheduler.go:292]  "msg"="Trying to start multiple training jobs"  "jobs"=[] "scheduler"="default"
I0721 17:57:17.949209   31979 scheduler.go:342]  "msg"="Trying to scale multiple training jobs"  "jobs"=[] "scheduler"="default"
I0721 17:57:17.949389   31979 scheduler.go:180]  "msg"="Nothing changed, skipped ajust placements"  "scheduler"="default"
I0721 17:57:17.949415   31979 scheduler.go:182]  "msg"="Finished resched"  "scheduler"="default"
I0721 17:57:44.822871   31979 scheduler.go:474]  "msg"="Training job completed"  "elaspedTotalSeconds"=5172.903166094 "gpuTotalSeconds"=5580.193531396 "job"="tf2-keras-cifar10-inceptionv3-elastic-20210721-043127" "ranTotalSeconds"=3815.133096812 "scheduler"="default" "waitedTotalSeconds"=1357.770069282
I0721 17:57:44.823099   31979 scheduler.go:135]  "msg"="Received resched event, may be blocked because of rate limit"  "blockedUntil"="2021-07-21T17:59:17.949613611+08:00" "lastResched"="2021-07-21T17:57:17.949613611+08:00" "received"="2021-07-21T17:57:44.822921189+08:00" "scheduler"="default"
I0721 17:59:17.949755   31979 scheduler.go:159]  "msg"="Started resched"  "scheduler"="default"
I0721 17:59:17.949844   31979 scheduler.go:193]  "msg"="Updating all jobs info"  "scheduler"="default"
I0721 17:59:17.952002   31979 elastic_fifo.go:73]  "msg"="Finished scheduling"  "algorithm"="ElasticFIFO" "freeGpu"=8 "result"={"tf2-keras-transformer-elastic-20210721-043555":4} "scheduler"="default"
I0721 17:59:17.952322   31979 scheduler.go:384]  "msg"="Trying to delete multiple training jobs"  "jobs"=[] "scheduler"="default"
I0721 17:59:17.952616   31979 scheduler.go:342]  "msg"="Trying to scale multiple training jobs"  "jobs"=[] "scheduler"="default"
I0721 17:59:17.952890   31979 scheduler.go:292]  "msg"="Trying to start multiple training jobs"  "jobs"=[] "scheduler"="default"
I0721 17:59:17.953172   31979 scheduler.go:342]  "msg"="Trying to scale multiple training jobs"  "jobs"=[] "scheduler"="default"
I0721 17:59:17.953491   31979 scheduler.go:180]  "msg"="Nothing changed, skipped ajust placements"  "scheduler"="default"
I0721 17:59:17.953524   31979 scheduler.go:182]  "msg"="Finished resched"  "scheduler"="default"
I0721 18:08:15.754972   31979 scheduler.go:474]  "msg"="Training job completed"  "elaspedTotalSeconds"=5539.864100684 "gpuTotalSeconds"=4845.184062618 "job"="tf2-keras-transformer-elastic-20210721-043555" "ranTotalSeconds"=1805.065906482 "scheduler"="default" "waitedTotalSeconds"=3734.798194202
I0721 18:08:15.755151   31979 scheduler.go:135]  "msg"="Received resched event, may be blocked because of rate limit"  "blockedUntil"="2021-07-21T18:01:17.953786468+08:00" "lastResched"="2021-07-21T17:59:17.953786468+08:00" "received"="2021-07-21T18:08:15.755013062+08:00" "scheduler"="default"
I0721 18:08:15.755800   31979 scheduler.go:159]  "msg"="Started resched"  "scheduler"="default"
I0721 18:08:15.755910   31979 scheduler.go:193]  "msg"="Updating all jobs info"  "scheduler"="default"
I0721 18:08:15.756299   31979 elastic_fifo.go:73]  "msg"="Finished scheduling"  "algorithm"="ElasticFIFO" "freeGpu"=12 "result"={} "scheduler"="default"
I0721 18:08:15.756619   31979 scheduler.go:384]  "msg"="Trying to delete multiple training jobs"  "jobs"=[] "scheduler"="default"
I0721 18:08:15.756922   31979 scheduler.go:342]  "msg"="Trying to scale multiple training jobs"  "jobs"=[] "scheduler"="default"
I0721 18:08:15.757244   31979 scheduler.go:292]  "msg"="Trying to start multiple training jobs"  "jobs"=[] "scheduler"="default"
I0721 18:08:15.757448   31979 scheduler.go:342]  "msg"="Trying to scale multiple training jobs"  "jobs"=[] "scheduler"="default"
I0721 18:08:15.757630   31979 scheduler.go:180]  "msg"="Nothing changed, skipped ajust placements"  "scheduler"="default"
I0721 18:08:15.757677   31979 scheduler.go:182]  "msg"="Finished resched"  "scheduler"="default"
