Log file created at: 2021/07/22 00:19:33
Running on machine: gpu4
Binary: Built with gc go1.13.15 for linux/amd64
Log line format: [IWEF]mmdd hh:mm:ss.uuuuuu threadid file:line] msg
I0722 00:19:33.478568   23824 main.go:19]  "msg"="Celeste - DLT jobs scheduler"  "version"="0.0.1"
I0722 00:19:33.479773   23824 main.go:20]  "msg"="Starting service"  
I0722 00:19:33.486345   23824 placement_manager.go:65]  "msg"="Starting placement manager"  "scheduler"="default"
I0722 00:19:33.487074   23824 placement_manager.go:95]  "msg"="Started placement manager"  "nodes"={"gpu3":{},"gpu4":{},"gpu5":{}} "scheduler"="default"
I0722 00:19:33.487566   23824 jobmaster.go:82]  "msg"="Starting scheduler"  "gpuType"="default"
I0722 00:19:33.487683   23824 scheduler.go:124]  "msg"="Starting scheduler"  "scheduler"="default"
I0722 00:19:33.518284   23824 scheduler.go:432]  "msg"="Start watching mpijob"  "scheduler"="default"
I0722 00:19:43.237955   23824 jobmaster.go:155]  "msg"="Training job created"  "job"="tf2-keras-cifar10-inceptionv3-elastic-20210722-121943"
I0722 00:19:43.238160   23824 scheduler.go:135]  "msg"="Received resched event, may be blocked because of rate limit"  "blockedUntil"="2021-07-22T00:19:33.487535798+08:00" "lastResched"="2021-07-22T00:19:33.487536061+08:00" "received"="2021-07-22T00:19:43.237247768+08:00" "scheduler"="default"
I0722 00:19:43.238928   23824 scheduler.go:159]  "msg"="Started resched"  "scheduler"="default"
I0722 00:19:43.239005   23824 scheduler.go:193]  "msg"="Updating all jobs info"  "scheduler"="default"
I0722 00:19:43.240482   23824 afsl.go:65]  "msg"="Finished scheduling"  "algorithm"="AFS-L" "freeGpu"=8 "result"={"tf2-keras-cifar10-inceptionv3-elastic-20210722-121943":4} "scheduler"="default"
I0722 00:19:43.240837   23824 scheduler.go:384]  "msg"="Trying to delete multiple training jobs"  "jobs"=[] "scheduler"="default"
I0722 00:19:43.241107   23824 scheduler.go:342]  "msg"="Trying to scale multiple training jobs"  "jobs"=[] "scheduler"="default"
I0722 00:19:43.241316   23824 scheduler.go:292]  "msg"="Trying to start multiple training jobs"  "jobs"=["tf2-keras-cifar10-inceptionv3-elastic-20210722-121943"] "scheduler"="default"
I0722 00:19:43.265038   23824 scheduler.go:342]  "msg"="Trying to scale multiple training jobs"  "jobs"=[] "scheduler"="default"
I0722 00:19:43.267018   23824 placement_manager.go:166]  "msg"="Started job placements adjustment"  "scheduler"="default"
I0722 00:19:43.267179   23824 placement_manager.go:192]  "msg"="Releasing slots"  "jobs"={} "nodes"={"gpu3":{},"gpu4":{},"gpu5":{}} "scheduler"="default"
I0722 00:19:43.267227   23824 placement_manager.go:250]  "msg"="Released slots"  "jobs"={} "nodes"={"gpu3":{},"gpu4":{},"gpu5":{}} "scheduler"="default"
I0722 00:19:43.267676   23824 placement_manager.go:305]  "msg"="Found best-fit"  "crossNode"=0 "nodes"=[{},{},{}] "requests"=[{},{}] "scheduler"="default"
I0722 00:19:43.268007   23824 placement_manager.go:339]  "msg"="nodeStates updated"  "new"={"gpu3":{},"gpu4":{},"gpu5":{}} "old"={"gpu3":{},"gpu4":{},"gpu5":{}} "scheduler"="default" "score"=0
I0722 00:19:43.268356   23824 placement_manager.go:387]  "msg"="jobStates updated"  "new"={"tf2-keras-cifar10-inceptionv3-elastic-20210722-121943":{}} "old"={} "scheduler"="default"
I0722 00:19:43.268677   23824 placement_manager.go:434]  "msg"="podNodeName updated"  "launchersToDelete"=0 "new"={"tf2-keras-cifar10-inceptionv3-elastic-20210722-121943-worker-0":"gpu3","tf2-keras-cifar10-inceptionv3-elastic-20210722-121943-worker-1":"gpu3","tf2-keras-cifar10-inceptionv3-elastic-20210722-121943-worker-2":"gpu3","tf2-keras-cifar10-inceptionv3-elastic-20210722-121943-worker-3":"gpu3"} "old"={} "scheduler"="default" "workersToDelete"=0
I0722 00:19:43.268975   23824 placement_manager.go:183]  "msg"="Finished job placements adjustment"  "scheduler"="default"
I0722 00:19:43.269219   23824 scheduler.go:182]  "msg"="Finished resched"  "scheduler"="default"
I0722 00:19:43.339947   23824 placement_manager.go:147]  "msg"="Adding toleration to pod"  "podName"="tf2-keras-cifar10-inceptionv3-elastic-20210722-121943-worker-0" "scheduler"="default" "toleration"={"key":"celeste/hostname","operator":"Equal","value":"gpu3","effect":"NoExecute"}
I0722 00:19:43.353588   23824 placement_manager.go:147]  "msg"="Adding toleration to pod"  "podName"="tf2-keras-cifar10-inceptionv3-elastic-20210722-121943-worker-1" "scheduler"="default" "toleration"={"key":"celeste/hostname","operator":"Equal","value":"gpu3","effect":"NoExecute"}
I0722 00:19:43.364720   23824 placement_manager.go:147]  "msg"="Adding toleration to pod"  "podName"="tf2-keras-cifar10-inceptionv3-elastic-20210722-121943-worker-2" "scheduler"="default" "toleration"={"key":"celeste/hostname","operator":"Equal","value":"gpu3","effect":"NoExecute"}
I0722 00:19:43.376496   23824 placement_manager.go:147]  "msg"="Adding toleration to pod"  "podName"="tf2-keras-cifar10-inceptionv3-elastic-20210722-121943-worker-3" "scheduler"="default" "toleration"={"key":"celeste/hostname","operator":"Equal","value":"gpu3","effect":"NoExecute"}
I0722 00:19:43.396075   23824 placement_manager.go:147]  "msg"="Adding toleration to pod"  "podName"="tf2-keras-cifar10-inceptionv3-elastic-20210722-121943-launcher" "scheduler"="default" "toleration"={"key":"celeste/hostname","operator":"Exists","effect":"NoExecute"}
I0722 00:20:06.206801   23824 jobmaster.go:155]  "msg"="Training job created"  "job"="tf2-keras-cifar10-resnet50-elastic-20210722-122006"
I0722 00:20:06.206907   23824 scheduler.go:135]  "msg"="Received resched event, may be blocked because of rate limit"  "blockedUntil"="2021-07-22T00:21:43.269412814+08:00" "lastResched"="2021-07-22T00:19:43.269412814+08:00" "received"="2021-07-22T00:20:06.206239839+08:00" "scheduler"="default"
I0722 00:20:34.183874   23824 jobmaster.go:155]  "msg"="Training job created"  "job"="tf2-keras-cifar10-inceptionv3-elastic-20210722-122034"
I0722 00:21:04.124352   23824 jobmaster.go:155]  "msg"="Training job created"  "job"="tf2-keras-cifar10-vgg16-elastic-20210722-122104"
I0722 00:21:26.069956   23824 jobmaster.go:155]  "msg"="Training job created"  "job"="tf2-keras-cifar10-vgg16-elastic-20210722-122126"
I0722 00:21:43.269522   23824 scheduler.go:159]  "msg"="Started resched"  "scheduler"="default"
I0722 00:21:43.269595   23824 scheduler.go:193]  "msg"="Updating all jobs info"  "scheduler"="default"
I0722 00:21:43.275253   23824 afsl.go:65]  "msg"="Finished scheduling"  "algorithm"="AFS-L" "freeGpu"=0 "result"={"tf2-keras-cifar10-inceptionv3-elastic-20210722-121943":1,"tf2-keras-cifar10-inceptionv3-elastic-20210722-122034":3,"tf2-keras-cifar10-resnet50-elastic-20210722-122006":2,"tf2-keras-cifar10-vgg16-elastic-20210722-122104":3,"tf2-keras-cifar10-vgg16-elastic-20210722-122126":3} "scheduler"="default"
I0722 00:21:43.275771   23824 scheduler.go:384]  "msg"="Trying to delete multiple training jobs"  "jobs"=[] "scheduler"="default"
I0722 00:21:43.276109   23824 scheduler.go:342]  "msg"="Trying to scale multiple training jobs"  "jobs"=["tf2-keras-cifar10-inceptionv3-elastic-20210722-121943"] "scheduler"="default"
I0722 00:21:43.292211   23824 scheduler.go:292]  "msg"="Trying to start multiple training jobs"  "jobs"=["tf2-keras-cifar10-resnet50-elastic-20210722-122006","tf2-keras-cifar10-inceptionv3-elastic-20210722-122034","tf2-keras-cifar10-vgg16-elastic-20210722-122104","tf2-keras-cifar10-vgg16-elastic-20210722-122126"] "scheduler"="default"
I0722 00:21:43.339281   23824 scheduler.go:342]  "msg"="Trying to scale multiple training jobs"  "jobs"=[] "scheduler"="default"
I0722 00:21:43.342998   23824 placement_manager.go:166]  "msg"="Started job placements adjustment"  "scheduler"="default"
I0722 00:21:43.343097   23824 placement_manager.go:192]  "msg"="Releasing slots"  "jobs"={"tf2-keras-cifar10-inceptionv3-elastic-20210722-121943":{}} "nodes"={"gpu3":{},"gpu4":{},"gpu5":{}} "scheduler"="default"
I0722 00:21:43.343166   23824 placement_manager.go:250]  "msg"="Released slots"  "jobs"={"tf2-keras-cifar10-inceptionv3-elastic-20210722-121943":{}} "nodes"={"gpu3":{},"gpu4":{},"gpu5":{}} "scheduler"="default"
I0722 00:21:43.343668   23824 placement_manager.go:305]  "msg"="Found best-fit"  "crossNode"=0 "nodes"=[{},{},{}] "requests"=[{},{},{},{},{},{},{},{},{},{}] "scheduler"="default"
I0722 00:21:43.344066   23824 placement_manager.go:339]  "msg"="nodeStates updated"  "new"={"gpu3":{},"gpu4":{},"gpu5":{}} "old"={"gpu3":{},"gpu4":{},"gpu5":{}} "scheduler"="default" "score"=1
I0722 00:21:43.344473   23824 placement_manager.go:387]  "msg"="jobStates updated"  "new"={"tf2-keras-cifar10-inceptionv3-elastic-20210722-121943":{},"tf2-keras-cifar10-inceptionv3-elastic-20210722-122034":{},"tf2-keras-cifar10-resnet50-elastic-20210722-122006":{},"tf2-keras-cifar10-vgg16-elastic-20210722-122104":{},"tf2-keras-cifar10-vgg16-elastic-20210722-122126":{}} "old"={"tf2-keras-cifar10-inceptionv3-elastic-20210722-121943":{}} "scheduler"="default"
I0722 00:21:43.345013   23824 placement_manager.go:434]  "msg"="podNodeName updated"  "launchersToDelete"=0 "new"={"tf2-keras-cifar10-inceptionv3-elastic-20210722-121943-worker-0":"gpu3","tf2-keras-cifar10-inceptionv3-elastic-20210722-122034-worker-0":"gpu5","tf2-keras-cifar10-inceptionv3-elastic-20210722-122034-worker-1":"gpu5","tf2-keras-cifar10-inceptionv3-elastic-20210722-122034-worker-2":"gpu5","tf2-keras-cifar10-resnet50-elastic-20210722-122006-worker-0":"gpu5","tf2-keras-cifar10-resnet50-elastic-20210722-122006-worker-1":"gpu4","tf2-keras-cifar10-resnet50-elastic-20210722-122006-worker-2":"gpu4","tf2-keras-cifar10-vgg16-elastic-20210722-122104-worker-0":"gpu4","tf2-keras-cifar10-vgg16-elastic-20210722-122104-worker-1":"gpu4","tf2-keras-cifar10-vgg16-elastic-20210722-122104-worker-2":"gpu4","tf2-keras-cifar10-vgg16-elastic-20210722-122126-worker-0":"gpu3","tf2-keras-cifar10-vgg16-elastic-20210722-122126-worker-1":"gpu3","tf2-keras-cifar10-vgg16-elastic-20210722-122126-worker-2":"gpu3"} "old"={"tf2-keras-cifar10-inceptionv3-elastic-20210722-121943-worker-0":"gpu3","tf2-keras-cifar10-inceptionv3-elastic-20210722-121943-worker-1":"gpu3","tf2-keras-cifar10-inceptionv3-elastic-20210722-121943-worker-2":"gpu3","tf2-keras-cifar10-inceptionv3-elastic-20210722-121943-worker-3":"gpu3"} "scheduler"="default" "workersToDelete"=0
I0722 00:21:43.345533   23824 placement_manager.go:183]  "msg"="Finished job placements adjustment"  "scheduler"="default"
I0722 00:21:43.345995   23824 scheduler.go:182]  "msg"="Finished resched"  "scheduler"="default"
I0722 00:21:44.508544   23824 placement_manager.go:147]  "msg"="Adding toleration to pod"  "podName"="tf2-keras-cifar10-resnet50-elastic-20210722-122006-worker-0" "scheduler"="default" "toleration"={"key":"celeste/hostname","operator":"Equal","value":"gpu5","effect":"NoExecute"}
I0722 00:21:44.904120   23824 placement_manager.go:147]  "msg"="Adding toleration to pod"  "podName"="tf2-keras-cifar10-resnet50-elastic-20210722-122006-worker-1" "scheduler"="default" "toleration"={"key":"celeste/hostname","operator":"Equal","value":"gpu4","effect":"NoExecute"}
I0722 00:21:45.306173   23824 placement_manager.go:147]  "msg"="Adding toleration to pod"  "podName"="tf2-keras-cifar10-resnet50-elastic-20210722-122006-launcher" "scheduler"="default" "toleration"={"key":"celeste/hostname","operator":"Exists","effect":"NoExecute"}
I0722 00:21:45.908576   23824 placement_manager.go:147]  "msg"="Adding toleration to pod"  "podName"="tf2-keras-cifar10-inceptionv3-elastic-20210722-122034-worker-0" "scheduler"="default" "toleration"={"key":"celeste/hostname","operator":"Equal","value":"gpu5","effect":"NoExecute"}
I0722 00:21:46.304082   23824 placement_manager.go:147]  "msg"="Adding toleration to pod"  "podName"="tf2-keras-cifar10-inceptionv3-elastic-20210722-122034-worker-1" "scheduler"="default" "toleration"={"key":"celeste/hostname","operator":"Equal","value":"gpu5","effect":"NoExecute"}
I0722 00:21:46.705535   23824 placement_manager.go:147]  "msg"="Adding toleration to pod"  "podName"="tf2-keras-cifar10-inceptionv3-elastic-20210722-122034-worker-2" "scheduler"="default" "toleration"={"key":"celeste/hostname","operator":"Equal","value":"gpu5","effect":"NoExecute"}
I0722 00:21:47.317761   23824 placement_manager.go:147]  "msg"="Adding toleration to pod"  "podName"="tf2-keras-cifar10-inceptionv3-elastic-20210722-122034-launcher" "scheduler"="default" "toleration"={"key":"celeste/hostname","operator":"Exists","effect":"NoExecute"}
I0722 00:21:47.717929   23824 placement_manager.go:147]  "msg"="Adding toleration to pod"  "podName"="tf2-keras-cifar10-vgg16-elastic-20210722-122104-worker-0" "scheduler"="default" "toleration"={"key":"celeste/hostname","operator":"Equal","value":"gpu4","effect":"NoExecute"}
I0722 00:21:48.114692   23824 placement_manager.go:147]  "msg"="Adding toleration to pod"  "podName"="tf2-keras-cifar10-vgg16-elastic-20210722-122104-worker-1" "scheduler"="default" "toleration"={"key":"celeste/hostname","operator":"Equal","value":"gpu4","effect":"NoExecute"}
I0722 00:21:48.515132   23824 placement_manager.go:147]  "msg"="Adding toleration to pod"  "podName"="tf2-keras-cifar10-vgg16-elastic-20210722-122104-worker-2" "scheduler"="default" "toleration"={"key":"celeste/hostname","operator":"Equal","value":"gpu4","effect":"NoExecute"}
I0722 00:21:48.917198   23824 placement_manager.go:147]  "msg"="Adding toleration to pod"  "podName"="tf2-keras-cifar10-vgg16-elastic-20210722-122104-launcher" "scheduler"="default" "toleration"={"key":"celeste/hostname","operator":"Exists","effect":"NoExecute"}
I0722 00:21:49.080766   23824 jobmaster.go:155]  "msg"="Training job created"  "job"="tf2-keras-transformer-elastic-20210722-122149"
I0722 00:21:49.080989   23824 scheduler.go:135]  "msg"="Received resched event, may be blocked because of rate limit"  "blockedUntil"="2021-07-22T00:23:43.346255992+08:00" "lastResched"="2021-07-22T00:21:43.346255992+08:00" "received"="2021-07-22T00:21:49.080124339+08:00" "scheduler"="default"
I0722 00:21:49.318349   23824 placement_manager.go:147]  "msg"="Adding toleration to pod"  "podName"="tf2-keras-cifar10-vgg16-elastic-20210722-122126-worker-0" "scheduler"="default" "toleration"={"key":"celeste/hostname","operator":"Equal","value":"gpu3","effect":"NoExecute"}
I0722 00:21:49.717046   23824 placement_manager.go:147]  "msg"="Adding toleration to pod"  "podName"="tf2-keras-cifar10-vgg16-elastic-20210722-122126-worker-1" "scheduler"="default" "toleration"={"key":"celeste/hostname","operator":"Equal","value":"gpu3","effect":"NoExecute"}
I0722 00:21:50.117964   23824 placement_manager.go:147]  "msg"="Adding toleration to pod"  "podName"="tf2-keras-cifar10-vgg16-elastic-20210722-122126-worker-2" "scheduler"="default" "toleration"={"key":"celeste/hostname","operator":"Equal","value":"gpu3","effect":"NoExecute"}
I0722 00:21:50.523625   23824 placement_manager.go:147]  "msg"="Adding toleration to pod"  "podName"="tf2-keras-cifar10-vgg16-elastic-20210722-122126-launcher" "scheduler"="default" "toleration"={"key":"celeste/hostname","operator":"Exists","effect":"NoExecute"}
I0722 00:22:15.953173   23824 jobmaster.go:155]  "msg"="Training job created"  "job"="tf2-keras-transformer-elastic-20210722-122215"
I0722 00:22:50.954487   23824 jobmaster.go:155]  "msg"="Training job created"  "job"="tf2-keras-cifar10-inceptionv3-elastic-20210722-122250"
I0722 00:23:27.839423   23824 jobmaster.go:155]  "msg"="Training job created"  "job"="tf2-keras-cifar10-resnet50-elastic-20210722-122327"
I0722 00:23:43.346305   23824 scheduler.go:159]  "msg"="Started resched"  "scheduler"="default"
I0722 00:23:43.346397   23824 scheduler.go:193]  "msg"="Updating all jobs info"  "scheduler"="default"
I0722 00:23:43.352729   23824 afsl.go:65]  "msg"="Finished scheduling"  "algorithm"="AFS-L" "freeGpu"=0 "result"={"tf2-keras-cifar10-inceptionv3-elastic-20210722-121943":1,"tf2-keras-cifar10-inceptionv3-elastic-20210722-122034":1,"tf2-keras-cifar10-inceptionv3-elastic-20210722-122250":1,"tf2-keras-cifar10-resnet50-elastic-20210722-122006":1,"tf2-keras-cifar10-resnet50-elastic-20210722-122327":2,"tf2-keras-cifar10-vgg16-elastic-20210722-122104":2,"tf2-keras-cifar10-vgg16-elastic-20210722-122126":2,"tf2-keras-transformer-elastic-20210722-122149":1,"tf2-keras-transformer-elastic-20210722-122215":1} "scheduler"="default"
I0722 00:23:43.353081   23824 scheduler.go:384]  "msg"="Trying to delete multiple training jobs"  "jobs"=[] "scheduler"="default"
I0722 00:23:43.353321   23824 scheduler.go:342]  "msg"="Trying to scale multiple training jobs"  "jobs"=["tf2-keras-cifar10-resnet50-elastic-20210722-122006","tf2-keras-cifar10-inceptionv3-elastic-20210722-122034","tf2-keras-cifar10-vgg16-elastic-20210722-122126","tf2-keras-cifar10-vgg16-elastic-20210722-122104"] "scheduler"="default"
I0722 00:23:43.419698   23824 scheduler.go:292]  "msg"="Trying to start multiple training jobs"  "jobs"=["tf2-keras-cifar10-inceptionv3-elastic-20210722-122250","tf2-keras-transformer-elastic-20210722-122149","tf2-keras-transformer-elastic-20210722-122215","tf2-keras-cifar10-resnet50-elastic-20210722-122327"] "scheduler"="default"
I0722 00:23:43.762980   23824 scheduler.go:342]  "msg"="Trying to scale multiple training jobs"  "jobs"=[] "scheduler"="default"
I0722 00:23:43.767697   23824 placement_manager.go:166]  "msg"="Started job placements adjustment"  "scheduler"="default"
I0722 00:23:43.767780   23824 placement_manager.go:192]  "msg"="Releasing slots"  "jobs"={"tf2-keras-cifar10-inceptionv3-elastic-20210722-121943":{},"tf2-keras-cifar10-inceptionv3-elastic-20210722-122034":{},"tf2-keras-cifar10-resnet50-elastic-20210722-122006":{},"tf2-keras-cifar10-vgg16-elastic-20210722-122104":{},"tf2-keras-cifar10-vgg16-elastic-20210722-122126":{}} "nodes"={"gpu3":{},"gpu4":{},"gpu5":{}} "scheduler"="default"
I0722 00:23:43.767905   23824 placement_manager.go:250]  "msg"="Released slots"  "jobs"={"tf2-keras-cifar10-inceptionv3-elastic-20210722-121943":{},"tf2-keras-cifar10-inceptionv3-elastic-20210722-122034":{},"tf2-keras-cifar10-resnet50-elastic-20210722-122006":{},"tf2-keras-cifar10-vgg16-elastic-20210722-122104":{},"tf2-keras-cifar10-vgg16-elastic-20210722-122126":{}} "nodes"={"gpu3":{},"gpu4":{},"gpu5":{}} "scheduler"="default"
I0722 00:23:43.768362   23824 placement_manager.go:305]  "msg"="Found best-fit"  "crossNode"=0 "nodes"=[{},{},{}] "requests"=[{},{},{},{},{},{},{},{},{},{},{},{},{},{},{},{},{},{}] "scheduler"="default"
I0722 00:23:43.768662   23824 placement_manager.go:339]  "msg"="nodeStates updated"  "new"={"gpu3":{},"gpu4":{},"gpu5":{}} "old"={"gpu3":{},"gpu4":{},"gpu5":{}} "scheduler"="default" "score"=4
I0722 00:23:43.768988   23824 placement_manager.go:387]  "msg"="jobStates updated"  "new"={"tf2-keras-cifar10-inceptionv3-elastic-20210722-121943":{},"tf2-keras-cifar10-inceptionv3-elastic-20210722-122034":{},"tf2-keras-cifar10-inceptionv3-elastic-20210722-122250":{},"tf2-keras-cifar10-resnet50-elastic-20210722-122006":{},"tf2-keras-cifar10-resnet50-elastic-20210722-122327":{},"tf2-keras-cifar10-vgg16-elastic-20210722-122104":{},"tf2-keras-cifar10-vgg16-elastic-20210722-122126":{},"tf2-keras-transformer-elastic-20210722-122149":{},"tf2-keras-transformer-elastic-20210722-122215":{}} "old"={"tf2-keras-cifar10-inceptionv3-elastic-20210722-121943":{},"tf2-keras-cifar10-inceptionv3-elastic-20210722-122034":{},"tf2-keras-cifar10-resnet50-elastic-20210722-122006":{},"tf2-keras-cifar10-vgg16-elastic-20210722-122104":{},"tf2-keras-cifar10-vgg16-elastic-20210722-122126":{}} "scheduler"="default"
I0722 00:23:43.769441   23824 placement_manager.go:434]  "msg"="podNodeName updated"  "launchersToDelete"=2 "new"={"tf2-keras-cifar10-inceptionv3-elastic-20210722-121943-worker-0":"gpu3","tf2-keras-cifar10-inceptionv3-elastic-20210722-122034-worker-0":"gpu5","tf2-keras-cifar10-inceptionv3-elastic-20210722-122250-worker-0":"gpu5","tf2-keras-cifar10-resnet50-elastic-20210722-122006-worker-0":"gpu3","tf2-keras-cifar10-resnet50-elastic-20210722-122327-worker-0":"gpu3","tf2-keras-cifar10-resnet50-elastic-20210722-122327-worker-1":"gpu3","tf2-keras-cifar10-vgg16-elastic-20210722-122104-worker-0":"gpu4","tf2-keras-cifar10-vgg16-elastic-20210722-122104-worker-1":"gpu4","tf2-keras-cifar10-vgg16-elastic-20210722-122126-worker-0":"gpu4","tf2-keras-cifar10-vgg16-elastic-20210722-122126-worker-1":"gpu4","tf2-keras-transformer-elastic-20210722-122149-worker-0":"gpu5","tf2-keras-transformer-elastic-20210722-122215-worker-0":"gpu5"} "old"={"tf2-keras-cifar10-inceptionv3-elastic-20210722-121943-worker-0":"gpu3","tf2-keras-cifar10-inceptionv3-elastic-20210722-122034-worker-0":"gpu5","tf2-keras-cifar10-inceptionv3-elastic-20210722-122034-worker-1":"gpu5","tf2-keras-cifar10-inceptionv3-elastic-20210722-122034-worker-2":"gpu5","tf2-keras-cifar10-resnet50-elastic-20210722-122006-worker-0":"gpu5","tf2-keras-cifar10-resnet50-elastic-20210722-122006-worker-1":"gpu4","tf2-keras-cifar10-resnet50-elastic-20210722-122006-worker-2":"gpu4","tf2-keras-cifar10-vgg16-elastic-20210722-122104-worker-0":"gpu4","tf2-keras-cifar10-vgg16-elastic-20210722-122104-worker-1":"gpu4","tf2-keras-cifar10-vgg16-elastic-20210722-122104-worker-2":"gpu4","tf2-keras-cifar10-vgg16-elastic-20210722-122126-worker-0":"gpu3","tf2-keras-cifar10-vgg16-elastic-20210722-122126-worker-1":"gpu3","tf2-keras-cifar10-vgg16-elastic-20210722-122126-worker-2":"gpu3"} "scheduler"="default" "workersToDelete"=3
I0722 00:23:43.769786   23824 placement_manager.go:451]  "msg"="Deleting pod that need migration"  "podName"="tf2-keras-cifar10-resnet50-elastic-20210722-122006-worker-0" "scheduler"="default"
I0722 00:23:43.774701   23824 placement_manager.go:451]  "msg"="Deleting pod that need migration"  "podName"="tf2-keras-cifar10-resnet50-elastic-20210722-122006-launcher" "scheduler"="default"
I0722 00:23:43.780143   23824 placement_manager.go:451]  "msg"="Deleting pod that need migration"  "podName"="tf2-keras-cifar10-vgg16-elastic-20210722-122126-worker-0" "scheduler"="default"
I0722 00:23:43.787702   23824 placement_manager.go:451]  "msg"="Deleting pod that need migration"  "podName"="tf2-keras-cifar10-vgg16-elastic-20210722-122126-worker-1" "scheduler"="default"
I0722 00:23:43.792195   23824 placement_manager.go:451]  "msg"="Deleting pod that need migration"  "podName"="tf2-keras-cifar10-vgg16-elastic-20210722-122126-launcher" "scheduler"="default"
I0722 00:23:43.803491   23824 placement_manager.go:183]  "msg"="Finished job placements adjustment"  "scheduler"="default"
I0722 00:23:43.803749   23824 scheduler.go:182]  "msg"="Finished resched"  "scheduler"="default"
I0722 00:23:46.986343   23824 placement_manager.go:147]  "msg"="Adding toleration to pod"  "podName"="tf2-keras-cifar10-inceptionv3-elastic-20210722-122250-worker-0" "scheduler"="default" "toleration"={"key":"celeste/hostname","operator":"Equal","value":"gpu5","effect":"NoExecute"}
I0722 00:23:47.582640   23824 placement_manager.go:147]  "msg"="Adding toleration to pod"  "podName"="tf2-keras-cifar10-inceptionv3-elastic-20210722-122250-launcher" "scheduler"="default" "toleration"={"key":"celeste/hostname","operator":"Exists","effect":"NoExecute"}
I0722 00:23:49.381499   23824 placement_manager.go:147]  "msg"="Adding toleration to pod"  "podName"="tf2-keras-transformer-elastic-20210722-122149-worker-0" "scheduler"="default" "toleration"={"key":"celeste/hostname","operator":"Equal","value":"gpu5","effect":"NoExecute"}
I0722 00:23:49.782639   23824 placement_manager.go:147]  "msg"="Adding toleration to pod"  "podName"="tf2-keras-transformer-elastic-20210722-122149-launcher" "scheduler"="default" "toleration"={"key":"celeste/hostname","operator":"Exists","effect":"NoExecute"}
I0722 00:23:49.981860   23824 placement_manager.go:147]  "msg"="Adding toleration to pod"  "podName"="tf2-keras-transformer-elastic-20210722-122215-worker-0" "scheduler"="default" "toleration"={"key":"celeste/hostname","operator":"Equal","value":"gpu5","effect":"NoExecute"}
I0722 00:23:50.382622   23824 placement_manager.go:147]  "msg"="Adding toleration to pod"  "podName"="tf2-keras-transformer-elastic-20210722-122215-launcher" "scheduler"="default" "toleration"={"key":"celeste/hostname","operator":"Exists","effect":"NoExecute"}
I0722 00:23:51.782087   23824 placement_manager.go:147]  "msg"="Adding toleration to pod"  "podName"="tf2-keras-cifar10-resnet50-elastic-20210722-122327-worker-0" "scheduler"="default" "toleration"={"key":"celeste/hostname","operator":"Equal","value":"gpu3","effect":"NoExecute"}
I0722 00:23:52.180274   23824 placement_manager.go:147]  "msg"="Adding toleration to pod"  "podName"="tf2-keras-cifar10-resnet50-elastic-20210722-122327-worker-1" "scheduler"="default" "toleration"={"key":"celeste/hostname","operator":"Equal","value":"gpu3","effect":"NoExecute"}
I0722 00:23:52.782863   23824 placement_manager.go:147]  "msg"="Adding toleration to pod"  "podName"="tf2-keras-cifar10-resnet50-elastic-20210722-122327-launcher" "scheduler"="default" "toleration"={"key":"celeste/hostname","operator":"Exists","effect":"NoExecute"}
I0722 00:23:53.783190   23824 placement_manager.go:147]  "msg"="Adding toleration to pod"  "podName"="tf2-keras-cifar10-vgg16-elastic-20210722-122126-launcher" "scheduler"="default" "toleration"={"key":"celeste/hostname","operator":"Exists","effect":"NoExecute"}
I0722 00:23:54.582536   23824 placement_manager.go:147]  "msg"="Adding toleration to pod"  "podName"="tf2-keras-cifar10-resnet50-elastic-20210722-122006-launcher" "scheduler"="default" "toleration"={"key":"celeste/hostname","operator":"Exists","effect":"NoExecute"}
I0722 00:23:54.759121   23824 jobmaster.go:155]  "msg"="Training job created"  "job"="tf2-keras-cifar10-inceptionv3-elastic-20210722-122354"
I0722 00:23:54.759261   23824 scheduler.go:135]  "msg"="Received resched event, may be blocked because of rate limit"  "blockedUntil"="2021-07-22T00:25:43.803965509+08:00" "lastResched"="2021-07-22T00:23:43.803965509+08:00" "received"="2021-07-22T00:23:54.75840447+08:00" "scheduler"="default"
I0722 00:23:55.181183   23824 placement_manager.go:147]  "msg"="Adding toleration to pod"  "podName"="tf2-keras-cifar10-vgg16-elastic-20210722-122126-worker-1" "scheduler"="default" "toleration"={"key":"celeste/hostname","operator":"Equal","value":"gpu4","effect":"NoExecute"}
I0722 00:23:56.183388   23824 placement_manager.go:147]  "msg"="Adding toleration to pod"  "podName"="tf2-keras-cifar10-resnet50-elastic-20210722-122006-worker-0" "scheduler"="default" "toleration"={"key":"celeste/hostname","operator":"Equal","value":"gpu3","effect":"NoExecute"}
I0722 00:23:59.987688   23824 placement_manager.go:147]  "msg"="Adding toleration to pod"  "podName"="tf2-keras-cifar10-vgg16-elastic-20210722-122126-worker-0" "scheduler"="default" "toleration"={"key":"celeste/hostname","operator":"Equal","value":"gpu4","effect":"NoExecute"}
I0722 00:24:21.640181   23824 jobmaster.go:155]  "msg"="Training job created"  "job"="tf2-keras-transformer-elastic-20210722-122421"
I0722 00:24:46.535083   23824 jobmaster.go:155]  "msg"="Training job created"  "job"="tf2-keras-cifar10-vgg16-elastic-20210722-122446"
I0722 00:25:13.483653   23824 jobmaster.go:155]  "msg"="Training job created"  "job"="tf2-keras-cifar10-vgg16-elastic-20210722-122513"
I0722 00:25:42.381534   23824 jobmaster.go:155]  "msg"="Training job created"  "job"="tf2-keras-cifar10-resnet50-elastic-20210722-122542"
I0722 00:25:43.804032   23824 scheduler.go:159]  "msg"="Started resched"  "scheduler"="default"
I0722 00:25:43.804099   23824 scheduler.go:193]  "msg"="Updating all jobs info"  "scheduler"="default"
I0722 00:25:43.812925   23824 afsl.go:65]  "msg"="Finished scheduling"  "algorithm"="AFS-L" "freeGpu"=0 "result"={"tf2-keras-cifar10-inceptionv3-elastic-20210722-121943":0,"tf2-keras-cifar10-inceptionv3-elastic-20210722-122034":0,"tf2-keras-cifar10-inceptionv3-elastic-20210722-122250":1,"tf2-keras-cifar10-inceptionv3-elastic-20210722-122354":1,"tf2-keras-cifar10-resnet50-elastic-20210722-122006":1,"tf2-keras-cifar10-resnet50-elastic-20210722-122327":1,"tf2-keras-cifar10-resnet50-elastic-20210722-122542":1,"tf2-keras-cifar10-vgg16-elastic-20210722-122104":1,"tf2-keras-cifar10-vgg16-elastic-20210722-122126":1,"tf2-keras-cifar10-vgg16-elastic-20210722-122446":1,"tf2-keras-cifar10-vgg16-elastic-20210722-122513":1,"tf2-keras-transformer-elastic-20210722-122149":1,"tf2-keras-transformer-elastic-20210722-122215":1,"tf2-keras-transformer-elastic-20210722-122421":1} "scheduler"="default"
I0722 00:25:43.813281   23824 scheduler.go:384]  "msg"="Trying to delete multiple training jobs"  "jobs"=["tf2-keras-cifar10-inceptionv3-elastic-20210722-122034","tf2-keras-cifar10-inceptionv3-elastic-20210722-121943"] "scheduler"="default"
I0722 00:25:43.833213   23824 scheduler.go:342]  "msg"="Trying to scale multiple training jobs"  "jobs"=["tf2-keras-cifar10-resnet50-elastic-20210722-122327","tf2-keras-cifar10-vgg16-elastic-20210722-122126","tf2-keras-cifar10-vgg16-elastic-20210722-122104"] "scheduler"="default"
I0722 00:25:43.876092   23824 scheduler.go:292]  "msg"="Trying to start multiple training jobs"  "jobs"=["tf2-keras-transformer-elastic-20210722-122421","tf2-keras-cifar10-vgg16-elastic-20210722-122446","tf2-keras-cifar10-vgg16-elastic-20210722-122513","tf2-keras-cifar10-resnet50-elastic-20210722-122542","tf2-keras-cifar10-inceptionv3-elastic-20210722-122354"] "scheduler"="default"
I0722 00:25:44.425193   23824 scheduler.go:342]  "msg"="Trying to scale multiple training jobs"  "jobs"=[] "scheduler"="default"
I0722 00:25:44.430122   23824 placement_manager.go:166]  "msg"="Started job placements adjustment"  "scheduler"="default"
I0722 00:25:44.430236   23824 placement_manager.go:192]  "msg"="Releasing slots"  "jobs"={"tf2-keras-cifar10-inceptionv3-elastic-20210722-121943":{},"tf2-keras-cifar10-inceptionv3-elastic-20210722-122034":{},"tf2-keras-cifar10-inceptionv3-elastic-20210722-122250":{},"tf2-keras-cifar10-resnet50-elastic-20210722-122006":{},"tf2-keras-cifar10-resnet50-elastic-20210722-122327":{},"tf2-keras-cifar10-vgg16-elastic-20210722-122104":{},"tf2-keras-cifar10-vgg16-elastic-20210722-122126":{},"tf2-keras-transformer-elastic-20210722-122149":{},"tf2-keras-transformer-elastic-20210722-122215":{}} "nodes"={"gpu3":{},"gpu4":{},"gpu5":{}} "scheduler"="default"
I0722 00:25:44.430352   23824 placement_manager.go:250]  "msg"="Released slots"  "jobs"={"tf2-keras-cifar10-inceptionv3-elastic-20210722-121943":{},"tf2-keras-cifar10-inceptionv3-elastic-20210722-122034":{},"tf2-keras-cifar10-inceptionv3-elastic-20210722-122250":{},"tf2-keras-cifar10-resnet50-elastic-20210722-122006":{},"tf2-keras-cifar10-resnet50-elastic-20210722-122327":{},"tf2-keras-cifar10-vgg16-elastic-20210722-122104":{},"tf2-keras-cifar10-vgg16-elastic-20210722-122126":{},"tf2-keras-transformer-elastic-20210722-122149":{},"tf2-keras-transformer-elastic-20210722-122215":{}} "nodes"={"gpu3":{},"gpu4":{},"gpu5":{}} "scheduler"="default"
I0722 00:25:44.430751   23824 placement_manager.go:305]  "msg"="Found best-fit"  "crossNode"=0 "nodes"=[{},{},{}] "requests"=[{},{},{},{},{},{},{},{},{},{},{},{},{},{},{},{},{},{},{},{},{},{},{},{},{},{},{},{}] "scheduler"="default"
I0722 00:25:44.431060   23824 placement_manager.go:339]  "msg"="nodeStates updated"  "new"={"gpu3":{},"gpu4":{},"gpu5":{}} "old"={"gpu3":{},"gpu4":{},"gpu5":{}} "scheduler"="default" "score"=4
I0722 00:25:44.431429   23824 placement_manager.go:387]  "msg"="jobStates updated"  "new"={"tf2-keras-cifar10-inceptionv3-elastic-20210722-122250":{},"tf2-keras-cifar10-inceptionv3-elastic-20210722-122354":{},"tf2-keras-cifar10-resnet50-elastic-20210722-122006":{},"tf2-keras-cifar10-resnet50-elastic-20210722-122327":{},"tf2-keras-cifar10-resnet50-elastic-20210722-122542":{},"tf2-keras-cifar10-vgg16-elastic-20210722-122104":{},"tf2-keras-cifar10-vgg16-elastic-20210722-122126":{},"tf2-keras-cifar10-vgg16-elastic-20210722-122446":{},"tf2-keras-cifar10-vgg16-elastic-20210722-122513":{},"tf2-keras-transformer-elastic-20210722-122149":{},"tf2-keras-transformer-elastic-20210722-122215":{},"tf2-keras-transformer-elastic-20210722-122421":{}} "old"={"tf2-keras-cifar10-inceptionv3-elastic-20210722-121943":{},"tf2-keras-cifar10-inceptionv3-elastic-20210722-122034":{},"tf2-keras-cifar10-inceptionv3-elastic-20210722-122250":{},"tf2-keras-cifar10-resnet50-elastic-20210722-122006":{},"tf2-keras-cifar10-resnet50-elastic-20210722-122327":{},"tf2-keras-cifar10-vgg16-elastic-20210722-122104":{},"tf2-keras-cifar10-vgg16-elastic-20210722-122126":{},"tf2-keras-transformer-elastic-20210722-122149":{},"tf2-keras-transformer-elastic-20210722-122215":{}} "scheduler"="default"
I0722 00:25:44.431855   23824 placement_manager.go:434]  "msg"="podNodeName updated"  "launchersToDelete"=3 "new"={"tf2-keras-cifar10-inceptionv3-elastic-20210722-122250-worker-0":"gpu3","tf2-keras-cifar10-inceptionv3-elastic-20210722-122354-worker-0":"gpu5","tf2-keras-cifar10-resnet50-elastic-20210722-122006-worker-0":"gpu3","tf2-keras-cifar10-resnet50-elastic-20210722-122327-worker-0":"gpu4","tf2-keras-cifar10-resnet50-elastic-20210722-122542-worker-0":"gpu4","tf2-keras-cifar10-vgg16-elastic-20210722-122104-worker-0":"gpu4","tf2-keras-cifar10-vgg16-elastic-20210722-122126-worker-0":"gpu5","tf2-keras-cifar10-vgg16-elastic-20210722-122446-worker-0":"gpu3","tf2-keras-cifar10-vgg16-elastic-20210722-122513-worker-0":"gpu4","tf2-keras-transformer-elastic-20210722-122149-worker-0":"gpu5","tf2-keras-transformer-elastic-20210722-122215-worker-0":"gpu5","tf2-keras-transformer-elastic-20210722-122421-worker-0":"gpu3"} "old"={"tf2-keras-cifar10-inceptionv3-elastic-20210722-121943-worker-0":"gpu3","tf2-keras-cifar10-inceptionv3-elastic-20210722-122034-worker-0":"gpu5","tf2-keras-cifar10-inceptionv3-elastic-20210722-122250-worker-0":"gpu5","tf2-keras-cifar10-resnet50-elastic-20210722-122006-worker-0":"gpu3","tf2-keras-cifar10-resnet50-elastic-20210722-122327-worker-0":"gpu3","tf2-keras-cifar10-resnet50-elastic-20210722-122327-worker-1":"gpu3","tf2-keras-cifar10-vgg16-elastic-20210722-122104-worker-0":"gpu4","tf2-keras-cifar10-vgg16-elastic-20210722-122104-worker-1":"gpu4","tf2-keras-cifar10-vgg16-elastic-20210722-122126-worker-0":"gpu4","tf2-keras-cifar10-vgg16-elastic-20210722-122126-worker-1":"gpu4","tf2-keras-transformer-elastic-20210722-122149-worker-0":"gpu5","tf2-keras-transformer-elastic-20210722-122215-worker-0":"gpu5"} "scheduler"="default" "workersToDelete"=3
I0722 00:25:44.432170   23824 placement_manager.go:451]  "msg"="Deleting pod that need migration"  "podName"="tf2-keras-cifar10-vgg16-elastic-20210722-122126-worker-0" "scheduler"="default"
I0722 00:25:44.439641   23824 placement_manager.go:451]  "msg"="Deleting pod that need migration"  "podName"="tf2-keras-cifar10-vgg16-elastic-20210722-122126-launcher" "scheduler"="default"
I0722 00:25:44.444814   23824 placement_manager.go:451]  "msg"="Deleting pod that need migration"  "podName"="tf2-keras-cifar10-inceptionv3-elastic-20210722-122250-worker-0" "scheduler"="default"
I0722 00:25:44.452757   23824 placement_manager.go:451]  "msg"="Deleting pod that need migration"  "podName"="tf2-keras-cifar10-inceptionv3-elastic-20210722-122250-launcher" "scheduler"="default"
I0722 00:25:44.462499   23824 placement_manager.go:451]  "msg"="Deleting pod that need migration"  "podName"="tf2-keras-cifar10-resnet50-elastic-20210722-122327-worker-0" "scheduler"="default"
I0722 00:25:44.467762   23824 placement_manager.go:451]  "msg"="Deleting pod that need migration"  "podName"="tf2-keras-cifar10-resnet50-elastic-20210722-122327-launcher" "scheduler"="default"
I0722 00:25:44.473546   23824 placement_manager.go:183]  "msg"="Finished job placements adjustment"  "scheduler"="default"
I0722 00:25:44.473849   23824 scheduler.go:182]  "msg"="Finished resched"  "scheduler"="default"
I0722 00:25:47.263908   23824 placement_manager.go:147]  "msg"="Adding toleration to pod"  "podName"="tf2-keras-transformer-elastic-20210722-122421-worker-0" "scheduler"="default" "toleration"={"key":"celeste/hostname","operator":"Equal","value":"gpu3","effect":"NoExecute"}
I0722 00:25:47.860475   23824 placement_manager.go:147]  "msg"="Adding toleration to pod"  "podName"="tf2-keras-transformer-elastic-20210722-122421-launcher" "scheduler"="default" "toleration"={"key":"celeste/hostname","operator":"Exists","effect":"NoExecute"}
I0722 00:25:48.060641   23824 placement_manager.go:147]  "msg"="Adding toleration to pod"  "podName"="tf2-keras-cifar10-vgg16-elastic-20210722-122446-worker-0" "scheduler"="default" "toleration"={"key":"celeste/hostname","operator":"Equal","value":"gpu3","effect":"NoExecute"}
I0722 00:25:48.661392   23824 placement_manager.go:147]  "msg"="Adding toleration to pod"  "podName"="tf2-keras-cifar10-vgg16-elastic-20210722-122446-launcher" "scheduler"="default" "toleration"={"key":"celeste/hostname","operator":"Exists","effect":"NoExecute"}
I0722 00:25:50.060433   23824 placement_manager.go:147]  "msg"="Adding toleration to pod"  "podName"="tf2-keras-cifar10-vgg16-elastic-20210722-122513-worker-0" "scheduler"="default" "toleration"={"key":"celeste/hostname","operator":"Equal","value":"gpu4","effect":"NoExecute"}
I0722 00:25:50.461078   23824 placement_manager.go:147]  "msg"="Adding toleration to pod"  "podName"="tf2-keras-cifar10-vgg16-elastic-20210722-122513-launcher" "scheduler"="default" "toleration"={"key":"celeste/hostname","operator":"Exists","effect":"NoExecute"}
I0722 00:25:50.660042   23824 placement_manager.go:147]  "msg"="Adding toleration to pod"  "podName"="tf2-keras-cifar10-resnet50-elastic-20210722-122542-worker-0" "scheduler"="default" "toleration"={"key":"celeste/hostname","operator":"Equal","value":"gpu4","effect":"NoExecute"}
I0722 00:25:51.060979   23824 placement_manager.go:147]  "msg"="Adding toleration to pod"  "podName"="tf2-keras-cifar10-resnet50-elastic-20210722-122542-launcher" "scheduler"="default" "toleration"={"key":"celeste/hostname","operator":"Exists","effect":"NoExecute"}
I0722 00:25:52.461252   23824 placement_manager.go:147]  "msg"="Adding toleration to pod"  "podName"="tf2-keras-cifar10-inceptionv3-elastic-20210722-122354-worker-0" "scheduler"="default" "toleration"={"key":"celeste/hostname","operator":"Equal","value":"gpu5","effect":"NoExecute"}
I0722 00:25:53.060141   23824 placement_manager.go:147]  "msg"="Adding toleration to pod"  "podName"="tf2-keras-cifar10-inceptionv3-elastic-20210722-122354-launcher" "scheduler"="default" "toleration"={"key":"celeste/hostname","operator":"Exists","effect":"NoExecute"}
I0722 00:25:53.274565   23824 placement_manager.go:147]  "msg"="Adding toleration to pod"  "podName"="tf2-keras-cifar10-resnet50-elastic-20210722-122327-worker-0" "scheduler"="default" "toleration"={"key":"celeste/hostname","operator":"Equal","value":"gpu4","effect":"NoExecute"}
I0722 00:25:53.674632   23824 placement_manager.go:147]  "msg"="Adding toleration to pod"  "podName"="tf2-keras-cifar10-resnet50-elastic-20210722-122327-launcher" "scheduler"="default" "toleration"={"key":"celeste/hostname","operator":"Exists","effect":"NoExecute"}
I0722 00:25:55.935774   23824 placement_manager.go:147]  "msg"="Adding toleration to pod"  "podName"="tf2-keras-cifar10-inceptionv3-elastic-20210722-122250-worker-0" "scheduler"="default" "toleration"={"key":"celeste/hostname","operator":"Equal","value":"gpu3","effect":"NoExecute"}
I0722 00:25:58.143531   23824 placement_manager.go:147]  "msg"="Adding toleration to pod"  "podName"="tf2-keras-cifar10-vgg16-elastic-20210722-122126-worker-0" "scheduler"="default" "toleration"={"key":"celeste/hostname","operator":"Equal","value":"gpu5","effect":"NoExecute"}
I0722 00:26:01.542107   23824 placement_manager.go:147]  "msg"="Adding toleration to pod"  "podName"="tf2-keras-cifar10-inceptionv3-elastic-20210722-122250-launcher" "scheduler"="default" "toleration"={"key":"celeste/hostname","operator":"Exists","effect":"NoExecute"}
I0722 00:26:04.233419   23824 placement_manager.go:147]  "msg"="Adding toleration to pod"  "podName"="tf2-keras-cifar10-vgg16-elastic-20210722-122126-launcher" "scheduler"="default" "toleration"={"key":"celeste/hostname","operator":"Exists","effect":"NoExecute"}
I0722 00:26:11.259528   23824 jobmaster.go:155]  "msg"="Training job created"  "job"="tf2-keras-cifar10-inceptionv3-elastic-20210722-122611"
I0722 00:26:11.259625   23824 scheduler.go:135]  "msg"="Received resched event, may be blocked because of rate limit"  "blockedUntil"="2021-07-22T00:27:44.474040598+08:00" "lastResched"="2021-07-22T00:25:44.474040598+08:00" "received"="2021-07-22T00:26:11.259007214+08:00" "scheduler"="default"
I0722 00:26:47.203521   23824 jobmaster.go:155]  "msg"="Training job created"  "job"="tf2-keras-transformer-elastic-20210722-122647"
I0722 00:27:10.108886   23824 jobmaster.go:155]  "msg"="Training job created"  "job"="tf2-keras-cifar10-inceptionv3-elastic-20210722-122710"
I0722 00:27:31.969601   23824 jobmaster.go:155]  "msg"="Training job created"  "job"="tf2-keras-cifar10-resnet50-elastic-20210722-122731"
I0722 00:27:44.474089   23824 scheduler.go:159]  "msg"="Started resched"  "scheduler"="default"
I0722 00:27:44.474154   23824 scheduler.go:193]  "msg"="Updating all jobs info"  "scheduler"="default"
I0722 00:27:44.483577   23824 afsl.go:65]  "msg"="Finished scheduling"  "algorithm"="AFS-L" "freeGpu"=0 "result"={"tf2-keras-cifar10-inceptionv3-elastic-20210722-121943":0,"tf2-keras-cifar10-inceptionv3-elastic-20210722-122034":0,"tf2-keras-cifar10-inceptionv3-elastic-20210722-122250":0,"tf2-keras-cifar10-inceptionv3-elastic-20210722-122354":0,"tf2-keras-cifar10-inceptionv3-elastic-20210722-122611":0,"tf2-keras-cifar10-inceptionv3-elastic-20210722-122710":0,"tf2-keras-cifar10-resnet50-elastic-20210722-122006":1,"tf2-keras-cifar10-resnet50-elastic-20210722-122327":1,"tf2-keras-cifar10-resnet50-elastic-20210722-122542":1,"tf2-keras-cifar10-resnet50-elastic-20210722-122731":1,"tf2-keras-cifar10-vgg16-elastic-20210722-122104":1,"tf2-keras-cifar10-vgg16-elastic-20210722-122126":1,"tf2-keras-cifar10-vgg16-elastic-20210722-122446":1,"tf2-keras-cifar10-vgg16-elastic-20210722-122513":1,"tf2-keras-transformer-elastic-20210722-122149":1,"tf2-keras-transformer-elastic-20210722-122215":1,"tf2-keras-transformer-elastic-20210722-122421":1,"tf2-keras-transformer-elastic-20210722-122647":1} "scheduler"="default"
I0722 00:27:44.484082   23824 scheduler.go:384]  "msg"="Trying to delete multiple training jobs"  "jobs"=["tf2-keras-cifar10-inceptionv3-elastic-20210722-122354","tf2-keras-cifar10-inceptionv3-elastic-20210722-122250"] "scheduler"="default"
I0722 00:27:44.519925   23824 scheduler.go:342]  "msg"="Trying to scale multiple training jobs"  "jobs"=[] "scheduler"="default"
I0722 00:27:44.520218   23824 scheduler.go:292]  "msg"="Trying to start multiple training jobs"  "jobs"=["tf2-keras-cifar10-resnet50-elastic-20210722-122731","tf2-keras-transformer-elastic-20210722-122647"] "scheduler"="default"
I0722 00:27:44.538331   23824 scheduler.go:342]  "msg"="Trying to scale multiple training jobs"  "jobs"=[] "scheduler"="default"
I0722 00:27:44.543869   23824 placement_manager.go:166]  "msg"="Started job placements adjustment"  "scheduler"="default"
I0722 00:27:44.543989   23824 placement_manager.go:192]  "msg"="Releasing slots"  "jobs"={"tf2-keras-cifar10-inceptionv3-elastic-20210722-122250":{},"tf2-keras-cifar10-inceptionv3-elastic-20210722-122354":{},"tf2-keras-cifar10-resnet50-elastic-20210722-122006":{},"tf2-keras-cifar10-resnet50-elastic-20210722-122327":{},"tf2-keras-cifar10-resnet50-elastic-20210722-122542":{},"tf2-keras-cifar10-vgg16-elastic-20210722-122104":{},"tf2-keras-cifar10-vgg16-elastic-20210722-122126":{},"tf2-keras-cifar10-vgg16-elastic-20210722-122446":{},"tf2-keras-cifar10-vgg16-elastic-20210722-122513":{},"tf2-keras-transformer-elastic-20210722-122149":{},"tf2-keras-transformer-elastic-20210722-122215":{},"tf2-keras-transformer-elastic-20210722-122421":{}} "nodes"={"gpu3":{},"gpu4":{},"gpu5":{}} "scheduler"="default"
I0722 00:27:44.544101   23824 placement_manager.go:250]  "msg"="Released slots"  "jobs"={"tf2-keras-cifar10-inceptionv3-elastic-20210722-122250":{},"tf2-keras-cifar10-inceptionv3-elastic-20210722-122354":{},"tf2-keras-cifar10-resnet50-elastic-20210722-122006":{},"tf2-keras-cifar10-resnet50-elastic-20210722-122327":{},"tf2-keras-cifar10-resnet50-elastic-20210722-122542":{},"tf2-keras-cifar10-vgg16-elastic-20210722-122104":{},"tf2-keras-cifar10-vgg16-elastic-20210722-122126":{},"tf2-keras-cifar10-vgg16-elastic-20210722-122446":{},"tf2-keras-cifar10-vgg16-elastic-20210722-122513":{},"tf2-keras-transformer-elastic-20210722-122149":{},"tf2-keras-transformer-elastic-20210722-122215":{},"tf2-keras-transformer-elastic-20210722-122421":{}} "nodes"={"gpu3":{},"gpu4":{},"gpu5":{}} "scheduler"="default"
I0722 00:27:44.544552   23824 placement_manager.go:305]  "msg"="Found best-fit"  "crossNode"=0 "nodes"=[{},{},{}] "requests"=[{},{},{},{},{},{},{},{},{},{},{},{},{},{},{},{},{},{},{},{},{},{},{},{},{},{},{},{},{},{},{},{},{},{},{},{}] "scheduler"="default"
I0722 00:27:44.545134   23824 placement_manager.go:339]  "msg"="nodeStates updated"  "new"={"gpu3":{},"gpu4":{},"gpu5":{}} "old"={"gpu3":{},"gpu4":{},"gpu5":{}} "scheduler"="default" "score"=6
I0722 00:27:44.545579   23824 placement_manager.go:387]  "msg"="jobStates updated"  "new"={"tf2-keras-cifar10-resnet50-elastic-20210722-122006":{},"tf2-keras-cifar10-resnet50-elastic-20210722-122327":{},"tf2-keras-cifar10-resnet50-elastic-20210722-122542":{},"tf2-keras-cifar10-resnet50-elastic-20210722-122731":{},"tf2-keras-cifar10-vgg16-elastic-20210722-122104":{},"tf2-keras-cifar10-vgg16-elastic-20210722-122126":{},"tf2-keras-cifar10-vgg16-elastic-20210722-122446":{},"tf2-keras-cifar10-vgg16-elastic-20210722-122513":{},"tf2-keras-transformer-elastic-20210722-122149":{},"tf2-keras-transformer-elastic-20210722-122215":{},"tf2-keras-transformer-elastic-20210722-122421":{},"tf2-keras-transformer-elastic-20210722-122647":{}} "old"={"tf2-keras-cifar10-inceptionv3-elastic-20210722-122250":{},"tf2-keras-cifar10-inceptionv3-elastic-20210722-122354":{},"tf2-keras-cifar10-resnet50-elastic-20210722-122006":{},"tf2-keras-cifar10-resnet50-elastic-20210722-122327":{},"tf2-keras-cifar10-resnet50-elastic-20210722-122542":{},"tf2-keras-cifar10-vgg16-elastic-20210722-122104":{},"tf2-keras-cifar10-vgg16-elastic-20210722-122126":{},"tf2-keras-cifar10-vgg16-elastic-20210722-122446":{},"tf2-keras-cifar10-vgg16-elastic-20210722-122513":{},"tf2-keras-transformer-elastic-20210722-122149":{},"tf2-keras-transformer-elastic-20210722-122215":{},"tf2-keras-transformer-elastic-20210722-122421":{}} "scheduler"="default"
I0722 00:27:44.546066   23824 placement_manager.go:434]  "msg"="podNodeName updated"  "launchersToDelete"=4 "new"={"tf2-keras-cifar10-resnet50-elastic-20210722-122006-worker-0":"gpu4","tf2-keras-cifar10-resnet50-elastic-20210722-122327-worker-0":"gpu4","tf2-keras-cifar10-resnet50-elastic-20210722-122542-worker-0":"gpu4","tf2-keras-cifar10-resnet50-elastic-20210722-122731-worker-0":"gpu3","tf2-keras-cifar10-vgg16-elastic-20210722-122104-worker-0":"gpu4","tf2-keras-cifar10-vgg16-elastic-20210722-122126-worker-0":"gpu5","tf2-keras-cifar10-vgg16-elastic-20210722-122446-worker-0":"gpu5","tf2-keras-cifar10-vgg16-elastic-20210722-122513-worker-0":"gpu3","tf2-keras-transformer-elastic-20210722-122149-worker-0":"gpu3","tf2-keras-transformer-elastic-20210722-122215-worker-0":"gpu5","tf2-keras-transformer-elastic-20210722-122421-worker-0":"gpu3","tf2-keras-transformer-elastic-20210722-122647-worker-0":"gpu5"} "old"={"tf2-keras-cifar10-inceptionv3-elastic-20210722-122250-worker-0":"gpu3","tf2-keras-cifar10-inceptionv3-elastic-20210722-122354-worker-0":"gpu5","tf2-keras-cifar10-resnet50-elastic-20210722-122006-worker-0":"gpu3","tf2-keras-cifar10-resnet50-elastic-20210722-122327-worker-0":"gpu4","tf2-keras-cifar10-resnet50-elastic-20210722-122542-worker-0":"gpu4","tf2-keras-cifar10-vgg16-elastic-20210722-122104-worker-0":"gpu4","tf2-keras-cifar10-vgg16-elastic-20210722-122126-worker-0":"gpu5","tf2-keras-cifar10-vgg16-elastic-20210722-122446-worker-0":"gpu3","tf2-keras-cifar10-vgg16-elastic-20210722-122513-worker-0":"gpu4","tf2-keras-transformer-elastic-20210722-122149-worker-0":"gpu5","tf2-keras-transformer-elastic-20210722-122215-worker-0":"gpu5","tf2-keras-transformer-elastic-20210722-122421-worker-0":"gpu3"} "scheduler"="default" "workersToDelete"=4
I0722 00:27:44.546467   23824 placement_manager.go:451]  "msg"="Deleting pod that need migration"  "podName"="tf2-keras-transformer-elastic-20210722-122149-worker-0" "scheduler"="default"
I0722 00:27:44.550681   23824 placement_manager.go:451]  "msg"="Deleting pod that need migration"  "podName"="tf2-keras-transformer-elastic-20210722-122149-launcher" "scheduler"="default"
I0722 00:27:44.555492   23824 placement_manager.go:451]  "msg"="Deleting pod that need migration"  "podName"="tf2-keras-cifar10-resnet50-elastic-20210722-122006-worker-0" "scheduler"="default"
I0722 00:27:44.560032   23824 placement_manager.go:451]  "msg"="Deleting pod that need migration"  "podName"="tf2-keras-cifar10-resnet50-elastic-20210722-122006-launcher" "scheduler"="default"
I0722 00:27:44.568136   23824 placement_manager.go:451]  "msg"="Deleting pod that need migration"  "podName"="tf2-keras-cifar10-vgg16-elastic-20210722-122446-worker-0" "scheduler"="default"
I0722 00:27:44.571220   23824 placement_manager.go:451]  "msg"="Deleting pod that need migration"  "podName"="tf2-keras-cifar10-vgg16-elastic-20210722-122446-launcher" "scheduler"="default"
I0722 00:27:44.574844   23824 placement_manager.go:451]  "msg"="Deleting pod that need migration"  "podName"="tf2-keras-cifar10-vgg16-elastic-20210722-122513-worker-0" "scheduler"="default"
I0722 00:27:44.583391   23824 placement_manager.go:451]  "msg"="Deleting pod that need migration"  "podName"="tf2-keras-cifar10-vgg16-elastic-20210722-122513-launcher" "scheduler"="default"
I0722 00:27:44.588566   23824 placement_manager.go:183]  "msg"="Finished job placements adjustment"  "scheduler"="default"
I0722 00:27:44.588785   23824 scheduler.go:182]  "msg"="Finished resched"  "scheduler"="default"
I0722 00:27:44.736758   23824 placement_manager.go:147]  "msg"="Adding toleration to pod"  "podName"="tf2-keras-cifar10-resnet50-elastic-20210722-122731-worker-0" "scheduler"="default" "toleration"={"key":"celeste/hostname","operator":"Equal","value":"gpu3","effect":"NoExecute"}
I0722 00:27:44.935558   23824 placement_manager.go:147]  "msg"="Adding toleration to pod"  "podName"="tf2-keras-transformer-elastic-20210722-122647-worker-0" "scheduler"="default" "toleration"={"key":"celeste/hostname","operator":"Equal","value":"gpu5","effect":"NoExecute"}
I0722 00:27:45.353088   23824 placement_manager.go:147]  "msg"="Adding toleration to pod"  "podName"="tf2-keras-cifar10-resnet50-elastic-20210722-122731-launcher" "scheduler"="default" "toleration"={"key":"celeste/hostname","operator":"Exists","effect":"NoExecute"}
I0722 00:27:45.758371   23824 placement_manager.go:147]  "msg"="Adding toleration to pod"  "podName"="tf2-keras-transformer-elastic-20210722-122647-launcher" "scheduler"="default" "toleration"={"key":"celeste/hostname","operator":"Exists","effect":"NoExecute"}
I0722 00:27:51.967766   23824 placement_manager.go:147]  "msg"="Adding toleration to pod"  "podName"="tf2-keras-cifar10-resnet50-elastic-20210722-122006-launcher" "scheduler"="default" "toleration"={"key":"celeste/hostname","operator":"Exists","effect":"NoExecute"}
I0722 00:27:52.004593   23824 placement_manager.go:147]  "msg"="Adding toleration to pod"  "podName"="tf2-keras-transformer-elastic-20210722-122149-worker-0" "scheduler"="default" "toleration"={"key":"celeste/hostname","operator":"Equal","value":"gpu3","effect":"NoExecute"}
I0722 00:27:53.088142   23824 placement_manager.go:147]  "msg"="Adding toleration to pod"  "podName"="tf2-keras-cifar10-vgg16-elastic-20210722-122513-launcher" "scheduler"="default" "toleration"={"key":"celeste/hostname","operator":"Exists","effect":"NoExecute"}
I0722 00:27:53.129725   23824 placement_manager.go:147]  "msg"="Adding toleration to pod"  "podName"="tf2-keras-cifar10-vgg16-elastic-20210722-122513-worker-0" "scheduler"="default" "toleration"={"key":"celeste/hostname","operator":"Equal","value":"gpu3","effect":"NoExecute"}
I0722 00:27:53.139479   23824 placement_manager.go:147]  "msg"="Adding toleration to pod"  "podName"="tf2-keras-cifar10-vgg16-elastic-20210722-122446-launcher" "scheduler"="default" "toleration"={"key":"celeste/hostname","operator":"Exists","effect":"NoExecute"}
I0722 00:27:54.045452   23824 placement_manager.go:147]  "msg"="Adding toleration to pod"  "podName"="tf2-keras-cifar10-resnet50-elastic-20210722-122006-worker-0" "scheduler"="default" "toleration"={"key":"celeste/hostname","operator":"Equal","value":"gpu4","effect":"NoExecute"}
I0722 00:28:01.433512   23824 placement_manager.go:147]  "msg"="Adding toleration to pod"  "podName"="tf2-keras-cifar10-vgg16-elastic-20210722-122446-worker-0" "scheduler"="default" "toleration"={"key":"celeste/hostname","operator":"Equal","value":"gpu5","effect":"NoExecute"}
I0722 00:28:04.585968   23824 placement_manager.go:147]  "msg"="Adding toleration to pod"  "podName"="tf2-keras-transformer-elastic-20210722-122149-launcher" "scheduler"="default" "toleration"={"key":"celeste/hostname","operator":"Exists","effect":"NoExecute"}
I0722 00:28:04.927332   23824 jobmaster.go:155]  "msg"="Training job created"  "job"="tf2-keras-cifar10-vgg16-elastic-20210722-122804"
I0722 00:28:04.927434   23824 scheduler.go:135]  "msg"="Received resched event, may be blocked because of rate limit"  "blockedUntil"="2021-07-22T00:29:44.588975075+08:00" "lastResched"="2021-07-22T00:27:44.588975075+08:00" "received"="2021-07-22T00:28:04.926811265+08:00" "scheduler"="default"
I0722 00:28:26.840599   23824 jobmaster.go:155]  "msg"="Training job created"  "job"="tf2-keras-transformer-elastic-20210722-122826"
I0722 00:29:06.922947   23824 jobmaster.go:155]  "msg"="Training job created"  "job"="tf2-keras-cifar10-vgg16-elastic-20210722-122906"
I0722 00:29:44.589064   23824 scheduler.go:159]  "msg"="Started resched"  "scheduler"="default"
I0722 00:29:44.589166   23824 scheduler.go:193]  "msg"="Updating all jobs info"  "scheduler"="default"
I0722 00:29:44.601923   23824 afsl.go:65]  "msg"="Finished scheduling"  "algorithm"="AFS-L" "freeGpu"=0 "result"={"tf2-keras-cifar10-inceptionv3-elastic-20210722-121943":0,"tf2-keras-cifar10-inceptionv3-elastic-20210722-122034":0,"tf2-keras-cifar10-inceptionv3-elastic-20210722-122250":0,"tf2-keras-cifar10-inceptionv3-elastic-20210722-122354":0,"tf2-keras-cifar10-inceptionv3-elastic-20210722-122611":0,"tf2-keras-cifar10-inceptionv3-elastic-20210722-122710":0,"tf2-keras-cifar10-resnet50-elastic-20210722-122006":1,"tf2-keras-cifar10-resnet50-elastic-20210722-122327":1,"tf2-keras-cifar10-resnet50-elastic-20210722-122542":1,"tf2-keras-cifar10-resnet50-elastic-20210722-122731":1,"tf2-keras-cifar10-vgg16-elastic-20210722-122104":1,"tf2-keras-cifar10-vgg16-elastic-20210722-122126":1,"tf2-keras-cifar10-vgg16-elastic-20210722-122446":1,"tf2-keras-cifar10-vgg16-elastic-20210722-122513":1,"tf2-keras-cifar10-vgg16-elastic-20210722-122804":1,"tf2-keras-cifar10-vgg16-elastic-20210722-122906":1,"tf2-keras-transformer-elastic-20210722-122149":1,"tf2-keras-transformer-elastic-20210722-122215":1,"tf2-keras-transformer-elastic-20210722-122421":0,"tf2-keras-transformer-elastic-20210722-122647":0,"tf2-keras-transformer-elastic-20210722-122826":0} "scheduler"="default"
I0722 00:29:44.602179   23824 scheduler.go:384]  "msg"="Trying to delete multiple training jobs"  "jobs"=["tf2-keras-transformer-elastic-20210722-122421","tf2-keras-transformer-elastic-20210722-122647"] "scheduler"="default"
I0722 00:29:44.621506   23824 scheduler.go:342]  "msg"="Trying to scale multiple training jobs"  "jobs"=[] "scheduler"="default"
I0722 00:29:44.621806   23824 scheduler.go:292]  "msg"="Trying to start multiple training jobs"  "jobs"=["tf2-keras-cifar10-vgg16-elastic-20210722-122804","tf2-keras-cifar10-vgg16-elastic-20210722-122906"] "scheduler"="default"
I0722 00:29:44.644045   23824 scheduler.go:342]  "msg"="Trying to scale multiple training jobs"  "jobs"=[] "scheduler"="default"
I0722 00:29:44.648915   23824 placement_manager.go:166]  "msg"="Started job placements adjustment"  "scheduler"="default"
I0722 00:29:44.649041   23824 placement_manager.go:192]  "msg"="Releasing slots"  "jobs"={"tf2-keras-cifar10-resnet50-elastic-20210722-122006":{},"tf2-keras-cifar10-resnet50-elastic-20210722-122327":{},"tf2-keras-cifar10-resnet50-elastic-20210722-122542":{},"tf2-keras-cifar10-resnet50-elastic-20210722-122731":{},"tf2-keras-cifar10-vgg16-elastic-20210722-122104":{},"tf2-keras-cifar10-vgg16-elastic-20210722-122126":{},"tf2-keras-cifar10-vgg16-elastic-20210722-122446":{},"tf2-keras-cifar10-vgg16-elastic-20210722-122513":{},"tf2-keras-transformer-elastic-20210722-122149":{},"tf2-keras-transformer-elastic-20210722-122215":{},"tf2-keras-transformer-elastic-20210722-122421":{},"tf2-keras-transformer-elastic-20210722-122647":{}} "nodes"={"gpu3":{},"gpu4":{},"gpu5":{}} "scheduler"="default"
I0722 00:29:44.649127   23824 placement_manager.go:250]  "msg"="Released slots"  "jobs"={"tf2-keras-cifar10-resnet50-elastic-20210722-122006":{},"tf2-keras-cifar10-resnet50-elastic-20210722-122327":{},"tf2-keras-cifar10-resnet50-elastic-20210722-122542":{},"tf2-keras-cifar10-resnet50-elastic-20210722-122731":{},"tf2-keras-cifar10-vgg16-elastic-20210722-122104":{},"tf2-keras-cifar10-vgg16-elastic-20210722-122126":{},"tf2-keras-cifar10-vgg16-elastic-20210722-122446":{},"tf2-keras-cifar10-vgg16-elastic-20210722-122513":{},"tf2-keras-transformer-elastic-20210722-122149":{},"tf2-keras-transformer-elastic-20210722-122215":{},"tf2-keras-transformer-elastic-20210722-122421":{},"tf2-keras-transformer-elastic-20210722-122647":{}} "nodes"={"gpu3":{},"gpu4":{},"gpu5":{}} "scheduler"="default"
I0722 00:29:44.649521   23824 placement_manager.go:305]  "msg"="Found best-fit"  "crossNode"=0 "nodes"=[{},{},{}] "requests"=[{},{},{},{},{},{},{},{},{},{},{},{},{},{},{},{},{},{},{},{},{},{},{},{},{},{},{},{},{},{},{},{},{},{},{},{},{},{},{},{},{},{}] "scheduler"="default"
I0722 00:29:44.649797   23824 placement_manager.go:339]  "msg"="nodeStates updated"  "new"={"gpu3":{},"gpu4":{},"gpu5":{}} "old"={"gpu3":{},"gpu4":{},"gpu5":{}} "scheduler"="default" "score"=5
I0722 00:29:44.650128   23824 placement_manager.go:387]  "msg"="jobStates updated"  "new"={"tf2-keras-cifar10-resnet50-elastic-20210722-122006":{},"tf2-keras-cifar10-resnet50-elastic-20210722-122327":{},"tf2-keras-cifar10-resnet50-elastic-20210722-122542":{},"tf2-keras-cifar10-resnet50-elastic-20210722-122731":{},"tf2-keras-cifar10-vgg16-elastic-20210722-122104":{},"tf2-keras-cifar10-vgg16-elastic-20210722-122126":{},"tf2-keras-cifar10-vgg16-elastic-20210722-122446":{},"tf2-keras-cifar10-vgg16-elastic-20210722-122513":{},"tf2-keras-cifar10-vgg16-elastic-20210722-122804":{},"tf2-keras-cifar10-vgg16-elastic-20210722-122906":{},"tf2-keras-transformer-elastic-20210722-122149":{},"tf2-keras-transformer-elastic-20210722-122215":{}} "old"={"tf2-keras-cifar10-resnet50-elastic-20210722-122006":{},"tf2-keras-cifar10-resnet50-elastic-20210722-122327":{},"tf2-keras-cifar10-resnet50-elastic-20210722-122542":{},"tf2-keras-cifar10-resnet50-elastic-20210722-122731":{},"tf2-keras-cifar10-vgg16-elastic-20210722-122104":{},"tf2-keras-cifar10-vgg16-elastic-20210722-122126":{},"tf2-keras-cifar10-vgg16-elastic-20210722-122446":{},"tf2-keras-cifar10-vgg16-elastic-20210722-122513":{},"tf2-keras-transformer-elastic-20210722-122149":{},"tf2-keras-transformer-elastic-20210722-122215":{},"tf2-keras-transformer-elastic-20210722-122421":{},"tf2-keras-transformer-elastic-20210722-122647":{}} "scheduler"="default"
I0722 00:29:44.650644   23824 placement_manager.go:434]  "msg"="podNodeName updated"  "launchersToDelete"=5 "new"={"tf2-keras-cifar10-resnet50-elastic-20210722-122006-worker-0":"gpu5","tf2-keras-cifar10-resnet50-elastic-20210722-122327-worker-0":"gpu4","tf2-keras-cifar10-resnet50-elastic-20210722-122542-worker-0":"gpu3","tf2-keras-cifar10-resnet50-elastic-20210722-122731-worker-0":"gpu3","tf2-keras-cifar10-vgg16-elastic-20210722-122104-worker-0":"gpu4","tf2-keras-cifar10-vgg16-elastic-20210722-122126-worker-0":"gpu5","tf2-keras-cifar10-vgg16-elastic-20210722-122446-worker-0":"gpu3","tf2-keras-cifar10-vgg16-elastic-20210722-122513-worker-0":"gpu3","tf2-keras-cifar10-vgg16-elastic-20210722-122804-worker-0":"gpu5","tf2-keras-cifar10-vgg16-elastic-20210722-122906-worker-0":"gpu4","tf2-keras-transformer-elastic-20210722-122149-worker-0":"gpu5","tf2-keras-transformer-elastic-20210722-122215-worker-0":"gpu4"} "old"={"tf2-keras-cifar10-resnet50-elastic-20210722-122006-worker-0":"gpu4","tf2-keras-cifar10-resnet50-elastic-20210722-122327-worker-0":"gpu4","tf2-keras-cifar10-resnet50-elastic-20210722-122542-worker-0":"gpu4","tf2-keras-cifar10-resnet50-elastic-20210722-122731-worker-0":"gpu3","tf2-keras-cifar10-vgg16-elastic-20210722-122104-worker-0":"gpu4","tf2-keras-cifar10-vgg16-elastic-20210722-122126-worker-0":"gpu5","tf2-keras-cifar10-vgg16-elastic-20210722-122446-worker-0":"gpu5","tf2-keras-cifar10-vgg16-elastic-20210722-122513-worker-0":"gpu3","tf2-keras-transformer-elastic-20210722-122149-worker-0":"gpu3","tf2-keras-transformer-elastic-20210722-122215-worker-0":"gpu5","tf2-keras-transformer-elastic-20210722-122421-worker-0":"gpu3","tf2-keras-transformer-elastic-20210722-122647-worker-0":"gpu5"} "scheduler"="default" "workersToDelete"=5
I0722 00:29:44.650983   23824 placement_manager.go:451]  "msg"="Deleting pod that need migration"  "podName"="tf2-keras-cifar10-resnet50-elastic-20210722-122006-worker-0" "scheduler"="default"
I0722 00:29:44.655955   23824 placement_manager.go:451]  "msg"="Deleting pod that need migration"  "podName"="tf2-keras-cifar10-resnet50-elastic-20210722-122006-launcher" "scheduler"="default"
I0722 00:29:44.661073   23824 placement_manager.go:451]  "msg"="Deleting pod that need migration"  "podName"="tf2-keras-transformer-elastic-20210722-122215-worker-0" "scheduler"="default"
I0722 00:29:44.674241   23824 placement_manager.go:451]  "msg"="Deleting pod that need migration"  "podName"="tf2-keras-transformer-elastic-20210722-122215-launcher" "scheduler"="default"
I0722 00:29:44.678185   23824 placement_manager.go:451]  "msg"="Deleting pod that need migration"  "podName"="tf2-keras-cifar10-vgg16-elastic-20210722-122446-worker-0" "scheduler"="default"
I0722 00:29:44.681202   23824 placement_manager.go:451]  "msg"="Deleting pod that need migration"  "podName"="tf2-keras-cifar10-vgg16-elastic-20210722-122446-launcher" "scheduler"="default"
I0722 00:29:44.686498   23824 placement_manager.go:451]  "msg"="Deleting pod that need migration"  "podName"="tf2-keras-cifar10-resnet50-elastic-20210722-122542-worker-0" "scheduler"="default"
I0722 00:29:44.691616   23824 placement_manager.go:451]  "msg"="Deleting pod that need migration"  "podName"="tf2-keras-cifar10-resnet50-elastic-20210722-122542-launcher" "scheduler"="default"
I0722 00:29:44.695676   23824 placement_manager.go:451]  "msg"="Deleting pod that need migration"  "podName"="tf2-keras-transformer-elastic-20210722-122149-worker-0" "scheduler"="default"
I0722 00:29:44.699527   23824 placement_manager.go:451]  "msg"="Deleting pod that need migration"  "podName"="tf2-keras-transformer-elastic-20210722-122149-launcher" "scheduler"="default"
I0722 00:29:44.704369   23824 placement_manager.go:183]  "msg"="Finished job placements adjustment"  "scheduler"="default"
I0722 00:29:44.704619   23824 scheduler.go:182]  "msg"="Finished resched"  "scheduler"="default"
I0722 00:29:44.844269   23824 placement_manager.go:147]  "msg"="Adding toleration to pod"  "podName"="tf2-keras-cifar10-vgg16-elastic-20210722-122804-worker-0" "scheduler"="default" "toleration"={"key":"celeste/hostname","operator":"Equal","value":"gpu5","effect":"NoExecute"}
I0722 00:29:45.057681   23824 placement_manager.go:147]  "msg"="Adding toleration to pod"  "podName"="tf2-keras-cifar10-vgg16-elastic-20210722-122906-worker-0" "scheduler"="default" "toleration"={"key":"celeste/hostname","operator":"Equal","value":"gpu4","effect":"NoExecute"}
I0722 00:29:45.459370   23824 placement_manager.go:147]  "msg"="Adding toleration to pod"  "podName"="tf2-keras-cifar10-vgg16-elastic-20210722-122804-launcher" "scheduler"="default" "toleration"={"key":"celeste/hostname","operator":"Exists","effect":"NoExecute"}
I0722 00:29:45.809937   23824 jobmaster.go:155]  "msg"="Training job created"  "job"="tf2-keras-cifar10-resnet50-elastic-20210722-122945"
I0722 00:29:45.810038   23824 scheduler.go:135]  "msg"="Received resched event, may be blocked because of rate limit"  "blockedUntil"="2021-07-22T00:31:44.704880159+08:00" "lastResched"="2021-07-22T00:29:44.704880159+08:00" "received"="2021-07-22T00:29:45.809604912+08:00" "scheduler"="default"
I0722 00:29:45.861515   23824 placement_manager.go:147]  "msg"="Adding toleration to pod"  "podName"="tf2-keras-cifar10-vgg16-elastic-20210722-122906-launcher" "scheduler"="default" "toleration"={"key":"celeste/hostname","operator":"Exists","effect":"NoExecute"}
I0722 00:29:54.439076   23824 placement_manager.go:147]  "msg"="Adding toleration to pod"  "podName"="tf2-keras-cifar10-resnet50-elastic-20210722-122006-launcher" "scheduler"="default" "toleration"={"key":"celeste/hostname","operator":"Exists","effect":"NoExecute"}
I0722 00:29:54.581897   23824 placement_manager.go:147]  "msg"="Adding toleration to pod"  "podName"="tf2-keras-cifar10-resnet50-elastic-20210722-122006-worker-0" "scheduler"="default" "toleration"={"key":"celeste/hostname","operator":"Equal","value":"gpu5","effect":"NoExecute"}
I0722 00:29:54.611842   23824 placement_manager.go:147]  "msg"="Adding toleration to pod"  "podName"="tf2-keras-cifar10-resnet50-elastic-20210722-122542-worker-0" "scheduler"="default" "toleration"={"key":"celeste/hostname","operator":"Equal","value":"gpu3","effect":"NoExecute"}
I0722 00:29:55.431088   23824 placement_manager.go:147]  "msg"="Adding toleration to pod"  "podName"="tf2-keras-transformer-elastic-20210722-122215-worker-0" "scheduler"="default" "toleration"={"key":"celeste/hostname","operator":"Equal","value":"gpu4","effect":"NoExecute"}
I0722 00:29:56.233746   23824 placement_manager.go:147]  "msg"="Adding toleration to pod"  "podName"="tf2-keras-cifar10-vgg16-elastic-20210722-122446-launcher" "scheduler"="default" "toleration"={"key":"celeste/hostname","operator":"Exists","effect":"NoExecute"}
I0722 00:29:59.285925   23824 placement_manager.go:147]  "msg"="Adding toleration to pod"  "podName"="tf2-keras-transformer-elastic-20210722-122149-worker-0" "scheduler"="default" "toleration"={"key":"celeste/hostname","operator":"Equal","value":"gpu5","effect":"NoExecute"}
I0722 00:30:00.045113   23824 placement_manager.go:147]  "msg"="Adding toleration to pod"  "podName"="tf2-keras-transformer-elastic-20210722-122149-launcher" "scheduler"="default" "toleration"={"key":"celeste/hostname","operator":"Exists","effect":"NoExecute"}
I0722 00:30:01.046208   23824 placement_manager.go:147]  "msg"="Adding toleration to pod"  "podName"="tf2-keras-cifar10-vgg16-elastic-20210722-122446-worker-0" "scheduler"="default" "toleration"={"key":"celeste/hostname","operator":"Equal","value":"gpu3","effect":"NoExecute"}
I0722 00:30:05.301646   23824 placement_manager.go:147]  "msg"="Adding toleration to pod"  "podName"="tf2-keras-transformer-elastic-20210722-122215-launcher" "scheduler"="default" "toleration"={"key":"celeste/hostname","operator":"Exists","effect":"NoExecute"}
I0722 00:30:06.293562   23824 placement_manager.go:147]  "msg"="Adding toleration to pod"  "podName"="tf2-keras-cifar10-resnet50-elastic-20210722-122542-launcher" "scheduler"="default" "toleration"={"key":"celeste/hostname","operator":"Exists","effect":"NoExecute"}
I0722 00:30:11.832086   23824 jobmaster.go:155]  "msg"="Training job created"  "job"="tf2-keras-cifar10-resnet50-elastic-20210722-123011"
I0722 00:30:39.691705   23824 jobmaster.go:155]  "msg"="Training job created"  "job"="tf2-keras-transformer-elastic-20210722-123039"
I0722 00:31:44.705003   23824 scheduler.go:159]  "msg"="Started resched"  "scheduler"="default"
I0722 00:31:44.705126   23824 scheduler.go:193]  "msg"="Updating all jobs info"  "scheduler"="default"
I0722 00:31:44.718453   23824 afsl.go:65]  "msg"="Finished scheduling"  "algorithm"="AFS-L" "freeGpu"=0 "result"={"tf2-keras-cifar10-inceptionv3-elastic-20210722-121943":0,"tf2-keras-cifar10-inceptionv3-elastic-20210722-122034":0,"tf2-keras-cifar10-inceptionv3-elastic-20210722-122250":0,"tf2-keras-cifar10-inceptionv3-elastic-20210722-122354":0,"tf2-keras-cifar10-inceptionv3-elastic-20210722-122611":0,"tf2-keras-cifar10-inceptionv3-elastic-20210722-122710":0,"tf2-keras-cifar10-resnet50-elastic-20210722-122006":1,"tf2-keras-cifar10-resnet50-elastic-20210722-122327":1,"tf2-keras-cifar10-resnet50-elastic-20210722-122542":1,"tf2-keras-cifar10-resnet50-elastic-20210722-122731":1,"tf2-keras-cifar10-resnet50-elastic-20210722-122945":1,"tf2-keras-cifar10-resnet50-elastic-20210722-123011":1,"tf2-keras-cifar10-vgg16-elastic-20210722-122104":1,"tf2-keras-cifar10-vgg16-elastic-20210722-122126":1,"tf2-keras-cifar10-vgg16-elastic-20210722-122446":1,"tf2-keras-cifar10-vgg16-elastic-20210722-122513":1,"tf2-keras-cifar10-vgg16-elastic-20210722-122804":1,"tf2-keras-cifar10-vgg16-elastic-20210722-122906":1,"tf2-keras-transformer-elastic-20210722-122149":0,"tf2-keras-transformer-elastic-20210722-122215":0,"tf2-keras-transformer-elastic-20210722-122421":0,"tf2-keras-transformer-elastic-20210722-122647":0,"tf2-keras-transformer-elastic-20210722-122826":0,"tf2-keras-transformer-elastic-20210722-123039":0} "scheduler"="default"
I0722 00:31:44.718780   23824 scheduler.go:384]  "msg"="Trying to delete multiple training jobs"  "jobs"=["tf2-keras-transformer-elastic-20210722-122149","tf2-keras-transformer-elastic-20210722-122215"] "scheduler"="default"
I0722 00:31:44.741964   23824 scheduler.go:342]  "msg"="Trying to scale multiple training jobs"  "jobs"=[] "scheduler"="default"
I0722 00:31:44.742303   23824 scheduler.go:292]  "msg"="Trying to start multiple training jobs"  "jobs"=["tf2-keras-cifar10-resnet50-elastic-20210722-122945","tf2-keras-cifar10-resnet50-elastic-20210722-123011"] "scheduler"="default"
I0722 00:31:44.758016   23824 scheduler.go:342]  "msg"="Trying to scale multiple training jobs"  "jobs"=[] "scheduler"="default"
I0722 00:31:44.762043   23824 placement_manager.go:166]  "msg"="Started job placements adjustment"  "scheduler"="default"
I0722 00:31:44.762125   23824 placement_manager.go:192]  "msg"="Releasing slots"  "jobs"={"tf2-keras-cifar10-resnet50-elastic-20210722-122006":{},"tf2-keras-cifar10-resnet50-elastic-20210722-122327":{},"tf2-keras-cifar10-resnet50-elastic-20210722-122542":{},"tf2-keras-cifar10-resnet50-elastic-20210722-122731":{},"tf2-keras-cifar10-vgg16-elastic-20210722-122104":{},"tf2-keras-cifar10-vgg16-elastic-20210722-122126":{},"tf2-keras-cifar10-vgg16-elastic-20210722-122446":{},"tf2-keras-cifar10-vgg16-elastic-20210722-122513":{},"tf2-keras-cifar10-vgg16-elastic-20210722-122804":{},"tf2-keras-cifar10-vgg16-elastic-20210722-122906":{},"tf2-keras-transformer-elastic-20210722-122149":{},"tf2-keras-transformer-elastic-20210722-122215":{}} "nodes"={"gpu3":{},"gpu4":{},"gpu5":{}} "scheduler"="default"
I0722 00:31:44.762211   23824 placement_manager.go:250]  "msg"="Released slots"  "jobs"={"tf2-keras-cifar10-resnet50-elastic-20210722-122006":{},"tf2-keras-cifar10-resnet50-elastic-20210722-122327":{},"tf2-keras-cifar10-resnet50-elastic-20210722-122542":{},"tf2-keras-cifar10-resnet50-elastic-20210722-122731":{},"tf2-keras-cifar10-vgg16-elastic-20210722-122104":{},"tf2-keras-cifar10-vgg16-elastic-20210722-122126":{},"tf2-keras-cifar10-vgg16-elastic-20210722-122446":{},"tf2-keras-cifar10-vgg16-elastic-20210722-122513":{},"tf2-keras-cifar10-vgg16-elastic-20210722-122804":{},"tf2-keras-cifar10-vgg16-elastic-20210722-122906":{},"tf2-keras-transformer-elastic-20210722-122149":{},"tf2-keras-transformer-elastic-20210722-122215":{}} "nodes"={"gpu3":{},"gpu4":{},"gpu5":{}} "scheduler"="default"
I0722 00:31:44.762715   23824 placement_manager.go:305]  "msg"="Found best-fit"  "crossNode"=0 "nodes"=[{},{},{}] "requests"=[{},{},{},{},{},{},{},{},{},{},{},{},{},{},{},{},{},{},{},{},{},{},{},{},{},{},{},{},{},{},{},{},{},{},{},{},{},{},{},{},{},{},{},{},{},{},{},{}] "scheduler"="default"
I0722 00:31:44.763081   23824 placement_manager.go:339]  "msg"="nodeStates updated"  "new"={"gpu3":{},"gpu4":{},"gpu5":{}} "old"={"gpu3":{},"gpu4":{},"gpu5":{}} "scheduler"="default" "score"=5
I0722 00:31:44.763507   23824 placement_manager.go:387]  "msg"="jobStates updated"  "new"={"tf2-keras-cifar10-resnet50-elastic-20210722-122006":{},"tf2-keras-cifar10-resnet50-elastic-20210722-122327":{},"tf2-keras-cifar10-resnet50-elastic-20210722-122542":{},"tf2-keras-cifar10-resnet50-elastic-20210722-122731":{},"tf2-keras-cifar10-resnet50-elastic-20210722-122945":{},"tf2-keras-cifar10-resnet50-elastic-20210722-123011":{},"tf2-keras-cifar10-vgg16-elastic-20210722-122104":{},"tf2-keras-cifar10-vgg16-elastic-20210722-122126":{},"tf2-keras-cifar10-vgg16-elastic-20210722-122446":{},"tf2-keras-cifar10-vgg16-elastic-20210722-122513":{},"tf2-keras-cifar10-vgg16-elastic-20210722-122804":{},"tf2-keras-cifar10-vgg16-elastic-20210722-122906":{}} "old"={"tf2-keras-cifar10-resnet50-elastic-20210722-122006":{},"tf2-keras-cifar10-resnet50-elastic-20210722-122327":{},"tf2-keras-cifar10-resnet50-elastic-20210722-122542":{},"tf2-keras-cifar10-resnet50-elastic-20210722-122731":{},"tf2-keras-cifar10-vgg16-elastic-20210722-122104":{},"tf2-keras-cifar10-vgg16-elastic-20210722-122126":{},"tf2-keras-cifar10-vgg16-elastic-20210722-122446":{},"tf2-keras-cifar10-vgg16-elastic-20210722-122513":{},"tf2-keras-cifar10-vgg16-elastic-20210722-122804":{},"tf2-keras-cifar10-vgg16-elastic-20210722-122906":{},"tf2-keras-transformer-elastic-20210722-122149":{},"tf2-keras-transformer-elastic-20210722-122215":{}} "scheduler"="default"
I0722 00:31:44.763890   23824 placement_manager.go:434]  "msg"="podNodeName updated"  "launchersToDelete"=5 "new"={"tf2-keras-cifar10-resnet50-elastic-20210722-122006-worker-0":"gpu5","tf2-keras-cifar10-resnet50-elastic-20210722-122327-worker-0":"gpu4","tf2-keras-cifar10-resnet50-elastic-20210722-122542-worker-0":"gpu5","tf2-keras-cifar10-resnet50-elastic-20210722-122731-worker-0":"gpu3","tf2-keras-cifar10-resnet50-elastic-20210722-122945-worker-0":"gpu3","tf2-keras-cifar10-resnet50-elastic-20210722-123011-worker-0":"gpu3","tf2-keras-cifar10-vgg16-elastic-20210722-122104-worker-0":"gpu3","tf2-keras-cifar10-vgg16-elastic-20210722-122126-worker-0":"gpu4","tf2-keras-cifar10-vgg16-elastic-20210722-122446-worker-0":"gpu4","tf2-keras-cifar10-vgg16-elastic-20210722-122513-worker-0":"gpu5","tf2-keras-cifar10-vgg16-elastic-20210722-122804-worker-0":"gpu5","tf2-keras-cifar10-vgg16-elastic-20210722-122906-worker-0":"gpu4"} "old"={"tf2-keras-cifar10-resnet50-elastic-20210722-122006-worker-0":"gpu5","tf2-keras-cifar10-resnet50-elastic-20210722-122327-worker-0":"gpu4","tf2-keras-cifar10-resnet50-elastic-20210722-122542-worker-0":"gpu3","tf2-keras-cifar10-resnet50-elastic-20210722-122731-worker-0":"gpu3","tf2-keras-cifar10-vgg16-elastic-20210722-122104-worker-0":"gpu4","tf2-keras-cifar10-vgg16-elastic-20210722-122126-worker-0":"gpu5","tf2-keras-cifar10-vgg16-elastic-20210722-122446-worker-0":"gpu3","tf2-keras-cifar10-vgg16-elastic-20210722-122513-worker-0":"gpu3","tf2-keras-cifar10-vgg16-elastic-20210722-122804-worker-0":"gpu5","tf2-keras-cifar10-vgg16-elastic-20210722-122906-worker-0":"gpu4","tf2-keras-transformer-elastic-20210722-122149-worker-0":"gpu5","tf2-keras-transformer-elastic-20210722-122215-worker-0":"gpu4"} "scheduler"="default" "workersToDelete"=5
I0722 00:31:44.764204   23824 placement_manager.go:451]  "msg"="Deleting pod that need migration"  "podName"="tf2-keras-cifar10-vgg16-elastic-20210722-122104-worker-0" "scheduler"="default"
I0722 00:31:44.768080   23824 placement_manager.go:451]  "msg"="Deleting pod that need migration"  "podName"="tf2-keras-cifar10-vgg16-elastic-20210722-122104-launcher" "scheduler"="default"
I0722 00:31:44.772384   23824 placement_manager.go:451]  "msg"="Deleting pod that need migration"  "podName"="tf2-keras-cifar10-vgg16-elastic-20210722-122446-worker-0" "scheduler"="default"
I0722 00:31:44.783107   23824 placement_manager.go:451]  "msg"="Deleting pod that need migration"  "podName"="tf2-keras-cifar10-vgg16-elastic-20210722-122446-launcher" "scheduler"="default"
I0722 00:31:44.788767   23824 placement_manager.go:451]  "msg"="Deleting pod that need migration"  "podName"="tf2-keras-cifar10-vgg16-elastic-20210722-122513-worker-0" "scheduler"="default"
I0722 00:31:44.796538   23824 placement_manager.go:451]  "msg"="Deleting pod that need migration"  "podName"="tf2-keras-cifar10-vgg16-elastic-20210722-122513-launcher" "scheduler"="default"
I0722 00:31:44.800786   23824 placement_manager.go:451]  "msg"="Deleting pod that need migration"  "podName"="tf2-keras-cifar10-resnet50-elastic-20210722-122542-worker-0" "scheduler"="default"
I0722 00:31:44.805438   23824 placement_manager.go:451]  "msg"="Deleting pod that need migration"  "podName"="tf2-keras-cifar10-resnet50-elastic-20210722-122542-launcher" "scheduler"="default"
I0722 00:31:44.809894   23824 placement_manager.go:451]  "msg"="Deleting pod that need migration"  "podName"="tf2-keras-cifar10-vgg16-elastic-20210722-122126-worker-0" "scheduler"="default"
I0722 00:31:44.816552   23824 placement_manager.go:451]  "msg"="Deleting pod that need migration"  "podName"="tf2-keras-cifar10-vgg16-elastic-20210722-122126-launcher" "scheduler"="default"
I0722 00:31:44.823041   23824 placement_manager.go:183]  "msg"="Finished job placements adjustment"  "scheduler"="default"
I0722 00:31:44.823341   23824 scheduler.go:182]  "msg"="Finished resched"  "scheduler"="default"
I0722 00:31:44.959788   23824 placement_manager.go:147]  "msg"="Adding toleration to pod"  "podName"="tf2-keras-cifar10-resnet50-elastic-20210722-122945-worker-0" "scheduler"="default" "toleration"={"key":"celeste/hostname","operator":"Equal","value":"gpu3","effect":"NoExecute"}
I0722 00:31:45.572614   23824 placement_manager.go:147]  "msg"="Adding toleration to pod"  "podName"="tf2-keras-cifar10-resnet50-elastic-20210722-123011-worker-0" "scheduler"="default" "toleration"={"key":"celeste/hostname","operator":"Equal","value":"gpu3","effect":"NoExecute"}
I0722 00:31:45.972376   23824 placement_manager.go:147]  "msg"="Adding toleration to pod"  "podName"="tf2-keras-cifar10-resnet50-elastic-20210722-122945-launcher" "scheduler"="default" "toleration"={"key":"celeste/hostname","operator":"Exists","effect":"NoExecute"}
I0722 00:31:46.373378   23824 placement_manager.go:147]  "msg"="Adding toleration to pod"  "podName"="tf2-keras-cifar10-resnet50-elastic-20210722-123011-launcher" "scheduler"="default" "toleration"={"key":"celeste/hostname","operator":"Exists","effect":"NoExecute"}
I0722 00:31:54.602295   23824 placement_manager.go:147]  "msg"="Adding toleration to pod"  "podName"="tf2-keras-cifar10-vgg16-elastic-20210722-122104-launcher" "scheduler"="default" "toleration"={"key":"celeste/hostname","operator":"Exists","effect":"NoExecute"}
I0722 00:31:54.650828   23824 placement_manager.go:147]  "msg"="Adding toleration to pod"  "podName"="tf2-keras-cifar10-vgg16-elastic-20210722-122104-worker-0" "scheduler"="default" "toleration"={"key":"celeste/hostname","operator":"Equal","value":"gpu3","effect":"NoExecute"}
I0722 00:31:59.741743   23824 placement_manager.go:147]  "msg"="Adding toleration to pod"  "podName"="tf2-keras-cifar10-vgg16-elastic-20210722-122126-worker-0" "scheduler"="default" "toleration"={"key":"celeste/hostname","operator":"Equal","value":"gpu4","effect":"NoExecute"}
I0722 00:31:59.774477   23824 placement_manager.go:147]  "msg"="Adding toleration to pod"  "podName"="tf2-keras-cifar10-vgg16-elastic-20210722-122446-launcher" "scheduler"="default" "toleration"={"key":"celeste/hostname","operator":"Exists","effect":"NoExecute"}
I0722 00:31:59.786242   23824 placement_manager.go:147]  "msg"="Adding toleration to pod"  "podName"="tf2-keras-cifar10-vgg16-elastic-20210722-122126-launcher" "scheduler"="default" "toleration"={"key":"celeste/hostname","operator":"Exists","effect":"NoExecute"}
I0722 00:32:00.730913   23824 placement_manager.go:147]  "msg"="Adding toleration to pod"  "podName"="tf2-keras-cifar10-vgg16-elastic-20210722-122513-launcher" "scheduler"="default" "toleration"={"key":"celeste/hostname","operator":"Exists","effect":"NoExecute"}
I0722 00:32:01.577284   23824 placement_manager.go:147]  "msg"="Adding toleration to pod"  "podName"="tf2-keras-cifar10-vgg16-elastic-20210722-122446-worker-0" "scheduler"="default" "toleration"={"key":"celeste/hostname","operator":"Equal","value":"gpu4","effect":"NoExecute"}
I0722 00:32:02.580192   23824 placement_manager.go:147]  "msg"="Adding toleration to pod"  "podName"="tf2-keras-cifar10-resnet50-elastic-20210722-122542-launcher" "scheduler"="default" "toleration"={"key":"celeste/hostname","operator":"Exists","effect":"NoExecute"}
I0722 00:32:03.767925   23824 placement_manager.go:147]  "msg"="Adding toleration to pod"  "podName"="tf2-keras-cifar10-vgg16-elastic-20210722-122513-worker-0" "scheduler"="default" "toleration"={"key":"celeste/hostname","operator":"Equal","value":"gpu5","effect":"NoExecute"}
I0722 00:32:04.566677   23824 placement_manager.go:147]  "msg"="Adding toleration to pod"  "podName"="tf2-keras-cifar10-resnet50-elastic-20210722-122542-worker-0" "scheduler"="default" "toleration"={"key":"celeste/hostname","operator":"Equal","value":"gpu5","effect":"NoExecute"}
I0722 00:43:46.715191   23824 scheduler.go:474]  "msg"="Training job completed"  "elaspedTotalSeconds"=1338.778854813 "gpuTotalSeconds"=1686.646947008 "job"="tf2-keras-cifar10-vgg16-elastic-20210722-122126" "ranTotalSeconds"=1326.343202125 "scheduler"="default" "waitedTotalSeconds"=12.435652688
I0722 00:43:46.715328   23824 scheduler.go:135]  "msg"="Received resched event, may be blocked because of rate limit"  "blockedUntil"="2021-07-22T00:33:44.823561995+08:00" "lastResched"="2021-07-22T00:31:44.823561995+08:00" "received"="2021-07-22T00:43:46.715221647+08:00" "scheduler"="default"
I0722 00:43:46.715778   23824 scheduler.go:159]  "msg"="Started resched"  "scheduler"="default"
I0722 00:43:46.715831   23824 scheduler.go:193]  "msg"="Updating all jobs info"  "scheduler"="default"
I0722 00:43:46.730664   23824 afsl.go:65]  "msg"="Finished scheduling"  "algorithm"="AFS-L" "freeGpu"=0 "result"={"tf2-keras-cifar10-inceptionv3-elastic-20210722-121943":0,"tf2-keras-cifar10-inceptionv3-elastic-20210722-122034":0,"tf2-keras-cifar10-inceptionv3-elastic-20210722-122250":0,"tf2-keras-cifar10-inceptionv3-elastic-20210722-122354":0,"tf2-keras-cifar10-inceptionv3-elastic-20210722-122611":0,"tf2-keras-cifar10-inceptionv3-elastic-20210722-122710":0,"tf2-keras-cifar10-resnet50-elastic-20210722-122006":1,"tf2-keras-cifar10-resnet50-elastic-20210722-122327":1,"tf2-keras-cifar10-resnet50-elastic-20210722-122542":1,"tf2-keras-cifar10-resnet50-elastic-20210722-122731":1,"tf2-keras-cifar10-resnet50-elastic-20210722-122945":1,"tf2-keras-cifar10-resnet50-elastic-20210722-123011":1,"tf2-keras-cifar10-vgg16-elastic-20210722-122104":1,"tf2-keras-cifar10-vgg16-elastic-20210722-122446":1,"tf2-keras-cifar10-vgg16-elastic-20210722-122513":1,"tf2-keras-cifar10-vgg16-elastic-20210722-122804":1,"tf2-keras-cifar10-vgg16-elastic-20210722-122906":1,"tf2-keras-transformer-elastic-20210722-122149":0,"tf2-keras-transformer-elastic-20210722-122215":1,"tf2-keras-transformer-elastic-20210722-122421":0,"tf2-keras-transformer-elastic-20210722-122647":0,"tf2-keras-transformer-elastic-20210722-122826":0,"tf2-keras-transformer-elastic-20210722-123039":0} "scheduler"="default"
I0722 00:43:46.731105   23824 scheduler.go:384]  "msg"="Trying to delete multiple training jobs"  "jobs"=[] "scheduler"="default"
I0722 00:43:46.731372   23824 scheduler.go:342]  "msg"="Trying to scale multiple training jobs"  "jobs"=[] "scheduler"="default"
I0722 00:43:46.731638   23824 scheduler.go:292]  "msg"="Trying to start multiple training jobs"  "jobs"=["tf2-keras-transformer-elastic-20210722-122215"] "scheduler"="default"
I0722 00:43:46.740896   23824 scheduler.go:342]  "msg"="Trying to scale multiple training jobs"  "jobs"=[] "scheduler"="default"
I0722 00:43:46.744947   23824 placement_manager.go:166]  "msg"="Started job placements adjustment"  "scheduler"="default"
I0722 00:43:46.745035   23824 placement_manager.go:192]  "msg"="Releasing slots"  "jobs"={"tf2-keras-cifar10-resnet50-elastic-20210722-122006":{},"tf2-keras-cifar10-resnet50-elastic-20210722-122327":{},"tf2-keras-cifar10-resnet50-elastic-20210722-122542":{},"tf2-keras-cifar10-resnet50-elastic-20210722-122731":{},"tf2-keras-cifar10-resnet50-elastic-20210722-122945":{},"tf2-keras-cifar10-resnet50-elastic-20210722-123011":{},"tf2-keras-cifar10-vgg16-elastic-20210722-122104":{},"tf2-keras-cifar10-vgg16-elastic-20210722-122126":{},"tf2-keras-cifar10-vgg16-elastic-20210722-122446":{},"tf2-keras-cifar10-vgg16-elastic-20210722-122513":{},"tf2-keras-cifar10-vgg16-elastic-20210722-122804":{},"tf2-keras-cifar10-vgg16-elastic-20210722-122906":{}} "nodes"={"gpu3":{},"gpu4":{},"gpu5":{}} "scheduler"="default"
I0722 00:43:46.745128   23824 placement_manager.go:250]  "msg"="Released slots"  "jobs"={"tf2-keras-cifar10-resnet50-elastic-20210722-122006":{},"tf2-keras-cifar10-resnet50-elastic-20210722-122327":{},"tf2-keras-cifar10-resnet50-elastic-20210722-122542":{},"tf2-keras-cifar10-resnet50-elastic-20210722-122731":{},"tf2-keras-cifar10-resnet50-elastic-20210722-122945":{},"tf2-keras-cifar10-resnet50-elastic-20210722-123011":{},"tf2-keras-cifar10-vgg16-elastic-20210722-122104":{},"tf2-keras-cifar10-vgg16-elastic-20210722-122126":{},"tf2-keras-cifar10-vgg16-elastic-20210722-122446":{},"tf2-keras-cifar10-vgg16-elastic-20210722-122513":{},"tf2-keras-cifar10-vgg16-elastic-20210722-122804":{},"tf2-keras-cifar10-vgg16-elastic-20210722-122906":{}} "nodes"={"gpu3":{},"gpu4":{},"gpu5":{}} "scheduler"="default"
I0722 00:43:46.745695   23824 placement_manager.go:305]  "msg"="Found best-fit"  "crossNode"=0 "nodes"=[{},{},{}] "requests"=[{},{},{},{},{},{},{},{},{},{},{},{},{},{},{},{},{},{},{},{},{},{},{},{},{},{},{},{},{},{},{},{},{},{},{},{},{},{},{},{},{},{},{},{},{},{}] "scheduler"="default"
I0722 00:43:46.746013   23824 placement_manager.go:339]  "msg"="nodeStates updated"  "new"={"gpu3":{},"gpu4":{},"gpu5":{}} "old"={"gpu3":{},"gpu4":{},"gpu5":{}} "scheduler"="default" "score"=7
I0722 00:43:46.746365   23824 placement_manager.go:387]  "msg"="jobStates updated"  "new"={"tf2-keras-cifar10-resnet50-elastic-20210722-122006":{},"tf2-keras-cifar10-resnet50-elastic-20210722-122327":{},"tf2-keras-cifar10-resnet50-elastic-20210722-122542":{},"tf2-keras-cifar10-resnet50-elastic-20210722-122731":{},"tf2-keras-cifar10-resnet50-elastic-20210722-122945":{},"tf2-keras-cifar10-resnet50-elastic-20210722-123011":{},"tf2-keras-cifar10-vgg16-elastic-20210722-122104":{},"tf2-keras-cifar10-vgg16-elastic-20210722-122446":{},"tf2-keras-cifar10-vgg16-elastic-20210722-122513":{},"tf2-keras-cifar10-vgg16-elastic-20210722-122804":{},"tf2-keras-cifar10-vgg16-elastic-20210722-122906":{},"tf2-keras-transformer-elastic-20210722-122215":{}} "old"={"tf2-keras-cifar10-resnet50-elastic-20210722-122006":{},"tf2-keras-cifar10-resnet50-elastic-20210722-122327":{},"tf2-keras-cifar10-resnet50-elastic-20210722-122542":{},"tf2-keras-cifar10-resnet50-elastic-20210722-122731":{},"tf2-keras-cifar10-resnet50-elastic-20210722-122945":{},"tf2-keras-cifar10-resnet50-elastic-20210722-123011":{},"tf2-keras-cifar10-vgg16-elastic-20210722-122104":{},"tf2-keras-cifar10-vgg16-elastic-20210722-122126":{},"tf2-keras-cifar10-vgg16-elastic-20210722-122446":{},"tf2-keras-cifar10-vgg16-elastic-20210722-122513":{},"tf2-keras-cifar10-vgg16-elastic-20210722-122804":{},"tf2-keras-cifar10-vgg16-elastic-20210722-122906":{}} "scheduler"="default"
I0722 00:43:46.746732   23824 placement_manager.go:434]  "msg"="podNodeName updated"  "launchersToDelete"=4 "new"={"tf2-keras-cifar10-resnet50-elastic-20210722-122006-worker-0":"gpu5","tf2-keras-cifar10-resnet50-elastic-20210722-122327-worker-0":"gpu4","tf2-keras-cifar10-resnet50-elastic-20210722-122542-worker-0":"gpu5","tf2-keras-cifar10-resnet50-elastic-20210722-122731-worker-0":"gpu4","tf2-keras-cifar10-resnet50-elastic-20210722-122945-worker-0":"gpu4","tf2-keras-cifar10-resnet50-elastic-20210722-123011-worker-0":"gpu3","tf2-keras-cifar10-vgg16-elastic-20210722-122104-worker-0":"gpu3","tf2-keras-cifar10-vgg16-elastic-20210722-122446-worker-0":"gpu5","tf2-keras-cifar10-vgg16-elastic-20210722-122513-worker-0":"gpu3","tf2-keras-cifar10-vgg16-elastic-20210722-122804-worker-0":"gpu5","tf2-keras-cifar10-vgg16-elastic-20210722-122906-worker-0":"gpu4","tf2-keras-transformer-elastic-20210722-122215-worker-0":"gpu3"} "old"={"tf2-keras-cifar10-resnet50-elastic-20210722-122006-worker-0":"gpu5","tf2-keras-cifar10-resnet50-elastic-20210722-122327-worker-0":"gpu4","tf2-keras-cifar10-resnet50-elastic-20210722-122542-worker-0":"gpu5","tf2-keras-cifar10-resnet50-elastic-20210722-122731-worker-0":"gpu3","tf2-keras-cifar10-resnet50-elastic-20210722-122945-worker-0":"gpu3","tf2-keras-cifar10-resnet50-elastic-20210722-123011-worker-0":"gpu3","tf2-keras-cifar10-vgg16-elastic-20210722-122104-worker-0":"gpu3","tf2-keras-cifar10-vgg16-elastic-20210722-122126-worker-0":"gpu4","tf2-keras-cifar10-vgg16-elastic-20210722-122446-worker-0":"gpu4","tf2-keras-cifar10-vgg16-elastic-20210722-122513-worker-0":"gpu5","tf2-keras-cifar10-vgg16-elastic-20210722-122804-worker-0":"gpu5","tf2-keras-cifar10-vgg16-elastic-20210722-122906-worker-0":"gpu4"} "scheduler"="default" "workersToDelete"=4
I0722 00:43:46.747020   23824 placement_manager.go:451]  "msg"="Deleting pod that need migration"  "podName"="tf2-keras-cifar10-vgg16-elastic-20210722-122446-worker-0" "scheduler"="default"
I0722 00:43:46.751071   23824 placement_manager.go:451]  "msg"="Deleting pod that need migration"  "podName"="tf2-keras-cifar10-vgg16-elastic-20210722-122446-launcher" "scheduler"="default"
I0722 00:43:46.755198   23824 placement_manager.go:451]  "msg"="Deleting pod that need migration"  "podName"="tf2-keras-cifar10-resnet50-elastic-20210722-122945-worker-0" "scheduler"="default"
I0722 00:43:46.767473   23824 placement_manager.go:451]  "msg"="Deleting pod that need migration"  "podName"="tf2-keras-cifar10-resnet50-elastic-20210722-122945-launcher" "scheduler"="default"
I0722 00:43:46.772110   23824 placement_manager.go:451]  "msg"="Deleting pod that need migration"  "podName"="tf2-keras-cifar10-resnet50-elastic-20210722-122731-worker-0" "scheduler"="default"
I0722 00:43:46.781798   23824 placement_manager.go:451]  "msg"="Deleting pod that need migration"  "podName"="tf2-keras-cifar10-resnet50-elastic-20210722-122731-launcher" "scheduler"="default"
I0722 00:43:46.789368   23824 placement_manager.go:451]  "msg"="Deleting pod that need migration"  "podName"="tf2-keras-cifar10-vgg16-elastic-20210722-122513-worker-0" "scheduler"="default"
I0722 00:43:46.794786   23824 placement_manager.go:451]  "msg"="Deleting pod that need migration"  "podName"="tf2-keras-cifar10-vgg16-elastic-20210722-122513-launcher" "scheduler"="default"
I0722 00:43:46.799614   23824 placement_manager.go:183]  "msg"="Finished job placements adjustment"  "scheduler"="default"
I0722 00:43:46.799866   23824 scheduler.go:182]  "msg"="Finished resched"  "scheduler"="default"
I0722 00:43:47.104656   23824 placement_manager.go:147]  "msg"="Adding toleration to pod"  "podName"="tf2-keras-transformer-elastic-20210722-122215-worker-0" "scheduler"="default" "toleration"={"key":"celeste/hostname","operator":"Equal","value":"gpu3","effect":"NoExecute"}
I0722 00:43:47.503108   23824 placement_manager.go:147]  "msg"="Adding toleration to pod"  "podName"="tf2-keras-transformer-elastic-20210722-122215-launcher" "scheduler"="default" "toleration"={"key":"celeste/hostname","operator":"Exists","effect":"NoExecute"}
I0722 00:43:55.297570   23824 placement_manager.go:147]  "msg"="Adding toleration to pod"  "podName"="tf2-keras-cifar10-vgg16-elastic-20210722-122513-launcher" "scheduler"="default" "toleration"={"key":"celeste/hostname","operator":"Exists","effect":"NoExecute"}
I0722 00:43:56.292594   23824 placement_manager.go:147]  "msg"="Adding toleration to pod"  "podName"="tf2-keras-cifar10-vgg16-elastic-20210722-122513-worker-0" "scheduler"="default" "toleration"={"key":"celeste/hostname","operator":"Equal","value":"gpu3","effect":"NoExecute"}
I0722 00:43:56.320914   23824 placement_manager.go:147]  "msg"="Adding toleration to pod"  "podName"="tf2-keras-cifar10-resnet50-elastic-20210722-122731-launcher" "scheduler"="default" "toleration"={"key":"celeste/hostname","operator":"Exists","effect":"NoExecute"}
I0722 00:43:56.332477   23824 placement_manager.go:147]  "msg"="Adding toleration to pod"  "podName"="tf2-keras-cifar10-vgg16-elastic-20210722-122446-launcher" "scheduler"="default" "toleration"={"key":"celeste/hostname","operator":"Exists","effect":"NoExecute"}
I0722 00:43:59.283295   23824 placement_manager.go:147]  "msg"="Adding toleration to pod"  "podName"="tf2-keras-cifar10-resnet50-elastic-20210722-122945-launcher" "scheduler"="default" "toleration"={"key":"celeste/hostname","operator":"Exists","effect":"NoExecute"}
I0722 00:43:59.350823   23824 placement_manager.go:147]  "msg"="Adding toleration to pod"  "podName"="tf2-keras-cifar10-resnet50-elastic-20210722-122731-worker-0" "scheduler"="default" "toleration"={"key":"celeste/hostname","operator":"Equal","value":"gpu4","effect":"NoExecute"}
I0722 00:43:59.955625   23824 placement_manager.go:147]  "msg"="Adding toleration to pod"  "podName"="tf2-keras-cifar10-resnet50-elastic-20210722-122945-worker-0" "scheduler"="default" "toleration"={"key":"celeste/hostname","operator":"Equal","value":"gpu4","effect":"NoExecute"}
I0722 00:44:05.368515   23824 placement_manager.go:147]  "msg"="Adding toleration to pod"  "podName"="tf2-keras-cifar10-vgg16-elastic-20210722-122446-worker-0" "scheduler"="default" "toleration"={"key":"celeste/hostname","operator":"Equal","value":"gpu5","effect":"NoExecute"}
I0722 00:48:05.543973   23824 scheduler.go:474]  "msg"="Training job completed"  "elaspedTotalSeconds"=1620.733902222 "gpuTotalSeconds"=1946.656360891 "job"="tf2-keras-cifar10-vgg16-elastic-20210722-122104" "ranTotalSeconds"=1586.352633323 "scheduler"="default" "waitedTotalSeconds"=34.381268899
I0722 00:48:05.544097   23824 scheduler.go:135]  "msg"="Received resched event, may be blocked because of rate limit"  "blockedUntil"="2021-07-22T00:45:46.800076064+08:00" "lastResched"="2021-07-22T00:43:46.800076064+08:00" "received"="2021-07-22T00:48:05.543999683+08:00" "scheduler"="default"
I0722 00:48:05.544561   23824 scheduler.go:159]  "msg"="Started resched"  "scheduler"="default"
I0722 00:48:05.544600   23824 scheduler.go:193]  "msg"="Updating all jobs info"  "scheduler"="default"
I0722 00:48:05.556562   23824 afsl.go:65]  "msg"="Finished scheduling"  "algorithm"="AFS-L" "freeGpu"=0 "result"={"tf2-keras-cifar10-inceptionv3-elastic-20210722-121943":0,"tf2-keras-cifar10-inceptionv3-elastic-20210722-122034":0,"tf2-keras-cifar10-inceptionv3-elastic-20210722-122250":0,"tf2-keras-cifar10-inceptionv3-elastic-20210722-122354":0,"tf2-keras-cifar10-inceptionv3-elastic-20210722-122611":0,"tf2-keras-cifar10-inceptionv3-elastic-20210722-122710":0,"tf2-keras-cifar10-resnet50-elastic-20210722-122006":1,"tf2-keras-cifar10-resnet50-elastic-20210722-122327":1,"tf2-keras-cifar10-resnet50-elastic-20210722-122542":1,"tf2-keras-cifar10-resnet50-elastic-20210722-122731":1,"tf2-keras-cifar10-resnet50-elastic-20210722-122945":1,"tf2-keras-cifar10-resnet50-elastic-20210722-123011":1,"tf2-keras-cifar10-vgg16-elastic-20210722-122446":1,"tf2-keras-cifar10-vgg16-elastic-20210722-122513":1,"tf2-keras-cifar10-vgg16-elastic-20210722-122804":1,"tf2-keras-cifar10-vgg16-elastic-20210722-122906":1,"tf2-keras-transformer-elastic-20210722-122149":1,"tf2-keras-transformer-elastic-20210722-122215":1,"tf2-keras-transformer-elastic-20210722-122421":0,"tf2-keras-transformer-elastic-20210722-122647":0,"tf2-keras-transformer-elastic-20210722-122826":0,"tf2-keras-transformer-elastic-20210722-123039":0} "scheduler"="default"
I0722 00:48:05.556855   23824 scheduler.go:384]  "msg"="Trying to delete multiple training jobs"  "jobs"=[] "scheduler"="default"
I0722 00:48:05.557083   23824 scheduler.go:342]  "msg"="Trying to scale multiple training jobs"  "jobs"=[] "scheduler"="default"
I0722 00:48:05.557278   23824 scheduler.go:292]  "msg"="Trying to start multiple training jobs"  "jobs"=["tf2-keras-transformer-elastic-20210722-122149"] "scheduler"="default"
I0722 00:48:05.567854   23824 scheduler.go:342]  "msg"="Trying to scale multiple training jobs"  "jobs"=[] "scheduler"="default"
I0722 00:48:05.572238   23824 placement_manager.go:166]  "msg"="Started job placements adjustment"  "scheduler"="default"
I0722 00:48:05.572337   23824 placement_manager.go:192]  "msg"="Releasing slots"  "jobs"={"tf2-keras-cifar10-resnet50-elastic-20210722-122006":{},"tf2-keras-cifar10-resnet50-elastic-20210722-122327":{},"tf2-keras-cifar10-resnet50-elastic-20210722-122542":{},"tf2-keras-cifar10-resnet50-elastic-20210722-122731":{},"tf2-keras-cifar10-resnet50-elastic-20210722-122945":{},"tf2-keras-cifar10-resnet50-elastic-20210722-123011":{},"tf2-keras-cifar10-vgg16-elastic-20210722-122104":{},"tf2-keras-cifar10-vgg16-elastic-20210722-122446":{},"tf2-keras-cifar10-vgg16-elastic-20210722-122513":{},"tf2-keras-cifar10-vgg16-elastic-20210722-122804":{},"tf2-keras-cifar10-vgg16-elastic-20210722-122906":{},"tf2-keras-transformer-elastic-20210722-122215":{}} "nodes"={"gpu3":{},"gpu4":{},"gpu5":{}} "scheduler"="default"
I0722 00:48:05.572441   23824 placement_manager.go:250]  "msg"="Released slots"  "jobs"={"tf2-keras-cifar10-resnet50-elastic-20210722-122006":{},"tf2-keras-cifar10-resnet50-elastic-20210722-122327":{},"tf2-keras-cifar10-resnet50-elastic-20210722-122542":{},"tf2-keras-cifar10-resnet50-elastic-20210722-122731":{},"tf2-keras-cifar10-resnet50-elastic-20210722-122945":{},"tf2-keras-cifar10-resnet50-elastic-20210722-123011":{},"tf2-keras-cifar10-vgg16-elastic-20210722-122104":{},"tf2-keras-cifar10-vgg16-elastic-20210722-122446":{},"tf2-keras-cifar10-vgg16-elastic-20210722-122513":{},"tf2-keras-cifar10-vgg16-elastic-20210722-122804":{},"tf2-keras-cifar10-vgg16-elastic-20210722-122906":{},"tf2-keras-transformer-elastic-20210722-122215":{}} "nodes"={"gpu3":{},"gpu4":{},"gpu5":{}} "scheduler"="default"
I0722 00:48:05.572878   23824 placement_manager.go:305]  "msg"="Found best-fit"  "crossNode"=0 "nodes"=[{},{},{}] "requests"=[{},{},{},{},{},{},{},{},{},{},{},{},{},{},{},{},{},{},{},{},{},{},{},{},{},{},{},{},{},{},{},{},{},{},{},{},{},{},{},{},{},{},{},{}] "scheduler"="default"
I0722 00:48:05.573170   23824 placement_manager.go:339]  "msg"="nodeStates updated"  "new"={"gpu3":{},"gpu4":{},"gpu5":{}} "old"={"gpu3":{},"gpu4":{},"gpu5":{}} "scheduler"="default" "score"=6
I0722 00:48:05.573452   23824 placement_manager.go:387]  "msg"="jobStates updated"  "new"={"tf2-keras-cifar10-resnet50-elastic-20210722-122006":{},"tf2-keras-cifar10-resnet50-elastic-20210722-122327":{},"tf2-keras-cifar10-resnet50-elastic-20210722-122542":{},"tf2-keras-cifar10-resnet50-elastic-20210722-122731":{},"tf2-keras-cifar10-resnet50-elastic-20210722-122945":{},"tf2-keras-cifar10-resnet50-elastic-20210722-123011":{},"tf2-keras-cifar10-vgg16-elastic-20210722-122446":{},"tf2-keras-cifar10-vgg16-elastic-20210722-122513":{},"tf2-keras-cifar10-vgg16-elastic-20210722-122804":{},"tf2-keras-cifar10-vgg16-elastic-20210722-122906":{},"tf2-keras-transformer-elastic-20210722-122149":{},"tf2-keras-transformer-elastic-20210722-122215":{}} "old"={"tf2-keras-cifar10-resnet50-elastic-20210722-122006":{},"tf2-keras-cifar10-resnet50-elastic-20210722-122327":{},"tf2-keras-cifar10-resnet50-elastic-20210722-122542":{},"tf2-keras-cifar10-resnet50-elastic-20210722-122731":{},"tf2-keras-cifar10-resnet50-elastic-20210722-122945":{},"tf2-keras-cifar10-resnet50-elastic-20210722-123011":{},"tf2-keras-cifar10-vgg16-elastic-20210722-122104":{},"tf2-keras-cifar10-vgg16-elastic-20210722-122446":{},"tf2-keras-cifar10-vgg16-elastic-20210722-122513":{},"tf2-keras-cifar10-vgg16-elastic-20210722-122804":{},"tf2-keras-cifar10-vgg16-elastic-20210722-122906":{},"tf2-keras-transformer-elastic-20210722-122215":{}} "scheduler"="default"
I0722 00:48:05.573852   23824 placement_manager.go:434]  "msg"="podNodeName updated"  "launchersToDelete"=5 "new"={"tf2-keras-cifar10-resnet50-elastic-20210722-122006-worker-0":"gpu4","tf2-keras-cifar10-resnet50-elastic-20210722-122327-worker-0":"gpu3","tf2-keras-cifar10-resnet50-elastic-20210722-122542-worker-0":"gpu4","tf2-keras-cifar10-resnet50-elastic-20210722-122731-worker-0":"gpu4","tf2-keras-cifar10-resnet50-elastic-20210722-122945-worker-0":"gpu4","tf2-keras-cifar10-resnet50-elastic-20210722-123011-worker-0":"gpu5","tf2-keras-cifar10-vgg16-elastic-20210722-122446-worker-0":"gpu5","tf2-keras-cifar10-vgg16-elastic-20210722-122513-worker-0":"gpu3","tf2-keras-cifar10-vgg16-elastic-20210722-122804-worker-0":"gpu5","tf2-keras-cifar10-vgg16-elastic-20210722-122906-worker-0":"gpu3","tf2-keras-transformer-elastic-20210722-122149-worker-0":"gpu5","tf2-keras-transformer-elastic-20210722-122215-worker-0":"gpu3"} "old"={"tf2-keras-cifar10-resnet50-elastic-20210722-122006-worker-0":"gpu5","tf2-keras-cifar10-resnet50-elastic-20210722-122327-worker-0":"gpu4","tf2-keras-cifar10-resnet50-elastic-20210722-122542-worker-0":"gpu5","tf2-keras-cifar10-resnet50-elastic-20210722-122731-worker-0":"gpu4","tf2-keras-cifar10-resnet50-elastic-20210722-122945-worker-0":"gpu4","tf2-keras-cifar10-resnet50-elastic-20210722-123011-worker-0":"gpu3","tf2-keras-cifar10-vgg16-elastic-20210722-122104-worker-0":"gpu3","tf2-keras-cifar10-vgg16-elastic-20210722-122446-worker-0":"gpu5","tf2-keras-cifar10-vgg16-elastic-20210722-122513-worker-0":"gpu3","tf2-keras-cifar10-vgg16-elastic-20210722-122804-worker-0":"gpu5","tf2-keras-cifar10-vgg16-elastic-20210722-122906-worker-0":"gpu4","tf2-keras-transformer-elastic-20210722-122215-worker-0":"gpu3"} "scheduler"="default" "workersToDelete"=5
I0722 00:48:05.574305   23824 placement_manager.go:451]  "msg"="Deleting pod that need migration"  "podName"="tf2-keras-cifar10-resnet50-elastic-20210722-123011-worker-0" "scheduler"="default"
I0722 00:48:05.581833   23824 placement_manager.go:451]  "msg"="Deleting pod that need migration"  "podName"="tf2-keras-cifar10-resnet50-elastic-20210722-123011-launcher" "scheduler"="default"
I0722 00:48:05.586987   23824 placement_manager.go:451]  "msg"="Deleting pod that need migration"  "podName"="tf2-keras-cifar10-vgg16-elastic-20210722-122906-worker-0" "scheduler"="default"
I0722 00:48:05.590993   23824 placement_manager.go:451]  "msg"="Deleting pod that need migration"  "podName"="tf2-keras-cifar10-vgg16-elastic-20210722-122906-launcher" "scheduler"="default"
I0722 00:48:05.596335   23824 placement_manager.go:451]  "msg"="Deleting pod that need migration"  "podName"="tf2-keras-cifar10-resnet50-elastic-20210722-122542-worker-0" "scheduler"="default"
I0722 00:48:05.600853   23824 placement_manager.go:451]  "msg"="Deleting pod that need migration"  "podName"="tf2-keras-cifar10-resnet50-elastic-20210722-122542-launcher" "scheduler"="default"
I0722 00:48:05.604326   23824 placement_manager.go:451]  "msg"="Deleting pod that need migration"  "podName"="tf2-keras-cifar10-resnet50-elastic-20210722-122327-worker-0" "scheduler"="default"
I0722 00:48:05.608393   23824 placement_manager.go:451]  "msg"="Deleting pod that need migration"  "podName"="tf2-keras-cifar10-resnet50-elastic-20210722-122327-launcher" "scheduler"="default"
I0722 00:48:05.612084   23824 placement_manager.go:451]  "msg"="Deleting pod that need migration"  "podName"="tf2-keras-cifar10-resnet50-elastic-20210722-122006-worker-0" "scheduler"="default"
I0722 00:48:05.615074   23824 placement_manager.go:451]  "msg"="Deleting pod that need migration"  "podName"="tf2-keras-cifar10-resnet50-elastic-20210722-122006-launcher" "scheduler"="default"
I0722 00:48:05.618995   23824 placement_manager.go:183]  "msg"="Finished job placements adjustment"  "scheduler"="default"
I0722 00:48:05.619257   23824 scheduler.go:182]  "msg"="Finished resched"  "scheduler"="default"
I0722 00:48:05.935198   23824 placement_manager.go:147]  "msg"="Adding toleration to pod"  "podName"="tf2-keras-transformer-elastic-20210722-122149-worker-0" "scheduler"="default" "toleration"={"key":"celeste/hostname","operator":"Equal","value":"gpu5","effect":"NoExecute"}
I0722 00:48:06.381490   23824 placement_manager.go:147]  "msg"="Adding toleration to pod"  "podName"="tf2-keras-transformer-elastic-20210722-122149-launcher" "scheduler"="default" "toleration"={"key":"celeste/hostname","operator":"Exists","effect":"NoExecute"}
I0722 00:48:12.765107   23824 placement_manager.go:147]  "msg"="Adding toleration to pod"  "podName"="tf2-keras-cifar10-resnet50-elastic-20210722-122327-worker-0" "scheduler"="default" "toleration"={"key":"celeste/hostname","operator":"Equal","value":"gpu3","effect":"NoExecute"}
I0722 00:48:12.779132   23824 placement_manager.go:147]  "msg"="Adding toleration to pod"  "podName"="tf2-keras-cifar10-vgg16-elastic-20210722-122906-worker-0" "scheduler"="default" "toleration"={"key":"celeste/hostname","operator":"Equal","value":"gpu3","effect":"NoExecute"}
I0722 00:48:12.796049   23824 placement_manager.go:147]  "msg"="Adding toleration to pod"  "podName"="tf2-keras-cifar10-resnet50-elastic-20210722-122327-launcher" "scheduler"="default" "toleration"={"key":"celeste/hostname","operator":"Exists","effect":"NoExecute"}
I0722 00:48:13.946651   23824 placement_manager.go:147]  "msg"="Adding toleration to pod"  "podName"="tf2-keras-cifar10-resnet50-elastic-20210722-122006-worker-0" "scheduler"="default" "toleration"={"key":"celeste/hostname","operator":"Equal","value":"gpu4","effect":"NoExecute"}
I0722 00:48:13.981390   23824 placement_manager.go:147]  "msg"="Adding toleration to pod"  "podName"="tf2-keras-cifar10-resnet50-elastic-20210722-122542-launcher" "scheduler"="default" "toleration"={"key":"celeste/hostname","operator":"Exists","effect":"NoExecute"}
I0722 00:48:13.994749   23824 placement_manager.go:147]  "msg"="Adding toleration to pod"  "podName"="tf2-keras-cifar10-resnet50-elastic-20210722-122542-worker-0" "scheduler"="default" "toleration"={"key":"celeste/hostname","operator":"Equal","value":"gpu4","effect":"NoExecute"}
I0722 00:48:15.814412   23824 placement_manager.go:147]  "msg"="Adding toleration to pod"  "podName"="tf2-keras-cifar10-vgg16-elastic-20210722-122906-launcher" "scheduler"="default" "toleration"={"key":"celeste/hostname","operator":"Exists","effect":"NoExecute"}
I0722 00:48:16.829220   23824 placement_manager.go:147]  "msg"="Adding toleration to pod"  "podName"="tf2-keras-cifar10-resnet50-elastic-20210722-123011-worker-0" "scheduler"="default" "toleration"={"key":"celeste/hostname","operator":"Equal","value":"gpu5","effect":"NoExecute"}
I0722 00:48:21.351034   23824 placement_manager.go:147]  "msg"="Adding toleration to pod"  "podName"="tf2-keras-cifar10-resnet50-elastic-20210722-122006-launcher" "scheduler"="default" "toleration"={"key":"celeste/hostname","operator":"Exists","effect":"NoExecute"}
I0722 00:48:22.147624   23824 placement_manager.go:147]  "msg"="Adding toleration to pod"  "podName"="tf2-keras-cifar10-resnet50-elastic-20210722-123011-launcher" "scheduler"="default" "toleration"={"key":"celeste/hostname","operator":"Exists","effect":"NoExecute"}
I0722 00:49:29.051753   23824 scheduler.go:474]  "msg"="Training job completed"  "elaspedTotalSeconds"=1557.021488304 "gpuTotalSeconds"=1666.650876256 "job"="tf2-keras-cifar10-resnet50-elastic-20210722-122327" "ranTotalSeconds"=1546.352561123 "scheduler"="default" "waitedTotalSeconds"=10.668927181
I0722 00:49:29.051902   23824 scheduler.go:135]  "msg"="Received resched event, may be blocked because of rate limit"  "blockedUntil"="2021-07-22T00:50:05.619477299+08:00" "lastResched"="2021-07-22T00:48:05.619477299+08:00" "received"="2021-07-22T00:49:29.051791706+08:00" "scheduler"="default"
I0722 00:50:05.619543   23824 scheduler.go:159]  "msg"="Started resched"  "scheduler"="default"
I0722 00:50:05.619622   23824 scheduler.go:193]  "msg"="Updating all jobs info"  "scheduler"="default"
I0722 00:50:05.632444   23824 afsl.go:65]  "msg"="Finished scheduling"  "algorithm"="AFS-L" "freeGpu"=0 "result"={"tf2-keras-cifar10-inceptionv3-elastic-20210722-121943":0,"tf2-keras-cifar10-inceptionv3-elastic-20210722-122034":0,"tf2-keras-cifar10-inceptionv3-elastic-20210722-122250":0,"tf2-keras-cifar10-inceptionv3-elastic-20210722-122354":0,"tf2-keras-cifar10-inceptionv3-elastic-20210722-122611":0,"tf2-keras-cifar10-inceptionv3-elastic-20210722-122710":0,"tf2-keras-cifar10-resnet50-elastic-20210722-122006":1,"tf2-keras-cifar10-resnet50-elastic-20210722-122542":1,"tf2-keras-cifar10-resnet50-elastic-20210722-122731":1,"tf2-keras-cifar10-resnet50-elastic-20210722-122945":1,"tf2-keras-cifar10-resnet50-elastic-20210722-123011":1,"tf2-keras-cifar10-vgg16-elastic-20210722-122446":1,"tf2-keras-cifar10-vgg16-elastic-20210722-122513":1,"tf2-keras-cifar10-vgg16-elastic-20210722-122804":1,"tf2-keras-cifar10-vgg16-elastic-20210722-122906":1,"tf2-keras-transformer-elastic-20210722-122149":1,"tf2-keras-transformer-elastic-20210722-122215":1,"tf2-keras-transformer-elastic-20210722-122421":1,"tf2-keras-transformer-elastic-20210722-122647":0,"tf2-keras-transformer-elastic-20210722-122826":0,"tf2-keras-transformer-elastic-20210722-123039":0} "scheduler"="default"
I0722 00:50:05.632926   23824 scheduler.go:384]  "msg"="Trying to delete multiple training jobs"  "jobs"=[] "scheduler"="default"
I0722 00:50:05.633289   23824 scheduler.go:342]  "msg"="Trying to scale multiple training jobs"  "jobs"=[] "scheduler"="default"
I0722 00:50:05.633691   23824 scheduler.go:292]  "msg"="Trying to start multiple training jobs"  "jobs"=["tf2-keras-transformer-elastic-20210722-122421"] "scheduler"="default"
I0722 00:50:05.648432   23824 scheduler.go:342]  "msg"="Trying to scale multiple training jobs"  "jobs"=[] "scheduler"="default"
I0722 00:50:05.652285   23824 placement_manager.go:166]  "msg"="Started job placements adjustment"  "scheduler"="default"
I0722 00:50:05.652433   23824 placement_manager.go:192]  "msg"="Releasing slots"  "jobs"={"tf2-keras-cifar10-resnet50-elastic-20210722-122006":{},"tf2-keras-cifar10-resnet50-elastic-20210722-122327":{},"tf2-keras-cifar10-resnet50-elastic-20210722-122542":{},"tf2-keras-cifar10-resnet50-elastic-20210722-122731":{},"tf2-keras-cifar10-resnet50-elastic-20210722-122945":{},"tf2-keras-cifar10-resnet50-elastic-20210722-123011":{},"tf2-keras-cifar10-vgg16-elastic-20210722-122446":{},"tf2-keras-cifar10-vgg16-elastic-20210722-122513":{},"tf2-keras-cifar10-vgg16-elastic-20210722-122804":{},"tf2-keras-cifar10-vgg16-elastic-20210722-122906":{},"tf2-keras-transformer-elastic-20210722-122149":{},"tf2-keras-transformer-elastic-20210722-122215":{}} "nodes"={"gpu3":{},"gpu4":{},"gpu5":{}} "scheduler"="default"
I0722 00:50:05.652539   23824 placement_manager.go:250]  "msg"="Released slots"  "jobs"={"tf2-keras-cifar10-resnet50-elastic-20210722-122006":{},"tf2-keras-cifar10-resnet50-elastic-20210722-122327":{},"tf2-keras-cifar10-resnet50-elastic-20210722-122542":{},"tf2-keras-cifar10-resnet50-elastic-20210722-122731":{},"tf2-keras-cifar10-resnet50-elastic-20210722-122945":{},"tf2-keras-cifar10-resnet50-elastic-20210722-123011":{},"tf2-keras-cifar10-vgg16-elastic-20210722-122446":{},"tf2-keras-cifar10-vgg16-elastic-20210722-122513":{},"tf2-keras-cifar10-vgg16-elastic-20210722-122804":{},"tf2-keras-cifar10-vgg16-elastic-20210722-122906":{},"tf2-keras-transformer-elastic-20210722-122149":{},"tf2-keras-transformer-elastic-20210722-122215":{}} "nodes"={"gpu3":{},"gpu4":{},"gpu5":{}} "scheduler"="default"
I0722 00:50:05.652987   23824 placement_manager.go:305]  "msg"="Found best-fit"  "crossNode"=0 "nodes"=[{},{},{}] "requests"=[{},{},{},{},{},{},{},{},{},{},{},{},{},{},{},{},{},{},{},{},{},{},{},{},{},{},{},{},{},{},{},{},{},{},{},{},{},{},{},{},{},{}] "scheduler"="default"
I0722 00:50:05.653276   23824 placement_manager.go:339]  "msg"="nodeStates updated"  "new"={"gpu3":{},"gpu4":{},"gpu5":{}} "old"={"gpu3":{},"gpu4":{},"gpu5":{}} "scheduler"="default" "score"=7
I0722 00:50:05.653571   23824 placement_manager.go:387]  "msg"="jobStates updated"  "new"={"tf2-keras-cifar10-resnet50-elastic-20210722-122006":{},"tf2-keras-cifar10-resnet50-elastic-20210722-122542":{},"tf2-keras-cifar10-resnet50-elastic-20210722-122731":{},"tf2-keras-cifar10-resnet50-elastic-20210722-122945":{},"tf2-keras-cifar10-resnet50-elastic-20210722-123011":{},"tf2-keras-cifar10-vgg16-elastic-20210722-122446":{},"tf2-keras-cifar10-vgg16-elastic-20210722-122513":{},"tf2-keras-cifar10-vgg16-elastic-20210722-122804":{},"tf2-keras-cifar10-vgg16-elastic-20210722-122906":{},"tf2-keras-transformer-elastic-20210722-122149":{},"tf2-keras-transformer-elastic-20210722-122215":{},"tf2-keras-transformer-elastic-20210722-122421":{}} "old"={"tf2-keras-cifar10-resnet50-elastic-20210722-122006":{},"tf2-keras-cifar10-resnet50-elastic-20210722-122327":{},"tf2-keras-cifar10-resnet50-elastic-20210722-122542":{},"tf2-keras-cifar10-resnet50-elastic-20210722-122731":{},"tf2-keras-cifar10-resnet50-elastic-20210722-122945":{},"tf2-keras-cifar10-resnet50-elastic-20210722-123011":{},"tf2-keras-cifar10-vgg16-elastic-20210722-122446":{},"tf2-keras-cifar10-vgg16-elastic-20210722-122513":{},"tf2-keras-cifar10-vgg16-elastic-20210722-122804":{},"tf2-keras-cifar10-vgg16-elastic-20210722-122906":{},"tf2-keras-transformer-elastic-20210722-122149":{},"tf2-keras-transformer-elastic-20210722-122215":{}} "scheduler"="default"
I0722 00:50:05.653927   23824 placement_manager.go:434]  "msg"="podNodeName updated"  "launchersToDelete"=4 "new"={"tf2-keras-cifar10-resnet50-elastic-20210722-122006-worker-0":"gpu4","tf2-keras-cifar10-resnet50-elastic-20210722-122542-worker-0":"gpu4","tf2-keras-cifar10-resnet50-elastic-20210722-122731-worker-0":"gpu3","tf2-keras-cifar10-resnet50-elastic-20210722-122945-worker-0":"gpu4","tf2-keras-cifar10-resnet50-elastic-20210722-123011-worker-0":"gpu3","tf2-keras-cifar10-vgg16-elastic-20210722-122446-worker-0":"gpu5","tf2-keras-cifar10-vgg16-elastic-20210722-122513-worker-0":"gpu3","tf2-keras-cifar10-vgg16-elastic-20210722-122804-worker-0":"gpu4","tf2-keras-cifar10-vgg16-elastic-20210722-122906-worker-0":"gpu3","tf2-keras-transformer-elastic-20210722-122149-worker-0":"gpu5","tf2-keras-transformer-elastic-20210722-122215-worker-0":"gpu5","tf2-keras-transformer-elastic-20210722-122421-worker-0":"gpu5"} "old"={"tf2-keras-cifar10-resnet50-elastic-20210722-122006-worker-0":"gpu4","tf2-keras-cifar10-resnet50-elastic-20210722-122327-worker-0":"gpu3","tf2-keras-cifar10-resnet50-elastic-20210722-122542-worker-0":"gpu4","tf2-keras-cifar10-resnet50-elastic-20210722-122731-worker-0":"gpu4","tf2-keras-cifar10-resnet50-elastic-20210722-122945-worker-0":"gpu4","tf2-keras-cifar10-resnet50-elastic-20210722-123011-worker-0":"gpu5","tf2-keras-cifar10-vgg16-elastic-20210722-122446-worker-0":"gpu5","tf2-keras-cifar10-vgg16-elastic-20210722-122513-worker-0":"gpu3","tf2-keras-cifar10-vgg16-elastic-20210722-122804-worker-0":"gpu5","tf2-keras-cifar10-vgg16-elastic-20210722-122906-worker-0":"gpu3","tf2-keras-transformer-elastic-20210722-122149-worker-0":"gpu5","tf2-keras-transformer-elastic-20210722-122215-worker-0":"gpu3"} "scheduler"="default" "workersToDelete"=4
I0722 00:50:05.654234   23824 placement_manager.go:451]  "msg"="Deleting pod that need migration"  "podName"="tf2-keras-transformer-elastic-20210722-122215-worker-0" "scheduler"="default"
I0722 00:50:05.659021   23824 placement_manager.go:451]  "msg"="Deleting pod that need migration"  "podName"="tf2-keras-transformer-elastic-20210722-122215-launcher" "scheduler"="default"
I0722 00:50:05.665145   23824 placement_manager.go:451]  "msg"="Deleting pod that need migration"  "podName"="tf2-keras-cifar10-resnet50-elastic-20210722-122731-worker-0" "scheduler"="default"
I0722 00:50:05.672623   23824 placement_manager.go:451]  "msg"="Deleting pod that need migration"  "podName"="tf2-keras-cifar10-resnet50-elastic-20210722-122731-launcher" "scheduler"="default"
I0722 00:50:05.676678   23824 placement_manager.go:451]  "msg"="Deleting pod that need migration"  "podName"="tf2-keras-cifar10-resnet50-elastic-20210722-123011-worker-0" "scheduler"="default"
I0722 00:50:05.681183   23824 placement_manager.go:451]  "msg"="Deleting pod that need migration"  "podName"="tf2-keras-cifar10-resnet50-elastic-20210722-123011-launcher" "scheduler"="default"
I0722 00:50:05.685536   23824 placement_manager.go:451]  "msg"="Deleting pod that need migration"  "podName"="tf2-keras-cifar10-vgg16-elastic-20210722-122804-worker-0" "scheduler"="default"
I0722 00:50:05.688245   23824 placement_manager.go:451]  "msg"="Deleting pod that need migration"  "podName"="tf2-keras-cifar10-vgg16-elastic-20210722-122804-launcher" "scheduler"="default"
I0722 00:50:05.692269   23824 placement_manager.go:183]  "msg"="Finished job placements adjustment"  "scheduler"="default"
I0722 00:50:05.692495   23824 scheduler.go:182]  "msg"="Finished resched"  "scheduler"="default"
I0722 00:50:05.697342   23824 placement_manager.go:147]  "msg"="Adding toleration to pod"  "podName"="tf2-keras-transformer-elastic-20210722-122421-worker-0" "scheduler"="default" "toleration"={"key":"celeste/hostname","operator":"Equal","value":"gpu5","effect":"NoExecute"}
I0722 00:50:06.061845   23824 placement_manager.go:147]  "msg"="Adding toleration to pod"  "podName"="tf2-keras-transformer-elastic-20210722-122421-launcher" "scheduler"="default" "toleration"={"key":"celeste/hostname","operator":"Exists","effect":"NoExecute"}
I0722 00:50:13.092492   23824 placement_manager.go:147]  "msg"="Adding toleration to pod"  "podName"="tf2-keras-cifar10-vgg16-elastic-20210722-122804-launcher" "scheduler"="default" "toleration"={"key":"celeste/hostname","operator":"Exists","effect":"NoExecute"}
I0722 00:50:13.134048   23824 placement_manager.go:147]  "msg"="Adding toleration to pod"  "podName"="tf2-keras-cifar10-resnet50-elastic-20210722-122731-worker-0" "scheduler"="default" "toleration"={"key":"celeste/hostname","operator":"Equal","value":"gpu3","effect":"NoExecute"}
I0722 00:50:19.286052   23824 placement_manager.go:147]  "msg"="Adding toleration to pod"  "podName"="tf2-keras-transformer-elastic-20210722-122215-worker-0" "scheduler"="default" "toleration"={"key":"celeste/hostname","operator":"Equal","value":"gpu5","effect":"NoExecute"}
I0722 00:50:20.933155   23824 placement_manager.go:147]  "msg"="Adding toleration to pod"  "podName"="tf2-keras-cifar10-resnet50-elastic-20210722-123011-worker-0" "scheduler"="default" "toleration"={"key":"celeste/hostname","operator":"Equal","value":"gpu3","effect":"NoExecute"}
I0722 00:50:21.721899   23824 placement_manager.go:147]  "msg"="Adding toleration to pod"  "podName"="tf2-keras-transformer-elastic-20210722-122215-launcher" "scheduler"="default" "toleration"={"key":"celeste/hostname","operator":"Exists","effect":"NoExecute"}
I0722 00:50:22.722948   23824 placement_manager.go:147]  "msg"="Adding toleration to pod"  "podName"="tf2-keras-cifar10-resnet50-elastic-20210722-123011-launcher" "scheduler"="default" "toleration"={"key":"celeste/hostname","operator":"Exists","effect":"NoExecute"}
I0722 00:50:23.916763   23824 placement_manager.go:147]  "msg"="Adding toleration to pod"  "podName"="tf2-keras-cifar10-vgg16-elastic-20210722-122804-worker-0" "scheduler"="default" "toleration"={"key":"celeste/hostname","operator":"Equal","value":"gpu4","effect":"NoExecute"}
I0722 00:50:24.593963   23824 placement_manager.go:147]  "msg"="Adding toleration to pod"  "podName"="tf2-keras-cifar10-resnet50-elastic-20210722-122731-launcher" "scheduler"="default" "toleration"={"key":"celeste/hostname","operator":"Exists","effect":"NoExecute"}
I0722 00:50:39.817210   23824 scheduler.go:474]  "msg"="Training job completed"  "elaspedTotalSeconds"=1828.656212053 "gpuTotalSeconds"=1856.360160832 "job"="tf2-keras-cifar10-resnet50-elastic-20210722-122006" "ranTotalSeconds"=1736.357432487 "scheduler"="default" "waitedTotalSeconds"=92.298779566
I0722 00:50:39.817358   23824 scheduler.go:135]  "msg"="Received resched event, may be blocked because of rate limit"  "blockedUntil"="2021-07-22T00:52:05.692814092+08:00" "lastResched"="2021-07-22T00:50:05.692814092+08:00" "received"="2021-07-22T00:50:39.81724211+08:00" "scheduler"="default"
I0722 00:51:36.225246   23824 scheduler.go:474]  "msg"="Training job completed"  "elaspedTotalSeconds"=1608.329365486 "gpuTotalSeconds"=1556.057789422 "job"="tf2-keras-cifar10-vgg16-elastic-20210722-122446" "ranTotalSeconds"=1556.057789422 "scheduler"="default" "waitedTotalSeconds"=52.271576064
I0722 00:51:42.104966   23824 scheduler.go:474]  "msg"="Training job completed"  "elaspedTotalSeconds"=1586.380868667 "gpuTotalSeconds"=1561.057857646 "job"="tf2-keras-cifar10-vgg16-elastic-20210722-122513" "ranTotalSeconds"=1561.057857646 "scheduler"="default" "waitedTotalSeconds"=25.323011021
I0722 00:52:05.692864   23824 scheduler.go:159]  "msg"="Started resched"  "scheduler"="default"
I0722 00:52:05.692908   23824 scheduler.go:193]  "msg"="Updating all jobs info"  "scheduler"="default"
I0722 00:52:05.706455   23824 afsl.go:65]  "msg"="Finished scheduling"  "algorithm"="AFS-L" "freeGpu"=0 "result"={"tf2-keras-cifar10-inceptionv3-elastic-20210722-121943":0,"tf2-keras-cifar10-inceptionv3-elastic-20210722-122034":0,"tf2-keras-cifar10-inceptionv3-elastic-20210722-122250":0,"tf2-keras-cifar10-inceptionv3-elastic-20210722-122354":0,"tf2-keras-cifar10-inceptionv3-elastic-20210722-122611":0,"tf2-keras-cifar10-inceptionv3-elastic-20210722-122710":0,"tf2-keras-cifar10-resnet50-elastic-20210722-122542":1,"tf2-keras-cifar10-resnet50-elastic-20210722-122731":1,"tf2-keras-cifar10-resnet50-elastic-20210722-122945":1,"tf2-keras-cifar10-resnet50-elastic-20210722-123011":1,"tf2-keras-cifar10-vgg16-elastic-20210722-122804":1,"tf2-keras-cifar10-vgg16-elastic-20210722-122906":1,"tf2-keras-transformer-elastic-20210722-122149":1,"tf2-keras-transformer-elastic-20210722-122215":1,"tf2-keras-transformer-elastic-20210722-122421":1,"tf2-keras-transformer-elastic-20210722-122647":1,"tf2-keras-transformer-elastic-20210722-122826":1,"tf2-keras-transformer-elastic-20210722-123039":1} "scheduler"="default"
I0722 00:52:05.706908   23824 scheduler.go:384]  "msg"="Trying to delete multiple training jobs"  "jobs"=[] "scheduler"="default"
I0722 00:52:05.707090   23824 scheduler.go:342]  "msg"="Trying to scale multiple training jobs"  "jobs"=[] "scheduler"="default"
I0722 00:52:05.707261   23824 scheduler.go:292]  "msg"="Trying to start multiple training jobs"  "jobs"=["tf2-keras-transformer-elastic-20210722-122826","tf2-keras-transformer-elastic-20210722-122647","tf2-keras-transformer-elastic-20210722-123039"] "scheduler"="default"
I0722 00:52:05.732248   23824 scheduler.go:342]  "msg"="Trying to scale multiple training jobs"  "jobs"=[] "scheduler"="default"
I0722 00:52:05.737522   23824 placement_manager.go:166]  "msg"="Started job placements adjustment"  "scheduler"="default"
I0722 00:52:05.737615   23824 placement_manager.go:192]  "msg"="Releasing slots"  "jobs"={"tf2-keras-cifar10-resnet50-elastic-20210722-122006":{},"tf2-keras-cifar10-resnet50-elastic-20210722-122542":{},"tf2-keras-cifar10-resnet50-elastic-20210722-122731":{},"tf2-keras-cifar10-resnet50-elastic-20210722-122945":{},"tf2-keras-cifar10-resnet50-elastic-20210722-123011":{},"tf2-keras-cifar10-vgg16-elastic-20210722-122446":{},"tf2-keras-cifar10-vgg16-elastic-20210722-122513":{},"tf2-keras-cifar10-vgg16-elastic-20210722-122804":{},"tf2-keras-cifar10-vgg16-elastic-20210722-122906":{},"tf2-keras-transformer-elastic-20210722-122149":{},"tf2-keras-transformer-elastic-20210722-122215":{},"tf2-keras-transformer-elastic-20210722-122421":{}} "nodes"={"gpu3":{},"gpu4":{},"gpu5":{}} "scheduler"="default"
I0722 00:52:05.737751   23824 placement_manager.go:250]  "msg"="Released slots"  "jobs"={"tf2-keras-cifar10-resnet50-elastic-20210722-122006":{},"tf2-keras-cifar10-resnet50-elastic-20210722-122542":{},"tf2-keras-cifar10-resnet50-elastic-20210722-122731":{},"tf2-keras-cifar10-resnet50-elastic-20210722-122945":{},"tf2-keras-cifar10-resnet50-elastic-20210722-123011":{},"tf2-keras-cifar10-vgg16-elastic-20210722-122446":{},"tf2-keras-cifar10-vgg16-elastic-20210722-122513":{},"tf2-keras-cifar10-vgg16-elastic-20210722-122804":{},"tf2-keras-cifar10-vgg16-elastic-20210722-122906":{},"tf2-keras-transformer-elastic-20210722-122149":{},"tf2-keras-transformer-elastic-20210722-122215":{},"tf2-keras-transformer-elastic-20210722-122421":{}} "nodes"={"gpu3":{},"gpu4":{},"gpu5":{}} "scheduler"="default"
I0722 00:52:05.738315   23824 placement_manager.go:305]  "msg"="Found best-fit"  "crossNode"=0 "nodes"=[{},{},{}] "requests"=[{},{},{},{},{},{},{},{},{},{},{},{},{},{},{},{},{},{},{},{},{},{},{},{},{},{},{},{},{},{},{},{},{},{},{},{}] "scheduler"="default"
I0722 00:52:05.738727   23824 placement_manager.go:339]  "msg"="nodeStates updated"  "new"={"gpu3":{},"gpu4":{},"gpu5":{}} "old"={"gpu3":{},"gpu4":{},"gpu5":{}} "scheduler"="default" "score"=5
I0722 00:52:05.739110   23824 placement_manager.go:387]  "msg"="jobStates updated"  "new"={"tf2-keras-cifar10-resnet50-elastic-20210722-122542":{},"tf2-keras-cifar10-resnet50-elastic-20210722-122731":{},"tf2-keras-cifar10-resnet50-elastic-20210722-122945":{},"tf2-keras-cifar10-resnet50-elastic-20210722-123011":{},"tf2-keras-cifar10-vgg16-elastic-20210722-122804":{},"tf2-keras-cifar10-vgg16-elastic-20210722-122906":{},"tf2-keras-transformer-elastic-20210722-122149":{},"tf2-keras-transformer-elastic-20210722-122215":{},"tf2-keras-transformer-elastic-20210722-122421":{},"tf2-keras-transformer-elastic-20210722-122647":{},"tf2-keras-transformer-elastic-20210722-122826":{},"tf2-keras-transformer-elastic-20210722-123039":{}} "old"={"tf2-keras-cifar10-resnet50-elastic-20210722-122006":{},"tf2-keras-cifar10-resnet50-elastic-20210722-122542":{},"tf2-keras-cifar10-resnet50-elastic-20210722-122731":{},"tf2-keras-cifar10-resnet50-elastic-20210722-122945":{},"tf2-keras-cifar10-resnet50-elastic-20210722-123011":{},"tf2-keras-cifar10-vgg16-elastic-20210722-122446":{},"tf2-keras-cifar10-vgg16-elastic-20210722-122513":{},"tf2-keras-cifar10-vgg16-elastic-20210722-122804":{},"tf2-keras-cifar10-vgg16-elastic-20210722-122906":{},"tf2-keras-transformer-elastic-20210722-122149":{},"tf2-keras-transformer-elastic-20210722-122215":{},"tf2-keras-transformer-elastic-20210722-122421":{}} "scheduler"="default"
I0722 00:52:05.739508   23824 placement_manager.go:434]  "msg"="podNodeName updated"  "launchersToDelete"=4 "new"={"tf2-keras-cifar10-resnet50-elastic-20210722-122542-worker-0":"gpu4","tf2-keras-cifar10-resnet50-elastic-20210722-122731-worker-0":"gpu3","tf2-keras-cifar10-resnet50-elastic-20210722-122945-worker-0":"gpu3","tf2-keras-cifar10-resnet50-elastic-20210722-123011-worker-0":"gpu3","tf2-keras-cifar10-vgg16-elastic-20210722-122804-worker-0":"gpu4","tf2-keras-cifar10-vgg16-elastic-20210722-122906-worker-0":"gpu5","tf2-keras-transformer-elastic-20210722-122149-worker-0":"gpu4","tf2-keras-transformer-elastic-20210722-122215-worker-0":"gpu5","tf2-keras-transformer-elastic-20210722-122421-worker-0":"gpu4","tf2-keras-transformer-elastic-20210722-122647-worker-0":"gpu5","tf2-keras-transformer-elastic-20210722-122826-worker-0":"gpu5","tf2-keras-transformer-elastic-20210722-123039-worker-0":"gpu3"} "old"={"tf2-keras-cifar10-resnet50-elastic-20210722-122006-worker-0":"gpu4","tf2-keras-cifar10-resnet50-elastic-20210722-122542-worker-0":"gpu4","tf2-keras-cifar10-resnet50-elastic-20210722-122731-worker-0":"gpu3","tf2-keras-cifar10-resnet50-elastic-20210722-122945-worker-0":"gpu4","tf2-keras-cifar10-resnet50-elastic-20210722-123011-worker-0":"gpu3","tf2-keras-cifar10-vgg16-elastic-20210722-122446-worker-0":"gpu5","tf2-keras-cifar10-vgg16-elastic-20210722-122513-worker-0":"gpu3","tf2-keras-cifar10-vgg16-elastic-20210722-122804-worker-0":"gpu4","tf2-keras-cifar10-vgg16-elastic-20210722-122906-worker-0":"gpu3","tf2-keras-transformer-elastic-20210722-122149-worker-0":"gpu5","tf2-keras-transformer-elastic-20210722-122215-worker-0":"gpu5","tf2-keras-transformer-elastic-20210722-122421-worker-0":"gpu5"} "scheduler"="default" "workersToDelete"=4
I0722 00:52:05.739825   23824 placement_manager.go:451]  "msg"="Deleting pod that need migration"  "podName"="tf2-keras-cifar10-resnet50-elastic-20210722-122945-worker-0" "scheduler"="default"
I0722 00:52:05.745825   23824 placement_manager.go:451]  "msg"="Deleting pod that need migration"  "podName"="tf2-keras-cifar10-resnet50-elastic-20210722-122945-launcher" "scheduler"="default"
I0722 00:52:05.750177   23824 placement_manager.go:451]  "msg"="Deleting pod that need migration"  "podName"="tf2-keras-cifar10-vgg16-elastic-20210722-122906-worker-0" "scheduler"="default"
I0722 00:52:05.754396   23824 placement_manager.go:451]  "msg"="Deleting pod that need migration"  "podName"="tf2-keras-cifar10-vgg16-elastic-20210722-122906-launcher" "scheduler"="default"
I0722 00:52:05.758433   23824 placement_manager.go:451]  "msg"="Deleting pod that need migration"  "podName"="tf2-keras-transformer-elastic-20210722-122421-worker-0" "scheduler"="default"
I0722 00:52:05.762979   23824 placement_manager.go:451]  "msg"="Deleting pod that need migration"  "podName"="tf2-keras-transformer-elastic-20210722-122421-launcher" "scheduler"="default"
I0722 00:52:05.772977   23824 placement_manager.go:451]  "msg"="Deleting pod that need migration"  "podName"="tf2-keras-transformer-elastic-20210722-122149-worker-0" "scheduler"="default"
I0722 00:52:05.783619   23824 placement_manager.go:451]  "msg"="Deleting pod that need migration"  "podName"="tf2-keras-transformer-elastic-20210722-122149-launcher" "scheduler"="default"
I0722 00:52:05.787454   23824 placement_manager.go:183]  "msg"="Finished job placements adjustment"  "scheduler"="default"
I0722 00:52:05.787702   23824 scheduler.go:182]  "msg"="Finished resched"  "scheduler"="default"
I0722 00:52:06.122915   23824 placement_manager.go:147]  "msg"="Adding toleration to pod"  "podName"="tf2-keras-transformer-elastic-20210722-122826-worker-0" "scheduler"="default" "toleration"={"key":"celeste/hostname","operator":"Equal","value":"gpu5","effect":"NoExecute"}
I0722 00:52:06.323630   23824 placement_manager.go:147]  "msg"="Adding toleration to pod"  "podName"="tf2-keras-transformer-elastic-20210722-122647-worker-0" "scheduler"="default" "toleration"={"key":"celeste/hostname","operator":"Equal","value":"gpu5","effect":"NoExecute"}
I0722 00:52:06.546556   23824 placement_manager.go:147]  "msg"="Adding toleration to pod"  "podName"="tf2-keras-transformer-elastic-20210722-122826-launcher" "scheduler"="default" "toleration"={"key":"celeste/hostname","operator":"Exists","effect":"NoExecute"}
I0722 00:52:06.950834   23824 placement_manager.go:147]  "msg"="Adding toleration to pod"  "podName"="tf2-keras-transformer-elastic-20210722-122647-launcher" "scheduler"="default" "toleration"={"key":"celeste/hostname","operator":"Exists","effect":"NoExecute"}
I0722 00:52:08.524191   23824 placement_manager.go:147]  "msg"="Adding toleration to pod"  "podName"="tf2-keras-transformer-elastic-20210722-123039-worker-0" "scheduler"="default" "toleration"={"key":"celeste/hostname","operator":"Equal","value":"gpu3","effect":"NoExecute"}
I0722 00:52:08.726124   23824 placement_manager.go:147]  "msg"="Adding toleration to pod"  "podName"="tf2-keras-transformer-elastic-20210722-123039-launcher" "scheduler"="default" "toleration"={"key":"celeste/hostname","operator":"Exists","effect":"NoExecute"}
I0722 00:52:12.704031   23824 placement_manager.go:147]  "msg"="Adding toleration to pod"  "podName"="tf2-keras-cifar10-resnet50-elastic-20210722-122945-worker-0" "scheduler"="default" "toleration"={"key":"celeste/hostname","operator":"Equal","value":"gpu3","effect":"NoExecute"}
I0722 00:52:14.632119   23824 placement_manager.go:147]  "msg"="Adding toleration to pod"  "podName"="tf2-keras-cifar10-vgg16-elastic-20210722-122906-launcher" "scheduler"="default" "toleration"={"key":"celeste/hostname","operator":"Exists","effect":"NoExecute"}
I0722 00:52:15.184457   23824 placement_manager.go:147]  "msg"="Adding toleration to pod"  "podName"="tf2-keras-cifar10-resnet50-elastic-20210722-122945-launcher" "scheduler"="default" "toleration"={"key":"celeste/hostname","operator":"Exists","effect":"NoExecute"}
I0722 00:52:16.577046   23824 placement_manager.go:147]  "msg"="Adding toleration to pod"  "podName"="tf2-keras-transformer-elastic-20210722-122421-launcher" "scheduler"="default" "toleration"={"key":"celeste/hostname","operator":"Exists","effect":"NoExecute"}
I0722 00:52:17.172894   23824 placement_manager.go:147]  "msg"="Adding toleration to pod"  "podName"="tf2-keras-transformer-elastic-20210722-122149-worker-0" "scheduler"="default" "toleration"={"key":"celeste/hostname","operator":"Equal","value":"gpu4","effect":"NoExecute"}
I0722 00:52:21.445461   23824 placement_manager.go:147]  "msg"="Adding toleration to pod"  "podName"="tf2-keras-cifar10-vgg16-elastic-20210722-122906-worker-0" "scheduler"="default" "toleration"={"key":"celeste/hostname","operator":"Equal","value":"gpu5","effect":"NoExecute"}
I0722 00:52:22.236319   23824 placement_manager.go:147]  "msg"="Adding toleration to pod"  "podName"="tf2-keras-transformer-elastic-20210722-122149-launcher" "scheduler"="default" "toleration"={"key":"celeste/hostname","operator":"Exists","effect":"NoExecute"}
I0722 00:52:22.372468   23824 placement_manager.go:147]  "msg"="Adding toleration to pod"  "podName"="tf2-keras-transformer-elastic-20210722-122421-worker-0" "scheduler"="default" "toleration"={"key":"celeste/hostname","operator":"Equal","value":"gpu4","effect":"NoExecute"}
I0722 00:53:26.373088   23824 scheduler.go:474]  "msg"="Training job completed"  "elaspedTotalSeconds"=1519.940830029 "gpuTotalSeconds"=1425.276334308 "job"="tf2-keras-cifar10-vgg16-elastic-20210722-122804" "ranTotalSeconds"=1425.276334308 "scheduler"="default" "waitedTotalSeconds"=94.664495721
I0722 00:53:26.373212   23824 scheduler.go:135]  "msg"="Received resched event, may be blocked because of rate limit"  "blockedUntil"="2021-07-22T00:54:05.787947195+08:00" "lastResched"="2021-07-22T00:52:05.787947195+08:00" "received"="2021-07-22T00:53:26.373122665+08:00" "scheduler"="default"
I0722 00:53:29.457762   23824 scheduler.go:474]  "msg"="Training job completed"  "elaspedTotalSeconds"=1552.898592753 "gpuTotalSeconds"=1545.391162984 "job"="tf2-keras-cifar10-resnet50-elastic-20210722-122731" "ranTotalSeconds"=1545.391162984 "scheduler"="default" "waitedTotalSeconds"=7.507429769
I0722 00:53:47.835334   23824 scheduler.go:474]  "msg"="Training job completed"  "elaspedTotalSeconds"=1682.487033339 "gpuTotalSeconds"=1682.487033339 "job"="tf2-keras-cifar10-resnet50-elastic-20210722-122542" "ranTotalSeconds"=1682.487033339 "scheduler"="default" "waitedTotalSeconds"=0
I0722 00:54:05.788035   23824 scheduler.go:159]  "msg"="Started resched"  "scheduler"="default"
I0722 00:54:05.788156   23824 scheduler.go:193]  "msg"="Updating all jobs info"  "scheduler"="default"
I0722 00:54:05.799620   23824 afsl.go:65]  "msg"="Finished scheduling"  "algorithm"="AFS-L" "freeGpu"=0 "result"={"tf2-keras-cifar10-inceptionv3-elastic-20210722-121943":0,"tf2-keras-cifar10-inceptionv3-elastic-20210722-122034":0,"tf2-keras-cifar10-inceptionv3-elastic-20210722-122250":0,"tf2-keras-cifar10-inceptionv3-elastic-20210722-122354":1,"tf2-keras-cifar10-inceptionv3-elastic-20210722-122611":1,"tf2-keras-cifar10-inceptionv3-elastic-20210722-122710":1,"tf2-keras-cifar10-resnet50-elastic-20210722-122945":1,"tf2-keras-cifar10-resnet50-elastic-20210722-123011":1,"tf2-keras-cifar10-vgg16-elastic-20210722-122906":1,"tf2-keras-transformer-elastic-20210722-122149":1,"tf2-keras-transformer-elastic-20210722-122215":1,"tf2-keras-transformer-elastic-20210722-122421":1,"tf2-keras-transformer-elastic-20210722-122647":1,"tf2-keras-transformer-elastic-20210722-122826":1,"tf2-keras-transformer-elastic-20210722-123039":1} "scheduler"="default"
I0722 00:54:05.800074   23824 scheduler.go:384]  "msg"="Trying to delete multiple training jobs"  "jobs"=[] "scheduler"="default"
I0722 00:54:05.800409   23824 scheduler.go:342]  "msg"="Trying to scale multiple training jobs"  "jobs"=[] "scheduler"="default"
I0722 00:54:05.800735   23824 scheduler.go:292]  "msg"="Trying to start multiple training jobs"  "jobs"=["tf2-keras-cifar10-inceptionv3-elastic-20210722-122354","tf2-keras-cifar10-inceptionv3-elastic-20210722-122611","tf2-keras-cifar10-inceptionv3-elastic-20210722-122710"] "scheduler"="default"
I0722 00:54:05.827865   23824 scheduler.go:342]  "msg"="Trying to scale multiple training jobs"  "jobs"=[] "scheduler"="default"
I0722 00:54:05.832482   23824 placement_manager.go:166]  "msg"="Started job placements adjustment"  "scheduler"="default"
I0722 00:54:05.832571   23824 placement_manager.go:192]  "msg"="Releasing slots"  "jobs"={"tf2-keras-cifar10-resnet50-elastic-20210722-122542":{},"tf2-keras-cifar10-resnet50-elastic-20210722-122731":{},"tf2-keras-cifar10-resnet50-elastic-20210722-122945":{},"tf2-keras-cifar10-resnet50-elastic-20210722-123011":{},"tf2-keras-cifar10-vgg16-elastic-20210722-122804":{},"tf2-keras-cifar10-vgg16-elastic-20210722-122906":{},"tf2-keras-transformer-elastic-20210722-122149":{},"tf2-keras-transformer-elastic-20210722-122215":{},"tf2-keras-transformer-elastic-20210722-122421":{},"tf2-keras-transformer-elastic-20210722-122647":{},"tf2-keras-transformer-elastic-20210722-122826":{},"tf2-keras-transformer-elastic-20210722-123039":{}} "nodes"={"gpu3":{},"gpu4":{},"gpu5":{}} "scheduler"="default"
I0722 00:54:05.832656   23824 placement_manager.go:250]  "msg"="Released slots"  "jobs"={"tf2-keras-cifar10-resnet50-elastic-20210722-122542":{},"tf2-keras-cifar10-resnet50-elastic-20210722-122731":{},"tf2-keras-cifar10-resnet50-elastic-20210722-122945":{},"tf2-keras-cifar10-resnet50-elastic-20210722-123011":{},"tf2-keras-cifar10-vgg16-elastic-20210722-122804":{},"tf2-keras-cifar10-vgg16-elastic-20210722-122906":{},"tf2-keras-transformer-elastic-20210722-122149":{},"tf2-keras-transformer-elastic-20210722-122215":{},"tf2-keras-transformer-elastic-20210722-122421":{},"tf2-keras-transformer-elastic-20210722-122647":{},"tf2-keras-transformer-elastic-20210722-122826":{},"tf2-keras-transformer-elastic-20210722-123039":{}} "nodes"={"gpu3":{},"gpu4":{},"gpu5":{}} "scheduler"="default"
I0722 00:54:05.833218   23824 placement_manager.go:305]  "msg"="Found best-fit"  "crossNode"=0 "nodes"=[{},{},{}] "requests"=[{},{},{},{},{},{},{},{},{},{},{},{},{},{},{},{},{},{},{},{},{},{},{},{},{},{},{},{},{},{}] "scheduler"="default"
I0722 00:54:05.833539   23824 placement_manager.go:339]  "msg"="nodeStates updated"  "new"={"gpu3":{},"gpu4":{},"gpu5":{}} "old"={"gpu3":{},"gpu4":{},"gpu5":{}} "scheduler"="default" "score"=5
I0722 00:54:05.833868   23824 placement_manager.go:387]  "msg"="jobStates updated"  "new"={"tf2-keras-cifar10-inceptionv3-elastic-20210722-122354":{},"tf2-keras-cifar10-inceptionv3-elastic-20210722-122611":{},"tf2-keras-cifar10-inceptionv3-elastic-20210722-122710":{},"tf2-keras-cifar10-resnet50-elastic-20210722-122945":{},"tf2-keras-cifar10-resnet50-elastic-20210722-123011":{},"tf2-keras-cifar10-vgg16-elastic-20210722-122906":{},"tf2-keras-transformer-elastic-20210722-122149":{},"tf2-keras-transformer-elastic-20210722-122215":{},"tf2-keras-transformer-elastic-20210722-122421":{},"tf2-keras-transformer-elastic-20210722-122647":{},"tf2-keras-transformer-elastic-20210722-122826":{},"tf2-keras-transformer-elastic-20210722-123039":{}} "old"={"tf2-keras-cifar10-resnet50-elastic-20210722-122542":{},"tf2-keras-cifar10-resnet50-elastic-20210722-122731":{},"tf2-keras-cifar10-resnet50-elastic-20210722-122945":{},"tf2-keras-cifar10-resnet50-elastic-20210722-123011":{},"tf2-keras-cifar10-vgg16-elastic-20210722-122804":{},"tf2-keras-cifar10-vgg16-elastic-20210722-122906":{},"tf2-keras-transformer-elastic-20210722-122149":{},"tf2-keras-transformer-elastic-20210722-122215":{},"tf2-keras-transformer-elastic-20210722-122421":{},"tf2-keras-transformer-elastic-20210722-122647":{},"tf2-keras-transformer-elastic-20210722-122826":{},"tf2-keras-transformer-elastic-20210722-123039":{}} "scheduler"="default"
I0722 00:54:05.834363   23824 placement_manager.go:434]  "msg"="podNodeName updated"  "launchersToDelete"=4 "new"={"tf2-keras-cifar10-inceptionv3-elastic-20210722-122354-worker-0":"gpu3","tf2-keras-cifar10-inceptionv3-elastic-20210722-122611-worker-0":"gpu5","tf2-keras-cifar10-inceptionv3-elastic-20210722-122710-worker-0":"gpu5","tf2-keras-cifar10-resnet50-elastic-20210722-122945-worker-0":"gpu4","tf2-keras-cifar10-resnet50-elastic-20210722-123011-worker-0":"gpu3","tf2-keras-cifar10-vgg16-elastic-20210722-122906-worker-0":"gpu5","tf2-keras-transformer-elastic-20210722-122149-worker-0":"gpu4","tf2-keras-transformer-elastic-20210722-122215-worker-0":"gpu5","tf2-keras-transformer-elastic-20210722-122421-worker-0":"gpu3","tf2-keras-transformer-elastic-20210722-122647-worker-0":"gpu4","tf2-keras-transformer-elastic-20210722-122826-worker-0":"gpu4","tf2-keras-transformer-elastic-20210722-123039-worker-0":"gpu3"} "old"={"tf2-keras-cifar10-resnet50-elastic-20210722-122542-worker-0":"gpu4","tf2-keras-cifar10-resnet50-elastic-20210722-122731-worker-0":"gpu3","tf2-keras-cifar10-resnet50-elastic-20210722-122945-worker-0":"gpu3","tf2-keras-cifar10-resnet50-elastic-20210722-123011-worker-0":"gpu3","tf2-keras-cifar10-vgg16-elastic-20210722-122804-worker-0":"gpu4","tf2-keras-cifar10-vgg16-elastic-20210722-122906-worker-0":"gpu5","tf2-keras-transformer-elastic-20210722-122149-worker-0":"gpu4","tf2-keras-transformer-elastic-20210722-122215-worker-0":"gpu5","tf2-keras-transformer-elastic-20210722-122421-worker-0":"gpu4","tf2-keras-transformer-elastic-20210722-122647-worker-0":"gpu5","tf2-keras-transformer-elastic-20210722-122826-worker-0":"gpu5","tf2-keras-transformer-elastic-20210722-123039-worker-0":"gpu3"} "scheduler"="default" "workersToDelete"=4
I0722 00:54:05.834657   23824 placement_manager.go:451]  "msg"="Deleting pod that need migration"  "podName"="tf2-keras-transformer-elastic-20210722-122647-worker-0" "scheduler"="default"
I0722 00:54:05.838787   23824 placement_manager.go:451]  "msg"="Deleting pod that need migration"  "podName"="tf2-keras-transformer-elastic-20210722-122647-launcher" "scheduler"="default"
I0722 00:54:05.846121   23824 placement_manager.go:451]  "msg"="Deleting pod that need migration"  "podName"="tf2-keras-cifar10-resnet50-elastic-20210722-122945-worker-0" "scheduler"="default"
I0722 00:54:05.850522   23824 placement_manager.go:451]  "msg"="Deleting pod that need migration"  "podName"="tf2-keras-cifar10-resnet50-elastic-20210722-122945-launcher" "scheduler"="default"
I0722 00:54:05.855414   23824 placement_manager.go:451]  "msg"="Deleting pod that need migration"  "podName"="tf2-keras-transformer-elastic-20210722-122421-worker-0" "scheduler"="default"
I0722 00:54:05.859170   23824 placement_manager.go:451]  "msg"="Deleting pod that need migration"  "podName"="tf2-keras-transformer-elastic-20210722-122421-launcher" "scheduler"="default"
I0722 00:54:05.862889   23824 placement_manager.go:451]  "msg"="Deleting pod that need migration"  "podName"="tf2-keras-transformer-elastic-20210722-122826-worker-0" "scheduler"="default"
I0722 00:54:05.866916   23824 placement_manager.go:451]  "msg"="Deleting pod that need migration"  "podName"="tf2-keras-transformer-elastic-20210722-122826-launcher" "scheduler"="default"
I0722 00:54:05.871272   23824 placement_manager.go:183]  "msg"="Finished job placements adjustment"  "scheduler"="default"
I0722 00:54:05.871532   23824 scheduler.go:182]  "msg"="Finished resched"  "scheduler"="default"
I0722 00:54:06.220467   23824 placement_manager.go:147]  "msg"="Adding toleration to pod"  "podName"="tf2-keras-cifar10-inceptionv3-elastic-20210722-122354-worker-0" "scheduler"="default" "toleration"={"key":"celeste/hostname","operator":"Equal","value":"gpu3","effect":"NoExecute"}
I0722 00:54:06.421784   23824 placement_manager.go:147]  "msg"="Adding toleration to pod"  "podName"="tf2-keras-cifar10-inceptionv3-elastic-20210722-122611-worker-0" "scheduler"="default" "toleration"={"key":"celeste/hostname","operator":"Equal","value":"gpu5","effect":"NoExecute"}
I0722 00:54:06.641169   23824 placement_manager.go:147]  "msg"="Adding toleration to pod"  "podName"="tf2-keras-cifar10-inceptionv3-elastic-20210722-122354-launcher" "scheduler"="default" "toleration"={"key":"celeste/hostname","operator":"Exists","effect":"NoExecute"}
I0722 00:54:07.044473   23824 placement_manager.go:147]  "msg"="Adding toleration to pod"  "podName"="tf2-keras-cifar10-inceptionv3-elastic-20210722-122611-launcher" "scheduler"="default" "toleration"={"key":"celeste/hostname","operator":"Exists","effect":"NoExecute"}
I0722 00:54:08.621145   23824 placement_manager.go:147]  "msg"="Adding toleration to pod"  "podName"="tf2-keras-cifar10-inceptionv3-elastic-20210722-122710-worker-0" "scheduler"="default" "toleration"={"key":"celeste/hostname","operator":"Equal","value":"gpu5","effect":"NoExecute"}
I0722 00:54:09.022429   23824 placement_manager.go:147]  "msg"="Adding toleration to pod"  "podName"="tf2-keras-cifar10-inceptionv3-elastic-20210722-122710-launcher" "scheduler"="default" "toleration"={"key":"celeste/hostname","operator":"Exists","effect":"NoExecute"}
I0722 00:54:13.467087   23824 placement_manager.go:147]  "msg"="Adding toleration to pod"  "podName"="tf2-keras-transformer-elastic-20210722-122421-launcher" "scheduler"="default" "toleration"={"key":"celeste/hostname","operator":"Exists","effect":"NoExecute"}
I0722 00:54:13.530144   23824 placement_manager.go:147]  "msg"="Adding toleration to pod"  "podName"="tf2-keras-transformer-elastic-20210722-122421-worker-0" "scheduler"="default" "toleration"={"key":"celeste/hostname","operator":"Equal","value":"gpu3","effect":"NoExecute"}
I0722 00:54:19.761009   23824 placement_manager.go:147]  "msg"="Adding toleration to pod"  "podName"="tf2-keras-cifar10-resnet50-elastic-20210722-122945-worker-0" "scheduler"="default" "toleration"={"key":"celeste/hostname","operator":"Equal","value":"gpu4","effect":"NoExecute"}
I0722 00:54:21.761490   23824 placement_manager.go:147]  "msg"="Adding toleration to pod"  "podName"="tf2-keras-transformer-elastic-20210722-122647-worker-0" "scheduler"="default" "toleration"={"key":"celeste/hostname","operator":"Equal","value":"gpu4","effect":"NoExecute"}
I0722 00:54:22.564408   23824 placement_manager.go:147]  "msg"="Adding toleration to pod"  "podName"="tf2-keras-transformer-elastic-20210722-122826-worker-0" "scheduler"="default" "toleration"={"key":"celeste/hostname","operator":"Equal","value":"gpu4","effect":"NoExecute"}
I0722 00:54:23.364446   23824 placement_manager.go:147]  "msg"="Adding toleration to pod"  "podName"="tf2-keras-cifar10-resnet50-elastic-20210722-122945-launcher" "scheduler"="default" "toleration"={"key":"celeste/hostname","operator":"Exists","effect":"NoExecute"}
I0722 00:54:24.958660   23824 placement_manager.go:147]  "msg"="Adding toleration to pod"  "podName"="tf2-keras-transformer-elastic-20210722-122826-launcher" "scheduler"="default" "toleration"={"key":"celeste/hostname","operator":"Exists","effect":"NoExecute"}
I0722 00:54:27.392390   23824 placement_manager.go:147]  "msg"="Adding toleration to pod"  "podName"="tf2-keras-transformer-elastic-20210722-122647-launcher" "scheduler"="default" "toleration"={"key":"celeste/hostname","operator":"Exists","effect":"NoExecute"}
I0722 00:54:37.199448   23824 scheduler.go:474]  "msg"="Training job completed"  "elaspedTotalSeconds"=1527.947268146 "gpuTotalSeconds"=1495.278408379 "job"="tf2-keras-cifar10-vgg16-elastic-20210722-122906" "ranTotalSeconds"=1495.278408379 "scheduler"="default" "waitedTotalSeconds"=32.668859767
I0722 00:54:37.199606   23824 scheduler.go:135]  "msg"="Received resched event, may be blocked because of rate limit"  "blockedUntil"="2021-07-22T00:56:05.871920388+08:00" "lastResched"="2021-07-22T00:54:05.871920388+08:00" "received"="2021-07-22T00:54:37.199494011+08:00" "scheduler"="default"
I0722 00:56:05.871977   23824 scheduler.go:159]  "msg"="Started resched"  "scheduler"="default"
I0722 00:56:05.872058   23824 scheduler.go:193]  "msg"="Updating all jobs info"  "scheduler"="default"
I0722 00:56:05.880876   23824 afsl.go:65]  "msg"="Finished scheduling"  "algorithm"="AFS-L" "freeGpu"=0 "result"={"tf2-keras-cifar10-inceptionv3-elastic-20210722-121943":0,"tf2-keras-cifar10-inceptionv3-elastic-20210722-122034":0,"tf2-keras-cifar10-inceptionv3-elastic-20210722-122250":1,"tf2-keras-cifar10-inceptionv3-elastic-20210722-122354":1,"tf2-keras-cifar10-inceptionv3-elastic-20210722-122611":1,"tf2-keras-cifar10-inceptionv3-elastic-20210722-122710":1,"tf2-keras-cifar10-resnet50-elastic-20210722-122945":1,"tf2-keras-cifar10-resnet50-elastic-20210722-123011":1,"tf2-keras-transformer-elastic-20210722-122149":1,"tf2-keras-transformer-elastic-20210722-122215":1,"tf2-keras-transformer-elastic-20210722-122421":1,"tf2-keras-transformer-elastic-20210722-122647":1,"tf2-keras-transformer-elastic-20210722-122826":1,"tf2-keras-transformer-elastic-20210722-123039":1} "scheduler"="default"
I0722 00:56:05.881272   23824 scheduler.go:384]  "msg"="Trying to delete multiple training jobs"  "jobs"=[] "scheduler"="default"
I0722 00:56:05.881587   23824 scheduler.go:342]  "msg"="Trying to scale multiple training jobs"  "jobs"=[] "scheduler"="default"
I0722 00:56:05.881877   23824 scheduler.go:292]  "msg"="Trying to start multiple training jobs"  "jobs"=["tf2-keras-cifar10-inceptionv3-elastic-20210722-122250"] "scheduler"="default"
I0722 00:56:05.892593   23824 scheduler.go:342]  "msg"="Trying to scale multiple training jobs"  "jobs"=[] "scheduler"="default"
I0722 00:56:05.896960   23824 placement_manager.go:166]  "msg"="Started job placements adjustment"  "scheduler"="default"
I0722 00:56:05.897039   23824 placement_manager.go:192]  "msg"="Releasing slots"  "jobs"={"tf2-keras-cifar10-inceptionv3-elastic-20210722-122354":{},"tf2-keras-cifar10-inceptionv3-elastic-20210722-122611":{},"tf2-keras-cifar10-inceptionv3-elastic-20210722-122710":{},"tf2-keras-cifar10-resnet50-elastic-20210722-122945":{},"tf2-keras-cifar10-resnet50-elastic-20210722-123011":{},"tf2-keras-cifar10-vgg16-elastic-20210722-122906":{},"tf2-keras-transformer-elastic-20210722-122149":{},"tf2-keras-transformer-elastic-20210722-122215":{},"tf2-keras-transformer-elastic-20210722-122421":{},"tf2-keras-transformer-elastic-20210722-122647":{},"tf2-keras-transformer-elastic-20210722-122826":{},"tf2-keras-transformer-elastic-20210722-123039":{}} "nodes"={"gpu3":{},"gpu4":{},"gpu5":{}} "scheduler"="default"
I0722 00:56:05.897107   23824 placement_manager.go:250]  "msg"="Released slots"  "jobs"={"tf2-keras-cifar10-inceptionv3-elastic-20210722-122354":{},"tf2-keras-cifar10-inceptionv3-elastic-20210722-122611":{},"tf2-keras-cifar10-inceptionv3-elastic-20210722-122710":{},"tf2-keras-cifar10-resnet50-elastic-20210722-122945":{},"tf2-keras-cifar10-resnet50-elastic-20210722-123011":{},"tf2-keras-cifar10-vgg16-elastic-20210722-122906":{},"tf2-keras-transformer-elastic-20210722-122149":{},"tf2-keras-transformer-elastic-20210722-122215":{},"tf2-keras-transformer-elastic-20210722-122421":{},"tf2-keras-transformer-elastic-20210722-122647":{},"tf2-keras-transformer-elastic-20210722-122826":{},"tf2-keras-transformer-elastic-20210722-123039":{}} "nodes"={"gpu3":{},"gpu4":{},"gpu5":{}} "scheduler"="default"
I0722 00:56:05.897444   23824 placement_manager.go:305]  "msg"="Found best-fit"  "crossNode"=0 "nodes"=[{},{},{}] "requests"=[{},{},{},{},{},{},{},{},{},{},{},{},{},{},{},{},{},{},{},{},{},{},{},{},{},{},{},{}] "scheduler"="default"
I0722 00:56:05.897746   23824 placement_manager.go:339]  "msg"="nodeStates updated"  "new"={"gpu3":{},"gpu4":{},"gpu5":{}} "old"={"gpu3":{},"gpu4":{},"gpu5":{}} "scheduler"="default" "score"=5
I0722 00:56:05.898045   23824 placement_manager.go:387]  "msg"="jobStates updated"  "new"={"tf2-keras-cifar10-inceptionv3-elastic-20210722-122250":{},"tf2-keras-cifar10-inceptionv3-elastic-20210722-122354":{},"tf2-keras-cifar10-inceptionv3-elastic-20210722-122611":{},"tf2-keras-cifar10-inceptionv3-elastic-20210722-122710":{},"tf2-keras-cifar10-resnet50-elastic-20210722-122945":{},"tf2-keras-cifar10-resnet50-elastic-20210722-123011":{},"tf2-keras-transformer-elastic-20210722-122149":{},"tf2-keras-transformer-elastic-20210722-122215":{},"tf2-keras-transformer-elastic-20210722-122421":{},"tf2-keras-transformer-elastic-20210722-122647":{},"tf2-keras-transformer-elastic-20210722-122826":{},"tf2-keras-transformer-elastic-20210722-123039":{}} "old"={"tf2-keras-cifar10-inceptionv3-elastic-20210722-122354":{},"tf2-keras-cifar10-inceptionv3-elastic-20210722-122611":{},"tf2-keras-cifar10-inceptionv3-elastic-20210722-122710":{},"tf2-keras-cifar10-resnet50-elastic-20210722-122945":{},"tf2-keras-cifar10-resnet50-elastic-20210722-123011":{},"tf2-keras-cifar10-vgg16-elastic-20210722-122906":{},"tf2-keras-transformer-elastic-20210722-122149":{},"tf2-keras-transformer-elastic-20210722-122215":{},"tf2-keras-transformer-elastic-20210722-122421":{},"tf2-keras-transformer-elastic-20210722-122647":{},"tf2-keras-transformer-elastic-20210722-122826":{},"tf2-keras-transformer-elastic-20210722-123039":{}} "scheduler"="default"
I0722 00:56:05.898461   23824 placement_manager.go:434]  "msg"="podNodeName updated"  "launchersToDelete"=6 "new"={"tf2-keras-cifar10-inceptionv3-elastic-20210722-122250-worker-0":"gpu3","tf2-keras-cifar10-inceptionv3-elastic-20210722-122354-worker-0":"gpu5","tf2-keras-cifar10-inceptionv3-elastic-20210722-122611-worker-0":"gpu3","tf2-keras-cifar10-inceptionv3-elastic-20210722-122710-worker-0":"gpu5","tf2-keras-cifar10-resnet50-elastic-20210722-122945-worker-0":"gpu5","tf2-keras-cifar10-resnet50-elastic-20210722-123011-worker-0":"gpu3","tf2-keras-transformer-elastic-20210722-122149-worker-0":"gpu4","tf2-keras-transformer-elastic-20210722-122215-worker-0":"gpu4","tf2-keras-transformer-elastic-20210722-122421-worker-0":"gpu4","tf2-keras-transformer-elastic-20210722-122647-worker-0":"gpu4","tf2-keras-transformer-elastic-20210722-122826-worker-0":"gpu5","tf2-keras-transformer-elastic-20210722-123039-worker-0":"gpu3"} "old"={"tf2-keras-cifar10-inceptionv3-elastic-20210722-122354-worker-0":"gpu3","tf2-keras-cifar10-inceptionv3-elastic-20210722-122611-worker-0":"gpu5","tf2-keras-cifar10-inceptionv3-elastic-20210722-122710-worker-0":"gpu5","tf2-keras-cifar10-resnet50-elastic-20210722-122945-worker-0":"gpu4","tf2-keras-cifar10-resnet50-elastic-20210722-123011-worker-0":"gpu3","tf2-keras-cifar10-vgg16-elastic-20210722-122906-worker-0":"gpu5","tf2-keras-transformer-elastic-20210722-122149-worker-0":"gpu4","tf2-keras-transformer-elastic-20210722-122215-worker-0":"gpu5","tf2-keras-transformer-elastic-20210722-122421-worker-0":"gpu3","tf2-keras-transformer-elastic-20210722-122647-worker-0":"gpu4","tf2-keras-transformer-elastic-20210722-122826-worker-0":"gpu4","tf2-keras-transformer-elastic-20210722-123039-worker-0":"gpu3"} "scheduler"="default" "workersToDelete"=6
I0722 00:56:05.898778   23824 placement_manager.go:451]  "msg"="Deleting pod that need migration"  "podName"="tf2-keras-transformer-elastic-20210722-122826-worker-0" "scheduler"="default"
I0722 00:56:05.910904   23824 placement_manager.go:451]  "msg"="Deleting pod that need migration"  "podName"="tf2-keras-transformer-elastic-20210722-122826-launcher" "scheduler"="default"
I0722 00:56:05.916001   23824 placement_manager.go:451]  "msg"="Deleting pod that need migration"  "podName"="tf2-keras-cifar10-resnet50-elastic-20210722-122945-worker-0" "scheduler"="default"
I0722 00:56:05.950961   23824 placement_manager.go:451]  "msg"="Deleting pod that need migration"  "podName"="tf2-keras-cifar10-resnet50-elastic-20210722-122945-launcher" "scheduler"="default"
I0722 00:56:05.958182   23824 placement_manager.go:451]  "msg"="Deleting pod that need migration"  "podName"="tf2-keras-transformer-elastic-20210722-122421-worker-0" "scheduler"="default"
I0722 00:56:05.961770   23824 placement_manager.go:451]  "msg"="Deleting pod that need migration"  "podName"="tf2-keras-transformer-elastic-20210722-122421-launcher" "scheduler"="default"
I0722 00:56:05.965704   23824 placement_manager.go:451]  "msg"="Deleting pod that need migration"  "podName"="tf2-keras-transformer-elastic-20210722-122215-worker-0" "scheduler"="default"
I0722 00:56:05.970083   23824 placement_manager.go:451]  "msg"="Deleting pod that need migration"  "podName"="tf2-keras-transformer-elastic-20210722-122215-launcher" "scheduler"="default"
I0722 00:56:05.974229   23824 placement_manager.go:451]  "msg"="Deleting pod that need migration"  "podName"="tf2-keras-cifar10-inceptionv3-elastic-20210722-122611-worker-0" "scheduler"="default"
I0722 00:56:05.977786   23824 placement_manager.go:451]  "msg"="Deleting pod that need migration"  "podName"="tf2-keras-cifar10-inceptionv3-elastic-20210722-122611-launcher" "scheduler"="default"
I0722 00:56:05.984748   23824 placement_manager.go:451]  "msg"="Deleting pod that need migration"  "podName"="tf2-keras-cifar10-inceptionv3-elastic-20210722-122354-worker-0" "scheduler"="default"
I0722 00:56:06.103166   23824 placement_manager.go:451]  "msg"="Deleting pod that need migration"  "podName"="tf2-keras-cifar10-inceptionv3-elastic-20210722-122354-launcher" "scheduler"="default"
I0722 00:56:06.300614   23824 placement_manager.go:147]  "msg"="Adding toleration to pod"  "podName"="tf2-keras-cifar10-inceptionv3-elastic-20210722-122250-worker-0" "scheduler"="default" "toleration"={"key":"celeste/hostname","operator":"Equal","value":"gpu3","effect":"NoExecute"}
I0722 00:56:06.307386   23824 placement_manager.go:183]  "msg"="Finished job placements adjustment"  "scheduler"="default"
I0722 00:56:06.307723   23824 scheduler.go:182]  "msg"="Finished resched"  "scheduler"="default"
I0722 00:56:06.705727   23824 placement_manager.go:147]  "msg"="Adding toleration to pod"  "podName"="tf2-keras-cifar10-inceptionv3-elastic-20210722-122250-launcher" "scheduler"="default" "toleration"={"key":"celeste/hostname","operator":"Exists","effect":"NoExecute"}
I0722 00:56:13.431216   23824 placement_manager.go:147]  "msg"="Adding toleration to pod"  "podName"="tf2-keras-transformer-elastic-20210722-122421-worker-0" "scheduler"="default" "toleration"={"key":"celeste/hostname","operator":"Equal","value":"gpu4","effect":"NoExecute"}
I0722 00:56:13.465406   23824 placement_manager.go:147]  "msg"="Adding toleration to pod"  "podName"="tf2-keras-cifar10-inceptionv3-elastic-20210722-122354-worker-0" "scheduler"="default" "toleration"={"key":"celeste/hostname","operator":"Equal","value":"gpu5","effect":"NoExecute"}
I0722 00:56:13.474664   23824 placement_manager.go:147]  "msg"="Adding toleration to pod"  "podName"="tf2-keras-cifar10-inceptionv3-elastic-20210722-122354-launcher" "scheduler"="default" "toleration"={"key":"celeste/hostname","operator":"Exists","effect":"NoExecute"}
I0722 00:56:14.963718   23824 placement_manager.go:147]  "msg"="Adding toleration to pod"  "podName"="tf2-keras-cifar10-resnet50-elastic-20210722-122945-launcher" "scheduler"="default" "toleration"={"key":"celeste/hostname","operator":"Exists","effect":"NoExecute"}
I0722 00:56:15.352566   23824 placement_manager.go:147]  "msg"="Adding toleration to pod"  "podName"="tf2-keras-transformer-elastic-20210722-122826-worker-0" "scheduler"="default" "toleration"={"key":"celeste/hostname","operator":"Equal","value":"gpu5","effect":"NoExecute"}
I0722 00:56:15.955864   23824 placement_manager.go:147]  "msg"="Adding toleration to pod"  "podName"="tf2-keras-transformer-elastic-20210722-122826-launcher" "scheduler"="default" "toleration"={"key":"celeste/hostname","operator":"Exists","effect":"NoExecute"}
I0722 00:56:16.355136   23824 placement_manager.go:147]  "msg"="Adding toleration to pod"  "podName"="tf2-keras-cifar10-resnet50-elastic-20210722-122945-worker-0" "scheduler"="default" "toleration"={"key":"celeste/hostname","operator":"Equal","value":"gpu5","effect":"NoExecute"}
I0722 00:56:16.758905   23824 placement_manager.go:147]  "msg"="Adding toleration to pod"  "podName"="tf2-keras-cifar10-inceptionv3-elastic-20210722-122611-launcher" "scheduler"="default" "toleration"={"key":"celeste/hostname","operator":"Exists","effect":"NoExecute"}
I0722 00:56:20.355396   23824 placement_manager.go:147]  "msg"="Adding toleration to pod"  "podName"="tf2-keras-transformer-elastic-20210722-122421-launcher" "scheduler"="default" "toleration"={"key":"celeste/hostname","operator":"Exists","effect":"NoExecute"}
I0722 00:56:30.351254   23824 placement_manager.go:147]  "msg"="Adding toleration to pod"  "podName"="tf2-keras-transformer-elastic-20210722-122215-launcher" "scheduler"="default" "toleration"={"key":"celeste/hostname","operator":"Exists","effect":"NoExecute"}
I0722 00:56:31.553992   23824 placement_manager.go:147]  "msg"="Adding toleration to pod"  "podName"="tf2-keras-cifar10-inceptionv3-elastic-20210722-122611-worker-0" "scheduler"="default" "toleration"={"key":"celeste/hostname","operator":"Equal","value":"gpu3","effect":"NoExecute"}
I0722 00:56:32.346158   23824 placement_manager.go:147]  "msg"="Adding toleration to pod"  "podName"="tf2-keras-transformer-elastic-20210722-122215-worker-0" "scheduler"="default" "toleration"={"key":"celeste/hostname","operator":"Equal","value":"gpu4","effect":"NoExecute"}
I0722 00:58:43.962800   23824 scheduler.go:474]  "msg"="Training job completed"  "elaspedTotalSeconds"=1708.045146918 "gpuTotalSeconds"=1620.169578042 "job"="tf2-keras-cifar10-resnet50-elastic-20210722-123011" "ranTotalSeconds"=1620.169578042 "scheduler"="default" "waitedTotalSeconds"=87.875568876
I0722 00:58:43.962951   23824 scheduler.go:135]  "msg"="Received resched event, may be blocked because of rate limit"  "blockedUntil"="2021-07-22T00:58:06.308107348+08:00" "lastResched"="2021-07-22T00:56:06.308107348+08:00" "received"="2021-07-22T00:58:43.962845021+08:00" "scheduler"="default"
I0722 00:58:43.963539   23824 scheduler.go:159]  "msg"="Started resched"  "scheduler"="default"
I0722 00:58:43.963619   23824 scheduler.go:193]  "msg"="Updating all jobs info"  "scheduler"="default"
I0722 00:58:43.973906   23824 afsl.go:65]  "msg"="Finished scheduling"  "algorithm"="AFS-L" "freeGpu"=0 "result"={"tf2-keras-cifar10-inceptionv3-elastic-20210722-121943":0,"tf2-keras-cifar10-inceptionv3-elastic-20210722-122034":1,"tf2-keras-cifar10-inceptionv3-elastic-20210722-122250":1,"tf2-keras-cifar10-inceptionv3-elastic-20210722-122354":1,"tf2-keras-cifar10-inceptionv3-elastic-20210722-122611":1,"tf2-keras-cifar10-inceptionv3-elastic-20210722-122710":1,"tf2-keras-cifar10-resnet50-elastic-20210722-122945":1,"tf2-keras-transformer-elastic-20210722-122149":1,"tf2-keras-transformer-elastic-20210722-122215":1,"tf2-keras-transformer-elastic-20210722-122421":1,"tf2-keras-transformer-elastic-20210722-122647":1,"tf2-keras-transformer-elastic-20210722-122826":1,"tf2-keras-transformer-elastic-20210722-123039":1} "scheduler"="default"
I0722 00:58:43.974247   23824 scheduler.go:384]  "msg"="Trying to delete multiple training jobs"  "jobs"=[] "scheduler"="default"
I0722 00:58:43.974499   23824 scheduler.go:342]  "msg"="Trying to scale multiple training jobs"  "jobs"=[] "scheduler"="default"
I0722 00:58:43.974696   23824 scheduler.go:292]  "msg"="Trying to start multiple training jobs"  "jobs"=["tf2-keras-cifar10-inceptionv3-elastic-20210722-122034"] "scheduler"="default"
I0722 00:58:43.985710   23824 scheduler.go:342]  "msg"="Trying to scale multiple training jobs"  "jobs"=[] "scheduler"="default"
I0722 00:58:43.989352   23824 placement_manager.go:166]  "msg"="Started job placements adjustment"  "scheduler"="default"
I0722 00:58:43.989426   23824 placement_manager.go:192]  "msg"="Releasing slots"  "jobs"={"tf2-keras-cifar10-inceptionv3-elastic-20210722-122250":{},"tf2-keras-cifar10-inceptionv3-elastic-20210722-122354":{},"tf2-keras-cifar10-inceptionv3-elastic-20210722-122611":{},"tf2-keras-cifar10-inceptionv3-elastic-20210722-122710":{},"tf2-keras-cifar10-resnet50-elastic-20210722-122945":{},"tf2-keras-cifar10-resnet50-elastic-20210722-123011":{},"tf2-keras-transformer-elastic-20210722-122149":{},"tf2-keras-transformer-elastic-20210722-122215":{},"tf2-keras-transformer-elastic-20210722-122421":{},"tf2-keras-transformer-elastic-20210722-122647":{},"tf2-keras-transformer-elastic-20210722-122826":{},"tf2-keras-transformer-elastic-20210722-123039":{}} "nodes"={"gpu3":{},"gpu4":{},"gpu5":{}} "scheduler"="default"
I0722 00:58:43.989502   23824 placement_manager.go:250]  "msg"="Released slots"  "jobs"={"tf2-keras-cifar10-inceptionv3-elastic-20210722-122250":{},"tf2-keras-cifar10-inceptionv3-elastic-20210722-122354":{},"tf2-keras-cifar10-inceptionv3-elastic-20210722-122611":{},"tf2-keras-cifar10-inceptionv3-elastic-20210722-122710":{},"tf2-keras-cifar10-resnet50-elastic-20210722-122945":{},"tf2-keras-cifar10-resnet50-elastic-20210722-123011":{},"tf2-keras-transformer-elastic-20210722-122149":{},"tf2-keras-transformer-elastic-20210722-122215":{},"tf2-keras-transformer-elastic-20210722-122421":{},"tf2-keras-transformer-elastic-20210722-122647":{},"tf2-keras-transformer-elastic-20210722-122826":{},"tf2-keras-transformer-elastic-20210722-123039":{}} "nodes"={"gpu3":{},"gpu4":{},"gpu5":{}} "scheduler"="default"
I0722 00:58:43.989940   23824 placement_manager.go:305]  "msg"="Found best-fit"  "crossNode"=0 "nodes"=[{},{},{}] "requests"=[{},{},{},{},{},{},{},{},{},{},{},{},{},{},{},{},{},{},{},{},{},{},{},{},{},{}] "scheduler"="default"
I0722 00:58:43.990223   23824 placement_manager.go:339]  "msg"="nodeStates updated"  "new"={"gpu3":{},"gpu4":{},"gpu5":{}} "old"={"gpu3":{},"gpu4":{},"gpu5":{}} "scheduler"="default" "score"=5
I0722 00:58:43.990512   23824 placement_manager.go:387]  "msg"="jobStates updated"  "new"={"tf2-keras-cifar10-inceptionv3-elastic-20210722-122034":{},"tf2-keras-cifar10-inceptionv3-elastic-20210722-122250":{},"tf2-keras-cifar10-inceptionv3-elastic-20210722-122354":{},"tf2-keras-cifar10-inceptionv3-elastic-20210722-122611":{},"tf2-keras-cifar10-inceptionv3-elastic-20210722-122710":{},"tf2-keras-cifar10-resnet50-elastic-20210722-122945":{},"tf2-keras-transformer-elastic-20210722-122149":{},"tf2-keras-transformer-elastic-20210722-122215":{},"tf2-keras-transformer-elastic-20210722-122421":{},"tf2-keras-transformer-elastic-20210722-122647":{},"tf2-keras-transformer-elastic-20210722-122826":{},"tf2-keras-transformer-elastic-20210722-123039":{}} "old"={"tf2-keras-cifar10-inceptionv3-elastic-20210722-122250":{},"tf2-keras-cifar10-inceptionv3-elastic-20210722-122354":{},"tf2-keras-cifar10-inceptionv3-elastic-20210722-122611":{},"tf2-keras-cifar10-inceptionv3-elastic-20210722-122710":{},"tf2-keras-cifar10-resnet50-elastic-20210722-122945":{},"tf2-keras-cifar10-resnet50-elastic-20210722-123011":{},"tf2-keras-transformer-elastic-20210722-122149":{},"tf2-keras-transformer-elastic-20210722-122215":{},"tf2-keras-transformer-elastic-20210722-122421":{},"tf2-keras-transformer-elastic-20210722-122647":{},"tf2-keras-transformer-elastic-20210722-122826":{},"tf2-keras-transformer-elastic-20210722-123039":{}} "scheduler"="default"
I0722 00:58:43.990840   23824 placement_manager.go:434]  "msg"="podNodeName updated"  "launchersToDelete"=6 "new"={"tf2-keras-cifar10-inceptionv3-elastic-20210722-122034-worker-0":"gpu3","tf2-keras-cifar10-inceptionv3-elastic-20210722-122250-worker-0":"gpu5","tf2-keras-cifar10-inceptionv3-elastic-20210722-122354-worker-0":"gpu4","tf2-keras-cifar10-inceptionv3-elastic-20210722-122611-worker-0":"gpu4","tf2-keras-cifar10-inceptionv3-elastic-20210722-122710-worker-0":"gpu5","tf2-keras-cifar10-resnet50-elastic-20210722-122945-worker-0":"gpu5","tf2-keras-transformer-elastic-20210722-122149-worker-0":"gpu3","tf2-keras-transformer-elastic-20210722-122215-worker-0":"gpu5","tf2-keras-transformer-elastic-20210722-122421-worker-0":"gpu4","tf2-keras-transformer-elastic-20210722-122647-worker-0":"gpu4","tf2-keras-transformer-elastic-20210722-122826-worker-0":"gpu3","tf2-keras-transformer-elastic-20210722-123039-worker-0":"gpu3"} "old"={"tf2-keras-cifar10-inceptionv3-elastic-20210722-122250-worker-0":"gpu3","tf2-keras-cifar10-inceptionv3-elastic-20210722-122354-worker-0":"gpu5","tf2-keras-cifar10-inceptionv3-elastic-20210722-122611-worker-0":"gpu3","tf2-keras-cifar10-inceptionv3-elastic-20210722-122710-worker-0":"gpu5","tf2-keras-cifar10-resnet50-elastic-20210722-122945-worker-0":"gpu5","tf2-keras-cifar10-resnet50-elastic-20210722-123011-worker-0":"gpu3","tf2-keras-transformer-elastic-20210722-122149-worker-0":"gpu4","tf2-keras-transformer-elastic-20210722-122215-worker-0":"gpu4","tf2-keras-transformer-elastic-20210722-122421-worker-0":"gpu4","tf2-keras-transformer-elastic-20210722-122647-worker-0":"gpu4","tf2-keras-transformer-elastic-20210722-122826-worker-0":"gpu5","tf2-keras-transformer-elastic-20210722-123039-worker-0":"gpu3"} "scheduler"="default" "workersToDelete"=6
I0722 00:58:43.991199   23824 placement_manager.go:451]  "msg"="Deleting pod that need migration"  "podName"="tf2-keras-cifar10-inceptionv3-elastic-20210722-122611-worker-0" "scheduler"="default"
I0722 00:58:43.995294   23824 placement_manager.go:451]  "msg"="Deleting pod that need migration"  "podName"="tf2-keras-cifar10-inceptionv3-elastic-20210722-122611-launcher" "scheduler"="default"
I0722 00:58:44.000595   23824 placement_manager.go:451]  "msg"="Deleting pod that need migration"  "podName"="tf2-keras-transformer-elastic-20210722-122149-worker-0" "scheduler"="default"
I0722 00:58:44.005505   23824 placement_manager.go:451]  "msg"="Deleting pod that need migration"  "podName"="tf2-keras-transformer-elastic-20210722-122149-launcher" "scheduler"="default"
I0722 00:58:44.013389   23824 placement_manager.go:451]  "msg"="Deleting pod that need migration"  "podName"="tf2-keras-transformer-elastic-20210722-122826-worker-0" "scheduler"="default"
I0722 00:58:44.018238   23824 placement_manager.go:451]  "msg"="Deleting pod that need migration"  "podName"="tf2-keras-transformer-elastic-20210722-122826-launcher" "scheduler"="default"
I0722 00:58:44.023991   23824 placement_manager.go:451]  "msg"="Deleting pod that need migration"  "podName"="tf2-keras-cifar10-inceptionv3-elastic-20210722-122250-worker-0" "scheduler"="default"
I0722 00:58:44.027336   23824 placement_manager.go:451]  "msg"="Deleting pod that need migration"  "podName"="tf2-keras-cifar10-inceptionv3-elastic-20210722-122250-launcher" "scheduler"="default"
I0722 00:58:44.031267   23824 placement_manager.go:451]  "msg"="Deleting pod that need migration"  "podName"="tf2-keras-transformer-elastic-20210722-122215-worker-0" "scheduler"="default"
I0722 00:58:44.034864   23824 placement_manager.go:451]  "msg"="Deleting pod that need migration"  "podName"="tf2-keras-transformer-elastic-20210722-122215-launcher" "scheduler"="default"
I0722 00:58:44.039138   23824 placement_manager.go:451]  "msg"="Deleting pod that need migration"  "podName"="tf2-keras-cifar10-inceptionv3-elastic-20210722-122354-worker-0" "scheduler"="default"
I0722 00:58:44.197285   23824 placement_manager.go:451]  "msg"="Deleting pod that need migration"  "podName"="tf2-keras-cifar10-inceptionv3-elastic-20210722-122354-launcher" "scheduler"="default"
I0722 00:58:44.397588   23824 placement_manager.go:183]  "msg"="Finished job placements adjustment"  "scheduler"="default"
I0722 00:58:44.398064   23824 scheduler.go:182]  "msg"="Finished resched"  "scheduler"="default"
I0722 00:58:44.560376   23824 placement_manager.go:147]  "msg"="Adding toleration to pod"  "podName"="tf2-keras-cifar10-inceptionv3-elastic-20210722-122034-worker-0" "scheduler"="default" "toleration"={"key":"celeste/hostname","operator":"Equal","value":"gpu3","effect":"NoExecute"}
I0722 00:58:44.958825   23824 placement_manager.go:147]  "msg"="Adding toleration to pod"  "podName"="tf2-keras-cifar10-inceptionv3-elastic-20210722-122034-launcher" "scheduler"="default" "toleration"={"key":"celeste/hostname","operator":"Exists","effect":"NoExecute"}
I0722 00:58:51.448647   23824 placement_manager.go:147]  "msg"="Adding toleration to pod"  "podName"="tf2-keras-transformer-elastic-20210722-122149-worker-0" "scheduler"="default" "toleration"={"key":"celeste/hostname","operator":"Equal","value":"gpu3","effect":"NoExecute"}
I0722 00:58:51.485822   23824 placement_manager.go:147]  "msg"="Adding toleration to pod"  "podName"="tf2-keras-transformer-elastic-20210722-122149-launcher" "scheduler"="default" "toleration"={"key":"celeste/hostname","operator":"Exists","effect":"NoExecute"}
I0722 00:58:51.495391   23824 placement_manager.go:147]  "msg"="Adding toleration to pod"  "podName"="tf2-keras-transformer-elastic-20210722-122215-worker-0" "scheduler"="default" "toleration"={"key":"celeste/hostname","operator":"Equal","value":"gpu5","effect":"NoExecute"}
I0722 00:58:52.599221   23824 placement_manager.go:147]  "msg"="Adding toleration to pod"  "podName"="tf2-keras-cifar10-inceptionv3-elastic-20210722-122354-worker-0" "scheduler"="default" "toleration"={"key":"celeste/hostname","operator":"Equal","value":"gpu4","effect":"NoExecute"}
I0722 00:58:53.002216   23824 placement_manager.go:147]  "msg"="Adding toleration to pod"  "podName"="tf2-keras-transformer-elastic-20210722-122215-launcher" "scheduler"="default" "toleration"={"key":"celeste/hostname","operator":"Exists","effect":"NoExecute"}
I0722 00:58:54.406252   23824 placement_manager.go:147]  "msg"="Adding toleration to pod"  "podName"="tf2-keras-transformer-elastic-20210722-122826-worker-0" "scheduler"="default" "toleration"={"key":"celeste/hostname","operator":"Equal","value":"gpu3","effect":"NoExecute"}
I0722 00:58:54.585503   23824 placement_manager.go:147]  "msg"="Adding toleration to pod"  "podName"="tf2-keras-cifar10-inceptionv3-elastic-20210722-122611-launcher" "scheduler"="default" "toleration"={"key":"celeste/hostname","operator":"Exists","effect":"NoExecute"}
I0722 00:58:54.801616   23824 placement_manager.go:147]  "msg"="Adding toleration to pod"  "podName"="tf2-keras-cifar10-inceptionv3-elastic-20210722-122250-launcher" "scheduler"="default" "toleration"={"key":"celeste/hostname","operator":"Exists","effect":"NoExecute"}
I0722 00:58:56.012482   23824 placement_manager.go:147]  "msg"="Adding toleration to pod"  "podName"="tf2-keras-cifar10-inceptionv3-elastic-20210722-122354-launcher" "scheduler"="default" "toleration"={"key":"celeste/hostname","operator":"Exists","effect":"NoExecute"}
I0722 00:58:58.417374   23824 placement_manager.go:147]  "msg"="Adding toleration to pod"  "podName"="tf2-keras-transformer-elastic-20210722-122826-launcher" "scheduler"="default" "toleration"={"key":"celeste/hostname","operator":"Exists","effect":"NoExecute"}
I0722 00:59:00.895141   23824 placement_manager.go:147]  "msg"="Adding toleration to pod"  "podName"="tf2-keras-cifar10-inceptionv3-elastic-20210722-122250-worker-0" "scheduler"="default" "toleration"={"key":"celeste/hostname","operator":"Equal","value":"gpu5","effect":"NoExecute"}
I0722 00:59:01.694163   23824 placement_manager.go:147]  "msg"="Adding toleration to pod"  "podName"="tf2-keras-cifar10-inceptionv3-elastic-20210722-122611-worker-0" "scheduler"="default" "toleration"={"key":"celeste/hostname","operator":"Equal","value":"gpu4","effect":"NoExecute"}
I0722 01:01:10.909806   23824 scheduler.go:474]  "msg"="Training job completed"  "elaspedTotalSeconds"=1884.072538323 "gpuTotalSeconds"=1770.174815803 "job"="tf2-keras-cifar10-resnet50-elastic-20210722-122945" "ranTotalSeconds"=1770.174815803 "scheduler"="default" "waitedTotalSeconds"=113.89772252
I0722 01:01:10.909948   23824 scheduler.go:135]  "msg"="Received resched event, may be blocked because of rate limit"  "blockedUntil"="2021-07-22T01:00:44.398287525+08:00" "lastResched"="2021-07-22T00:58:44.398287525+08:00" "received"="2021-07-22T01:01:10.90983745+08:00" "scheduler"="default"
I0722 01:01:10.915557   23824 scheduler.go:159]  "msg"="Started resched"  "scheduler"="default"
I0722 01:01:10.915619   23824 scheduler.go:193]  "msg"="Updating all jobs info"  "scheduler"="default"
I0722 01:01:10.928048   23824 afsl.go:65]  "msg"="Finished scheduling"  "algorithm"="AFS-L" "freeGpu"=0 "result"={"tf2-keras-cifar10-inceptionv3-elastic-20210722-121943":1,"tf2-keras-cifar10-inceptionv3-elastic-20210722-122034":1,"tf2-keras-cifar10-inceptionv3-elastic-20210722-122250":1,"tf2-keras-cifar10-inceptionv3-elastic-20210722-122354":1,"tf2-keras-cifar10-inceptionv3-elastic-20210722-122611":1,"tf2-keras-cifar10-inceptionv3-elastic-20210722-122710":1,"tf2-keras-transformer-elastic-20210722-122149":1,"tf2-keras-transformer-elastic-20210722-122215":1,"tf2-keras-transformer-elastic-20210722-122421":1,"tf2-keras-transformer-elastic-20210722-122647":1,"tf2-keras-transformer-elastic-20210722-122826":1,"tf2-keras-transformer-elastic-20210722-123039":1} "scheduler"="default"
I0722 01:01:10.931815   23824 scheduler.go:384]  "msg"="Trying to delete multiple training jobs"  "jobs"=[] "scheduler"="default"
I0722 01:01:10.935414   23824 scheduler.go:342]  "msg"="Trying to scale multiple training jobs"  "jobs"=[] "scheduler"="default"
I0722 01:01:10.938529   23824 scheduler.go:292]  "msg"="Trying to start multiple training jobs"  "jobs"=["tf2-keras-cifar10-inceptionv3-elastic-20210722-121943"] "scheduler"="default"
I0722 01:01:10.948787   23824 scheduler.go:342]  "msg"="Trying to scale multiple training jobs"  "jobs"=[] "scheduler"="default"
I0722 01:01:10.955822   23824 placement_manager.go:166]  "msg"="Started job placements adjustment"  "scheduler"="default"
I0722 01:01:10.955874   23824 placement_manager.go:192]  "msg"="Releasing slots"  "jobs"={"tf2-keras-cifar10-inceptionv3-elastic-20210722-122034":{},"tf2-keras-cifar10-inceptionv3-elastic-20210722-122250":{},"tf2-keras-cifar10-inceptionv3-elastic-20210722-122354":{},"tf2-keras-cifar10-inceptionv3-elastic-20210722-122611":{},"tf2-keras-cifar10-inceptionv3-elastic-20210722-122710":{},"tf2-keras-cifar10-resnet50-elastic-20210722-122945":{},"tf2-keras-transformer-elastic-20210722-122149":{},"tf2-keras-transformer-elastic-20210722-122215":{},"tf2-keras-transformer-elastic-20210722-122421":{},"tf2-keras-transformer-elastic-20210722-122647":{},"tf2-keras-transformer-elastic-20210722-122826":{},"tf2-keras-transformer-elastic-20210722-123039":{}} "nodes"={"gpu3":{},"gpu4":{},"gpu5":{}} "scheduler"="default"
I0722 01:01:10.955944   23824 placement_manager.go:250]  "msg"="Released slots"  "jobs"={"tf2-keras-cifar10-inceptionv3-elastic-20210722-122034":{},"tf2-keras-cifar10-inceptionv3-elastic-20210722-122250":{},"tf2-keras-cifar10-inceptionv3-elastic-20210722-122354":{},"tf2-keras-cifar10-inceptionv3-elastic-20210722-122611":{},"tf2-keras-cifar10-inceptionv3-elastic-20210722-122710":{},"tf2-keras-cifar10-resnet50-elastic-20210722-122945":{},"tf2-keras-transformer-elastic-20210722-122149":{},"tf2-keras-transformer-elastic-20210722-122215":{},"tf2-keras-transformer-elastic-20210722-122421":{},"tf2-keras-transformer-elastic-20210722-122647":{},"tf2-keras-transformer-elastic-20210722-122826":{},"tf2-keras-transformer-elastic-20210722-123039":{}} "nodes"={"gpu3":{},"gpu4":{},"gpu5":{}} "scheduler"="default"
I0722 01:01:10.956295   23824 placement_manager.go:305]  "msg"="Found best-fit"  "crossNode"=0 "nodes"=[{},{},{}] "requests"=[{},{},{},{},{},{},{},{},{},{},{},{},{},{},{},{},{},{},{},{},{},{},{},{}] "scheduler"="default"
I0722 01:01:10.956555   23824 placement_manager.go:339]  "msg"="nodeStates updated"  "new"={"gpu3":{},"gpu4":{},"gpu5":{}} "old"={"gpu3":{},"gpu4":{},"gpu5":{}} "scheduler"="default" "score"=5
I0722 01:01:10.956768   23824 placement_manager.go:387]  "msg"="jobStates updated"  "new"={"tf2-keras-cifar10-inceptionv3-elastic-20210722-121943":{},"tf2-keras-cifar10-inceptionv3-elastic-20210722-122034":{},"tf2-keras-cifar10-inceptionv3-elastic-20210722-122250":{},"tf2-keras-cifar10-inceptionv3-elastic-20210722-122354":{},"tf2-keras-cifar10-inceptionv3-elastic-20210722-122611":{},"tf2-keras-cifar10-inceptionv3-elastic-20210722-122710":{},"tf2-keras-transformer-elastic-20210722-122149":{},"tf2-keras-transformer-elastic-20210722-122215":{},"tf2-keras-transformer-elastic-20210722-122421":{},"tf2-keras-transformer-elastic-20210722-122647":{},"tf2-keras-transformer-elastic-20210722-122826":{},"tf2-keras-transformer-elastic-20210722-123039":{}} "old"={"tf2-keras-cifar10-inceptionv3-elastic-20210722-122034":{},"tf2-keras-cifar10-inceptionv3-elastic-20210722-122250":{},"tf2-keras-cifar10-inceptionv3-elastic-20210722-122354":{},"tf2-keras-cifar10-inceptionv3-elastic-20210722-122611":{},"tf2-keras-cifar10-inceptionv3-elastic-20210722-122710":{},"tf2-keras-cifar10-resnet50-elastic-20210722-122945":{},"tf2-keras-transformer-elastic-20210722-122149":{},"tf2-keras-transformer-elastic-20210722-122215":{},"tf2-keras-transformer-elastic-20210722-122421":{},"tf2-keras-transformer-elastic-20210722-122647":{},"tf2-keras-transformer-elastic-20210722-122826":{},"tf2-keras-transformer-elastic-20210722-123039":{}} "scheduler"="default"
I0722 01:01:10.957085   23824 placement_manager.go:434]  "msg"="podNodeName updated"  "launchersToDelete"=6 "new"={"tf2-keras-cifar10-inceptionv3-elastic-20210722-121943-worker-0":"gpu3","tf2-keras-cifar10-inceptionv3-elastic-20210722-122034-worker-0":"gpu4","tf2-keras-cifar10-inceptionv3-elastic-20210722-122250-worker-0":"gpu4","tf2-keras-cifar10-inceptionv3-elastic-20210722-122354-worker-0":"gpu5","tf2-keras-cifar10-inceptionv3-elastic-20210722-122611-worker-0":"gpu4","tf2-keras-cifar10-inceptionv3-elastic-20210722-122710-worker-0":"gpu3","tf2-keras-transformer-elastic-20210722-122149-worker-0":"gpu3","tf2-keras-transformer-elastic-20210722-122215-worker-0":"gpu5","tf2-keras-transformer-elastic-20210722-122421-worker-0":"gpu5","tf2-keras-transformer-elastic-20210722-122647-worker-0":"gpu4","tf2-keras-transformer-elastic-20210722-122826-worker-0":"gpu5","tf2-keras-transformer-elastic-20210722-123039-worker-0":"gpu3"} "old"={"tf2-keras-cifar10-inceptionv3-elastic-20210722-122034-worker-0":"gpu3","tf2-keras-cifar10-inceptionv3-elastic-20210722-122250-worker-0":"gpu5","tf2-keras-cifar10-inceptionv3-elastic-20210722-122354-worker-0":"gpu4","tf2-keras-cifar10-inceptionv3-elastic-20210722-122611-worker-0":"gpu4","tf2-keras-cifar10-inceptionv3-elastic-20210722-122710-worker-0":"gpu5","tf2-keras-cifar10-resnet50-elastic-20210722-122945-worker-0":"gpu5","tf2-keras-transformer-elastic-20210722-122149-worker-0":"gpu3","tf2-keras-transformer-elastic-20210722-122215-worker-0":"gpu5","tf2-keras-transformer-elastic-20210722-122421-worker-0":"gpu4","tf2-keras-transformer-elastic-20210722-122647-worker-0":"gpu4","tf2-keras-transformer-elastic-20210722-122826-worker-0":"gpu3","tf2-keras-transformer-elastic-20210722-123039-worker-0":"gpu3"} "scheduler"="default" "workersToDelete"=6
I0722 01:01:10.957346   23824 placement_manager.go:451]  "msg"="Deleting pod that need migration"  "podName"="tf2-keras-cifar10-inceptionv3-elastic-20210722-122034-worker-0" "scheduler"="default"
I0722 01:01:10.961568   23824 placement_manager.go:451]  "msg"="Deleting pod that need migration"  "podName"="tf2-keras-cifar10-inceptionv3-elastic-20210722-122034-launcher" "scheduler"="default"
I0722 01:01:10.965416   23824 placement_manager.go:451]  "msg"="Deleting pod that need migration"  "podName"="tf2-keras-transformer-elastic-20210722-122421-worker-0" "scheduler"="default"
I0722 01:01:10.970808   23824 placement_manager.go:451]  "msg"="Deleting pod that need migration"  "podName"="tf2-keras-transformer-elastic-20210722-122421-launcher" "scheduler"="default"
I0722 01:01:10.978815   23824 placement_manager.go:451]  "msg"="Deleting pod that need migration"  "podName"="tf2-keras-cifar10-inceptionv3-elastic-20210722-122354-worker-0" "scheduler"="default"
I0722 01:01:10.984827   23824 placement_manager.go:451]  "msg"="Deleting pod that need migration"  "podName"="tf2-keras-cifar10-inceptionv3-elastic-20210722-122354-launcher" "scheduler"="default"
I0722 01:01:10.987898   23824 placement_manager.go:451]  "msg"="Deleting pod that need migration"  "podName"="tf2-keras-transformer-elastic-20210722-122826-worker-0" "scheduler"="default"
I0722 01:01:10.991020   23824 placement_manager.go:451]  "msg"="Deleting pod that need migration"  "podName"="tf2-keras-transformer-elastic-20210722-122826-launcher" "scheduler"="default"
I0722 01:01:10.994254   23824 placement_manager.go:451]  "msg"="Deleting pod that need migration"  "podName"="tf2-keras-cifar10-inceptionv3-elastic-20210722-122250-worker-0" "scheduler"="default"
I0722 01:01:10.998027   23824 placement_manager.go:451]  "msg"="Deleting pod that need migration"  "podName"="tf2-keras-cifar10-inceptionv3-elastic-20210722-122250-launcher" "scheduler"="default"
I0722 01:01:11.002035   23824 placement_manager.go:451]  "msg"="Deleting pod that need migration"  "podName"="tf2-keras-cifar10-inceptionv3-elastic-20210722-122710-worker-0" "scheduler"="default"
I0722 01:01:11.162224   23824 placement_manager.go:451]  "msg"="Deleting pod that need migration"  "podName"="tf2-keras-cifar10-inceptionv3-elastic-20210722-122710-launcher" "scheduler"="default"
I0722 01:01:11.295076   23824 placement_manager.go:147]  "msg"="Adding toleration to pod"  "podName"="tf2-keras-cifar10-inceptionv3-elastic-20210722-121943-worker-0" "scheduler"="default" "toleration"={"key":"celeste/hostname","operator":"Equal","value":"gpu3","effect":"NoExecute"}
I0722 01:01:11.363493   23824 placement_manager.go:183]  "msg"="Finished job placements adjustment"  "scheduler"="default"
I0722 01:01:11.363760   23824 scheduler.go:182]  "msg"="Finished resched"  "scheduler"="default"
I0722 01:01:11.766716   23824 placement_manager.go:147]  "msg"="Adding toleration to pod"  "podName"="tf2-keras-cifar10-inceptionv3-elastic-20210722-121943-launcher" "scheduler"="default" "toleration"={"key":"celeste/hostname","operator":"Exists","effect":"NoExecute"}
I0722 01:01:18.917732   23824 placement_manager.go:147]  "msg"="Adding toleration to pod"  "podName"="tf2-keras-transformer-elastic-20210722-122421-launcher" "scheduler"="default" "toleration"={"key":"celeste/hostname","operator":"Exists","effect":"NoExecute"}
I0722 01:01:24.600732   23824 placement_manager.go:147]  "msg"="Adding toleration to pod"  "podName"="tf2-keras-transformer-elastic-20210722-122421-worker-0" "scheduler"="default" "toleration"={"key":"celeste/hostname","operator":"Equal","value":"gpu5","effect":"NoExecute"}
I0722 01:01:24.637735   23824 placement_manager.go:147]  "msg"="Adding toleration to pod"  "podName"="tf2-keras-cifar10-inceptionv3-elastic-20210722-122354-worker-0" "scheduler"="default" "toleration"={"key":"celeste/hostname","operator":"Equal","value":"gpu5","effect":"NoExecute"}
I0722 01:01:24.985308   23824 placement_manager.go:147]  "msg"="Adding toleration to pod"  "podName"="tf2-keras-cifar10-inceptionv3-elastic-20210722-122710-launcher" "scheduler"="default" "toleration"={"key":"celeste/hostname","operator":"Exists","effect":"NoExecute"}
I0722 01:01:26.191488   23824 placement_manager.go:147]  "msg"="Adding toleration to pod"  "podName"="tf2-keras-cifar10-inceptionv3-elastic-20210722-122354-launcher" "scheduler"="default" "toleration"={"key":"celeste/hostname","operator":"Exists","effect":"NoExecute"}
I0722 01:01:29.275846   23824 placement_manager.go:147]  "msg"="Adding toleration to pod"  "podName"="tf2-keras-transformer-elastic-20210722-122826-worker-0" "scheduler"="default" "toleration"={"key":"celeste/hostname","operator":"Equal","value":"gpu5","effect":"NoExecute"}
I0722 01:01:29.315872   23824 placement_manager.go:147]  "msg"="Adding toleration to pod"  "podName"="tf2-keras-cifar10-inceptionv3-elastic-20210722-122034-worker-0" "scheduler"="default" "toleration"={"key":"celeste/hostname","operator":"Equal","value":"gpu4","effect":"NoExecute"}
I0722 01:01:29.326563   23824 placement_manager.go:147]  "msg"="Adding toleration to pod"  "podName"="tf2-keras-transformer-elastic-20210722-122826-launcher" "scheduler"="default" "toleration"={"key":"celeste/hostname","operator":"Exists","effect":"NoExecute"}
I0722 01:01:32.069997   23824 placement_manager.go:147]  "msg"="Adding toleration to pod"  "podName"="tf2-keras-cifar10-inceptionv3-elastic-20210722-122250-launcher" "scheduler"="default" "toleration"={"key":"celeste/hostname","operator":"Exists","effect":"NoExecute"}
I0722 01:01:34.863838   23824 placement_manager.go:147]  "msg"="Adding toleration to pod"  "podName"="tf2-keras-cifar10-inceptionv3-elastic-20210722-122250-worker-0" "scheduler"="default" "toleration"={"key":"celeste/hostname","operator":"Equal","value":"gpu4","effect":"NoExecute"}
I0722 01:01:35.663797   23824 placement_manager.go:147]  "msg"="Adding toleration to pod"  "podName"="tf2-keras-cifar10-inceptionv3-elastic-20210722-122710-worker-0" "scheduler"="default" "toleration"={"key":"celeste/hostname","operator":"Equal","value":"gpu3","effect":"NoExecute"}
I0722 01:01:36.470810   23824 placement_manager.go:147]  "msg"="Adding toleration to pod"  "podName"="tf2-keras-cifar10-inceptionv3-elastic-20210722-122034-launcher" "scheduler"="default" "toleration"={"key":"celeste/hostname","operator":"Exists","effect":"NoExecute"}
I0722 01:22:04.104180   23824 scheduler.go:474]  "msg"="Training job completed"  "elaspedTotalSeconds"=3583.972376697 "gpuTotalSeconds"=2776.275900904 "job"="tf2-keras-transformer-elastic-20210722-122215" "ranTotalSeconds"=2776.275900904 "scheduler"="default" "waitedTotalSeconds"=807.696475793
I0722 01:22:04.104320   23824 scheduler.go:135]  "msg"="Received resched event, may be blocked because of rate limit"  "blockedUntil"="2021-07-22T01:03:11.36398812+08:00" "lastResched"="2021-07-22T01:01:11.36398812+08:00" "received"="2021-07-22T01:22:04.104227761+08:00" "scheduler"="default"
I0722 01:22:04.104792   23824 scheduler.go:159]  "msg"="Started resched"  "scheduler"="default"
I0722 01:22:04.104842   23824 scheduler.go:193]  "msg"="Updating all jobs info"  "scheduler"="default"
I0722 01:22:04.112336   23824 afsl.go:65]  "msg"="Finished scheduling"  "algorithm"="AFS-L" "freeGpu"=0 "result"={"tf2-keras-cifar10-inceptionv3-elastic-20210722-121943":1,"tf2-keras-cifar10-inceptionv3-elastic-20210722-122034":0,"tf2-keras-cifar10-inceptionv3-elastic-20210722-122250":0,"tf2-keras-cifar10-inceptionv3-elastic-20210722-122354":0,"tf2-keras-cifar10-inceptionv3-elastic-20210722-122611":1,"tf2-keras-cifar10-inceptionv3-elastic-20210722-122710":2,"tf2-keras-transformer-elastic-20210722-122149":1,"tf2-keras-transformer-elastic-20210722-122421":1,"tf2-keras-transformer-elastic-20210722-122647":2,"tf2-keras-transformer-elastic-20210722-122826":2,"tf2-keras-transformer-elastic-20210722-123039":2} "scheduler"="default"
I0722 01:22:04.112701   23824 scheduler.go:384]  "msg"="Trying to delete multiple training jobs"  "jobs"=["tf2-keras-cifar10-inceptionv3-elastic-20210722-122354","tf2-keras-cifar10-inceptionv3-elastic-20210722-122034","tf2-keras-cifar10-inceptionv3-elastic-20210722-122250"] "scheduler"="default"
I0722 01:22:04.135719   23824 scheduler.go:342]  "msg"="Trying to scale multiple training jobs"  "jobs"=[] "scheduler"="default"
I0722 01:22:04.135989   23824 scheduler.go:292]  "msg"="Trying to start multiple training jobs"  "jobs"=[] "scheduler"="default"
I0722 01:22:04.136191   23824 scheduler.go:342]  "msg"="Trying to scale multiple training jobs"  "jobs"=["tf2-keras-transformer-elastic-20210722-122826","tf2-keras-transformer-elastic-20210722-123039","tf2-keras-transformer-elastic-20210722-122647","tf2-keras-cifar10-inceptionv3-elastic-20210722-122710"] "scheduler"="default"
I0722 01:22:04.327595   23824 placement_manager.go:166]  "msg"="Started job placements adjustment"  "scheduler"="default"
I0722 01:22:04.327693   23824 placement_manager.go:192]  "msg"="Releasing slots"  "jobs"={"tf2-keras-cifar10-inceptionv3-elastic-20210722-121943":{},"tf2-keras-cifar10-inceptionv3-elastic-20210722-122034":{},"tf2-keras-cifar10-inceptionv3-elastic-20210722-122250":{},"tf2-keras-cifar10-inceptionv3-elastic-20210722-122354":{},"tf2-keras-cifar10-inceptionv3-elastic-20210722-122611":{},"tf2-keras-cifar10-inceptionv3-elastic-20210722-122710":{},"tf2-keras-transformer-elastic-20210722-122149":{},"tf2-keras-transformer-elastic-20210722-122215":{},"tf2-keras-transformer-elastic-20210722-122421":{},"tf2-keras-transformer-elastic-20210722-122647":{},"tf2-keras-transformer-elastic-20210722-122826":{},"tf2-keras-transformer-elastic-20210722-123039":{}} "nodes"={"gpu3":{},"gpu4":{},"gpu5":{}} "scheduler"="default"
I0722 01:22:04.327842   23824 placement_manager.go:250]  "msg"="Released slots"  "jobs"={"tf2-keras-cifar10-inceptionv3-elastic-20210722-121943":{},"tf2-keras-cifar10-inceptionv3-elastic-20210722-122034":{},"tf2-keras-cifar10-inceptionv3-elastic-20210722-122250":{},"tf2-keras-cifar10-inceptionv3-elastic-20210722-122354":{},"tf2-keras-cifar10-inceptionv3-elastic-20210722-122611":{},"tf2-keras-cifar10-inceptionv3-elastic-20210722-122710":{},"tf2-keras-transformer-elastic-20210722-122149":{},"tf2-keras-transformer-elastic-20210722-122215":{},"tf2-keras-transformer-elastic-20210722-122421":{},"tf2-keras-transformer-elastic-20210722-122647":{},"tf2-keras-transformer-elastic-20210722-122826":{},"tf2-keras-transformer-elastic-20210722-123039":{}} "nodes"={"gpu3":{},"gpu4":{},"gpu5":{}} "scheduler"="default"
I0722 01:22:04.328380   23824 placement_manager.go:305]  "msg"="Found best-fit"  "crossNode"=0 "nodes"=[{},{},{}] "requests"=[{},{},{},{},{},{},{},{},{},{},{},{},{},{},{},{},{},{},{},{},{},{}] "scheduler"="default"
I0722 01:22:04.328687   23824 placement_manager.go:339]  "msg"="nodeStates updated"  "new"={"gpu3":{},"gpu4":{},"gpu5":{}} "old"={"gpu3":{},"gpu4":{},"gpu5":{}} "scheduler"="default" "score"=4
I0722 01:22:04.329070   23824 placement_manager.go:387]  "msg"="jobStates updated"  "new"={"tf2-keras-cifar10-inceptionv3-elastic-20210722-121943":{},"tf2-keras-cifar10-inceptionv3-elastic-20210722-122611":{},"tf2-keras-cifar10-inceptionv3-elastic-20210722-122710":{},"tf2-keras-transformer-elastic-20210722-122149":{},"tf2-keras-transformer-elastic-20210722-122421":{},"tf2-keras-transformer-elastic-20210722-122647":{},"tf2-keras-transformer-elastic-20210722-122826":{},"tf2-keras-transformer-elastic-20210722-123039":{}} "old"={"tf2-keras-cifar10-inceptionv3-elastic-20210722-121943":{},"tf2-keras-cifar10-inceptionv3-elastic-20210722-122034":{},"tf2-keras-cifar10-inceptionv3-elastic-20210722-122250":{},"tf2-keras-cifar10-inceptionv3-elastic-20210722-122354":{},"tf2-keras-cifar10-inceptionv3-elastic-20210722-122611":{},"tf2-keras-cifar10-inceptionv3-elastic-20210722-122710":{},"tf2-keras-transformer-elastic-20210722-122149":{},"tf2-keras-transformer-elastic-20210722-122215":{},"tf2-keras-transformer-elastic-20210722-122421":{},"tf2-keras-transformer-elastic-20210722-122647":{},"tf2-keras-transformer-elastic-20210722-122826":{},"tf2-keras-transformer-elastic-20210722-123039":{}} "scheduler"="default"
I0722 01:22:04.329502   23824 placement_manager.go:434]  "msg"="podNodeName updated"  "launchersToDelete"=2 "new"={"tf2-keras-cifar10-inceptionv3-elastic-20210722-121943-worker-0":"gpu3","tf2-keras-cifar10-inceptionv3-elastic-20210722-122611-worker-0":"gpu3","tf2-keras-cifar10-inceptionv3-elastic-20210722-122710-worker-0":"gpu4","tf2-keras-cifar10-inceptionv3-elastic-20210722-122710-worker-1":"gpu4","tf2-keras-transformer-elastic-20210722-122149-worker-0":"gpu3","tf2-keras-transformer-elastic-20210722-122421-worker-0":"gpu3","tf2-keras-transformer-elastic-20210722-122647-worker-0":"gpu4","tf2-keras-transformer-elastic-20210722-122647-worker-1":"gpu4","tf2-keras-transformer-elastic-20210722-122826-worker-0":"gpu5","tf2-keras-transformer-elastic-20210722-122826-worker-1":"gpu5","tf2-keras-transformer-elastic-20210722-123039-worker-0":"gpu5","tf2-keras-transformer-elastic-20210722-123039-worker-1":"gpu5"} "old"={"tf2-keras-cifar10-inceptionv3-elastic-20210722-121943-worker-0":"gpu3","tf2-keras-cifar10-inceptionv3-elastic-20210722-122034-worker-0":"gpu4","tf2-keras-cifar10-inceptionv3-elastic-20210722-122250-worker-0":"gpu4","tf2-keras-cifar10-inceptionv3-elastic-20210722-122354-worker-0":"gpu5","tf2-keras-cifar10-inceptionv3-elastic-20210722-122611-worker-0":"gpu4","tf2-keras-cifar10-inceptionv3-elastic-20210722-122710-worker-0":"gpu3","tf2-keras-transformer-elastic-20210722-122149-worker-0":"gpu3","tf2-keras-transformer-elastic-20210722-122215-worker-0":"gpu5","tf2-keras-transformer-elastic-20210722-122421-worker-0":"gpu5","tf2-keras-transformer-elastic-20210722-122647-worker-0":"gpu4","tf2-keras-transformer-elastic-20210722-122826-worker-0":"gpu5","tf2-keras-transformer-elastic-20210722-123039-worker-0":"gpu3"} "scheduler"="default" "workersToDelete"=4
I0722 01:22:04.329825   23824 placement_manager.go:451]  "msg"="Deleting pod that need migration"  "podName"="tf2-keras-transformer-elastic-20210722-123039-worker-0" "scheduler"="default"
I0722 01:22:04.336389   23824 placement_manager.go:451]  "msg"="Deleting pod that need migration"  "podName"="tf2-keras-transformer-elastic-20210722-122421-worker-0" "scheduler"="default"
I0722 01:22:04.340863   23824 placement_manager.go:451]  "msg"="Deleting pod that need migration"  "podName"="tf2-keras-transformer-elastic-20210722-122421-launcher" "scheduler"="default"
I0722 01:22:04.346399   23824 placement_manager.go:451]  "msg"="Deleting pod that need migration"  "podName"="tf2-keras-cifar10-inceptionv3-elastic-20210722-122611-worker-0" "scheduler"="default"
I0722 01:22:04.350848   23824 placement_manager.go:451]  "msg"="Deleting pod that need migration"  "podName"="tf2-keras-cifar10-inceptionv3-elastic-20210722-122611-launcher" "scheduler"="default"
I0722 01:22:04.359185   23824 placement_manager.go:451]  "msg"="Deleting pod that need migration"  "podName"="tf2-keras-cifar10-inceptionv3-elastic-20210722-122710-worker-0" "scheduler"="default"
I0722 01:22:04.365186   23824 placement_manager.go:183]  "msg"="Finished job placements adjustment"  "scheduler"="default"
I0722 01:22:04.365509   23824 scheduler.go:182]  "msg"="Finished resched"  "scheduler"="default"
I0722 01:22:04.498741   23824 placement_manager.go:147]  "msg"="Adding toleration to pod"  "podName"="tf2-keras-transformer-elastic-20210722-123039-worker-1" "scheduler"="default" "toleration"={"key":"celeste/hostname","operator":"Equal","value":"gpu5","effect":"NoExecute"}
I0722 01:22:05.098757   23824 placement_manager.go:147]  "msg"="Adding toleration to pod"  "podName"="tf2-keras-transformer-elastic-20210722-122647-worker-1" "scheduler"="default" "toleration"={"key":"celeste/hostname","operator":"Equal","value":"gpu4","effect":"NoExecute"}
I0722 01:22:05.698751   23824 placement_manager.go:147]  "msg"="Adding toleration to pod"  "podName"="tf2-keras-cifar10-inceptionv3-elastic-20210722-122710-worker-1" "scheduler"="default" "toleration"={"key":"celeste/hostname","operator":"Equal","value":"gpu4","effect":"NoExecute"}
I0722 01:22:18.031677   23824 placement_manager.go:147]  "msg"="Adding toleration to pod"  "podName"="tf2-keras-transformer-elastic-20210722-122421-launcher" "scheduler"="default" "toleration"={"key":"celeste/hostname","operator":"Exists","effect":"NoExecute"}
I0722 01:22:19.273564   23824 placement_manager.go:147]  "msg"="Adding toleration to pod"  "podName"="tf2-keras-transformer-elastic-20210722-123039-worker-0" "scheduler"="default" "toleration"={"key":"celeste/hostname","operator":"Equal","value":"gpu5","effect":"NoExecute"}
I0722 01:22:19.306965   23824 placement_manager.go:147]  "msg"="Adding toleration to pod"  "podName"="tf2-keras-cifar10-inceptionv3-elastic-20210722-122710-worker-0" "scheduler"="default" "toleration"={"key":"celeste/hostname","operator":"Equal","value":"gpu4","effect":"NoExecute"}
I0722 01:22:19.630613   23824 placement_manager.go:147]  "msg"="Adding toleration to pod"  "podName"="tf2-keras-cifar10-inceptionv3-elastic-20210722-122611-launcher" "scheduler"="default" "toleration"={"key":"celeste/hostname","operator":"Exists","effect":"NoExecute"}
I0722 01:22:20.431457   23824 placement_manager.go:147]  "msg"="Adding toleration to pod"  "podName"="tf2-keras-cifar10-inceptionv3-elastic-20210722-122611-worker-0" "scheduler"="default" "toleration"={"key":"celeste/hostname","operator":"Equal","value":"gpu3","effect":"NoExecute"}
I0722 01:22:24.408419   23824 placement_manager.go:147]  "msg"="Adding toleration to pod"  "podName"="tf2-keras-transformer-elastic-20210722-122421-worker-0" "scheduler"="default" "toleration"={"key":"celeste/hostname","operator":"Equal","value":"gpu3","effect":"NoExecute"}
I0722 01:25:16.479971   23824 scheduler.go:474]  "msg"="Training job completed"  "elaspedTotalSeconds"=3805.851314588 "gpuTotalSeconds"=2711.272943458 "job"="tf2-keras-transformer-elastic-20210722-122149" "ranTotalSeconds"=2711.272943458 "scheduler"="default" "waitedTotalSeconds"=1094.57837113
I0722 01:25:16.480067   23824 scheduler.go:135]  "msg"="Received resched event, may be blocked because of rate limit"  "blockedUntil"="2021-07-22T01:24:04.365800315+08:00" "lastResched"="2021-07-22T01:22:04.365800315+08:00" "received"="2021-07-22T01:25:16.479996292+08:00" "scheduler"="default"
I0722 01:25:16.480622   23824 scheduler.go:159]  "msg"="Started resched"  "scheduler"="default"
I0722 01:25:16.480695   23824 scheduler.go:193]  "msg"="Updating all jobs info"  "scheduler"="default"
I0722 01:25:16.488969   23824 afsl.go:65]  "msg"="Finished scheduling"  "algorithm"="AFS-L" "freeGpu"=0 "result"={"tf2-keras-cifar10-inceptionv3-elastic-20210722-121943":1,"tf2-keras-cifar10-inceptionv3-elastic-20210722-122034":0,"tf2-keras-cifar10-inceptionv3-elastic-20210722-122250":0,"tf2-keras-cifar10-inceptionv3-elastic-20210722-122354":0,"tf2-keras-cifar10-inceptionv3-elastic-20210722-122611":1,"tf2-keras-cifar10-inceptionv3-elastic-20210722-122710":2,"tf2-keras-transformer-elastic-20210722-122421":2,"tf2-keras-transformer-elastic-20210722-122647":2,"tf2-keras-transformer-elastic-20210722-122826":2,"tf2-keras-transformer-elastic-20210722-123039":2} "scheduler"="default"
I0722 01:25:16.489288   23824 scheduler.go:384]  "msg"="Trying to delete multiple training jobs"  "jobs"=[] "scheduler"="default"
I0722 01:25:16.489525   23824 scheduler.go:342]  "msg"="Trying to scale multiple training jobs"  "jobs"=[] "scheduler"="default"
I0722 01:25:16.489791   23824 scheduler.go:292]  "msg"="Trying to start multiple training jobs"  "jobs"=[] "scheduler"="default"
I0722 01:25:16.490011   23824 scheduler.go:342]  "msg"="Trying to scale multiple training jobs"  "jobs"=["tf2-keras-transformer-elastic-20210722-122421"] "scheduler"="default"
I0722 01:25:16.509046   23824 placement_manager.go:166]  "msg"="Started job placements adjustment"  "scheduler"="default"
I0722 01:25:16.509099   23824 placement_manager.go:192]  "msg"="Releasing slots"  "jobs"={"tf2-keras-cifar10-inceptionv3-elastic-20210722-121943":{},"tf2-keras-cifar10-inceptionv3-elastic-20210722-122611":{},"tf2-keras-cifar10-inceptionv3-elastic-20210722-122710":{},"tf2-keras-transformer-elastic-20210722-122149":{},"tf2-keras-transformer-elastic-20210722-122421":{},"tf2-keras-transformer-elastic-20210722-122647":{},"tf2-keras-transformer-elastic-20210722-122826":{},"tf2-keras-transformer-elastic-20210722-123039":{}} "nodes"={"gpu3":{},"gpu4":{},"gpu5":{}} "scheduler"="default"
I0722 01:25:16.509145   23824 placement_manager.go:250]  "msg"="Released slots"  "jobs"={"tf2-keras-cifar10-inceptionv3-elastic-20210722-121943":{},"tf2-keras-cifar10-inceptionv3-elastic-20210722-122611":{},"tf2-keras-cifar10-inceptionv3-elastic-20210722-122710":{},"tf2-keras-transformer-elastic-20210722-122149":{},"tf2-keras-transformer-elastic-20210722-122421":{},"tf2-keras-transformer-elastic-20210722-122647":{},"tf2-keras-transformer-elastic-20210722-122826":{},"tf2-keras-transformer-elastic-20210722-123039":{}} "nodes"={"gpu3":{},"gpu4":{},"gpu5":{}} "scheduler"="default"
I0722 01:25:16.509627   23824 placement_manager.go:305]  "msg"="Found best-fit"  "crossNode"=0 "nodes"=[{},{},{}] "requests"=[{},{},{},{},{},{},{},{},{},{},{},{},{},{},{},{},{},{},{},{}] "scheduler"="default"
I0722 01:25:16.510032   23824 placement_manager.go:339]  "msg"="nodeStates updated"  "new"={"gpu3":{},"gpu4":{},"gpu5":{}} "old"={"gpu3":{},"gpu4":{},"gpu5":{}} "scheduler"="default" "score"=6
I0722 01:25:16.510363   23824 placement_manager.go:387]  "msg"="jobStates updated"  "new"={"tf2-keras-cifar10-inceptionv3-elastic-20210722-121943":{},"tf2-keras-cifar10-inceptionv3-elastic-20210722-122611":{},"tf2-keras-cifar10-inceptionv3-elastic-20210722-122710":{},"tf2-keras-transformer-elastic-20210722-122421":{},"tf2-keras-transformer-elastic-20210722-122647":{},"tf2-keras-transformer-elastic-20210722-122826":{},"tf2-keras-transformer-elastic-20210722-123039":{}} "old"={"tf2-keras-cifar10-inceptionv3-elastic-20210722-121943":{},"tf2-keras-cifar10-inceptionv3-elastic-20210722-122611":{},"tf2-keras-cifar10-inceptionv3-elastic-20210722-122710":{},"tf2-keras-transformer-elastic-20210722-122149":{},"tf2-keras-transformer-elastic-20210722-122421":{},"tf2-keras-transformer-elastic-20210722-122647":{},"tf2-keras-transformer-elastic-20210722-122826":{},"tf2-keras-transformer-elastic-20210722-123039":{}} "scheduler"="default"
I0722 01:25:16.510740   23824 placement_manager.go:434]  "msg"="podNodeName updated"  "launchersToDelete"=2 "new"={"tf2-keras-cifar10-inceptionv3-elastic-20210722-121943-worker-0":"gpu3","tf2-keras-cifar10-inceptionv3-elastic-20210722-122611-worker-0":"gpu3","tf2-keras-cifar10-inceptionv3-elastic-20210722-122710-worker-0":"gpu4","tf2-keras-cifar10-inceptionv3-elastic-20210722-122710-worker-1":"gpu4","tf2-keras-transformer-elastic-20210722-122421-worker-0":"gpu5","tf2-keras-transformer-elastic-20210722-122421-worker-1":"gpu5","tf2-keras-transformer-elastic-20210722-122647-worker-0":"gpu3","tf2-keras-transformer-elastic-20210722-122647-worker-1":"gpu3","tf2-keras-transformer-elastic-20210722-122826-worker-0":"gpu4","tf2-keras-transformer-elastic-20210722-122826-worker-1":"gpu4","tf2-keras-transformer-elastic-20210722-123039-worker-0":"gpu5","tf2-keras-transformer-elastic-20210722-123039-worker-1":"gpu5"} "old"={"tf2-keras-cifar10-inceptionv3-elastic-20210722-121943-worker-0":"gpu3","tf2-keras-cifar10-inceptionv3-elastic-20210722-122611-worker-0":"gpu3","tf2-keras-cifar10-inceptionv3-elastic-20210722-122710-worker-0":"gpu4","tf2-keras-cifar10-inceptionv3-elastic-20210722-122710-worker-1":"gpu4","tf2-keras-transformer-elastic-20210722-122149-worker-0":"gpu3","tf2-keras-transformer-elastic-20210722-122421-worker-0":"gpu3","tf2-keras-transformer-elastic-20210722-122647-worker-0":"gpu4","tf2-keras-transformer-elastic-20210722-122647-worker-1":"gpu4","tf2-keras-transformer-elastic-20210722-122826-worker-0":"gpu5","tf2-keras-transformer-elastic-20210722-122826-worker-1":"gpu5","tf2-keras-transformer-elastic-20210722-123039-worker-0":"gpu5","tf2-keras-transformer-elastic-20210722-123039-worker-1":"gpu5"} "scheduler"="default" "workersToDelete"=5
I0722 01:25:16.511036   23824 placement_manager.go:451]  "msg"="Deleting pod that need migration"  "podName"="tf2-keras-transformer-elastic-20210722-122826-worker-0" "scheduler"="default"
I0722 01:25:16.518111   23824 placement_manager.go:451]  "msg"="Deleting pod that need migration"  "podName"="tf2-keras-transformer-elastic-20210722-122826-worker-1" "scheduler"="default"
I0722 01:25:16.524600   23824 placement_manager.go:451]  "msg"="Deleting pod that need migration"  "podName"="tf2-keras-transformer-elastic-20210722-122826-launcher" "scheduler"="default"
I0722 01:25:16.529826   23824 placement_manager.go:451]  "msg"="Deleting pod that need migration"  "podName"="tf2-keras-transformer-elastic-20210722-122421-worker-0" "scheduler"="default"
I0722 01:25:16.537525   23824 placement_manager.go:451]  "msg"="Deleting pod that need migration"  "podName"="tf2-keras-transformer-elastic-20210722-122647-worker-0" "scheduler"="default"
I0722 01:25:16.541918   23824 placement_manager.go:147]  "msg"="Adding toleration to pod"  "podName"="tf2-keras-transformer-elastic-20210722-122421-worker-1" "scheduler"="default" "toleration"={"key":"celeste/hostname","operator":"Equal","value":"gpu5","effect":"NoExecute"}
I0722 01:25:16.564701   23824 placement_manager.go:451]  "msg"="Deleting pod that need migration"  "podName"="tf2-keras-transformer-elastic-20210722-122647-worker-1" "scheduler"="default"
I0722 01:25:16.569725   23824 placement_manager.go:451]  "msg"="Deleting pod that need migration"  "podName"="tf2-keras-transformer-elastic-20210722-122647-launcher" "scheduler"="default"
I0722 01:25:16.573649   23824 placement_manager.go:183]  "msg"="Finished job placements adjustment"  "scheduler"="default"
I0722 01:25:16.573909   23824 scheduler.go:182]  "msg"="Finished resched"  "scheduler"="default"
I0722 01:25:16.719537   23824 placement_manager.go:147]  "msg"="Adding toleration to pod"  "podName"="tf2-keras-transformer-elastic-20210722-122826-worker-1" "scheduler"="default" "toleration"={"key":"celeste/hostname","operator":"Equal","value":"gpu4","effect":"NoExecute"}
I0722 01:25:23.654626   23824 placement_manager.go:147]  "msg"="Adding toleration to pod"  "podName"="tf2-keras-transformer-elastic-20210722-122421-worker-0" "scheduler"="default" "toleration"={"key":"celeste/hostname","operator":"Equal","value":"gpu5","effect":"NoExecute"}
I0722 01:25:24.423636   23824 placement_manager.go:147]  "msg"="Adding toleration to pod"  "podName"="tf2-keras-transformer-elastic-20210722-122647-launcher" "scheduler"="default" "toleration"={"key":"celeste/hostname","operator":"Exists","effect":"NoExecute"}
I0722 01:25:26.341513   23824 placement_manager.go:147]  "msg"="Adding toleration to pod"  "podName"="tf2-keras-transformer-elastic-20210722-122826-launcher" "scheduler"="default" "toleration"={"key":"celeste/hostname","operator":"Exists","effect":"NoExecute"}
I0722 01:25:29.749885   23824 placement_manager.go:147]  "msg"="Adding toleration to pod"  "podName"="tf2-keras-transformer-elastic-20210722-122826-worker-0" "scheduler"="default" "toleration"={"key":"celeste/hostname","operator":"Equal","value":"gpu4","effect":"NoExecute"}
I0722 01:25:35.194022   23824 placement_manager.go:147]  "msg"="Adding toleration to pod"  "podName"="tf2-keras-transformer-elastic-20210722-122647-worker-0" "scheduler"="default" "toleration"={"key":"celeste/hostname","operator":"Equal","value":"gpu3","effect":"NoExecute"}
I0722 01:25:35.993057   23824 placement_manager.go:147]  "msg"="Adding toleration to pod"  "podName"="tf2-keras-transformer-elastic-20210722-122647-worker-1" "scheduler"="default" "toleration"={"key":"celeste/hostname","operator":"Equal","value":"gpu3","effect":"NoExecute"}
I0722 01:29:39.860198   23824 scheduler.go:474]  "msg"="Training job completed"  "elaspedTotalSeconds"=3535.248919053 "gpuTotalSeconds"=2705.09037258 "job"="tf2-keras-transformer-elastic-20210722-123039" "ranTotalSeconds"=2250.075273683 "scheduler"="default" "waitedTotalSeconds"=1285.17364537
I0722 01:29:39.860378   23824 scheduler.go:135]  "msg"="Received resched event, may be blocked because of rate limit"  "blockedUntil"="2021-07-22T01:27:16.574080213+08:00" "lastResched"="2021-07-22T01:25:16.574080213+08:00" "received"="2021-07-22T01:29:39.860241841+08:00" "scheduler"="default"
I0722 01:29:39.860797   23824 scheduler.go:159]  "msg"="Started resched"  "scheduler"="default"
I0722 01:29:39.860862   23824 scheduler.go:193]  "msg"="Updating all jobs info"  "scheduler"="default"
I0722 01:29:39.867996   23824 afsl.go:65]  "msg"="Finished scheduling"  "algorithm"="AFS-L" "freeGpu"=0 "result"={"tf2-keras-cifar10-inceptionv3-elastic-20210722-121943":2,"tf2-keras-cifar10-inceptionv3-elastic-20210722-122034":0,"tf2-keras-cifar10-inceptionv3-elastic-20210722-122250":0,"tf2-keras-cifar10-inceptionv3-elastic-20210722-122354":0,"tf2-keras-cifar10-inceptionv3-elastic-20210722-122611":1,"tf2-keras-cifar10-inceptionv3-elastic-20210722-122710":3,"tf2-keras-transformer-elastic-20210722-122421":2,"tf2-keras-transformer-elastic-20210722-122647":2,"tf2-keras-transformer-elastic-20210722-122826":2} "scheduler"="default"
I0722 01:29:39.868469   23824 scheduler.go:384]  "msg"="Trying to delete multiple training jobs"  "jobs"=[] "scheduler"="default"
I0722 01:29:39.868731   23824 scheduler.go:342]  "msg"="Trying to scale multiple training jobs"  "jobs"=[] "scheduler"="default"
I0722 01:29:39.868927   23824 scheduler.go:292]  "msg"="Trying to start multiple training jobs"  "jobs"=[] "scheduler"="default"
I0722 01:29:39.869113   23824 scheduler.go:342]  "msg"="Trying to scale multiple training jobs"  "jobs"=["tf2-keras-cifar10-inceptionv3-elastic-20210722-122710","tf2-keras-cifar10-inceptionv3-elastic-20210722-121943"] "scheduler"="default"
I0722 01:29:39.901560   23824 placement_manager.go:166]  "msg"="Started job placements adjustment"  "scheduler"="default"
I0722 01:29:39.901647   23824 placement_manager.go:192]  "msg"="Releasing slots"  "jobs"={"tf2-keras-cifar10-inceptionv3-elastic-20210722-121943":{},"tf2-keras-cifar10-inceptionv3-elastic-20210722-122611":{},"tf2-keras-cifar10-inceptionv3-elastic-20210722-122710":{},"tf2-keras-transformer-elastic-20210722-122421":{},"tf2-keras-transformer-elastic-20210722-122647":{},"tf2-keras-transformer-elastic-20210722-122826":{},"tf2-keras-transformer-elastic-20210722-123039":{}} "nodes"={"gpu3":{},"gpu4":{},"gpu5":{}} "scheduler"="default"
I0722 01:29:39.901740   23824 placement_manager.go:250]  "msg"="Released slots"  "jobs"={"tf2-keras-cifar10-inceptionv3-elastic-20210722-121943":{},"tf2-keras-cifar10-inceptionv3-elastic-20210722-122611":{},"tf2-keras-cifar10-inceptionv3-elastic-20210722-122710":{},"tf2-keras-transformer-elastic-20210722-122421":{},"tf2-keras-transformer-elastic-20210722-122647":{},"tf2-keras-transformer-elastic-20210722-122826":{},"tf2-keras-transformer-elastic-20210722-123039":{}} "nodes"={"gpu3":{},"gpu4":{},"gpu5":{}} "scheduler"="default"
I0722 01:29:39.902291   23824 placement_manager.go:305]  "msg"="Found best-fit"  "crossNode"=0 "nodes"=[{},{},{}] "requests"=[{},{},{},{},{},{},{},{},{},{},{},{},{},{},{},{},{},{}] "scheduler"="default"
I0722 01:29:39.902553   23824 placement_manager.go:339]  "msg"="nodeStates updated"  "new"={"gpu3":{},"gpu4":{},"gpu5":{}} "old"={"gpu3":{},"gpu4":{},"gpu5":{}} "scheduler"="default" "score"=6
I0722 01:29:39.902777   23824 placement_manager.go:387]  "msg"="jobStates updated"  "new"={"tf2-keras-cifar10-inceptionv3-elastic-20210722-121943":{},"tf2-keras-cifar10-inceptionv3-elastic-20210722-122611":{},"tf2-keras-cifar10-inceptionv3-elastic-20210722-122710":{},"tf2-keras-transformer-elastic-20210722-122421":{},"tf2-keras-transformer-elastic-20210722-122647":{},"tf2-keras-transformer-elastic-20210722-122826":{}} "old"={"tf2-keras-cifar10-inceptionv3-elastic-20210722-121943":{},"tf2-keras-cifar10-inceptionv3-elastic-20210722-122611":{},"tf2-keras-cifar10-inceptionv3-elastic-20210722-122710":{},"tf2-keras-transformer-elastic-20210722-122421":{},"tf2-keras-transformer-elastic-20210722-122647":{},"tf2-keras-transformer-elastic-20210722-122826":{},"tf2-keras-transformer-elastic-20210722-123039":{}} "scheduler"="default"
I0722 01:29:39.903074   23824 placement_manager.go:434]  "msg"="podNodeName updated"  "launchersToDelete"=2 "new"={"tf2-keras-cifar10-inceptionv3-elastic-20210722-121943-worker-0":"gpu5","tf2-keras-cifar10-inceptionv3-elastic-20210722-121943-worker-1":"gpu5","tf2-keras-cifar10-inceptionv3-elastic-20210722-122611-worker-0":"gpu4","tf2-keras-cifar10-inceptionv3-elastic-20210722-122710-worker-0":"gpu4","tf2-keras-cifar10-inceptionv3-elastic-20210722-122710-worker-1":"gpu4","tf2-keras-cifar10-inceptionv3-elastic-20210722-122710-worker-2":"gpu4","tf2-keras-transformer-elastic-20210722-122421-worker-0":"gpu5","tf2-keras-transformer-elastic-20210722-122421-worker-1":"gpu5","tf2-keras-transformer-elastic-20210722-122647-worker-0":"gpu3","tf2-keras-transformer-elastic-20210722-122647-worker-1":"gpu3","tf2-keras-transformer-elastic-20210722-122826-worker-0":"gpu3","tf2-keras-transformer-elastic-20210722-122826-worker-1":"gpu3"} "old"={"tf2-keras-cifar10-inceptionv3-elastic-20210722-121943-worker-0":"gpu3","tf2-keras-cifar10-inceptionv3-elastic-20210722-122611-worker-0":"gpu3","tf2-keras-cifar10-inceptionv3-elastic-20210722-122710-worker-0":"gpu4","tf2-keras-cifar10-inceptionv3-elastic-20210722-122710-worker-1":"gpu4","tf2-keras-transformer-elastic-20210722-122421-worker-0":"gpu5","tf2-keras-transformer-elastic-20210722-122421-worker-1":"gpu5","tf2-keras-transformer-elastic-20210722-122647-worker-0":"gpu3","tf2-keras-transformer-elastic-20210722-122647-worker-1":"gpu3","tf2-keras-transformer-elastic-20210722-122826-worker-0":"gpu4","tf2-keras-transformer-elastic-20210722-122826-worker-1":"gpu4","tf2-keras-transformer-elastic-20210722-123039-worker-0":"gpu5","tf2-keras-transformer-elastic-20210722-123039-worker-1":"gpu5"} "scheduler"="default" "workersToDelete"=4
I0722 01:29:39.903316   23824 placement_manager.go:451]  "msg"="Deleting pod that need migration"  "podName"="tf2-keras-cifar10-inceptionv3-elastic-20210722-122611-worker-0" "scheduler"="default"
I0722 01:29:39.907877   23824 placement_manager.go:451]  "msg"="Deleting pod that need migration"  "podName"="tf2-keras-cifar10-inceptionv3-elastic-20210722-122611-launcher" "scheduler"="default"
I0722 01:29:39.911976   23824 placement_manager.go:451]  "msg"="Deleting pod that need migration"  "podName"="tf2-keras-transformer-elastic-20210722-122826-worker-0" "scheduler"="default"
I0722 01:29:39.916658   23824 placement_manager.go:147]  "msg"="Adding toleration to pod"  "podName"="tf2-keras-cifar10-inceptionv3-elastic-20210722-122710-worker-2" "scheduler"="default" "toleration"={"key":"celeste/hostname","operator":"Equal","value":"gpu4","effect":"NoExecute"}
I0722 01:29:39.921371   23824 placement_manager.go:451]  "msg"="Deleting pod that need migration"  "podName"="tf2-keras-transformer-elastic-20210722-122826-worker-1" "scheduler"="default"
I0722 01:29:39.936528   23824 placement_manager.go:451]  "msg"="Deleting pod that need migration"  "podName"="tf2-keras-transformer-elastic-20210722-122826-launcher" "scheduler"="default"
I0722 01:29:39.941460   23824 placement_manager.go:451]  "msg"="Deleting pod that need migration"  "podName"="tf2-keras-cifar10-inceptionv3-elastic-20210722-121943-worker-0" "scheduler"="default"
I0722 01:29:39.945278   23824 placement_manager.go:183]  "msg"="Finished job placements adjustment"  "scheduler"="default"
I0722 01:29:39.945561   23824 scheduler.go:182]  "msg"="Finished resched"  "scheduler"="default"
I0722 01:29:40.453448   23824 placement_manager.go:147]  "msg"="Adding toleration to pod"  "podName"="tf2-keras-cifar10-inceptionv3-elastic-20210722-121943-worker-1" "scheduler"="default" "toleration"={"key":"celeste/hostname","operator":"Equal","value":"gpu5","effect":"NoExecute"}
I0722 01:29:48.285769   23824 placement_manager.go:147]  "msg"="Adding toleration to pod"  "podName"="tf2-keras-cifar10-inceptionv3-elastic-20210722-122611-launcher" "scheduler"="default" "toleration"={"key":"celeste/hostname","operator":"Exists","effect":"NoExecute"}
I0722 01:29:54.587451   23824 placement_manager.go:147]  "msg"="Adding toleration to pod"  "podName"="tf2-keras-transformer-elastic-20210722-122826-launcher" "scheduler"="default" "toleration"={"key":"celeste/hostname","operator":"Exists","effect":"NoExecute"}
I0722 01:29:54.636337   23824 placement_manager.go:147]  "msg"="Adding toleration to pod"  "podName"="tf2-keras-transformer-elastic-20210722-122826-worker-0" "scheduler"="default" "toleration"={"key":"celeste/hostname","operator":"Equal","value":"gpu3","effect":"NoExecute"}
I0722 01:29:54.647096   23824 placement_manager.go:147]  "msg"="Adding toleration to pod"  "podName"="tf2-keras-transformer-elastic-20210722-122826-worker-1" "scheduler"="default" "toleration"={"key":"celeste/hostname","operator":"Equal","value":"gpu3","effect":"NoExecute"}
I0722 01:30:00.284033   23824 placement_manager.go:147]  "msg"="Adding toleration to pod"  "podName"="tf2-keras-cifar10-inceptionv3-elastic-20210722-122611-worker-0" "scheduler"="default" "toleration"={"key":"celeste/hostname","operator":"Equal","value":"gpu4","effect":"NoExecute"}
I0722 01:30:01.071727   23824 placement_manager.go:147]  "msg"="Adding toleration to pod"  "podName"="tf2-keras-cifar10-inceptionv3-elastic-20210722-121943-worker-0" "scheduler"="default" "toleration"={"key":"celeste/hostname","operator":"Equal","value":"gpu5","effect":"NoExecute"}
I0722 01:30:54.816264   23824 scheduler.go:474]  "msg"="Training job completed"  "elaspedTotalSeconds"=3842.744181067 "gpuTotalSeconds"=2975.219249622 "job"="tf2-keras-transformer-elastic-20210722-122647" "ranTotalSeconds"=2445.197143922 "scheduler"="default" "waitedTotalSeconds"=1397.547037145
I0722 01:30:54.816419   23824 scheduler.go:135]  "msg"="Received resched event, may be blocked because of rate limit"  "blockedUntil"="2021-07-22T01:31:39.945785885+08:00" "lastResched"="2021-07-22T01:29:39.945785885+08:00" "received"="2021-07-22T01:30:54.816307859+08:00" "scheduler"="default"
I0722 01:31:23.530650   23824 scheduler.go:474]  "msg"="Training job completed"  "elaspedTotalSeconds"=4018.308064047 "gpuTotalSeconds"=3080.887563624 "job"="tf2-keras-transformer-elastic-20210722-122421" "ranTotalSeconds"=2715.871197577 "scheduler"="default" "waitedTotalSeconds"=1302.43686647
I0722 01:31:39.945845   23824 scheduler.go:159]  "msg"="Started resched"  "scheduler"="default"
I0722 01:31:39.945916   23824 scheduler.go:193]  "msg"="Updating all jobs info"  "scheduler"="default"
I0722 01:31:39.950552   23824 afsl.go:65]  "msg"="Finished scheduling"  "algorithm"="AFS-L" "freeGpu"=0 "result"={"tf2-keras-cifar10-inceptionv3-elastic-20210722-121943":2,"tf2-keras-cifar10-inceptionv3-elastic-20210722-122034":1,"tf2-keras-cifar10-inceptionv3-elastic-20210722-122250":0,"tf2-keras-cifar10-inceptionv3-elastic-20210722-122354":2,"tf2-keras-cifar10-inceptionv3-elastic-20210722-122611":2,"tf2-keras-cifar10-inceptionv3-elastic-20210722-122710":3,"tf2-keras-transformer-elastic-20210722-122826":2} "scheduler"="default"
I0722 01:31:39.950837   23824 scheduler.go:384]  "msg"="Trying to delete multiple training jobs"  "jobs"=[] "scheduler"="default"
I0722 01:31:39.951071   23824 scheduler.go:342]  "msg"="Trying to scale multiple training jobs"  "jobs"=[] "scheduler"="default"
I0722 01:31:39.951249   23824 scheduler.go:292]  "msg"="Trying to start multiple training jobs"  "jobs"=["tf2-keras-cifar10-inceptionv3-elastic-20210722-122034","tf2-keras-cifar10-inceptionv3-elastic-20210722-122354"] "scheduler"="default"
I0722 01:31:39.976549   23824 scheduler.go:342]  "msg"="Trying to scale multiple training jobs"  "jobs"=["tf2-keras-cifar10-inceptionv3-elastic-20210722-122611"] "scheduler"="default"
I0722 01:31:40.006312   23824 placement_manager.go:166]  "msg"="Started job placements adjustment"  "scheduler"="default"
I0722 01:31:40.006444   23824 placement_manager.go:192]  "msg"="Releasing slots"  "jobs"={"tf2-keras-cifar10-inceptionv3-elastic-20210722-121943":{},"tf2-keras-cifar10-inceptionv3-elastic-20210722-122611":{},"tf2-keras-cifar10-inceptionv3-elastic-20210722-122710":{},"tf2-keras-transformer-elastic-20210722-122421":{},"tf2-keras-transformer-elastic-20210722-122647":{},"tf2-keras-transformer-elastic-20210722-122826":{}} "nodes"={"gpu3":{},"gpu4":{},"gpu5":{}} "scheduler"="default"
I0722 01:31:40.006572   23824 placement_manager.go:250]  "msg"="Released slots"  "jobs"={"tf2-keras-cifar10-inceptionv3-elastic-20210722-121943":{},"tf2-keras-cifar10-inceptionv3-elastic-20210722-122611":{},"tf2-keras-cifar10-inceptionv3-elastic-20210722-122710":{},"tf2-keras-transformer-elastic-20210722-122421":{},"tf2-keras-transformer-elastic-20210722-122647":{},"tf2-keras-transformer-elastic-20210722-122826":{}} "nodes"={"gpu3":{},"gpu4":{},"gpu5":{}} "scheduler"="default"
I0722 01:31:40.007003   23824 placement_manager.go:305]  "msg"="Found best-fit"  "crossNode"=0 "nodes"=[{},{},{}] "requests"=[{},{},{},{},{},{},{},{},{},{},{},{},{},{}] "scheduler"="default"
I0722 01:31:40.007363   23824 placement_manager.go:339]  "msg"="nodeStates updated"  "new"={"gpu3":{},"gpu4":{},"gpu5":{}} "old"={"gpu3":{},"gpu4":{},"gpu5":{}} "scheduler"="default" "score"=7
I0722 01:31:40.007776   23824 placement_manager.go:387]  "msg"="jobStates updated"  "new"={"tf2-keras-cifar10-inceptionv3-elastic-20210722-121943":{},"tf2-keras-cifar10-inceptionv3-elastic-20210722-122034":{},"tf2-keras-cifar10-inceptionv3-elastic-20210722-122354":{},"tf2-keras-cifar10-inceptionv3-elastic-20210722-122611":{},"tf2-keras-cifar10-inceptionv3-elastic-20210722-122710":{},"tf2-keras-transformer-elastic-20210722-122826":{}} "old"={"tf2-keras-cifar10-inceptionv3-elastic-20210722-121943":{},"tf2-keras-cifar10-inceptionv3-elastic-20210722-122611":{},"tf2-keras-cifar10-inceptionv3-elastic-20210722-122710":{},"tf2-keras-transformer-elastic-20210722-122421":{},"tf2-keras-transformer-elastic-20210722-122647":{},"tf2-keras-transformer-elastic-20210722-122826":{}} "scheduler"="default"
I0722 01:31:40.008309   23824 placement_manager.go:434]  "msg"="podNodeName updated"  "launchersToDelete"=0 "new"={"tf2-keras-cifar10-inceptionv3-elastic-20210722-121943-worker-0":"gpu5","tf2-keras-cifar10-inceptionv3-elastic-20210722-121943-worker-1":"gpu5","tf2-keras-cifar10-inceptionv3-elastic-20210722-122034-worker-0":"gpu4","tf2-keras-cifar10-inceptionv3-elastic-20210722-122354-worker-0":"gpu5","tf2-keras-cifar10-inceptionv3-elastic-20210722-122354-worker-1":"gpu5","tf2-keras-cifar10-inceptionv3-elastic-20210722-122611-worker-0":"gpu3","tf2-keras-cifar10-inceptionv3-elastic-20210722-122611-worker-1":"gpu3","tf2-keras-cifar10-inceptionv3-elastic-20210722-122710-worker-0":"gpu4","tf2-keras-cifar10-inceptionv3-elastic-20210722-122710-worker-1":"gpu4","tf2-keras-cifar10-inceptionv3-elastic-20210722-122710-worker-2":"gpu4","tf2-keras-transformer-elastic-20210722-122826-worker-0":"gpu3","tf2-keras-transformer-elastic-20210722-122826-worker-1":"gpu3"} "old"={"tf2-keras-cifar10-inceptionv3-elastic-20210722-121943-worker-0":"gpu5","tf2-keras-cifar10-inceptionv3-elastic-20210722-121943-worker-1":"gpu5","tf2-keras-cifar10-inceptionv3-elastic-20210722-122611-worker-0":"gpu4","tf2-keras-cifar10-inceptionv3-elastic-20210722-122710-worker-0":"gpu4","tf2-keras-cifar10-inceptionv3-elastic-20210722-122710-worker-1":"gpu4","tf2-keras-cifar10-inceptionv3-elastic-20210722-122710-worker-2":"gpu4","tf2-keras-transformer-elastic-20210722-122421-worker-0":"gpu5","tf2-keras-transformer-elastic-20210722-122421-worker-1":"gpu5","tf2-keras-transformer-elastic-20210722-122647-worker-0":"gpu3","tf2-keras-transformer-elastic-20210722-122647-worker-1":"gpu3","tf2-keras-transformer-elastic-20210722-122826-worker-0":"gpu3","tf2-keras-transformer-elastic-20210722-122826-worker-1":"gpu3"} "scheduler"="default" "workersToDelete"=1
I0722 01:31:40.008678   23824 placement_manager.go:451]  "msg"="Deleting pod that need migration"  "podName"="tf2-keras-cifar10-inceptionv3-elastic-20210722-122611-worker-0" "scheduler"="default"
I0722 01:31:40.012944   23824 placement_manager.go:183]  "msg"="Finished job placements adjustment"  "scheduler"="default"
I0722 01:31:40.013295   23824 scheduler.go:182]  "msg"="Finished resched"  "scheduler"="default"
I0722 01:31:40.175996   23824 placement_manager.go:147]  "msg"="Adding toleration to pod"  "podName"="tf2-keras-cifar10-inceptionv3-elastic-20210722-122034-worker-0" "scheduler"="default" "toleration"={"key":"celeste/hostname","operator":"Equal","value":"gpu4","effect":"NoExecute"}
I0722 01:31:40.374718   23824 placement_manager.go:147]  "msg"="Adding toleration to pod"  "podName"="tf2-keras-cifar10-inceptionv3-elastic-20210722-122354-worker-0" "scheduler"="default" "toleration"={"key":"celeste/hostname","operator":"Equal","value":"gpu5","effect":"NoExecute"}
I0722 01:31:40.576244   23824 placement_manager.go:147]  "msg"="Adding toleration to pod"  "podName"="tf2-keras-cifar10-inceptionv3-elastic-20210722-122034-launcher" "scheduler"="default" "toleration"={"key":"celeste/hostname","operator":"Exists","effect":"NoExecute"}
I0722 01:31:40.774880   23824 placement_manager.go:147]  "msg"="Adding toleration to pod"  "podName"="tf2-keras-cifar10-inceptionv3-elastic-20210722-122354-worker-1" "scheduler"="default" "toleration"={"key":"celeste/hostname","operator":"Equal","value":"gpu5","effect":"NoExecute"}
I0722 01:31:41.175922   23824 placement_manager.go:147]  "msg"="Adding toleration to pod"  "podName"="tf2-keras-cifar10-inceptionv3-elastic-20210722-122354-launcher" "scheduler"="default" "toleration"={"key":"celeste/hostname","operator":"Exists","effect":"NoExecute"}
I0722 01:31:41.575942   23824 placement_manager.go:147]  "msg"="Adding toleration to pod"  "podName"="tf2-keras-cifar10-inceptionv3-elastic-20210722-122611-worker-1" "scheduler"="default" "toleration"={"key":"celeste/hostname","operator":"Equal","value":"gpu3","effect":"NoExecute"}
I0722 01:31:54.581638   23824 placement_manager.go:147]  "msg"="Adding toleration to pod"  "podName"="tf2-keras-cifar10-inceptionv3-elastic-20210722-122611-worker-0" "scheduler"="default" "toleration"={"key":"celeste/hostname","operator":"Equal","value":"gpu3","effect":"NoExecute"}
I0722 01:34:45.086413   23824 scheduler.go:474]  "msg"="Training job completed"  "elaspedTotalSeconds"=3978.177853247 "gpuTotalSeconds"=3325.246018305 "job"="tf2-keras-transformer-elastic-20210722-122826" "ranTotalSeconds"=2560.153116724 "scheduler"="default" "waitedTotalSeconds"=1418.024736523
I0722 01:34:45.086572   23824 scheduler.go:135]  "msg"="Received resched event, may be blocked because of rate limit"  "blockedUntil"="2021-07-22T01:33:40.013590161+08:00" "lastResched"="2021-07-22T01:31:40.013590161+08:00" "received"="2021-07-22T01:34:45.086457946+08:00" "scheduler"="default"
I0722 01:34:45.087082   23824 scheduler.go:159]  "msg"="Started resched"  "scheduler"="default"
I0722 01:34:45.087119   23824 scheduler.go:193]  "msg"="Updating all jobs info"  "scheduler"="default"
I0722 01:34:45.092262   23824 afsl.go:65]  "msg"="Finished scheduling"  "algorithm"="AFS-L" "freeGpu"=0 "result"={"tf2-keras-cifar10-inceptionv3-elastic-20210722-121943":2,"tf2-keras-cifar10-inceptionv3-elastic-20210722-122034":1,"tf2-keras-cifar10-inceptionv3-elastic-20210722-122250":1,"tf2-keras-cifar10-inceptionv3-elastic-20210722-122354":1,"tf2-keras-cifar10-inceptionv3-elastic-20210722-122611":3,"tf2-keras-cifar10-inceptionv3-elastic-20210722-122710":4} "scheduler"="default"
I0722 01:34:45.092567   23824 scheduler.go:384]  "msg"="Trying to delete multiple training jobs"  "jobs"=[] "scheduler"="default"
I0722 01:34:45.092856   23824 scheduler.go:342]  "msg"="Trying to scale multiple training jobs"  "jobs"=["tf2-keras-cifar10-inceptionv3-elastic-20210722-122354"] "scheduler"="default"
I0722 01:34:45.107382   23824 scheduler.go:292]  "msg"="Trying to start multiple training jobs"  "jobs"=["tf2-keras-cifar10-inceptionv3-elastic-20210722-122250"] "scheduler"="default"
I0722 01:34:45.116793   23824 scheduler.go:342]  "msg"="Trying to scale multiple training jobs"  "jobs"=["tf2-keras-cifar10-inceptionv3-elastic-20210722-122611","tf2-keras-cifar10-inceptionv3-elastic-20210722-122710"] "scheduler"="default"
I0722 01:34:45.144046   23824 placement_manager.go:166]  "msg"="Started job placements adjustment"  "scheduler"="default"
I0722 01:34:45.144096   23824 placement_manager.go:192]  "msg"="Releasing slots"  "jobs"={"tf2-keras-cifar10-inceptionv3-elastic-20210722-121943":{},"tf2-keras-cifar10-inceptionv3-elastic-20210722-122034":{},"tf2-keras-cifar10-inceptionv3-elastic-20210722-122354":{},"tf2-keras-cifar10-inceptionv3-elastic-20210722-122611":{},"tf2-keras-cifar10-inceptionv3-elastic-20210722-122710":{},"tf2-keras-transformer-elastic-20210722-122826":{}} "nodes"={"gpu3":{},"gpu4":{},"gpu5":{}} "scheduler"="default"
I0722 01:34:45.144176   23824 placement_manager.go:250]  "msg"="Released slots"  "jobs"={"tf2-keras-cifar10-inceptionv3-elastic-20210722-121943":{},"tf2-keras-cifar10-inceptionv3-elastic-20210722-122034":{},"tf2-keras-cifar10-inceptionv3-elastic-20210722-122354":{},"tf2-keras-cifar10-inceptionv3-elastic-20210722-122611":{},"tf2-keras-cifar10-inceptionv3-elastic-20210722-122710":{},"tf2-keras-transformer-elastic-20210722-122826":{}} "nodes"={"gpu3":{},"gpu4":{},"gpu5":{}} "scheduler"="default"
I0722 01:34:45.144506   23824 placement_manager.go:305]  "msg"="Found best-fit"  "crossNode"=0 "nodes"=[{},{},{}] "requests"=[{},{},{},{},{},{},{},{},{},{},{},{}] "scheduler"="default"
I0722 01:34:45.144778   23824 placement_manager.go:339]  "msg"="nodeStates updated"  "new"={"gpu3":{},"gpu4":{},"gpu5":{}} "old"={"gpu3":{},"gpu4":{},"gpu5":{}} "scheduler"="default" "score"=8
I0722 01:34:45.144975   23824 placement_manager.go:387]  "msg"="jobStates updated"  "new"={"tf2-keras-cifar10-inceptionv3-elastic-20210722-121943":{},"tf2-keras-cifar10-inceptionv3-elastic-20210722-122034":{},"tf2-keras-cifar10-inceptionv3-elastic-20210722-122250":{},"tf2-keras-cifar10-inceptionv3-elastic-20210722-122354":{},"tf2-keras-cifar10-inceptionv3-elastic-20210722-122611":{},"tf2-keras-cifar10-inceptionv3-elastic-20210722-122710":{}} "old"={"tf2-keras-cifar10-inceptionv3-elastic-20210722-121943":{},"tf2-keras-cifar10-inceptionv3-elastic-20210722-122034":{},"tf2-keras-cifar10-inceptionv3-elastic-20210722-122354":{},"tf2-keras-cifar10-inceptionv3-elastic-20210722-122611":{},"tf2-keras-cifar10-inceptionv3-elastic-20210722-122710":{},"tf2-keras-transformer-elastic-20210722-122826":{}} "scheduler"="default"
I0722 01:34:45.145212   23824 placement_manager.go:434]  "msg"="podNodeName updated"  "launchersToDelete"=1 "new"={"tf2-keras-cifar10-inceptionv3-elastic-20210722-121943-worker-0":"gpu5","tf2-keras-cifar10-inceptionv3-elastic-20210722-121943-worker-1":"gpu5","tf2-keras-cifar10-inceptionv3-elastic-20210722-122034-worker-0":"gpu3","tf2-keras-cifar10-inceptionv3-elastic-20210722-122250-worker-0":"gpu5","tf2-keras-cifar10-inceptionv3-elastic-20210722-122354-worker-0":"gpu5","tf2-keras-cifar10-inceptionv3-elastic-20210722-122611-worker-0":"gpu3","tf2-keras-cifar10-inceptionv3-elastic-20210722-122611-worker-1":"gpu3","tf2-keras-cifar10-inceptionv3-elastic-20210722-122611-worker-2":"gpu3","tf2-keras-cifar10-inceptionv3-elastic-20210722-122710-worker-0":"gpu4","tf2-keras-cifar10-inceptionv3-elastic-20210722-122710-worker-1":"gpu4","tf2-keras-cifar10-inceptionv3-elastic-20210722-122710-worker-2":"gpu4","tf2-keras-cifar10-inceptionv3-elastic-20210722-122710-worker-3":"gpu4"} "old"={"tf2-keras-cifar10-inceptionv3-elastic-20210722-121943-worker-0":"gpu5","tf2-keras-cifar10-inceptionv3-elastic-20210722-121943-worker-1":"gpu5","tf2-keras-cifar10-inceptionv3-elastic-20210722-122034-worker-0":"gpu4","tf2-keras-cifar10-inceptionv3-elastic-20210722-122354-worker-0":"gpu5","tf2-keras-cifar10-inceptionv3-elastic-20210722-122354-worker-1":"gpu5","tf2-keras-cifar10-inceptionv3-elastic-20210722-122611-worker-0":"gpu3","tf2-keras-cifar10-inceptionv3-elastic-20210722-122611-worker-1":"gpu3","tf2-keras-cifar10-inceptionv3-elastic-20210722-122710-worker-0":"gpu4","tf2-keras-cifar10-inceptionv3-elastic-20210722-122710-worker-1":"gpu4","tf2-keras-cifar10-inceptionv3-elastic-20210722-122710-worker-2":"gpu4","tf2-keras-transformer-elastic-20210722-122826-worker-0":"gpu3","tf2-keras-transformer-elastic-20210722-122826-worker-1":"gpu3"} "scheduler"="default" "workersToDelete"=1
I0722 01:34:45.145465   23824 placement_manager.go:451]  "msg"="Deleting pod that need migration"  "podName"="tf2-keras-cifar10-inceptionv3-elastic-20210722-122034-worker-0" "scheduler"="default"
I0722 01:34:45.149601   23824 placement_manager.go:451]  "msg"="Deleting pod that need migration"  "podName"="tf2-keras-cifar10-inceptionv3-elastic-20210722-122034-launcher" "scheduler"="default"
I0722 01:34:45.153900   23824 placement_manager.go:183]  "msg"="Finished job placements adjustment"  "scheduler"="default"
I0722 01:34:45.154160   23824 scheduler.go:182]  "msg"="Finished resched"  "scheduler"="default"
I0722 01:34:46.481855   23824 placement_manager.go:147]  "msg"="Adding toleration to pod"  "podName"="tf2-keras-cifar10-inceptionv3-elastic-20210722-122611-worker-2" "scheduler"="default" "toleration"={"key":"celeste/hostname","operator":"Equal","value":"gpu3","effect":"NoExecute"}
I0722 01:34:46.679414   23824 placement_manager.go:147]  "msg"="Adding toleration to pod"  "podName"="tf2-keras-cifar10-inceptionv3-elastic-20210722-122250-worker-0" "scheduler"="default" "toleration"={"key":"celeste/hostname","operator":"Equal","value":"gpu5","effect":"NoExecute"}
I0722 01:34:47.079680   23824 placement_manager.go:147]  "msg"="Adding toleration to pod"  "podName"="tf2-keras-cifar10-inceptionv3-elastic-20210722-122250-launcher" "scheduler"="default" "toleration"={"key":"celeste/hostname","operator":"Exists","effect":"NoExecute"}
I0722 01:34:48.078650   23824 placement_manager.go:147]  "msg"="Adding toleration to pod"  "podName"="tf2-keras-cifar10-inceptionv3-elastic-20210722-122710-worker-3" "scheduler"="default" "toleration"={"key":"celeste/hostname","operator":"Equal","value":"gpu4","effect":"NoExecute"}
I0722 01:34:54.609441   23824 placement_manager.go:147]  "msg"="Adding toleration to pod"  "podName"="tf2-keras-cifar10-inceptionv3-elastic-20210722-122034-worker-0" "scheduler"="default" "toleration"={"key":"celeste/hostname","operator":"Equal","value":"gpu3","effect":"NoExecute"}
I0722 01:35:00.336989   23824 placement_manager.go:147]  "msg"="Adding toleration to pod"  "podName"="tf2-keras-cifar10-inceptionv3-elastic-20210722-122034-launcher" "scheduler"="default" "toleration"={"key":"celeste/hostname","operator":"Exists","effect":"NoExecute"}
I0722 01:40:15.402322   23824 scheduler.go:474]  "msg"="Training job completed"  "elaspedTotalSeconds"=4384.92004718 "gpuTotalSeconds"=4835.361468742 "job"="tf2-keras-cifar10-inceptionv3-elastic-20210722-122710" "ranTotalSeconds"=2770.159642187 "scheduler"="default" "waitedTotalSeconds"=1614.760404993
I0722 01:40:15.402530   23824 scheduler.go:135]  "msg"="Received resched event, may be blocked because of rate limit"  "blockedUntil"="2021-07-22T01:36:45.154418584+08:00" "lastResched"="2021-07-22T01:34:45.154418584+08:00" "received"="2021-07-22T01:40:15.402378765+08:00" "scheduler"="default"
I0722 01:40:15.403209   23824 scheduler.go:159]  "msg"="Started resched"  "scheduler"="default"
I0722 01:40:15.403288   23824 scheduler.go:193]  "msg"="Updating all jobs info"  "scheduler"="default"
I0722 01:40:15.408312   23824 afsl.go:65]  "msg"="Finished scheduling"  "algorithm"="AFS-L" "freeGpu"=0 "result"={"tf2-keras-cifar10-inceptionv3-elastic-20210722-121943":2,"tf2-keras-cifar10-inceptionv3-elastic-20210722-122034":2,"tf2-keras-cifar10-inceptionv3-elastic-20210722-122250":2,"tf2-keras-cifar10-inceptionv3-elastic-20210722-122354":3,"tf2-keras-cifar10-inceptionv3-elastic-20210722-122611":3} "scheduler"="default"
I0722 01:40:15.408685   23824 scheduler.go:384]  "msg"="Trying to delete multiple training jobs"  "jobs"=[] "scheduler"="default"
I0722 01:40:15.409008   23824 scheduler.go:342]  "msg"="Trying to scale multiple training jobs"  "jobs"=[] "scheduler"="default"
I0722 01:40:15.409250   23824 scheduler.go:292]  "msg"="Trying to start multiple training jobs"  "jobs"=[] "scheduler"="default"
I0722 01:40:15.409471   23824 scheduler.go:342]  "msg"="Trying to scale multiple training jobs"  "jobs"=["tf2-keras-cifar10-inceptionv3-elastic-20210722-122034","tf2-keras-cifar10-inceptionv3-elastic-20210722-122250","tf2-keras-cifar10-inceptionv3-elastic-20210722-122354"] "scheduler"="default"
I0722 01:40:15.459381   23824 placement_manager.go:166]  "msg"="Started job placements adjustment"  "scheduler"="default"
I0722 01:40:15.459480   23824 placement_manager.go:192]  "msg"="Releasing slots"  "jobs"={"tf2-keras-cifar10-inceptionv3-elastic-20210722-121943":{},"tf2-keras-cifar10-inceptionv3-elastic-20210722-122034":{},"tf2-keras-cifar10-inceptionv3-elastic-20210722-122250":{},"tf2-keras-cifar10-inceptionv3-elastic-20210722-122354":{},"tf2-keras-cifar10-inceptionv3-elastic-20210722-122611":{},"tf2-keras-cifar10-inceptionv3-elastic-20210722-122710":{}} "nodes"={"gpu3":{},"gpu4":{},"gpu5":{}} "scheduler"="default"
I0722 01:40:15.459547   23824 placement_manager.go:250]  "msg"="Released slots"  "jobs"={"tf2-keras-cifar10-inceptionv3-elastic-20210722-121943":{},"tf2-keras-cifar10-inceptionv3-elastic-20210722-122034":{},"tf2-keras-cifar10-inceptionv3-elastic-20210722-122250":{},"tf2-keras-cifar10-inceptionv3-elastic-20210722-122354":{},"tf2-keras-cifar10-inceptionv3-elastic-20210722-122611":{},"tf2-keras-cifar10-inceptionv3-elastic-20210722-122710":{}} "nodes"={"gpu3":{},"gpu4":{},"gpu5":{}} "scheduler"="default"
I0722 01:40:15.460078   23824 placement_manager.go:305]  "msg"="Found best-fit"  "crossNode"=0 "nodes"=[{},{},{}] "requests"=[{},{},{},{},{},{},{},{},{},{}] "scheduler"="default"
I0722 01:40:15.460414   23824 placement_manager.go:339]  "msg"="nodeStates updated"  "new"={"gpu3":{},"gpu4":{},"gpu5":{}} "old"={"gpu3":{},"gpu4":{},"gpu5":{}} "scheduler"="default" "score"=7
I0722 01:40:15.460741   23824 placement_manager.go:387]  "msg"="jobStates updated"  "new"={"tf2-keras-cifar10-inceptionv3-elastic-20210722-121943":{},"tf2-keras-cifar10-inceptionv3-elastic-20210722-122034":{},"tf2-keras-cifar10-inceptionv3-elastic-20210722-122250":{},"tf2-keras-cifar10-inceptionv3-elastic-20210722-122354":{},"tf2-keras-cifar10-inceptionv3-elastic-20210722-122611":{}} "old"={"tf2-keras-cifar10-inceptionv3-elastic-20210722-121943":{},"tf2-keras-cifar10-inceptionv3-elastic-20210722-122034":{},"tf2-keras-cifar10-inceptionv3-elastic-20210722-122250":{},"tf2-keras-cifar10-inceptionv3-elastic-20210722-122354":{},"tf2-keras-cifar10-inceptionv3-elastic-20210722-122611":{},"tf2-keras-cifar10-inceptionv3-elastic-20210722-122710":{}} "scheduler"="default"
I0722 01:40:15.461154   23824 placement_manager.go:434]  "msg"="podNodeName updated"  "launchersToDelete"=0 "new"={"tf2-keras-cifar10-inceptionv3-elastic-20210722-121943-worker-0":"gpu5","tf2-keras-cifar10-inceptionv3-elastic-20210722-121943-worker-1":"gpu5","tf2-keras-cifar10-inceptionv3-elastic-20210722-122034-worker-0":"gpu4","tf2-keras-cifar10-inceptionv3-elastic-20210722-122034-worker-1":"gpu3","tf2-keras-cifar10-inceptionv3-elastic-20210722-122034-worker-2":"gpu3","tf2-keras-cifar10-inceptionv3-elastic-20210722-122250-worker-0":"gpu5","tf2-keras-cifar10-inceptionv3-elastic-20210722-122250-worker-1":"gpu5","tf2-keras-cifar10-inceptionv3-elastic-20210722-122354-worker-0":"gpu4","tf2-keras-cifar10-inceptionv3-elastic-20210722-122354-worker-1":"gpu4","tf2-keras-cifar10-inceptionv3-elastic-20210722-122354-worker-2":"gpu4","tf2-keras-cifar10-inceptionv3-elastic-20210722-122611-worker-0":"gpu3","tf2-keras-cifar10-inceptionv3-elastic-20210722-122611-worker-1":"gpu3","tf2-keras-cifar10-inceptionv3-elastic-20210722-122611-worker-2":"gpu3"} "old"={"tf2-keras-cifar10-inceptionv3-elastic-20210722-121943-worker-0":"gpu5","tf2-keras-cifar10-inceptionv3-elastic-20210722-121943-worker-1":"gpu5","tf2-keras-cifar10-inceptionv3-elastic-20210722-122034-worker-0":"gpu3","tf2-keras-cifar10-inceptionv3-elastic-20210722-122250-worker-0":"gpu5","tf2-keras-cifar10-inceptionv3-elastic-20210722-122354-worker-0":"gpu5","tf2-keras-cifar10-inceptionv3-elastic-20210722-122611-worker-0":"gpu3","tf2-keras-cifar10-inceptionv3-elastic-20210722-122611-worker-1":"gpu3","tf2-keras-cifar10-inceptionv3-elastic-20210722-122611-worker-2":"gpu3","tf2-keras-cifar10-inceptionv3-elastic-20210722-122710-worker-0":"gpu4","tf2-keras-cifar10-inceptionv3-elastic-20210722-122710-worker-1":"gpu4","tf2-keras-cifar10-inceptionv3-elastic-20210722-122710-worker-2":"gpu4","tf2-keras-cifar10-inceptionv3-elastic-20210722-122710-worker-3":"gpu4"} "scheduler"="default" "workersToDelete"=2
I0722 01:40:15.461393   23824 placement_manager.go:451]  "msg"="Deleting pod that need migration"  "podName"="tf2-keras-cifar10-inceptionv3-elastic-20210722-122354-worker-0" "scheduler"="default"
I0722 01:40:15.465129   23824 placement_manager.go:451]  "msg"="Deleting pod that need migration"  "podName"="tf2-keras-cifar10-inceptionv3-elastic-20210722-122034-worker-0" "scheduler"="default"
I0722 01:40:15.470778   23824 placement_manager.go:183]  "msg"="Finished job placements adjustment"  "scheduler"="default"
I0722 01:40:15.471099   23824 scheduler.go:182]  "msg"="Finished resched"  "scheduler"="default"
I0722 01:40:15.794070   23824 placement_manager.go:147]  "msg"="Adding toleration to pod"  "podName"="tf2-keras-cifar10-inceptionv3-elastic-20210722-122034-worker-1" "scheduler"="default" "toleration"={"key":"celeste/hostname","operator":"Equal","value":"gpu3","effect":"NoExecute"}
I0722 01:40:16.791736   23824 placement_manager.go:147]  "msg"="Adding toleration to pod"  "podName"="tf2-keras-cifar10-inceptionv3-elastic-20210722-122250-worker-1" "scheduler"="default" "toleration"={"key":"celeste/hostname","operator":"Equal","value":"gpu5","effect":"NoExecute"}
I0722 01:40:16.991361   23824 placement_manager.go:147]  "msg"="Adding toleration to pod"  "podName"="tf2-keras-cifar10-inceptionv3-elastic-20210722-122354-worker-1" "scheduler"="default" "toleration"={"key":"celeste/hostname","operator":"Equal","value":"gpu4","effect":"NoExecute"}
I0722 01:40:17.389035   23824 placement_manager.go:147]  "msg"="Adding toleration to pod"  "podName"="tf2-keras-cifar10-inceptionv3-elastic-20210722-122354-worker-2" "scheduler"="default" "toleration"={"key":"celeste/hostname","operator":"Equal","value":"gpu4","effect":"NoExecute"}
I0722 01:40:29.283078   23824 placement_manager.go:147]  "msg"="Adding toleration to pod"  "podName"="tf2-keras-cifar10-inceptionv3-elastic-20210722-122034-worker-0" "scheduler"="default" "toleration"={"key":"celeste/hostname","operator":"Equal","value":"gpu4","effect":"NoExecute"}
I0722 01:40:29.729857   23824 placement_manager.go:147]  "msg"="Adding toleration to pod"  "podName"="tf2-keras-cifar10-inceptionv3-elastic-20210722-122354-worker-0" "scheduler"="default" "toleration"={"key":"celeste/hostname","operator":"Equal","value":"gpu4","effect":"NoExecute"}
I0722 01:47:51.716490   23824 scheduler.go:474]  "msg"="Training job completed"  "elaspedTotalSeconds"=5286.804976056 "gpuTotalSeconds"=4596.633994709 "job"="tf2-keras-cifar10-inceptionv3-elastic-20210722-121943" "ranTotalSeconds"=3155.72902059 "scheduler"="default" "waitedTotalSeconds"=2131.075955466
I0722 01:47:51.716639   23824 scheduler.go:135]  "msg"="Received resched event, may be blocked because of rate limit"  "blockedUntil"="2021-07-22T01:42:15.471300961+08:00" "lastResched"="2021-07-22T01:40:15.471300961+08:00" "received"="2021-07-22T01:47:51.716527209+08:00" "scheduler"="default"
I0722 01:47:51.717129   23824 scheduler.go:159]  "msg"="Started resched"  "scheduler"="default"
I0722 01:47:51.717192   23824 scheduler.go:193]  "msg"="Updating all jobs info"  "scheduler"="default"
I0722 01:47:51.720884   23824 afsl.go:65]  "msg"="Finished scheduling"  "algorithm"="AFS-L" "freeGpu"=0 "result"={"tf2-keras-cifar10-inceptionv3-elastic-20210722-122034":1,"tf2-keras-cifar10-inceptionv3-elastic-20210722-122250":3,"tf2-keras-cifar10-inceptionv3-elastic-20210722-122354":4,"tf2-keras-cifar10-inceptionv3-elastic-20210722-122611":4} "scheduler"="default"
I0722 01:47:51.721169   23824 scheduler.go:384]  "msg"="Trying to delete multiple training jobs"  "jobs"=[] "scheduler"="default"
I0722 01:47:51.721460   23824 scheduler.go:342]  "msg"="Trying to scale multiple training jobs"  "jobs"=["tf2-keras-cifar10-inceptionv3-elastic-20210722-122034"] "scheduler"="default"
I0722 01:47:51.736751   23824 scheduler.go:292]  "msg"="Trying to start multiple training jobs"  "jobs"=[] "scheduler"="default"
I0722 01:47:51.737109   23824 scheduler.go:342]  "msg"="Trying to scale multiple training jobs"  "jobs"=["tf2-keras-cifar10-inceptionv3-elastic-20210722-122250","tf2-keras-cifar10-inceptionv3-elastic-20210722-122354","tf2-keras-cifar10-inceptionv3-elastic-20210722-122611"] "scheduler"="default"
I0722 01:47:51.786350   23824 placement_manager.go:166]  "msg"="Started job placements adjustment"  "scheduler"="default"
I0722 01:47:51.786410   23824 placement_manager.go:192]  "msg"="Releasing slots"  "jobs"={"tf2-keras-cifar10-inceptionv3-elastic-20210722-121943":{},"tf2-keras-cifar10-inceptionv3-elastic-20210722-122034":{},"tf2-keras-cifar10-inceptionv3-elastic-20210722-122250":{},"tf2-keras-cifar10-inceptionv3-elastic-20210722-122354":{},"tf2-keras-cifar10-inceptionv3-elastic-20210722-122611":{}} "nodes"={"gpu3":{},"gpu4":{},"gpu5":{}} "scheduler"="default"
I0722 01:47:51.786453   23824 placement_manager.go:250]  "msg"="Released slots"  "jobs"={"tf2-keras-cifar10-inceptionv3-elastic-20210722-121943":{},"tf2-keras-cifar10-inceptionv3-elastic-20210722-122034":{},"tf2-keras-cifar10-inceptionv3-elastic-20210722-122250":{},"tf2-keras-cifar10-inceptionv3-elastic-20210722-122354":{},"tf2-keras-cifar10-inceptionv3-elastic-20210722-122611":{}} "nodes"={"gpu3":{},"gpu4":{},"gpu5":{}} "scheduler"="default"
I0722 01:47:51.786929   23824 placement_manager.go:305]  "msg"="Found best-fit"  "crossNode"=0 "nodes"=[{},{},{}] "requests"=[{},{},{},{},{},{},{},{}] "scheduler"="default"
I0722 01:47:51.787150   23824 placement_manager.go:339]  "msg"="nodeStates updated"  "new"={"gpu3":{},"gpu4":{},"gpu5":{}} "old"={"gpu3":{},"gpu4":{},"gpu5":{}} "scheduler"="default" "score"=8
I0722 01:47:51.787366   23824 placement_manager.go:387]  "msg"="jobStates updated"  "new"={"tf2-keras-cifar10-inceptionv3-elastic-20210722-122034":{},"tf2-keras-cifar10-inceptionv3-elastic-20210722-122250":{},"tf2-keras-cifar10-inceptionv3-elastic-20210722-122354":{},"tf2-keras-cifar10-inceptionv3-elastic-20210722-122611":{}} "old"={"tf2-keras-cifar10-inceptionv3-elastic-20210722-121943":{},"tf2-keras-cifar10-inceptionv3-elastic-20210722-122034":{},"tf2-keras-cifar10-inceptionv3-elastic-20210722-122250":{},"tf2-keras-cifar10-inceptionv3-elastic-20210722-122354":{},"tf2-keras-cifar10-inceptionv3-elastic-20210722-122611":{}} "scheduler"="default"
I0722 01:47:51.787630   23824 placement_manager.go:434]  "msg"="podNodeName updated"  "launchersToDelete"=1 "new"={"tf2-keras-cifar10-inceptionv3-elastic-20210722-122034-worker-0":"gpu5","tf2-keras-cifar10-inceptionv3-elastic-20210722-122250-worker-0":"gpu5","tf2-keras-cifar10-inceptionv3-elastic-20210722-122250-worker-1":"gpu5","tf2-keras-cifar10-inceptionv3-elastic-20210722-122250-worker-2":"gpu5","tf2-keras-cifar10-inceptionv3-elastic-20210722-122354-worker-0":"gpu4","tf2-keras-cifar10-inceptionv3-elastic-20210722-122354-worker-1":"gpu4","tf2-keras-cifar10-inceptionv3-elastic-20210722-122354-worker-2":"gpu4","tf2-keras-cifar10-inceptionv3-elastic-20210722-122354-worker-3":"gpu4","tf2-keras-cifar10-inceptionv3-elastic-20210722-122611-worker-0":"gpu3","tf2-keras-cifar10-inceptionv3-elastic-20210722-122611-worker-1":"gpu3","tf2-keras-cifar10-inceptionv3-elastic-20210722-122611-worker-2":"gpu3","tf2-keras-cifar10-inceptionv3-elastic-20210722-122611-worker-3":"gpu3"} "old"={"tf2-keras-cifar10-inceptionv3-elastic-20210722-121943-worker-0":"gpu5","tf2-keras-cifar10-inceptionv3-elastic-20210722-121943-worker-1":"gpu5","tf2-keras-cifar10-inceptionv3-elastic-20210722-122034-worker-0":"gpu4","tf2-keras-cifar10-inceptionv3-elastic-20210722-122034-worker-1":"gpu3","tf2-keras-cifar10-inceptionv3-elastic-20210722-122034-worker-2":"gpu3","tf2-keras-cifar10-inceptionv3-elastic-20210722-122250-worker-0":"gpu5","tf2-keras-cifar10-inceptionv3-elastic-20210722-122250-worker-1":"gpu5","tf2-keras-cifar10-inceptionv3-elastic-20210722-122354-worker-0":"gpu4","tf2-keras-cifar10-inceptionv3-elastic-20210722-122354-worker-1":"gpu4","tf2-keras-cifar10-inceptionv3-elastic-20210722-122354-worker-2":"gpu4","tf2-keras-cifar10-inceptionv3-elastic-20210722-122611-worker-0":"gpu3","tf2-keras-cifar10-inceptionv3-elastic-20210722-122611-worker-1":"gpu3","tf2-keras-cifar10-inceptionv3-elastic-20210722-122611-worker-2":"gpu3"} "scheduler"="default" "workersToDelete"=1
I0722 01:47:51.787936   23824 placement_manager.go:451]  "msg"="Deleting pod that need migration"  "podName"="tf2-keras-cifar10-inceptionv3-elastic-20210722-122034-worker-0" "scheduler"="default"
I0722 01:47:51.792579   23824 placement_manager.go:451]  "msg"="Deleting pod that need migration"  "podName"="tf2-keras-cifar10-inceptionv3-elastic-20210722-122034-launcher" "scheduler"="default"
I0722 01:47:51.798595   23824 placement_manager.go:183]  "msg"="Finished job placements adjustment"  "scheduler"="default"
I0722 01:47:51.798829   23824 scheduler.go:182]  "msg"="Finished resched"  "scheduler"="default"
I0722 01:47:52.310738   23824 placement_manager.go:147]  "msg"="Adding toleration to pod"  "podName"="tf2-keras-cifar10-inceptionv3-elastic-20210722-122250-worker-2" "scheduler"="default" "toleration"={"key":"celeste/hostname","operator":"Equal","value":"gpu5","effect":"NoExecute"}
I0722 01:47:53.506926   23824 placement_manager.go:147]  "msg"="Adding toleration to pod"  "podName"="tf2-keras-cifar10-inceptionv3-elastic-20210722-122354-worker-3" "scheduler"="default" "toleration"={"key":"celeste/hostname","operator":"Equal","value":"gpu4","effect":"NoExecute"}
I0722 01:47:53.705184   23824 placement_manager.go:147]  "msg"="Adding toleration to pod"  "podName"="tf2-keras-cifar10-inceptionv3-elastic-20210722-122611-worker-3" "scheduler"="default" "toleration"={"key":"celeste/hostname","operator":"Equal","value":"gpu3","effect":"NoExecute"}
I0722 01:48:04.589454   23824 placement_manager.go:147]  "msg"="Adding toleration to pod"  "podName"="tf2-keras-cifar10-inceptionv3-elastic-20210722-122034-worker-0" "scheduler"="default" "toleration"={"key":"celeste/hostname","operator":"Equal","value":"gpu5","effect":"NoExecute"}
I0722 01:48:09.289246   23824 placement_manager.go:147]  "msg"="Adding toleration to pod"  "podName"="tf2-keras-cifar10-inceptionv3-elastic-20210722-122034-launcher" "scheduler"="default" "toleration"={"key":"celeste/hostname","operator":"Exists","effect":"NoExecute"}
I0722 01:48:23.871922   23824 scheduler.go:474]  "msg"="Training job completed"  "elaspedTotalSeconds"=4928.784435043 "gpuTotalSeconds"=5105.296216201 "job"="tf2-keras-cifar10-inceptionv3-elastic-20210722-122611" "ranTotalSeconds"=3255.174724436 "scheduler"="default" "waitedTotalSeconds"=1673.609710607
I0722 01:48:23.872067   23824 scheduler.go:135]  "msg"="Received resched event, may be blocked because of rate limit"  "blockedUntil"="2021-07-22T01:49:51.799103603+08:00" "lastResched"="2021-07-22T01:47:51.799103603+08:00" "received"="2021-07-22T01:48:23.871954404+08:00" "scheduler"="default"
I0722 01:49:51.799164   23824 scheduler.go:159]  "msg"="Started resched"  "scheduler"="default"
I0722 01:49:51.799214   23824 scheduler.go:193]  "msg"="Updating all jobs info"  "scheduler"="default"
I0722 01:49:51.801970   23824 afsl.go:65]  "msg"="Finished scheduling"  "algorithm"="AFS-L" "freeGpu"=0 "result"={"tf2-keras-cifar10-inceptionv3-elastic-20210722-122034":4,"tf2-keras-cifar10-inceptionv3-elastic-20210722-122250":4,"tf2-keras-cifar10-inceptionv3-elastic-20210722-122354":4} "scheduler"="default"
I0722 01:49:51.802232   23824 scheduler.go:384]  "msg"="Trying to delete multiple training jobs"  "jobs"=[] "scheduler"="default"
I0722 01:49:51.802541   23824 scheduler.go:342]  "msg"="Trying to scale multiple training jobs"  "jobs"=[] "scheduler"="default"
I0722 01:49:51.802754   23824 scheduler.go:292]  "msg"="Trying to start multiple training jobs"  "jobs"=[] "scheduler"="default"
I0722 01:49:51.802953   23824 scheduler.go:342]  "msg"="Trying to scale multiple training jobs"  "jobs"=["tf2-keras-cifar10-inceptionv3-elastic-20210722-122034","tf2-keras-cifar10-inceptionv3-elastic-20210722-122250"] "scheduler"="default"
I0722 01:49:51.842132   23824 placement_manager.go:166]  "msg"="Started job placements adjustment"  "scheduler"="default"
I0722 01:49:51.842199   23824 placement_manager.go:192]  "msg"="Releasing slots"  "jobs"={"tf2-keras-cifar10-inceptionv3-elastic-20210722-122034":{},"tf2-keras-cifar10-inceptionv3-elastic-20210722-122250":{},"tf2-keras-cifar10-inceptionv3-elastic-20210722-122354":{},"tf2-keras-cifar10-inceptionv3-elastic-20210722-122611":{}} "nodes"={"gpu3":{},"gpu4":{},"gpu5":{}} "scheduler"="default"
I0722 01:49:51.842249   23824 placement_manager.go:250]  "msg"="Released slots"  "jobs"={"tf2-keras-cifar10-inceptionv3-elastic-20210722-122034":{},"tf2-keras-cifar10-inceptionv3-elastic-20210722-122250":{},"tf2-keras-cifar10-inceptionv3-elastic-20210722-122354":{},"tf2-keras-cifar10-inceptionv3-elastic-20210722-122611":{}} "nodes"={"gpu3":{},"gpu4":{},"gpu5":{}} "scheduler"="default"
I0722 01:49:51.842569   23824 placement_manager.go:305]  "msg"="Found best-fit"  "crossNode"=0 "nodes"=[{},{},{}] "requests"=[{},{},{},{},{},{}] "scheduler"="default"
I0722 01:49:51.842846   23824 placement_manager.go:339]  "msg"="nodeStates updated"  "new"={"gpu3":{},"gpu4":{},"gpu5":{}} "old"={"gpu3":{},"gpu4":{},"gpu5":{}} "scheduler"="default" "score"=7
I0722 01:49:51.843193   23824 placement_manager.go:387]  "msg"="jobStates updated"  "new"={"tf2-keras-cifar10-inceptionv3-elastic-20210722-122034":{},"tf2-keras-cifar10-inceptionv3-elastic-20210722-122250":{},"tf2-keras-cifar10-inceptionv3-elastic-20210722-122354":{}} "old"={"tf2-keras-cifar10-inceptionv3-elastic-20210722-122034":{},"tf2-keras-cifar10-inceptionv3-elastic-20210722-122250":{},"tf2-keras-cifar10-inceptionv3-elastic-20210722-122354":{},"tf2-keras-cifar10-inceptionv3-elastic-20210722-122611":{}} "scheduler"="default"
I0722 01:49:51.843492   23824 placement_manager.go:434]  "msg"="podNodeName updated"  "launchersToDelete"=0 "new"={"tf2-keras-cifar10-inceptionv3-elastic-20210722-122034-worker-0":"gpu3","tf2-keras-cifar10-inceptionv3-elastic-20210722-122034-worker-1":"gpu3","tf2-keras-cifar10-inceptionv3-elastic-20210722-122034-worker-2":"gpu3","tf2-keras-cifar10-inceptionv3-elastic-20210722-122034-worker-3":"gpu3","tf2-keras-cifar10-inceptionv3-elastic-20210722-122250-worker-0":"gpu5","tf2-keras-cifar10-inceptionv3-elastic-20210722-122250-worker-1":"gpu5","tf2-keras-cifar10-inceptionv3-elastic-20210722-122250-worker-2":"gpu5","tf2-keras-cifar10-inceptionv3-elastic-20210722-122250-worker-3":"gpu5","tf2-keras-cifar10-inceptionv3-elastic-20210722-122354-worker-0":"gpu4","tf2-keras-cifar10-inceptionv3-elastic-20210722-122354-worker-1":"gpu4","tf2-keras-cifar10-inceptionv3-elastic-20210722-122354-worker-2":"gpu4","tf2-keras-cifar10-inceptionv3-elastic-20210722-122354-worker-3":"gpu4"} "old"={"tf2-keras-cifar10-inceptionv3-elastic-20210722-122034-worker-0":"gpu5","tf2-keras-cifar10-inceptionv3-elastic-20210722-122250-worker-0":"gpu5","tf2-keras-cifar10-inceptionv3-elastic-20210722-122250-worker-1":"gpu5","tf2-keras-cifar10-inceptionv3-elastic-20210722-122250-worker-2":"gpu5","tf2-keras-cifar10-inceptionv3-elastic-20210722-122354-worker-0":"gpu4","tf2-keras-cifar10-inceptionv3-elastic-20210722-122354-worker-1":"gpu4","tf2-keras-cifar10-inceptionv3-elastic-20210722-122354-worker-2":"gpu4","tf2-keras-cifar10-inceptionv3-elastic-20210722-122354-worker-3":"gpu4","tf2-keras-cifar10-inceptionv3-elastic-20210722-122611-worker-0":"gpu3","tf2-keras-cifar10-inceptionv3-elastic-20210722-122611-worker-1":"gpu3","tf2-keras-cifar10-inceptionv3-elastic-20210722-122611-worker-2":"gpu3","tf2-keras-cifar10-inceptionv3-elastic-20210722-122611-worker-3":"gpu3"} "scheduler"="default" "workersToDelete"=1
I0722 01:49:51.843797   23824 placement_manager.go:451]  "msg"="Deleting pod that need migration"  "podName"="tf2-keras-cifar10-inceptionv3-elastic-20210722-122034-worker-0" "scheduler"="default"
I0722 01:49:51.849006   23824 placement_manager.go:183]  "msg"="Finished job placements adjustment"  "scheduler"="default"
I0722 01:49:51.849308   23824 scheduler.go:182]  "msg"="Finished resched"  "scheduler"="default"
I0722 01:49:51.867482   23824 placement_manager.go:147]  "msg"="Adding toleration to pod"  "podName"="tf2-keras-cifar10-inceptionv3-elastic-20210722-122034-worker-1" "scheduler"="default" "toleration"={"key":"celeste/hostname","operator":"Equal","value":"gpu3","effect":"NoExecute"}
I0722 01:49:51.905861   23824 placement_manager.go:147]  "msg"="Adding toleration to pod"  "podName"="tf2-keras-cifar10-inceptionv3-elastic-20210722-122250-worker-3" "scheduler"="default" "toleration"={"key":"celeste/hostname","operator":"Equal","value":"gpu5","effect":"NoExecute"}
I0722 01:49:51.916415   23824 placement_manager.go:147]  "msg"="Adding toleration to pod"  "podName"="tf2-keras-cifar10-inceptionv3-elastic-20210722-122034-worker-2" "scheduler"="default" "toleration"={"key":"celeste/hostname","operator":"Equal","value":"gpu3","effect":"NoExecute"}
I0722 01:49:51.928177   23824 placement_manager.go:147]  "msg"="Adding toleration to pod"  "podName"="tf2-keras-cifar10-inceptionv3-elastic-20210722-122034-worker-3" "scheduler"="default" "toleration"={"key":"celeste/hostname","operator":"Equal","value":"gpu3","effect":"NoExecute"}
I0722 01:50:09.762267   23824 placement_manager.go:147]  "msg"="Adding toleration to pod"  "podName"="tf2-keras-cifar10-inceptionv3-elastic-20210722-122034-worker-0" "scheduler"="default" "toleration"={"key":"celeste/hostname","operator":"Equal","value":"gpu3","effect":"NoExecute"}
I0722 01:54:30.069766   23824 scheduler.go:474]  "msg"="Training job completed"  "elaspedTotalSeconds"=5435.295162351 "gpuTotalSeconds"=5470.963944825 "job"="tf2-keras-cifar10-inceptionv3-elastic-20210722-122354" "ranTotalSeconds"=3170.832112383 "scheduler"="default" "waitedTotalSeconds"=2264.463049968
I0722 01:54:30.070126   23824 scheduler.go:135]  "msg"="Received resched event, may be blocked because of rate limit"  "blockedUntil"="2021-07-22T01:51:51.849540284+08:00" "lastResched"="2021-07-22T01:49:51.849540284+08:00" "received"="2021-07-22T01:54:30.069818254+08:00" "scheduler"="default"
I0722 01:54:30.070698   23824 scheduler.go:159]  "msg"="Started resched"  "scheduler"="default"
I0722 01:54:30.070770   23824 scheduler.go:193]  "msg"="Updating all jobs info"  "scheduler"="default"
I0722 01:54:30.073336   23824 afsl.go:65]  "msg"="Finished scheduling"  "algorithm"="AFS-L" "freeGpu"=4 "result"={"tf2-keras-cifar10-inceptionv3-elastic-20210722-122034":4,"tf2-keras-cifar10-inceptionv3-elastic-20210722-122250":4} "scheduler"="default"
I0722 01:54:30.073594   23824 scheduler.go:384]  "msg"="Trying to delete multiple training jobs"  "jobs"=[] "scheduler"="default"
I0722 01:54:30.073933   23824 scheduler.go:342]  "msg"="Trying to scale multiple training jobs"  "jobs"=[] "scheduler"="default"
I0722 01:54:30.074191   23824 scheduler.go:292]  "msg"="Trying to start multiple training jobs"  "jobs"=[] "scheduler"="default"
I0722 01:54:30.074410   23824 scheduler.go:342]  "msg"="Trying to scale multiple training jobs"  "jobs"=[] "scheduler"="default"
I0722 01:54:30.074789   23824 scheduler.go:180]  "msg"="Nothing changed, skipped ajust placements"  "scheduler"="default"
I0722 01:54:30.074825   23824 scheduler.go:182]  "msg"="Finished resched"  "scheduler"="default"
I0722 01:58:06.651983   23824 scheduler.go:474]  "msg"="Training job completed"  "elaspedTotalSeconds"=5714.109095043 "gpuTotalSeconds"=5376.139468396 "job"="tf2-keras-cifar10-inceptionv3-elastic-20210722-122250" "ranTotalSeconds"=3196.066879943 "scheduler"="default" "waitedTotalSeconds"=2518.0422151
I0722 01:58:06.652186   23824 scheduler.go:135]  "msg"="Received resched event, may be blocked because of rate limit"  "blockedUntil"="2021-07-22T01:56:30.075080202+08:00" "lastResched"="2021-07-22T01:54:30.075080202+08:00" "received"="2021-07-22T01:58:06.652034292+08:00" "scheduler"="default"
I0722 01:58:06.652793   23824 scheduler.go:159]  "msg"="Started resched"  "scheduler"="default"
I0722 01:58:06.652830   23824 scheduler.go:193]  "msg"="Updating all jobs info"  "scheduler"="default"
I0722 01:58:06.654623   23824 afsl.go:65]  "msg"="Finished scheduling"  "algorithm"="AFS-L" "freeGpu"=8 "result"={"tf2-keras-cifar10-inceptionv3-elastic-20210722-122034":4} "scheduler"="default"
I0722 01:58:06.654892   23824 scheduler.go:384]  "msg"="Trying to delete multiple training jobs"  "jobs"=[] "scheduler"="default"
I0722 01:58:06.655176   23824 scheduler.go:342]  "msg"="Trying to scale multiple training jobs"  "jobs"=[] "scheduler"="default"
I0722 01:58:06.655485   23824 scheduler.go:292]  "msg"="Trying to start multiple training jobs"  "jobs"=[] "scheduler"="default"
I0722 01:58:06.655748   23824 scheduler.go:342]  "msg"="Trying to scale multiple training jobs"  "jobs"=[] "scheduler"="default"
I0722 01:58:06.656022   23824 scheduler.go:180]  "msg"="Nothing changed, skipped ajust placements"  "scheduler"="default"
I0722 01:58:06.656056   23824 scheduler.go:182]  "msg"="Finished resched"  "scheduler"="default"
I0722 01:59:59.864822   23824 scheduler.go:474]  "msg"="Training job completed"  "elaspedTotalSeconds"=5960.884306449 "gpuTotalSeconds"=5850.554233577 "job"="tf2-keras-cifar10-inceptionv3-elastic-20210722-122034" "ranTotalSeconds"=3340.468508087 "scheduler"="default" "waitedTotalSeconds"=2620.415798362
I0722 01:59:59.865000   23824 scheduler.go:135]  "msg"="Received resched event, may be blocked because of rate limit"  "blockedUntil"="2021-07-22T02:00:06.656247153+08:00" "lastResched"="2021-07-22T01:58:06.656247153+08:00" "received"="2021-07-22T01:59:59.864863872+08:00" "scheduler"="default"
I0722 02:00:06.656292   23824 scheduler.go:159]  "msg"="Started resched"  "scheduler"="default"
I0722 02:00:06.656330   23824 scheduler.go:193]  "msg"="Updating all jobs info"  "scheduler"="default"
I0722 02:00:06.656827   23824 afsl.go:65]  "msg"="Finished scheduling"  "algorithm"="AFS-L" "freeGpu"=12 "result"={} "scheduler"="default"
I0722 02:00:06.657045   23824 scheduler.go:384]  "msg"="Trying to delete multiple training jobs"  "jobs"=[] "scheduler"="default"
I0722 02:00:06.657189   23824 scheduler.go:342]  "msg"="Trying to scale multiple training jobs"  "jobs"=[] "scheduler"="default"
I0722 02:00:06.657330   23824 scheduler.go:292]  "msg"="Trying to start multiple training jobs"  "jobs"=[] "scheduler"="default"
I0722 02:00:06.657474   23824 scheduler.go:342]  "msg"="Trying to scale multiple training jobs"  "jobs"=[] "scheduler"="default"
I0722 02:00:06.657610   23824 scheduler.go:180]  "msg"="Nothing changed, skipped ajust placements"  "scheduler"="default"
I0722 02:00:06.657625   23824 scheduler.go:182]  "msg"="Finished resched"  "scheduler"="default"
