Log file created at: 2021/07/23 04:14:43
Running on machine: gpu4
Binary: Built with gc go1.13.15 for linux/amd64
Log line format: [IWEF]mmdd hh:mm:ss.uuuuuu threadid file:line] msg
I0723 04:14:43.818104   16467 main.go:19]  "msg"="Celeste - DLT jobs scheduler"  "version"="0.0.1"
I0723 04:14:43.818925   16467 main.go:20]  "msg"="Starting service"  
I0723 04:14:43.824173   16467 placement_manager.go:65]  "msg"="Starting placement manager"  "scheduler"="default"
I0723 04:14:43.824875   16467 placement_manager.go:95]  "msg"="Started placement manager"  "nodes"={"gpu3":{},"gpu4":{},"gpu5":{}} "scheduler"="default"
I0723 04:14:43.825431   16467 jobmaster.go:82]  "msg"="Starting scheduler"  "gpuType"="default"
I0723 04:14:43.825521   16467 scheduler.go:124]  "msg"="Starting scheduler"  "scheduler"="default"
I0723 04:14:43.854955   16467 scheduler.go:432]  "msg"="Start watching mpijob"  "scheduler"="default"
I0723 04:15:09.201767   16467 jobmaster.go:155]  "msg"="Training job created"  "job"="tf2-keras-cifar10-inceptionv3-elastic-20210723-041509"
I0723 04:15:09.201936   16467 scheduler.go:135]  "msg"="Received resched event, may be blocked because of rate limit"  "blockedUntil"="2021-07-23T04:14:43.825396063+08:00" "lastResched"="2021-07-23T04:14:43.825396369+08:00" "received"="2021-07-23T04:15:09.20101255+08:00" "scheduler"="default"
I0723 04:15:09.202567   16467 scheduler.go:159]  "msg"="Started resched"  "scheduler"="default"
I0723 04:15:09.202638   16467 scheduler.go:193]  "msg"="Updating all jobs info"  "scheduler"="default"
I0723 04:15:09.204518   16467 elastic_fifo.go:73]  "msg"="Finished scheduling"  "algorithm"="ElasticFIFO" "freeGpu"=8 "result"={"tf2-keras-cifar10-inceptionv3-elastic-20210723-041509":4} "scheduler"="default"
I0723 04:15:09.204840   16467 scheduler.go:384]  "msg"="Trying to delete multiple training jobs"  "jobs"=[] "scheduler"="default"
I0723 04:15:09.205194   16467 scheduler.go:342]  "msg"="Trying to scale multiple training jobs"  "jobs"=[] "scheduler"="default"
I0723 04:15:09.205472   16467 scheduler.go:292]  "msg"="Trying to start multiple training jobs"  "jobs"=["tf2-keras-cifar10-inceptionv3-elastic-20210723-041509"] "scheduler"="default"
I0723 04:15:09.228439   16467 scheduler.go:342]  "msg"="Trying to scale multiple training jobs"  "jobs"=[] "scheduler"="default"
I0723 04:15:09.230129   16467 placement_manager.go:166]  "msg"="Started job placements adjustment"  "scheduler"="default"
I0723 04:15:09.230204   16467 placement_manager.go:192]  "msg"="Releasing slots"  "jobs"={} "nodes"={"gpu3":{},"gpu4":{},"gpu5":{}} "scheduler"="default"
I0723 04:15:09.230231   16467 placement_manager.go:250]  "msg"="Released slots"  "jobs"={} "nodes"={"gpu3":{},"gpu4":{},"gpu5":{}} "scheduler"="default"
I0723 04:15:09.230598   16467 placement_manager.go:305]  "msg"="Found best-fit"  "crossNode"=0 "nodes"=[{},{},{}] "requests"=[{},{}] "scheduler"="default"
I0723 04:15:09.230921   16467 placement_manager.go:339]  "msg"="nodeStates updated"  "new"={"gpu3":{},"gpu4":{},"gpu5":{}} "old"={"gpu3":{},"gpu4":{},"gpu5":{}} "scheduler"="default" "score"=0
I0723 04:15:09.231295   16467 placement_manager.go:387]  "msg"="jobStates updated"  "new"={"tf2-keras-cifar10-inceptionv3-elastic-20210723-041509":{}} "old"={} "scheduler"="default"
I0723 04:15:09.231603   16467 placement_manager.go:434]  "msg"="podNodeName updated"  "launchersToDelete"=0 "new"={"tf2-keras-cifar10-inceptionv3-elastic-20210723-041509-worker-0":"gpu3","tf2-keras-cifar10-inceptionv3-elastic-20210723-041509-worker-1":"gpu3","tf2-keras-cifar10-inceptionv3-elastic-20210723-041509-worker-2":"gpu3","tf2-keras-cifar10-inceptionv3-elastic-20210723-041509-worker-3":"gpu3"} "old"={} "scheduler"="default" "workersToDelete"=0
I0723 04:15:09.231901   16467 placement_manager.go:183]  "msg"="Finished job placements adjustment"  "scheduler"="default"
I0723 04:15:09.232172   16467 scheduler.go:182]  "msg"="Finished resched"  "scheduler"="default"
I0723 04:15:09.292243   16467 placement_manager.go:147]  "msg"="Adding toleration to pod"  "podName"="tf2-keras-cifar10-inceptionv3-elastic-20210723-041509-worker-0" "scheduler"="default" "toleration"={"key":"celeste/hostname","operator":"Equal","value":"gpu3","effect":"NoExecute"}
I0723 04:15:09.326355   16467 placement_manager.go:147]  "msg"="Adding toleration to pod"  "podName"="tf2-keras-cifar10-inceptionv3-elastic-20210723-041509-worker-1" "scheduler"="default" "toleration"={"key":"celeste/hostname","operator":"Equal","value":"gpu3","effect":"NoExecute"}
I0723 04:15:09.336067   16467 placement_manager.go:147]  "msg"="Adding toleration to pod"  "podName"="tf2-keras-cifar10-inceptionv3-elastic-20210723-041509-worker-2" "scheduler"="default" "toleration"={"key":"celeste/hostname","operator":"Equal","value":"gpu3","effect":"NoExecute"}
I0723 04:15:09.348321   16467 placement_manager.go:147]  "msg"="Adding toleration to pod"  "podName"="tf2-keras-cifar10-inceptionv3-elastic-20210723-041509-worker-3" "scheduler"="default" "toleration"={"key":"celeste/hostname","operator":"Equal","value":"gpu3","effect":"NoExecute"}
I0723 04:15:09.356849   16467 placement_manager.go:147]  "msg"="Adding toleration to pod"  "podName"="tf2-keras-cifar10-inceptionv3-elastic-20210723-041509-launcher" "scheduler"="default" "toleration"={"key":"celeste/hostname","operator":"Exists","effect":"NoExecute"}
I0723 04:15:16.160753   16467 jobmaster.go:155]  "msg"="Training job created"  "job"="tf2-keras-cifar10-resnet50-elastic-20210723-041516"
I0723 04:15:16.160912   16467 scheduler.go:135]  "msg"="Received resched event, may be blocked because of rate limit"  "blockedUntil"="2021-07-23T04:17:09.232357379+08:00" "lastResched"="2021-07-23T04:15:09.232357379+08:00" "received"="2021-07-23T04:15:16.159976725+08:00" "scheduler"="default"
I0723 04:15:21.106337   16467 jobmaster.go:155]  "msg"="Training job created"  "job"="tf2-keras-cifar10-inceptionv3-elastic-20210723-041521"
I0723 04:15:51.128555   16467 jobmaster.go:155]  "msg"="Training job created"  "job"="tf2-keras-cifar10-vgg16-elastic-20210723-041551"
I0723 04:16:18.112123   16467 jobmaster.go:155]  "msg"="Training job created"  "job"="tf2-keras-cifar10-vgg16-elastic-20210723-041618"
I0723 04:17:09.232451   16467 scheduler.go:159]  "msg"="Started resched"  "scheduler"="default"
I0723 04:17:09.232537   16467 scheduler.go:193]  "msg"="Updating all jobs info"  "scheduler"="default"
I0723 04:17:09.239465   16467 elastic_fifo.go:73]  "msg"="Finished scheduling"  "algorithm"="ElasticFIFO" "freeGpu"=0 "result"={"tf2-keras-cifar10-inceptionv3-elastic-20210723-041509":3,"tf2-keras-cifar10-inceptionv3-elastic-20210723-041521":2,"tf2-keras-cifar10-resnet50-elastic-20210723-041516":3,"tf2-keras-cifar10-vgg16-elastic-20210723-041551":2,"tf2-keras-cifar10-vgg16-elastic-20210723-041618":2} "scheduler"="default"
I0723 04:17:09.240001   16467 scheduler.go:384]  "msg"="Trying to delete multiple training jobs"  "jobs"=[] "scheduler"="default"
I0723 04:17:09.240523   16467 scheduler.go:342]  "msg"="Trying to scale multiple training jobs"  "jobs"=["tf2-keras-cifar10-inceptionv3-elastic-20210723-041509"] "scheduler"="default"
I0723 04:17:09.267432   16467 scheduler.go:292]  "msg"="Trying to start multiple training jobs"  "jobs"=["tf2-keras-cifar10-resnet50-elastic-20210723-041516","tf2-keras-cifar10-inceptionv3-elastic-20210723-041521","tf2-keras-cifar10-vgg16-elastic-20210723-041551","tf2-keras-cifar10-vgg16-elastic-20210723-041618"] "scheduler"="default"
I0723 04:17:09.298783   16467 scheduler.go:342]  "msg"="Trying to scale multiple training jobs"  "jobs"=[] "scheduler"="default"
I0723 04:17:09.302216   16467 placement_manager.go:166]  "msg"="Started job placements adjustment"  "scheduler"="default"
I0723 04:17:09.302298   16467 placement_manager.go:192]  "msg"="Releasing slots"  "jobs"={"tf2-keras-cifar10-inceptionv3-elastic-20210723-041509":{}} "nodes"={"gpu3":{},"gpu4":{},"gpu5":{}} "scheduler"="default"
I0723 04:17:09.302365   16467 placement_manager.go:250]  "msg"="Released slots"  "jobs"={"tf2-keras-cifar10-inceptionv3-elastic-20210723-041509":{}} "nodes"={"gpu3":{},"gpu4":{},"gpu5":{}} "scheduler"="default"
I0723 04:17:09.303017   16467 placement_manager.go:305]  "msg"="Found best-fit"  "crossNode"=0 "nodes"=[{},{},{}] "requests"=[{},{},{},{},{},{},{},{},{},{}] "scheduler"="default"
I0723 04:17:09.303512   16467 placement_manager.go:339]  "msg"="nodeStates updated"  "new"={"gpu3":{},"gpu4":{},"gpu5":{}} "old"={"gpu3":{},"gpu4":{},"gpu5":{}} "scheduler"="default" "score"=3
I0723 04:17:09.303937   16467 placement_manager.go:387]  "msg"="jobStates updated"  "new"={"tf2-keras-cifar10-inceptionv3-elastic-20210723-041509":{},"tf2-keras-cifar10-inceptionv3-elastic-20210723-041521":{},"tf2-keras-cifar10-resnet50-elastic-20210723-041516":{},"tf2-keras-cifar10-vgg16-elastic-20210723-041551":{},"tf2-keras-cifar10-vgg16-elastic-20210723-041618":{}} "old"={"tf2-keras-cifar10-inceptionv3-elastic-20210723-041509":{}} "scheduler"="default"
I0723 04:17:09.304395   16467 placement_manager.go:434]  "msg"="podNodeName updated"  "launchersToDelete"=0 "new"={"tf2-keras-cifar10-inceptionv3-elastic-20210723-041509-worker-0":"gpu3","tf2-keras-cifar10-inceptionv3-elastic-20210723-041509-worker-1":"gpu3","tf2-keras-cifar10-inceptionv3-elastic-20210723-041509-worker-2":"gpu3","tf2-keras-cifar10-inceptionv3-elastic-20210723-041521-worker-0":"gpu3","tf2-keras-cifar10-inceptionv3-elastic-20210723-041521-worker-1":"gpu4","tf2-keras-cifar10-inceptionv3-elastic-20210723-041521-worker-2":"gpu4","tf2-keras-cifar10-resnet50-elastic-20210723-041516-worker-0":"gpu4","tf2-keras-cifar10-resnet50-elastic-20210723-041516-worker-1":"gpu4","tf2-keras-cifar10-resnet50-elastic-20210723-041516-worker-2":"gpu4","tf2-keras-cifar10-vgg16-elastic-20210723-041551-worker-0":"gpu5","tf2-keras-cifar10-vgg16-elastic-20210723-041551-worker-1":"gpu5","tf2-keras-cifar10-vgg16-elastic-20210723-041618-worker-0":"gpu5","tf2-keras-cifar10-vgg16-elastic-20210723-041618-worker-1":"gpu5"} "old"={"tf2-keras-cifar10-inceptionv3-elastic-20210723-041509-worker-0":"gpu3","tf2-keras-cifar10-inceptionv3-elastic-20210723-041509-worker-1":"gpu3","tf2-keras-cifar10-inceptionv3-elastic-20210723-041509-worker-2":"gpu3","tf2-keras-cifar10-inceptionv3-elastic-20210723-041509-worker-3":"gpu3"} "scheduler"="default" "workersToDelete"=0
I0723 04:17:09.304791   16467 placement_manager.go:183]  "msg"="Finished job placements adjustment"  "scheduler"="default"
I0723 04:17:09.305061   16467 scheduler.go:182]  "msg"="Finished resched"  "scheduler"="default"
I0723 04:17:10.080642   16467 placement_manager.go:147]  "msg"="Adding toleration to pod"  "podName"="tf2-keras-cifar10-resnet50-elastic-20210723-041516-worker-0" "scheduler"="default" "toleration"={"key":"celeste/hostname","operator":"Equal","value":"gpu4","effect":"NoExecute"}
I0723 04:17:10.479362   16467 placement_manager.go:147]  "msg"="Adding toleration to pod"  "podName"="tf2-keras-cifar10-resnet50-elastic-20210723-041516-worker-1" "scheduler"="default" "toleration"={"key":"celeste/hostname","operator":"Equal","value":"gpu4","effect":"NoExecute"}
I0723 04:17:10.880921   16467 placement_manager.go:147]  "msg"="Adding toleration to pod"  "podName"="tf2-keras-cifar10-resnet50-elastic-20210723-041516-worker-2" "scheduler"="default" "toleration"={"key":"celeste/hostname","operator":"Equal","value":"gpu4","effect":"NoExecute"}
I0723 04:17:11.279299   16467 placement_manager.go:147]  "msg"="Adding toleration to pod"  "podName"="tf2-keras-cifar10-resnet50-elastic-20210723-041516-launcher" "scheduler"="default" "toleration"={"key":"celeste/hostname","operator":"Exists","effect":"NoExecute"}
I0723 04:17:11.480046   16467 placement_manager.go:147]  "msg"="Adding toleration to pod"  "podName"="tf2-keras-cifar10-inceptionv3-elastic-20210723-041521-worker-0" "scheduler"="default" "toleration"={"key":"celeste/hostname","operator":"Equal","value":"gpu3","effect":"NoExecute"}
I0723 04:17:12.087944   16467 placement_manager.go:147]  "msg"="Adding toleration to pod"  "podName"="tf2-keras-cifar10-inceptionv3-elastic-20210723-041521-worker-1" "scheduler"="default" "toleration"={"key":"celeste/hostname","operator":"Equal","value":"gpu4","effect":"NoExecute"}
I0723 04:17:12.487634   16467 placement_manager.go:147]  "msg"="Adding toleration to pod"  "podName"="tf2-keras-cifar10-inceptionv3-elastic-20210723-041521-launcher" "scheduler"="default" "toleration"={"key":"celeste/hostname","operator":"Exists","effect":"NoExecute"}
I0723 04:17:13.282881   16467 placement_manager.go:147]  "msg"="Adding toleration to pod"  "podName"="tf2-keras-cifar10-vgg16-elastic-20210723-041551-worker-0" "scheduler"="default" "toleration"={"key":"celeste/hostname","operator":"Equal","value":"gpu5","effect":"NoExecute"}
I0723 04:17:13.690933   16467 placement_manager.go:147]  "msg"="Adding toleration to pod"  "podName"="tf2-keras-cifar10-vgg16-elastic-20210723-041551-worker-1" "scheduler"="default" "toleration"={"key":"celeste/hostname","operator":"Equal","value":"gpu5","effect":"NoExecute"}
I0723 04:17:14.087479   16467 placement_manager.go:147]  "msg"="Adding toleration to pod"  "podName"="tf2-keras-cifar10-vgg16-elastic-20210723-041551-launcher" "scheduler"="default" "toleration"={"key":"celeste/hostname","operator":"Exists","effect":"NoExecute"}
I0723 04:17:14.490772   16467 placement_manager.go:147]  "msg"="Adding toleration to pod"  "podName"="tf2-keras-cifar10-vgg16-elastic-20210723-041618-worker-0" "scheduler"="default" "toleration"={"key":"celeste/hostname","operator":"Equal","value":"gpu5","effect":"NoExecute"}
I0723 04:17:14.889331   16467 placement_manager.go:147]  "msg"="Adding toleration to pod"  "podName"="tf2-keras-cifar10-vgg16-elastic-20210723-041618-worker-1" "scheduler"="default" "toleration"={"key":"celeste/hostname","operator":"Equal","value":"gpu5","effect":"NoExecute"}
I0723 04:17:15.289926   16467 placement_manager.go:147]  "msg"="Adding toleration to pod"  "podName"="tf2-keras-cifar10-vgg16-elastic-20210723-041618-launcher" "scheduler"="default" "toleration"={"key":"celeste/hostname","operator":"Exists","effect":"NoExecute"}
I0723 04:17:53.044738   16467 jobmaster.go:155]  "msg"="Training job created"  "job"="tf2-keras-transformer-elastic-20210723-041753"
I0723 04:17:53.044927   16467 scheduler.go:135]  "msg"="Received resched event, may be blocked because of rate limit"  "blockedUntil"="2021-07-23T04:19:09.305415064+08:00" "lastResched"="2021-07-23T04:17:09.305415064+08:00" "received"="2021-07-23T04:17:53.044107324+08:00" "scheduler"="default"
I0723 04:19:09.305559   16467 scheduler.go:159]  "msg"="Started resched"  "scheduler"="default"
I0723 04:19:09.305625   16467 scheduler.go:193]  "msg"="Updating all jobs info"  "scheduler"="default"
I0723 04:19:09.312396   16467 elastic_fifo.go:73]  "msg"="Finished scheduling"  "algorithm"="ElasticFIFO" "freeGpu"=0 "result"={"tf2-keras-cifar10-inceptionv3-elastic-20210723-041509":2,"tf2-keras-cifar10-inceptionv3-elastic-20210723-041521":2,"tf2-keras-cifar10-resnet50-elastic-20210723-041516":2,"tf2-keras-cifar10-vgg16-elastic-20210723-041551":2,"tf2-keras-cifar10-vgg16-elastic-20210723-041618":2,"tf2-keras-transformer-elastic-20210723-041753":2} "scheduler"="default"
I0723 04:19:09.312781   16467 scheduler.go:384]  "msg"="Trying to delete multiple training jobs"  "jobs"=[] "scheduler"="default"
I0723 04:19:09.313157   16467 scheduler.go:342]  "msg"="Trying to scale multiple training jobs"  "jobs"=["tf2-keras-cifar10-inceptionv3-elastic-20210723-041509","tf2-keras-cifar10-resnet50-elastic-20210723-041516"] "scheduler"="default"
I0723 04:19:09.348932   16467 scheduler.go:292]  "msg"="Trying to start multiple training jobs"  "jobs"=["tf2-keras-transformer-elastic-20210723-041753"] "scheduler"="default"
I0723 04:19:09.357786   16467 scheduler.go:342]  "msg"="Trying to scale multiple training jobs"  "jobs"=[] "scheduler"="default"
I0723 04:19:09.360778   16467 placement_manager.go:166]  "msg"="Started job placements adjustment"  "scheduler"="default"
I0723 04:19:09.360865   16467 placement_manager.go:192]  "msg"="Releasing slots"  "jobs"={"tf2-keras-cifar10-inceptionv3-elastic-20210723-041509":{},"tf2-keras-cifar10-inceptionv3-elastic-20210723-041521":{},"tf2-keras-cifar10-resnet50-elastic-20210723-041516":{},"tf2-keras-cifar10-vgg16-elastic-20210723-041551":{},"tf2-keras-cifar10-vgg16-elastic-20210723-041618":{}} "nodes"={"gpu3":{},"gpu4":{},"gpu5":{}} "scheduler"="default"
I0723 04:19:09.360927   16467 placement_manager.go:250]  "msg"="Released slots"  "jobs"={"tf2-keras-cifar10-inceptionv3-elastic-20210723-041509":{},"tf2-keras-cifar10-inceptionv3-elastic-20210723-041521":{},"tf2-keras-cifar10-resnet50-elastic-20210723-041516":{},"tf2-keras-cifar10-vgg16-elastic-20210723-041551":{},"tf2-keras-cifar10-vgg16-elastic-20210723-041618":{}} "nodes"={"gpu3":{},"gpu4":{},"gpu5":{}} "scheduler"="default"
I0723 04:19:09.361348   16467 placement_manager.go:305]  "msg"="Found best-fit"  "crossNode"=0 "nodes"=[{},{},{}] "requests"=[{},{},{},{},{},{},{},{},{},{},{},{}] "scheduler"="default"
I0723 04:19:09.361627   16467 placement_manager.go:339]  "msg"="nodeStates updated"  "new"={"gpu3":{},"gpu4":{},"gpu5":{}} "old"={"gpu3":{},"gpu4":{},"gpu5":{}} "scheduler"="default" "score"=5
I0723 04:19:09.361900   16467 placement_manager.go:387]  "msg"="jobStates updated"  "new"={"tf2-keras-cifar10-inceptionv3-elastic-20210723-041509":{},"tf2-keras-cifar10-inceptionv3-elastic-20210723-041521":{},"tf2-keras-cifar10-resnet50-elastic-20210723-041516":{},"tf2-keras-cifar10-vgg16-elastic-20210723-041551":{},"tf2-keras-cifar10-vgg16-elastic-20210723-041618":{},"tf2-keras-transformer-elastic-20210723-041753":{}} "old"={"tf2-keras-cifar10-inceptionv3-elastic-20210723-041509":{},"tf2-keras-cifar10-inceptionv3-elastic-20210723-041521":{},"tf2-keras-cifar10-resnet50-elastic-20210723-041516":{},"tf2-keras-cifar10-vgg16-elastic-20210723-041551":{},"tf2-keras-cifar10-vgg16-elastic-20210723-041618":{}} "scheduler"="default"
I0723 04:19:09.362336   16467 placement_manager.go:434]  "msg"="podNodeName updated"  "launchersToDelete"=2 "new"={"tf2-keras-cifar10-inceptionv3-elastic-20210723-041509-worker-0":"gpu4","tf2-keras-cifar10-inceptionv3-elastic-20210723-041509-worker-1":"gpu4","tf2-keras-cifar10-inceptionv3-elastic-20210723-041521-worker-0":"gpu3","tf2-keras-cifar10-inceptionv3-elastic-20210723-041521-worker-1":"gpu3","tf2-keras-cifar10-resnet50-elastic-20210723-041516-worker-0":"gpu4","tf2-keras-cifar10-resnet50-elastic-20210723-041516-worker-1":"gpu4","tf2-keras-cifar10-vgg16-elastic-20210723-041551-worker-0":"gpu3","tf2-keras-cifar10-vgg16-elastic-20210723-041551-worker-1":"gpu3","tf2-keras-cifar10-vgg16-elastic-20210723-041618-worker-0":"gpu5","tf2-keras-cifar10-vgg16-elastic-20210723-041618-worker-1":"gpu5","tf2-keras-transformer-elastic-20210723-041753-worker-0":"gpu5","tf2-keras-transformer-elastic-20210723-041753-worker-1":"gpu5"} "old"={"tf2-keras-cifar10-inceptionv3-elastic-20210723-041509-worker-0":"gpu3","tf2-keras-cifar10-inceptionv3-elastic-20210723-041509-worker-1":"gpu3","tf2-keras-cifar10-inceptionv3-elastic-20210723-041509-worker-2":"gpu3","tf2-keras-cifar10-inceptionv3-elastic-20210723-041521-worker-0":"gpu3","tf2-keras-cifar10-inceptionv3-elastic-20210723-041521-worker-1":"gpu4","tf2-keras-cifar10-inceptionv3-elastic-20210723-041521-worker-2":"gpu4","tf2-keras-cifar10-resnet50-elastic-20210723-041516-worker-0":"gpu4","tf2-keras-cifar10-resnet50-elastic-20210723-041516-worker-1":"gpu4","tf2-keras-cifar10-resnet50-elastic-20210723-041516-worker-2":"gpu4","tf2-keras-cifar10-vgg16-elastic-20210723-041551-worker-0":"gpu5","tf2-keras-cifar10-vgg16-elastic-20210723-041551-worker-1":"gpu5","tf2-keras-cifar10-vgg16-elastic-20210723-041618-worker-0":"gpu5","tf2-keras-cifar10-vgg16-elastic-20210723-041618-worker-1":"gpu5"} "scheduler"="default" "workersToDelete"=5
I0723 04:19:09.362589   16467 placement_manager.go:451]  "msg"="Deleting pod that need migration"  "podName"="tf2-keras-cifar10-inceptionv3-elastic-20210723-041509-worker-0" "scheduler"="default"
I0723 04:19:09.370011   16467 placement_manager.go:451]  "msg"="Deleting pod that need migration"  "podName"="tf2-keras-cifar10-inceptionv3-elastic-20210723-041509-worker-1" "scheduler"="default"
I0723 04:19:09.388305   16467 placement_manager.go:451]  "msg"="Deleting pod that need migration"  "podName"="tf2-keras-cifar10-inceptionv3-elastic-20210723-041509-launcher" "scheduler"="default"
I0723 04:19:09.396933   16467 placement_manager.go:451]  "msg"="Deleting pod that need migration"  "podName"="tf2-keras-cifar10-inceptionv3-elastic-20210723-041521-worker-1" "scheduler"="default"
I0723 04:19:09.400992   16467 placement_manager.go:451]  "msg"="Deleting pod that need migration"  "podName"="tf2-keras-cifar10-vgg16-elastic-20210723-041551-worker-0" "scheduler"="default"
I0723 04:19:09.404986   16467 placement_manager.go:451]  "msg"="Deleting pod that need migration"  "podName"="tf2-keras-cifar10-vgg16-elastic-20210723-041551-worker-1" "scheduler"="default"
I0723 04:19:09.408978   16467 placement_manager.go:451]  "msg"="Deleting pod that need migration"  "podName"="tf2-keras-cifar10-vgg16-elastic-20210723-041551-launcher" "scheduler"="default"
I0723 04:19:09.417538   16467 placement_manager.go:183]  "msg"="Finished job placements adjustment"  "scheduler"="default"
I0723 04:19:09.417878   16467 scheduler.go:182]  "msg"="Finished resched"  "scheduler"="default"
I0723 04:19:10.346268   16467 placement_manager.go:147]  "msg"="Adding toleration to pod"  "podName"="tf2-keras-transformer-elastic-20210723-041753-worker-0" "scheduler"="default" "toleration"={"key":"celeste/hostname","operator":"Equal","value":"gpu5","effect":"NoExecute"}
I0723 04:19:10.946302   16467 placement_manager.go:147]  "msg"="Adding toleration to pod"  "podName"="tf2-keras-transformer-elastic-20210723-041753-worker-1" "scheduler"="default" "toleration"={"key":"celeste/hostname","operator":"Equal","value":"gpu5","effect":"NoExecute"}
I0723 04:19:11.346277   16467 placement_manager.go:147]  "msg"="Adding toleration to pod"  "podName"="tf2-keras-transformer-elastic-20210723-041753-launcher" "scheduler"="default" "toleration"={"key":"celeste/hostname","operator":"Exists","effect":"NoExecute"}
I0723 04:19:18.525459   16467 placement_manager.go:147]  "msg"="Adding toleration to pod"  "podName"="tf2-keras-cifar10-inceptionv3-elastic-20210723-041509-launcher" "scheduler"="default" "toleration"={"key":"celeste/hostname","operator":"Exists","effect":"NoExecute"}
I0723 04:19:23.833149   16467 placement_manager.go:147]  "msg"="Adding toleration to pod"  "podName"="tf2-keras-cifar10-inceptionv3-elastic-20210723-041509-worker-0" "scheduler"="default" "toleration"={"key":"celeste/hostname","operator":"Equal","value":"gpu4","effect":"NoExecute"}
I0723 04:19:23.866056   16467 placement_manager.go:147]  "msg"="Adding toleration to pod"  "podName"="tf2-keras-cifar10-inceptionv3-elastic-20210723-041509-worker-1" "scheduler"="default" "toleration"={"key":"celeste/hostname","operator":"Equal","value":"gpu4","effect":"NoExecute"}
I0723 04:19:25.264333   16467 placement_manager.go:147]  "msg"="Adding toleration to pod"  "podName"="tf2-keras-cifar10-inceptionv3-elastic-20210723-041521-worker-1" "scheduler"="default" "toleration"={"key":"celeste/hostname","operator":"Equal","value":"gpu3","effect":"NoExecute"}
I0723 04:19:30.974439   16467 placement_manager.go:147]  "msg"="Adding toleration to pod"  "podName"="tf2-keras-cifar10-vgg16-elastic-20210723-041551-worker-1" "scheduler"="default" "toleration"={"key":"celeste/hostname","operator":"Equal","value":"gpu3","effect":"NoExecute"}
I0723 04:19:31.379751   16467 placement_manager.go:147]  "msg"="Adding toleration to pod"  "podName"="tf2-keras-cifar10-vgg16-elastic-20210723-041551-worker-0" "scheduler"="default" "toleration"={"key":"celeste/hostname","operator":"Equal","value":"gpu3","effect":"NoExecute"}
I0723 04:19:32.178608   16467 placement_manager.go:147]  "msg"="Adding toleration to pod"  "podName"="tf2-keras-cifar10-vgg16-elastic-20210723-041551-launcher" "scheduler"="default" "toleration"={"key":"celeste/hostname","operator":"Exists","effect":"NoExecute"}
I0723 04:28:36.112704   16467 jobmaster.go:155]  "msg"="Training job created"  "job"="tf2-keras-transformer-elastic-20210723-042836"
I0723 04:28:36.112803   16467 scheduler.go:135]  "msg"="Received resched event, may be blocked because of rate limit"  "blockedUntil"="2021-07-23T04:21:09.418143557+08:00" "lastResched"="2021-07-23T04:19:09.418143557+08:00" "received"="2021-07-23T04:28:36.112194768+08:00" "scheduler"="default"
I0723 04:28:36.113320   16467 scheduler.go:159]  "msg"="Started resched"  "scheduler"="default"
I0723 04:28:36.113402   16467 scheduler.go:193]  "msg"="Updating all jobs info"  "scheduler"="default"
I0723 04:28:36.120685   16467 elastic_fifo.go:73]  "msg"="Finished scheduling"  "algorithm"="ElasticFIFO" "freeGpu"=0 "result"={"tf2-keras-cifar10-inceptionv3-elastic-20210723-041509":2,"tf2-keras-cifar10-inceptionv3-elastic-20210723-041521":2,"tf2-keras-cifar10-resnet50-elastic-20210723-041516":2,"tf2-keras-cifar10-vgg16-elastic-20210723-041551":2,"tf2-keras-cifar10-vgg16-elastic-20210723-041618":2,"tf2-keras-transformer-elastic-20210723-041753":1,"tf2-keras-transformer-elastic-20210723-042836":1} "scheduler"="default"
I0723 04:28:36.121047   16467 scheduler.go:384]  "msg"="Trying to delete multiple training jobs"  "jobs"=[] "scheduler"="default"
I0723 04:28:36.121418   16467 scheduler.go:342]  "msg"="Trying to scale multiple training jobs"  "jobs"=["tf2-keras-transformer-elastic-20210723-041753"] "scheduler"="default"
I0723 04:28:36.141869   16467 scheduler.go:292]  "msg"="Trying to start multiple training jobs"  "jobs"=["tf2-keras-transformer-elastic-20210723-042836"] "scheduler"="default"
I0723 04:28:36.153616   16467 scheduler.go:342]  "msg"="Trying to scale multiple training jobs"  "jobs"=[] "scheduler"="default"
I0723 04:28:36.157072   16467 placement_manager.go:166]  "msg"="Started job placements adjustment"  "scheduler"="default"
I0723 04:28:36.157161   16467 placement_manager.go:192]  "msg"="Releasing slots"  "jobs"={"tf2-keras-cifar10-inceptionv3-elastic-20210723-041509":{},"tf2-keras-cifar10-inceptionv3-elastic-20210723-041521":{},"tf2-keras-cifar10-resnet50-elastic-20210723-041516":{},"tf2-keras-cifar10-vgg16-elastic-20210723-041551":{},"tf2-keras-cifar10-vgg16-elastic-20210723-041618":{},"tf2-keras-transformer-elastic-20210723-041753":{}} "nodes"={"gpu3":{},"gpu4":{},"gpu5":{}} "scheduler"="default"
I0723 04:28:36.157247   16467 placement_manager.go:250]  "msg"="Released slots"  "jobs"={"tf2-keras-cifar10-inceptionv3-elastic-20210723-041509":{},"tf2-keras-cifar10-inceptionv3-elastic-20210723-041521":{},"tf2-keras-cifar10-resnet50-elastic-20210723-041516":{},"tf2-keras-cifar10-vgg16-elastic-20210723-041551":{},"tf2-keras-cifar10-vgg16-elastic-20210723-041618":{},"tf2-keras-transformer-elastic-20210723-041753":{}} "nodes"={"gpu3":{},"gpu4":{},"gpu5":{}} "scheduler"="default"
I0723 04:28:36.157693   16467 placement_manager.go:305]  "msg"="Found best-fit"  "crossNode"=0 "nodes"=[{},{},{}] "requests"=[{},{},{},{},{},{},{},{},{},{},{},{},{},{}] "scheduler"="default"
I0723 04:28:36.157994   16467 placement_manager.go:339]  "msg"="nodeStates updated"  "new"={"gpu3":{},"gpu4":{},"gpu5":{}} "old"={"gpu3":{},"gpu4":{},"gpu5":{}} "scheduler"="default" "score"=11
I0723 04:28:36.158321   16467 placement_manager.go:387]  "msg"="jobStates updated"  "new"={"tf2-keras-cifar10-inceptionv3-elastic-20210723-041509":{},"tf2-keras-cifar10-inceptionv3-elastic-20210723-041521":{},"tf2-keras-cifar10-resnet50-elastic-20210723-041516":{},"tf2-keras-cifar10-vgg16-elastic-20210723-041551":{},"tf2-keras-cifar10-vgg16-elastic-20210723-041618":{},"tf2-keras-transformer-elastic-20210723-041753":{},"tf2-keras-transformer-elastic-20210723-042836":{}} "old"={"tf2-keras-cifar10-inceptionv3-elastic-20210723-041509":{},"tf2-keras-cifar10-inceptionv3-elastic-20210723-041521":{},"tf2-keras-cifar10-resnet50-elastic-20210723-041516":{},"tf2-keras-cifar10-vgg16-elastic-20210723-041551":{},"tf2-keras-cifar10-vgg16-elastic-20210723-041618":{},"tf2-keras-transformer-elastic-20210723-041753":{}} "scheduler"="default"
I0723 04:28:36.158697   16467 placement_manager.go:434]  "msg"="podNodeName updated"  "launchersToDelete"=0 "new"={"tf2-keras-cifar10-inceptionv3-elastic-20210723-041509-worker-0":"gpu4","tf2-keras-cifar10-inceptionv3-elastic-20210723-041509-worker-1":"gpu4","tf2-keras-cifar10-inceptionv3-elastic-20210723-041521-worker-0":"gpu3","tf2-keras-cifar10-inceptionv3-elastic-20210723-041521-worker-1":"gpu3","tf2-keras-cifar10-resnet50-elastic-20210723-041516-worker-0":"gpu4","tf2-keras-cifar10-resnet50-elastic-20210723-041516-worker-1":"gpu4","tf2-keras-cifar10-vgg16-elastic-20210723-041551-worker-0":"gpu3","tf2-keras-cifar10-vgg16-elastic-20210723-041551-worker-1":"gpu3","tf2-keras-cifar10-vgg16-elastic-20210723-041618-worker-0":"gpu5","tf2-keras-cifar10-vgg16-elastic-20210723-041618-worker-1":"gpu5","tf2-keras-transformer-elastic-20210723-041753-worker-0":"gpu5","tf2-keras-transformer-elastic-20210723-042836-worker-0":"gpu5"} "old"={"tf2-keras-cifar10-inceptionv3-elastic-20210723-041509-worker-0":"gpu4","tf2-keras-cifar10-inceptionv3-elastic-20210723-041509-worker-1":"gpu4","tf2-keras-cifar10-inceptionv3-elastic-20210723-041521-worker-0":"gpu3","tf2-keras-cifar10-inceptionv3-elastic-20210723-041521-worker-1":"gpu3","tf2-keras-cifar10-resnet50-elastic-20210723-041516-worker-0":"gpu4","tf2-keras-cifar10-resnet50-elastic-20210723-041516-worker-1":"gpu4","tf2-keras-cifar10-vgg16-elastic-20210723-041551-worker-0":"gpu3","tf2-keras-cifar10-vgg16-elastic-20210723-041551-worker-1":"gpu3","tf2-keras-cifar10-vgg16-elastic-20210723-041618-worker-0":"gpu5","tf2-keras-cifar10-vgg16-elastic-20210723-041618-worker-1":"gpu5","tf2-keras-transformer-elastic-20210723-041753-worker-0":"gpu5","tf2-keras-transformer-elastic-20210723-041753-worker-1":"gpu5"} "scheduler"="default" "workersToDelete"=0
I0723 04:28:36.159086   16467 placement_manager.go:183]  "msg"="Finished job placements adjustment"  "scheduler"="default"
I0723 04:28:36.159378   16467 scheduler.go:182]  "msg"="Finished resched"  "scheduler"="default"
I0723 04:28:36.556794   16467 placement_manager.go:147]  "msg"="Adding toleration to pod"  "podName"="tf2-keras-transformer-elastic-20210723-042836-worker-0" "scheduler"="default" "toleration"={"key":"celeste/hostname","operator":"Equal","value":"gpu5","effect":"NoExecute"}
I0723 04:28:36.958061   16467 placement_manager.go:147]  "msg"="Adding toleration to pod"  "podName"="tf2-keras-transformer-elastic-20210723-042836-launcher" "scheduler"="default" "toleration"={"key":"celeste/hostname","operator":"Exists","effect":"NoExecute"}
I0723 04:30:11.581269   16467 scheduler.go:474]  "msg"="Training job completed"  "elaspedTotalSeconds"=830.742553421 "gpuTotalSeconds"=1560.042775006 "job"="tf2-keras-cifar10-vgg16-elastic-20210723-041618" "ranTotalSeconds"=780.021387503 "scheduler"="default" "waitedTotalSeconds"=50.721165918
I0723 04:30:11.581407   16467 scheduler.go:135]  "msg"="Received resched event, may be blocked because of rate limit"  "blockedUntil"="2021-07-23T04:30:36.159629388+08:00" "lastResched"="2021-07-23T04:28:36.159629388+08:00" "received"="2021-07-23T04:30:11.581301937+08:00" "scheduler"="default"
I0723 04:30:18.544249   16467 scheduler.go:474]  "msg"="Training job completed"  "elaspedTotalSeconds"=862.726242176 "gpuTotalSeconds"=1570.043006652 "job"="tf2-keras-cifar10-vgg16-elastic-20210723-041551" "ranTotalSeconds"=785.021503326 "scheduler"="default" "waitedTotalSeconds"=77.70473885
I0723 04:30:36.159679   16467 scheduler.go:159]  "msg"="Started resched"  "scheduler"="default"
I0723 04:30:36.159721   16467 scheduler.go:193]  "msg"="Updating all jobs info"  "scheduler"="default"
I0723 04:30:36.164564   16467 elastic_fifo.go:73]  "msg"="Finished scheduling"  "algorithm"="ElasticFIFO" "freeGpu"=0 "result"={"tf2-keras-cifar10-inceptionv3-elastic-20210723-041509":3,"tf2-keras-cifar10-inceptionv3-elastic-20210723-041521":2,"tf2-keras-cifar10-resnet50-elastic-20210723-041516":3,"tf2-keras-transformer-elastic-20210723-041753":2,"tf2-keras-transformer-elastic-20210723-042836":2} "scheduler"="default"
I0723 04:30:36.164926   16467 scheduler.go:384]  "msg"="Trying to delete multiple training jobs"  "jobs"=[] "scheduler"="default"
I0723 04:30:36.165269   16467 scheduler.go:342]  "msg"="Trying to scale multiple training jobs"  "jobs"=[] "scheduler"="default"
I0723 04:30:36.165564   16467 scheduler.go:292]  "msg"="Trying to start multiple training jobs"  "jobs"=[] "scheduler"="default"
I0723 04:30:36.165904   16467 scheduler.go:342]  "msg"="Trying to scale multiple training jobs"  "jobs"=["tf2-keras-cifar10-inceptionv3-elastic-20210723-041509","tf2-keras-cifar10-resnet50-elastic-20210723-041516","tf2-keras-transformer-elastic-20210723-041753","tf2-keras-transformer-elastic-20210723-042836"] "scheduler"="default"
I0723 04:30:36.229920   16467 placement_manager.go:166]  "msg"="Started job placements adjustment"  "scheduler"="default"
I0723 04:30:36.230012   16467 placement_manager.go:192]  "msg"="Releasing slots"  "jobs"={"tf2-keras-cifar10-inceptionv3-elastic-20210723-041509":{},"tf2-keras-cifar10-inceptionv3-elastic-20210723-041521":{},"tf2-keras-cifar10-resnet50-elastic-20210723-041516":{},"tf2-keras-cifar10-vgg16-elastic-20210723-041551":{},"tf2-keras-cifar10-vgg16-elastic-20210723-041618":{},"tf2-keras-transformer-elastic-20210723-041753":{},"tf2-keras-transformer-elastic-20210723-042836":{}} "nodes"={"gpu3":{},"gpu4":{},"gpu5":{}} "scheduler"="default"
I0723 04:30:36.230083   16467 placement_manager.go:250]  "msg"="Released slots"  "jobs"={"tf2-keras-cifar10-inceptionv3-elastic-20210723-041509":{},"tf2-keras-cifar10-inceptionv3-elastic-20210723-041521":{},"tf2-keras-cifar10-resnet50-elastic-20210723-041516":{},"tf2-keras-cifar10-vgg16-elastic-20210723-041551":{},"tf2-keras-cifar10-vgg16-elastic-20210723-041618":{},"tf2-keras-transformer-elastic-20210723-041753":{},"tf2-keras-transformer-elastic-20210723-042836":{}} "nodes"={"gpu3":{},"gpu4":{},"gpu5":{}} "scheduler"="default"
I0723 04:30:36.230534   16467 placement_manager.go:305]  "msg"="Found best-fit"  "crossNode"=0 "nodes"=[{},{},{}] "requests"=[{},{},{},{},{},{},{},{},{},{}] "scheduler"="default"
I0723 04:30:36.230925   16467 placement_manager.go:339]  "msg"="nodeStates updated"  "new"={"gpu3":{},"gpu4":{},"gpu5":{}} "old"={"gpu3":{},"gpu4":{},"gpu5":{}} "scheduler"="default" "score"=5
I0723 04:30:36.231414   16467 placement_manager.go:387]  "msg"="jobStates updated"  "new"={"tf2-keras-cifar10-inceptionv3-elastic-20210723-041509":{},"tf2-keras-cifar10-inceptionv3-elastic-20210723-041521":{},"tf2-keras-cifar10-resnet50-elastic-20210723-041516":{},"tf2-keras-transformer-elastic-20210723-041753":{},"tf2-keras-transformer-elastic-20210723-042836":{}} "old"={"tf2-keras-cifar10-inceptionv3-elastic-20210723-041509":{},"tf2-keras-cifar10-inceptionv3-elastic-20210723-041521":{},"tf2-keras-cifar10-resnet50-elastic-20210723-041516":{},"tf2-keras-cifar10-vgg16-elastic-20210723-041551":{},"tf2-keras-cifar10-vgg16-elastic-20210723-041618":{},"tf2-keras-transformer-elastic-20210723-041753":{},"tf2-keras-transformer-elastic-20210723-042836":{}} "scheduler"="default"
I0723 04:30:36.231889   16467 placement_manager.go:434]  "msg"="podNodeName updated"  "launchersToDelete"=0 "new"={"tf2-keras-cifar10-inceptionv3-elastic-20210723-041509-worker-0":"gpu5","tf2-keras-cifar10-inceptionv3-elastic-20210723-041509-worker-1":"gpu5","tf2-keras-cifar10-inceptionv3-elastic-20210723-041509-worker-2":"gpu5","tf2-keras-cifar10-inceptionv3-elastic-20210723-041521-worker-0":"gpu3","tf2-keras-cifar10-inceptionv3-elastic-20210723-041521-worker-1":"gpu3","tf2-keras-cifar10-resnet50-elastic-20210723-041516-worker-0":"gpu4","tf2-keras-cifar10-resnet50-elastic-20210723-041516-worker-1":"gpu4","tf2-keras-cifar10-resnet50-elastic-20210723-041516-worker-2":"gpu4","tf2-keras-transformer-elastic-20210723-041753-worker-0":"gpu3","tf2-keras-transformer-elastic-20210723-041753-worker-1":"gpu3","tf2-keras-transformer-elastic-20210723-042836-worker-0":"gpu5","tf2-keras-transformer-elastic-20210723-042836-worker-1":"gpu4","tf2-keras-transformer-elastic-20210723-042836-worker-2":"gpu4"} "old"={"tf2-keras-cifar10-inceptionv3-elastic-20210723-041509-worker-0":"gpu4","tf2-keras-cifar10-inceptionv3-elastic-20210723-041509-worker-1":"gpu4","tf2-keras-cifar10-inceptionv3-elastic-20210723-041521-worker-0":"gpu3","tf2-keras-cifar10-inceptionv3-elastic-20210723-041521-worker-1":"gpu3","tf2-keras-cifar10-resnet50-elastic-20210723-041516-worker-0":"gpu4","tf2-keras-cifar10-resnet50-elastic-20210723-041516-worker-1":"gpu4","tf2-keras-cifar10-vgg16-elastic-20210723-041551-worker-0":"gpu3","tf2-keras-cifar10-vgg16-elastic-20210723-041551-worker-1":"gpu3","tf2-keras-cifar10-vgg16-elastic-20210723-041618-worker-0":"gpu5","tf2-keras-cifar10-vgg16-elastic-20210723-041618-worker-1":"gpu5","tf2-keras-transformer-elastic-20210723-041753-worker-0":"gpu5","tf2-keras-transformer-elastic-20210723-042836-worker-0":"gpu5"} "scheduler"="default" "workersToDelete"=3
I0723 04:30:36.232237   16467 placement_manager.go:451]  "msg"="Deleting pod that need migration"  "podName"="tf2-keras-cifar10-inceptionv3-elastic-20210723-041509-worker-0" "scheduler"="default"
I0723 04:30:36.245821   16467 placement_manager.go:147]  "msg"="Adding toleration to pod"  "podName"="tf2-keras-cifar10-resnet50-elastic-20210723-041516-worker-2" "scheduler"="default" "toleration"={"key":"celeste/hostname","operator":"Equal","value":"gpu4","effect":"NoExecute"}
I0723 04:30:36.246897   16467 placement_manager.go:451]  "msg"="Deleting pod that need migration"  "podName"="tf2-keras-cifar10-inceptionv3-elastic-20210723-041509-worker-1" "scheduler"="default"
I0723 04:30:36.252879   16467 placement_manager.go:451]  "msg"="Deleting pod that need migration"  "podName"="tf2-keras-transformer-elastic-20210723-041753-worker-0" "scheduler"="default"
I0723 04:30:36.260515   16467 placement_manager.go:183]  "msg"="Finished job placements adjustment"  "scheduler"="default"
I0723 04:30:36.261023   16467 scheduler.go:182]  "msg"="Finished resched"  "scheduler"="default"
I0723 04:30:36.393896   16467 placement_manager.go:147]  "msg"="Adding toleration to pod"  "podName"="tf2-keras-transformer-elastic-20210723-041753-worker-1" "scheduler"="default" "toleration"={"key":"celeste/hostname","operator":"Equal","value":"gpu3","effect":"NoExecute"}
I0723 04:30:36.592718   16467 placement_manager.go:147]  "msg"="Adding toleration to pod"  "podName"="tf2-keras-transformer-elastic-20210723-042836-worker-1" "scheduler"="default" "toleration"={"key":"celeste/hostname","operator":"Equal","value":"gpu4","effect":"NoExecute"}
I0723 04:30:40.983195   16467 scheduler.go:474]  "msg"="Training job completed"  "elaspedTotalSeconds"=922.694599183 "gpuTotalSeconds"=1745.047937665 "job"="tf2-keras-cifar10-resnet50-elastic-20210723-041516" "ranTotalSeconds"=810.022078818 "scheduler"="default" "waitedTotalSeconds"=112.672520365
I0723 04:30:40.983329   16467 scheduler.go:135]  "msg"="Received resched event, may be blocked because of rate limit"  "blockedUntil"="2021-07-23T04:32:36.261281671+08:00" "lastResched"="2021-07-23T04:30:36.261281671+08:00" "received"="2021-07-23T04:30:40.983235188+08:00" "scheduler"="default"
I0723 04:30:49.722863   16467 placement_manager.go:147]  "msg"="Adding toleration to pod"  "podName"="tf2-keras-transformer-elastic-20210723-041753-worker-0" "scheduler"="default" "toleration"={"key":"celeste/hostname","operator":"Equal","value":"gpu3","effect":"NoExecute"}
I0723 04:30:54.602777   16467 placement_manager.go:147]  "msg"="Adding toleration to pod"  "podName"="tf2-keras-cifar10-inceptionv3-elastic-20210723-041509-worker-0" "scheduler"="default" "toleration"={"key":"celeste/hostname","operator":"Equal","value":"gpu5","effect":"NoExecute"}
I0723 04:30:54.638950   16467 placement_manager.go:147]  "msg"="Adding toleration to pod"  "podName"="tf2-keras-cifar10-inceptionv3-elastic-20210723-041509-worker-1" "scheduler"="default" "toleration"={"key":"celeste/hostname","operator":"Equal","value":"gpu5","effect":"NoExecute"}
I0723 04:31:56.161616   16467 jobmaster.go:155]  "msg"="Training job created"  "job"="tf2-keras-cifar10-inceptionv3-elastic-20210723-043156"
I0723 04:32:36.261332   16467 scheduler.go:159]  "msg"="Started resched"  "scheduler"="default"
I0723 04:32:36.261376   16467 scheduler.go:193]  "msg"="Updating all jobs info"  "scheduler"="default"
I0723 04:32:36.267158   16467 elastic_fifo.go:73]  "msg"="Finished scheduling"  "algorithm"="ElasticFIFO" "freeGpu"=0 "result"={"tf2-keras-cifar10-inceptionv3-elastic-20210723-041509":3,"tf2-keras-cifar10-inceptionv3-elastic-20210723-041521":3,"tf2-keras-cifar10-inceptionv3-elastic-20210723-043156":2,"tf2-keras-transformer-elastic-20210723-041753":2,"tf2-keras-transformer-elastic-20210723-042836":2} "scheduler"="default"
I0723 04:32:36.267643   16467 scheduler.go:384]  "msg"="Trying to delete multiple training jobs"  "jobs"=[] "scheduler"="default"
I0723 04:32:36.267967   16467 scheduler.go:342]  "msg"="Trying to scale multiple training jobs"  "jobs"=[] "scheduler"="default"
I0723 04:32:36.268195   16467 scheduler.go:292]  "msg"="Trying to start multiple training jobs"  "jobs"=["tf2-keras-cifar10-inceptionv3-elastic-20210723-043156"] "scheduler"="default"
I0723 04:32:36.285573   16467 scheduler.go:342]  "msg"="Trying to scale multiple training jobs"  "jobs"=["tf2-keras-cifar10-inceptionv3-elastic-20210723-041521"] "scheduler"="default"
I0723 04:32:36.313935   16467 placement_manager.go:166]  "msg"="Started job placements adjustment"  "scheduler"="default"
I0723 04:32:36.314017   16467 placement_manager.go:192]  "msg"="Releasing slots"  "jobs"={"tf2-keras-cifar10-inceptionv3-elastic-20210723-041509":{},"tf2-keras-cifar10-inceptionv3-elastic-20210723-041521":{},"tf2-keras-cifar10-resnet50-elastic-20210723-041516":{},"tf2-keras-transformer-elastic-20210723-041753":{},"tf2-keras-transformer-elastic-20210723-042836":{}} "nodes"={"gpu3":{},"gpu4":{},"gpu5":{}} "scheduler"="default"
I0723 04:32:36.314079   16467 placement_manager.go:250]  "msg"="Released slots"  "jobs"={"tf2-keras-cifar10-inceptionv3-elastic-20210723-041509":{},"tf2-keras-cifar10-inceptionv3-elastic-20210723-041521":{},"tf2-keras-cifar10-resnet50-elastic-20210723-041516":{},"tf2-keras-transformer-elastic-20210723-041753":{},"tf2-keras-transformer-elastic-20210723-042836":{}} "nodes"={"gpu3":{},"gpu4":{},"gpu5":{}} "scheduler"="default"
I0723 04:32:36.314481   16467 placement_manager.go:305]  "msg"="Found best-fit"  "crossNode"=0 "nodes"=[{},{},{}] "requests"=[{},{},{},{},{},{},{},{},{},{}] "scheduler"="default"
I0723 04:32:36.314926   16467 placement_manager.go:339]  "msg"="nodeStates updated"  "new"={"gpu3":{},"gpu4":{},"gpu5":{}} "old"={"gpu3":{},"gpu4":{},"gpu5":{}} "scheduler"="default" "score"=6
I0723 04:32:36.315314   16467 placement_manager.go:387]  "msg"="jobStates updated"  "new"={"tf2-keras-cifar10-inceptionv3-elastic-20210723-041509":{},"tf2-keras-cifar10-inceptionv3-elastic-20210723-041521":{},"tf2-keras-cifar10-inceptionv3-elastic-20210723-043156":{},"tf2-keras-transformer-elastic-20210723-041753":{},"tf2-keras-transformer-elastic-20210723-042836":{}} "old"={"tf2-keras-cifar10-inceptionv3-elastic-20210723-041509":{},"tf2-keras-cifar10-inceptionv3-elastic-20210723-041521":{},"tf2-keras-cifar10-resnet50-elastic-20210723-041516":{},"tf2-keras-transformer-elastic-20210723-041753":{},"tf2-keras-transformer-elastic-20210723-042836":{}} "scheduler"="default"
I0723 04:32:36.315799   16467 placement_manager.go:434]  "msg"="podNodeName updated"  "launchersToDelete"=1 "new"={"tf2-keras-cifar10-inceptionv3-elastic-20210723-041509-worker-0":"gpu5","tf2-keras-cifar10-inceptionv3-elastic-20210723-041509-worker-1":"gpu5","tf2-keras-cifar10-inceptionv3-elastic-20210723-041509-worker-2":"gpu5","tf2-keras-cifar10-inceptionv3-elastic-20210723-041521-worker-0":"gpu3","tf2-keras-cifar10-inceptionv3-elastic-20210723-041521-worker-1":"gpu3","tf2-keras-cifar10-inceptionv3-elastic-20210723-041521-worker-2":"gpu3","tf2-keras-cifar10-inceptionv3-elastic-20210723-043156-worker-0":"gpu5","tf2-keras-cifar10-inceptionv3-elastic-20210723-043156-worker-1":"gpu3","tf2-keras-cifar10-inceptionv3-elastic-20210723-043156-worker-2":"gpu3","tf2-keras-transformer-elastic-20210723-041753-worker-0":"gpu4","tf2-keras-transformer-elastic-20210723-041753-worker-1":"gpu4","tf2-keras-transformer-elastic-20210723-042836-worker-0":"gpu4","tf2-keras-transformer-elastic-20210723-042836-worker-1":"gpu4"} "old"={"tf2-keras-cifar10-inceptionv3-elastic-20210723-041509-worker-0":"gpu5","tf2-keras-cifar10-inceptionv3-elastic-20210723-041509-worker-1":"gpu5","tf2-keras-cifar10-inceptionv3-elastic-20210723-041509-worker-2":"gpu5","tf2-keras-cifar10-inceptionv3-elastic-20210723-041521-worker-0":"gpu3","tf2-keras-cifar10-inceptionv3-elastic-20210723-041521-worker-1":"gpu3","tf2-keras-cifar10-resnet50-elastic-20210723-041516-worker-0":"gpu4","tf2-keras-cifar10-resnet50-elastic-20210723-041516-worker-1":"gpu4","tf2-keras-cifar10-resnet50-elastic-20210723-041516-worker-2":"gpu4","tf2-keras-transformer-elastic-20210723-041753-worker-0":"gpu3","tf2-keras-transformer-elastic-20210723-041753-worker-1":"gpu3","tf2-keras-transformer-elastic-20210723-042836-worker-0":"gpu5","tf2-keras-transformer-elastic-20210723-042836-worker-1":"gpu4","tf2-keras-transformer-elastic-20210723-042836-worker-2":"gpu4"} "scheduler"="default" "workersToDelete"=3
I0723 04:32:36.316111   16467 placement_manager.go:451]  "msg"="Deleting pod that need migration"  "podName"="tf2-keras-transformer-elastic-20210723-042836-worker-0" "scheduler"="default"
I0723 04:32:36.325755   16467 placement_manager.go:451]  "msg"="Deleting pod that need migration"  "podName"="tf2-keras-transformer-elastic-20210723-041753-worker-0" "scheduler"="default"
I0723 04:32:36.335386   16467 placement_manager.go:451]  "msg"="Deleting pod that need migration"  "podName"="tf2-keras-transformer-elastic-20210723-041753-worker-1" "scheduler"="default"
I0723 04:32:36.340626   16467 placement_manager.go:451]  "msg"="Deleting pod that need migration"  "podName"="tf2-keras-transformer-elastic-20210723-041753-launcher" "scheduler"="default"
I0723 04:32:36.358573   16467 placement_manager.go:183]  "msg"="Finished job placements adjustment"  "scheduler"="default"
I0723 04:32:36.358989   16467 scheduler.go:182]  "msg"="Finished resched"  "scheduler"="default"
I0723 04:32:36.495236   16467 placement_manager.go:147]  "msg"="Adding toleration to pod"  "podName"="tf2-keras-cifar10-inceptionv3-elastic-20210723-041521-worker-2" "scheduler"="default" "toleration"={"key":"celeste/hostname","operator":"Equal","value":"gpu3","effect":"NoExecute"}
I0723 04:32:36.513919   16467 placement_manager.go:147]  "msg"="Adding toleration to pod"  "podName"="tf2-keras-cifar10-inceptionv3-elastic-20210723-043156-worker-0" "scheduler"="default" "toleration"={"key":"celeste/hostname","operator":"Equal","value":"gpu5","effect":"NoExecute"}
I0723 04:32:36.893691   16467 placement_manager.go:147]  "msg"="Adding toleration to pod"  "podName"="tf2-keras-cifar10-inceptionv3-elastic-20210723-043156-worker-1" "scheduler"="default" "toleration"={"key":"celeste/hostname","operator":"Equal","value":"gpu3","effect":"NoExecute"}
I0723 04:32:37.093558   16467 placement_manager.go:147]  "msg"="Adding toleration to pod"  "podName"="tf2-keras-cifar10-inceptionv3-elastic-20210723-043156-launcher" "scheduler"="default" "toleration"={"key":"celeste/hostname","operator":"Exists","effect":"NoExecute"}
I0723 04:32:49.753818   16467 placement_manager.go:147]  "msg"="Adding toleration to pod"  "podName"="tf2-keras-transformer-elastic-20210723-041753-launcher" "scheduler"="default" "toleration"={"key":"celeste/hostname","operator":"Exists","effect":"NoExecute"}
I0723 04:32:49.792756   16467 placement_manager.go:147]  "msg"="Adding toleration to pod"  "podName"="tf2-keras-transformer-elastic-20210723-042836-worker-0" "scheduler"="default" "toleration"={"key":"celeste/hostname","operator":"Equal","value":"gpu4","effect":"NoExecute"}
I0723 04:32:54.504915   16467 placement_manager.go:147]  "msg"="Adding toleration to pod"  "podName"="tf2-keras-transformer-elastic-20210723-041753-worker-1" "scheduler"="default" "toleration"={"key":"celeste/hostname","operator":"Equal","value":"gpu4","effect":"NoExecute"}
I0723 04:32:55.306551   16467 placement_manager.go:147]  "msg"="Adding toleration to pod"  "podName"="tf2-keras-transformer-elastic-20210723-041753-worker-0" "scheduler"="default" "toleration"={"key":"celeste/hostname","operator":"Equal","value":"gpu4","effect":"NoExecute"}
I0723 04:36:18.203826   16467 jobmaster.go:155]  "msg"="Training job created"  "job"="tf2-keras-cifar10-resnet50-elastic-20210723-043618"
I0723 04:36:18.203938   16467 scheduler.go:135]  "msg"="Received resched event, may be blocked because of rate limit"  "blockedUntil"="2021-07-23T04:34:36.35937103+08:00" "lastResched"="2021-07-23T04:32:36.35937103+08:00" "received"="2021-07-23T04:36:18.203249453+08:00" "scheduler"="default"
I0723 04:36:18.204502   16467 scheduler.go:159]  "msg"="Started resched"  "scheduler"="default"
I0723 04:36:18.204547   16467 scheduler.go:193]  "msg"="Updating all jobs info"  "scheduler"="default"
I0723 04:36:18.210864   16467 elastic_fifo.go:73]  "msg"="Finished scheduling"  "algorithm"="ElasticFIFO" "freeGpu"=0 "result"={"tf2-keras-cifar10-inceptionv3-elastic-20210723-041509":2,"tf2-keras-cifar10-inceptionv3-elastic-20210723-041521":2,"tf2-keras-cifar10-inceptionv3-elastic-20210723-043156":2,"tf2-keras-cifar10-resnet50-elastic-20210723-043618":2,"tf2-keras-transformer-elastic-20210723-041753":2,"tf2-keras-transformer-elastic-20210723-042836":2} "scheduler"="default"
I0723 04:36:18.211358   16467 scheduler.go:384]  "msg"="Trying to delete multiple training jobs"  "jobs"=[] "scheduler"="default"
I0723 04:36:18.211648   16467 scheduler.go:342]  "msg"="Trying to scale multiple training jobs"  "jobs"=["tf2-keras-cifar10-inceptionv3-elastic-20210723-041509","tf2-keras-cifar10-inceptionv3-elastic-20210723-041521"] "scheduler"="default"
I0723 04:36:18.242744   16467 scheduler.go:292]  "msg"="Trying to start multiple training jobs"  "jobs"=["tf2-keras-cifar10-resnet50-elastic-20210723-043618"] "scheduler"="default"
I0723 04:36:18.252347   16467 scheduler.go:342]  "msg"="Trying to scale multiple training jobs"  "jobs"=[] "scheduler"="default"
I0723 04:36:18.257687   16467 placement_manager.go:166]  "msg"="Started job placements adjustment"  "scheduler"="default"
I0723 04:36:18.257788   16467 placement_manager.go:192]  "msg"="Releasing slots"  "jobs"={"tf2-keras-cifar10-inceptionv3-elastic-20210723-041509":{},"tf2-keras-cifar10-inceptionv3-elastic-20210723-041521":{},"tf2-keras-cifar10-inceptionv3-elastic-20210723-043156":{},"tf2-keras-transformer-elastic-20210723-041753":{},"tf2-keras-transformer-elastic-20210723-042836":{}} "nodes"={"gpu3":{},"gpu4":{},"gpu5":{}} "scheduler"="default"
I0723 04:36:18.257836   16467 placement_manager.go:250]  "msg"="Released slots"  "jobs"={"tf2-keras-cifar10-inceptionv3-elastic-20210723-041509":{},"tf2-keras-cifar10-inceptionv3-elastic-20210723-041521":{},"tf2-keras-cifar10-inceptionv3-elastic-20210723-043156":{},"tf2-keras-transformer-elastic-20210723-041753":{},"tf2-keras-transformer-elastic-20210723-042836":{}} "nodes"={"gpu3":{},"gpu4":{},"gpu5":{}} "scheduler"="default"
I0723 04:36:18.258270   16467 placement_manager.go:305]  "msg"="Found best-fit"  "crossNode"=0 "nodes"=[{},{},{}] "requests"=[{},{},{},{},{},{},{},{},{},{},{},{}] "scheduler"="default"
I0723 04:36:18.258529   16467 placement_manager.go:339]  "msg"="nodeStates updated"  "new"={"gpu3":{},"gpu4":{},"gpu5":{}} "old"={"gpu3":{},"gpu4":{},"gpu5":{}} "scheduler"="default" "score"=7
I0723 04:36:18.258836   16467 placement_manager.go:387]  "msg"="jobStates updated"  "new"={"tf2-keras-cifar10-inceptionv3-elastic-20210723-041509":{},"tf2-keras-cifar10-inceptionv3-elastic-20210723-041521":{},"tf2-keras-cifar10-inceptionv3-elastic-20210723-043156":{},"tf2-keras-cifar10-resnet50-elastic-20210723-043618":{},"tf2-keras-transformer-elastic-20210723-041753":{},"tf2-keras-transformer-elastic-20210723-042836":{}} "old"={"tf2-keras-cifar10-inceptionv3-elastic-20210723-041509":{},"tf2-keras-cifar10-inceptionv3-elastic-20210723-041521":{},"tf2-keras-cifar10-inceptionv3-elastic-20210723-043156":{},"tf2-keras-transformer-elastic-20210723-041753":{},"tf2-keras-transformer-elastic-20210723-042836":{}} "scheduler"="default"
I0723 04:36:18.259212   16467 placement_manager.go:434]  "msg"="podNodeName updated"  "launchersToDelete"=1 "new"={"tf2-keras-cifar10-inceptionv3-elastic-20210723-041509-worker-0":"gpu3","tf2-keras-cifar10-inceptionv3-elastic-20210723-041509-worker-1":"gpu3","tf2-keras-cifar10-inceptionv3-elastic-20210723-041521-worker-0":"gpu3","tf2-keras-cifar10-inceptionv3-elastic-20210723-041521-worker-1":"gpu3","tf2-keras-cifar10-inceptionv3-elastic-20210723-043156-worker-0":"gpu5","tf2-keras-cifar10-inceptionv3-elastic-20210723-043156-worker-1":"gpu5","tf2-keras-cifar10-resnet50-elastic-20210723-043618-worker-0":"gpu5","tf2-keras-cifar10-resnet50-elastic-20210723-043618-worker-1":"gpu5","tf2-keras-transformer-elastic-20210723-041753-worker-0":"gpu4","tf2-keras-transformer-elastic-20210723-041753-worker-1":"gpu4","tf2-keras-transformer-elastic-20210723-042836-worker-0":"gpu4","tf2-keras-transformer-elastic-20210723-042836-worker-1":"gpu4"} "old"={"tf2-keras-cifar10-inceptionv3-elastic-20210723-041509-worker-0":"gpu5","tf2-keras-cifar10-inceptionv3-elastic-20210723-041509-worker-1":"gpu5","tf2-keras-cifar10-inceptionv3-elastic-20210723-041509-worker-2":"gpu5","tf2-keras-cifar10-inceptionv3-elastic-20210723-041521-worker-0":"gpu3","tf2-keras-cifar10-inceptionv3-elastic-20210723-041521-worker-1":"gpu3","tf2-keras-cifar10-inceptionv3-elastic-20210723-041521-worker-2":"gpu3","tf2-keras-cifar10-inceptionv3-elastic-20210723-043156-worker-0":"gpu5","tf2-keras-cifar10-inceptionv3-elastic-20210723-043156-worker-1":"gpu3","tf2-keras-cifar10-inceptionv3-elastic-20210723-043156-worker-2":"gpu3","tf2-keras-transformer-elastic-20210723-041753-worker-0":"gpu4","tf2-keras-transformer-elastic-20210723-041753-worker-1":"gpu4","tf2-keras-transformer-elastic-20210723-042836-worker-0":"gpu4","tf2-keras-transformer-elastic-20210723-042836-worker-1":"gpu4"} "scheduler"="default" "workersToDelete"=3
I0723 04:36:18.259542   16467 placement_manager.go:451]  "msg"="Deleting pod that need migration"  "podName"="tf2-keras-cifar10-inceptionv3-elastic-20210723-041509-worker-0" "scheduler"="default"
I0723 04:36:18.264744   16467 placement_manager.go:451]  "msg"="Deleting pod that need migration"  "podName"="tf2-keras-cifar10-inceptionv3-elastic-20210723-041509-worker-1" "scheduler"="default"
I0723 04:36:18.280886   16467 placement_manager.go:451]  "msg"="Deleting pod that need migration"  "podName"="tf2-keras-cifar10-inceptionv3-elastic-20210723-041509-launcher" "scheduler"="default"
I0723 04:36:18.288184   16467 placement_manager.go:451]  "msg"="Deleting pod that need migration"  "podName"="tf2-keras-cifar10-inceptionv3-elastic-20210723-043156-worker-1" "scheduler"="default"
I0723 04:36:18.294721   16467 placement_manager.go:183]  "msg"="Finished job placements adjustment"  "scheduler"="default"
I0723 04:36:18.294958   16467 scheduler.go:182]  "msg"="Finished resched"  "scheduler"="default"
I0723 04:36:19.843346   16467 placement_manager.go:147]  "msg"="Adding toleration to pod"  "podName"="tf2-keras-cifar10-resnet50-elastic-20210723-043618-worker-0" "scheduler"="default" "toleration"={"key":"celeste/hostname","operator":"Equal","value":"gpu5","effect":"NoExecute"}
I0723 04:36:20.443962   16467 placement_manager.go:147]  "msg"="Adding toleration to pod"  "podName"="tf2-keras-cifar10-resnet50-elastic-20210723-043618-worker-1" "scheduler"="default" "toleration"={"key":"celeste/hostname","operator":"Equal","value":"gpu5","effect":"NoExecute"}
I0723 04:36:20.844095   16467 placement_manager.go:147]  "msg"="Adding toleration to pod"  "podName"="tf2-keras-cifar10-resnet50-elastic-20210723-043618-launcher" "scheduler"="default" "toleration"={"key":"celeste/hostname","operator":"Exists","effect":"NoExecute"}
I0723 04:36:26.369577   16467 placement_manager.go:147]  "msg"="Adding toleration to pod"  "podName"="tf2-keras-cifar10-inceptionv3-elastic-20210723-041509-launcher" "scheduler"="default" "toleration"={"key":"celeste/hostname","operator":"Exists","effect":"NoExecute"}
I0723 04:36:33.847943   16467 placement_manager.go:147]  "msg"="Adding toleration to pod"  "podName"="tf2-keras-cifar10-inceptionv3-elastic-20210723-043156-worker-1" "scheduler"="default" "toleration"={"key":"celeste/hostname","operator":"Equal","value":"gpu5","effect":"NoExecute"}
I0723 04:36:40.364092   16467 placement_manager.go:147]  "msg"="Adding toleration to pod"  "podName"="tf2-keras-cifar10-inceptionv3-elastic-20210723-041509-worker-0" "scheduler"="default" "toleration"={"key":"celeste/hostname","operator":"Equal","value":"gpu3","effect":"NoExecute"}
I0723 04:36:41.160796   16467 placement_manager.go:147]  "msg"="Adding toleration to pod"  "podName"="tf2-keras-cifar10-inceptionv3-elastic-20210723-041509-worker-1" "scheduler"="default" "toleration"={"key":"celeste/hostname","operator":"Equal","value":"gpu3","effect":"NoExecute"}
I0723 04:40:44.278177   16467 jobmaster.go:155]  "msg"="Training job created"  "job"="tf2-keras-cifar10-inceptionv3-elastic-20210723-044044"
I0723 04:40:44.278307   16467 scheduler.go:135]  "msg"="Received resched event, may be blocked because of rate limit"  "blockedUntil"="2021-07-23T04:38:18.295161991+08:00" "lastResched"="2021-07-23T04:36:18.295161991+08:00" "received"="2021-07-23T04:40:44.277633009+08:00" "scheduler"="default"
I0723 04:40:44.278715   16467 scheduler.go:159]  "msg"="Started resched"  "scheduler"="default"
I0723 04:40:44.278774   16467 scheduler.go:193]  "msg"="Updating all jobs info"  "scheduler"="default"
I0723 04:40:44.284678   16467 elastic_fifo.go:73]  "msg"="Finished scheduling"  "algorithm"="ElasticFIFO" "freeGpu"=0 "result"={"tf2-keras-cifar10-inceptionv3-elastic-20210723-041509":2,"tf2-keras-cifar10-inceptionv3-elastic-20210723-041521":2,"tf2-keras-cifar10-inceptionv3-elastic-20210723-043156":2,"tf2-keras-cifar10-inceptionv3-elastic-20210723-044044":1,"tf2-keras-cifar10-resnet50-elastic-20210723-043618":1,"tf2-keras-transformer-elastic-20210723-041753":2,"tf2-keras-transformer-elastic-20210723-042836":2} "scheduler"="default"
I0723 04:40:44.285023   16467 scheduler.go:384]  "msg"="Trying to delete multiple training jobs"  "jobs"=[] "scheduler"="default"
I0723 04:40:44.285318   16467 scheduler.go:342]  "msg"="Trying to scale multiple training jobs"  "jobs"=["tf2-keras-cifar10-resnet50-elastic-20210723-043618"] "scheduler"="default"
I0723 04:40:44.301390   16467 scheduler.go:292]  "msg"="Trying to start multiple training jobs"  "jobs"=["tf2-keras-cifar10-inceptionv3-elastic-20210723-044044"] "scheduler"="default"
I0723 04:40:44.311456   16467 scheduler.go:342]  "msg"="Trying to scale multiple training jobs"  "jobs"=[] "scheduler"="default"
I0723 04:40:44.314573   16467 placement_manager.go:166]  "msg"="Started job placements adjustment"  "scheduler"="default"
I0723 04:40:44.314658   16467 placement_manager.go:192]  "msg"="Releasing slots"  "jobs"={"tf2-keras-cifar10-inceptionv3-elastic-20210723-041509":{},"tf2-keras-cifar10-inceptionv3-elastic-20210723-041521":{},"tf2-keras-cifar10-inceptionv3-elastic-20210723-043156":{},"tf2-keras-cifar10-resnet50-elastic-20210723-043618":{},"tf2-keras-transformer-elastic-20210723-041753":{},"tf2-keras-transformer-elastic-20210723-042836":{}} "nodes"={"gpu3":{},"gpu4":{},"gpu5":{}} "scheduler"="default"
I0723 04:40:44.314721   16467 placement_manager.go:250]  "msg"="Released slots"  "jobs"={"tf2-keras-cifar10-inceptionv3-elastic-20210723-041509":{},"tf2-keras-cifar10-inceptionv3-elastic-20210723-041521":{},"tf2-keras-cifar10-inceptionv3-elastic-20210723-043156":{},"tf2-keras-cifar10-resnet50-elastic-20210723-043618":{},"tf2-keras-transformer-elastic-20210723-041753":{},"tf2-keras-transformer-elastic-20210723-042836":{}} "nodes"={"gpu3":{},"gpu4":{},"gpu5":{}} "scheduler"="default"
I0723 04:40:44.315204   16467 placement_manager.go:305]  "msg"="Found best-fit"  "crossNode"=0 "nodes"=[{},{},{}] "requests"=[{},{},{},{},{},{},{},{},{},{},{},{},{},{}] "scheduler"="default"
I0723 04:40:44.315631   16467 placement_manager.go:339]  "msg"="nodeStates updated"  "new"={"gpu3":{},"gpu4":{},"gpu5":{}} "old"={"gpu3":{},"gpu4":{},"gpu5":{}} "scheduler"="default" "score"=6
I0723 04:40:44.315910   16467 placement_manager.go:387]  "msg"="jobStates updated"  "new"={"tf2-keras-cifar10-inceptionv3-elastic-20210723-041509":{},"tf2-keras-cifar10-inceptionv3-elastic-20210723-041521":{},"tf2-keras-cifar10-inceptionv3-elastic-20210723-043156":{},"tf2-keras-cifar10-inceptionv3-elastic-20210723-044044":{},"tf2-keras-cifar10-resnet50-elastic-20210723-043618":{},"tf2-keras-transformer-elastic-20210723-041753":{},"tf2-keras-transformer-elastic-20210723-042836":{}} "old"={"tf2-keras-cifar10-inceptionv3-elastic-20210723-041509":{},"tf2-keras-cifar10-inceptionv3-elastic-20210723-041521":{},"tf2-keras-cifar10-inceptionv3-elastic-20210723-043156":{},"tf2-keras-cifar10-resnet50-elastic-20210723-043618":{},"tf2-keras-transformer-elastic-20210723-041753":{},"tf2-keras-transformer-elastic-20210723-042836":{}} "scheduler"="default"
I0723 04:40:44.316356   16467 placement_manager.go:434]  "msg"="podNodeName updated"  "launchersToDelete"=3 "new"={"tf2-keras-cifar10-inceptionv3-elastic-20210723-041509-worker-0":"gpu5","tf2-keras-cifar10-inceptionv3-elastic-20210723-041509-worker-1":"gpu5","tf2-keras-cifar10-inceptionv3-elastic-20210723-041521-worker-0":"gpu3","tf2-keras-cifar10-inceptionv3-elastic-20210723-041521-worker-1":"gpu3","tf2-keras-cifar10-inceptionv3-elastic-20210723-043156-worker-0":"gpu5","tf2-keras-cifar10-inceptionv3-elastic-20210723-043156-worker-1":"gpu5","tf2-keras-cifar10-inceptionv3-elastic-20210723-044044-worker-0":"gpu4","tf2-keras-cifar10-resnet50-elastic-20210723-043618-worker-0":"gpu4","tf2-keras-transformer-elastic-20210723-041753-worker-0":"gpu3","tf2-keras-transformer-elastic-20210723-041753-worker-1":"gpu3","tf2-keras-transformer-elastic-20210723-042836-worker-0":"gpu4","tf2-keras-transformer-elastic-20210723-042836-worker-1":"gpu4"} "old"={"tf2-keras-cifar10-inceptionv3-elastic-20210723-041509-worker-0":"gpu3","tf2-keras-cifar10-inceptionv3-elastic-20210723-041509-worker-1":"gpu3","tf2-keras-cifar10-inceptionv3-elastic-20210723-041521-worker-0":"gpu3","tf2-keras-cifar10-inceptionv3-elastic-20210723-041521-worker-1":"gpu3","tf2-keras-cifar10-inceptionv3-elastic-20210723-043156-worker-0":"gpu5","tf2-keras-cifar10-inceptionv3-elastic-20210723-043156-worker-1":"gpu5","tf2-keras-cifar10-resnet50-elastic-20210723-043618-worker-0":"gpu5","tf2-keras-cifar10-resnet50-elastic-20210723-043618-worker-1":"gpu5","tf2-keras-transformer-elastic-20210723-041753-worker-0":"gpu4","tf2-keras-transformer-elastic-20210723-041753-worker-1":"gpu4","tf2-keras-transformer-elastic-20210723-042836-worker-0":"gpu4","tf2-keras-transformer-elastic-20210723-042836-worker-1":"gpu4"} "scheduler"="default" "workersToDelete"=5
I0723 04:40:44.316595   16467 placement_manager.go:451]  "msg"="Deleting pod that need migration"  "podName"="tf2-keras-cifar10-resnet50-elastic-20210723-043618-worker-0" "scheduler"="default"
I0723 04:40:44.320890   16467 placement_manager.go:451]  "msg"="Deleting pod that need migration"  "podName"="tf2-keras-cifar10-resnet50-elastic-20210723-043618-launcher" "scheduler"="default"
I0723 04:40:44.326717   16467 placement_manager.go:451]  "msg"="Deleting pod that need migration"  "podName"="tf2-keras-cifar10-inceptionv3-elastic-20210723-041509-worker-0" "scheduler"="default"
I0723 04:40:44.330448   16467 placement_manager.go:451]  "msg"="Deleting pod that need migration"  "podName"="tf2-keras-cifar10-inceptionv3-elastic-20210723-041509-worker-1" "scheduler"="default"
I0723 04:40:44.336296   16467 placement_manager.go:451]  "msg"="Deleting pod that need migration"  "podName"="tf2-keras-cifar10-inceptionv3-elastic-20210723-041509-launcher" "scheduler"="default"
I0723 04:40:44.351134   16467 placement_manager.go:451]  "msg"="Deleting pod that need migration"  "podName"="tf2-keras-transformer-elastic-20210723-041753-worker-0" "scheduler"="default"
I0723 04:40:44.355003   16467 placement_manager.go:451]  "msg"="Deleting pod that need migration"  "podName"="tf2-keras-transformer-elastic-20210723-041753-worker-1" "scheduler"="default"
I0723 04:40:44.360383   16467 placement_manager.go:451]  "msg"="Deleting pod that need migration"  "podName"="tf2-keras-transformer-elastic-20210723-041753-launcher" "scheduler"="default"
I0723 04:40:44.364229   16467 placement_manager.go:183]  "msg"="Finished job placements adjustment"  "scheduler"="default"
I0723 04:40:44.364602   16467 scheduler.go:182]  "msg"="Finished resched"  "scheduler"="default"
I0723 04:40:45.317579   16467 placement_manager.go:147]  "msg"="Adding toleration to pod"  "podName"="tf2-keras-cifar10-inceptionv3-elastic-20210723-044044-worker-0" "scheduler"="default" "toleration"={"key":"celeste/hostname","operator":"Equal","value":"gpu4","effect":"NoExecute"}
I0723 04:40:45.916289   16467 placement_manager.go:147]  "msg"="Adding toleration to pod"  "podName"="tf2-keras-cifar10-inceptionv3-elastic-20210723-044044-launcher" "scheduler"="default" "toleration"={"key":"celeste/hostname","operator":"Exists","effect":"NoExecute"}
I0723 04:40:52.435385   16467 placement_manager.go:147]  "msg"="Adding toleration to pod"  "podName"="tf2-keras-cifar10-inceptionv3-elastic-20210723-041509-worker-1" "scheduler"="default" "toleration"={"key":"celeste/hostname","operator":"Equal","value":"gpu5","effect":"NoExecute"}
I0723 04:40:52.477042   16467 placement_manager.go:147]  "msg"="Adding toleration to pod"  "podName"="tf2-keras-cifar10-inceptionv3-elastic-20210723-041509-worker-0" "scheduler"="default" "toleration"={"key":"celeste/hostname","operator":"Equal","value":"gpu5","effect":"NoExecute"}
I0723 04:40:53.860004   16467 placement_manager.go:147]  "msg"="Adding toleration to pod"  "podName"="tf2-keras-cifar10-resnet50-elastic-20210723-043618-launcher" "scheduler"="default" "toleration"={"key":"celeste/hostname","operator":"Exists","effect":"NoExecute"}
I0723 04:40:53.897019   16467 placement_manager.go:147]  "msg"="Adding toleration to pod"  "podName"="tf2-keras-transformer-elastic-20210723-041753-launcher" "scheduler"="default" "toleration"={"key":"celeste/hostname","operator":"Exists","effect":"NoExecute"}
I0723 04:40:54.671170   16467 placement_manager.go:147]  "msg"="Adding toleration to pod"  "podName"="tf2-keras-transformer-elastic-20210723-041753-worker-1" "scheduler"="default" "toleration"={"key":"celeste/hostname","operator":"Equal","value":"gpu3","effect":"NoExecute"}
I0723 04:40:55.061124   16467 placement_manager.go:147]  "msg"="Adding toleration to pod"  "podName"="tf2-keras-transformer-elastic-20210723-041753-worker-0" "scheduler"="default" "toleration"={"key":"celeste/hostname","operator":"Equal","value":"gpu3","effect":"NoExecute"}
I0723 04:40:55.399752   16467 placement_manager.go:147]  "msg"="Adding toleration to pod"  "podName"="tf2-keras-cifar10-inceptionv3-elastic-20210723-041509-launcher" "scheduler"="default" "toleration"={"key":"celeste/hostname","operator":"Exists","effect":"NoExecute"}
I0723 04:41:02.192750   16467 jobmaster.go:155]  "msg"="Training job created"  "job"="tf2-keras-transformer-elastic-20210723-044102"
I0723 04:41:02.192827   16467 scheduler.go:135]  "msg"="Received resched event, may be blocked because of rate limit"  "blockedUntil"="2021-07-23T04:42:44.364907497+08:00" "lastResched"="2021-07-23T04:40:44.364907497+08:00" "received"="2021-07-23T04:41:02.192205412+08:00" "scheduler"="default"
I0723 04:41:02.393869   16467 placement_manager.go:147]  "msg"="Adding toleration to pod"  "podName"="tf2-keras-cifar10-resnet50-elastic-20210723-043618-worker-0" "scheduler"="default" "toleration"={"key":"celeste/hostname","operator":"Equal","value":"gpu4","effect":"NoExecute"}
I0723 04:41:28.187545   16467 jobmaster.go:155]  "msg"="Training job created"  "job"="tf2-keras-cifar10-vgg16-elastic-20210723-044128"
I0723 04:42:44.364986   16467 scheduler.go:159]  "msg"="Started resched"  "scheduler"="default"
I0723 04:42:44.365108   16467 scheduler.go:193]  "msg"="Updating all jobs info"  "scheduler"="default"
I0723 04:42:44.372733   16467 elastic_fifo.go:73]  "msg"="Finished scheduling"  "algorithm"="ElasticFIFO" "freeGpu"=0 "result"={"tf2-keras-cifar10-inceptionv3-elastic-20210723-041509":2,"tf2-keras-cifar10-inceptionv3-elastic-20210723-041521":2,"tf2-keras-cifar10-inceptionv3-elastic-20210723-043156":1,"tf2-keras-cifar10-inceptionv3-elastic-20210723-044044":1,"tf2-keras-cifar10-resnet50-elastic-20210723-043618":1,"tf2-keras-cifar10-vgg16-elastic-20210723-044128":1,"tf2-keras-transformer-elastic-20210723-041753":2,"tf2-keras-transformer-elastic-20210723-042836":1,"tf2-keras-transformer-elastic-20210723-044102":1} "scheduler"="default"
I0723 04:42:44.373069   16467 scheduler.go:384]  "msg"="Trying to delete multiple training jobs"  "jobs"=[] "scheduler"="default"
I0723 04:42:44.373388   16467 scheduler.go:342]  "msg"="Trying to scale multiple training jobs"  "jobs"=["tf2-keras-transformer-elastic-20210723-042836","tf2-keras-cifar10-inceptionv3-elastic-20210723-043156"] "scheduler"="default"
I0723 04:42:44.406995   16467 scheduler.go:292]  "msg"="Trying to start multiple training jobs"  "jobs"=["tf2-keras-cifar10-vgg16-elastic-20210723-044128","tf2-keras-transformer-elastic-20210723-044102"] "scheduler"="default"
I0723 04:42:44.420486   16467 scheduler.go:342]  "msg"="Trying to scale multiple training jobs"  "jobs"=[] "scheduler"="default"
I0723 04:42:44.424459   16467 placement_manager.go:166]  "msg"="Started job placements adjustment"  "scheduler"="default"
I0723 04:42:44.424521   16467 placement_manager.go:192]  "msg"="Releasing slots"  "jobs"={"tf2-keras-cifar10-inceptionv3-elastic-20210723-041509":{},"tf2-keras-cifar10-inceptionv3-elastic-20210723-041521":{},"tf2-keras-cifar10-inceptionv3-elastic-20210723-043156":{},"tf2-keras-cifar10-inceptionv3-elastic-20210723-044044":{},"tf2-keras-cifar10-resnet50-elastic-20210723-043618":{},"tf2-keras-transformer-elastic-20210723-041753":{},"tf2-keras-transformer-elastic-20210723-042836":{}} "nodes"={"gpu3":{},"gpu4":{},"gpu5":{}} "scheduler"="default"
I0723 04:42:44.424580   16467 placement_manager.go:250]  "msg"="Released slots"  "jobs"={"tf2-keras-cifar10-inceptionv3-elastic-20210723-041509":{},"tf2-keras-cifar10-inceptionv3-elastic-20210723-041521":{},"tf2-keras-cifar10-inceptionv3-elastic-20210723-043156":{},"tf2-keras-cifar10-inceptionv3-elastic-20210723-044044":{},"tf2-keras-cifar10-resnet50-elastic-20210723-043618":{},"tf2-keras-transformer-elastic-20210723-041753":{},"tf2-keras-transformer-elastic-20210723-042836":{}} "nodes"={"gpu3":{},"gpu4":{},"gpu5":{}} "scheduler"="default"
I0723 04:42:44.425017   16467 placement_manager.go:305]  "msg"="Found best-fit"  "crossNode"=0 "nodes"=[{},{},{}] "requests"=[{},{},{},{},{},{},{},{},{},{},{},{},{},{},{},{},{},{}] "scheduler"="default"
I0723 04:42:44.425322   16467 placement_manager.go:339]  "msg"="nodeStates updated"  "new"={"gpu3":{},"gpu4":{},"gpu5":{}} "old"={"gpu3":{},"gpu4":{},"gpu5":{}} "scheduler"="default" "score"=6
I0723 04:42:44.425617   16467 placement_manager.go:387]  "msg"="jobStates updated"  "new"={"tf2-keras-cifar10-inceptionv3-elastic-20210723-041509":{},"tf2-keras-cifar10-inceptionv3-elastic-20210723-041521":{},"tf2-keras-cifar10-inceptionv3-elastic-20210723-043156":{},"tf2-keras-cifar10-inceptionv3-elastic-20210723-044044":{},"tf2-keras-cifar10-resnet50-elastic-20210723-043618":{},"tf2-keras-cifar10-vgg16-elastic-20210723-044128":{},"tf2-keras-transformer-elastic-20210723-041753":{},"tf2-keras-transformer-elastic-20210723-042836":{},"tf2-keras-transformer-elastic-20210723-044102":{}} "old"={"tf2-keras-cifar10-inceptionv3-elastic-20210723-041509":{},"tf2-keras-cifar10-inceptionv3-elastic-20210723-041521":{},"tf2-keras-cifar10-inceptionv3-elastic-20210723-043156":{},"tf2-keras-cifar10-inceptionv3-elastic-20210723-044044":{},"tf2-keras-cifar10-resnet50-elastic-20210723-043618":{},"tf2-keras-transformer-elastic-20210723-041753":{},"tf2-keras-transformer-elastic-20210723-042836":{}} "scheduler"="default"
I0723 04:42:44.425986   16467 placement_manager.go:434]  "msg"="podNodeName updated"  "launchersToDelete"=3 "new"={"tf2-keras-cifar10-inceptionv3-elastic-20210723-041509-worker-0":"gpu5","tf2-keras-cifar10-inceptionv3-elastic-20210723-041509-worker-1":"gpu5","tf2-keras-cifar10-inceptionv3-elastic-20210723-041521-worker-0":"gpu5","tf2-keras-cifar10-inceptionv3-elastic-20210723-041521-worker-1":"gpu5","tf2-keras-cifar10-inceptionv3-elastic-20210723-043156-worker-0":"gpu4","tf2-keras-cifar10-inceptionv3-elastic-20210723-044044-worker-0":"gpu4","tf2-keras-cifar10-resnet50-elastic-20210723-043618-worker-0":"gpu4","tf2-keras-cifar10-vgg16-elastic-20210723-044128-worker-0":"gpu3","tf2-keras-transformer-elastic-20210723-041753-worker-0":"gpu3","tf2-keras-transformer-elastic-20210723-041753-worker-1":"gpu3","tf2-keras-transformer-elastic-20210723-042836-worker-0":"gpu3","tf2-keras-transformer-elastic-20210723-044102-worker-0":"gpu4"} "old"={"tf2-keras-cifar10-inceptionv3-elastic-20210723-041509-worker-0":"gpu5","tf2-keras-cifar10-inceptionv3-elastic-20210723-041509-worker-1":"gpu5","tf2-keras-cifar10-inceptionv3-elastic-20210723-041521-worker-0":"gpu3","tf2-keras-cifar10-inceptionv3-elastic-20210723-041521-worker-1":"gpu3","tf2-keras-cifar10-inceptionv3-elastic-20210723-043156-worker-0":"gpu5","tf2-keras-cifar10-inceptionv3-elastic-20210723-043156-worker-1":"gpu5","tf2-keras-cifar10-inceptionv3-elastic-20210723-044044-worker-0":"gpu4","tf2-keras-cifar10-resnet50-elastic-20210723-043618-worker-0":"gpu4","tf2-keras-transformer-elastic-20210723-041753-worker-0":"gpu3","tf2-keras-transformer-elastic-20210723-041753-worker-1":"gpu3","tf2-keras-transformer-elastic-20210723-042836-worker-0":"gpu4","tf2-keras-transformer-elastic-20210723-042836-worker-1":"gpu4"} "scheduler"="default" "workersToDelete"=4
I0723 04:42:44.426246   16467 placement_manager.go:451]  "msg"="Deleting pod that need migration"  "podName"="tf2-keras-cifar10-inceptionv3-elastic-20210723-043156-worker-0" "scheduler"="default"
I0723 04:42:44.430044   16467 placement_manager.go:451]  "msg"="Deleting pod that need migration"  "podName"="tf2-keras-cifar10-inceptionv3-elastic-20210723-043156-launcher" "scheduler"="default"
I0723 04:42:44.435573   16467 placement_manager.go:451]  "msg"="Deleting pod that need migration"  "podName"="tf2-keras-cifar10-inceptionv3-elastic-20210723-041521-worker-0" "scheduler"="default"
I0723 04:42:44.439917   16467 placement_manager.go:451]  "msg"="Deleting pod that need migration"  "podName"="tf2-keras-cifar10-inceptionv3-elastic-20210723-041521-worker-1" "scheduler"="default"
I0723 04:42:44.449131   16467 placement_manager.go:451]  "msg"="Deleting pod that need migration"  "podName"="tf2-keras-cifar10-inceptionv3-elastic-20210723-041521-launcher" "scheduler"="default"
I0723 04:42:44.453106   16467 placement_manager.go:451]  "msg"="Deleting pod that need migration"  "podName"="tf2-keras-transformer-elastic-20210723-042836-worker-0" "scheduler"="default"
I0723 04:42:44.459460   16467 placement_manager.go:451]  "msg"="Deleting pod that need migration"  "podName"="tf2-keras-transformer-elastic-20210723-042836-launcher" "scheduler"="default"
I0723 04:42:44.464179   16467 placement_manager.go:183]  "msg"="Finished job placements adjustment"  "scheduler"="default"
I0723 04:42:44.464495   16467 scheduler.go:182]  "msg"="Finished resched"  "scheduler"="default"
I0723 04:42:46.008331   16467 placement_manager.go:147]  "msg"="Adding toleration to pod"  "podName"="tf2-keras-cifar10-vgg16-elastic-20210723-044128-worker-0" "scheduler"="default" "toleration"={"key":"celeste/hostname","operator":"Equal","value":"gpu3","effect":"NoExecute"}
I0723 04:42:46.407190   16467 placement_manager.go:147]  "msg"="Adding toleration to pod"  "podName"="tf2-keras-cifar10-vgg16-elastic-20210723-044128-launcher" "scheduler"="default" "toleration"={"key":"celeste/hostname","operator":"Exists","effect":"NoExecute"}
I0723 04:42:46.606294   16467 placement_manager.go:147]  "msg"="Adding toleration to pod"  "podName"="tf2-keras-transformer-elastic-20210723-044102-worker-0" "scheduler"="default" "toleration"={"key":"celeste/hostname","operator":"Equal","value":"gpu4","effect":"NoExecute"}
I0723 04:42:47.006494   16467 placement_manager.go:147]  "msg"="Adding toleration to pod"  "podName"="tf2-keras-transformer-elastic-20210723-044102-launcher" "scheduler"="default" "toleration"={"key":"celeste/hostname","operator":"Exists","effect":"NoExecute"}
I0723 04:42:52.707794   16467 placement_manager.go:147]  "msg"="Adding toleration to pod"  "podName"="tf2-keras-transformer-elastic-20210723-042836-launcher" "scheduler"="default" "toleration"={"key":"celeste/hostname","operator":"Exists","effect":"NoExecute"}
I0723 04:42:54.216372   16467 placement_manager.go:147]  "msg"="Adding toleration to pod"  "podName"="tf2-keras-cifar10-inceptionv3-elastic-20210723-041521-worker-0" "scheduler"="default" "toleration"={"key":"celeste/hostname","operator":"Equal","value":"gpu5","effect":"NoExecute"}
I0723 04:42:54.249139   16467 placement_manager.go:147]  "msg"="Adding toleration to pod"  "podName"="tf2-keras-cifar10-inceptionv3-elastic-20210723-041521-worker-1" "scheduler"="default" "toleration"={"key":"celeste/hostname","operator":"Equal","value":"gpu5","effect":"NoExecute"}
I0723 04:43:01.285743   16467 placement_manager.go:147]  "msg"="Adding toleration to pod"  "podName"="tf2-keras-cifar10-inceptionv3-elastic-20210723-043156-worker-0" "scheduler"="default" "toleration"={"key":"celeste/hostname","operator":"Equal","value":"gpu4","effect":"NoExecute"}
I0723 04:43:01.678532   16467 placement_manager.go:147]  "msg"="Adding toleration to pod"  "podName"="tf2-keras-cifar10-inceptionv3-elastic-20210723-043156-launcher" "scheduler"="default" "toleration"={"key":"celeste/hostname","operator":"Exists","effect":"NoExecute"}
I0723 04:43:08.025222   16467 placement_manager.go:147]  "msg"="Adding toleration to pod"  "podName"="tf2-keras-transformer-elastic-20210723-042836-worker-0" "scheduler"="default" "toleration"={"key":"celeste/hostname","operator":"Equal","value":"gpu3","effect":"NoExecute"}
I0723 04:43:08.821497   16467 placement_manager.go:147]  "msg"="Adding toleration to pod"  "podName"="tf2-keras-cifar10-inceptionv3-elastic-20210723-041521-launcher" "scheduler"="default" "toleration"={"key":"celeste/hostname","operator":"Exists","effect":"NoExecute"}
I0723 04:43:19.149036   16467 jobmaster.go:155]  "msg"="Training job created"  "job"="tf2-keras-cifar10-vgg16-elastic-20210723-044319"
I0723 04:43:19.149206   16467 scheduler.go:135]  "msg"="Received resched event, may be blocked because of rate limit"  "blockedUntil"="2021-07-23T04:44:44.464712009+08:00" "lastResched"="2021-07-23T04:42:44.464712009+08:00" "received"="2021-07-23T04:43:19.148377437+08:00" "scheduler"="default"
I0723 04:44:03.084898   16467 jobmaster.go:155]  "msg"="Training job created"  "job"="tf2-keras-cifar10-resnet50-elastic-20210723-044403"
I0723 04:44:05.027077   16467 jobmaster.go:155]  "msg"="Training job created"  "job"="tf2-keras-cifar10-inceptionv3-elastic-20210723-044405"
I0723 04:44:15.932311   16467 jobmaster.go:155]  "msg"="Training job created"  "job"="tf2-keras-transformer-elastic-20210723-044415"
I0723 04:44:18.837711   16467 jobmaster.go:155]  "msg"="Training job created"  "job"="tf2-keras-cifar10-inceptionv3-elastic-20210723-044418"
I0723 04:44:44.464760   16467 scheduler.go:159]  "msg"="Started resched"  "scheduler"="default"
I0723 04:44:44.464803   16467 scheduler.go:193]  "msg"="Updating all jobs info"  "scheduler"="default"
I0723 04:44:44.477674   16467 elastic_fifo.go:73]  "msg"="Finished scheduling"  "algorithm"="ElasticFIFO" "freeGpu"=0 "result"={"tf2-keras-cifar10-inceptionv3-elastic-20210723-041509":1,"tf2-keras-cifar10-inceptionv3-elastic-20210723-041521":1,"tf2-keras-cifar10-inceptionv3-elastic-20210723-043156":1,"tf2-keras-cifar10-inceptionv3-elastic-20210723-044044":1,"tf2-keras-cifar10-inceptionv3-elastic-20210723-044405":1,"tf2-keras-cifar10-inceptionv3-elastic-20210723-044418":0,"tf2-keras-cifar10-resnet50-elastic-20210723-043618":1,"tf2-keras-cifar10-resnet50-elastic-20210723-044403":1,"tf2-keras-cifar10-vgg16-elastic-20210723-044128":1,"tf2-keras-cifar10-vgg16-elastic-20210723-044319":1,"tf2-keras-transformer-elastic-20210723-041753":1,"tf2-keras-transformer-elastic-20210723-042836":1,"tf2-keras-transformer-elastic-20210723-044102":1,"tf2-keras-transformer-elastic-20210723-044415":0} "scheduler"="default"
I0723 04:44:44.478085   16467 scheduler.go:384]  "msg"="Trying to delete multiple training jobs"  "jobs"=[] "scheduler"="default"
I0723 04:44:44.478463   16467 scheduler.go:342]  "msg"="Trying to scale multiple training jobs"  "jobs"=["tf2-keras-transformer-elastic-20210723-041753","tf2-keras-cifar10-inceptionv3-elastic-20210723-041521","tf2-keras-cifar10-inceptionv3-elastic-20210723-041509"] "scheduler"="default"
I0723 04:44:44.529815   16467 scheduler.go:292]  "msg"="Trying to start multiple training jobs"  "jobs"=["tf2-keras-cifar10-resnet50-elastic-20210723-044403","tf2-keras-cifar10-vgg16-elastic-20210723-044319","tf2-keras-cifar10-inceptionv3-elastic-20210723-044405"] "scheduler"="default"
I0723 04:44:44.554109   16467 scheduler.go:342]  "msg"="Trying to scale multiple training jobs"  "jobs"=[] "scheduler"="default"
I0723 04:44:44.559506   16467 placement_manager.go:166]  "msg"="Started job placements adjustment"  "scheduler"="default"
I0723 04:44:44.559597   16467 placement_manager.go:192]  "msg"="Releasing slots"  "jobs"={"tf2-keras-cifar10-inceptionv3-elastic-20210723-041509":{},"tf2-keras-cifar10-inceptionv3-elastic-20210723-041521":{},"tf2-keras-cifar10-inceptionv3-elastic-20210723-043156":{},"tf2-keras-cifar10-inceptionv3-elastic-20210723-044044":{},"tf2-keras-cifar10-resnet50-elastic-20210723-043618":{},"tf2-keras-cifar10-vgg16-elastic-20210723-044128":{},"tf2-keras-transformer-elastic-20210723-041753":{},"tf2-keras-transformer-elastic-20210723-042836":{},"tf2-keras-transformer-elastic-20210723-044102":{}} "nodes"={"gpu3":{},"gpu4":{},"gpu5":{}} "scheduler"="default"
I0723 04:44:44.559669   16467 placement_manager.go:250]  "msg"="Released slots"  "jobs"={"tf2-keras-cifar10-inceptionv3-elastic-20210723-041509":{},"tf2-keras-cifar10-inceptionv3-elastic-20210723-041521":{},"tf2-keras-cifar10-inceptionv3-elastic-20210723-043156":{},"tf2-keras-cifar10-inceptionv3-elastic-20210723-044044":{},"tf2-keras-cifar10-resnet50-elastic-20210723-043618":{},"tf2-keras-cifar10-vgg16-elastic-20210723-044128":{},"tf2-keras-transformer-elastic-20210723-041753":{},"tf2-keras-transformer-elastic-20210723-042836":{},"tf2-keras-transformer-elastic-20210723-044102":{}} "nodes"={"gpu3":{},"gpu4":{},"gpu5":{}} "scheduler"="default"
I0723 04:44:44.560222   16467 placement_manager.go:305]  "msg"="Found best-fit"  "crossNode"=0 "nodes"=[{},{},{}] "requests"=[{},{},{},{},{},{},{},{},{},{},{},{},{},{},{},{},{},{},{},{},{},{},{},{},{},{},{},{}] "scheduler"="default"
I0723 04:44:44.560595   16467 placement_manager.go:339]  "msg"="nodeStates updated"  "new"={"gpu3":{},"gpu4":{},"gpu5":{}} "old"={"gpu3":{},"gpu4":{},"gpu5":{}} "scheduler"="default" "score"=4
I0723 04:44:44.560994   16467 placement_manager.go:387]  "msg"="jobStates updated"  "new"={"tf2-keras-cifar10-inceptionv3-elastic-20210723-041509":{},"tf2-keras-cifar10-inceptionv3-elastic-20210723-041521":{},"tf2-keras-cifar10-inceptionv3-elastic-20210723-043156":{},"tf2-keras-cifar10-inceptionv3-elastic-20210723-044044":{},"tf2-keras-cifar10-inceptionv3-elastic-20210723-044405":{},"tf2-keras-cifar10-resnet50-elastic-20210723-043618":{},"tf2-keras-cifar10-resnet50-elastic-20210723-044403":{},"tf2-keras-cifar10-vgg16-elastic-20210723-044128":{},"tf2-keras-cifar10-vgg16-elastic-20210723-044319":{},"tf2-keras-transformer-elastic-20210723-041753":{},"tf2-keras-transformer-elastic-20210723-042836":{},"tf2-keras-transformer-elastic-20210723-044102":{}} "old"={"tf2-keras-cifar10-inceptionv3-elastic-20210723-041509":{},"tf2-keras-cifar10-inceptionv3-elastic-20210723-041521":{},"tf2-keras-cifar10-inceptionv3-elastic-20210723-043156":{},"tf2-keras-cifar10-inceptionv3-elastic-20210723-044044":{},"tf2-keras-cifar10-resnet50-elastic-20210723-043618":{},"tf2-keras-cifar10-vgg16-elastic-20210723-044128":{},"tf2-keras-transformer-elastic-20210723-041753":{},"tf2-keras-transformer-elastic-20210723-042836":{},"tf2-keras-transformer-elastic-20210723-044102":{}} "scheduler"="default"
I0723 04:44:44.561611   16467 placement_manager.go:434]  "msg"="podNodeName updated"  "launchersToDelete"=5 "new"={"tf2-keras-cifar10-inceptionv3-elastic-20210723-041509-worker-0":"gpu5","tf2-keras-cifar10-inceptionv3-elastic-20210723-041521-worker-0":"gpu4","tf2-keras-cifar10-inceptionv3-elastic-20210723-043156-worker-0":"gpu4","tf2-keras-cifar10-inceptionv3-elastic-20210723-044044-worker-0":"gpu5","tf2-keras-cifar10-inceptionv3-elastic-20210723-044405-worker-0":"gpu5","tf2-keras-cifar10-resnet50-elastic-20210723-043618-worker-0":"gpu4","tf2-keras-cifar10-resnet50-elastic-20210723-044403-worker-0":"gpu3","tf2-keras-cifar10-vgg16-elastic-20210723-044128-worker-0":"gpu3","tf2-keras-cifar10-vgg16-elastic-20210723-044319-worker-0":"gpu3","tf2-keras-transformer-elastic-20210723-041753-worker-0":"gpu4","tf2-keras-transformer-elastic-20210723-042836-worker-0":"gpu5","tf2-keras-transformer-elastic-20210723-044102-worker-0":"gpu3"} "old"={"tf2-keras-cifar10-inceptionv3-elastic-20210723-041509-worker-0":"gpu5","tf2-keras-cifar10-inceptionv3-elastic-20210723-041509-worker-1":"gpu5","tf2-keras-cifar10-inceptionv3-elastic-20210723-041521-worker-0":"gpu5","tf2-keras-cifar10-inceptionv3-elastic-20210723-041521-worker-1":"gpu5","tf2-keras-cifar10-inceptionv3-elastic-20210723-043156-worker-0":"gpu4","tf2-keras-cifar10-inceptionv3-elastic-20210723-044044-worker-0":"gpu4","tf2-keras-cifar10-resnet50-elastic-20210723-043618-worker-0":"gpu4","tf2-keras-cifar10-vgg16-elastic-20210723-044128-worker-0":"gpu3","tf2-keras-transformer-elastic-20210723-041753-worker-0":"gpu3","tf2-keras-transformer-elastic-20210723-041753-worker-1":"gpu3","tf2-keras-transformer-elastic-20210723-042836-worker-0":"gpu3","tf2-keras-transformer-elastic-20210723-044102-worker-0":"gpu4"} "scheduler"="default" "workersToDelete"=5
I0723 04:44:44.563290   16467 placement_manager.go:451]  "msg"="Deleting pod that need migration"  "podName"="tf2-keras-transformer-elastic-20210723-041753-worker-0" "scheduler"="default"
I0723 04:44:44.567499   16467 placement_manager.go:451]  "msg"="Deleting pod that need migration"  "podName"="tf2-keras-transformer-elastic-20210723-041753-launcher" "scheduler"="default"
I0723 04:44:44.572536   16467 placement_manager.go:451]  "msg"="Deleting pod that need migration"  "podName"="tf2-keras-cifar10-inceptionv3-elastic-20210723-044044-worker-0" "scheduler"="default"
I0723 04:44:44.582816   16467 placement_manager.go:451]  "msg"="Deleting pod that need migration"  "podName"="tf2-keras-cifar10-inceptionv3-elastic-20210723-044044-launcher" "scheduler"="default"
I0723 04:44:44.589299   16467 placement_manager.go:451]  "msg"="Deleting pod that need migration"  "podName"="tf2-keras-transformer-elastic-20210723-044102-worker-0" "scheduler"="default"
I0723 04:44:44.593766   16467 placement_manager.go:451]  "msg"="Deleting pod that need migration"  "podName"="tf2-keras-transformer-elastic-20210723-044102-launcher" "scheduler"="default"
I0723 04:44:44.601213   16467 placement_manager.go:451]  "msg"="Deleting pod that need migration"  "podName"="tf2-keras-cifar10-inceptionv3-elastic-20210723-041521-worker-0" "scheduler"="default"
I0723 04:44:44.604980   16467 placement_manager.go:451]  "msg"="Deleting pod that need migration"  "podName"="tf2-keras-cifar10-inceptionv3-elastic-20210723-041521-launcher" "scheduler"="default"
I0723 04:44:44.610132   16467 placement_manager.go:451]  "msg"="Deleting pod that need migration"  "podName"="tf2-keras-transformer-elastic-20210723-042836-worker-0" "scheduler"="default"
I0723 04:44:44.614407   16467 placement_manager.go:451]  "msg"="Deleting pod that need migration"  "podName"="tf2-keras-transformer-elastic-20210723-042836-launcher" "scheduler"="default"
I0723 04:44:44.619291   16467 placement_manager.go:183]  "msg"="Finished job placements adjustment"  "scheduler"="default"
I0723 04:44:44.619558   16467 scheduler.go:182]  "msg"="Finished resched"  "scheduler"="default"
I0723 04:44:47.112586   16467 placement_manager.go:147]  "msg"="Adding toleration to pod"  "podName"="tf2-keras-cifar10-resnet50-elastic-20210723-044403-worker-0" "scheduler"="default" "toleration"={"key":"celeste/hostname","operator":"Equal","value":"gpu3","effect":"NoExecute"}
I0723 04:44:47.508843   16467 placement_manager.go:147]  "msg"="Adding toleration to pod"  "podName"="tf2-keras-cifar10-resnet50-elastic-20210723-044403-launcher" "scheduler"="default" "toleration"={"key":"celeste/hostname","operator":"Exists","effect":"NoExecute"}
I0723 04:44:48.708942   16467 placement_manager.go:147]  "msg"="Adding toleration to pod"  "podName"="tf2-keras-cifar10-vgg16-elastic-20210723-044319-worker-0" "scheduler"="default" "toleration"={"key":"celeste/hostname","operator":"Equal","value":"gpu3","effect":"NoExecute"}
I0723 04:44:49.110397   16467 placement_manager.go:147]  "msg"="Adding toleration to pod"  "podName"="tf2-keras-cifar10-vgg16-elastic-20210723-044319-launcher" "scheduler"="default" "toleration"={"key":"celeste/hostname","operator":"Exists","effect":"NoExecute"}
I0723 04:44:50.309170   16467 placement_manager.go:147]  "msg"="Adding toleration to pod"  "podName"="tf2-keras-cifar10-inceptionv3-elastic-20210723-044405-worker-0" "scheduler"="default" "toleration"={"key":"celeste/hostname","operator":"Equal","value":"gpu5","effect":"NoExecute"}
I0723 04:44:50.710850   16467 placement_manager.go:147]  "msg"="Adding toleration to pod"  "podName"="tf2-keras-cifar10-inceptionv3-elastic-20210723-044405-launcher" "scheduler"="default" "toleration"={"key":"celeste/hostname","operator":"Exists","effect":"NoExecute"}
I0723 04:44:53.439891   16467 placement_manager.go:147]  "msg"="Adding toleration to pod"  "podName"="tf2-keras-transformer-elastic-20210723-042836-launcher" "scheduler"="default" "toleration"={"key":"celeste/hostname","operator":"Exists","effect":"NoExecute"}
I0723 04:44:54.910187   16467 placement_manager.go:147]  "msg"="Adding toleration to pod"  "podName"="tf2-keras-cifar10-inceptionv3-elastic-20210723-044044-worker-0" "scheduler"="default" "toleration"={"key":"celeste/hostname","operator":"Equal","value":"gpu5","effect":"NoExecute"}
I0723 04:44:55.110556   16467 placement_manager.go:147]  "msg"="Adding toleration to pod"  "podName"="tf2-keras-transformer-elastic-20210723-041753-worker-0" "scheduler"="default" "toleration"={"key":"celeste/hostname","operator":"Equal","value":"gpu4","effect":"NoExecute"}
I0723 04:44:55.510402   16467 placement_manager.go:147]  "msg"="Adding toleration to pod"  "podName"="tf2-keras-transformer-elastic-20210723-044102-launcher" "scheduler"="default" "toleration"={"key":"celeste/hostname","operator":"Exists","effect":"NoExecute"}
I0723 04:44:56.108738   16467 placement_manager.go:147]  "msg"="Adding toleration to pod"  "podName"="tf2-keras-transformer-elastic-20210723-044102-worker-0" "scheduler"="default" "toleration"={"key":"celeste/hostname","operator":"Equal","value":"gpu3","effect":"NoExecute"}
I0723 04:44:56.511687   16467 placement_manager.go:147]  "msg"="Adding toleration to pod"  "podName"="tf2-keras-cifar10-inceptionv3-elastic-20210723-044044-launcher" "scheduler"="default" "toleration"={"key":"celeste/hostname","operator":"Exists","effect":"NoExecute"}
I0723 04:44:57.108800   16467 placement_manager.go:147]  "msg"="Adding toleration to pod"  "podName"="tf2-keras-transformer-elastic-20210723-042836-worker-0" "scheduler"="default" "toleration"={"key":"celeste/hostname","operator":"Equal","value":"gpu5","effect":"NoExecute"}
I0723 04:44:57.718458   16467 placement_manager.go:147]  "msg"="Adding toleration to pod"  "podName"="tf2-keras-cifar10-inceptionv3-elastic-20210723-041521-worker-0" "scheduler"="default" "toleration"={"key":"celeste/hostname","operator":"Equal","value":"gpu4","effect":"NoExecute"}
I0723 04:45:00.842618   16467 placement_manager.go:147]  "msg"="Adding toleration to pod"  "podName"="tf2-keras-cifar10-inceptionv3-elastic-20210723-041521-launcher" "scheduler"="default" "toleration"={"key":"celeste/hostname","operator":"Exists","effect":"NoExecute"}
I0723 04:45:04.254620   16467 placement_manager.go:147]  "msg"="Adding toleration to pod"  "podName"="tf2-keras-transformer-elastic-20210723-041753-launcher" "scheduler"="default" "toleration"={"key":"celeste/hostname","operator":"Exists","effect":"NoExecute"}
I0723 04:46:49.868566   16467 jobmaster.go:155]  "msg"="Training job created"  "job"="tf2-keras-cifar10-resnet50-elastic-20210723-044649"
I0723 04:46:49.868697   16467 scheduler.go:135]  "msg"="Received resched event, may be blocked because of rate limit"  "blockedUntil"="2021-07-23T04:46:44.619760809+08:00" "lastResched"="2021-07-23T04:44:44.619760809+08:00" "received"="2021-07-23T04:46:49.868061856+08:00" "scheduler"="default"
I0723 04:46:49.869352   16467 scheduler.go:159]  "msg"="Started resched"  "scheduler"="default"
I0723 04:46:49.869415   16467 scheduler.go:193]  "msg"="Updating all jobs info"  "scheduler"="default"
I0723 04:46:49.881851   16467 elastic_fifo.go:73]  "msg"="Finished scheduling"  "algorithm"="ElasticFIFO" "freeGpu"=0 "result"={"tf2-keras-cifar10-inceptionv3-elastic-20210723-041509":1,"tf2-keras-cifar10-inceptionv3-elastic-20210723-041521":1,"tf2-keras-cifar10-inceptionv3-elastic-20210723-043156":1,"tf2-keras-cifar10-inceptionv3-elastic-20210723-044044":1,"tf2-keras-cifar10-inceptionv3-elastic-20210723-044405":1,"tf2-keras-cifar10-inceptionv3-elastic-20210723-044418":0,"tf2-keras-cifar10-resnet50-elastic-20210723-043618":1,"tf2-keras-cifar10-resnet50-elastic-20210723-044403":1,"tf2-keras-cifar10-resnet50-elastic-20210723-044649":0,"tf2-keras-cifar10-vgg16-elastic-20210723-044128":1,"tf2-keras-cifar10-vgg16-elastic-20210723-044319":1,"tf2-keras-transformer-elastic-20210723-041753":1,"tf2-keras-transformer-elastic-20210723-042836":1,"tf2-keras-transformer-elastic-20210723-044102":1,"tf2-keras-transformer-elastic-20210723-044415":0} "scheduler"="default"
I0723 04:46:49.882208   16467 scheduler.go:384]  "msg"="Trying to delete multiple training jobs"  "jobs"=[] "scheduler"="default"
I0723 04:46:49.882442   16467 scheduler.go:342]  "msg"="Trying to scale multiple training jobs"  "jobs"=[] "scheduler"="default"
I0723 04:46:49.882610   16467 scheduler.go:292]  "msg"="Trying to start multiple training jobs"  "jobs"=[] "scheduler"="default"
I0723 04:46:49.882810   16467 scheduler.go:342]  "msg"="Trying to scale multiple training jobs"  "jobs"=[] "scheduler"="default"
I0723 04:46:49.883039   16467 scheduler.go:180]  "msg"="Nothing changed, skipped ajust placements"  "scheduler"="default"
I0723 04:46:49.883065   16467 scheduler.go:182]  "msg"="Finished resched"  "scheduler"="default"
I0723 04:54:29.952295   16467 scheduler.go:474]  "msg"="Training job completed"  "elaspedTotalSeconds"=2195.858298 "gpuTotalSeconds"=3535.106852346 "job"="tf2-keras-transformer-elastic-20210723-041753" "ranTotalSeconds"=2120.066081742 "scheduler"="default" "waitedTotalSeconds"=75.792216258
I0723 04:54:29.952459   16467 scheduler.go:135]  "msg"="Received resched event, may be blocked because of rate limit"  "blockedUntil"="2021-07-23T04:48:49.883238712+08:00" "lastResched"="2021-07-23T04:46:49.883238712+08:00" "received"="2021-07-23T04:54:29.952329035+08:00" "scheduler"="default"
I0723 04:54:29.952983   16467 scheduler.go:159]  "msg"="Started resched"  "scheduler"="default"
I0723 04:54:29.953054   16467 scheduler.go:193]  "msg"="Updating all jobs info"  "scheduler"="default"
I0723 04:54:29.965699   16467 elastic_fifo.go:73]  "msg"="Finished scheduling"  "algorithm"="ElasticFIFO" "freeGpu"=0 "result"={"tf2-keras-cifar10-inceptionv3-elastic-20210723-041509":1,"tf2-keras-cifar10-inceptionv3-elastic-20210723-041521":1,"tf2-keras-cifar10-inceptionv3-elastic-20210723-043156":1,"tf2-keras-cifar10-inceptionv3-elastic-20210723-044044":1,"tf2-keras-cifar10-inceptionv3-elastic-20210723-044405":1,"tf2-keras-cifar10-inceptionv3-elastic-20210723-044418":0,"tf2-keras-cifar10-resnet50-elastic-20210723-043618":1,"tf2-keras-cifar10-resnet50-elastic-20210723-044403":1,"tf2-keras-cifar10-resnet50-elastic-20210723-044649":0,"tf2-keras-cifar10-vgg16-elastic-20210723-044128":1,"tf2-keras-cifar10-vgg16-elastic-20210723-044319":1,"tf2-keras-transformer-elastic-20210723-042836":1,"tf2-keras-transformer-elastic-20210723-044102":1,"tf2-keras-transformer-elastic-20210723-044415":1} "scheduler"="default"
I0723 04:54:29.966301   16467 scheduler.go:384]  "msg"="Trying to delete multiple training jobs"  "jobs"=[] "scheduler"="default"
I0723 04:54:29.966627   16467 scheduler.go:342]  "msg"="Trying to scale multiple training jobs"  "jobs"=[] "scheduler"="default"
I0723 04:54:29.966909   16467 scheduler.go:292]  "msg"="Trying to start multiple training jobs"  "jobs"=["tf2-keras-transformer-elastic-20210723-044415"] "scheduler"="default"
I0723 04:54:29.976808   16467 scheduler.go:342]  "msg"="Trying to scale multiple training jobs"  "jobs"=[] "scheduler"="default"
I0723 04:54:29.981428   16467 placement_manager.go:166]  "msg"="Started job placements adjustment"  "scheduler"="default"
I0723 04:54:29.981531   16467 placement_manager.go:192]  "msg"="Releasing slots"  "jobs"={"tf2-keras-cifar10-inceptionv3-elastic-20210723-041509":{},"tf2-keras-cifar10-inceptionv3-elastic-20210723-041521":{},"tf2-keras-cifar10-inceptionv3-elastic-20210723-043156":{},"tf2-keras-cifar10-inceptionv3-elastic-20210723-044044":{},"tf2-keras-cifar10-inceptionv3-elastic-20210723-044405":{},"tf2-keras-cifar10-resnet50-elastic-20210723-043618":{},"tf2-keras-cifar10-resnet50-elastic-20210723-044403":{},"tf2-keras-cifar10-vgg16-elastic-20210723-044128":{},"tf2-keras-cifar10-vgg16-elastic-20210723-044319":{},"tf2-keras-transformer-elastic-20210723-041753":{},"tf2-keras-transformer-elastic-20210723-042836":{},"tf2-keras-transformer-elastic-20210723-044102":{}} "nodes"={"gpu3":{},"gpu4":{},"gpu5":{}} "scheduler"="default"
I0723 04:54:29.981678   16467 placement_manager.go:250]  "msg"="Released slots"  "jobs"={"tf2-keras-cifar10-inceptionv3-elastic-20210723-041509":{},"tf2-keras-cifar10-inceptionv3-elastic-20210723-041521":{},"tf2-keras-cifar10-inceptionv3-elastic-20210723-043156":{},"tf2-keras-cifar10-inceptionv3-elastic-20210723-044044":{},"tf2-keras-cifar10-inceptionv3-elastic-20210723-044405":{},"tf2-keras-cifar10-resnet50-elastic-20210723-043618":{},"tf2-keras-cifar10-resnet50-elastic-20210723-044403":{},"tf2-keras-cifar10-vgg16-elastic-20210723-044128":{},"tf2-keras-cifar10-vgg16-elastic-20210723-044319":{},"tf2-keras-transformer-elastic-20210723-041753":{},"tf2-keras-transformer-elastic-20210723-042836":{},"tf2-keras-transformer-elastic-20210723-044102":{}} "nodes"={"gpu3":{},"gpu4":{},"gpu5":{}} "scheduler"="default"
I0723 04:54:29.982249   16467 placement_manager.go:305]  "msg"="Found best-fit"  "crossNode"=0 "nodes"=[{},{},{}] "requests"=[{},{},{},{},{},{},{},{},{},{},{},{},{},{},{},{},{},{},{},{},{},{},{},{},{},{},{},{}] "scheduler"="default"
I0723 04:54:29.982624   16467 placement_manager.go:339]  "msg"="nodeStates updated"  "new"={"gpu3":{},"gpu4":{},"gpu5":{}} "old"={"gpu3":{},"gpu4":{},"gpu5":{}} "scheduler"="default" "score"=5
I0723 04:54:29.983017   16467 placement_manager.go:387]  "msg"="jobStates updated"  "new"={"tf2-keras-cifar10-inceptionv3-elastic-20210723-041509":{},"tf2-keras-cifar10-inceptionv3-elastic-20210723-041521":{},"tf2-keras-cifar10-inceptionv3-elastic-20210723-043156":{},"tf2-keras-cifar10-inceptionv3-elastic-20210723-044044":{},"tf2-keras-cifar10-inceptionv3-elastic-20210723-044405":{},"tf2-keras-cifar10-resnet50-elastic-20210723-043618":{},"tf2-keras-cifar10-resnet50-elastic-20210723-044403":{},"tf2-keras-cifar10-vgg16-elastic-20210723-044128":{},"tf2-keras-cifar10-vgg16-elastic-20210723-044319":{},"tf2-keras-transformer-elastic-20210723-042836":{},"tf2-keras-transformer-elastic-20210723-044102":{},"tf2-keras-transformer-elastic-20210723-044415":{}} "old"={"tf2-keras-cifar10-inceptionv3-elastic-20210723-041509":{},"tf2-keras-cifar10-inceptionv3-elastic-20210723-041521":{},"tf2-keras-cifar10-inceptionv3-elastic-20210723-043156":{},"tf2-keras-cifar10-inceptionv3-elastic-20210723-044044":{},"tf2-keras-cifar10-inceptionv3-elastic-20210723-044405":{},"tf2-keras-cifar10-resnet50-elastic-20210723-043618":{},"tf2-keras-cifar10-resnet50-elastic-20210723-044403":{},"tf2-keras-cifar10-vgg16-elastic-20210723-044128":{},"tf2-keras-cifar10-vgg16-elastic-20210723-044319":{},"tf2-keras-transformer-elastic-20210723-041753":{},"tf2-keras-transformer-elastic-20210723-042836":{},"tf2-keras-transformer-elastic-20210723-044102":{}} "scheduler"="default"
I0723 04:54:29.983418   16467 placement_manager.go:434]  "msg"="podNodeName updated"  "launchersToDelete"=6 "new"={"tf2-keras-cifar10-inceptionv3-elastic-20210723-041509-worker-0":"gpu5","tf2-keras-cifar10-inceptionv3-elastic-20210723-041521-worker-0":"gpu4","tf2-keras-cifar10-inceptionv3-elastic-20210723-043156-worker-0":"gpu4","tf2-keras-cifar10-inceptionv3-elastic-20210723-044044-worker-0":"gpu4","tf2-keras-cifar10-inceptionv3-elastic-20210723-044405-worker-0":"gpu3","tf2-keras-cifar10-resnet50-elastic-20210723-043618-worker-0":"gpu3","tf2-keras-cifar10-resnet50-elastic-20210723-044403-worker-0":"gpu3","tf2-keras-cifar10-vgg16-elastic-20210723-044128-worker-0":"gpu5","tf2-keras-cifar10-vgg16-elastic-20210723-044319-worker-0":"gpu5","tf2-keras-transformer-elastic-20210723-042836-worker-0":"gpu5","tf2-keras-transformer-elastic-20210723-044102-worker-0":"gpu4","tf2-keras-transformer-elastic-20210723-044415-worker-0":"gpu3"} "old"={"tf2-keras-cifar10-inceptionv3-elastic-20210723-041509-worker-0":"gpu5","tf2-keras-cifar10-inceptionv3-elastic-20210723-041521-worker-0":"gpu4","tf2-keras-cifar10-inceptionv3-elastic-20210723-043156-worker-0":"gpu4","tf2-keras-cifar10-inceptionv3-elastic-20210723-044044-worker-0":"gpu5","tf2-keras-cifar10-inceptionv3-elastic-20210723-044405-worker-0":"gpu5","tf2-keras-cifar10-resnet50-elastic-20210723-043618-worker-0":"gpu4","tf2-keras-cifar10-resnet50-elastic-20210723-044403-worker-0":"gpu3","tf2-keras-cifar10-vgg16-elastic-20210723-044128-worker-0":"gpu3","tf2-keras-cifar10-vgg16-elastic-20210723-044319-worker-0":"gpu3","tf2-keras-transformer-elastic-20210723-041753-worker-0":"gpu4","tf2-keras-transformer-elastic-20210723-042836-worker-0":"gpu5","tf2-keras-transformer-elastic-20210723-044102-worker-0":"gpu3"} "scheduler"="default" "workersToDelete"=6
I0723 04:54:29.983746   16467 placement_manager.go:451]  "msg"="Deleting pod that need migration"  "podName"="tf2-keras-cifar10-vgg16-elastic-20210723-044128-worker-0" "scheduler"="default"
I0723 04:54:29.991224   16467 placement_manager.go:451]  "msg"="Deleting pod that need migration"  "podName"="tf2-keras-cifar10-vgg16-elastic-20210723-044128-launcher" "scheduler"="default"
I0723 04:54:30.004150   16467 placement_manager.go:451]  "msg"="Deleting pod that need migration"  "podName"="tf2-keras-cifar10-vgg16-elastic-20210723-044319-worker-0" "scheduler"="default"
I0723 04:54:30.011034   16467 placement_manager.go:451]  "msg"="Deleting pod that need migration"  "podName"="tf2-keras-cifar10-vgg16-elastic-20210723-044319-launcher" "scheduler"="default"
I0723 04:54:30.014940   16467 placement_manager.go:451]  "msg"="Deleting pod that need migration"  "podName"="tf2-keras-cifar10-resnet50-elastic-20210723-043618-worker-0" "scheduler"="default"
I0723 04:54:30.019393   16467 placement_manager.go:451]  "msg"="Deleting pod that need migration"  "podName"="tf2-keras-cifar10-resnet50-elastic-20210723-043618-launcher" "scheduler"="default"
I0723 04:54:30.023259   16467 placement_manager.go:451]  "msg"="Deleting pod that need migration"  "podName"="tf2-keras-transformer-elastic-20210723-044102-worker-0" "scheduler"="default"
I0723 04:54:30.033488   16467 placement_manager.go:451]  "msg"="Deleting pod that need migration"  "podName"="tf2-keras-transformer-elastic-20210723-044102-launcher" "scheduler"="default"
I0723 04:54:30.038391   16467 placement_manager.go:451]  "msg"="Deleting pod that need migration"  "podName"="tf2-keras-cifar10-inceptionv3-elastic-20210723-044044-worker-0" "scheduler"="default"
I0723 04:54:30.048780   16467 placement_manager.go:451]  "msg"="Deleting pod that need migration"  "podName"="tf2-keras-cifar10-inceptionv3-elastic-20210723-044044-launcher" "scheduler"="default"
I0723 04:54:30.055399   16467 placement_manager.go:451]  "msg"="Deleting pod that need migration"  "podName"="tf2-keras-cifar10-inceptionv3-elastic-20210723-044405-worker-0" "scheduler"="default"
I0723 04:54:30.190543   16467 placement_manager.go:451]  "msg"="Deleting pod that need migration"  "podName"="tf2-keras-cifar10-inceptionv3-elastic-20210723-044405-launcher" "scheduler"="default"
I0723 04:54:30.343800   16467 placement_manager.go:147]  "msg"="Adding toleration to pod"  "podName"="tf2-keras-transformer-elastic-20210723-044415-worker-0" "scheduler"="default" "toleration"={"key":"celeste/hostname","operator":"Equal","value":"gpu3","effect":"NoExecute"}
I0723 04:54:30.389938   16467 placement_manager.go:183]  "msg"="Finished job placements adjustment"  "scheduler"="default"
I0723 04:54:30.390203   16467 scheduler.go:182]  "msg"="Finished resched"  "scheduler"="default"
I0723 04:54:30.792828   16467 placement_manager.go:147]  "msg"="Adding toleration to pod"  "podName"="tf2-keras-transformer-elastic-20210723-044415-launcher" "scheduler"="default" "toleration"={"key":"celeste/hostname","operator":"Exists","effect":"NoExecute"}
I0723 04:54:36.799213   16467 placement_manager.go:147]  "msg"="Adding toleration to pod"  "podName"="tf2-keras-cifar10-vgg16-elastic-20210723-044319-launcher" "scheduler"="default" "toleration"={"key":"celeste/hostname","operator":"Exists","effect":"NoExecute"}
I0723 04:54:37.132861   16467 placement_manager.go:147]  "msg"="Adding toleration to pod"  "podName"="tf2-keras-cifar10-resnet50-elastic-20210723-043618-worker-0" "scheduler"="default" "toleration"={"key":"celeste/hostname","operator":"Equal","value":"gpu3","effect":"NoExecute"}
I0723 04:54:38.444781   16467 placement_manager.go:147]  "msg"="Adding toleration to pod"  "podName"="tf2-keras-cifar10-vgg16-elastic-20210723-044128-launcher" "scheduler"="default" "toleration"={"key":"celeste/hostname","operator":"Exists","effect":"NoExecute"}
I0723 04:54:39.835912   16467 placement_manager.go:147]  "msg"="Adding toleration to pod"  "podName"="tf2-keras-cifar10-inceptionv3-elastic-20210723-044405-worker-0" "scheduler"="default" "toleration"={"key":"celeste/hostname","operator":"Equal","value":"gpu3","effect":"NoExecute"}
I0723 04:54:40.334319   16467 placement_manager.go:147]  "msg"="Adding toleration to pod"  "podName"="tf2-keras-cifar10-vgg16-elastic-20210723-044319-worker-0" "scheduler"="default" "toleration"={"key":"celeste/hostname","operator":"Equal","value":"gpu5","effect":"NoExecute"}
I0723 04:54:41.137408   16467 placement_manager.go:147]  "msg"="Adding toleration to pod"  "podName"="tf2-keras-cifar10-vgg16-elastic-20210723-044128-worker-0" "scheduler"="default" "toleration"={"key":"celeste/hostname","operator":"Equal","value":"gpu5","effect":"NoExecute"}
I0723 04:54:42.336735   16467 placement_manager.go:147]  "msg"="Adding toleration to pod"  "podName"="tf2-keras-transformer-elastic-20210723-044102-worker-0" "scheduler"="default" "toleration"={"key":"celeste/hostname","operator":"Equal","value":"gpu4","effect":"NoExecute"}
I0723 04:54:43.149831   16467 placement_manager.go:147]  "msg"="Adding toleration to pod"  "podName"="tf2-keras-transformer-elastic-20210723-044102-launcher" "scheduler"="default" "toleration"={"key":"celeste/hostname","operator":"Exists","effect":"NoExecute"}
I0723 04:54:45.736260   16467 placement_manager.go:147]  "msg"="Adding toleration to pod"  "podName"="tf2-keras-cifar10-inceptionv3-elastic-20210723-044405-launcher" "scheduler"="default" "toleration"={"key":"celeste/hostname","operator":"Exists","effect":"NoExecute"}
I0723 04:54:50.423896   16467 placement_manager.go:147]  "msg"="Adding toleration to pod"  "podName"="tf2-keras-cifar10-inceptionv3-elastic-20210723-044044-launcher" "scheduler"="default" "toleration"={"key":"celeste/hostname","operator":"Exists","effect":"NoExecute"}
I0723 04:54:51.625983   16467 placement_manager.go:147]  "msg"="Adding toleration to pod"  "podName"="tf2-keras-cifar10-inceptionv3-elastic-20210723-044044-worker-0" "scheduler"="default" "toleration"={"key":"celeste/hostname","operator":"Equal","value":"gpu4","effect":"NoExecute"}
I0723 04:54:52.623073   16467 placement_manager.go:147]  "msg"="Adding toleration to pod"  "podName"="tf2-keras-cifar10-resnet50-elastic-20210723-043618-launcher" "scheduler"="default" "toleration"={"key":"celeste/hostname","operator":"Exists","effect":"NoExecute"}
I0723 04:59:51.583196   16467 scheduler.go:474]  "msg"="Training job completed"  "elaspedTotalSeconds"=1410.71098812 "gpuTotalSeconds"=1676.381808322 "job"="tf2-keras-cifar10-resnet50-elastic-20210723-043618" "ranTotalSeconds"=1410.71098812 "scheduler"="default" "waitedTotalSeconds"=0
I0723 04:59:51.583403   16467 scheduler.go:135]  "msg"="Received resched event, may be blocked because of rate limit"  "blockedUntil"="2021-07-23T04:56:30.390428416+08:00" "lastResched"="2021-07-23T04:54:30.390428416+08:00" "received"="2021-07-23T04:59:51.583281367+08:00" "scheduler"="default"
I0723 04:59:51.583903   16467 scheduler.go:159]  "msg"="Started resched"  "scheduler"="default"
I0723 04:59:51.584003   16467 scheduler.go:193]  "msg"="Updating all jobs info"  "scheduler"="default"
I0723 04:59:51.596041   16467 elastic_fifo.go:73]  "msg"="Finished scheduling"  "algorithm"="ElasticFIFO" "freeGpu"=0 "result"={"tf2-keras-cifar10-inceptionv3-elastic-20210723-041509":1,"tf2-keras-cifar10-inceptionv3-elastic-20210723-041521":1,"tf2-keras-cifar10-inceptionv3-elastic-20210723-043156":1,"tf2-keras-cifar10-inceptionv3-elastic-20210723-044044":1,"tf2-keras-cifar10-inceptionv3-elastic-20210723-044405":1,"tf2-keras-cifar10-inceptionv3-elastic-20210723-044418":1,"tf2-keras-cifar10-resnet50-elastic-20210723-044403":1,"tf2-keras-cifar10-resnet50-elastic-20210723-044649":0,"tf2-keras-cifar10-vgg16-elastic-20210723-044128":1,"tf2-keras-cifar10-vgg16-elastic-20210723-044319":1,"tf2-keras-transformer-elastic-20210723-042836":1,"tf2-keras-transformer-elastic-20210723-044102":1,"tf2-keras-transformer-elastic-20210723-044415":1} "scheduler"="default"
I0723 04:59:51.596360   16467 scheduler.go:384]  "msg"="Trying to delete multiple training jobs"  "jobs"=[] "scheduler"="default"
I0723 04:59:51.596594   16467 scheduler.go:342]  "msg"="Trying to scale multiple training jobs"  "jobs"=[] "scheduler"="default"
I0723 04:59:51.596774   16467 scheduler.go:292]  "msg"="Trying to start multiple training jobs"  "jobs"=["tf2-keras-cifar10-inceptionv3-elastic-20210723-044418"] "scheduler"="default"
I0723 04:59:51.606306   16467 scheduler.go:342]  "msg"="Trying to scale multiple training jobs"  "jobs"=[] "scheduler"="default"
I0723 04:59:51.609596   16467 placement_manager.go:166]  "msg"="Started job placements adjustment"  "scheduler"="default"
I0723 04:59:51.609733   16467 placement_manager.go:192]  "msg"="Releasing slots"  "jobs"={"tf2-keras-cifar10-inceptionv3-elastic-20210723-041509":{},"tf2-keras-cifar10-inceptionv3-elastic-20210723-041521":{},"tf2-keras-cifar10-inceptionv3-elastic-20210723-043156":{},"tf2-keras-cifar10-inceptionv3-elastic-20210723-044044":{},"tf2-keras-cifar10-inceptionv3-elastic-20210723-044405":{},"tf2-keras-cifar10-resnet50-elastic-20210723-043618":{},"tf2-keras-cifar10-resnet50-elastic-20210723-044403":{},"tf2-keras-cifar10-vgg16-elastic-20210723-044128":{},"tf2-keras-cifar10-vgg16-elastic-20210723-044319":{},"tf2-keras-transformer-elastic-20210723-042836":{},"tf2-keras-transformer-elastic-20210723-044102":{},"tf2-keras-transformer-elastic-20210723-044415":{}} "nodes"={"gpu3":{},"gpu4":{},"gpu5":{}} "scheduler"="default"
I0723 04:59:51.609826   16467 placement_manager.go:250]  "msg"="Released slots"  "jobs"={"tf2-keras-cifar10-inceptionv3-elastic-20210723-041509":{},"tf2-keras-cifar10-inceptionv3-elastic-20210723-041521":{},"tf2-keras-cifar10-inceptionv3-elastic-20210723-043156":{},"tf2-keras-cifar10-inceptionv3-elastic-20210723-044044":{},"tf2-keras-cifar10-inceptionv3-elastic-20210723-044405":{},"tf2-keras-cifar10-resnet50-elastic-20210723-043618":{},"tf2-keras-cifar10-resnet50-elastic-20210723-044403":{},"tf2-keras-cifar10-vgg16-elastic-20210723-044128":{},"tf2-keras-cifar10-vgg16-elastic-20210723-044319":{},"tf2-keras-transformer-elastic-20210723-042836":{},"tf2-keras-transformer-elastic-20210723-044102":{},"tf2-keras-transformer-elastic-20210723-044415":{}} "nodes"={"gpu3":{},"gpu4":{},"gpu5":{}} "scheduler"="default"
I0723 04:59:51.610263   16467 placement_manager.go:305]  "msg"="Found best-fit"  "crossNode"=0 "nodes"=[{},{},{}] "requests"=[{},{},{},{},{},{},{},{},{},{},{},{},{},{},{},{},{},{},{},{},{},{},{},{},{},{}] "scheduler"="default"
I0723 04:59:51.610617   16467 placement_manager.go:339]  "msg"="nodeStates updated"  "new"={"gpu3":{},"gpu4":{},"gpu5":{}} "old"={"gpu3":{},"gpu4":{},"gpu5":{}} "scheduler"="default" "score"=5
I0723 04:59:51.611036   16467 placement_manager.go:387]  "msg"="jobStates updated"  "new"={"tf2-keras-cifar10-inceptionv3-elastic-20210723-041509":{},"tf2-keras-cifar10-inceptionv3-elastic-20210723-041521":{},"tf2-keras-cifar10-inceptionv3-elastic-20210723-043156":{},"tf2-keras-cifar10-inceptionv3-elastic-20210723-044044":{},"tf2-keras-cifar10-inceptionv3-elastic-20210723-044405":{},"tf2-keras-cifar10-inceptionv3-elastic-20210723-044418":{},"tf2-keras-cifar10-resnet50-elastic-20210723-044403":{},"tf2-keras-cifar10-vgg16-elastic-20210723-044128":{},"tf2-keras-cifar10-vgg16-elastic-20210723-044319":{},"tf2-keras-transformer-elastic-20210723-042836":{},"tf2-keras-transformer-elastic-20210723-044102":{},"tf2-keras-transformer-elastic-20210723-044415":{}} "old"={"tf2-keras-cifar10-inceptionv3-elastic-20210723-041509":{},"tf2-keras-cifar10-inceptionv3-elastic-20210723-041521":{},"tf2-keras-cifar10-inceptionv3-elastic-20210723-043156":{},"tf2-keras-cifar10-inceptionv3-elastic-20210723-044044":{},"tf2-keras-cifar10-inceptionv3-elastic-20210723-044405":{},"tf2-keras-cifar10-resnet50-elastic-20210723-043618":{},"tf2-keras-cifar10-resnet50-elastic-20210723-044403":{},"tf2-keras-cifar10-vgg16-elastic-20210723-044128":{},"tf2-keras-cifar10-vgg16-elastic-20210723-044319":{},"tf2-keras-transformer-elastic-20210723-042836":{},"tf2-keras-transformer-elastic-20210723-044102":{},"tf2-keras-transformer-elastic-20210723-044415":{}} "scheduler"="default"
I0723 04:59:51.611509   16467 placement_manager.go:434]  "msg"="podNodeName updated"  "launchersToDelete"=6 "new"={"tf2-keras-cifar10-inceptionv3-elastic-20210723-041509-worker-0":"gpu4","tf2-keras-cifar10-inceptionv3-elastic-20210723-041521-worker-0":"gpu4","tf2-keras-cifar10-inceptionv3-elastic-20210723-043156-worker-0":"gpu3","tf2-keras-cifar10-inceptionv3-elastic-20210723-044044-worker-0":"gpu4","tf2-keras-cifar10-inceptionv3-elastic-20210723-044405-worker-0":"gpu5","tf2-keras-cifar10-inceptionv3-elastic-20210723-044418-worker-0":"gpu4","tf2-keras-cifar10-resnet50-elastic-20210723-044403-worker-0":"gpu5","tf2-keras-cifar10-vgg16-elastic-20210723-044128-worker-0":"gpu5","tf2-keras-cifar10-vgg16-elastic-20210723-044319-worker-0":"gpu3","tf2-keras-transformer-elastic-20210723-042836-worker-0":"gpu5","tf2-keras-transformer-elastic-20210723-044102-worker-0":"gpu3","tf2-keras-transformer-elastic-20210723-044415-worker-0":"gpu3"} "old"={"tf2-keras-cifar10-inceptionv3-elastic-20210723-041509-worker-0":"gpu5","tf2-keras-cifar10-inceptionv3-elastic-20210723-041521-worker-0":"gpu4","tf2-keras-cifar10-inceptionv3-elastic-20210723-043156-worker-0":"gpu4","tf2-keras-cifar10-inceptionv3-elastic-20210723-044044-worker-0":"gpu4","tf2-keras-cifar10-inceptionv3-elastic-20210723-044405-worker-0":"gpu3","tf2-keras-cifar10-resnet50-elastic-20210723-043618-worker-0":"gpu3","tf2-keras-cifar10-resnet50-elastic-20210723-044403-worker-0":"gpu3","tf2-keras-cifar10-vgg16-elastic-20210723-044128-worker-0":"gpu5","tf2-keras-cifar10-vgg16-elastic-20210723-044319-worker-0":"gpu5","tf2-keras-transformer-elastic-20210723-042836-worker-0":"gpu5","tf2-keras-transformer-elastic-20210723-044102-worker-0":"gpu4","tf2-keras-transformer-elastic-20210723-044415-worker-0":"gpu3"} "scheduler"="default" "workersToDelete"=6
I0723 04:59:51.611776   16467 placement_manager.go:451]  "msg"="Deleting pod that need migration"  "podName"="tf2-keras-cifar10-inceptionv3-elastic-20210723-041509-worker-0" "scheduler"="default"
I0723 04:59:51.617120   16467 placement_manager.go:451]  "msg"="Deleting pod that need migration"  "podName"="tf2-keras-cifar10-inceptionv3-elastic-20210723-041509-launcher" "scheduler"="default"
I0723 04:59:51.623461   16467 placement_manager.go:451]  "msg"="Deleting pod that need migration"  "podName"="tf2-keras-cifar10-inceptionv3-elastic-20210723-044405-worker-0" "scheduler"="default"
I0723 04:59:51.626555   16467 placement_manager.go:451]  "msg"="Deleting pod that need migration"  "podName"="tf2-keras-cifar10-inceptionv3-elastic-20210723-044405-launcher" "scheduler"="default"
I0723 04:59:51.629710   16467 placement_manager.go:451]  "msg"="Deleting pod that need migration"  "podName"="tf2-keras-cifar10-inceptionv3-elastic-20210723-043156-worker-0" "scheduler"="default"
I0723 04:59:51.641235   16467 placement_manager.go:451]  "msg"="Deleting pod that need migration"  "podName"="tf2-keras-cifar10-inceptionv3-elastic-20210723-043156-launcher" "scheduler"="default"
I0723 04:59:51.651585   16467 placement_manager.go:451]  "msg"="Deleting pod that need migration"  "podName"="tf2-keras-transformer-elastic-20210723-044102-worker-0" "scheduler"="default"
I0723 04:59:51.655802   16467 placement_manager.go:451]  "msg"="Deleting pod that need migration"  "podName"="tf2-keras-transformer-elastic-20210723-044102-launcher" "scheduler"="default"
I0723 04:59:51.660939   16467 placement_manager.go:451]  "msg"="Deleting pod that need migration"  "podName"="tf2-keras-cifar10-vgg16-elastic-20210723-044319-worker-0" "scheduler"="default"
I0723 04:59:51.665989   16467 placement_manager.go:451]  "msg"="Deleting pod that need migration"  "podName"="tf2-keras-cifar10-vgg16-elastic-20210723-044319-launcher" "scheduler"="default"
I0723 04:59:51.671438   16467 placement_manager.go:451]  "msg"="Deleting pod that need migration"  "podName"="tf2-keras-cifar10-resnet50-elastic-20210723-044403-worker-0" "scheduler"="default"
I0723 04:59:51.816017   16467 placement_manager.go:451]  "msg"="Deleting pod that need migration"  "podName"="tf2-keras-cifar10-resnet50-elastic-20210723-044403-launcher" "scheduler"="default"
I0723 04:59:51.979651   16467 placement_manager.go:147]  "msg"="Adding toleration to pod"  "podName"="tf2-keras-cifar10-inceptionv3-elastic-20210723-044418-worker-0" "scheduler"="default" "toleration"={"key":"celeste/hostname","operator":"Equal","value":"gpu4","effect":"NoExecute"}
I0723 04:59:52.017941   16467 placement_manager.go:183]  "msg"="Finished job placements adjustment"  "scheduler"="default"
I0723 04:59:52.018231   16467 scheduler.go:182]  "msg"="Finished resched"  "scheduler"="default"
I0723 04:59:52.420205   16467 placement_manager.go:147]  "msg"="Adding toleration to pod"  "podName"="tf2-keras-cifar10-inceptionv3-elastic-20210723-044418-launcher" "scheduler"="default" "toleration"={"key":"celeste/hostname","operator":"Exists","effect":"NoExecute"}
I0723 04:59:56.934553   16467 jobmaster.go:155]  "msg"="Training job created"  "job"="tf2-keras-cifar10-vgg16-elastic-20210723-045956"
I0723 04:59:56.934665   16467 scheduler.go:135]  "msg"="Received resched event, may be blocked because of rate limit"  "blockedUntil"="2021-07-23T05:01:52.018618058+08:00" "lastResched"="2021-07-23T04:59:52.018618058+08:00" "received"="2021-07-23T04:59:56.933840149+08:00" "scheduler"="default"
I0723 04:59:58.579729   16467 placement_manager.go:147]  "msg"="Adding toleration to pod"  "podName"="tf2-keras-cifar10-vgg16-elastic-20210723-044319-worker-0" "scheduler"="default" "toleration"={"key":"celeste/hostname","operator":"Equal","value":"gpu3","effect":"NoExecute"}
I0723 05:00:00.080190   16467 placement_manager.go:147]  "msg"="Adding toleration to pod"  "podName"="tf2-keras-transformer-elastic-20210723-044102-launcher" "scheduler"="default" "toleration"={"key":"celeste/hostname","operator":"Exists","effect":"NoExecute"}
I0723 05:00:01.535746   16467 placement_manager.go:147]  "msg"="Adding toleration to pod"  "podName"="tf2-keras-cifar10-vgg16-elastic-20210723-044319-launcher" "scheduler"="default" "toleration"={"key":"celeste/hostname","operator":"Exists","effect":"NoExecute"}
I0723 05:00:04.583380   16467 placement_manager.go:147]  "msg"="Adding toleration to pod"  "podName"="tf2-keras-cifar10-inceptionv3-elastic-20210723-041509-launcher" "scheduler"="default" "toleration"={"key":"celeste/hostname","operator":"Exists","effect":"NoExecute"}
I0723 05:00:04.631540   16467 placement_manager.go:147]  "msg"="Adding toleration to pod"  "podName"="tf2-keras-cifar10-resnet50-elastic-20210723-044403-launcher" "scheduler"="default" "toleration"={"key":"celeste/hostname","operator":"Exists","effect":"NoExecute"}
I0723 05:00:04.642229   16467 placement_manager.go:147]  "msg"="Adding toleration to pod"  "podName"="tf2-keras-transformer-elastic-20210723-044102-worker-0" "scheduler"="default" "toleration"={"key":"celeste/hostname","operator":"Equal","value":"gpu3","effect":"NoExecute"}
I0723 05:00:04.660167   16467 placement_manager.go:147]  "msg"="Adding toleration to pod"  "podName"="tf2-keras-cifar10-inceptionv3-elastic-20210723-043156-worker-0" "scheduler"="default" "toleration"={"key":"celeste/hostname","operator":"Equal","value":"gpu3","effect":"NoExecute"}
I0723 05:00:04.669041   16467 placement_manager.go:147]  "msg"="Adding toleration to pod"  "podName"="tf2-keras-cifar10-inceptionv3-elastic-20210723-043156-launcher" "scheduler"="default" "toleration"={"key":"celeste/hostname","operator":"Exists","effect":"NoExecute"}
I0723 05:00:05.326525   16467 placement_manager.go:147]  "msg"="Adding toleration to pod"  "podName"="tf2-keras-cifar10-inceptionv3-elastic-20210723-044405-worker-0" "scheduler"="default" "toleration"={"key":"celeste/hostname","operator":"Equal","value":"gpu5","effect":"NoExecute"}
I0723 05:00:07.935401   16467 placement_manager.go:147]  "msg"="Adding toleration to pod"  "podName"="tf2-keras-cifar10-inceptionv3-elastic-20210723-044405-launcher" "scheduler"="default" "toleration"={"key":"celeste/hostname","operator":"Exists","effect":"NoExecute"}
I0723 05:00:09.524651   16467 placement_manager.go:147]  "msg"="Adding toleration to pod"  "podName"="tf2-keras-cifar10-resnet50-elastic-20210723-044403-worker-0" "scheduler"="default" "toleration"={"key":"celeste/hostname","operator":"Equal","value":"gpu5","effect":"NoExecute"}
I0723 05:00:11.868010   16467 placement_manager.go:147]  "msg"="Adding toleration to pod"  "podName"="tf2-keras-cifar10-inceptionv3-elastic-20210723-041509-worker-0" "scheduler"="default" "toleration"={"key":"celeste/hostname","operator":"Equal","value":"gpu4","effect":"NoExecute"}
I0723 05:01:52.018718   16467 scheduler.go:159]  "msg"="Started resched"  "scheduler"="default"
I0723 05:01:52.018809   16467 scheduler.go:193]  "msg"="Updating all jobs info"  "scheduler"="default"
I0723 05:01:52.030204   16467 elastic_fifo.go:73]  "msg"="Finished scheduling"  "algorithm"="ElasticFIFO" "freeGpu"=0 "result"={"tf2-keras-cifar10-inceptionv3-elastic-20210723-041509":1,"tf2-keras-cifar10-inceptionv3-elastic-20210723-041521":1,"tf2-keras-cifar10-inceptionv3-elastic-20210723-043156":1,"tf2-keras-cifar10-inceptionv3-elastic-20210723-044044":1,"tf2-keras-cifar10-inceptionv3-elastic-20210723-044405":1,"tf2-keras-cifar10-inceptionv3-elastic-20210723-044418":1,"tf2-keras-cifar10-resnet50-elastic-20210723-044403":1,"tf2-keras-cifar10-resnet50-elastic-20210723-044649":0,"tf2-keras-cifar10-vgg16-elastic-20210723-044128":1,"tf2-keras-cifar10-vgg16-elastic-20210723-044319":1,"tf2-keras-cifar10-vgg16-elastic-20210723-045956":0,"tf2-keras-transformer-elastic-20210723-042836":1,"tf2-keras-transformer-elastic-20210723-044102":1,"tf2-keras-transformer-elastic-20210723-044415":1} "scheduler"="default"
I0723 05:01:52.030485   16467 scheduler.go:384]  "msg"="Trying to delete multiple training jobs"  "jobs"=[] "scheduler"="default"
I0723 05:01:52.030713   16467 scheduler.go:342]  "msg"="Trying to scale multiple training jobs"  "jobs"=[] "scheduler"="default"
I0723 05:01:52.030890   16467 scheduler.go:292]  "msg"="Trying to start multiple training jobs"  "jobs"=[] "scheduler"="default"
I0723 05:01:52.031092   16467 scheduler.go:342]  "msg"="Trying to scale multiple training jobs"  "jobs"=[] "scheduler"="default"
I0723 05:01:52.031291   16467 scheduler.go:180]  "msg"="Nothing changed, skipped ajust placements"  "scheduler"="default"
I0723 05:01:52.031311   16467 scheduler.go:182]  "msg"="Finished resched"  "scheduler"="default"
I0723 05:06:06.966758   16467 jobmaster.go:155]  "msg"="Training job created"  "job"="tf2-keras-transformer-elastic-20210723-050606"
I0723 05:06:06.966936   16467 scheduler.go:135]  "msg"="Received resched event, may be blocked because of rate limit"  "blockedUntil"="2021-07-23T05:03:52.031497673+08:00" "lastResched"="2021-07-23T05:01:52.031497673+08:00" "received"="2021-07-23T05:06:06.966203063+08:00" "scheduler"="default"
I0723 05:06:06.967673   16467 scheduler.go:159]  "msg"="Started resched"  "scheduler"="default"
I0723 05:06:06.967713   16467 scheduler.go:193]  "msg"="Updating all jobs info"  "scheduler"="default"
I0723 05:06:06.979544   16467 elastic_fifo.go:73]  "msg"="Finished scheduling"  "algorithm"="ElasticFIFO" "freeGpu"=0 "result"={"tf2-keras-cifar10-inceptionv3-elastic-20210723-041509":1,"tf2-keras-cifar10-inceptionv3-elastic-20210723-041521":1,"tf2-keras-cifar10-inceptionv3-elastic-20210723-043156":1,"tf2-keras-cifar10-inceptionv3-elastic-20210723-044044":1,"tf2-keras-cifar10-inceptionv3-elastic-20210723-044405":1,"tf2-keras-cifar10-inceptionv3-elastic-20210723-044418":1,"tf2-keras-cifar10-resnet50-elastic-20210723-044403":1,"tf2-keras-cifar10-resnet50-elastic-20210723-044649":0,"tf2-keras-cifar10-vgg16-elastic-20210723-044128":1,"tf2-keras-cifar10-vgg16-elastic-20210723-044319":1,"tf2-keras-cifar10-vgg16-elastic-20210723-045956":0,"tf2-keras-transformer-elastic-20210723-042836":1,"tf2-keras-transformer-elastic-20210723-044102":1,"tf2-keras-transformer-elastic-20210723-044415":1,"tf2-keras-transformer-elastic-20210723-050606":0} "scheduler"="default"
I0723 05:06:06.980034   16467 scheduler.go:384]  "msg"="Trying to delete multiple training jobs"  "jobs"=[] "scheduler"="default"
I0723 05:06:06.980263   16467 scheduler.go:342]  "msg"="Trying to scale multiple training jobs"  "jobs"=[] "scheduler"="default"
I0723 05:06:06.980447   16467 scheduler.go:292]  "msg"="Trying to start multiple training jobs"  "jobs"=[] "scheduler"="default"
I0723 05:06:06.980628   16467 scheduler.go:342]  "msg"="Trying to scale multiple training jobs"  "jobs"=[] "scheduler"="default"
I0723 05:06:06.980890   16467 scheduler.go:180]  "msg"="Nothing changed, skipped ajust placements"  "scheduler"="default"
I0723 05:06:06.980918   16467 scheduler.go:182]  "msg"="Finished resched"  "scheduler"="default"
I0723 05:06:24.845652   16467 jobmaster.go:155]  "msg"="Training job created"  "job"="tf2-keras-cifar10-vgg16-elastic-20210723-050624"
I0723 05:06:24.845793   16467 scheduler.go:135]  "msg"="Received resched event, may be blocked because of rate limit"  "blockedUntil"="2021-07-23T05:08:06.981151249+08:00" "lastResched"="2021-07-23T05:06:06.981151249+08:00" "received"="2021-07-23T05:06:24.845082066+08:00" "scheduler"="default"
I0723 05:06:39.743535   16467 jobmaster.go:155]  "msg"="Training job created"  "job"="tf2-keras-cifar10-resnet50-elastic-20210723-050639"
I0723 05:06:56.291980   16467 scheduler.go:474]  "msg"="Training job completed"  "elaspedTotalSeconds"=1525.742699401 "gpuTotalSeconds"=1450.052416135 "job"="tf2-keras-cifar10-vgg16-elastic-20210723-044128" "ranTotalSeconds"=1450.052416135 "scheduler"="default" "waitedTotalSeconds"=75.690283266
I0723 05:08:06.981275   16467 scheduler.go:159]  "msg"="Started resched"  "scheduler"="default"
I0723 05:08:06.981353   16467 scheduler.go:193]  "msg"="Updating all jobs info"  "scheduler"="default"
I0723 05:08:06.994949   16467 elastic_fifo.go:73]  "msg"="Finished scheduling"  "algorithm"="ElasticFIFO" "freeGpu"=0 "result"={"tf2-keras-cifar10-inceptionv3-elastic-20210723-041509":1,"tf2-keras-cifar10-inceptionv3-elastic-20210723-041521":1,"tf2-keras-cifar10-inceptionv3-elastic-20210723-043156":1,"tf2-keras-cifar10-inceptionv3-elastic-20210723-044044":1,"tf2-keras-cifar10-inceptionv3-elastic-20210723-044405":1,"tf2-keras-cifar10-inceptionv3-elastic-20210723-044418":1,"tf2-keras-cifar10-resnet50-elastic-20210723-044403":1,"tf2-keras-cifar10-resnet50-elastic-20210723-044649":1,"tf2-keras-cifar10-resnet50-elastic-20210723-050639":0,"tf2-keras-cifar10-vgg16-elastic-20210723-044319":1,"tf2-keras-cifar10-vgg16-elastic-20210723-045956":0,"tf2-keras-cifar10-vgg16-elastic-20210723-050624":0,"tf2-keras-transformer-elastic-20210723-042836":1,"tf2-keras-transformer-elastic-20210723-044102":1,"tf2-keras-transformer-elastic-20210723-044415":1,"tf2-keras-transformer-elastic-20210723-050606":0} "scheduler"="default"
I0723 05:08:06.995260   16467 scheduler.go:384]  "msg"="Trying to delete multiple training jobs"  "jobs"=[] "scheduler"="default"
I0723 05:08:06.995666   16467 scheduler.go:342]  "msg"="Trying to scale multiple training jobs"  "jobs"=[] "scheduler"="default"
I0723 05:08:06.995928   16467 scheduler.go:292]  "msg"="Trying to start multiple training jobs"  "jobs"=["tf2-keras-cifar10-resnet50-elastic-20210723-044649"] "scheduler"="default"
I0723 05:08:07.007501   16467 scheduler.go:342]  "msg"="Trying to scale multiple training jobs"  "jobs"=[] "scheduler"="default"
I0723 05:08:07.011692   16467 placement_manager.go:166]  "msg"="Started job placements adjustment"  "scheduler"="default"
I0723 05:08:07.011778   16467 placement_manager.go:192]  "msg"="Releasing slots"  "jobs"={"tf2-keras-cifar10-inceptionv3-elastic-20210723-041509":{},"tf2-keras-cifar10-inceptionv3-elastic-20210723-041521":{},"tf2-keras-cifar10-inceptionv3-elastic-20210723-043156":{},"tf2-keras-cifar10-inceptionv3-elastic-20210723-044044":{},"tf2-keras-cifar10-inceptionv3-elastic-20210723-044405":{},"tf2-keras-cifar10-inceptionv3-elastic-20210723-044418":{},"tf2-keras-cifar10-resnet50-elastic-20210723-044403":{},"tf2-keras-cifar10-vgg16-elastic-20210723-044128":{},"tf2-keras-cifar10-vgg16-elastic-20210723-044319":{},"tf2-keras-transformer-elastic-20210723-042836":{},"tf2-keras-transformer-elastic-20210723-044102":{},"tf2-keras-transformer-elastic-20210723-044415":{}} "nodes"={"gpu3":{},"gpu4":{},"gpu5":{}} "scheduler"="default"
I0723 05:08:07.011920   16467 placement_manager.go:250]  "msg"="Released slots"  "jobs"={"tf2-keras-cifar10-inceptionv3-elastic-20210723-041509":{},"tf2-keras-cifar10-inceptionv3-elastic-20210723-041521":{},"tf2-keras-cifar10-inceptionv3-elastic-20210723-043156":{},"tf2-keras-cifar10-inceptionv3-elastic-20210723-044044":{},"tf2-keras-cifar10-inceptionv3-elastic-20210723-044405":{},"tf2-keras-cifar10-inceptionv3-elastic-20210723-044418":{},"tf2-keras-cifar10-resnet50-elastic-20210723-044403":{},"tf2-keras-cifar10-vgg16-elastic-20210723-044128":{},"tf2-keras-cifar10-vgg16-elastic-20210723-044319":{},"tf2-keras-transformer-elastic-20210723-042836":{},"tf2-keras-transformer-elastic-20210723-044102":{},"tf2-keras-transformer-elastic-20210723-044415":{}} "nodes"={"gpu3":{},"gpu4":{},"gpu5":{}} "scheduler"="default"
I0723 05:08:07.012403   16467 placement_manager.go:305]  "msg"="Found best-fit"  "crossNode"=0 "nodes"=[{},{},{}] "requests"=[{},{},{},{},{},{},{},{},{},{},{},{},{},{},{},{},{},{},{},{},{},{},{},{},{},{},{},{},{},{},{},{}] "scheduler"="default"
I0723 05:08:07.012787   16467 placement_manager.go:339]  "msg"="nodeStates updated"  "new"={"gpu3":{},"gpu4":{},"gpu5":{}} "old"={"gpu3":{},"gpu4":{},"gpu5":{}} "scheduler"="default" "score"=6
I0723 05:08:07.013087   16467 placement_manager.go:387]  "msg"="jobStates updated"  "new"={"tf2-keras-cifar10-inceptionv3-elastic-20210723-041509":{},"tf2-keras-cifar10-inceptionv3-elastic-20210723-041521":{},"tf2-keras-cifar10-inceptionv3-elastic-20210723-043156":{},"tf2-keras-cifar10-inceptionv3-elastic-20210723-044044":{},"tf2-keras-cifar10-inceptionv3-elastic-20210723-044405":{},"tf2-keras-cifar10-inceptionv3-elastic-20210723-044418":{},"tf2-keras-cifar10-resnet50-elastic-20210723-044403":{},"tf2-keras-cifar10-resnet50-elastic-20210723-044649":{},"tf2-keras-cifar10-vgg16-elastic-20210723-044319":{},"tf2-keras-transformer-elastic-20210723-042836":{},"tf2-keras-transformer-elastic-20210723-044102":{},"tf2-keras-transformer-elastic-20210723-044415":{}} "old"={"tf2-keras-cifar10-inceptionv3-elastic-20210723-041509":{},"tf2-keras-cifar10-inceptionv3-elastic-20210723-041521":{},"tf2-keras-cifar10-inceptionv3-elastic-20210723-043156":{},"tf2-keras-cifar10-inceptionv3-elastic-20210723-044044":{},"tf2-keras-cifar10-inceptionv3-elastic-20210723-044405":{},"tf2-keras-cifar10-inceptionv3-elastic-20210723-044418":{},"tf2-keras-cifar10-resnet50-elastic-20210723-044403":{},"tf2-keras-cifar10-vgg16-elastic-20210723-044128":{},"tf2-keras-cifar10-vgg16-elastic-20210723-044319":{},"tf2-keras-transformer-elastic-20210723-042836":{},"tf2-keras-transformer-elastic-20210723-044102":{},"tf2-keras-transformer-elastic-20210723-044415":{}} "scheduler"="default"
I0723 05:08:07.013481   16467 placement_manager.go:434]  "msg"="podNodeName updated"  "launchersToDelete"=5 "new"={"tf2-keras-cifar10-inceptionv3-elastic-20210723-041509-worker-0":"gpu3","tf2-keras-cifar10-inceptionv3-elastic-20210723-041521-worker-0":"gpu4","tf2-keras-cifar10-inceptionv3-elastic-20210723-043156-worker-0":"gpu5","tf2-keras-cifar10-inceptionv3-elastic-20210723-044044-worker-0":"gpu5","tf2-keras-cifar10-inceptionv3-elastic-20210723-044405-worker-0":"gpu5","tf2-keras-cifar10-inceptionv3-elastic-20210723-044418-worker-0":"gpu4","tf2-keras-cifar10-resnet50-elastic-20210723-044403-worker-0":"gpu5","tf2-keras-cifar10-resnet50-elastic-20210723-044649-worker-0":"gpu3","tf2-keras-cifar10-vgg16-elastic-20210723-044319-worker-0":"gpu3","tf2-keras-transformer-elastic-20210723-042836-worker-0":"gpu4","tf2-keras-transformer-elastic-20210723-044102-worker-0":"gpu4","tf2-keras-transformer-elastic-20210723-044415-worker-0":"gpu3"} "old"={"tf2-keras-cifar10-inceptionv3-elastic-20210723-041509-worker-0":"gpu4","tf2-keras-cifar10-inceptionv3-elastic-20210723-041521-worker-0":"gpu4","tf2-keras-cifar10-inceptionv3-elastic-20210723-043156-worker-0":"gpu3","tf2-keras-cifar10-inceptionv3-elastic-20210723-044044-worker-0":"gpu4","tf2-keras-cifar10-inceptionv3-elastic-20210723-044405-worker-0":"gpu5","tf2-keras-cifar10-inceptionv3-elastic-20210723-044418-worker-0":"gpu4","tf2-keras-cifar10-resnet50-elastic-20210723-044403-worker-0":"gpu5","tf2-keras-cifar10-vgg16-elastic-20210723-044128-worker-0":"gpu5","tf2-keras-cifar10-vgg16-elastic-20210723-044319-worker-0":"gpu3","tf2-keras-transformer-elastic-20210723-042836-worker-0":"gpu5","tf2-keras-transformer-elastic-20210723-044102-worker-0":"gpu3","tf2-keras-transformer-elastic-20210723-044415-worker-0":"gpu3"} "scheduler"="default" "workersToDelete"=5
I0723 05:08:07.013815   16467 placement_manager.go:451]  "msg"="Deleting pod that need migration"  "podName"="tf2-keras-transformer-elastic-20210723-042836-worker-0" "scheduler"="default"
I0723 05:08:07.021779   16467 placement_manager.go:451]  "msg"="Deleting pod that need migration"  "podName"="tf2-keras-transformer-elastic-20210723-042836-launcher" "scheduler"="default"
I0723 05:08:07.028061   16467 placement_manager.go:451]  "msg"="Deleting pod that need migration"  "podName"="tf2-keras-transformer-elastic-20210723-044102-worker-0" "scheduler"="default"
I0723 05:08:07.043318   16467 placement_manager.go:451]  "msg"="Deleting pod that need migration"  "podName"="tf2-keras-transformer-elastic-20210723-044102-launcher" "scheduler"="default"
I0723 05:08:07.049033   16467 placement_manager.go:451]  "msg"="Deleting pod that need migration"  "podName"="tf2-keras-cifar10-inceptionv3-elastic-20210723-044044-worker-0" "scheduler"="default"
I0723 05:08:07.053612   16467 placement_manager.go:451]  "msg"="Deleting pod that need migration"  "podName"="tf2-keras-cifar10-inceptionv3-elastic-20210723-044044-launcher" "scheduler"="default"
I0723 05:08:07.057207   16467 placement_manager.go:451]  "msg"="Deleting pod that need migration"  "podName"="tf2-keras-cifar10-inceptionv3-elastic-20210723-041509-worker-0" "scheduler"="default"
I0723 05:08:07.063632   16467 placement_manager.go:451]  "msg"="Deleting pod that need migration"  "podName"="tf2-keras-cifar10-inceptionv3-elastic-20210723-041509-launcher" "scheduler"="default"
I0723 05:08:07.072751   16467 placement_manager.go:451]  "msg"="Deleting pod that need migration"  "podName"="tf2-keras-cifar10-inceptionv3-elastic-20210723-043156-worker-0" "scheduler"="default"
I0723 05:08:07.078293   16467 placement_manager.go:451]  "msg"="Deleting pod that need migration"  "podName"="tf2-keras-cifar10-inceptionv3-elastic-20210723-043156-launcher" "scheduler"="default"
I0723 05:08:07.090239   16467 placement_manager.go:183]  "msg"="Finished job placements adjustment"  "scheduler"="default"
I0723 05:08:07.090521   16467 scheduler.go:182]  "msg"="Finished resched"  "scheduler"="default"
I0723 05:08:07.213593   16467 placement_manager.go:147]  "msg"="Adding toleration to pod"  "podName"="tf2-keras-cifar10-resnet50-elastic-20210723-044649-worker-0" "scheduler"="default" "toleration"={"key":"celeste/hostname","operator":"Equal","value":"gpu3","effect":"NoExecute"}
I0723 05:08:07.822061   16467 placement_manager.go:147]  "msg"="Adding toleration to pod"  "podName"="tf2-keras-cifar10-resnet50-elastic-20210723-044649-launcher" "scheduler"="default" "toleration"={"key":"celeste/hostname","operator":"Exists","effect":"NoExecute"}
I0723 05:08:08.022735   16467 scheduler.go:474]  "msg"="Training job completed"  "elaspedTotalSeconds"=2367.819198608 "gpuTotalSeconds"=3097.841576523 "job"="tf2-keras-transformer-elastic-20210723-042836" "ranTotalSeconds"=2367.819198608 "scheduler"="default" "waitedTotalSeconds"=0
I0723 05:08:08.022899   16467 scheduler.go:135]  "msg"="Received resched event, may be blocked because of rate limit"  "blockedUntil"="2021-07-23T05:10:07.09077367+08:00" "lastResched"="2021-07-23T05:08:07.09077367+08:00" "received"="2021-07-23T05:08:08.022781702+08:00" "scheduler"="default"
I0723 05:08:14.394134   16467 placement_manager.go:147]  "msg"="Adding toleration to pod"  "podName"="tf2-keras-cifar10-inceptionv3-elastic-20210723-041509-launcher" "scheduler"="default" "toleration"={"key":"celeste/hostname","operator":"Exists","effect":"NoExecute"}
I0723 05:08:14.497255   16467 placement_manager.go:147]  "msg"="Adding toleration to pod"  "podName"="tf2-keras-cifar10-inceptionv3-elastic-20210723-043156-launcher" "scheduler"="default" "toleration"={"key":"celeste/hostname","operator":"Exists","effect":"NoExecute"}
I0723 05:08:19.776021   16467 placement_manager.go:147]  "msg"="Adding toleration to pod"  "podName"="tf2-keras-cifar10-inceptionv3-elastic-20210723-044044-launcher" "scheduler"="default" "toleration"={"key":"celeste/hostname","operator":"Exists","effect":"NoExecute"}
I0723 05:08:23.838253   16467 placement_manager.go:147]  "msg"="Adding toleration to pod"  "podName"="tf2-keras-cifar10-inceptionv3-elastic-20210723-043156-worker-0" "scheduler"="default" "toleration"={"key":"celeste/hostname","operator":"Equal","value":"gpu5","effect":"NoExecute"}
I0723 05:08:23.895711   16467 placement_manager.go:147]  "msg"="Adding toleration to pod"  "podName"="tf2-keras-transformer-elastic-20210723-044102-launcher" "scheduler"="default" "toleration"={"key":"celeste/hostname","operator":"Exists","effect":"NoExecute"}
I0723 05:08:24.428938   16467 placement_manager.go:147]  "msg"="Adding toleration to pod"  "podName"="tf2-keras-transformer-elastic-20210723-044102-worker-0" "scheduler"="default" "toleration"={"key":"celeste/hostname","operator":"Equal","value":"gpu4","effect":"NoExecute"}
I0723 05:08:25.249412   16467 placement_manager.go:147]  "msg"="Adding toleration to pod"  "podName"="tf2-keras-cifar10-inceptionv3-elastic-20210723-044044-worker-0" "scheduler"="default" "toleration"={"key":"celeste/hostname","operator":"Equal","value":"gpu5","effect":"NoExecute"}
I0723 05:08:26.061022   16467 placement_manager.go:147]  "msg"="Adding toleration to pod"  "podName"="tf2-keras-cifar10-inceptionv3-elastic-20210723-041509-worker-0" "scheduler"="default" "toleration"={"key":"celeste/hostname","operator":"Equal","value":"gpu3","effect":"NoExecute"}
I0723 05:08:42.786937   16467 jobmaster.go:155]  "msg"="Training job created"  "job"="tf2-keras-cifar10-resnet50-elastic-20210723-050842"
I0723 05:09:07.672411   16467 jobmaster.go:155]  "msg"="Training job created"  "job"="tf2-keras-transformer-elastic-20210723-050907"
I0723 05:09:13.086648   16467 scheduler.go:474]  "msg"="Training job completed"  "elaspedTotalSeconds"=1549.784553261 "gpuTotalSeconds"=1465.052540812 "job"="tf2-keras-cifar10-vgg16-elastic-20210723-044319" "ranTotalSeconds"=1465.052540812 "scheduler"="default" "waitedTotalSeconds"=84.732012449
I0723 05:10:07.090904   16467 scheduler.go:159]  "msg"="Started resched"  "scheduler"="default"
I0723 05:10:07.091043   16467 scheduler.go:193]  "msg"="Updating all jobs info"  "scheduler"="default"
I0723 05:10:07.104418   16467 elastic_fifo.go:73]  "msg"="Finished scheduling"  "algorithm"="ElasticFIFO" "freeGpu"=0 "result"={"tf2-keras-cifar10-inceptionv3-elastic-20210723-041509":1,"tf2-keras-cifar10-inceptionv3-elastic-20210723-041521":1,"tf2-keras-cifar10-inceptionv3-elastic-20210723-043156":1,"tf2-keras-cifar10-inceptionv3-elastic-20210723-044044":1,"tf2-keras-cifar10-inceptionv3-elastic-20210723-044405":1,"tf2-keras-cifar10-inceptionv3-elastic-20210723-044418":1,"tf2-keras-cifar10-resnet50-elastic-20210723-044403":1,"tf2-keras-cifar10-resnet50-elastic-20210723-044649":1,"tf2-keras-cifar10-resnet50-elastic-20210723-050639":0,"tf2-keras-cifar10-resnet50-elastic-20210723-050842":0,"tf2-keras-cifar10-vgg16-elastic-20210723-045956":1,"tf2-keras-cifar10-vgg16-elastic-20210723-050624":0,"tf2-keras-transformer-elastic-20210723-044102":1,"tf2-keras-transformer-elastic-20210723-044415":1,"tf2-keras-transformer-elastic-20210723-050606":1,"tf2-keras-transformer-elastic-20210723-050907":0} "scheduler"="default"
I0723 05:10:07.104793   16467 scheduler.go:384]  "msg"="Trying to delete multiple training jobs"  "jobs"=[] "scheduler"="default"
I0723 05:10:07.105015   16467 scheduler.go:342]  "msg"="Trying to scale multiple training jobs"  "jobs"=[] "scheduler"="default"
I0723 05:10:07.105178   16467 scheduler.go:292]  "msg"="Trying to start multiple training jobs"  "jobs"=["tf2-keras-transformer-elastic-20210723-050606","tf2-keras-cifar10-vgg16-elastic-20210723-045956"] "scheduler"="default"
I0723 05:10:07.132945   16467 scheduler.go:342]  "msg"="Trying to scale multiple training jobs"  "jobs"=[] "scheduler"="default"
I0723 05:10:07.138940   16467 placement_manager.go:166]  "msg"="Started job placements adjustment"  "scheduler"="default"
I0723 05:10:07.139075   16467 placement_manager.go:192]  "msg"="Releasing slots"  "jobs"={"tf2-keras-cifar10-inceptionv3-elastic-20210723-041509":{},"tf2-keras-cifar10-inceptionv3-elastic-20210723-041521":{},"tf2-keras-cifar10-inceptionv3-elastic-20210723-043156":{},"tf2-keras-cifar10-inceptionv3-elastic-20210723-044044":{},"tf2-keras-cifar10-inceptionv3-elastic-20210723-044405":{},"tf2-keras-cifar10-inceptionv3-elastic-20210723-044418":{},"tf2-keras-cifar10-resnet50-elastic-20210723-044403":{},"tf2-keras-cifar10-resnet50-elastic-20210723-044649":{},"tf2-keras-cifar10-vgg16-elastic-20210723-044319":{},"tf2-keras-transformer-elastic-20210723-042836":{},"tf2-keras-transformer-elastic-20210723-044102":{},"tf2-keras-transformer-elastic-20210723-044415":{}} "nodes"={"gpu3":{},"gpu4":{},"gpu5":{}} "scheduler"="default"
I0723 05:10:07.139170   16467 placement_manager.go:250]  "msg"="Released slots"  "jobs"={"tf2-keras-cifar10-inceptionv3-elastic-20210723-041509":{},"tf2-keras-cifar10-inceptionv3-elastic-20210723-041521":{},"tf2-keras-cifar10-inceptionv3-elastic-20210723-043156":{},"tf2-keras-cifar10-inceptionv3-elastic-20210723-044044":{},"tf2-keras-cifar10-inceptionv3-elastic-20210723-044405":{},"tf2-keras-cifar10-inceptionv3-elastic-20210723-044418":{},"tf2-keras-cifar10-resnet50-elastic-20210723-044403":{},"tf2-keras-cifar10-resnet50-elastic-20210723-044649":{},"tf2-keras-cifar10-vgg16-elastic-20210723-044319":{},"tf2-keras-transformer-elastic-20210723-042836":{},"tf2-keras-transformer-elastic-20210723-044102":{},"tf2-keras-transformer-elastic-20210723-044415":{}} "nodes"={"gpu3":{},"gpu4":{},"gpu5":{}} "scheduler"="default"
I0723 05:10:07.139539   16467 placement_manager.go:305]  "msg"="Found best-fit"  "crossNode"=0 "nodes"=[{},{},{}] "requests"=[{},{},{},{},{},{},{},{},{},{},{},{},{},{},{},{},{},{},{},{},{},{},{},{},{},{},{},{},{},{},{},{}] "scheduler"="default"
I0723 05:10:07.139900   16467 placement_manager.go:339]  "msg"="nodeStates updated"  "new"={"gpu3":{},"gpu4":{},"gpu5":{}} "old"={"gpu3":{},"gpu4":{},"gpu5":{}} "scheduler"="default" "score"=5
I0723 05:10:07.140372   16467 placement_manager.go:387]  "msg"="jobStates updated"  "new"={"tf2-keras-cifar10-inceptionv3-elastic-20210723-041509":{},"tf2-keras-cifar10-inceptionv3-elastic-20210723-041521":{},"tf2-keras-cifar10-inceptionv3-elastic-20210723-043156":{},"tf2-keras-cifar10-inceptionv3-elastic-20210723-044044":{},"tf2-keras-cifar10-inceptionv3-elastic-20210723-044405":{},"tf2-keras-cifar10-inceptionv3-elastic-20210723-044418":{},"tf2-keras-cifar10-resnet50-elastic-20210723-044403":{},"tf2-keras-cifar10-resnet50-elastic-20210723-044649":{},"tf2-keras-cifar10-vgg16-elastic-20210723-045956":{},"tf2-keras-transformer-elastic-20210723-044102":{},"tf2-keras-transformer-elastic-20210723-044415":{},"tf2-keras-transformer-elastic-20210723-050606":{}} "old"={"tf2-keras-cifar10-inceptionv3-elastic-20210723-041509":{},"tf2-keras-cifar10-inceptionv3-elastic-20210723-041521":{},"tf2-keras-cifar10-inceptionv3-elastic-20210723-043156":{},"tf2-keras-cifar10-inceptionv3-elastic-20210723-044044":{},"tf2-keras-cifar10-inceptionv3-elastic-20210723-044405":{},"tf2-keras-cifar10-inceptionv3-elastic-20210723-044418":{},"tf2-keras-cifar10-resnet50-elastic-20210723-044403":{},"tf2-keras-cifar10-resnet50-elastic-20210723-044649":{},"tf2-keras-cifar10-vgg16-elastic-20210723-044319":{},"tf2-keras-transformer-elastic-20210723-042836":{},"tf2-keras-transformer-elastic-20210723-044102":{},"tf2-keras-transformer-elastic-20210723-044415":{}} "scheduler"="default"
I0723 05:10:07.140922   16467 placement_manager.go:434]  "msg"="podNodeName updated"  "launchersToDelete"=5 "new"={"tf2-keras-cifar10-inceptionv3-elastic-20210723-041509-worker-0":"gpu3","tf2-keras-cifar10-inceptionv3-elastic-20210723-041521-worker-0":"gpu3","tf2-keras-cifar10-inceptionv3-elastic-20210723-043156-worker-0":"gpu5","tf2-keras-cifar10-inceptionv3-elastic-20210723-044044-worker-0":"gpu3","tf2-keras-cifar10-inceptionv3-elastic-20210723-044405-worker-0":"gpu4","tf2-keras-cifar10-inceptionv3-elastic-20210723-044418-worker-0":"gpu4","tf2-keras-cifar10-resnet50-elastic-20210723-044403-worker-0":"gpu4","tf2-keras-cifar10-resnet50-elastic-20210723-044649-worker-0":"gpu5","tf2-keras-cifar10-vgg16-elastic-20210723-045956-worker-0":"gpu5","tf2-keras-transformer-elastic-20210723-044102-worker-0":"gpu4","tf2-keras-transformer-elastic-20210723-044415-worker-0":"gpu3","tf2-keras-transformer-elastic-20210723-050606-worker-0":"gpu5"} "old"={"tf2-keras-cifar10-inceptionv3-elastic-20210723-041509-worker-0":"gpu3","tf2-keras-cifar10-inceptionv3-elastic-20210723-041521-worker-0":"gpu4","tf2-keras-cifar10-inceptionv3-elastic-20210723-043156-worker-0":"gpu5","tf2-keras-cifar10-inceptionv3-elastic-20210723-044044-worker-0":"gpu5","tf2-keras-cifar10-inceptionv3-elastic-20210723-044405-worker-0":"gpu5","tf2-keras-cifar10-inceptionv3-elastic-20210723-044418-worker-0":"gpu4","tf2-keras-cifar10-resnet50-elastic-20210723-044403-worker-0":"gpu5","tf2-keras-cifar10-resnet50-elastic-20210723-044649-worker-0":"gpu3","tf2-keras-cifar10-vgg16-elastic-20210723-044319-worker-0":"gpu3","tf2-keras-transformer-elastic-20210723-042836-worker-0":"gpu4","tf2-keras-transformer-elastic-20210723-044102-worker-0":"gpu4","tf2-keras-transformer-elastic-20210723-044415-worker-0":"gpu3"} "scheduler"="default" "workersToDelete"=5
I0723 05:10:07.141276   16467 placement_manager.go:451]  "msg"="Deleting pod that need migration"  "podName"="tf2-keras-cifar10-resnet50-elastic-20210723-044403-worker-0" "scheduler"="default"
I0723 05:10:07.148523   16467 placement_manager.go:451]  "msg"="Deleting pod that need migration"  "podName"="tf2-keras-cifar10-resnet50-elastic-20210723-044403-launcher" "scheduler"="default"
I0723 05:10:07.159514   16467 placement_manager.go:451]  "msg"="Deleting pod that need migration"  "podName"="tf2-keras-cifar10-inceptionv3-elastic-20210723-044405-worker-0" "scheduler"="default"
I0723 05:10:07.164047   16467 placement_manager.go:451]  "msg"="Deleting pod that need migration"  "podName"="tf2-keras-cifar10-inceptionv3-elastic-20210723-044405-launcher" "scheduler"="default"
I0723 05:10:07.168122   16467 placement_manager.go:451]  "msg"="Deleting pod that need migration"  "podName"="tf2-keras-cifar10-inceptionv3-elastic-20210723-041521-worker-0" "scheduler"="default"
I0723 05:10:07.171713   16467 placement_manager.go:451]  "msg"="Deleting pod that need migration"  "podName"="tf2-keras-cifar10-inceptionv3-elastic-20210723-041521-launcher" "scheduler"="default"
I0723 05:10:07.175113   16467 placement_manager.go:451]  "msg"="Deleting pod that need migration"  "podName"="tf2-keras-cifar10-resnet50-elastic-20210723-044649-worker-0" "scheduler"="default"
I0723 05:10:07.178242   16467 placement_manager.go:451]  "msg"="Deleting pod that need migration"  "podName"="tf2-keras-cifar10-resnet50-elastic-20210723-044649-launcher" "scheduler"="default"
I0723 05:10:07.181951   16467 placement_manager.go:451]  "msg"="Deleting pod that need migration"  "podName"="tf2-keras-cifar10-inceptionv3-elastic-20210723-044044-worker-0" "scheduler"="default"
I0723 05:10:07.186379   16467 placement_manager.go:451]  "msg"="Deleting pod that need migration"  "podName"="tf2-keras-cifar10-inceptionv3-elastic-20210723-044044-launcher" "scheduler"="default"
I0723 05:10:07.192864   16467 placement_manager.go:183]  "msg"="Finished job placements adjustment"  "scheduler"="default"
I0723 05:10:07.193057   16467 scheduler.go:182]  "msg"="Finished resched"  "scheduler"="default"
I0723 05:10:07.326386   16467 placement_manager.go:147]  "msg"="Adding toleration to pod"  "podName"="tf2-keras-transformer-elastic-20210723-050606-worker-0" "scheduler"="default" "toleration"={"key":"celeste/hostname","operator":"Equal","value":"gpu5","effect":"NoExecute"}
I0723 05:10:07.547693   16467 placement_manager.go:147]  "msg"="Adding toleration to pod"  "podName"="tf2-keras-cifar10-vgg16-elastic-20210723-045956-worker-0" "scheduler"="default" "toleration"={"key":"celeste/hostname","operator":"Equal","value":"gpu5","effect":"NoExecute"}
I0723 05:10:07.949119   16467 placement_manager.go:147]  "msg"="Adding toleration to pod"  "podName"="tf2-keras-transformer-elastic-20210723-050606-launcher" "scheduler"="default" "toleration"={"key":"celeste/hostname","operator":"Exists","effect":"NoExecute"}
I0723 05:10:08.350765   16467 placement_manager.go:147]  "msg"="Adding toleration to pod"  "podName"="tf2-keras-cifar10-vgg16-elastic-20210723-045956-launcher" "scheduler"="default" "toleration"={"key":"celeste/hostname","operator":"Exists","effect":"NoExecute"}
I0723 05:10:14.348137   16467 placement_manager.go:147]  "msg"="Adding toleration to pod"  "podName"="tf2-keras-cifar10-resnet50-elastic-20210723-044649-worker-0" "scheduler"="default" "toleration"={"key":"celeste/hostname","operator":"Equal","value":"gpu5","effect":"NoExecute"}
I0723 05:10:14.646192   16467 placement_manager.go:147]  "msg"="Adding toleration to pod"  "podName"="tf2-keras-cifar10-resnet50-elastic-20210723-044649-launcher" "scheduler"="default" "toleration"={"key":"celeste/hostname","operator":"Exists","effect":"NoExecute"}
I0723 05:10:16.817443   16467 placement_manager.go:147]  "msg"="Adding toleration to pod"  "podName"="tf2-keras-cifar10-resnet50-elastic-20210723-044403-launcher" "scheduler"="default" "toleration"={"key":"celeste/hostname","operator":"Exists","effect":"NoExecute"}
I0723 05:10:18.425019   16467 placement_manager.go:147]  "msg"="Adding toleration to pod"  "podName"="tf2-keras-cifar10-inceptionv3-elastic-20210723-044405-worker-0" "scheduler"="default" "toleration"={"key":"celeste/hostname","operator":"Equal","value":"gpu4","effect":"NoExecute"}
I0723 05:10:19.212876   16467 placement_manager.go:147]  "msg"="Adding toleration to pod"  "podName"="tf2-keras-cifar10-inceptionv3-elastic-20210723-044044-worker-0" "scheduler"="default" "toleration"={"key":"celeste/hostname","operator":"Equal","value":"gpu3","effect":"NoExecute"}
I0723 05:10:21.612253   16467 placement_manager.go:147]  "msg"="Adding toleration to pod"  "podName"="tf2-keras-cifar10-resnet50-elastic-20210723-044403-worker-0" "scheduler"="default" "toleration"={"key":"celeste/hostname","operator":"Equal","value":"gpu4","effect":"NoExecute"}
I0723 05:10:22.615611   16467 placement_manager.go:147]  "msg"="Adding toleration to pod"  "podName"="tf2-keras-cifar10-inceptionv3-elastic-20210723-044044-launcher" "scheduler"="default" "toleration"={"key":"celeste/hostname","operator":"Exists","effect":"NoExecute"}
I0723 05:10:25.330852   16467 placement_manager.go:147]  "msg"="Adding toleration to pod"  "podName"="tf2-keras-cifar10-inceptionv3-elastic-20210723-041521-launcher" "scheduler"="default" "toleration"={"key":"celeste/hostname","operator":"Exists","effect":"NoExecute"}
I0723 05:10:26.533201   16467 placement_manager.go:147]  "msg"="Adding toleration to pod"  "podName"="tf2-keras-cifar10-inceptionv3-elastic-20210723-041521-worker-0" "scheduler"="default" "toleration"={"key":"celeste/hostname","operator":"Equal","value":"gpu3","effect":"NoExecute"}
I0723 05:10:33.618215   16467 placement_manager.go:147]  "msg"="Adding toleration to pod"  "podName"="tf2-keras-cifar10-inceptionv3-elastic-20210723-044405-launcher" "scheduler"="default" "toleration"={"key":"celeste/hostname","operator":"Exists","effect":"NoExecute"}
I0723 05:11:40.019423   16467 scheduler.go:474]  "msg"="Training job completed"  "elaspedTotalSeconds"=1655.853846181 "gpuTotalSeconds"=1615.057692493 "job"="tf2-keras-cifar10-resnet50-elastic-20210723-044403" "ranTotalSeconds"=1615.057692493 "scheduler"="default" "waitedTotalSeconds"=40.796153688
I0723 05:11:40.019557   16467 scheduler.go:135]  "msg"="Received resched event, may be blocked because of rate limit"  "blockedUntil"="2021-07-23T05:12:07.193198186+08:00" "lastResched"="2021-07-23T05:10:07.193198186+08:00" "received"="2021-07-23T05:11:40.019451045+08:00" "scheduler"="default"
I0723 05:12:07.193268   16467 scheduler.go:159]  "msg"="Started resched"  "scheduler"="default"
I0723 05:12:07.193342   16467 scheduler.go:193]  "msg"="Updating all jobs info"  "scheduler"="default"
I0723 05:12:07.205633   16467 elastic_fifo.go:73]  "msg"="Finished scheduling"  "algorithm"="ElasticFIFO" "freeGpu"=0 "result"={"tf2-keras-cifar10-inceptionv3-elastic-20210723-041509":1,"tf2-keras-cifar10-inceptionv3-elastic-20210723-041521":1,"tf2-keras-cifar10-inceptionv3-elastic-20210723-043156":1,"tf2-keras-cifar10-inceptionv3-elastic-20210723-044044":1,"tf2-keras-cifar10-inceptionv3-elastic-20210723-044405":1,"tf2-keras-cifar10-inceptionv3-elastic-20210723-044418":1,"tf2-keras-cifar10-resnet50-elastic-20210723-044649":1,"tf2-keras-cifar10-resnet50-elastic-20210723-050639":0,"tf2-keras-cifar10-resnet50-elastic-20210723-050842":0,"tf2-keras-cifar10-vgg16-elastic-20210723-045956":1,"tf2-keras-cifar10-vgg16-elastic-20210723-050624":1,"tf2-keras-transformer-elastic-20210723-044102":1,"tf2-keras-transformer-elastic-20210723-044415":1,"tf2-keras-transformer-elastic-20210723-050606":1,"tf2-keras-transformer-elastic-20210723-050907":0} "scheduler"="default"
I0723 05:12:07.206071   16467 scheduler.go:384]  "msg"="Trying to delete multiple training jobs"  "jobs"=[] "scheduler"="default"
I0723 05:12:07.206424   16467 scheduler.go:342]  "msg"="Trying to scale multiple training jobs"  "jobs"=[] "scheduler"="default"
I0723 05:12:07.206624   16467 scheduler.go:292]  "msg"="Trying to start multiple training jobs"  "jobs"=["tf2-keras-cifar10-vgg16-elastic-20210723-050624"] "scheduler"="default"
I0723 05:12:07.219470   16467 scheduler.go:342]  "msg"="Trying to scale multiple training jobs"  "jobs"=[] "scheduler"="default"
I0723 05:12:07.224463   16467 placement_manager.go:166]  "msg"="Started job placements adjustment"  "scheduler"="default"
I0723 05:12:07.224555   16467 placement_manager.go:192]  "msg"="Releasing slots"  "jobs"={"tf2-keras-cifar10-inceptionv3-elastic-20210723-041509":{},"tf2-keras-cifar10-inceptionv3-elastic-20210723-041521":{},"tf2-keras-cifar10-inceptionv3-elastic-20210723-043156":{},"tf2-keras-cifar10-inceptionv3-elastic-20210723-044044":{},"tf2-keras-cifar10-inceptionv3-elastic-20210723-044405":{},"tf2-keras-cifar10-inceptionv3-elastic-20210723-044418":{},"tf2-keras-cifar10-resnet50-elastic-20210723-044403":{},"tf2-keras-cifar10-resnet50-elastic-20210723-044649":{},"tf2-keras-cifar10-vgg16-elastic-20210723-045956":{},"tf2-keras-transformer-elastic-20210723-044102":{},"tf2-keras-transformer-elastic-20210723-044415":{},"tf2-keras-transformer-elastic-20210723-050606":{}} "nodes"={"gpu3":{},"gpu4":{},"gpu5":{}} "scheduler"="default"
I0723 05:12:07.224632   16467 placement_manager.go:250]  "msg"="Released slots"  "jobs"={"tf2-keras-cifar10-inceptionv3-elastic-20210723-041509":{},"tf2-keras-cifar10-inceptionv3-elastic-20210723-041521":{},"tf2-keras-cifar10-inceptionv3-elastic-20210723-043156":{},"tf2-keras-cifar10-inceptionv3-elastic-20210723-044044":{},"tf2-keras-cifar10-inceptionv3-elastic-20210723-044405":{},"tf2-keras-cifar10-inceptionv3-elastic-20210723-044418":{},"tf2-keras-cifar10-resnet50-elastic-20210723-044403":{},"tf2-keras-cifar10-resnet50-elastic-20210723-044649":{},"tf2-keras-cifar10-vgg16-elastic-20210723-045956":{},"tf2-keras-transformer-elastic-20210723-044102":{},"tf2-keras-transformer-elastic-20210723-044415":{},"tf2-keras-transformer-elastic-20210723-050606":{}} "nodes"={"gpu3":{},"gpu4":{},"gpu5":{}} "scheduler"="default"
I0723 05:12:07.225216   16467 placement_manager.go:305]  "msg"="Found best-fit"  "crossNode"=0 "nodes"=[{},{},{}] "requests"=[{},{},{},{},{},{},{},{},{},{},{},{},{},{},{},{},{},{},{},{},{},{},{},{},{},{},{},{},{},{}] "scheduler"="default"
I0723 05:12:07.225508   16467 placement_manager.go:339]  "msg"="nodeStates updated"  "new"={"gpu3":{},"gpu4":{},"gpu5":{}} "old"={"gpu3":{},"gpu4":{},"gpu5":{}} "scheduler"="default" "score"=5
I0723 05:12:07.225799   16467 placement_manager.go:387]  "msg"="jobStates updated"  "new"={"tf2-keras-cifar10-inceptionv3-elastic-20210723-041509":{},"tf2-keras-cifar10-inceptionv3-elastic-20210723-041521":{},"tf2-keras-cifar10-inceptionv3-elastic-20210723-043156":{},"tf2-keras-cifar10-inceptionv3-elastic-20210723-044044":{},"tf2-keras-cifar10-inceptionv3-elastic-20210723-044405":{},"tf2-keras-cifar10-inceptionv3-elastic-20210723-044418":{},"tf2-keras-cifar10-resnet50-elastic-20210723-044649":{},"tf2-keras-cifar10-vgg16-elastic-20210723-045956":{},"tf2-keras-cifar10-vgg16-elastic-20210723-050624":{},"tf2-keras-transformer-elastic-20210723-044102":{},"tf2-keras-transformer-elastic-20210723-044415":{},"tf2-keras-transformer-elastic-20210723-050606":{}} "old"={"tf2-keras-cifar10-inceptionv3-elastic-20210723-041509":{},"tf2-keras-cifar10-inceptionv3-elastic-20210723-041521":{},"tf2-keras-cifar10-inceptionv3-elastic-20210723-043156":{},"tf2-keras-cifar10-inceptionv3-elastic-20210723-044044":{},"tf2-keras-cifar10-inceptionv3-elastic-20210723-044405":{},"tf2-keras-cifar10-inceptionv3-elastic-20210723-044418":{},"tf2-keras-cifar10-resnet50-elastic-20210723-044403":{},"tf2-keras-cifar10-resnet50-elastic-20210723-044649":{},"tf2-keras-cifar10-vgg16-elastic-20210723-045956":{},"tf2-keras-transformer-elastic-20210723-044102":{},"tf2-keras-transformer-elastic-20210723-044415":{},"tf2-keras-transformer-elastic-20210723-050606":{}} "scheduler"="default"
I0723 05:12:07.226180   16467 placement_manager.go:434]  "msg"="podNodeName updated"  "launchersToDelete"=6 "new"={"tf2-keras-cifar10-inceptionv3-elastic-20210723-041509-worker-0":"gpu4","tf2-keras-cifar10-inceptionv3-elastic-20210723-041521-worker-0":"gpu3","tf2-keras-cifar10-inceptionv3-elastic-20210723-043156-worker-0":"gpu3","tf2-keras-cifar10-inceptionv3-elastic-20210723-044044-worker-0":"gpu3","tf2-keras-cifar10-inceptionv3-elastic-20210723-044405-worker-0":"gpu3","tf2-keras-cifar10-inceptionv3-elastic-20210723-044418-worker-0":"gpu5","tf2-keras-cifar10-resnet50-elastic-20210723-044649-worker-0":"gpu5","tf2-keras-cifar10-vgg16-elastic-20210723-045956-worker-0":"gpu4","tf2-keras-cifar10-vgg16-elastic-20210723-050624-worker-0":"gpu4","tf2-keras-transformer-elastic-20210723-044102-worker-0":"gpu4","tf2-keras-transformer-elastic-20210723-044415-worker-0":"gpu5","tf2-keras-transformer-elastic-20210723-050606-worker-0":"gpu5"} "old"={"tf2-keras-cifar10-inceptionv3-elastic-20210723-041509-worker-0":"gpu3","tf2-keras-cifar10-inceptionv3-elastic-20210723-041521-worker-0":"gpu3","tf2-keras-cifar10-inceptionv3-elastic-20210723-043156-worker-0":"gpu5","tf2-keras-cifar10-inceptionv3-elastic-20210723-044044-worker-0":"gpu3","tf2-keras-cifar10-inceptionv3-elastic-20210723-044405-worker-0":"gpu4","tf2-keras-cifar10-inceptionv3-elastic-20210723-044418-worker-0":"gpu4","tf2-keras-cifar10-resnet50-elastic-20210723-044403-worker-0":"gpu4","tf2-keras-cifar10-resnet50-elastic-20210723-044649-worker-0":"gpu5","tf2-keras-cifar10-vgg16-elastic-20210723-045956-worker-0":"gpu5","tf2-keras-transformer-elastic-20210723-044102-worker-0":"gpu4","tf2-keras-transformer-elastic-20210723-044415-worker-0":"gpu3","tf2-keras-transformer-elastic-20210723-050606-worker-0":"gpu5"} "scheduler"="default" "workersToDelete"=6
I0723 05:12:07.226506   16467 placement_manager.go:451]  "msg"="Deleting pod that need migration"  "podName"="tf2-keras-cifar10-inceptionv3-elastic-20210723-043156-worker-0" "scheduler"="default"
I0723 05:12:07.231612   16467 placement_manager.go:451]  "msg"="Deleting pod that need migration"  "podName"="tf2-keras-cifar10-inceptionv3-elastic-20210723-043156-launcher" "scheduler"="default"
I0723 05:12:07.236139   16467 placement_manager.go:451]  "msg"="Deleting pod that need migration"  "podName"="tf2-keras-cifar10-inceptionv3-elastic-20210723-044405-worker-0" "scheduler"="default"
I0723 05:12:07.247467   16467 placement_manager.go:451]  "msg"="Deleting pod that need migration"  "podName"="tf2-keras-cifar10-inceptionv3-elastic-20210723-044405-launcher" "scheduler"="default"
I0723 05:12:07.255794   16467 placement_manager.go:451]  "msg"="Deleting pod that need migration"  "podName"="tf2-keras-transformer-elastic-20210723-044415-worker-0" "scheduler"="default"
I0723 05:12:07.260087   16467 placement_manager.go:451]  "msg"="Deleting pod that need migration"  "podName"="tf2-keras-transformer-elastic-20210723-044415-launcher" "scheduler"="default"
I0723 05:12:07.264449   16467 placement_manager.go:451]  "msg"="Deleting pod that need migration"  "podName"="tf2-keras-cifar10-inceptionv3-elastic-20210723-041509-worker-0" "scheduler"="default"
I0723 05:12:07.267753   16467 placement_manager.go:451]  "msg"="Deleting pod that need migration"  "podName"="tf2-keras-cifar10-inceptionv3-elastic-20210723-041509-launcher" "scheduler"="default"
I0723 05:12:07.271231   16467 placement_manager.go:451]  "msg"="Deleting pod that need migration"  "podName"="tf2-keras-cifar10-inceptionv3-elastic-20210723-044418-worker-0" "scheduler"="default"
I0723 05:12:07.277435   16467 placement_manager.go:451]  "msg"="Deleting pod that need migration"  "podName"="tf2-keras-cifar10-inceptionv3-elastic-20210723-044418-launcher" "scheduler"="default"
I0723 05:12:07.284973   16467 placement_manager.go:451]  "msg"="Deleting pod that need migration"  "podName"="tf2-keras-cifar10-vgg16-elastic-20210723-045956-worker-0" "scheduler"="default"
I0723 05:12:07.429907   16467 placement_manager.go:147]  "msg"="Adding toleration to pod"  "podName"="tf2-keras-cifar10-vgg16-elastic-20210723-050624-worker-0" "scheduler"="default" "toleration"={"key":"celeste/hostname","operator":"Equal","value":"gpu4","effect":"NoExecute"}
I0723 05:12:07.433051   16467 placement_manager.go:451]  "msg"="Deleting pod that need migration"  "podName"="tf2-keras-cifar10-vgg16-elastic-20210723-045956-launcher" "scheduler"="default"
I0723 05:12:07.833852   16467 placement_manager.go:183]  "msg"="Finished job placements adjustment"  "scheduler"="default"
I0723 05:12:07.834098   16467 scheduler.go:182]  "msg"="Finished resched"  "scheduler"="default"
I0723 05:12:08.036587   16467 placement_manager.go:147]  "msg"="Adding toleration to pod"  "podName"="tf2-keras-cifar10-vgg16-elastic-20210723-050624-launcher" "scheduler"="default" "toleration"={"key":"celeste/hostname","operator":"Exists","effect":"NoExecute"}
I0723 05:12:15.729757   16467 placement_manager.go:147]  "msg"="Adding toleration to pod"  "podName"="tf2-keras-cifar10-inceptionv3-elastic-20210723-041509-launcher" "scheduler"="default" "toleration"={"key":"celeste/hostname","operator":"Exists","effect":"NoExecute"}
I0723 05:12:17.464676   16467 placement_manager.go:147]  "msg"="Adding toleration to pod"  "podName"="tf2-keras-cifar10-inceptionv3-elastic-20210723-043156-launcher" "scheduler"="default" "toleration"={"key":"celeste/hostname","operator":"Exists","effect":"NoExecute"}
I0723 05:12:18.060763   16467 placement_manager.go:147]  "msg"="Adding toleration to pod"  "podName"="tf2-keras-cifar10-inceptionv3-elastic-20210723-044418-worker-0" "scheduler"="default" "toleration"={"key":"celeste/hostname","operator":"Equal","value":"gpu5","effect":"NoExecute"}
I0723 05:12:18.457955   16467 placement_manager.go:147]  "msg"="Adding toleration to pod"  "podName"="tf2-keras-cifar10-inceptionv3-elastic-20210723-044405-worker-0" "scheduler"="default" "toleration"={"key":"celeste/hostname","operator":"Equal","value":"gpu3","effect":"NoExecute"}
I0723 05:12:19.264041   16467 placement_manager.go:147]  "msg"="Adding toleration to pod"  "podName"="tf2-keras-cifar10-inceptionv3-elastic-20210723-044405-launcher" "scheduler"="default" "toleration"={"key":"celeste/hostname","operator":"Exists","effect":"NoExecute"}
I0723 05:12:20.394983   16467 placement_manager.go:147]  "msg"="Adding toleration to pod"  "podName"="tf2-keras-cifar10-vgg16-elastic-20210723-045956-worker-0" "scheduler"="default" "toleration"={"key":"celeste/hostname","operator":"Equal","value":"gpu4","effect":"NoExecute"}
I0723 05:12:21.305912   16467 placement_manager.go:147]  "msg"="Adding toleration to pod"  "podName"="tf2-keras-cifar10-inceptionv3-elastic-20210723-044418-launcher" "scheduler"="default" "toleration"={"key":"celeste/hostname","operator":"Exists","effect":"NoExecute"}
I0723 05:12:22.190461   16467 placement_manager.go:147]  "msg"="Adding toleration to pod"  "podName"="tf2-keras-transformer-elastic-20210723-044415-launcher" "scheduler"="default" "toleration"={"key":"celeste/hostname","operator":"Exists","effect":"NoExecute"}
I0723 05:12:23.392909   16467 placement_manager.go:147]  "msg"="Adding toleration to pod"  "podName"="tf2-keras-cifar10-inceptionv3-elastic-20210723-043156-worker-0" "scheduler"="default" "toleration"={"key":"celeste/hostname","operator":"Equal","value":"gpu3","effect":"NoExecute"}
I0723 05:12:24.517233   16467 placement_manager.go:147]  "msg"="Adding toleration to pod"  "podName"="tf2-keras-cifar10-inceptionv3-elastic-20210723-041509-worker-0" "scheduler"="default" "toleration"={"key":"celeste/hostname","operator":"Equal","value":"gpu4","effect":"NoExecute"}
I0723 05:12:24.600601   16467 placement_manager.go:147]  "msg"="Adding toleration to pod"  "podName"="tf2-keras-cifar10-vgg16-elastic-20210723-045956-launcher" "scheduler"="default" "toleration"={"key":"celeste/hostname","operator":"Exists","effect":"NoExecute"}
I0723 05:12:25.318761   16467 placement_manager.go:147]  "msg"="Adding toleration to pod"  "podName"="tf2-keras-transformer-elastic-20210723-044415-worker-0" "scheduler"="default" "toleration"={"key":"celeste/hostname","operator":"Equal","value":"gpu5","effect":"NoExecute"}
I0723 05:16:06.615962   16467 scheduler.go:474]  "msg"="Training job completed"  "elaspedTotalSeconds"=3654.745993995 "gpuTotalSeconds"=6128.702378814 "job"="tf2-keras-cifar10-inceptionv3-elastic-20210723-041509" "ranTotalSeconds"=3654.745993995 "scheduler"="default" "waitedTotalSeconds"=0
I0723 05:16:06.616114   16467 scheduler.go:135]  "msg"="Received resched event, may be blocked because of rate limit"  "blockedUntil"="2021-07-23T05:14:07.834317047+08:00" "lastResched"="2021-07-23T05:12:07.834317047+08:00" "received"="2021-07-23T05:16:06.616006864+08:00" "scheduler"="default"
I0723 05:16:06.617176   16467 scheduler.go:159]  "msg"="Started resched"  "scheduler"="default"
I0723 05:16:06.617362   16467 scheduler.go:193]  "msg"="Updating all jobs info"  "scheduler"="default"
I0723 05:16:06.632183   16467 elastic_fifo.go:73]  "msg"="Finished scheduling"  "algorithm"="ElasticFIFO" "freeGpu"=0 "result"={"tf2-keras-cifar10-inceptionv3-elastic-20210723-041521":1,"tf2-keras-cifar10-inceptionv3-elastic-20210723-043156":1,"tf2-keras-cifar10-inceptionv3-elastic-20210723-044044":1,"tf2-keras-cifar10-inceptionv3-elastic-20210723-044405":1,"tf2-keras-cifar10-inceptionv3-elastic-20210723-044418":1,"tf2-keras-cifar10-resnet50-elastic-20210723-044649":1,"tf2-keras-cifar10-resnet50-elastic-20210723-050639":1,"tf2-keras-cifar10-resnet50-elastic-20210723-050842":0,"tf2-keras-cifar10-vgg16-elastic-20210723-045956":1,"tf2-keras-cifar10-vgg16-elastic-20210723-050624":1,"tf2-keras-transformer-elastic-20210723-044102":1,"tf2-keras-transformer-elastic-20210723-044415":1,"tf2-keras-transformer-elastic-20210723-050606":1,"tf2-keras-transformer-elastic-20210723-050907":0} "scheduler"="default"
I0723 05:16:06.632715   16467 scheduler.go:384]  "msg"="Trying to delete multiple training jobs"  "jobs"=[] "scheduler"="default"
I0723 05:16:06.633000   16467 scheduler.go:342]  "msg"="Trying to scale multiple training jobs"  "jobs"=[] "scheduler"="default"
I0723 05:16:06.633227   16467 scheduler.go:292]  "msg"="Trying to start multiple training jobs"  "jobs"=["tf2-keras-cifar10-resnet50-elastic-20210723-050639"] "scheduler"="default"
I0723 05:16:06.643012   16467 scheduler.go:342]  "msg"="Trying to scale multiple training jobs"  "jobs"=[] "scheduler"="default"
I0723 05:16:06.646622   16467 placement_manager.go:166]  "msg"="Started job placements adjustment"  "scheduler"="default"
I0723 05:16:06.646701   16467 placement_manager.go:192]  "msg"="Releasing slots"  "jobs"={"tf2-keras-cifar10-inceptionv3-elastic-20210723-041509":{},"tf2-keras-cifar10-inceptionv3-elastic-20210723-041521":{},"tf2-keras-cifar10-inceptionv3-elastic-20210723-043156":{},"tf2-keras-cifar10-inceptionv3-elastic-20210723-044044":{},"tf2-keras-cifar10-inceptionv3-elastic-20210723-044405":{},"tf2-keras-cifar10-inceptionv3-elastic-20210723-044418":{},"tf2-keras-cifar10-resnet50-elastic-20210723-044649":{},"tf2-keras-cifar10-vgg16-elastic-20210723-045956":{},"tf2-keras-cifar10-vgg16-elastic-20210723-050624":{},"tf2-keras-transformer-elastic-20210723-044102":{},"tf2-keras-transformer-elastic-20210723-044415":{},"tf2-keras-transformer-elastic-20210723-050606":{}} "nodes"={"gpu3":{},"gpu4":{},"gpu5":{}} "scheduler"="default"
I0723 05:16:06.646765   16467 placement_manager.go:250]  "msg"="Released slots"  "jobs"={"tf2-keras-cifar10-inceptionv3-elastic-20210723-041509":{},"tf2-keras-cifar10-inceptionv3-elastic-20210723-041521":{},"tf2-keras-cifar10-inceptionv3-elastic-20210723-043156":{},"tf2-keras-cifar10-inceptionv3-elastic-20210723-044044":{},"tf2-keras-cifar10-inceptionv3-elastic-20210723-044405":{},"tf2-keras-cifar10-inceptionv3-elastic-20210723-044418":{},"tf2-keras-cifar10-resnet50-elastic-20210723-044649":{},"tf2-keras-cifar10-vgg16-elastic-20210723-045956":{},"tf2-keras-cifar10-vgg16-elastic-20210723-050624":{},"tf2-keras-transformer-elastic-20210723-044102":{},"tf2-keras-transformer-elastic-20210723-044415":{},"tf2-keras-transformer-elastic-20210723-050606":{}} "nodes"={"gpu3":{},"gpu4":{},"gpu5":{}} "scheduler"="default"
I0723 05:16:06.647145   16467 placement_manager.go:305]  "msg"="Found best-fit"  "crossNode"=0 "nodes"=[{},{},{}] "requests"=[{},{},{},{},{},{},{},{},{},{},{},{},{},{},{},{},{},{},{},{},{},{},{},{},{},{},{},{}] "scheduler"="default"
I0723 05:16:06.647494   16467 placement_manager.go:339]  "msg"="nodeStates updated"  "new"={"gpu3":{},"gpu4":{},"gpu5":{}} "old"={"gpu3":{},"gpu4":{},"gpu5":{}} "scheduler"="default" "score"=5
I0723 05:16:06.647813   16467 placement_manager.go:387]  "msg"="jobStates updated"  "new"={"tf2-keras-cifar10-inceptionv3-elastic-20210723-041521":{},"tf2-keras-cifar10-inceptionv3-elastic-20210723-043156":{},"tf2-keras-cifar10-inceptionv3-elastic-20210723-044044":{},"tf2-keras-cifar10-inceptionv3-elastic-20210723-044405":{},"tf2-keras-cifar10-inceptionv3-elastic-20210723-044418":{},"tf2-keras-cifar10-resnet50-elastic-20210723-044649":{},"tf2-keras-cifar10-resnet50-elastic-20210723-050639":{},"tf2-keras-cifar10-vgg16-elastic-20210723-045956":{},"tf2-keras-cifar10-vgg16-elastic-20210723-050624":{},"tf2-keras-transformer-elastic-20210723-044102":{},"tf2-keras-transformer-elastic-20210723-044415":{},"tf2-keras-transformer-elastic-20210723-050606":{}} "old"={"tf2-keras-cifar10-inceptionv3-elastic-20210723-041509":{},"tf2-keras-cifar10-inceptionv3-elastic-20210723-041521":{},"tf2-keras-cifar10-inceptionv3-elastic-20210723-043156":{},"tf2-keras-cifar10-inceptionv3-elastic-20210723-044044":{},"tf2-keras-cifar10-inceptionv3-elastic-20210723-044405":{},"tf2-keras-cifar10-inceptionv3-elastic-20210723-044418":{},"tf2-keras-cifar10-resnet50-elastic-20210723-044649":{},"tf2-keras-cifar10-vgg16-elastic-20210723-045956":{},"tf2-keras-cifar10-vgg16-elastic-20210723-050624":{},"tf2-keras-transformer-elastic-20210723-044102":{},"tf2-keras-transformer-elastic-20210723-044415":{},"tf2-keras-transformer-elastic-20210723-050606":{}} "scheduler"="default"
I0723 05:16:06.648204   16467 placement_manager.go:434]  "msg"="podNodeName updated"  "launchersToDelete"=6 "new"={"tf2-keras-cifar10-inceptionv3-elastic-20210723-041521-worker-0":"gpu4","tf2-keras-cifar10-inceptionv3-elastic-20210723-043156-worker-0":"gpu5","tf2-keras-cifar10-inceptionv3-elastic-20210723-044044-worker-0":"gpu3","tf2-keras-cifar10-inceptionv3-elastic-20210723-044405-worker-0":"gpu3","tf2-keras-cifar10-inceptionv3-elastic-20210723-044418-worker-0":"gpu3","tf2-keras-cifar10-resnet50-elastic-20210723-044649-worker-0":"gpu5","tf2-keras-cifar10-resnet50-elastic-20210723-050639-worker-0":"gpu4","tf2-keras-cifar10-vgg16-elastic-20210723-045956-worker-0":"gpu3","tf2-keras-cifar10-vgg16-elastic-20210723-050624-worker-0":"gpu5","tf2-keras-transformer-elastic-20210723-044102-worker-0":"gpu4","tf2-keras-transformer-elastic-20210723-044415-worker-0":"gpu4","tf2-keras-transformer-elastic-20210723-050606-worker-0":"gpu5"} "old"={"tf2-keras-cifar10-inceptionv3-elastic-20210723-041509-worker-0":"gpu4","tf2-keras-cifar10-inceptionv3-elastic-20210723-041521-worker-0":"gpu3","tf2-keras-cifar10-inceptionv3-elastic-20210723-043156-worker-0":"gpu3","tf2-keras-cifar10-inceptionv3-elastic-20210723-044044-worker-0":"gpu3","tf2-keras-cifar10-inceptionv3-elastic-20210723-044405-worker-0":"gpu3","tf2-keras-cifar10-inceptionv3-elastic-20210723-044418-worker-0":"gpu5","tf2-keras-cifar10-resnet50-elastic-20210723-044649-worker-0":"gpu5","tf2-keras-cifar10-vgg16-elastic-20210723-045956-worker-0":"gpu4","tf2-keras-cifar10-vgg16-elastic-20210723-050624-worker-0":"gpu4","tf2-keras-transformer-elastic-20210723-044102-worker-0":"gpu4","tf2-keras-transformer-elastic-20210723-044415-worker-0":"gpu5","tf2-keras-transformer-elastic-20210723-050606-worker-0":"gpu5"} "scheduler"="default" "workersToDelete"=6
I0723 05:16:06.648516   16467 placement_manager.go:451]  "msg"="Deleting pod that need migration"  "podName"="tf2-keras-cifar10-inceptionv3-elastic-20210723-041521-worker-0" "scheduler"="default"
I0723 05:16:06.653490   16467 placement_manager.go:451]  "msg"="Deleting pod that need migration"  "podName"="tf2-keras-cifar10-inceptionv3-elastic-20210723-041521-launcher" "scheduler"="default"
I0723 05:16:06.658432   16467 placement_manager.go:451]  "msg"="Deleting pod that need migration"  "podName"="tf2-keras-cifar10-vgg16-elastic-20210723-045956-worker-0" "scheduler"="default"
I0723 05:16:06.662305   16467 placement_manager.go:451]  "msg"="Deleting pod that need migration"  "podName"="tf2-keras-cifar10-vgg16-elastic-20210723-045956-launcher" "scheduler"="default"
I0723 05:16:06.666753   16467 placement_manager.go:451]  "msg"="Deleting pod that need migration"  "podName"="tf2-keras-cifar10-vgg16-elastic-20210723-050624-worker-0" "scheduler"="default"
I0723 05:16:06.670589   16467 placement_manager.go:451]  "msg"="Deleting pod that need migration"  "podName"="tf2-keras-cifar10-vgg16-elastic-20210723-050624-launcher" "scheduler"="default"
I0723 05:16:06.674411   16467 placement_manager.go:451]  "msg"="Deleting pod that need migration"  "podName"="tf2-keras-cifar10-inceptionv3-elastic-20210723-043156-worker-0" "scheduler"="default"
I0723 05:16:06.680543   16467 placement_manager.go:451]  "msg"="Deleting pod that need migration"  "podName"="tf2-keras-cifar10-inceptionv3-elastic-20210723-043156-launcher" "scheduler"="default"
I0723 05:16:06.684694   16467 placement_manager.go:451]  "msg"="Deleting pod that need migration"  "podName"="tf2-keras-transformer-elastic-20210723-044415-worker-0" "scheduler"="default"
I0723 05:16:06.687819   16467 placement_manager.go:451]  "msg"="Deleting pod that need migration"  "podName"="tf2-keras-transformer-elastic-20210723-044415-launcher" "scheduler"="default"
I0723 05:16:06.701422   16467 placement_manager.go:451]  "msg"="Deleting pod that need migration"  "podName"="tf2-keras-cifar10-inceptionv3-elastic-20210723-044418-worker-0" "scheduler"="default"
I0723 05:16:06.852872   16467 placement_manager.go:451]  "msg"="Deleting pod that need migration"  "podName"="tf2-keras-cifar10-inceptionv3-elastic-20210723-044418-launcher" "scheduler"="default"
I0723 05:16:07.008974   16467 placement_manager.go:147]  "msg"="Adding toleration to pod"  "podName"="tf2-keras-cifar10-resnet50-elastic-20210723-050639-worker-0" "scheduler"="default" "toleration"={"key":"celeste/hostname","operator":"Equal","value":"gpu4","effect":"NoExecute"}
I0723 05:16:07.056190   16467 placement_manager.go:183]  "msg"="Finished job placements adjustment"  "scheduler"="default"
I0723 05:16:07.056439   16467 scheduler.go:182]  "msg"="Finished resched"  "scheduler"="default"
I0723 05:16:07.454220   16467 placement_manager.go:147]  "msg"="Adding toleration to pod"  "podName"="tf2-keras-cifar10-resnet50-elastic-20210723-050639-launcher" "scheduler"="default" "toleration"={"key":"celeste/hostname","operator":"Exists","effect":"NoExecute"}
I0723 05:16:14.298834   16467 placement_manager.go:147]  "msg"="Adding toleration to pod"  "podName"="tf2-keras-cifar10-inceptionv3-elastic-20210723-041521-worker-0" "scheduler"="default" "toleration"={"key":"celeste/hostname","operator":"Equal","value":"gpu4","effect":"NoExecute"}
I0723 05:16:14.334103   16467 placement_manager.go:147]  "msg"="Adding toleration to pod"  "podName"="tf2-keras-cifar10-inceptionv3-elastic-20210723-043156-worker-0" "scheduler"="default" "toleration"={"key":"celeste/hostname","operator":"Equal","value":"gpu5","effect":"NoExecute"}
I0723 05:16:14.997591   16467 placement_manager.go:147]  "msg"="Adding toleration to pod"  "podName"="tf2-keras-transformer-elastic-20210723-044415-launcher" "scheduler"="default" "toleration"={"key":"celeste/hostname","operator":"Exists","effect":"NoExecute"}
I0723 05:16:15.799881   16467 placement_manager.go:147]  "msg"="Adding toleration to pod"  "podName"="tf2-keras-cifar10-inceptionv3-elastic-20210723-044418-launcher" "scheduler"="default" "toleration"={"key":"celeste/hostname","operator":"Exists","effect":"NoExecute"}
I0723 05:16:17.596664   16467 placement_manager.go:147]  "msg"="Adding toleration to pod"  "podName"="tf2-keras-transformer-elastic-20210723-044415-worker-0" "scheduler"="default" "toleration"={"key":"celeste/hostname","operator":"Equal","value":"gpu4","effect":"NoExecute"}
I0723 05:16:18.386270   16467 placement_manager.go:147]  "msg"="Adding toleration to pod"  "podName"="tf2-keras-cifar10-inceptionv3-elastic-20210723-043156-launcher" "scheduler"="default" "toleration"={"key":"celeste/hostname","operator":"Exists","effect":"NoExecute"}
I0723 05:16:22.984841   16467 placement_manager.go:147]  "msg"="Adding toleration to pod"  "podName"="tf2-keras-cifar10-inceptionv3-elastic-20210723-044418-worker-0" "scheduler"="default" "toleration"={"key":"celeste/hostname","operator":"Equal","value":"gpu3","effect":"NoExecute"}
I0723 05:16:25.298259   16467 placement_manager.go:147]  "msg"="Adding toleration to pod"  "podName"="tf2-keras-cifar10-vgg16-elastic-20210723-045956-worker-0" "scheduler"="default" "toleration"={"key":"celeste/hostname","operator":"Equal","value":"gpu3","effect":"NoExecute"}
I0723 05:16:26.288130   16467 placement_manager.go:147]  "msg"="Adding toleration to pod"  "podName"="tf2-keras-cifar10-vgg16-elastic-20210723-045956-launcher" "scheduler"="default" "toleration"={"key":"celeste/hostname","operator":"Exists","effect":"NoExecute"}
I0723 05:16:27.890756   16467 placement_manager.go:147]  "msg"="Adding toleration to pod"  "podName"="tf2-keras-cifar10-vgg16-elastic-20210723-050624-launcher" "scheduler"="default" "toleration"={"key":"celeste/hostname","operator":"Exists","effect":"NoExecute"}
I0723 05:16:29.088198   16467 placement_manager.go:147]  "msg"="Adding toleration to pod"  "podName"="tf2-keras-cifar10-inceptionv3-elastic-20210723-041521-launcher" "scheduler"="default" "toleration"={"key":"celeste/hostname","operator":"Exists","effect":"NoExecute"}
I0723 05:16:30.086900   16467 placement_manager.go:147]  "msg"="Adding toleration to pod"  "podName"="tf2-keras-cifar10-vgg16-elastic-20210723-050624-worker-0" "scheduler"="default" "toleration"={"key":"celeste/hostname","operator":"Equal","value":"gpu5","effect":"NoExecute"}
I0723 05:22:54.820630   16467 scheduler.go:474]  "msg"="Training job completed"  "elaspedTotalSeconds"=4052.856863915 "gpuTotalSeconds"=5820.18530082 "job"="tf2-keras-cifar10-inceptionv3-elastic-20210723-041521" "ranTotalSeconds"=3945.129929797 "scheduler"="default" "waitedTotalSeconds"=107.726934118
I0723 05:22:54.821224   16467 scheduler.go:135]  "msg"="Received resched event, may be blocked because of rate limit"  "blockedUntil"="2021-07-23T05:18:07.056748241+08:00" "lastResched"="2021-07-23T05:16:07.056748241+08:00" "received"="2021-07-23T05:22:54.821125757+08:00" "scheduler"="default"
I0723 05:22:54.821961   16467 scheduler.go:159]  "msg"="Started resched"  "scheduler"="default"
I0723 05:22:54.822040   16467 scheduler.go:193]  "msg"="Updating all jobs info"  "scheduler"="default"
I0723 05:22:54.833999   16467 elastic_fifo.go:73]  "msg"="Finished scheduling"  "algorithm"="ElasticFIFO" "freeGpu"=0 "result"={"tf2-keras-cifar10-inceptionv3-elastic-20210723-043156":1,"tf2-keras-cifar10-inceptionv3-elastic-20210723-044044":1,"tf2-keras-cifar10-inceptionv3-elastic-20210723-044405":1,"tf2-keras-cifar10-inceptionv3-elastic-20210723-044418":1,"tf2-keras-cifar10-resnet50-elastic-20210723-044649":1,"tf2-keras-cifar10-resnet50-elastic-20210723-050639":1,"tf2-keras-cifar10-resnet50-elastic-20210723-050842":1,"tf2-keras-cifar10-vgg16-elastic-20210723-045956":1,"tf2-keras-cifar10-vgg16-elastic-20210723-050624":1,"tf2-keras-transformer-elastic-20210723-044102":1,"tf2-keras-transformer-elastic-20210723-044415":1,"tf2-keras-transformer-elastic-20210723-050606":1,"tf2-keras-transformer-elastic-20210723-050907":0} "scheduler"="default"
I0723 05:22:54.834471   16467 scheduler.go:384]  "msg"="Trying to delete multiple training jobs"  "jobs"=[] "scheduler"="default"
I0723 05:22:54.834805   16467 scheduler.go:342]  "msg"="Trying to scale multiple training jobs"  "jobs"=[] "scheduler"="default"
I0723 05:22:54.835060   16467 scheduler.go:292]  "msg"="Trying to start multiple training jobs"  "jobs"=["tf2-keras-cifar10-resnet50-elastic-20210723-050842"] "scheduler"="default"
I0723 05:22:54.844141   16467 scheduler.go:342]  "msg"="Trying to scale multiple training jobs"  "jobs"=[] "scheduler"="default"
I0723 05:22:54.849002   16467 placement_manager.go:166]  "msg"="Started job placements adjustment"  "scheduler"="default"
I0723 05:22:54.849093   16467 placement_manager.go:192]  "msg"="Releasing slots"  "jobs"={"tf2-keras-cifar10-inceptionv3-elastic-20210723-041521":{},"tf2-keras-cifar10-inceptionv3-elastic-20210723-043156":{},"tf2-keras-cifar10-inceptionv3-elastic-20210723-044044":{},"tf2-keras-cifar10-inceptionv3-elastic-20210723-044405":{},"tf2-keras-cifar10-inceptionv3-elastic-20210723-044418":{},"tf2-keras-cifar10-resnet50-elastic-20210723-044649":{},"tf2-keras-cifar10-resnet50-elastic-20210723-050639":{},"tf2-keras-cifar10-vgg16-elastic-20210723-045956":{},"tf2-keras-cifar10-vgg16-elastic-20210723-050624":{},"tf2-keras-transformer-elastic-20210723-044102":{},"tf2-keras-transformer-elastic-20210723-044415":{},"tf2-keras-transformer-elastic-20210723-050606":{}} "nodes"={"gpu3":{},"gpu4":{},"gpu5":{}} "scheduler"="default"
I0723 05:22:54.849172   16467 placement_manager.go:250]  "msg"="Released slots"  "jobs"={"tf2-keras-cifar10-inceptionv3-elastic-20210723-041521":{},"tf2-keras-cifar10-inceptionv3-elastic-20210723-043156":{},"tf2-keras-cifar10-inceptionv3-elastic-20210723-044044":{},"tf2-keras-cifar10-inceptionv3-elastic-20210723-044405":{},"tf2-keras-cifar10-inceptionv3-elastic-20210723-044418":{},"tf2-keras-cifar10-resnet50-elastic-20210723-044649":{},"tf2-keras-cifar10-resnet50-elastic-20210723-050639":{},"tf2-keras-cifar10-vgg16-elastic-20210723-045956":{},"tf2-keras-cifar10-vgg16-elastic-20210723-050624":{},"tf2-keras-transformer-elastic-20210723-044102":{},"tf2-keras-transformer-elastic-20210723-044415":{},"tf2-keras-transformer-elastic-20210723-050606":{}} "nodes"={"gpu3":{},"gpu4":{},"gpu5":{}} "scheduler"="default"
I0723 05:22:54.849546   16467 placement_manager.go:305]  "msg"="Found best-fit"  "crossNode"=0 "nodes"=[{},{},{}] "requests"=[{},{},{},{},{},{},{},{},{},{},{},{},{},{},{},{},{},{},{},{},{},{},{},{},{},{}] "scheduler"="default"
I0723 05:22:54.849926   16467 placement_manager.go:339]  "msg"="nodeStates updated"  "new"={"gpu3":{},"gpu4":{},"gpu5":{}} "old"={"gpu3":{},"gpu4":{},"gpu5":{}} "scheduler"="default" "score"=6
I0723 05:22:54.850254   16467 placement_manager.go:387]  "msg"="jobStates updated"  "new"={"tf2-keras-cifar10-inceptionv3-elastic-20210723-043156":{},"tf2-keras-cifar10-inceptionv3-elastic-20210723-044044":{},"tf2-keras-cifar10-inceptionv3-elastic-20210723-044405":{},"tf2-keras-cifar10-inceptionv3-elastic-20210723-044418":{},"tf2-keras-cifar10-resnet50-elastic-20210723-044649":{},"tf2-keras-cifar10-resnet50-elastic-20210723-050639":{},"tf2-keras-cifar10-resnet50-elastic-20210723-050842":{},"tf2-keras-cifar10-vgg16-elastic-20210723-045956":{},"tf2-keras-cifar10-vgg16-elastic-20210723-050624":{},"tf2-keras-transformer-elastic-20210723-044102":{},"tf2-keras-transformer-elastic-20210723-044415":{},"tf2-keras-transformer-elastic-20210723-050606":{}} "old"={"tf2-keras-cifar10-inceptionv3-elastic-20210723-041521":{},"tf2-keras-cifar10-inceptionv3-elastic-20210723-043156":{},"tf2-keras-cifar10-inceptionv3-elastic-20210723-044044":{},"tf2-keras-cifar10-inceptionv3-elastic-20210723-044405":{},"tf2-keras-cifar10-inceptionv3-elastic-20210723-044418":{},"tf2-keras-cifar10-resnet50-elastic-20210723-044649":{},"tf2-keras-cifar10-resnet50-elastic-20210723-050639":{},"tf2-keras-cifar10-vgg16-elastic-20210723-045956":{},"tf2-keras-cifar10-vgg16-elastic-20210723-050624":{},"tf2-keras-transformer-elastic-20210723-044102":{},"tf2-keras-transformer-elastic-20210723-044415":{},"tf2-keras-transformer-elastic-20210723-050606":{}} "scheduler"="default"
I0723 05:22:54.850657   16467 placement_manager.go:434]  "msg"="podNodeName updated"  "launchersToDelete"=5 "new"={"tf2-keras-cifar10-inceptionv3-elastic-20210723-043156-worker-0":"gpu5","tf2-keras-cifar10-inceptionv3-elastic-20210723-044044-worker-0":"gpu5","tf2-keras-cifar10-inceptionv3-elastic-20210723-044405-worker-0":"gpu3","tf2-keras-cifar10-inceptionv3-elastic-20210723-044418-worker-0":"gpu3","tf2-keras-cifar10-resnet50-elastic-20210723-044649-worker-0":"gpu4","tf2-keras-cifar10-resnet50-elastic-20210723-050639-worker-0":"gpu4","tf2-keras-cifar10-resnet50-elastic-20210723-050842-worker-0":"gpu3","tf2-keras-cifar10-vgg16-elastic-20210723-045956-worker-0":"gpu5","tf2-keras-cifar10-vgg16-elastic-20210723-050624-worker-0":"gpu5","tf2-keras-transformer-elastic-20210723-044102-worker-0":"gpu3","tf2-keras-transformer-elastic-20210723-044415-worker-0":"gpu4","tf2-keras-transformer-elastic-20210723-050606-worker-0":"gpu4"} "old"={"tf2-keras-cifar10-inceptionv3-elastic-20210723-041521-worker-0":"gpu4","tf2-keras-cifar10-inceptionv3-elastic-20210723-043156-worker-0":"gpu5","tf2-keras-cifar10-inceptionv3-elastic-20210723-044044-worker-0":"gpu3","tf2-keras-cifar10-inceptionv3-elastic-20210723-044405-worker-0":"gpu3","tf2-keras-cifar10-inceptionv3-elastic-20210723-044418-worker-0":"gpu3","tf2-keras-cifar10-resnet50-elastic-20210723-044649-worker-0":"gpu5","tf2-keras-cifar10-resnet50-elastic-20210723-050639-worker-0":"gpu4","tf2-keras-cifar10-vgg16-elastic-20210723-045956-worker-0":"gpu3","tf2-keras-cifar10-vgg16-elastic-20210723-050624-worker-0":"gpu5","tf2-keras-transformer-elastic-20210723-044102-worker-0":"gpu4","tf2-keras-transformer-elastic-20210723-044415-worker-0":"gpu4","tf2-keras-transformer-elastic-20210723-050606-worker-0":"gpu5"} "scheduler"="default" "workersToDelete"=5
I0723 05:22:54.851028   16467 placement_manager.go:451]  "msg"="Deleting pod that need migration"  "podName"="tf2-keras-cifar10-resnet50-elastic-20210723-044649-worker-0" "scheduler"="default"
I0723 05:22:54.854834   16467 placement_manager.go:451]  "msg"="Deleting pod that need migration"  "podName"="tf2-keras-cifar10-resnet50-elastic-20210723-044649-launcher" "scheduler"="default"
I0723 05:22:54.859491   16467 placement_manager.go:451]  "msg"="Deleting pod that need migration"  "podName"="tf2-keras-cifar10-inceptionv3-elastic-20210723-044044-worker-0" "scheduler"="default"
I0723 05:22:54.864776   16467 placement_manager.go:451]  "msg"="Deleting pod that need migration"  "podName"="tf2-keras-cifar10-inceptionv3-elastic-20210723-044044-launcher" "scheduler"="default"
I0723 05:22:54.869081   16467 placement_manager.go:451]  "msg"="Deleting pod that need migration"  "podName"="tf2-keras-transformer-elastic-20210723-044102-worker-0" "scheduler"="default"
I0723 05:22:54.876305   16467 placement_manager.go:451]  "msg"="Deleting pod that need migration"  "podName"="tf2-keras-transformer-elastic-20210723-044102-launcher" "scheduler"="default"
I0723 05:22:54.879578   16467 placement_manager.go:451]  "msg"="Deleting pod that need migration"  "podName"="tf2-keras-transformer-elastic-20210723-050606-worker-0" "scheduler"="default"
I0723 05:22:54.886202   16467 placement_manager.go:451]  "msg"="Deleting pod that need migration"  "podName"="tf2-keras-transformer-elastic-20210723-050606-launcher" "scheduler"="default"
I0723 05:22:54.894756   16467 placement_manager.go:451]  "msg"="Deleting pod that need migration"  "podName"="tf2-keras-cifar10-vgg16-elastic-20210723-045956-worker-0" "scheduler"="default"
I0723 05:22:54.898625   16467 placement_manager.go:451]  "msg"="Deleting pod that need migration"  "podName"="tf2-keras-cifar10-vgg16-elastic-20210723-045956-launcher" "scheduler"="default"
I0723 05:22:54.904554   16467 placement_manager.go:183]  "msg"="Finished job placements adjustment"  "scheduler"="default"
I0723 05:22:54.904799   16467 scheduler.go:182]  "msg"="Finished resched"  "scheduler"="default"
I0723 05:22:55.416073   16467 placement_manager.go:147]  "msg"="Adding toleration to pod"  "podName"="tf2-keras-cifar10-resnet50-elastic-20210723-050842-worker-0" "scheduler"="default" "toleration"={"key":"celeste/hostname","operator":"Equal","value":"gpu3","effect":"NoExecute"}
I0723 05:22:55.815090   16467 placement_manager.go:147]  "msg"="Adding toleration to pod"  "podName"="tf2-keras-cifar10-resnet50-elastic-20210723-050842-launcher" "scheduler"="default" "toleration"={"key":"celeste/hostname","operator":"Exists","effect":"NoExecute"}
I0723 05:23:02.300038   16467 placement_manager.go:147]  "msg"="Adding toleration to pod"  "podName"="tf2-keras-cifar10-inceptionv3-elastic-20210723-044044-launcher" "scheduler"="default" "toleration"={"key":"celeste/hostname","operator":"Exists","effect":"NoExecute"}
I0723 05:23:02.338451   16467 placement_manager.go:147]  "msg"="Adding toleration to pod"  "podName"="tf2-keras-cifar10-inceptionv3-elastic-20210723-044044-worker-0" "scheduler"="default" "toleration"={"key":"celeste/hostname","operator":"Equal","value":"gpu5","effect":"NoExecute"}
I0723 05:23:09.763776   16467 placement_manager.go:147]  "msg"="Adding toleration to pod"  "podName"="tf2-keras-transformer-elastic-20210723-050606-launcher" "scheduler"="default" "toleration"={"key":"celeste/hostname","operator":"Exists","effect":"NoExecute"}
I0723 05:23:09.805996   16467 placement_manager.go:147]  "msg"="Adding toleration to pod"  "podName"="tf2-keras-cifar10-resnet50-elastic-20210723-044649-worker-0" "scheduler"="default" "toleration"={"key":"celeste/hostname","operator":"Equal","value":"gpu4","effect":"NoExecute"}
I0723 05:23:09.814619   16467 placement_manager.go:147]  "msg"="Adding toleration to pod"  "podName"="tf2-keras-transformer-elastic-20210723-050606-worker-0" "scheduler"="default" "toleration"={"key":"celeste/hostname","operator":"Equal","value":"gpu4","effect":"NoExecute"}
I0723 05:23:09.823794   16467 placement_manager.go:147]  "msg"="Adding toleration to pod"  "podName"="tf2-keras-cifar10-resnet50-elastic-20210723-044649-launcher" "scheduler"="default" "toleration"={"key":"celeste/hostname","operator":"Exists","effect":"NoExecute"}
I0723 05:23:14.553515   16467 placement_manager.go:147]  "msg"="Adding toleration to pod"  "podName"="tf2-keras-cifar10-vgg16-elastic-20210723-045956-worker-0" "scheduler"="default" "toleration"={"key":"celeste/hostname","operator":"Equal","value":"gpu5","effect":"NoExecute"}
I0723 05:23:14.964171   16467 placement_manager.go:147]  "msg"="Adding toleration to pod"  "podName"="tf2-keras-cifar10-vgg16-elastic-20210723-045956-launcher" "scheduler"="default" "toleration"={"key":"celeste/hostname","operator":"Exists","effect":"NoExecute"}
I0723 05:23:16.839405   16467 placement_manager.go:147]  "msg"="Adding toleration to pod"  "podName"="tf2-keras-transformer-elastic-20210723-044102-worker-0" "scheduler"="default" "toleration"={"key":"celeste/hostname","operator":"Equal","value":"gpu3","effect":"NoExecute"}
I0723 05:23:18.839893   16467 placement_manager.go:147]  "msg"="Adding toleration to pod"  "podName"="tf2-keras-transformer-elastic-20210723-044102-launcher" "scheduler"="default" "toleration"={"key":"celeste/hostname","operator":"Exists","effect":"NoExecute"}
I0723 05:28:48.362567   16467 scheduler.go:474]  "msg"="Training job completed"  "elaspedTotalSeconds"=2861.783593527 "gpuTotalSeconds"=2760.098517353 "job"="tf2-keras-transformer-elastic-20210723-044102" "ranTotalSeconds"=2760.098517353 "scheduler"="default" "waitedTotalSeconds"=101.685076174
I0723 05:28:48.362701   16467 scheduler.go:135]  "msg"="Received resched event, may be blocked because of rate limit"  "blockedUntil"="2021-07-23T05:24:54.905008941+08:00" "lastResched"="2021-07-23T05:22:54.905008941+08:00" "received"="2021-07-23T05:28:48.362612344+08:00" "scheduler"="default"
I0723 05:28:48.363383   16467 scheduler.go:159]  "msg"="Started resched"  "scheduler"="default"
I0723 05:28:48.363447   16467 scheduler.go:193]  "msg"="Updating all jobs info"  "scheduler"="default"
I0723 05:28:48.372304   16467 elastic_fifo.go:73]  "msg"="Finished scheduling"  "algorithm"="ElasticFIFO" "freeGpu"=0 "result"={"tf2-keras-cifar10-inceptionv3-elastic-20210723-043156":1,"tf2-keras-cifar10-inceptionv3-elastic-20210723-044044":1,"tf2-keras-cifar10-inceptionv3-elastic-20210723-044405":1,"tf2-keras-cifar10-inceptionv3-elastic-20210723-044418":1,"tf2-keras-cifar10-resnet50-elastic-20210723-044649":1,"tf2-keras-cifar10-resnet50-elastic-20210723-050639":1,"tf2-keras-cifar10-resnet50-elastic-20210723-050842":1,"tf2-keras-cifar10-vgg16-elastic-20210723-045956":1,"tf2-keras-cifar10-vgg16-elastic-20210723-050624":1,"tf2-keras-transformer-elastic-20210723-044415":1,"tf2-keras-transformer-elastic-20210723-050606":1,"tf2-keras-transformer-elastic-20210723-050907":1} "scheduler"="default"
I0723 05:28:48.372703   16467 scheduler.go:384]  "msg"="Trying to delete multiple training jobs"  "jobs"=[] "scheduler"="default"
I0723 05:28:48.372985   16467 scheduler.go:342]  "msg"="Trying to scale multiple training jobs"  "jobs"=[] "scheduler"="default"
I0723 05:28:48.373239   16467 scheduler.go:292]  "msg"="Trying to start multiple training jobs"  "jobs"=["tf2-keras-transformer-elastic-20210723-050907"] "scheduler"="default"
I0723 05:28:48.382312   16467 scheduler.go:342]  "msg"="Trying to scale multiple training jobs"  "jobs"=[] "scheduler"="default"
I0723 05:28:48.386671   16467 placement_manager.go:166]  "msg"="Started job placements adjustment"  "scheduler"="default"
I0723 05:28:48.386746   16467 placement_manager.go:192]  "msg"="Releasing slots"  "jobs"={"tf2-keras-cifar10-inceptionv3-elastic-20210723-043156":{},"tf2-keras-cifar10-inceptionv3-elastic-20210723-044044":{},"tf2-keras-cifar10-inceptionv3-elastic-20210723-044405":{},"tf2-keras-cifar10-inceptionv3-elastic-20210723-044418":{},"tf2-keras-cifar10-resnet50-elastic-20210723-044649":{},"tf2-keras-cifar10-resnet50-elastic-20210723-050639":{},"tf2-keras-cifar10-resnet50-elastic-20210723-050842":{},"tf2-keras-cifar10-vgg16-elastic-20210723-045956":{},"tf2-keras-cifar10-vgg16-elastic-20210723-050624":{},"tf2-keras-transformer-elastic-20210723-044102":{},"tf2-keras-transformer-elastic-20210723-044415":{},"tf2-keras-transformer-elastic-20210723-050606":{}} "nodes"={"gpu3":{},"gpu4":{},"gpu5":{}} "scheduler"="default"
I0723 05:28:48.386822   16467 placement_manager.go:250]  "msg"="Released slots"  "jobs"={"tf2-keras-cifar10-inceptionv3-elastic-20210723-043156":{},"tf2-keras-cifar10-inceptionv3-elastic-20210723-044044":{},"tf2-keras-cifar10-inceptionv3-elastic-20210723-044405":{},"tf2-keras-cifar10-inceptionv3-elastic-20210723-044418":{},"tf2-keras-cifar10-resnet50-elastic-20210723-044649":{},"tf2-keras-cifar10-resnet50-elastic-20210723-050639":{},"tf2-keras-cifar10-resnet50-elastic-20210723-050842":{},"tf2-keras-cifar10-vgg16-elastic-20210723-045956":{},"tf2-keras-cifar10-vgg16-elastic-20210723-050624":{},"tf2-keras-transformer-elastic-20210723-044102":{},"tf2-keras-transformer-elastic-20210723-044415":{},"tf2-keras-transformer-elastic-20210723-050606":{}} "nodes"={"gpu3":{},"gpu4":{},"gpu5":{}} "scheduler"="default"
I0723 05:28:48.387239   16467 placement_manager.go:305]  "msg"="Found best-fit"  "crossNode"=0 "nodes"=[{},{},{}] "requests"=[{},{},{},{},{},{},{},{},{},{},{},{},{},{},{},{},{},{},{},{},{},{},{},{}] "scheduler"="default"
I0723 05:28:48.387476   16467 placement_manager.go:339]  "msg"="nodeStates updated"  "new"={"gpu3":{},"gpu4":{},"gpu5":{}} "old"={"gpu3":{},"gpu4":{},"gpu5":{}} "scheduler"="default" "score"=5
I0723 05:28:48.387799   16467 placement_manager.go:387]  "msg"="jobStates updated"  "new"={"tf2-keras-cifar10-inceptionv3-elastic-20210723-043156":{},"tf2-keras-cifar10-inceptionv3-elastic-20210723-044044":{},"tf2-keras-cifar10-inceptionv3-elastic-20210723-044405":{},"tf2-keras-cifar10-inceptionv3-elastic-20210723-044418":{},"tf2-keras-cifar10-resnet50-elastic-20210723-044649":{},"tf2-keras-cifar10-resnet50-elastic-20210723-050639":{},"tf2-keras-cifar10-resnet50-elastic-20210723-050842":{},"tf2-keras-cifar10-vgg16-elastic-20210723-045956":{},"tf2-keras-cifar10-vgg16-elastic-20210723-050624":{},"tf2-keras-transformer-elastic-20210723-044415":{},"tf2-keras-transformer-elastic-20210723-050606":{},"tf2-keras-transformer-elastic-20210723-050907":{}} "old"={"tf2-keras-cifar10-inceptionv3-elastic-20210723-043156":{},"tf2-keras-cifar10-inceptionv3-elastic-20210723-044044":{},"tf2-keras-cifar10-inceptionv3-elastic-20210723-044405":{},"tf2-keras-cifar10-inceptionv3-elastic-20210723-044418":{},"tf2-keras-cifar10-resnet50-elastic-20210723-044649":{},"tf2-keras-cifar10-resnet50-elastic-20210723-050639":{},"tf2-keras-cifar10-resnet50-elastic-20210723-050842":{},"tf2-keras-cifar10-vgg16-elastic-20210723-045956":{},"tf2-keras-cifar10-vgg16-elastic-20210723-050624":{},"tf2-keras-transformer-elastic-20210723-044102":{},"tf2-keras-transformer-elastic-20210723-044415":{},"tf2-keras-transformer-elastic-20210723-050606":{}} "scheduler"="default"
I0723 05:28:48.388345   16467 placement_manager.go:434]  "msg"="podNodeName updated"  "launchersToDelete"=6 "new"={"tf2-keras-cifar10-inceptionv3-elastic-20210723-043156-worker-0":"gpu4","tf2-keras-cifar10-inceptionv3-elastic-20210723-044044-worker-0":"gpu5","tf2-keras-cifar10-inceptionv3-elastic-20210723-044405-worker-0":"gpu3","tf2-keras-cifar10-inceptionv3-elastic-20210723-044418-worker-0":"gpu5","tf2-keras-cifar10-resnet50-elastic-20210723-044649-worker-0":"gpu4","tf2-keras-cifar10-resnet50-elastic-20210723-050639-worker-0":"gpu4","tf2-keras-cifar10-resnet50-elastic-20210723-050842-worker-0":"gpu4","tf2-keras-cifar10-vgg16-elastic-20210723-045956-worker-0":"gpu3","tf2-keras-cifar10-vgg16-elastic-20210723-050624-worker-0":"gpu5","tf2-keras-transformer-elastic-20210723-044415-worker-0":"gpu5","tf2-keras-transformer-elastic-20210723-050606-worker-0":"gpu3","tf2-keras-transformer-elastic-20210723-050907-worker-0":"gpu3"} "old"={"tf2-keras-cifar10-inceptionv3-elastic-20210723-043156-worker-0":"gpu5","tf2-keras-cifar10-inceptionv3-elastic-20210723-044044-worker-0":"gpu5","tf2-keras-cifar10-inceptionv3-elastic-20210723-044405-worker-0":"gpu3","tf2-keras-cifar10-inceptionv3-elastic-20210723-044418-worker-0":"gpu3","tf2-keras-cifar10-resnet50-elastic-20210723-044649-worker-0":"gpu4","tf2-keras-cifar10-resnet50-elastic-20210723-050639-worker-0":"gpu4","tf2-keras-cifar10-resnet50-elastic-20210723-050842-worker-0":"gpu3","tf2-keras-cifar10-vgg16-elastic-20210723-045956-worker-0":"gpu5","tf2-keras-cifar10-vgg16-elastic-20210723-050624-worker-0":"gpu5","tf2-keras-transformer-elastic-20210723-044102-worker-0":"gpu3","tf2-keras-transformer-elastic-20210723-044415-worker-0":"gpu4","tf2-keras-transformer-elastic-20210723-050606-worker-0":"gpu4"} "scheduler"="default" "workersToDelete"=6
I0723 05:28:48.388660   16467 placement_manager.go:451]  "msg"="Deleting pod that need migration"  "podName"="tf2-keras-cifar10-vgg16-elastic-20210723-045956-worker-0" "scheduler"="default"
I0723 05:28:48.392374   16467 placement_manager.go:451]  "msg"="Deleting pod that need migration"  "podName"="tf2-keras-cifar10-vgg16-elastic-20210723-045956-launcher" "scheduler"="default"
I0723 05:28:48.397491   16467 placement_manager.go:451]  "msg"="Deleting pod that need migration"  "podName"="tf2-keras-transformer-elastic-20210723-050606-worker-0" "scheduler"="default"
I0723 05:28:48.411125   16467 placement_manager.go:451]  "msg"="Deleting pod that need migration"  "podName"="tf2-keras-transformer-elastic-20210723-050606-launcher" "scheduler"="default"
I0723 05:28:48.420943   16467 placement_manager.go:451]  "msg"="Deleting pod that need migration"  "podName"="tf2-keras-transformer-elastic-20210723-044415-worker-0" "scheduler"="default"
I0723 05:28:48.424931   16467 placement_manager.go:451]  "msg"="Deleting pod that need migration"  "podName"="tf2-keras-transformer-elastic-20210723-044415-launcher" "scheduler"="default"
I0723 05:28:48.429131   16467 placement_manager.go:451]  "msg"="Deleting pod that need migration"  "podName"="tf2-keras-cifar10-inceptionv3-elastic-20210723-044418-worker-0" "scheduler"="default"
I0723 05:28:48.433117   16467 placement_manager.go:451]  "msg"="Deleting pod that need migration"  "podName"="tf2-keras-cifar10-inceptionv3-elastic-20210723-044418-launcher" "scheduler"="default"
I0723 05:28:48.436489   16467 placement_manager.go:451]  "msg"="Deleting pod that need migration"  "podName"="tf2-keras-cifar10-inceptionv3-elastic-20210723-043156-worker-0" "scheduler"="default"
I0723 05:28:48.440665   16467 placement_manager.go:451]  "msg"="Deleting pod that need migration"  "podName"="tf2-keras-cifar10-inceptionv3-elastic-20210723-043156-launcher" "scheduler"="default"
I0723 05:28:48.444626   16467 placement_manager.go:451]  "msg"="Deleting pod that need migration"  "podName"="tf2-keras-cifar10-resnet50-elastic-20210723-050842-worker-0" "scheduler"="default"
I0723 05:28:48.593901   16467 placement_manager.go:451]  "msg"="Deleting pod that need migration"  "podName"="tf2-keras-cifar10-resnet50-elastic-20210723-050842-launcher" "scheduler"="default"
I0723 05:28:48.793343   16467 placement_manager.go:183]  "msg"="Finished job placements adjustment"  "scheduler"="default"
I0723 05:28:48.793719   16467 scheduler.go:182]  "msg"="Finished resched"  "scheduler"="default"
I0723 05:28:48.957877   16467 placement_manager.go:147]  "msg"="Adding toleration to pod"  "podName"="tf2-keras-transformer-elastic-20210723-050907-worker-0" "scheduler"="default" "toleration"={"key":"celeste/hostname","operator":"Equal","value":"gpu3","effect":"NoExecute"}
I0723 05:28:49.356930   16467 placement_manager.go:147]  "msg"="Adding toleration to pod"  "podName"="tf2-keras-transformer-elastic-20210723-050907-launcher" "scheduler"="default" "toleration"={"key":"celeste/hostname","operator":"Exists","effect":"NoExecute"}
I0723 05:28:57.833185   16467 placement_manager.go:147]  "msg"="Adding toleration to pod"  "podName"="tf2-keras-cifar10-vgg16-elastic-20210723-045956-launcher" "scheduler"="default" "toleration"={"key":"celeste/hostname","operator":"Exists","effect":"NoExecute"}
I0723 05:28:57.874506   16467 placement_manager.go:147]  "msg"="Adding toleration to pod"  "podName"="tf2-keras-transformer-elastic-20210723-044415-launcher" "scheduler"="default" "toleration"={"key":"celeste/hostname","operator":"Exists","effect":"NoExecute"}
I0723 05:28:59.397150   16467 placement_manager.go:147]  "msg"="Adding toleration to pod"  "podName"="tf2-keras-cifar10-inceptionv3-elastic-20210723-043156-worker-0" "scheduler"="default" "toleration"={"key":"celeste/hostname","operator":"Equal","value":"gpu4","effect":"NoExecute"}
I0723 05:29:00.193898   16467 placement_manager.go:147]  "msg"="Adding toleration to pod"  "podName"="tf2-keras-cifar10-vgg16-elastic-20210723-045956-worker-0" "scheduler"="default" "toleration"={"key":"celeste/hostname","operator":"Equal","value":"gpu3","effect":"NoExecute"}
I0723 05:29:02.207711   16467 placement_manager.go:147]  "msg"="Adding toleration to pod"  "podName"="tf2-keras-cifar10-inceptionv3-elastic-20210723-044418-launcher" "scheduler"="default" "toleration"={"key":"celeste/hostname","operator":"Exists","effect":"NoExecute"}
I0723 05:29:03.198207   16467 placement_manager.go:147]  "msg"="Adding toleration to pod"  "podName"="tf2-keras-cifar10-inceptionv3-elastic-20210723-043156-launcher" "scheduler"="default" "toleration"={"key":"celeste/hostname","operator":"Exists","effect":"NoExecute"}
I0723 05:29:03.899442   16467 placement_manager.go:147]  "msg"="Adding toleration to pod"  "podName"="tf2-keras-cifar10-inceptionv3-elastic-20210723-044418-worker-0" "scheduler"="default" "toleration"={"key":"celeste/hostname","operator":"Equal","value":"gpu5","effect":"NoExecute"}
I0723 05:29:04.512608   16467 placement_manager.go:147]  "msg"="Adding toleration to pod"  "podName"="tf2-keras-cifar10-resnet50-elastic-20210723-050842-worker-0" "scheduler"="default" "toleration"={"key":"celeste/hostname","operator":"Equal","value":"gpu4","effect":"NoExecute"}
I0723 05:29:04.665861   16467 placement_manager.go:147]  "msg"="Adding toleration to pod"  "podName"="tf2-keras-cifar10-resnet50-elastic-20210723-050842-launcher" "scheduler"="default" "toleration"={"key":"celeste/hostname","operator":"Exists","effect":"NoExecute"}
I0723 05:29:05.668867   16467 placement_manager.go:147]  "msg"="Adding toleration to pod"  "podName"="tf2-keras-transformer-elastic-20210723-050606-launcher" "scheduler"="default" "toleration"={"key":"celeste/hostname","operator":"Exists","effect":"NoExecute"}
I0723 05:29:06.463886   16467 placement_manager.go:147]  "msg"="Adding toleration to pod"  "podName"="tf2-keras-transformer-elastic-20210723-044415-worker-0" "scheduler"="default" "toleration"={"key":"celeste/hostname","operator":"Equal","value":"gpu5","effect":"NoExecute"}
I0723 05:29:07.264243   16467 placement_manager.go:147]  "msg"="Adding toleration to pod"  "podName"="tf2-keras-transformer-elastic-20210723-050606-worker-0" "scheduler"="default" "toleration"={"key":"celeste/hostname","operator":"Equal","value":"gpu3","effect":"NoExecute"}
I0723 05:34:36.796743   16467 scheduler.go:474]  "msg"="Training job completed"  "elaspedTotalSeconds"=2864.12001384 "gpuTotalSeconds"=1590.056404061 "job"="tf2-keras-cifar10-resnet50-elastic-20210723-044649" "ranTotalSeconds"=1590.056404061 "scheduler"="default" "waitedTotalSeconds"=1274.063609779
I0723 05:34:36.796889   16467 scheduler.go:135]  "msg"="Received resched event, may be blocked because of rate limit"  "blockedUntil"="2021-07-23T05:30:48.793991967+08:00" "lastResched"="2021-07-23T05:28:48.793991967+08:00" "received"="2021-07-23T05:34:36.796777736+08:00" "scheduler"="default"
I0723 05:34:36.797492   16467 scheduler.go:159]  "msg"="Started resched"  "scheduler"="default"
I0723 05:34:36.797558   16467 scheduler.go:193]  "msg"="Updating all jobs info"  "scheduler"="default"
I0723 05:34:36.809498   16467 elastic_fifo.go:73]  "msg"="Finished scheduling"  "algorithm"="ElasticFIFO" "freeGpu"=0 "result"={"tf2-keras-cifar10-inceptionv3-elastic-20210723-043156":2,"tf2-keras-cifar10-inceptionv3-elastic-20210723-044044":1,"tf2-keras-cifar10-inceptionv3-elastic-20210723-044405":1,"tf2-keras-cifar10-inceptionv3-elastic-20210723-044418":1,"tf2-keras-cifar10-resnet50-elastic-20210723-050639":1,"tf2-keras-cifar10-resnet50-elastic-20210723-050842":1,"tf2-keras-cifar10-vgg16-elastic-20210723-045956":1,"tf2-keras-cifar10-vgg16-elastic-20210723-050624":1,"tf2-keras-transformer-elastic-20210723-044415":1,"tf2-keras-transformer-elastic-20210723-050606":1,"tf2-keras-transformer-elastic-20210723-050907":1} "scheduler"="default"
I0723 05:34:36.809768   16467 scheduler.go:384]  "msg"="Trying to delete multiple training jobs"  "jobs"=[] "scheduler"="default"
I0723 05:34:36.809994   16467 scheduler.go:342]  "msg"="Trying to scale multiple training jobs"  "jobs"=[] "scheduler"="default"
I0723 05:34:36.810257   16467 scheduler.go:292]  "msg"="Trying to start multiple training jobs"  "jobs"=[] "scheduler"="default"
I0723 05:34:36.810430   16467 scheduler.go:342]  "msg"="Trying to scale multiple training jobs"  "jobs"=["tf2-keras-cifar10-inceptionv3-elastic-20210723-043156"] "scheduler"="default"
I0723 05:34:36.827601   16467 placement_manager.go:166]  "msg"="Started job placements adjustment"  "scheduler"="default"
I0723 05:34:36.827679   16467 placement_manager.go:192]  "msg"="Releasing slots"  "jobs"={"tf2-keras-cifar10-inceptionv3-elastic-20210723-043156":{},"tf2-keras-cifar10-inceptionv3-elastic-20210723-044044":{},"tf2-keras-cifar10-inceptionv3-elastic-20210723-044405":{},"tf2-keras-cifar10-inceptionv3-elastic-20210723-044418":{},"tf2-keras-cifar10-resnet50-elastic-20210723-044649":{},"tf2-keras-cifar10-resnet50-elastic-20210723-050639":{},"tf2-keras-cifar10-resnet50-elastic-20210723-050842":{},"tf2-keras-cifar10-vgg16-elastic-20210723-045956":{},"tf2-keras-cifar10-vgg16-elastic-20210723-050624":{},"tf2-keras-transformer-elastic-20210723-044415":{},"tf2-keras-transformer-elastic-20210723-050606":{},"tf2-keras-transformer-elastic-20210723-050907":{}} "nodes"={"gpu3":{},"gpu4":{},"gpu5":{}} "scheduler"="default"
I0723 05:34:36.827755   16467 placement_manager.go:250]  "msg"="Released slots"  "jobs"={"tf2-keras-cifar10-inceptionv3-elastic-20210723-043156":{},"tf2-keras-cifar10-inceptionv3-elastic-20210723-044044":{},"tf2-keras-cifar10-inceptionv3-elastic-20210723-044405":{},"tf2-keras-cifar10-inceptionv3-elastic-20210723-044418":{},"tf2-keras-cifar10-resnet50-elastic-20210723-044649":{},"tf2-keras-cifar10-resnet50-elastic-20210723-050639":{},"tf2-keras-cifar10-resnet50-elastic-20210723-050842":{},"tf2-keras-cifar10-vgg16-elastic-20210723-045956":{},"tf2-keras-cifar10-vgg16-elastic-20210723-050624":{},"tf2-keras-transformer-elastic-20210723-044415":{},"tf2-keras-transformer-elastic-20210723-050606":{},"tf2-keras-transformer-elastic-20210723-050907":{}} "nodes"={"gpu3":{},"gpu4":{},"gpu5":{}} "scheduler"="default"
I0723 05:34:36.828203   16467 placement_manager.go:305]  "msg"="Found best-fit"  "crossNode"=0 "nodes"=[{},{},{}] "requests"=[{},{},{},{},{},{},{},{},{},{},{},{},{},{},{},{},{},{},{},{},{},{}] "scheduler"="default"
I0723 05:34:36.828534   16467 placement_manager.go:339]  "msg"="nodeStates updated"  "new"={"gpu3":{},"gpu4":{},"gpu5":{}} "old"={"gpu3":{},"gpu4":{},"gpu5":{}} "scheduler"="default" "score"=6
I0723 05:34:36.828825   16467 placement_manager.go:387]  "msg"="jobStates updated"  "new"={"tf2-keras-cifar10-inceptionv3-elastic-20210723-043156":{},"tf2-keras-cifar10-inceptionv3-elastic-20210723-044044":{},"tf2-keras-cifar10-inceptionv3-elastic-20210723-044405":{},"tf2-keras-cifar10-inceptionv3-elastic-20210723-044418":{},"tf2-keras-cifar10-resnet50-elastic-20210723-050639":{},"tf2-keras-cifar10-resnet50-elastic-20210723-050842":{},"tf2-keras-cifar10-vgg16-elastic-20210723-045956":{},"tf2-keras-cifar10-vgg16-elastic-20210723-050624":{},"tf2-keras-transformer-elastic-20210723-044415":{},"tf2-keras-transformer-elastic-20210723-050606":{},"tf2-keras-transformer-elastic-20210723-050907":{}} "old"={"tf2-keras-cifar10-inceptionv3-elastic-20210723-043156":{},"tf2-keras-cifar10-inceptionv3-elastic-20210723-044044":{},"tf2-keras-cifar10-inceptionv3-elastic-20210723-044405":{},"tf2-keras-cifar10-inceptionv3-elastic-20210723-044418":{},"tf2-keras-cifar10-resnet50-elastic-20210723-044649":{},"tf2-keras-cifar10-resnet50-elastic-20210723-050639":{},"tf2-keras-cifar10-resnet50-elastic-20210723-050842":{},"tf2-keras-cifar10-vgg16-elastic-20210723-045956":{},"tf2-keras-cifar10-vgg16-elastic-20210723-050624":{},"tf2-keras-transformer-elastic-20210723-044415":{},"tf2-keras-transformer-elastic-20210723-050606":{},"tf2-keras-transformer-elastic-20210723-050907":{}} "scheduler"="default"
I0723 05:34:36.829172   16467 placement_manager.go:434]  "msg"="podNodeName updated"  "launchersToDelete"=5 "new"={"tf2-keras-cifar10-inceptionv3-elastic-20210723-043156-worker-0":"gpu4","tf2-keras-cifar10-inceptionv3-elastic-20210723-043156-worker-1":"gpu4","tf2-keras-cifar10-inceptionv3-elastic-20210723-044044-worker-0":"gpu5","tf2-keras-cifar10-inceptionv3-elastic-20210723-044405-worker-0":"gpu5","tf2-keras-cifar10-inceptionv3-elastic-20210723-044418-worker-0":"gpu4","tf2-keras-cifar10-resnet50-elastic-20210723-050639-worker-0":"gpu4","tf2-keras-cifar10-resnet50-elastic-20210723-050842-worker-0":"gpu3","tf2-keras-cifar10-vgg16-elastic-20210723-045956-worker-0":"gpu3","tf2-keras-cifar10-vgg16-elastic-20210723-050624-worker-0":"gpu3","tf2-keras-transformer-elastic-20210723-044415-worker-0":"gpu5","tf2-keras-transformer-elastic-20210723-050606-worker-0":"gpu3","tf2-keras-transformer-elastic-20210723-050907-worker-0":"gpu5"} "old"={"tf2-keras-cifar10-inceptionv3-elastic-20210723-043156-worker-0":"gpu4","tf2-keras-cifar10-inceptionv3-elastic-20210723-044044-worker-0":"gpu5","tf2-keras-cifar10-inceptionv3-elastic-20210723-044405-worker-0":"gpu3","tf2-keras-cifar10-inceptionv3-elastic-20210723-044418-worker-0":"gpu5","tf2-keras-cifar10-resnet50-elastic-20210723-044649-worker-0":"gpu4","tf2-keras-cifar10-resnet50-elastic-20210723-050639-worker-0":"gpu4","tf2-keras-cifar10-resnet50-elastic-20210723-050842-worker-0":"gpu4","tf2-keras-cifar10-vgg16-elastic-20210723-045956-worker-0":"gpu3","tf2-keras-cifar10-vgg16-elastic-20210723-050624-worker-0":"gpu5","tf2-keras-transformer-elastic-20210723-044415-worker-0":"gpu5","tf2-keras-transformer-elastic-20210723-050606-worker-0":"gpu3","tf2-keras-transformer-elastic-20210723-050907-worker-0":"gpu3"} "scheduler"="default" "workersToDelete"=5
I0723 05:34:36.829552   16467 placement_manager.go:451]  "msg"="Deleting pod that need migration"  "podName"="tf2-keras-cifar10-resnet50-elastic-20210723-050842-worker-0" "scheduler"="default"
I0723 05:34:36.836197   16467 placement_manager.go:451]  "msg"="Deleting pod that need migration"  "podName"="tf2-keras-cifar10-resnet50-elastic-20210723-050842-launcher" "scheduler"="default"
I0723 05:34:36.841581   16467 placement_manager.go:451]  "msg"="Deleting pod that need migration"  "podName"="tf2-keras-cifar10-inceptionv3-elastic-20210723-044405-worker-0" "scheduler"="default"
I0723 05:34:36.850015   16467 placement_manager.go:451]  "msg"="Deleting pod that need migration"  "podName"="tf2-keras-cifar10-inceptionv3-elastic-20210723-044405-launcher" "scheduler"="default"
I0723 05:34:36.854847   16467 placement_manager.go:451]  "msg"="Deleting pod that need migration"  "podName"="tf2-keras-cifar10-inceptionv3-elastic-20210723-044418-worker-0" "scheduler"="default"
I0723 05:34:36.862650   16467 placement_manager.go:147]  "msg"="Adding toleration to pod"  "podName"="tf2-keras-cifar10-inceptionv3-elastic-20210723-043156-worker-1" "scheduler"="default" "toleration"={"key":"celeste/hostname","operator":"Equal","value":"gpu4","effect":"NoExecute"}
I0723 05:34:36.867693   16467 placement_manager.go:451]  "msg"="Deleting pod that need migration"  "podName"="tf2-keras-cifar10-inceptionv3-elastic-20210723-044418-launcher" "scheduler"="default"
I0723 05:34:36.877710   16467 placement_manager.go:451]  "msg"="Deleting pod that need migration"  "podName"="tf2-keras-cifar10-vgg16-elastic-20210723-050624-worker-0" "scheduler"="default"
I0723 05:34:36.881161   16467 placement_manager.go:451]  "msg"="Deleting pod that need migration"  "podName"="tf2-keras-cifar10-vgg16-elastic-20210723-050624-launcher" "scheduler"="default"
I0723 05:34:36.884571   16467 placement_manager.go:451]  "msg"="Deleting pod that need migration"  "podName"="tf2-keras-transformer-elastic-20210723-050907-worker-0" "scheduler"="default"
I0723 05:34:37.034583   16467 placement_manager.go:451]  "msg"="Deleting pod that need migration"  "podName"="tf2-keras-transformer-elastic-20210723-050907-launcher" "scheduler"="default"
I0723 05:34:37.438025   16467 placement_manager.go:183]  "msg"="Finished job placements adjustment"  "scheduler"="default"
I0723 05:34:37.438345   16467 scheduler.go:182]  "msg"="Finished resched"  "scheduler"="default"
I0723 05:34:43.893544   16467 placement_manager.go:147]  "msg"="Adding toleration to pod"  "podName"="tf2-keras-cifar10-inceptionv3-elastic-20210723-044405-launcher" "scheduler"="default" "toleration"={"key":"celeste/hostname","operator":"Exists","effect":"NoExecute"}
I0723 05:34:49.762500   16467 placement_manager.go:147]  "msg"="Adding toleration to pod"  "podName"="tf2-keras-cifar10-inceptionv3-elastic-20210723-044418-worker-0" "scheduler"="default" "toleration"={"key":"celeste/hostname","operator":"Equal","value":"gpu4","effect":"NoExecute"}
I0723 05:34:49.804840   16467 placement_manager.go:147]  "msg"="Adding toleration to pod"  "podName"="tf2-keras-cifar10-inceptionv3-elastic-20210723-044418-launcher" "scheduler"="default" "toleration"={"key":"celeste/hostname","operator":"Exists","effect":"NoExecute"}
I0723 05:34:49.816515   16467 placement_manager.go:147]  "msg"="Adding toleration to pod"  "podName"="tf2-keras-transformer-elastic-20210723-050907-launcher" "scheduler"="default" "toleration"={"key":"celeste/hostname","operator":"Exists","effect":"NoExecute"}
I0723 05:34:49.825238   16467 placement_manager.go:147]  "msg"="Adding toleration to pod"  "podName"="tf2-keras-cifar10-vgg16-elastic-20210723-050624-worker-0" "scheduler"="default" "toleration"={"key":"celeste/hostname","operator":"Equal","value":"gpu3","effect":"NoExecute"}
I0723 05:34:54.109347   16467 placement_manager.go:147]  "msg"="Adding toleration to pod"  "podName"="tf2-keras-cifar10-inceptionv3-elastic-20210723-044405-worker-0" "scheduler"="default" "toleration"={"key":"celeste/hostname","operator":"Equal","value":"gpu5","effect":"NoExecute"}
I0723 05:34:54.507153   16467 placement_manager.go:147]  "msg"="Adding toleration to pod"  "podName"="tf2-keras-transformer-elastic-20210723-050907-worker-0" "scheduler"="default" "toleration"={"key":"celeste/hostname","operator":"Equal","value":"gpu5","effect":"NoExecute"}
I0723 05:34:55.245460   16467 placement_manager.go:147]  "msg"="Adding toleration to pod"  "podName"="tf2-keras-cifar10-resnet50-elastic-20210723-050842-worker-0" "scheduler"="default" "toleration"={"key":"celeste/hostname","operator":"Equal","value":"gpu3","effect":"NoExecute"}
I0723 05:34:56.046342   16467 placement_manager.go:147]  "msg"="Adding toleration to pod"  "podName"="tf2-keras-cifar10-resnet50-elastic-20210723-050842-launcher" "scheduler"="default" "toleration"={"key":"celeste/hostname","operator":"Exists","effect":"NoExecute"}
I0723 05:34:56.845285   16467 placement_manager.go:147]  "msg"="Adding toleration to pod"  "podName"="tf2-keras-cifar10-vgg16-elastic-20210723-050624-launcher" "scheduler"="default" "toleration"={"key":"celeste/hostname","operator":"Exists","effect":"NoExecute"}
I0723 05:35:52.011005   16467 scheduler.go:474]  "msg"="Training job completed"  "elaspedTotalSeconds"=2152.056826239 "gpuTotalSeconds"=1545.056008077 "job"="tf2-keras-cifar10-vgg16-elastic-20210723-045956" "ranTotalSeconds"=1545.056008077 "scheduler"="default" "waitedTotalSeconds"=607.000818162
I0723 05:35:52.011153   16467 scheduler.go:135]  "msg"="Received resched event, may be blocked because of rate limit"  "blockedUntil"="2021-07-23T05:36:37.43861061+08:00" "lastResched"="2021-07-23T05:34:37.43861061+08:00" "received"="2021-07-23T05:35:52.011041832+08:00" "scheduler"="default"
I0723 05:36:16.767099   16467 scheduler.go:474]  "msg"="Training job completed"  "elaspedTotalSeconds"=1789.146589395 "gpuTotalSeconds"=1450.052658792 "job"="tf2-keras-cifar10-vgg16-elastic-20210723-050624" "ranTotalSeconds"=1450.052658792 "scheduler"="default" "waitedTotalSeconds"=339.093930603
I0723 05:36:37.438731   16467 scheduler.go:159]  "msg"="Started resched"  "scheduler"="default"
I0723 05:36:37.438821   16467 scheduler.go:193]  "msg"="Updating all jobs info"  "scheduler"="default"
I0723 05:36:37.449336   16467 elastic_fifo.go:73]  "msg"="Finished scheduling"  "algorithm"="ElasticFIFO" "freeGpu"=0 "result"={"tf2-keras-cifar10-inceptionv3-elastic-20210723-043156":2,"tf2-keras-cifar10-inceptionv3-elastic-20210723-044044":2,"tf2-keras-cifar10-inceptionv3-elastic-20210723-044405":2,"tf2-keras-cifar10-inceptionv3-elastic-20210723-044418":1,"tf2-keras-cifar10-resnet50-elastic-20210723-050639":1,"tf2-keras-cifar10-resnet50-elastic-20210723-050842":1,"tf2-keras-transformer-elastic-20210723-044415":1,"tf2-keras-transformer-elastic-20210723-050606":1,"tf2-keras-transformer-elastic-20210723-050907":1} "scheduler"="default"
I0723 05:36:37.449786   16467 scheduler.go:384]  "msg"="Trying to delete multiple training jobs"  "jobs"=[] "scheduler"="default"
I0723 05:36:37.450071   16467 scheduler.go:342]  "msg"="Trying to scale multiple training jobs"  "jobs"=[] "scheduler"="default"
I0723 05:36:37.450310   16467 scheduler.go:292]  "msg"="Trying to start multiple training jobs"  "jobs"=[] "scheduler"="default"
I0723 05:36:37.450500   16467 scheduler.go:342]  "msg"="Trying to scale multiple training jobs"  "jobs"=["tf2-keras-cifar10-inceptionv3-elastic-20210723-044044","tf2-keras-cifar10-inceptionv3-elastic-20210723-044405"] "scheduler"="default"
I0723 05:36:37.493550   16467 placement_manager.go:166]  "msg"="Started job placements adjustment"  "scheduler"="default"
I0723 05:36:37.493637   16467 placement_manager.go:192]  "msg"="Releasing slots"  "jobs"={"tf2-keras-cifar10-inceptionv3-elastic-20210723-043156":{},"tf2-keras-cifar10-inceptionv3-elastic-20210723-044044":{},"tf2-keras-cifar10-inceptionv3-elastic-20210723-044405":{},"tf2-keras-cifar10-inceptionv3-elastic-20210723-044418":{},"tf2-keras-cifar10-resnet50-elastic-20210723-050639":{},"tf2-keras-cifar10-resnet50-elastic-20210723-050842":{},"tf2-keras-cifar10-vgg16-elastic-20210723-045956":{},"tf2-keras-cifar10-vgg16-elastic-20210723-050624":{},"tf2-keras-transformer-elastic-20210723-044415":{},"tf2-keras-transformer-elastic-20210723-050606":{},"tf2-keras-transformer-elastic-20210723-050907":{}} "nodes"={"gpu3":{},"gpu4":{},"gpu5":{}} "scheduler"="default"
I0723 05:36:37.493747   16467 placement_manager.go:250]  "msg"="Released slots"  "jobs"={"tf2-keras-cifar10-inceptionv3-elastic-20210723-043156":{},"tf2-keras-cifar10-inceptionv3-elastic-20210723-044044":{},"tf2-keras-cifar10-inceptionv3-elastic-20210723-044405":{},"tf2-keras-cifar10-inceptionv3-elastic-20210723-044418":{},"tf2-keras-cifar10-resnet50-elastic-20210723-050639":{},"tf2-keras-cifar10-resnet50-elastic-20210723-050842":{},"tf2-keras-cifar10-vgg16-elastic-20210723-045956":{},"tf2-keras-cifar10-vgg16-elastic-20210723-050624":{},"tf2-keras-transformer-elastic-20210723-044415":{},"tf2-keras-transformer-elastic-20210723-050606":{},"tf2-keras-transformer-elastic-20210723-050907":{}} "nodes"={"gpu3":{},"gpu4":{},"gpu5":{}} "scheduler"="default"
I0723 05:36:37.494169   16467 placement_manager.go:305]  "msg"="Found best-fit"  "crossNode"=0 "nodes"=[{},{},{}] "requests"=[{},{},{},{},{},{},{},{},{},{},{},{},{},{},{},{},{},{}] "scheduler"="default"
I0723 05:36:37.494549   16467 placement_manager.go:339]  "msg"="nodeStates updated"  "new"={"gpu3":{},"gpu4":{},"gpu5":{}} "old"={"gpu3":{},"gpu4":{},"gpu5":{}} "scheduler"="default" "score"=7
I0723 05:36:37.495046   16467 placement_manager.go:387]  "msg"="jobStates updated"  "new"={"tf2-keras-cifar10-inceptionv3-elastic-20210723-043156":{},"tf2-keras-cifar10-inceptionv3-elastic-20210723-044044":{},"tf2-keras-cifar10-inceptionv3-elastic-20210723-044405":{},"tf2-keras-cifar10-inceptionv3-elastic-20210723-044418":{},"tf2-keras-cifar10-resnet50-elastic-20210723-050639":{},"tf2-keras-cifar10-resnet50-elastic-20210723-050842":{},"tf2-keras-transformer-elastic-20210723-044415":{},"tf2-keras-transformer-elastic-20210723-050606":{},"tf2-keras-transformer-elastic-20210723-050907":{}} "old"={"tf2-keras-cifar10-inceptionv3-elastic-20210723-043156":{},"tf2-keras-cifar10-inceptionv3-elastic-20210723-044044":{},"tf2-keras-cifar10-inceptionv3-elastic-20210723-044405":{},"tf2-keras-cifar10-inceptionv3-elastic-20210723-044418":{},"tf2-keras-cifar10-resnet50-elastic-20210723-050639":{},"tf2-keras-cifar10-resnet50-elastic-20210723-050842":{},"tf2-keras-cifar10-vgg16-elastic-20210723-045956":{},"tf2-keras-cifar10-vgg16-elastic-20210723-050624":{},"tf2-keras-transformer-elastic-20210723-044415":{},"tf2-keras-transformer-elastic-20210723-050606":{},"tf2-keras-transformer-elastic-20210723-050907":{}} "scheduler"="default"
I0723 05:36:37.495664   16467 placement_manager.go:434]  "msg"="podNodeName updated"  "launchersToDelete"=2 "new"={"tf2-keras-cifar10-inceptionv3-elastic-20210723-043156-worker-0":"gpu4","tf2-keras-cifar10-inceptionv3-elastic-20210723-043156-worker-1":"gpu4","tf2-keras-cifar10-inceptionv3-elastic-20210723-044044-worker-0":"gpu4","tf2-keras-cifar10-inceptionv3-elastic-20210723-044044-worker-1":"gpu4","tf2-keras-cifar10-inceptionv3-elastic-20210723-044405-worker-0":"gpu5","tf2-keras-cifar10-inceptionv3-elastic-20210723-044405-worker-1":"gpu5","tf2-keras-cifar10-inceptionv3-elastic-20210723-044418-worker-0":"gpu3","tf2-keras-cifar10-resnet50-elastic-20210723-050639-worker-0":"gpu3","tf2-keras-cifar10-resnet50-elastic-20210723-050842-worker-0":"gpu3","tf2-keras-transformer-elastic-20210723-044415-worker-0":"gpu5","tf2-keras-transformer-elastic-20210723-050606-worker-0":"gpu3","tf2-keras-transformer-elastic-20210723-050907-worker-0":"gpu5"} "old"={"tf2-keras-cifar10-inceptionv3-elastic-20210723-043156-worker-0":"gpu4","tf2-keras-cifar10-inceptionv3-elastic-20210723-043156-worker-1":"gpu4","tf2-keras-cifar10-inceptionv3-elastic-20210723-044044-worker-0":"gpu5","tf2-keras-cifar10-inceptionv3-elastic-20210723-044405-worker-0":"gpu5","tf2-keras-cifar10-inceptionv3-elastic-20210723-044418-worker-0":"gpu4","tf2-keras-cifar10-resnet50-elastic-20210723-050639-worker-0":"gpu4","tf2-keras-cifar10-resnet50-elastic-20210723-050842-worker-0":"gpu3","tf2-keras-cifar10-vgg16-elastic-20210723-045956-worker-0":"gpu3","tf2-keras-cifar10-vgg16-elastic-20210723-050624-worker-0":"gpu3","tf2-keras-transformer-elastic-20210723-044415-worker-0":"gpu5","tf2-keras-transformer-elastic-20210723-050606-worker-0":"gpu3","tf2-keras-transformer-elastic-20210723-050907-worker-0":"gpu5"} "scheduler"="default" "workersToDelete"=3
I0723 05:36:37.496199   16467 placement_manager.go:451]  "msg"="Deleting pod that need migration"  "podName"="tf2-keras-cifar10-inceptionv3-elastic-20210723-044418-worker-0" "scheduler"="default"
I0723 05:36:37.501490   16467 placement_manager.go:147]  "msg"="Adding toleration to pod"  "podName"="tf2-keras-cifar10-inceptionv3-elastic-20210723-044044-worker-1" "scheduler"="default" "toleration"={"key":"celeste/hostname","operator":"Equal","value":"gpu4","effect":"NoExecute"}
I0723 05:36:37.501885   16467 placement_manager.go:451]  "msg"="Deleting pod that need migration"  "podName"="tf2-keras-cifar10-inceptionv3-elastic-20210723-044418-launcher" "scheduler"="default"
I0723 05:36:37.514914   16467 placement_manager.go:451]  "msg"="Deleting pod that need migration"  "podName"="tf2-keras-cifar10-inceptionv3-elastic-20210723-044044-worker-0" "scheduler"="default"
I0723 05:36:37.524785   16467 placement_manager.go:451]  "msg"="Deleting pod that need migration"  "podName"="tf2-keras-cifar10-resnet50-elastic-20210723-050639-worker-0" "scheduler"="default"
I0723 05:36:37.530048   16467 placement_manager.go:451]  "msg"="Deleting pod that need migration"  "podName"="tf2-keras-cifar10-resnet50-elastic-20210723-050639-launcher" "scheduler"="default"
I0723 05:36:37.534891   16467 placement_manager.go:183]  "msg"="Finished job placements adjustment"  "scheduler"="default"
I0723 05:36:37.535196   16467 scheduler.go:182]  "msg"="Finished resched"  "scheduler"="default"
I0723 05:36:37.549100   16467 placement_manager.go:147]  "msg"="Adding toleration to pod"  "podName"="tf2-keras-cifar10-inceptionv3-elastic-20210723-044405-worker-1" "scheduler"="default" "toleration"={"key":"celeste/hostname","operator":"Equal","value":"gpu5","effect":"NoExecute"}
I0723 05:36:44.493970   16467 placement_manager.go:147]  "msg"="Adding toleration to pod"  "podName"="tf2-keras-cifar10-resnet50-elastic-20210723-050639-launcher" "scheduler"="default" "toleration"={"key":"celeste/hostname","operator":"Exists","effect":"NoExecute"}
I0723 05:36:47.996722   16467 placement_manager.go:147]  "msg"="Adding toleration to pod"  "podName"="tf2-keras-cifar10-inceptionv3-elastic-20210723-044418-launcher" "scheduler"="default" "toleration"={"key":"celeste/hostname","operator":"Exists","effect":"NoExecute"}
I0723 05:36:49.756965   16467 placement_manager.go:147]  "msg"="Adding toleration to pod"  "podName"="tf2-keras-cifar10-inceptionv3-elastic-20210723-044044-worker-0" "scheduler"="default" "toleration"={"key":"celeste/hostname","operator":"Equal","value":"gpu4","effect":"NoExecute"}
I0723 05:36:55.198598   16467 placement_manager.go:147]  "msg"="Adding toleration to pod"  "podName"="tf2-keras-cifar10-resnet50-elastic-20210723-050639-worker-0" "scheduler"="default" "toleration"={"key":"celeste/hostname","operator":"Equal","value":"gpu3","effect":"NoExecute"}
I0723 05:36:55.995991   16467 placement_manager.go:147]  "msg"="Adding toleration to pod"  "podName"="tf2-keras-cifar10-inceptionv3-elastic-20210723-044418-worker-0" "scheduler"="default" "toleration"={"key":"celeste/hostname","operator":"Equal","value":"gpu3","effect":"NoExecute"}
I0723 05:37:53.741883   16467 scheduler.go:474]  "msg"="Training job completed"  "elaspedTotalSeconds"=3213.062854559 "gpuTotalSeconds"=2600.091845617 "job"="tf2-keras-transformer-elastic-20210723-044415" "ranTotalSeconds"=2600.091845617 "scheduler"="default" "waitedTotalSeconds"=612.971008942
I0723 05:37:53.742004   16467 scheduler.go:135]  "msg"="Received resched event, may be blocked because of rate limit"  "blockedUntil"="2021-07-23T05:38:37.535392177+08:00" "lastResched"="2021-07-23T05:36:37.535392177+08:00" "received"="2021-07-23T05:37:53.741907061+08:00" "scheduler"="default"
I0723 05:38:37.535521   16467 scheduler.go:159]  "msg"="Started resched"  "scheduler"="default"
I0723 05:38:37.535580   16467 scheduler.go:193]  "msg"="Updating all jobs info"  "scheduler"="default"
I0723 05:38:37.543257   16467 elastic_fifo.go:73]  "msg"="Finished scheduling"  "algorithm"="ElasticFIFO" "freeGpu"=0 "result"={"tf2-keras-cifar10-inceptionv3-elastic-20210723-043156":2,"tf2-keras-cifar10-inceptionv3-elastic-20210723-044044":2,"tf2-keras-cifar10-inceptionv3-elastic-20210723-044405":2,"tf2-keras-cifar10-inceptionv3-elastic-20210723-044418":2,"tf2-keras-cifar10-resnet50-elastic-20210723-050639":1,"tf2-keras-cifar10-resnet50-elastic-20210723-050842":1,"tf2-keras-transformer-elastic-20210723-050606":1,"tf2-keras-transformer-elastic-20210723-050907":1} "scheduler"="default"
I0723 05:38:37.543556   16467 scheduler.go:384]  "msg"="Trying to delete multiple training jobs"  "jobs"=[] "scheduler"="default"
I0723 05:38:37.543774   16467 scheduler.go:342]  "msg"="Trying to scale multiple training jobs"  "jobs"=[] "scheduler"="default"
I0723 05:38:37.543985   16467 scheduler.go:292]  "msg"="Trying to start multiple training jobs"  "jobs"=[] "scheduler"="default"
I0723 05:38:37.544228   16467 scheduler.go:342]  "msg"="Trying to scale multiple training jobs"  "jobs"=["tf2-keras-cifar10-inceptionv3-elastic-20210723-044418"] "scheduler"="default"
I0723 05:38:37.568569   16467 placement_manager.go:166]  "msg"="Started job placements adjustment"  "scheduler"="default"
I0723 05:38:37.568665   16467 placement_manager.go:192]  "msg"="Releasing slots"  "jobs"={"tf2-keras-cifar10-inceptionv3-elastic-20210723-043156":{},"tf2-keras-cifar10-inceptionv3-elastic-20210723-044044":{},"tf2-keras-cifar10-inceptionv3-elastic-20210723-044405":{},"tf2-keras-cifar10-inceptionv3-elastic-20210723-044418":{},"tf2-keras-cifar10-resnet50-elastic-20210723-050639":{},"tf2-keras-cifar10-resnet50-elastic-20210723-050842":{},"tf2-keras-transformer-elastic-20210723-044415":{},"tf2-keras-transformer-elastic-20210723-050606":{},"tf2-keras-transformer-elastic-20210723-050907":{}} "nodes"={"gpu3":{},"gpu4":{},"gpu5":{}} "scheduler"="default"
I0723 05:38:37.568735   16467 placement_manager.go:250]  "msg"="Released slots"  "jobs"={"tf2-keras-cifar10-inceptionv3-elastic-20210723-043156":{},"tf2-keras-cifar10-inceptionv3-elastic-20210723-044044":{},"tf2-keras-cifar10-inceptionv3-elastic-20210723-044405":{},"tf2-keras-cifar10-inceptionv3-elastic-20210723-044418":{},"tf2-keras-cifar10-resnet50-elastic-20210723-050639":{},"tf2-keras-cifar10-resnet50-elastic-20210723-050842":{},"tf2-keras-transformer-elastic-20210723-044415":{},"tf2-keras-transformer-elastic-20210723-050606":{},"tf2-keras-transformer-elastic-20210723-050907":{}} "nodes"={"gpu3":{},"gpu4":{},"gpu5":{}} "scheduler"="default"
I0723 05:38:37.569150   16467 placement_manager.go:305]  "msg"="Found best-fit"  "crossNode"=0 "nodes"=[{},{},{}] "requests"=[{},{},{},{},{},{},{},{},{},{},{},{},{},{},{},{}] "scheduler"="default"
I0723 05:38:37.569407   16467 placement_manager.go:339]  "msg"="nodeStates updated"  "new"={"gpu3":{},"gpu4":{},"gpu5":{}} "old"={"gpu3":{},"gpu4":{},"gpu5":{}} "scheduler"="default" "score"=9
I0723 05:38:37.569700   16467 placement_manager.go:387]  "msg"="jobStates updated"  "new"={"tf2-keras-cifar10-inceptionv3-elastic-20210723-043156":{},"tf2-keras-cifar10-inceptionv3-elastic-20210723-044044":{},"tf2-keras-cifar10-inceptionv3-elastic-20210723-044405":{},"tf2-keras-cifar10-inceptionv3-elastic-20210723-044418":{},"tf2-keras-cifar10-resnet50-elastic-20210723-050639":{},"tf2-keras-cifar10-resnet50-elastic-20210723-050842":{},"tf2-keras-transformer-elastic-20210723-050606":{},"tf2-keras-transformer-elastic-20210723-050907":{}} "old"={"tf2-keras-cifar10-inceptionv3-elastic-20210723-043156":{},"tf2-keras-cifar10-inceptionv3-elastic-20210723-044044":{},"tf2-keras-cifar10-inceptionv3-elastic-20210723-044405":{},"tf2-keras-cifar10-inceptionv3-elastic-20210723-044418":{},"tf2-keras-cifar10-resnet50-elastic-20210723-050639":{},"tf2-keras-cifar10-resnet50-elastic-20210723-050842":{},"tf2-keras-transformer-elastic-20210723-044415":{},"tf2-keras-transformer-elastic-20210723-050606":{},"tf2-keras-transformer-elastic-20210723-050907":{}} "scheduler"="default"
I0723 05:38:37.570123   16467 placement_manager.go:434]  "msg"="podNodeName updated"  "launchersToDelete"=1 "new"={"tf2-keras-cifar10-inceptionv3-elastic-20210723-043156-worker-0":"gpu4","tf2-keras-cifar10-inceptionv3-elastic-20210723-043156-worker-1":"gpu4","tf2-keras-cifar10-inceptionv3-elastic-20210723-044044-worker-0":"gpu4","tf2-keras-cifar10-inceptionv3-elastic-20210723-044044-worker-1":"gpu4","tf2-keras-cifar10-inceptionv3-elastic-20210723-044405-worker-0":"gpu5","tf2-keras-cifar10-inceptionv3-elastic-20210723-044405-worker-1":"gpu5","tf2-keras-cifar10-inceptionv3-elastic-20210723-044418-worker-0":"gpu5","tf2-keras-cifar10-inceptionv3-elastic-20210723-044418-worker-1":"gpu5","tf2-keras-cifar10-resnet50-elastic-20210723-050639-worker-0":"gpu3","tf2-keras-cifar10-resnet50-elastic-20210723-050842-worker-0":"gpu3","tf2-keras-transformer-elastic-20210723-050606-worker-0":"gpu3","tf2-keras-transformer-elastic-20210723-050907-worker-0":"gpu3"} "old"={"tf2-keras-cifar10-inceptionv3-elastic-20210723-043156-worker-0":"gpu4","tf2-keras-cifar10-inceptionv3-elastic-20210723-043156-worker-1":"gpu4","tf2-keras-cifar10-inceptionv3-elastic-20210723-044044-worker-0":"gpu4","tf2-keras-cifar10-inceptionv3-elastic-20210723-044044-worker-1":"gpu4","tf2-keras-cifar10-inceptionv3-elastic-20210723-044405-worker-0":"gpu5","tf2-keras-cifar10-inceptionv3-elastic-20210723-044405-worker-1":"gpu5","tf2-keras-cifar10-inceptionv3-elastic-20210723-044418-worker-0":"gpu3","tf2-keras-cifar10-resnet50-elastic-20210723-050639-worker-0":"gpu3","tf2-keras-cifar10-resnet50-elastic-20210723-050842-worker-0":"gpu3","tf2-keras-transformer-elastic-20210723-044415-worker-0":"gpu5","tf2-keras-transformer-elastic-20210723-050606-worker-0":"gpu3","tf2-keras-transformer-elastic-20210723-050907-worker-0":"gpu5"} "scheduler"="default" "workersToDelete"=2
I0723 05:38:37.570369   16467 placement_manager.go:451]  "msg"="Deleting pod that need migration"  "podName"="tf2-keras-transformer-elastic-20210723-050907-worker-0" "scheduler"="default"
I0723 05:38:37.583207   16467 placement_manager.go:451]  "msg"="Deleting pod that need migration"  "podName"="tf2-keras-transformer-elastic-20210723-050907-launcher" "scheduler"="default"
I0723 05:38:37.587908   16467 placement_manager.go:451]  "msg"="Deleting pod that need migration"  "podName"="tf2-keras-cifar10-inceptionv3-elastic-20210723-044418-worker-0" "scheduler"="default"
I0723 05:38:37.601349   16467 placement_manager.go:183]  "msg"="Finished job placements adjustment"  "scheduler"="default"
I0723 05:38:37.601686   16467 scheduler.go:182]  "msg"="Finished resched"  "scheduler"="default"
I0723 05:38:37.604532   16467 placement_manager.go:147]  "msg"="Adding toleration to pod"  "podName"="tf2-keras-cifar10-inceptionv3-elastic-20210723-044418-worker-1" "scheduler"="default" "toleration"={"key":"celeste/hostname","operator":"Equal","value":"gpu5","effect":"NoExecute"}
I0723 05:38:49.751508   16467 placement_manager.go:147]  "msg"="Adding toleration to pod"  "podName"="tf2-keras-transformer-elastic-20210723-050907-worker-0" "scheduler"="default" "toleration"={"key":"celeste/hostname","operator":"Equal","value":"gpu3","effect":"NoExecute"}
I0723 05:38:49.787896   16467 placement_manager.go:147]  "msg"="Adding toleration to pod"  "podName"="tf2-keras-transformer-elastic-20210723-050907-launcher" "scheduler"="default" "toleration"={"key":"celeste/hostname","operator":"Exists","effect":"NoExecute"}
I0723 05:38:54.619452   16467 placement_manager.go:147]  "msg"="Adding toleration to pod"  "podName"="tf2-keras-cifar10-inceptionv3-elastic-20210723-044418-worker-0" "scheduler"="default" "toleration"={"key":"celeste/hostname","operator":"Equal","value":"gpu5","effect":"NoExecute"}
I0723 05:41:27.553014   16467 scheduler.go:474]  "msg"="Training job completed"  "elaspedTotalSeconds"=2084.258511684 "gpuTotalSeconds"=1520.053660656 "job"="tf2-keras-cifar10-resnet50-elastic-20210723-050639" "ranTotalSeconds"=1520.053660656 "scheduler"="default" "waitedTotalSeconds"=564.204851028
I0723 05:41:27.553183   16467 scheduler.go:135]  "msg"="Received resched event, may be blocked because of rate limit"  "blockedUntil"="2021-07-23T05:40:37.601916102+08:00" "lastResched"="2021-07-23T05:38:37.601916102+08:00" "received"="2021-07-23T05:41:27.553064676+08:00" "scheduler"="default"
I0723 05:41:27.553757   16467 scheduler.go:159]  "msg"="Started resched"  "scheduler"="default"
I0723 05:41:27.553794   16467 scheduler.go:193]  "msg"="Updating all jobs info"  "scheduler"="default"
I0723 05:41:27.561994   16467 elastic_fifo.go:73]  "msg"="Finished scheduling"  "algorithm"="ElasticFIFO" "freeGpu"=0 "result"={"tf2-keras-cifar10-inceptionv3-elastic-20210723-043156":2,"tf2-keras-cifar10-inceptionv3-elastic-20210723-044044":2,"tf2-keras-cifar10-inceptionv3-elastic-20210723-044405":2,"tf2-keras-cifar10-inceptionv3-elastic-20210723-044418":2,"tf2-keras-cifar10-resnet50-elastic-20210723-050842":1,"tf2-keras-transformer-elastic-20210723-050606":2,"tf2-keras-transformer-elastic-20210723-050907":1} "scheduler"="default"
I0723 05:41:27.562438   16467 scheduler.go:384]  "msg"="Trying to delete multiple training jobs"  "jobs"=[] "scheduler"="default"
I0723 05:41:27.562676   16467 scheduler.go:342]  "msg"="Trying to scale multiple training jobs"  "jobs"=[] "scheduler"="default"
I0723 05:41:27.562930   16467 scheduler.go:292]  "msg"="Trying to start multiple training jobs"  "jobs"=[] "scheduler"="default"
I0723 05:41:27.563151   16467 scheduler.go:342]  "msg"="Trying to scale multiple training jobs"  "jobs"=["tf2-keras-transformer-elastic-20210723-050606"] "scheduler"="default"
I0723 05:41:27.582914   16467 placement_manager.go:166]  "msg"="Started job placements adjustment"  "scheduler"="default"
I0723 05:41:27.582995   16467 placement_manager.go:192]  "msg"="Releasing slots"  "jobs"={"tf2-keras-cifar10-inceptionv3-elastic-20210723-043156":{},"tf2-keras-cifar10-inceptionv3-elastic-20210723-044044":{},"tf2-keras-cifar10-inceptionv3-elastic-20210723-044405":{},"tf2-keras-cifar10-inceptionv3-elastic-20210723-044418":{},"tf2-keras-cifar10-resnet50-elastic-20210723-050639":{},"tf2-keras-cifar10-resnet50-elastic-20210723-050842":{},"tf2-keras-transformer-elastic-20210723-050606":{},"tf2-keras-transformer-elastic-20210723-050907":{}} "nodes"={"gpu3":{},"gpu4":{},"gpu5":{}} "scheduler"="default"
I0723 05:41:27.583070   16467 placement_manager.go:250]  "msg"="Released slots"  "jobs"={"tf2-keras-cifar10-inceptionv3-elastic-20210723-043156":{},"tf2-keras-cifar10-inceptionv3-elastic-20210723-044044":{},"tf2-keras-cifar10-inceptionv3-elastic-20210723-044405":{},"tf2-keras-cifar10-inceptionv3-elastic-20210723-044418":{},"tf2-keras-cifar10-resnet50-elastic-20210723-050639":{},"tf2-keras-cifar10-resnet50-elastic-20210723-050842":{},"tf2-keras-transformer-elastic-20210723-050606":{},"tf2-keras-transformer-elastic-20210723-050907":{}} "nodes"={"gpu3":{},"gpu4":{},"gpu5":{}} "scheduler"="default"
I0723 05:41:27.583624   16467 placement_manager.go:305]  "msg"="Found best-fit"  "crossNode"=0 "nodes"=[{},{},{}] "requests"=[{},{},{},{},{},{},{},{},{},{},{},{},{},{}] "scheduler"="default"
I0723 05:41:27.583976   16467 placement_manager.go:339]  "msg"="nodeStates updated"  "new"={"gpu3":{},"gpu4":{},"gpu5":{}} "old"={"gpu3":{},"gpu4":{},"gpu5":{}} "scheduler"="default" "score"=8
I0723 05:41:27.584306   16467 placement_manager.go:387]  "msg"="jobStates updated"  "new"={"tf2-keras-cifar10-inceptionv3-elastic-20210723-043156":{},"tf2-keras-cifar10-inceptionv3-elastic-20210723-044044":{},"tf2-keras-cifar10-inceptionv3-elastic-20210723-044405":{},"tf2-keras-cifar10-inceptionv3-elastic-20210723-044418":{},"tf2-keras-cifar10-resnet50-elastic-20210723-050842":{},"tf2-keras-transformer-elastic-20210723-050606":{},"tf2-keras-transformer-elastic-20210723-050907":{}} "old"={"tf2-keras-cifar10-inceptionv3-elastic-20210723-043156":{},"tf2-keras-cifar10-inceptionv3-elastic-20210723-044044":{},"tf2-keras-cifar10-inceptionv3-elastic-20210723-044405":{},"tf2-keras-cifar10-inceptionv3-elastic-20210723-044418":{},"tf2-keras-cifar10-resnet50-elastic-20210723-050639":{},"tf2-keras-cifar10-resnet50-elastic-20210723-050842":{},"tf2-keras-transformer-elastic-20210723-050606":{},"tf2-keras-transformer-elastic-20210723-050907":{}} "scheduler"="default"
I0723 05:41:27.584703   16467 placement_manager.go:434]  "msg"="podNodeName updated"  "launchersToDelete"=1 "new"={"tf2-keras-cifar10-inceptionv3-elastic-20210723-043156-worker-0":"gpu4","tf2-keras-cifar10-inceptionv3-elastic-20210723-043156-worker-1":"gpu4","tf2-keras-cifar10-inceptionv3-elastic-20210723-044044-worker-0":"gpu4","tf2-keras-cifar10-inceptionv3-elastic-20210723-044044-worker-1":"gpu4","tf2-keras-cifar10-inceptionv3-elastic-20210723-044405-worker-0":"gpu3","tf2-keras-cifar10-inceptionv3-elastic-20210723-044405-worker-1":"gpu3","tf2-keras-cifar10-inceptionv3-elastic-20210723-044418-worker-0":"gpu5","tf2-keras-cifar10-inceptionv3-elastic-20210723-044418-worker-1":"gpu5","tf2-keras-cifar10-resnet50-elastic-20210723-050842-worker-0":"gpu3","tf2-keras-transformer-elastic-20210723-050606-worker-0":"gpu5","tf2-keras-transformer-elastic-20210723-050606-worker-1":"gpu5","tf2-keras-transformer-elastic-20210723-050907-worker-0":"gpu3"} "old"={"tf2-keras-cifar10-inceptionv3-elastic-20210723-043156-worker-0":"gpu4","tf2-keras-cifar10-inceptionv3-elastic-20210723-043156-worker-1":"gpu4","tf2-keras-cifar10-inceptionv3-elastic-20210723-044044-worker-0":"gpu4","tf2-keras-cifar10-inceptionv3-elastic-20210723-044044-worker-1":"gpu4","tf2-keras-cifar10-inceptionv3-elastic-20210723-044405-worker-0":"gpu5","tf2-keras-cifar10-inceptionv3-elastic-20210723-044405-worker-1":"gpu5","tf2-keras-cifar10-inceptionv3-elastic-20210723-044418-worker-0":"gpu5","tf2-keras-cifar10-inceptionv3-elastic-20210723-044418-worker-1":"gpu5","tf2-keras-cifar10-resnet50-elastic-20210723-050639-worker-0":"gpu3","tf2-keras-cifar10-resnet50-elastic-20210723-050842-worker-0":"gpu3","tf2-keras-transformer-elastic-20210723-050606-worker-0":"gpu3","tf2-keras-transformer-elastic-20210723-050907-worker-0":"gpu3"} "scheduler"="default" "workersToDelete"=3
I0723 05:41:27.584996   16467 placement_manager.go:451]  "msg"="Deleting pod that need migration"  "podName"="tf2-keras-cifar10-inceptionv3-elastic-20210723-044405-worker-0" "scheduler"="default"
I0723 05:41:27.592073   16467 placement_manager.go:451]  "msg"="Deleting pod that need migration"  "podName"="tf2-keras-cifar10-inceptionv3-elastic-20210723-044405-worker-1" "scheduler"="default"
I0723 05:41:27.599936   16467 placement_manager.go:451]  "msg"="Deleting pod that need migration"  "podName"="tf2-keras-cifar10-inceptionv3-elastic-20210723-044405-launcher" "scheduler"="default"
I0723 05:41:27.615322   16467 placement_manager.go:451]  "msg"="Deleting pod that need migration"  "podName"="tf2-keras-transformer-elastic-20210723-050606-worker-0" "scheduler"="default"
I0723 05:41:27.619967   16467 placement_manager.go:183]  "msg"="Finished job placements adjustment"  "scheduler"="default"
I0723 05:41:27.620197   16467 scheduler.go:182]  "msg"="Finished resched"  "scheduler"="default"
I0723 05:41:27.631619   16467 placement_manager.go:147]  "msg"="Adding toleration to pod"  "podName"="tf2-keras-transformer-elastic-20210723-050606-worker-1" "scheduler"="default" "toleration"={"key":"celeste/hostname","operator":"Equal","value":"gpu5","effect":"NoExecute"}
I0723 05:41:34.617823   16467 placement_manager.go:147]  "msg"="Adding toleration to pod"  "podName"="tf2-keras-cifar10-inceptionv3-elastic-20210723-044405-launcher" "scheduler"="default" "toleration"={"key":"celeste/hostname","operator":"Exists","effect":"NoExecute"}
I0723 05:41:40.432612   16467 placement_manager.go:147]  "msg"="Adding toleration to pod"  "podName"="tf2-keras-cifar10-inceptionv3-elastic-20210723-044405-worker-0" "scheduler"="default" "toleration"={"key":"celeste/hostname","operator":"Equal","value":"gpu3","effect":"NoExecute"}
I0723 05:41:41.224491   16467 placement_manager.go:147]  "msg"="Adding toleration to pod"  "podName"="tf2-keras-cifar10-inceptionv3-elastic-20210723-044405-worker-1" "scheduler"="default" "toleration"={"key":"celeste/hostname","operator":"Equal","value":"gpu3","effect":"NoExecute"}
I0723 05:41:44.501975   16467 placement_manager.go:147]  "msg"="Adding toleration to pod"  "podName"="tf2-keras-transformer-elastic-20210723-050606-worker-0" "scheduler"="default" "toleration"={"key":"celeste/hostname","operator":"Equal","value":"gpu5","effect":"NoExecute"}
I0723 05:41:59.256746   16467 scheduler.go:474]  "msg"="Training job completed"  "elaspedTotalSeconds"=4202.841417595 "gpuTotalSeconds"=5220.178619417 "job"="tf2-keras-cifar10-inceptionv3-elastic-20210723-043156" "ranTotalSeconds"=4165.144668092 "scheduler"="default" "waitedTotalSeconds"=37.696749503
I0723 05:41:59.256939   16467 scheduler.go:135]  "msg"="Received resched event, may be blocked because of rate limit"  "blockedUntil"="2021-07-23T05:43:27.62033074+08:00" "lastResched"="2021-07-23T05:41:27.62033074+08:00" "received"="2021-07-23T05:41:59.256783483+08:00" "scheduler"="default"
I0723 05:43:27.620423   16467 scheduler.go:159]  "msg"="Started resched"  "scheduler"="default"
I0723 05:43:27.620489   16467 scheduler.go:193]  "msg"="Updating all jobs info"  "scheduler"="default"
I0723 05:43:27.626160   16467 elastic_fifo.go:73]  "msg"="Finished scheduling"  "algorithm"="ElasticFIFO" "freeGpu"=0 "result"={"tf2-keras-cifar10-inceptionv3-elastic-20210723-044044":2,"tf2-keras-cifar10-inceptionv3-elastic-20210723-044405":2,"tf2-keras-cifar10-inceptionv3-elastic-20210723-044418":2,"tf2-keras-cifar10-resnet50-elastic-20210723-050842":2,"tf2-keras-transformer-elastic-20210723-050606":2,"tf2-keras-transformer-elastic-20210723-050907":2} "scheduler"="default"
I0723 05:43:27.626610   16467 scheduler.go:384]  "msg"="Trying to delete multiple training jobs"  "jobs"=[] "scheduler"="default"
I0723 05:43:27.627057   16467 scheduler.go:342]  "msg"="Trying to scale multiple training jobs"  "jobs"=[] "scheduler"="default"
I0723 05:43:27.627403   16467 scheduler.go:292]  "msg"="Trying to start multiple training jobs"  "jobs"=[] "scheduler"="default"
I0723 05:43:27.627704   16467 scheduler.go:342]  "msg"="Trying to scale multiple training jobs"  "jobs"=["tf2-keras-cifar10-resnet50-elastic-20210723-050842","tf2-keras-transformer-elastic-20210723-050907"] "scheduler"="default"
I0723 05:43:27.669248   16467 placement_manager.go:166]  "msg"="Started job placements adjustment"  "scheduler"="default"
I0723 05:43:27.669353   16467 placement_manager.go:192]  "msg"="Releasing slots"  "jobs"={"tf2-keras-cifar10-inceptionv3-elastic-20210723-043156":{},"tf2-keras-cifar10-inceptionv3-elastic-20210723-044044":{},"tf2-keras-cifar10-inceptionv3-elastic-20210723-044405":{},"tf2-keras-cifar10-inceptionv3-elastic-20210723-044418":{},"tf2-keras-cifar10-resnet50-elastic-20210723-050842":{},"tf2-keras-transformer-elastic-20210723-050606":{},"tf2-keras-transformer-elastic-20210723-050907":{}} "nodes"={"gpu3":{},"gpu4":{},"gpu5":{}} "scheduler"="default"
I0723 05:43:27.669425   16467 placement_manager.go:250]  "msg"="Released slots"  "jobs"={"tf2-keras-cifar10-inceptionv3-elastic-20210723-043156":{},"tf2-keras-cifar10-inceptionv3-elastic-20210723-044044":{},"tf2-keras-cifar10-inceptionv3-elastic-20210723-044405":{},"tf2-keras-cifar10-inceptionv3-elastic-20210723-044418":{},"tf2-keras-cifar10-resnet50-elastic-20210723-050842":{},"tf2-keras-transformer-elastic-20210723-050606":{},"tf2-keras-transformer-elastic-20210723-050907":{}} "nodes"={"gpu3":{},"gpu4":{},"gpu5":{}} "scheduler"="default"
I0723 05:43:27.669991   16467 placement_manager.go:305]  "msg"="Found best-fit"  "crossNode"=0 "nodes"=[{},{},{}] "requests"=[{},{},{},{},{},{},{},{},{},{},{},{}] "scheduler"="default"
I0723 05:43:27.670288   16467 placement_manager.go:339]  "msg"="nodeStates updated"  "new"={"gpu3":{},"gpu4":{},"gpu5":{}} "old"={"gpu3":{},"gpu4":{},"gpu5":{}} "scheduler"="default" "score"=8
I0723 05:43:27.670692   16467 placement_manager.go:387]  "msg"="jobStates updated"  "new"={"tf2-keras-cifar10-inceptionv3-elastic-20210723-044044":{},"tf2-keras-cifar10-inceptionv3-elastic-20210723-044405":{},"tf2-keras-cifar10-inceptionv3-elastic-20210723-044418":{},"tf2-keras-cifar10-resnet50-elastic-20210723-050842":{},"tf2-keras-transformer-elastic-20210723-050606":{},"tf2-keras-transformer-elastic-20210723-050907":{}} "old"={"tf2-keras-cifar10-inceptionv3-elastic-20210723-043156":{},"tf2-keras-cifar10-inceptionv3-elastic-20210723-044044":{},"tf2-keras-cifar10-inceptionv3-elastic-20210723-044405":{},"tf2-keras-cifar10-inceptionv3-elastic-20210723-044418":{},"tf2-keras-cifar10-resnet50-elastic-20210723-050842":{},"tf2-keras-transformer-elastic-20210723-050606":{},"tf2-keras-transformer-elastic-20210723-050907":{}} "scheduler"="default"
I0723 05:43:27.671157   16467 placement_manager.go:434]  "msg"="podNodeName updated"  "launchersToDelete"=1 "new"={"tf2-keras-cifar10-inceptionv3-elastic-20210723-044044-worker-0":"gpu4","tf2-keras-cifar10-inceptionv3-elastic-20210723-044044-worker-1":"gpu4","tf2-keras-cifar10-inceptionv3-elastic-20210723-044405-worker-0":"gpu4","tf2-keras-cifar10-inceptionv3-elastic-20210723-044405-worker-1":"gpu4","tf2-keras-cifar10-inceptionv3-elastic-20210723-044418-worker-0":"gpu5","tf2-keras-cifar10-inceptionv3-elastic-20210723-044418-worker-1":"gpu5","tf2-keras-cifar10-resnet50-elastic-20210723-050842-worker-0":"gpu3","tf2-keras-cifar10-resnet50-elastic-20210723-050842-worker-1":"gpu3","tf2-keras-transformer-elastic-20210723-050606-worker-0":"gpu5","tf2-keras-transformer-elastic-20210723-050606-worker-1":"gpu5","tf2-keras-transformer-elastic-20210723-050907-worker-0":"gpu3","tf2-keras-transformer-elastic-20210723-050907-worker-1":"gpu3"} "old"={"tf2-keras-cifar10-inceptionv3-elastic-20210723-043156-worker-0":"gpu4","tf2-keras-cifar10-inceptionv3-elastic-20210723-043156-worker-1":"gpu4","tf2-keras-cifar10-inceptionv3-elastic-20210723-044044-worker-0":"gpu4","tf2-keras-cifar10-inceptionv3-elastic-20210723-044044-worker-1":"gpu4","tf2-keras-cifar10-inceptionv3-elastic-20210723-044405-worker-0":"gpu3","tf2-keras-cifar10-inceptionv3-elastic-20210723-044405-worker-1":"gpu3","tf2-keras-cifar10-inceptionv3-elastic-20210723-044418-worker-0":"gpu5","tf2-keras-cifar10-inceptionv3-elastic-20210723-044418-worker-1":"gpu5","tf2-keras-cifar10-resnet50-elastic-20210723-050842-worker-0":"gpu3","tf2-keras-transformer-elastic-20210723-050606-worker-0":"gpu5","tf2-keras-transformer-elastic-20210723-050606-worker-1":"gpu5","tf2-keras-transformer-elastic-20210723-050907-worker-0":"gpu3"} "scheduler"="default" "workersToDelete"=2
I0723 05:43:27.671501   16467 placement_manager.go:451]  "msg"="Deleting pod that need migration"  "podName"="tf2-keras-cifar10-inceptionv3-elastic-20210723-044405-worker-0" "scheduler"="default"
I0723 05:43:27.678801   16467 placement_manager.go:451]  "msg"="Deleting pod that need migration"  "podName"="tf2-keras-cifar10-inceptionv3-elastic-20210723-044405-worker-1" "scheduler"="default"
I0723 05:43:27.681821   16467 placement_manager.go:147]  "msg"="Adding toleration to pod"  "podName"="tf2-keras-cifar10-resnet50-elastic-20210723-050842-worker-1" "scheduler"="default" "toleration"={"key":"celeste/hostname","operator":"Equal","value":"gpu3","effect":"NoExecute"}
I0723 05:43:27.684055   16467 placement_manager.go:451]  "msg"="Deleting pod that need migration"  "podName"="tf2-keras-cifar10-inceptionv3-elastic-20210723-044405-launcher" "scheduler"="default"
I0723 05:43:27.702237   16467 placement_manager.go:183]  "msg"="Finished job placements adjustment"  "scheduler"="default"
I0723 05:43:27.702574   16467 scheduler.go:182]  "msg"="Finished resched"  "scheduler"="default"
I0723 05:43:27.725979   16467 placement_manager.go:147]  "msg"="Adding toleration to pod"  "podName"="tf2-keras-transformer-elastic-20210723-050907-worker-1" "scheduler"="default" "toleration"={"key":"celeste/hostname","operator":"Equal","value":"gpu3","effect":"NoExecute"}
I0723 05:43:34.453295   16467 placement_manager.go:147]  "msg"="Adding toleration to pod"  "podName"="tf2-keras-cifar10-inceptionv3-elastic-20210723-044405-launcher" "scheduler"="default" "toleration"={"key":"celeste/hostname","operator":"Exists","effect":"NoExecute"}
I0723 05:43:44.583730   16467 placement_manager.go:147]  "msg"="Adding toleration to pod"  "podName"="tf2-keras-cifar10-inceptionv3-elastic-20210723-044405-worker-0" "scheduler"="default" "toleration"={"key":"celeste/hostname","operator":"Equal","value":"gpu4","effect":"NoExecute"}
I0723 05:43:45.381615   16467 placement_manager.go:147]  "msg"="Adding toleration to pod"  "podName"="tf2-keras-cifar10-inceptionv3-elastic-20210723-044405-worker-1" "scheduler"="default" "toleration"={"key":"celeste/hostname","operator":"Equal","value":"gpu4","effect":"NoExecute"}
I0723 05:47:25.521419   16467 scheduler.go:474]  "msg"="Training job completed"  "elaspedTotalSeconds"=2321.226492459 "gpuTotalSeconds"=1710.057056335 "job"="tf2-keras-cifar10-resnet50-elastic-20210723-050842" "ranTotalSeconds"=1470.049487136 "scheduler"="default" "waitedTotalSeconds"=851.177005323
I0723 05:47:25.521596   16467 scheduler.go:135]  "msg"="Received resched event, may be blocked because of rate limit"  "blockedUntil"="2021-07-23T05:45:27.702763643+08:00" "lastResched"="2021-07-23T05:43:27.702763643+08:00" "received"="2021-07-23T05:47:25.521456722+08:00" "scheduler"="default"
I0723 05:47:25.522130   16467 scheduler.go:159]  "msg"="Started resched"  "scheduler"="default"
I0723 05:47:25.522166   16467 scheduler.go:193]  "msg"="Updating all jobs info"  "scheduler"="default"
I0723 05:47:25.526896   16467 elastic_fifo.go:73]  "msg"="Finished scheduling"  "algorithm"="ElasticFIFO" "freeGpu"=0 "result"={"tf2-keras-cifar10-inceptionv3-elastic-20210723-044044":3,"tf2-keras-cifar10-inceptionv3-elastic-20210723-044405":3,"tf2-keras-cifar10-inceptionv3-elastic-20210723-044418":2,"tf2-keras-transformer-elastic-20210723-050606":2,"tf2-keras-transformer-elastic-20210723-050907":2} "scheduler"="default"
I0723 05:47:25.527246   16467 scheduler.go:384]  "msg"="Trying to delete multiple training jobs"  "jobs"=[] "scheduler"="default"
I0723 05:47:25.527555   16467 scheduler.go:342]  "msg"="Trying to scale multiple training jobs"  "jobs"=[] "scheduler"="default"
I0723 05:47:25.527783   16467 scheduler.go:292]  "msg"="Trying to start multiple training jobs"  "jobs"=[] "scheduler"="default"
I0723 05:47:25.528027   16467 scheduler.go:342]  "msg"="Trying to scale multiple training jobs"  "jobs"=["tf2-keras-cifar10-inceptionv3-elastic-20210723-044044","tf2-keras-cifar10-inceptionv3-elastic-20210723-044405"] "scheduler"="default"
I0723 05:47:25.556675   16467 placement_manager.go:166]  "msg"="Started job placements adjustment"  "scheduler"="default"
I0723 05:47:25.556845   16467 placement_manager.go:192]  "msg"="Releasing slots"  "jobs"={"tf2-keras-cifar10-inceptionv3-elastic-20210723-044044":{},"tf2-keras-cifar10-inceptionv3-elastic-20210723-044405":{},"tf2-keras-cifar10-inceptionv3-elastic-20210723-044418":{},"tf2-keras-cifar10-resnet50-elastic-20210723-050842":{},"tf2-keras-transformer-elastic-20210723-050606":{},"tf2-keras-transformer-elastic-20210723-050907":{}} "nodes"={"gpu3":{},"gpu4":{},"gpu5":{}} "scheduler"="default"
I0723 05:47:25.556931   16467 placement_manager.go:250]  "msg"="Released slots"  "jobs"={"tf2-keras-cifar10-inceptionv3-elastic-20210723-044044":{},"tf2-keras-cifar10-inceptionv3-elastic-20210723-044405":{},"tf2-keras-cifar10-inceptionv3-elastic-20210723-044418":{},"tf2-keras-cifar10-resnet50-elastic-20210723-050842":{},"tf2-keras-transformer-elastic-20210723-050606":{},"tf2-keras-transformer-elastic-20210723-050907":{}} "nodes"={"gpu3":{},"gpu4":{},"gpu5":{}} "scheduler"="default"
I0723 05:47:25.557539   16467 placement_manager.go:305]  "msg"="Found best-fit"  "crossNode"=0 "nodes"=[{},{},{}] "requests"=[{},{},{},{},{},{},{},{},{},{}] "scheduler"="default"
I0723 05:47:25.557960   16467 placement_manager.go:339]  "msg"="nodeStates updated"  "new"={"gpu3":{},"gpu4":{},"gpu5":{}} "old"={"gpu3":{},"gpu4":{},"gpu5":{}} "scheduler"="default" "score"=8
I0723 05:47:25.558301   16467 placement_manager.go:387]  "msg"="jobStates updated"  "new"={"tf2-keras-cifar10-inceptionv3-elastic-20210723-044044":{},"tf2-keras-cifar10-inceptionv3-elastic-20210723-044405":{},"tf2-keras-cifar10-inceptionv3-elastic-20210723-044418":{},"tf2-keras-transformer-elastic-20210723-050606":{},"tf2-keras-transformer-elastic-20210723-050907":{}} "old"={"tf2-keras-cifar10-inceptionv3-elastic-20210723-044044":{},"tf2-keras-cifar10-inceptionv3-elastic-20210723-044405":{},"tf2-keras-cifar10-inceptionv3-elastic-20210723-044418":{},"tf2-keras-cifar10-resnet50-elastic-20210723-050842":{},"tf2-keras-transformer-elastic-20210723-050606":{},"tf2-keras-transformer-elastic-20210723-050907":{}} "scheduler"="default"
I0723 05:47:25.558815   16467 placement_manager.go:434]  "msg"="podNodeName updated"  "launchersToDelete"=0 "new"={"tf2-keras-cifar10-inceptionv3-elastic-20210723-044044-worker-0":"gpu4","tf2-keras-cifar10-inceptionv3-elastic-20210723-044044-worker-1":"gpu4","tf2-keras-cifar10-inceptionv3-elastic-20210723-044044-worker-2":"gpu4","tf2-keras-cifar10-inceptionv3-elastic-20210723-044405-worker-0":"gpu3","tf2-keras-cifar10-inceptionv3-elastic-20210723-044405-worker-1":"gpu3","tf2-keras-cifar10-inceptionv3-elastic-20210723-044405-worker-2":"gpu3","tf2-keras-cifar10-inceptionv3-elastic-20210723-044418-worker-0":"gpu5","tf2-keras-cifar10-inceptionv3-elastic-20210723-044418-worker-1":"gpu5","tf2-keras-transformer-elastic-20210723-050606-worker-0":"gpu5","tf2-keras-transformer-elastic-20210723-050606-worker-1":"gpu5","tf2-keras-transformer-elastic-20210723-050907-worker-0":"gpu4","tf2-keras-transformer-elastic-20210723-050907-worker-1":"gpu3","tf2-keras-transformer-elastic-20210723-050907-worker-2":"gpu3"} "old"={"tf2-keras-cifar10-inceptionv3-elastic-20210723-044044-worker-0":"gpu4","tf2-keras-cifar10-inceptionv3-elastic-20210723-044044-worker-1":"gpu4","tf2-keras-cifar10-inceptionv3-elastic-20210723-044405-worker-0":"gpu4","tf2-keras-cifar10-inceptionv3-elastic-20210723-044405-worker-1":"gpu4","tf2-keras-cifar10-inceptionv3-elastic-20210723-044418-worker-0":"gpu5","tf2-keras-cifar10-inceptionv3-elastic-20210723-044418-worker-1":"gpu5","tf2-keras-cifar10-resnet50-elastic-20210723-050842-worker-0":"gpu3","tf2-keras-cifar10-resnet50-elastic-20210723-050842-worker-1":"gpu3","tf2-keras-transformer-elastic-20210723-050606-worker-0":"gpu5","tf2-keras-transformer-elastic-20210723-050606-worker-1":"gpu5","tf2-keras-transformer-elastic-20210723-050907-worker-0":"gpu3","tf2-keras-transformer-elastic-20210723-050907-worker-1":"gpu3"} "scheduler"="default" "workersToDelete"=3
I0723 05:47:25.559118   16467 placement_manager.go:451]  "msg"="Deleting pod that need migration"  "podName"="tf2-keras-transformer-elastic-20210723-050907-worker-0" "scheduler"="default"
I0723 05:47:25.562725   16467 placement_manager.go:451]  "msg"="Deleting pod that need migration"  "podName"="tf2-keras-cifar10-inceptionv3-elastic-20210723-044405-worker-0" "scheduler"="default"
I0723 05:47:25.567347   16467 placement_manager.go:451]  "msg"="Deleting pod that need migration"  "podName"="tf2-keras-cifar10-inceptionv3-elastic-20210723-044405-worker-1" "scheduler"="default"
I0723 05:47:25.572042   16467 placement_manager.go:183]  "msg"="Finished job placements adjustment"  "scheduler"="default"
I0723 05:47:25.572273   16467 scheduler.go:182]  "msg"="Finished resched"  "scheduler"="default"
I0723 05:47:25.576305   16467 placement_manager.go:147]  "msg"="Adding toleration to pod"  "podName"="tf2-keras-cifar10-inceptionv3-elastic-20210723-044044-worker-2" "scheduler"="default" "toleration"={"key":"celeste/hostname","operator":"Equal","value":"gpu4","effect":"NoExecute"}
I0723 05:47:26.116051   16467 placement_manager.go:147]  "msg"="Adding toleration to pod"  "podName"="tf2-keras-cifar10-inceptionv3-elastic-20210723-044405-worker-2" "scheduler"="default" "toleration"={"key":"celeste/hostname","operator":"Equal","value":"gpu3","effect":"NoExecute"}
I0723 05:47:35.559525   16467 placement_manager.go:147]  "msg"="Adding toleration to pod"  "podName"="tf2-keras-transformer-elastic-20210723-050907-worker-0" "scheduler"="default" "toleration"={"key":"celeste/hostname","operator":"Equal","value":"gpu4","effect":"NoExecute"}
I0723 05:47:45.251624   16467 placement_manager.go:147]  "msg"="Adding toleration to pod"  "podName"="tf2-keras-cifar10-inceptionv3-elastic-20210723-044405-worker-0" "scheduler"="default" "toleration"={"key":"celeste/hostname","operator":"Equal","value":"gpu3","effect":"NoExecute"}
I0723 05:47:46.032389   16467 placement_manager.go:147]  "msg"="Adding toleration to pod"  "podName"="tf2-keras-cifar10-inceptionv3-elastic-20210723-044405-worker-1" "scheduler"="default" "toleration"={"key":"celeste/hostname","operator":"Equal","value":"gpu3","effect":"NoExecute"}
I0723 05:49:15.438566   16467 scheduler.go:474]  "msg"="Training job completed"  "elaspedTotalSeconds"=4109.739234716 "gpuTotalSeconds"=4979.768351724 "job"="tf2-keras-cifar10-inceptionv3-elastic-20210723-044044" "ranTotalSeconds"=4109.739234716 "scheduler"="default" "waitedTotalSeconds"=0
I0723 05:49:15.438735   16467 scheduler.go:135]  "msg"="Received resched event, may be blocked because of rate limit"  "blockedUntil"="2021-07-23T05:49:25.57244215+08:00" "lastResched"="2021-07-23T05:47:25.57244215+08:00" "received"="2021-07-23T05:49:15.438610826+08:00" "scheduler"="default"
I0723 05:49:25.572502   16467 scheduler.go:159]  "msg"="Started resched"  "scheduler"="default"
I0723 05:49:25.572550   16467 scheduler.go:193]  "msg"="Updating all jobs info"  "scheduler"="default"
I0723 05:49:25.576617   16467 elastic_fifo.go:73]  "msg"="Finished scheduling"  "algorithm"="ElasticFIFO" "freeGpu"=0 "result"={"tf2-keras-cifar10-inceptionv3-elastic-20210723-044405":3,"tf2-keras-cifar10-inceptionv3-elastic-20210723-044418":3,"tf2-keras-transformer-elastic-20210723-050606":3,"tf2-keras-transformer-elastic-20210723-050907":3} "scheduler"="default"
I0723 05:49:25.576883   16467 scheduler.go:384]  "msg"="Trying to delete multiple training jobs"  "jobs"=[] "scheduler"="default"
I0723 05:49:25.577133   16467 scheduler.go:342]  "msg"="Trying to scale multiple training jobs"  "jobs"=[] "scheduler"="default"
I0723 05:49:25.577380   16467 scheduler.go:292]  "msg"="Trying to start multiple training jobs"  "jobs"=[] "scheduler"="default"
I0723 05:49:25.577598   16467 scheduler.go:342]  "msg"="Trying to scale multiple training jobs"  "jobs"=["tf2-keras-cifar10-inceptionv3-elastic-20210723-044418","tf2-keras-transformer-elastic-20210723-050606","tf2-keras-transformer-elastic-20210723-050907"] "scheduler"="default"
I0723 05:49:25.626253   16467 placement_manager.go:166]  "msg"="Started job placements adjustment"  "scheduler"="default"
I0723 05:49:25.626373   16467 placement_manager.go:192]  "msg"="Releasing slots"  "jobs"={"tf2-keras-cifar10-inceptionv3-elastic-20210723-044044":{},"tf2-keras-cifar10-inceptionv3-elastic-20210723-044405":{},"tf2-keras-cifar10-inceptionv3-elastic-20210723-044418":{},"tf2-keras-transformer-elastic-20210723-050606":{},"tf2-keras-transformer-elastic-20210723-050907":{}} "nodes"={"gpu3":{},"gpu4":{},"gpu5":{}} "scheduler"="default"
I0723 05:49:25.626455   16467 placement_manager.go:250]  "msg"="Released slots"  "jobs"={"tf2-keras-cifar10-inceptionv3-elastic-20210723-044044":{},"tf2-keras-cifar10-inceptionv3-elastic-20210723-044405":{},"tf2-keras-cifar10-inceptionv3-elastic-20210723-044418":{},"tf2-keras-transformer-elastic-20210723-050606":{},"tf2-keras-transformer-elastic-20210723-050907":{}} "nodes"={"gpu3":{},"gpu4":{},"gpu5":{}} "scheduler"="default"
I0723 05:49:25.626901   16467 placement_manager.go:305]  "msg"="Found best-fit"  "crossNode"=0 "nodes"=[{},{},{}] "requests"=[{},{},{},{},{},{},{},{}] "scheduler"="default"
I0723 05:49:25.627199   16467 placement_manager.go:339]  "msg"="nodeStates updated"  "new"={"gpu3":{},"gpu4":{},"gpu5":{}} "old"={"gpu3":{},"gpu4":{},"gpu5":{}} "scheduler"="default" "score"=7
I0723 05:49:25.627554   16467 placement_manager.go:387]  "msg"="jobStates updated"  "new"={"tf2-keras-cifar10-inceptionv3-elastic-20210723-044405":{},"tf2-keras-cifar10-inceptionv3-elastic-20210723-044418":{},"tf2-keras-transformer-elastic-20210723-050606":{},"tf2-keras-transformer-elastic-20210723-050907":{}} "old"={"tf2-keras-cifar10-inceptionv3-elastic-20210723-044044":{},"tf2-keras-cifar10-inceptionv3-elastic-20210723-044405":{},"tf2-keras-cifar10-inceptionv3-elastic-20210723-044418":{},"tf2-keras-transformer-elastic-20210723-050606":{},"tf2-keras-transformer-elastic-20210723-050907":{}} "scheduler"="default"
I0723 05:49:25.627936   16467 placement_manager.go:434]  "msg"="podNodeName updated"  "launchersToDelete"=0 "new"={"tf2-keras-cifar10-inceptionv3-elastic-20210723-044405-worker-0":"gpu3","tf2-keras-cifar10-inceptionv3-elastic-20210723-044405-worker-1":"gpu3","tf2-keras-cifar10-inceptionv3-elastic-20210723-044405-worker-2":"gpu3","tf2-keras-cifar10-inceptionv3-elastic-20210723-044418-worker-0":"gpu4","tf2-keras-cifar10-inceptionv3-elastic-20210723-044418-worker-1":"gpu4","tf2-keras-cifar10-inceptionv3-elastic-20210723-044418-worker-2":"gpu4","tf2-keras-transformer-elastic-20210723-050606-worker-0":"gpu5","tf2-keras-transformer-elastic-20210723-050606-worker-1":"gpu5","tf2-keras-transformer-elastic-20210723-050606-worker-2":"gpu5","tf2-keras-transformer-elastic-20210723-050907-worker-0":"gpu3","tf2-keras-transformer-elastic-20210723-050907-worker-1":"gpu4","tf2-keras-transformer-elastic-20210723-050907-worker-2":"gpu5","tf2-keras-transformer-elastic-20210723-050907-worker-3":"gpu5","tf2-keras-transformer-elastic-20210723-050907-worker-4":"gpu5"} "old"={"tf2-keras-cifar10-inceptionv3-elastic-20210723-044044-worker-0":"gpu4","tf2-keras-cifar10-inceptionv3-elastic-20210723-044044-worker-1":"gpu4","tf2-keras-cifar10-inceptionv3-elastic-20210723-044044-worker-2":"gpu4","tf2-keras-cifar10-inceptionv3-elastic-20210723-044405-worker-0":"gpu3","tf2-keras-cifar10-inceptionv3-elastic-20210723-044405-worker-1":"gpu3","tf2-keras-cifar10-inceptionv3-elastic-20210723-044405-worker-2":"gpu3","tf2-keras-cifar10-inceptionv3-elastic-20210723-044418-worker-0":"gpu5","tf2-keras-cifar10-inceptionv3-elastic-20210723-044418-worker-1":"gpu5","tf2-keras-transformer-elastic-20210723-050606-worker-0":"gpu5","tf2-keras-transformer-elastic-20210723-050606-worker-1":"gpu5","tf2-keras-transformer-elastic-20210723-050907-worker-0":"gpu4","tf2-keras-transformer-elastic-20210723-050907-worker-1":"gpu3","tf2-keras-transformer-elastic-20210723-050907-worker-2":"gpu3"} "scheduler"="default" "workersToDelete"=5
I0723 05:49:25.628265   16467 placement_manager.go:451]  "msg"="Deleting pod that need migration"  "podName"="tf2-keras-transformer-elastic-20210723-050907-worker-0" "scheduler"="default"
I0723 05:49:25.644518   16467 placement_manager.go:451]  "msg"="Deleting pod that need migration"  "podName"="tf2-keras-transformer-elastic-20210723-050907-worker-1" "scheduler"="default"
I0723 05:49:25.647511   16467 placement_manager.go:147]  "msg"="Adding toleration to pod"  "podName"="tf2-keras-transformer-elastic-20210723-050606-worker-2" "scheduler"="default" "toleration"={"key":"celeste/hostname","operator":"Equal","value":"gpu5","effect":"NoExecute"}
I0723 05:49:25.649058   16467 placement_manager.go:451]  "msg"="Deleting pod that need migration"  "podName"="tf2-keras-transformer-elastic-20210723-050907-worker-2" "scheduler"="default"
E0723 05:49:25.654752   16467 placement_manager.go:455]  "msg"="Failed to delete pod" "error"="pods \"tf2-keras-transformer-elastic-20210723-050907-worker-2\" not found"  "podName"="tf2-keras-transformer-elastic-20210723-050907-worker-2" "scheduler"="default"
I0723 05:49:25.654801   16467 placement_manager.go:451]  "msg"="Deleting pod that need migration"  "podName"="tf2-keras-cifar10-inceptionv3-elastic-20210723-044418-worker-0" "scheduler"="default"
I0723 05:49:25.672696   16467 placement_manager.go:451]  "msg"="Deleting pod that need migration"  "podName"="tf2-keras-cifar10-inceptionv3-elastic-20210723-044418-worker-1" "scheduler"="default"
I0723 05:49:25.679651   16467 placement_manager.go:183]  "msg"="Finished job placements adjustment"  "scheduler"="default"
I0723 05:49:25.679903   16467 scheduler.go:182]  "msg"="Finished resched"  "scheduler"="default"
I0723 05:49:26.010189   16467 placement_manager.go:147]  "msg"="Adding toleration to pod"  "podName"="tf2-keras-transformer-elastic-20210723-050907-worker-2" "scheduler"="default" "toleration"={"key":"celeste/hostname","operator":"Equal","value":"gpu5","effect":"NoExecute"}
I0723 05:49:39.757455   16467 placement_manager.go:147]  "msg"="Adding toleration to pod"  "podName"="tf2-keras-cifar10-inceptionv3-elastic-20210723-044418-worker-1" "scheduler"="default" "toleration"={"key":"celeste/hostname","operator":"Equal","value":"gpu4","effect":"NoExecute"}
I0723 05:49:39.808274   16467 placement_manager.go:147]  "msg"="Adding toleration to pod"  "podName"="tf2-keras-cifar10-inceptionv3-elastic-20210723-044418-worker-0" "scheduler"="default" "toleration"={"key":"celeste/hostname","operator":"Equal","value":"gpu4","effect":"NoExecute"}
I0723 05:49:43.835163   16467 placement_manager.go:147]  "msg"="Adding toleration to pod"  "podName"="tf2-keras-transformer-elastic-20210723-050907-worker-1" "scheduler"="default" "toleration"={"key":"celeste/hostname","operator":"Equal","value":"gpu4","effect":"NoExecute"}
I0723 05:49:46.539300   16467 scheduler.go:474]  "msg"="Training job completed"  "elaspedTotalSeconds"=2617.052043498 "gpuTotalSeconds"=2900.100991187 "job"="tf2-keras-transformer-elastic-20210723-050606" "ranTotalSeconds"=2380.083376441 "scheduler"="default" "waitedTotalSeconds"=236.968667057
I0723 05:49:46.539502   16467 scheduler.go:135]  "msg"="Received resched event, may be blocked because of rate limit"  "blockedUntil"="2021-07-23T05:51:25.680105731+08:00" "lastResched"="2021-07-23T05:49:25.680105731+08:00" "received"="2021-07-23T05:49:46.539344481+08:00" "scheduler"="default"
I0723 05:49:46.653393   16467 placement_manager.go:147]  "msg"="Adding toleration to pod"  "podName"="tf2-keras-transformer-elastic-20210723-050907-worker-0" "scheduler"="default" "toleration"={"key":"celeste/hostname","operator":"Equal","value":"gpu3","effect":"NoExecute"}
I0723 05:51:25.680274   16467 scheduler.go:159]  "msg"="Started resched"  "scheduler"="default"
I0723 05:51:25.680401   16467 scheduler.go:193]  "msg"="Updating all jobs info"  "scheduler"="default"
I0723 05:51:25.684506   16467 elastic_fifo.go:73]  "msg"="Finished scheduling"  "algorithm"="ElasticFIFO" "freeGpu"=0 "result"={"tf2-keras-cifar10-inceptionv3-elastic-20210723-044405":4,"tf2-keras-cifar10-inceptionv3-elastic-20210723-044418":4,"tf2-keras-transformer-elastic-20210723-050907":4} "scheduler"="default"
I0723 05:51:25.684808   16467 scheduler.go:384]  "msg"="Trying to delete multiple training jobs"  "jobs"=[] "scheduler"="default"
I0723 05:51:25.685042   16467 scheduler.go:342]  "msg"="Trying to scale multiple training jobs"  "jobs"=[] "scheduler"="default"
I0723 05:51:25.685245   16467 scheduler.go:292]  "msg"="Trying to start multiple training jobs"  "jobs"=[] "scheduler"="default"
I0723 05:51:25.685478   16467 scheduler.go:342]  "msg"="Trying to scale multiple training jobs"  "jobs"=["tf2-keras-cifar10-inceptionv3-elastic-20210723-044418","tf2-keras-transformer-elastic-20210723-050907","tf2-keras-cifar10-inceptionv3-elastic-20210723-044405"] "scheduler"="default"
I0723 05:51:25.735691   16467 placement_manager.go:166]  "msg"="Started job placements adjustment"  "scheduler"="default"
I0723 05:51:25.735780   16467 placement_manager.go:192]  "msg"="Releasing slots"  "jobs"={"tf2-keras-cifar10-inceptionv3-elastic-20210723-044405":{},"tf2-keras-cifar10-inceptionv3-elastic-20210723-044418":{},"tf2-keras-transformer-elastic-20210723-050606":{},"tf2-keras-transformer-elastic-20210723-050907":{}} "nodes"={"gpu3":{},"gpu4":{},"gpu5":{}} "scheduler"="default"
I0723 05:51:25.735848   16467 placement_manager.go:250]  "msg"="Released slots"  "jobs"={"tf2-keras-cifar10-inceptionv3-elastic-20210723-044405":{},"tf2-keras-cifar10-inceptionv3-elastic-20210723-044418":{},"tf2-keras-transformer-elastic-20210723-050606":{},"tf2-keras-transformer-elastic-20210723-050907":{}} "nodes"={"gpu3":{},"gpu4":{},"gpu5":{}} "scheduler"="default"
I0723 05:51:25.736297   16467 placement_manager.go:305]  "msg"="Found best-fit"  "crossNode"=0 "nodes"=[{},{},{}] "requests"=[{},{},{},{},{},{}] "scheduler"="default"
I0723 05:51:25.736533   16467 placement_manager.go:339]  "msg"="nodeStates updated"  "new"={"gpu3":{},"gpu4":{},"gpu5":{}} "old"={"gpu3":{},"gpu4":{},"gpu5":{}} "scheduler"="default" "score"=8
I0723 05:51:25.736808   16467 placement_manager.go:387]  "msg"="jobStates updated"  "new"={"tf2-keras-cifar10-inceptionv3-elastic-20210723-044405":{},"tf2-keras-cifar10-inceptionv3-elastic-20210723-044418":{},"tf2-keras-transformer-elastic-20210723-050907":{}} "old"={"tf2-keras-cifar10-inceptionv3-elastic-20210723-044405":{},"tf2-keras-cifar10-inceptionv3-elastic-20210723-044418":{},"tf2-keras-transformer-elastic-20210723-050606":{},"tf2-keras-transformer-elastic-20210723-050907":{}} "scheduler"="default"
I0723 05:51:25.737116   16467 placement_manager.go:434]  "msg"="podNodeName updated"  "launchersToDelete"=0 "new"={"tf2-keras-cifar10-inceptionv3-elastic-20210723-044405-worker-0":"gpu3","tf2-keras-cifar10-inceptionv3-elastic-20210723-044405-worker-1":"gpu3","tf2-keras-cifar10-inceptionv3-elastic-20210723-044405-worker-2":"gpu3","tf2-keras-cifar10-inceptionv3-elastic-20210723-044405-worker-3":"gpu3","tf2-keras-cifar10-inceptionv3-elastic-20210723-044418-worker-0":"gpu4","tf2-keras-cifar10-inceptionv3-elastic-20210723-044418-worker-1":"gpu4","tf2-keras-cifar10-inceptionv3-elastic-20210723-044418-worker-2":"gpu4","tf2-keras-cifar10-inceptionv3-elastic-20210723-044418-worker-3":"gpu4","tf2-keras-transformer-elastic-20210723-050907-worker-0":"gpu5","tf2-keras-transformer-elastic-20210723-050907-worker-1":"gpu5","tf2-keras-transformer-elastic-20210723-050907-worker-2":"gpu5","tf2-keras-transformer-elastic-20210723-050907-worker-3":"gpu5"} "old"={"tf2-keras-cifar10-inceptionv3-elastic-20210723-044405-worker-0":"gpu3","tf2-keras-cifar10-inceptionv3-elastic-20210723-044405-worker-1":"gpu3","tf2-keras-cifar10-inceptionv3-elastic-20210723-044405-worker-2":"gpu3","tf2-keras-cifar10-inceptionv3-elastic-20210723-044418-worker-0":"gpu4","tf2-keras-cifar10-inceptionv3-elastic-20210723-044418-worker-1":"gpu4","tf2-keras-cifar10-inceptionv3-elastic-20210723-044418-worker-2":"gpu4","tf2-keras-transformer-elastic-20210723-050606-worker-0":"gpu5","tf2-keras-transformer-elastic-20210723-050606-worker-1":"gpu5","tf2-keras-transformer-elastic-20210723-050606-worker-2":"gpu5","tf2-keras-transformer-elastic-20210723-050907-worker-0":"gpu3","tf2-keras-transformer-elastic-20210723-050907-worker-1":"gpu4","tf2-keras-transformer-elastic-20210723-050907-worker-2":"gpu5","tf2-keras-transformer-elastic-20210723-050907-worker-3":"gpu5","tf2-keras-transformer-elastic-20210723-050907-worker-4":"gpu5"} "scheduler"="default" "workersToDelete"=2
I0723 05:51:25.737386   16467 placement_manager.go:451]  "msg"="Deleting pod that need migration"  "podName"="tf2-keras-transformer-elastic-20210723-050907-worker-0" "scheduler"="default"
I0723 05:51:25.743375   16467 placement_manager.go:451]  "msg"="Deleting pod that need migration"  "podName"="tf2-keras-transformer-elastic-20210723-050907-worker-1" "scheduler"="default"
I0723 05:51:25.746668   16467 placement_manager.go:147]  "msg"="Adding toleration to pod"  "podName"="tf2-keras-cifar10-inceptionv3-elastic-20210723-044418-worker-3" "scheduler"="default" "toleration"={"key":"celeste/hostname","operator":"Equal","value":"gpu4","effect":"NoExecute"}
I0723 05:51:25.961198   16467 placement_manager.go:183]  "msg"="Finished job placements adjustment"  "scheduler"="default"
I0723 05:51:25.961738   16467 scheduler.go:182]  "msg"="Finished resched"  "scheduler"="default"
I0723 05:51:25.994704   16467 placement_manager.go:147]  "msg"="Adding toleration to pod"  "podName"="tf2-keras-transformer-elastic-20210723-050907-worker-3" "scheduler"="default" "toleration"={"key":"celeste/hostname","operator":"Equal","value":"gpu5","effect":"NoExecute"}
I0723 05:51:26.004251   16467 placement_manager.go:147]  "msg"="Adding toleration to pod"  "podName"="tf2-keras-cifar10-inceptionv3-elastic-20210723-044405-worker-3" "scheduler"="default" "toleration"={"key":"celeste/hostname","operator":"Equal","value":"gpu3","effect":"NoExecute"}
I0723 05:51:34.747577   16467 placement_manager.go:147]  "msg"="Adding toleration to pod"  "podName"="tf2-keras-transformer-elastic-20210723-050907-worker-1" "scheduler"="default" "toleration"={"key":"celeste/hostname","operator":"Equal","value":"gpu5","effect":"NoExecute"}
I0723 05:51:43.832772   16467 placement_manager.go:147]  "msg"="Adding toleration to pod"  "podName"="tf2-keras-transformer-elastic-20210723-050907-worker-0" "scheduler"="default" "toleration"={"key":"celeste/hostname","operator":"Equal","value":"gpu5","effect":"NoExecute"}
I0723 05:54:01.251574   16467 scheduler.go:474]  "msg"="Training job completed"  "elaspedTotalSeconds"=4194.000600799 "gpuTotalSeconds"=5750.20224072 "job"="tf2-keras-cifar10-inceptionv3-elastic-20210723-044405" "ranTotalSeconds"=4155.146624958 "scheduler"="default" "waitedTotalSeconds"=38.853975841
I0723 05:54:01.251717   16467 scheduler.go:135]  "msg"="Received resched event, may be blocked because of rate limit"  "blockedUntil"="2021-07-23T05:53:25.962018735+08:00" "lastResched"="2021-07-23T05:51:25.962018735+08:00" "received"="2021-07-23T05:54:01.251609833+08:00" "scheduler"="default"
I0723 05:54:01.252221   16467 scheduler.go:159]  "msg"="Started resched"  "scheduler"="default"
I0723 05:54:01.252246   16467 scheduler.go:193]  "msg"="Updating all jobs info"  "scheduler"="default"
I0723 05:54:01.255191   16467 elastic_fifo.go:73]  "msg"="Finished scheduling"  "algorithm"="ElasticFIFO" "freeGpu"=4 "result"={"tf2-keras-cifar10-inceptionv3-elastic-20210723-044418":4,"tf2-keras-transformer-elastic-20210723-050907":4} "scheduler"="default"
I0723 05:54:01.255578   16467 scheduler.go:384]  "msg"="Trying to delete multiple training jobs"  "jobs"=[] "scheduler"="default"
I0723 05:54:01.255906   16467 scheduler.go:342]  "msg"="Trying to scale multiple training jobs"  "jobs"=[] "scheduler"="default"
I0723 05:54:01.256273   16467 scheduler.go:292]  "msg"="Trying to start multiple training jobs"  "jobs"=[] "scheduler"="default"
I0723 05:54:01.256545   16467 scheduler.go:342]  "msg"="Trying to scale multiple training jobs"  "jobs"=[] "scheduler"="default"
I0723 05:54:01.256783   16467 scheduler.go:180]  "msg"="Nothing changed, skipped ajust placements"  "scheduler"="default"
I0723 05:54:01.256823   16467 scheduler.go:182]  "msg"="Finished resched"  "scheduler"="default"
I0723 05:59:50.600458   16467 scheduler.go:474]  "msg"="Training job completed"  "elaspedTotalSeconds"=4530.202147632 "gpuTotalSeconds"=6005.208717749 "job"="tf2-keras-cifar10-inceptionv3-elastic-20210723-044418" "ranTotalSeconds"=3600.124881173 "scheduler"="default" "waitedTotalSeconds"=930.077266459
I0723 05:59:50.600678   16467 scheduler.go:135]  "msg"="Received resched event, may be blocked because of rate limit"  "blockedUntil"="2021-07-23T05:56:01.257042541+08:00" "lastResched"="2021-07-23T05:54:01.257042541+08:00" "received"="2021-07-23T05:59:50.600553184+08:00" "scheduler"="default"
I0723 05:59:50.601392   16467 scheduler.go:159]  "msg"="Started resched"  "scheduler"="default"
I0723 05:59:50.601481   16467 scheduler.go:193]  "msg"="Updating all jobs info"  "scheduler"="default"
I0723 05:59:50.603962   16467 elastic_fifo.go:73]  "msg"="Finished scheduling"  "algorithm"="ElasticFIFO" "freeGpu"=8 "result"={"tf2-keras-transformer-elastic-20210723-050907":4} "scheduler"="default"
I0723 05:59:50.604397   16467 scheduler.go:384]  "msg"="Trying to delete multiple training jobs"  "jobs"=[] "scheduler"="default"
I0723 05:59:50.604747   16467 scheduler.go:342]  "msg"="Trying to scale multiple training jobs"  "jobs"=[] "scheduler"="default"
I0723 05:59:50.605101   16467 scheduler.go:292]  "msg"="Trying to start multiple training jobs"  "jobs"=[] "scheduler"="default"
I0723 05:59:50.605379   16467 scheduler.go:342]  "msg"="Trying to scale multiple training jobs"  "jobs"=[] "scheduler"="default"
I0723 05:59:50.605709   16467 scheduler.go:180]  "msg"="Nothing changed, skipped ajust placements"  "scheduler"="default"
I0723 05:59:50.605742   16467 scheduler.go:182]  "msg"="Finished resched"  "scheduler"="default"
I0723 06:02:31.186009   16467 scheduler.go:474]  "msg"="Training job completed"  "elaspedTotalSeconds"=3201.37453659 "gpuTotalSeconds"=4620.164957969 "job"="tf2-keras-transformer-elastic-20210723-050907" "ranTotalSeconds"=2025.070234598 "scheduler"="default" "waitedTotalSeconds"=1176.304301992
I0723 06:02:31.186188   16467 scheduler.go:135]  "msg"="Received resched event, may be blocked because of rate limit"  "blockedUntil"="2021-07-23T06:01:50.606137849+08:00" "lastResched"="2021-07-23T05:59:50.606137849+08:00" "received"="2021-07-23T06:02:31.186057146+08:00" "scheduler"="default"
I0723 06:02:31.186811   16467 scheduler.go:159]  "msg"="Started resched"  "scheduler"="default"
I0723 06:02:31.186850   16467 scheduler.go:193]  "msg"="Updating all jobs info"  "scheduler"="default"
I0723 06:02:31.187212   16467 elastic_fifo.go:73]  "msg"="Finished scheduling"  "algorithm"="ElasticFIFO" "freeGpu"=12 "result"={} "scheduler"="default"
I0723 06:02:31.187644   16467 scheduler.go:384]  "msg"="Trying to delete multiple training jobs"  "jobs"=[] "scheduler"="default"
I0723 06:02:31.188028   16467 scheduler.go:342]  "msg"="Trying to scale multiple training jobs"  "jobs"=[] "scheduler"="default"
I0723 06:02:31.188469   16467 scheduler.go:292]  "msg"="Trying to start multiple training jobs"  "jobs"=[] "scheduler"="default"
I0723 06:02:31.188845   16467 scheduler.go:342]  "msg"="Trying to scale multiple training jobs"  "jobs"=[] "scheduler"="default"
I0723 06:02:31.189238   16467 scheduler.go:180]  "msg"="Nothing changed, skipped ajust placements"  "scheduler"="default"
I0723 06:02:31.189270   16467 scheduler.go:182]  "msg"="Finished resched"  "scheduler"="default"
