Log file created at: 2021/07/23 16:25:43
Running on machine: gpu4
Binary: Built with gc go1.13.15 for linux/amd64
Log line format: [IWEF]mmdd hh:mm:ss.uuuuuu threadid file:line] msg
I0723 16:25:43.737560    7682 main.go:19]  "msg"="Celeste - DLT jobs scheduler"  "version"="0.0.1"
I0723 16:25:43.738332    7682 main.go:20]  "msg"="Starting service"  
I0723 16:25:43.742315    7682 placement_manager.go:65]  "msg"="Starting placement manager"  "scheduler"="default"
I0723 16:25:43.744359    7682 placement_manager.go:95]  "msg"="Started placement manager"  "nodes"={"gpu3":{},"gpu4":{},"gpu5":{}} "scheduler"="default"
I0723 16:25:43.744769    7682 jobmaster.go:82]  "msg"="Starting scheduler"  "gpuType"="default"
I0723 16:25:43.744860    7682 scheduler.go:124]  "msg"="Starting scheduler"  "scheduler"="default"
I0723 16:25:43.777063    7682 scheduler.go:432]  "msg"="Start watching mpijob"  "scheduler"="default"
I0723 16:25:50.279682    7682 jobmaster.go:155]  "msg"="Training job created"  "job"="tf2-keras-cifar10-inceptionv3-elastic-20210723-042550"
I0723 16:25:50.279885    7682 scheduler.go:135]  "msg"="Received resched event, may be blocked because of rate limit"  "blockedUntil"="2021-07-23T16:25:43.744742515+08:00" "lastResched"="2021-07-23T16:25:43.744742708+08:00" "received"="2021-07-23T16:25:50.278749344+08:00" "scheduler"="default"
I0723 16:25:50.280692    7682 scheduler.go:159]  "msg"="Started resched"  "scheduler"="default"
I0723 16:25:50.280788    7682 scheduler.go:193]  "msg"="Updating all jobs info"  "scheduler"="default"
I0723 16:25:50.282910    7682 afsl.go:65]  "msg"="Finished scheduling"  "algorithm"="AFS-L" "freeGpu"=8 "result"={"tf2-keras-cifar10-inceptionv3-elastic-20210723-042550":4} "scheduler"="default"
I0723 16:25:50.283318    7682 scheduler.go:384]  "msg"="Trying to delete multiple training jobs"  "jobs"=[] "scheduler"="default"
I0723 16:25:50.283757    7682 scheduler.go:342]  "msg"="Trying to scale multiple training jobs"  "jobs"=[] "scheduler"="default"
I0723 16:25:50.284186    7682 scheduler.go:292]  "msg"="Trying to start multiple training jobs"  "jobs"=["tf2-keras-cifar10-inceptionv3-elastic-20210723-042550"] "scheduler"="default"
I0723 16:25:50.305753    7682 scheduler.go:342]  "msg"="Trying to scale multiple training jobs"  "jobs"=[] "scheduler"="default"
I0723 16:25:50.307851    7682 placement_manager.go:166]  "msg"="Started job placements adjustment"  "scheduler"="default"
I0723 16:25:50.308007    7682 placement_manager.go:192]  "msg"="Releasing slots"  "jobs"={} "nodes"={"gpu3":{},"gpu4":{},"gpu5":{}} "scheduler"="default"
I0723 16:25:50.308058    7682 placement_manager.go:250]  "msg"="Released slots"  "jobs"={} "nodes"={"gpu3":{},"gpu4":{},"gpu5":{}} "scheduler"="default"
I0723 16:25:50.308452    7682 placement_manager.go:305]  "msg"="Found best-fit"  "crossNode"=0 "nodes"=[{},{},{}] "requests"=[{},{}] "scheduler"="default"
I0723 16:25:50.308770    7682 placement_manager.go:339]  "msg"="nodeStates updated"  "new"={"gpu3":{},"gpu4":{},"gpu5":{}} "old"={"gpu3":{},"gpu4":{},"gpu5":{}} "scheduler"="default" "score"=0
I0723 16:25:50.309006    7682 placement_manager.go:387]  "msg"="jobStates updated"  "new"={"tf2-keras-cifar10-inceptionv3-elastic-20210723-042550":{}} "old"={} "scheduler"="default"
I0723 16:25:50.309243    7682 placement_manager.go:434]  "msg"="podNodeName updated"  "launchersToDelete"=0 "new"={"tf2-keras-cifar10-inceptionv3-elastic-20210723-042550-worker-0":"gpu3","tf2-keras-cifar10-inceptionv3-elastic-20210723-042550-worker-1":"gpu3","tf2-keras-cifar10-inceptionv3-elastic-20210723-042550-worker-2":"gpu3","tf2-keras-cifar10-inceptionv3-elastic-20210723-042550-worker-3":"gpu3"} "old"={} "scheduler"="default" "workersToDelete"=0
I0723 16:25:50.309481    7682 placement_manager.go:183]  "msg"="Finished job placements adjustment"  "scheduler"="default"
I0723 16:25:50.309720    7682 scheduler.go:182]  "msg"="Finished resched"  "scheduler"="default"
I0723 16:25:50.379360    7682 placement_manager.go:147]  "msg"="Adding toleration to pod"  "podName"="tf2-keras-cifar10-inceptionv3-elastic-20210723-042550-worker-0" "scheduler"="default" "toleration"={"key":"celeste/hostname","operator":"Equal","value":"gpu3","effect":"NoExecute"}
I0723 16:25:50.393416    7682 placement_manager.go:147]  "msg"="Adding toleration to pod"  "podName"="tf2-keras-cifar10-inceptionv3-elastic-20210723-042550-worker-1" "scheduler"="default" "toleration"={"key":"celeste/hostname","operator":"Equal","value":"gpu3","effect":"NoExecute"}
I0723 16:25:50.406247    7682 placement_manager.go:147]  "msg"="Adding toleration to pod"  "podName"="tf2-keras-cifar10-inceptionv3-elastic-20210723-042550-worker-2" "scheduler"="default" "toleration"={"key":"celeste/hostname","operator":"Equal","value":"gpu3","effect":"NoExecute"}
I0723 16:25:50.414950    7682 placement_manager.go:147]  "msg"="Adding toleration to pod"  "podName"="tf2-keras-cifar10-inceptionv3-elastic-20210723-042550-worker-3" "scheduler"="default" "toleration"={"key":"celeste/hostname","operator":"Equal","value":"gpu3","effect":"NoExecute"}
I0723 16:25:50.425490    7682 placement_manager.go:147]  "msg"="Adding toleration to pod"  "podName"="tf2-keras-cifar10-inceptionv3-elastic-20210723-042550-launcher" "scheduler"="default" "toleration"={"key":"celeste/hostname","operator":"Exists","effect":"NoExecute"}
I0723 16:25:57.517032    7682 jobmaster.go:155]  "msg"="Training job created"  "job"="tf2-keras-cifar10-resnet50-elastic-20210723-042557"
I0723 16:25:57.517209    7682 scheduler.go:135]  "msg"="Received resched event, may be blocked because of rate limit"  "blockedUntil"="2021-07-23T16:27:50.309955092+08:00" "lastResched"="2021-07-23T16:25:50.309955092+08:00" "received"="2021-07-23T16:25:57.516235445+08:00" "scheduler"="default"
I0723 16:26:02.650950    7682 jobmaster.go:155]  "msg"="Training job created"  "job"="tf2-keras-cifar10-inceptionv3-elastic-20210723-042602"
I0723 16:26:32.683644    7682 jobmaster.go:155]  "msg"="Training job created"  "job"="tf2-keras-cifar10-vgg16-elastic-20210723-042632"
I0723 16:26:59.689360    7682 jobmaster.go:155]  "msg"="Training job created"  "job"="tf2-keras-cifar10-vgg16-elastic-20210723-042659"
I0723 16:27:50.310058    7682 scheduler.go:159]  "msg"="Started resched"  "scheduler"="default"
I0723 16:27:50.310116    7682 scheduler.go:193]  "msg"="Updating all jobs info"  "scheduler"="default"
I0723 16:27:50.316750    7682 afsl.go:65]  "msg"="Finished scheduling"  "algorithm"="AFS-L" "freeGpu"=0 "result"={"tf2-keras-cifar10-inceptionv3-elastic-20210723-042550":1,"tf2-keras-cifar10-inceptionv3-elastic-20210723-042602":3,"tf2-keras-cifar10-resnet50-elastic-20210723-042557":2,"tf2-keras-cifar10-vgg16-elastic-20210723-042632":3,"tf2-keras-cifar10-vgg16-elastic-20210723-042659":3} "scheduler"="default"
I0723 16:27:50.317100    7682 scheduler.go:384]  "msg"="Trying to delete multiple training jobs"  "jobs"=[] "scheduler"="default"
I0723 16:27:50.317407    7682 scheduler.go:342]  "msg"="Trying to scale multiple training jobs"  "jobs"=["tf2-keras-cifar10-inceptionv3-elastic-20210723-042550"] "scheduler"="default"
I0723 16:27:50.334116    7682 scheduler.go:292]  "msg"="Trying to start multiple training jobs"  "jobs"=["tf2-keras-cifar10-resnet50-elastic-20210723-042557","tf2-keras-cifar10-inceptionv3-elastic-20210723-042602","tf2-keras-cifar10-vgg16-elastic-20210723-042632","tf2-keras-cifar10-vgg16-elastic-20210723-042659"] "scheduler"="default"
I0723 16:27:50.364279    7682 scheduler.go:342]  "msg"="Trying to scale multiple training jobs"  "jobs"=[] "scheduler"="default"
I0723 16:27:50.367154    7682 placement_manager.go:166]  "msg"="Started job placements adjustment"  "scheduler"="default"
I0723 16:27:50.367248    7682 placement_manager.go:192]  "msg"="Releasing slots"  "jobs"={"tf2-keras-cifar10-inceptionv3-elastic-20210723-042550":{}} "nodes"={"gpu3":{},"gpu4":{},"gpu5":{}} "scheduler"="default"
I0723 16:27:50.367334    7682 placement_manager.go:250]  "msg"="Released slots"  "jobs"={"tf2-keras-cifar10-inceptionv3-elastic-20210723-042550":{}} "nodes"={"gpu3":{},"gpu4":{},"gpu5":{}} "scheduler"="default"
I0723 16:27:50.367828    7682 placement_manager.go:305]  "msg"="Found best-fit"  "crossNode"=0 "nodes"=[{},{},{}] "requests"=[{},{},{},{},{},{},{},{},{},{}] "scheduler"="default"
I0723 16:27:50.368225    7682 placement_manager.go:339]  "msg"="nodeStates updated"  "new"={"gpu3":{},"gpu4":{},"gpu5":{}} "old"={"gpu3":{},"gpu4":{},"gpu5":{}} "scheduler"="default" "score"=1
I0723 16:27:50.368548    7682 placement_manager.go:387]  "msg"="jobStates updated"  "new"={"tf2-keras-cifar10-inceptionv3-elastic-20210723-042550":{},"tf2-keras-cifar10-inceptionv3-elastic-20210723-042602":{},"tf2-keras-cifar10-resnet50-elastic-20210723-042557":{},"tf2-keras-cifar10-vgg16-elastic-20210723-042632":{},"tf2-keras-cifar10-vgg16-elastic-20210723-042659":{}} "old"={"tf2-keras-cifar10-inceptionv3-elastic-20210723-042550":{}} "scheduler"="default"
I0723 16:27:50.368974    7682 placement_manager.go:434]  "msg"="podNodeName updated"  "launchersToDelete"=0 "new"={"tf2-keras-cifar10-inceptionv3-elastic-20210723-042550-worker-0":"gpu3","tf2-keras-cifar10-inceptionv3-elastic-20210723-042602-worker-0":"gpu4","tf2-keras-cifar10-inceptionv3-elastic-20210723-042602-worker-1":"gpu4","tf2-keras-cifar10-inceptionv3-elastic-20210723-042602-worker-2":"gpu4","tf2-keras-cifar10-resnet50-elastic-20210723-042557-worker-0":"gpu4","tf2-keras-cifar10-resnet50-elastic-20210723-042557-worker-1":"gpu4","tf2-keras-cifar10-resnet50-elastic-20210723-042557-worker-2":"gpu5","tf2-keras-cifar10-vgg16-elastic-20210723-042632-worker-0":"gpu3","tf2-keras-cifar10-vgg16-elastic-20210723-042632-worker-1":"gpu3","tf2-keras-cifar10-vgg16-elastic-20210723-042632-worker-2":"gpu3","tf2-keras-cifar10-vgg16-elastic-20210723-042659-worker-0":"gpu5","tf2-keras-cifar10-vgg16-elastic-20210723-042659-worker-1":"gpu5","tf2-keras-cifar10-vgg16-elastic-20210723-042659-worker-2":"gpu5"} "old"={"tf2-keras-cifar10-inceptionv3-elastic-20210723-042550-worker-0":"gpu3","tf2-keras-cifar10-inceptionv3-elastic-20210723-042550-worker-1":"gpu3","tf2-keras-cifar10-inceptionv3-elastic-20210723-042550-worker-2":"gpu3","tf2-keras-cifar10-inceptionv3-elastic-20210723-042550-worker-3":"gpu3"} "scheduler"="default" "workersToDelete"=0
I0723 16:27:50.369376    7682 placement_manager.go:183]  "msg"="Finished job placements adjustment"  "scheduler"="default"
I0723 16:27:50.369684    7682 scheduler.go:182]  "msg"="Finished resched"  "scheduler"="default"
I0723 16:27:51.150021    7682 placement_manager.go:147]  "msg"="Adding toleration to pod"  "podName"="tf2-keras-cifar10-resnet50-elastic-20210723-042557-worker-0" "scheduler"="default" "toleration"={"key":"celeste/hostname","operator":"Equal","value":"gpu4","effect":"NoExecute"}
I0723 16:27:51.748431    7682 placement_manager.go:147]  "msg"="Adding toleration to pod"  "podName"="tf2-keras-cifar10-resnet50-elastic-20210723-042557-worker-1" "scheduler"="default" "toleration"={"key":"celeste/hostname","operator":"Equal","value":"gpu4","effect":"NoExecute"}
I0723 16:27:52.146059    7682 placement_manager.go:147]  "msg"="Adding toleration to pod"  "podName"="tf2-keras-cifar10-resnet50-elastic-20210723-042557-launcher" "scheduler"="default" "toleration"={"key":"celeste/hostname","operator":"Exists","effect":"NoExecute"}
I0723 16:27:53.146413    7682 placement_manager.go:147]  "msg"="Adding toleration to pod"  "podName"="tf2-keras-cifar10-inceptionv3-elastic-20210723-042602-worker-0" "scheduler"="default" "toleration"={"key":"celeste/hostname","operator":"Equal","value":"gpu4","effect":"NoExecute"}
I0723 16:27:53.547382    7682 placement_manager.go:147]  "msg"="Adding toleration to pod"  "podName"="tf2-keras-cifar10-inceptionv3-elastic-20210723-042602-worker-1" "scheduler"="default" "toleration"={"key":"celeste/hostname","operator":"Equal","value":"gpu4","effect":"NoExecute"}
I0723 16:27:53.947973    7682 placement_manager.go:147]  "msg"="Adding toleration to pod"  "podName"="tf2-keras-cifar10-inceptionv3-elastic-20210723-042602-worker-2" "scheduler"="default" "toleration"={"key":"celeste/hostname","operator":"Equal","value":"gpu4","effect":"NoExecute"}
I0723 16:27:54.148301    7682 placement_manager.go:147]  "msg"="Adding toleration to pod"  "podName"="tf2-keras-cifar10-vgg16-elastic-20210723-042632-worker-0" "scheduler"="default" "toleration"={"key":"celeste/hostname","operator":"Equal","value":"gpu3","effect":"NoExecute"}
I0723 16:27:54.758454    7682 placement_manager.go:147]  "msg"="Adding toleration to pod"  "podName"="tf2-keras-cifar10-inceptionv3-elastic-20210723-042602-launcher" "scheduler"="default" "toleration"={"key":"celeste/hostname","operator":"Exists","effect":"NoExecute"}
I0723 16:27:55.158288    7682 placement_manager.go:147]  "msg"="Adding toleration to pod"  "podName"="tf2-keras-cifar10-vgg16-elastic-20210723-042632-worker-1" "scheduler"="default" "toleration"={"key":"celeste/hostname","operator":"Equal","value":"gpu3","effect":"NoExecute"}
I0723 16:27:55.558270    7682 placement_manager.go:147]  "msg"="Adding toleration to pod"  "podName"="tf2-keras-cifar10-vgg16-elastic-20210723-042632-worker-2" "scheduler"="default" "toleration"={"key":"celeste/hostname","operator":"Equal","value":"gpu3","effect":"NoExecute"}
I0723 16:27:55.959102    7682 placement_manager.go:147]  "msg"="Adding toleration to pod"  "podName"="tf2-keras-cifar10-vgg16-elastic-20210723-042632-launcher" "scheduler"="default" "toleration"={"key":"celeste/hostname","operator":"Exists","effect":"NoExecute"}
I0723 16:27:56.362548    7682 placement_manager.go:147]  "msg"="Adding toleration to pod"  "podName"="tf2-keras-cifar10-vgg16-elastic-20210723-042659-worker-0" "scheduler"="default" "toleration"={"key":"celeste/hostname","operator":"Equal","value":"gpu5","effect":"NoExecute"}
I0723 16:27:56.761281    7682 placement_manager.go:147]  "msg"="Adding toleration to pod"  "podName"="tf2-keras-cifar10-vgg16-elastic-20210723-042659-worker-1" "scheduler"="default" "toleration"={"key":"celeste/hostname","operator":"Equal","value":"gpu5","effect":"NoExecute"}
I0723 16:27:57.345792    7682 placement_manager.go:147]  "msg"="Adding toleration to pod"  "podName"="tf2-keras-cifar10-vgg16-elastic-20210723-042659-worker-2" "scheduler"="default" "toleration"={"key":"celeste/hostname","operator":"Equal","value":"gpu5","effect":"NoExecute"}
I0723 16:27:57.747208    7682 placement_manager.go:147]  "msg"="Adding toleration to pod"  "podName"="tf2-keras-cifar10-vgg16-elastic-20210723-042659-launcher" "scheduler"="default" "toleration"={"key":"celeste/hostname","operator":"Exists","effect":"NoExecute"}
I0723 16:28:24.991037    7682 placement_manager.go:147]  "msg"="Adding toleration to pod"  "podName"="tf2-keras-cifar10-inceptionv3-elastic-20210723-042602-worker-2" "scheduler"="default" "toleration"={"key":"celeste/hostname","operator":"Equal","value":"gpu4","effect":"NoExecute"}
I0723 16:28:34.685918    7682 jobmaster.go:155]  "msg"="Training job created"  "job"="tf2-keras-transformer-elastic-20210723-042834"
I0723 16:28:34.686066    7682 scheduler.go:135]  "msg"="Received resched event, may be blocked because of rate limit"  "blockedUntil"="2021-07-23T16:29:50.369917759+08:00" "lastResched"="2021-07-23T16:27:50.369917759+08:00" "received"="2021-07-23T16:28:34.685410488+08:00" "scheduler"="default"
I0723 16:29:05.573405    7682 placement_manager.go:147]  "msg"="Adding toleration to pod"  "podName"="tf2-keras-cifar10-inceptionv3-elastic-20210723-042602-worker-2" "scheduler"="default" "toleration"={"key":"celeste/hostname","operator":"Equal","value":"gpu4","effect":"NoExecute"}
I0723 16:29:50.370010    7682 scheduler.go:159]  "msg"="Started resched"  "scheduler"="default"
I0723 16:29:50.370117    7682 scheduler.go:193]  "msg"="Updating all jobs info"  "scheduler"="default"
I0723 16:29:50.377003    7682 afsl.go:65]  "msg"="Finished scheduling"  "algorithm"="AFS-L" "freeGpu"=0 "result"={"tf2-keras-cifar10-inceptionv3-elastic-20210723-042550":1,"tf2-keras-cifar10-inceptionv3-elastic-20210723-042602":2,"tf2-keras-cifar10-resnet50-elastic-20210723-042557":2,"tf2-keras-cifar10-vgg16-elastic-20210723-042632":2,"tf2-keras-cifar10-vgg16-elastic-20210723-042659":3,"tf2-keras-transformer-elastic-20210723-042834":2} "scheduler"="default"
I0723 16:29:50.377370    7682 scheduler.go:384]  "msg"="Trying to delete multiple training jobs"  "jobs"=[] "scheduler"="default"
I0723 16:29:50.377688    7682 scheduler.go:342]  "msg"="Trying to scale multiple training jobs"  "jobs"=["tf2-keras-cifar10-inceptionv3-elastic-20210723-042602","tf2-keras-cifar10-vgg16-elastic-20210723-042632"] "scheduler"="default"
I0723 16:29:50.417295    7682 scheduler.go:292]  "msg"="Trying to start multiple training jobs"  "jobs"=["tf2-keras-transformer-elastic-20210723-042834"] "scheduler"="default"
I0723 16:29:50.427635    7682 scheduler.go:342]  "msg"="Trying to scale multiple training jobs"  "jobs"=[] "scheduler"="default"
I0723 16:29:50.430872    7682 placement_manager.go:166]  "msg"="Started job placements adjustment"  "scheduler"="default"
I0723 16:29:50.430968    7682 placement_manager.go:192]  "msg"="Releasing slots"  "jobs"={"tf2-keras-cifar10-inceptionv3-elastic-20210723-042550":{},"tf2-keras-cifar10-inceptionv3-elastic-20210723-042602":{},"tf2-keras-cifar10-resnet50-elastic-20210723-042557":{},"tf2-keras-cifar10-vgg16-elastic-20210723-042632":{},"tf2-keras-cifar10-vgg16-elastic-20210723-042659":{}} "nodes"={"gpu3":{},"gpu4":{},"gpu5":{}} "scheduler"="default"
I0723 16:29:50.431053    7682 placement_manager.go:250]  "msg"="Released slots"  "jobs"={"tf2-keras-cifar10-inceptionv3-elastic-20210723-042550":{},"tf2-keras-cifar10-inceptionv3-elastic-20210723-042602":{},"tf2-keras-cifar10-resnet50-elastic-20210723-042557":{},"tf2-keras-cifar10-vgg16-elastic-20210723-042632":{},"tf2-keras-cifar10-vgg16-elastic-20210723-042659":{}} "nodes"={"gpu3":{},"gpu4":{},"gpu5":{}} "scheduler"="default"
I0723 16:29:50.431515    7682 placement_manager.go:305]  "msg"="Found best-fit"  "crossNode"=0 "nodes"=[{},{},{}] "requests"=[{},{},{},{},{},{},{},{},{},{},{},{}] "scheduler"="default"
I0723 16:29:50.431909    7682 placement_manager.go:339]  "msg"="nodeStates updated"  "new"={"gpu3":{},"gpu4":{},"gpu5":{}} "old"={"gpu3":{},"gpu4":{},"gpu5":{}} "scheduler"="default" "score"=7
I0723 16:29:50.432320    7682 placement_manager.go:387]  "msg"="jobStates updated"  "new"={"tf2-keras-cifar10-inceptionv3-elastic-20210723-042550":{},"tf2-keras-cifar10-inceptionv3-elastic-20210723-042602":{},"tf2-keras-cifar10-resnet50-elastic-20210723-042557":{},"tf2-keras-cifar10-vgg16-elastic-20210723-042632":{},"tf2-keras-cifar10-vgg16-elastic-20210723-042659":{},"tf2-keras-transformer-elastic-20210723-042834":{}} "old"={"tf2-keras-cifar10-inceptionv3-elastic-20210723-042550":{},"tf2-keras-cifar10-inceptionv3-elastic-20210723-042602":{},"tf2-keras-cifar10-resnet50-elastic-20210723-042557":{},"tf2-keras-cifar10-vgg16-elastic-20210723-042632":{},"tf2-keras-cifar10-vgg16-elastic-20210723-042659":{}} "scheduler"="default"
I0723 16:29:50.432727    7682 placement_manager.go:434]  "msg"="podNodeName updated"  "launchersToDelete"=2 "new"={"tf2-keras-cifar10-inceptionv3-elastic-20210723-042550-worker-0":"gpu5","tf2-keras-cifar10-inceptionv3-elastic-20210723-042602-worker-0":"gpu3","tf2-keras-cifar10-inceptionv3-elastic-20210723-042602-worker-1":"gpu3","tf2-keras-cifar10-resnet50-elastic-20210723-042557-worker-0":"gpu4","tf2-keras-cifar10-resnet50-elastic-20210723-042557-worker-1":"gpu4","tf2-keras-cifar10-vgg16-elastic-20210723-042632-worker-0":"gpu3","tf2-keras-cifar10-vgg16-elastic-20210723-042632-worker-1":"gpu3","tf2-keras-cifar10-vgg16-elastic-20210723-042659-worker-0":"gpu5","tf2-keras-cifar10-vgg16-elastic-20210723-042659-worker-1":"gpu5","tf2-keras-cifar10-vgg16-elastic-20210723-042659-worker-2":"gpu5","tf2-keras-transformer-elastic-20210723-042834-worker-0":"gpu4","tf2-keras-transformer-elastic-20210723-042834-worker-1":"gpu4"} "old"={"tf2-keras-cifar10-inceptionv3-elastic-20210723-042550-worker-0":"gpu3","tf2-keras-cifar10-inceptionv3-elastic-20210723-042602-worker-0":"gpu4","tf2-keras-cifar10-inceptionv3-elastic-20210723-042602-worker-1":"gpu4","tf2-keras-cifar10-inceptionv3-elastic-20210723-042602-worker-2":"gpu4","tf2-keras-cifar10-resnet50-elastic-20210723-042557-worker-0":"gpu4","tf2-keras-cifar10-resnet50-elastic-20210723-042557-worker-1":"gpu4","tf2-keras-cifar10-resnet50-elastic-20210723-042557-worker-2":"gpu5","tf2-keras-cifar10-vgg16-elastic-20210723-042632-worker-0":"gpu3","tf2-keras-cifar10-vgg16-elastic-20210723-042632-worker-1":"gpu3","tf2-keras-cifar10-vgg16-elastic-20210723-042632-worker-2":"gpu3","tf2-keras-cifar10-vgg16-elastic-20210723-042659-worker-0":"gpu5","tf2-keras-cifar10-vgg16-elastic-20210723-042659-worker-1":"gpu5","tf2-keras-cifar10-vgg16-elastic-20210723-042659-worker-2":"gpu5"} "scheduler"="default" "workersToDelete"=3
I0723 16:29:50.433232    7682 placement_manager.go:451]  "msg"="Deleting pod that need migration"  "podName"="tf2-keras-cifar10-inceptionv3-elastic-20210723-042550-worker-0" "scheduler"="default"
I0723 16:29:50.437734    7682 placement_manager.go:451]  "msg"="Deleting pod that need migration"  "podName"="tf2-keras-cifar10-inceptionv3-elastic-20210723-042550-launcher" "scheduler"="default"
I0723 16:29:50.459224    7682 placement_manager.go:451]  "msg"="Deleting pod that need migration"  "podName"="tf2-keras-cifar10-inceptionv3-elastic-20210723-042602-worker-0" "scheduler"="default"
I0723 16:29:50.465139    7682 placement_manager.go:451]  "msg"="Deleting pod that need migration"  "podName"="tf2-keras-cifar10-inceptionv3-elastic-20210723-042602-worker-1" "scheduler"="default"
I0723 16:29:50.469517    7682 placement_manager.go:451]  "msg"="Deleting pod that need migration"  "podName"="tf2-keras-cifar10-inceptionv3-elastic-20210723-042602-launcher" "scheduler"="default"
I0723 16:29:50.475118    7682 placement_manager.go:183]  "msg"="Finished job placements adjustment"  "scheduler"="default"
I0723 16:29:50.475624    7682 scheduler.go:182]  "msg"="Finished resched"  "scheduler"="default"
I0723 16:29:51.814148    7682 placement_manager.go:147]  "msg"="Adding toleration to pod"  "podName"="tf2-keras-transformer-elastic-20210723-042834-worker-0" "scheduler"="default" "toleration"={"key":"celeste/hostname","operator":"Equal","value":"gpu4","effect":"NoExecute"}
I0723 16:29:52.412245    7682 placement_manager.go:147]  "msg"="Adding toleration to pod"  "podName"="tf2-keras-transformer-elastic-20210723-042834-worker-1" "scheduler"="default" "toleration"={"key":"celeste/hostname","operator":"Equal","value":"gpu4","effect":"NoExecute"}
I0723 16:29:52.812200    7682 placement_manager.go:147]  "msg"="Adding toleration to pod"  "podName"="tf2-keras-transformer-elastic-20210723-042834-launcher" "scheduler"="default" "toleration"={"key":"celeste/hostname","operator":"Exists","effect":"NoExecute"}
I0723 16:30:03.875354    7682 placement_manager.go:147]  "msg"="Adding toleration to pod"  "podName"="tf2-keras-cifar10-inceptionv3-elastic-20210723-042550-launcher" "scheduler"="default" "toleration"={"key":"celeste/hostname","operator":"Exists","effect":"NoExecute"}
I0723 16:30:03.913419    7682 placement_manager.go:147]  "msg"="Adding toleration to pod"  "podName"="tf2-keras-cifar10-inceptionv3-elastic-20210723-042550-worker-0" "scheduler"="default" "toleration"={"key":"celeste/hostname","operator":"Equal","value":"gpu5","effect":"NoExecute"}
I0723 16:30:04.587213    7682 placement_manager.go:147]  "msg"="Adding toleration to pod"  "podName"="tf2-keras-cifar10-inceptionv3-elastic-20210723-042602-worker-1" "scheduler"="default" "toleration"={"key":"celeste/hostname","operator":"Equal","value":"gpu3","effect":"NoExecute"}
I0723 16:30:04.802945    7682 placement_manager.go:147]  "msg"="Adding toleration to pod"  "podName"="tf2-keras-cifar10-inceptionv3-elastic-20210723-042602-launcher" "scheduler"="default" "toleration"={"key":"celeste/hostname","operator":"Exists","effect":"NoExecute"}
I0723 16:30:05.198764    7682 placement_manager.go:147]  "msg"="Adding toleration to pod"  "podName"="tf2-keras-cifar10-inceptionv3-elastic-20210723-042602-worker-0" "scheduler"="default" "toleration"={"key":"celeste/hostname","operator":"Equal","value":"gpu3","effect":"NoExecute"}
I0723 16:39:17.797388    7682 jobmaster.go:155]  "msg"="Training job created"  "job"="tf2-keras-transformer-elastic-20210723-043917"
I0723 16:39:17.797470    7682 scheduler.go:135]  "msg"="Received resched event, may be blocked because of rate limit"  "blockedUntil"="2021-07-23T16:31:50.476039664+08:00" "lastResched"="2021-07-23T16:29:50.476039664+08:00" "received"="2021-07-23T16:39:17.796677009+08:00" "scheduler"="default"
I0723 16:39:17.797992    7682 scheduler.go:159]  "msg"="Started resched"  "scheduler"="default"
I0723 16:39:17.798084    7682 scheduler.go:193]  "msg"="Updating all jobs info"  "scheduler"="default"
I0723 16:39:17.806167    7682 afsl.go:65]  "msg"="Finished scheduling"  "algorithm"="AFS-L" "freeGpu"=0 "result"={"tf2-keras-cifar10-inceptionv3-elastic-20210723-042550":1,"tf2-keras-cifar10-inceptionv3-elastic-20210723-042602":1,"tf2-keras-cifar10-resnet50-elastic-20210723-042557":2,"tf2-keras-cifar10-vgg16-elastic-20210723-042632":2,"tf2-keras-cifar10-vgg16-elastic-20210723-042659":2,"tf2-keras-transformer-elastic-20210723-042834":2,"tf2-keras-transformer-elastic-20210723-043917":2} "scheduler"="default"
I0723 16:39:17.806507    7682 scheduler.go:384]  "msg"="Trying to delete multiple training jobs"  "jobs"=[] "scheduler"="default"
I0723 16:39:17.806774    7682 scheduler.go:342]  "msg"="Trying to scale multiple training jobs"  "jobs"=["tf2-keras-cifar10-vgg16-elastic-20210723-042659","tf2-keras-cifar10-inceptionv3-elastic-20210723-042602"] "scheduler"="default"
I0723 16:39:17.834477    7682 scheduler.go:292]  "msg"="Trying to start multiple training jobs"  "jobs"=["tf2-keras-transformer-elastic-20210723-043917"] "scheduler"="default"
I0723 16:39:17.842697    7682 scheduler.go:342]  "msg"="Trying to scale multiple training jobs"  "jobs"=[] "scheduler"="default"
I0723 16:39:17.845461    7682 placement_manager.go:166]  "msg"="Started job placements adjustment"  "scheduler"="default"
I0723 16:39:17.845526    7682 placement_manager.go:192]  "msg"="Releasing slots"  "jobs"={"tf2-keras-cifar10-inceptionv3-elastic-20210723-042550":{},"tf2-keras-cifar10-inceptionv3-elastic-20210723-042602":{},"tf2-keras-cifar10-resnet50-elastic-20210723-042557":{},"tf2-keras-cifar10-vgg16-elastic-20210723-042632":{},"tf2-keras-cifar10-vgg16-elastic-20210723-042659":{},"tf2-keras-transformer-elastic-20210723-042834":{}} "nodes"={"gpu3":{},"gpu4":{},"gpu5":{}} "scheduler"="default"
I0723 16:39:17.845582    7682 placement_manager.go:250]  "msg"="Released slots"  "jobs"={"tf2-keras-cifar10-inceptionv3-elastic-20210723-042550":{},"tf2-keras-cifar10-inceptionv3-elastic-20210723-042602":{},"tf2-keras-cifar10-resnet50-elastic-20210723-042557":{},"tf2-keras-cifar10-vgg16-elastic-20210723-042632":{},"tf2-keras-cifar10-vgg16-elastic-20210723-042659":{},"tf2-keras-transformer-elastic-20210723-042834":{}} "nodes"={"gpu3":{},"gpu4":{},"gpu5":{}} "scheduler"="default"
I0723 16:39:17.845896    7682 placement_manager.go:305]  "msg"="Found best-fit"  "crossNode"=0 "nodes"=[{},{},{}] "requests"=[{},{},{},{},{},{},{},{},{},{},{},{},{},{}] "scheduler"="default"
I0723 16:39:17.846202    7682 placement_manager.go:339]  "msg"="nodeStates updated"  "new"={"gpu3":{},"gpu4":{},"gpu5":{}} "old"={"gpu3":{},"gpu4":{},"gpu5":{}} "scheduler"="default" "score"=5
I0723 16:39:17.846512    7682 placement_manager.go:387]  "msg"="jobStates updated"  "new"={"tf2-keras-cifar10-inceptionv3-elastic-20210723-042550":{},"tf2-keras-cifar10-inceptionv3-elastic-20210723-042602":{},"tf2-keras-cifar10-resnet50-elastic-20210723-042557":{},"tf2-keras-cifar10-vgg16-elastic-20210723-042632":{},"tf2-keras-cifar10-vgg16-elastic-20210723-042659":{},"tf2-keras-transformer-elastic-20210723-042834":{},"tf2-keras-transformer-elastic-20210723-043917":{}} "old"={"tf2-keras-cifar10-inceptionv3-elastic-20210723-042550":{},"tf2-keras-cifar10-inceptionv3-elastic-20210723-042602":{},"tf2-keras-cifar10-resnet50-elastic-20210723-042557":{},"tf2-keras-cifar10-vgg16-elastic-20210723-042632":{},"tf2-keras-cifar10-vgg16-elastic-20210723-042659":{},"tf2-keras-transformer-elastic-20210723-042834":{}} "scheduler"="default"
I0723 16:39:17.846983    7682 placement_manager.go:434]  "msg"="podNodeName updated"  "launchersToDelete"=3 "new"={"tf2-keras-cifar10-inceptionv3-elastic-20210723-042550-worker-0":"gpu3","tf2-keras-cifar10-inceptionv3-elastic-20210723-042602-worker-0":"gpu3","tf2-keras-cifar10-resnet50-elastic-20210723-042557-worker-0":"gpu3","tf2-keras-cifar10-resnet50-elastic-20210723-042557-worker-1":"gpu3","tf2-keras-cifar10-vgg16-elastic-20210723-042632-worker-0":"gpu5","tf2-keras-cifar10-vgg16-elastic-20210723-042632-worker-1":"gpu5","tf2-keras-cifar10-vgg16-elastic-20210723-042659-worker-0":"gpu5","tf2-keras-cifar10-vgg16-elastic-20210723-042659-worker-1":"gpu5","tf2-keras-transformer-elastic-20210723-042834-worker-0":"gpu4","tf2-keras-transformer-elastic-20210723-042834-worker-1":"gpu4","tf2-keras-transformer-elastic-20210723-043917-worker-0":"gpu4","tf2-keras-transformer-elastic-20210723-043917-worker-1":"gpu4"} "old"={"tf2-keras-cifar10-inceptionv3-elastic-20210723-042550-worker-0":"gpu5","tf2-keras-cifar10-inceptionv3-elastic-20210723-042602-worker-0":"gpu3","tf2-keras-cifar10-inceptionv3-elastic-20210723-042602-worker-1":"gpu3","tf2-keras-cifar10-resnet50-elastic-20210723-042557-worker-0":"gpu4","tf2-keras-cifar10-resnet50-elastic-20210723-042557-worker-1":"gpu4","tf2-keras-cifar10-vgg16-elastic-20210723-042632-worker-0":"gpu3","tf2-keras-cifar10-vgg16-elastic-20210723-042632-worker-1":"gpu3","tf2-keras-cifar10-vgg16-elastic-20210723-042659-worker-0":"gpu5","tf2-keras-cifar10-vgg16-elastic-20210723-042659-worker-1":"gpu5","tf2-keras-cifar10-vgg16-elastic-20210723-042659-worker-2":"gpu5","tf2-keras-transformer-elastic-20210723-042834-worker-0":"gpu4","tf2-keras-transformer-elastic-20210723-042834-worker-1":"gpu4"} "scheduler"="default" "workersToDelete"=5
I0723 16:39:17.847395    7682 placement_manager.go:451]  "msg"="Deleting pod that need migration"  "podName"="tf2-keras-cifar10-vgg16-elastic-20210723-042632-worker-0" "scheduler"="default"
I0723 16:39:17.852180    7682 placement_manager.go:451]  "msg"="Deleting pod that need migration"  "podName"="tf2-keras-cifar10-vgg16-elastic-20210723-042632-worker-1" "scheduler"="default"
I0723 16:39:17.856089    7682 placement_manager.go:451]  "msg"="Deleting pod that need migration"  "podName"="tf2-keras-cifar10-vgg16-elastic-20210723-042632-launcher" "scheduler"="default"
I0723 16:39:17.861641    7682 placement_manager.go:451]  "msg"="Deleting pod that need migration"  "podName"="tf2-keras-cifar10-resnet50-elastic-20210723-042557-worker-0" "scheduler"="default"
I0723 16:39:17.870237    7682 placement_manager.go:451]  "msg"="Deleting pod that need migration"  "podName"="tf2-keras-cifar10-resnet50-elastic-20210723-042557-worker-1" "scheduler"="default"
I0723 16:39:17.885089    7682 placement_manager.go:451]  "msg"="Deleting pod that need migration"  "podName"="tf2-keras-cifar10-resnet50-elastic-20210723-042557-launcher" "scheduler"="default"
I0723 16:39:17.890276    7682 placement_manager.go:451]  "msg"="Deleting pod that need migration"  "podName"="tf2-keras-cifar10-inceptionv3-elastic-20210723-042550-worker-0" "scheduler"="default"
I0723 16:39:17.894487    7682 placement_manager.go:451]  "msg"="Deleting pod that need migration"  "podName"="tf2-keras-cifar10-inceptionv3-elastic-20210723-042550-launcher" "scheduler"="default"
I0723 16:39:17.898885    7682 placement_manager.go:183]  "msg"="Finished job placements adjustment"  "scheduler"="default"
I0723 16:39:17.899220    7682 scheduler.go:182]  "msg"="Finished resched"  "scheduler"="default"
I0723 16:39:19.634728    7682 placement_manager.go:147]  "msg"="Adding toleration to pod"  "podName"="tf2-keras-transformer-elastic-20210723-043917-worker-0" "scheduler"="default" "toleration"={"key":"celeste/hostname","operator":"Equal","value":"gpu4","effect":"NoExecute"}
I0723 16:39:20.036153    7682 placement_manager.go:147]  "msg"="Adding toleration to pod"  "podName"="tf2-keras-transformer-elastic-20210723-043917-worker-1" "scheduler"="default" "toleration"={"key":"celeste/hostname","operator":"Equal","value":"gpu4","effect":"NoExecute"}
I0723 16:39:20.437082    7682 placement_manager.go:147]  "msg"="Adding toleration to pod"  "podName"="tf2-keras-transformer-elastic-20210723-043917-launcher" "scheduler"="default" "toleration"={"key":"celeste/hostname","operator":"Exists","effect":"NoExecute"}
I0723 16:39:29.755830    7682 placement_manager.go:147]  "msg"="Adding toleration to pod"  "podName"="tf2-keras-cifar10-vgg16-elastic-20210723-042632-launcher" "scheduler"="default" "toleration"={"key":"celeste/hostname","operator":"Exists","effect":"NoExecute"}
I0723 16:39:29.804642    7682 placement_manager.go:147]  "msg"="Adding toleration to pod"  "podName"="tf2-keras-cifar10-inceptionv3-elastic-20210723-042550-worker-0" "scheduler"="default" "toleration"={"key":"celeste/hostname","operator":"Equal","value":"gpu3","effect":"NoExecute"}
I0723 16:39:34.454948    7682 placement_manager.go:147]  "msg"="Adding toleration to pod"  "podName"="tf2-keras-cifar10-vgg16-elastic-20210723-042632-worker-0" "scheduler"="default" "toleration"={"key":"celeste/hostname","operator":"Equal","value":"gpu5","effect":"NoExecute"}
I0723 16:39:34.853007    7682 placement_manager.go:147]  "msg"="Adding toleration to pod"  "podName"="tf2-keras-cifar10-vgg16-elastic-20210723-042632-worker-1" "scheduler"="default" "toleration"={"key":"celeste/hostname","operator":"Equal","value":"gpu5","effect":"NoExecute"}
I0723 16:39:35.365596    7682 placement_manager.go:147]  "msg"="Adding toleration to pod"  "podName"="tf2-keras-cifar10-resnet50-elastic-20210723-042557-worker-0" "scheduler"="default" "toleration"={"key":"celeste/hostname","operator":"Equal","value":"gpu3","effect":"NoExecute"}
I0723 16:39:36.369011    7682 placement_manager.go:147]  "msg"="Adding toleration to pod"  "podName"="tf2-keras-cifar10-resnet50-elastic-20210723-042557-launcher" "scheduler"="default" "toleration"={"key":"celeste/hostname","operator":"Exists","effect":"NoExecute"}
I0723 16:39:37.168348    7682 placement_manager.go:147]  "msg"="Adding toleration to pod"  "podName"="tf2-keras-cifar10-resnet50-elastic-20210723-042557-worker-1" "scheduler"="default" "toleration"={"key":"celeste/hostname","operator":"Equal","value":"gpu3","effect":"NoExecute"}
I0723 16:39:37.965261    7682 placement_manager.go:147]  "msg"="Adding toleration to pod"  "podName"="tf2-keras-cifar10-inceptionv3-elastic-20210723-042550-launcher" "scheduler"="default" "toleration"={"key":"celeste/hostname","operator":"Exists","effect":"NoExecute"}
I0723 16:41:12.346633    7682 scheduler.go:474]  "msg"="Training job completed"  "elaspedTotalSeconds"=876.087683056 "gpuTotalSeconds"=1720.048344283 "job"="tf2-keras-cifar10-vgg16-elastic-20210723-042632" "ranTotalSeconds"=800.022647149 "scheduler"="default" "waitedTotalSeconds"=76.065035907
I0723 16:41:12.346752    7682 scheduler.go:135]  "msg"="Received resched event, may be blocked because of rate limit"  "blockedUntil"="2021-07-23T16:41:17.899710978+08:00" "lastResched"="2021-07-23T16:39:17.899710978+08:00" "received"="2021-07-23T16:41:12.346658632+08:00" "scheduler"="default"
I0723 16:41:17.899851    7682 scheduler.go:159]  "msg"="Started resched"  "scheduler"="default"
I0723 16:41:17.899975    7682 scheduler.go:193]  "msg"="Updating all jobs info"  "scheduler"="default"
I0723 16:41:17.907526    7682 afsl.go:65]  "msg"="Finished scheduling"  "algorithm"="AFS-L" "freeGpu"=0 "result"={"tf2-keras-cifar10-inceptionv3-elastic-20210723-042550":1,"tf2-keras-cifar10-inceptionv3-elastic-20210723-042602":2,"tf2-keras-cifar10-resnet50-elastic-20210723-042557":3,"tf2-keras-cifar10-vgg16-elastic-20210723-042659":2,"tf2-keras-transformer-elastic-20210723-042834":2,"tf2-keras-transformer-elastic-20210723-043917":2} "scheduler"="default"
I0723 16:41:17.907852    7682 scheduler.go:384]  "msg"="Trying to delete multiple training jobs"  "jobs"=[] "scheduler"="default"
I0723 16:41:17.908070    7682 scheduler.go:342]  "msg"="Trying to scale multiple training jobs"  "jobs"=[] "scheduler"="default"
I0723 16:41:17.908332    7682 scheduler.go:292]  "msg"="Trying to start multiple training jobs"  "jobs"=[] "scheduler"="default"
I0723 16:41:17.908563    7682 scheduler.go:342]  "msg"="Trying to scale multiple training jobs"  "jobs"=["tf2-keras-cifar10-resnet50-elastic-20210723-042557","tf2-keras-cifar10-inceptionv3-elastic-20210723-042602"] "scheduler"="default"
I0723 16:41:17.939574    7682 placement_manager.go:166]  "msg"="Started job placements adjustment"  "scheduler"="default"
I0723 16:41:17.939642    7682 placement_manager.go:192]  "msg"="Releasing slots"  "jobs"={"tf2-keras-cifar10-inceptionv3-elastic-20210723-042550":{},"tf2-keras-cifar10-inceptionv3-elastic-20210723-042602":{},"tf2-keras-cifar10-resnet50-elastic-20210723-042557":{},"tf2-keras-cifar10-vgg16-elastic-20210723-042632":{},"tf2-keras-cifar10-vgg16-elastic-20210723-042659":{},"tf2-keras-transformer-elastic-20210723-042834":{},"tf2-keras-transformer-elastic-20210723-043917":{}} "nodes"={"gpu3":{},"gpu4":{},"gpu5":{}} "scheduler"="default"
I0723 16:41:17.939694    7682 placement_manager.go:250]  "msg"="Released slots"  "jobs"={"tf2-keras-cifar10-inceptionv3-elastic-20210723-042550":{},"tf2-keras-cifar10-inceptionv3-elastic-20210723-042602":{},"tf2-keras-cifar10-resnet50-elastic-20210723-042557":{},"tf2-keras-cifar10-vgg16-elastic-20210723-042632":{},"tf2-keras-cifar10-vgg16-elastic-20210723-042659":{},"tf2-keras-transformer-elastic-20210723-042834":{},"tf2-keras-transformer-elastic-20210723-043917":{}} "nodes"={"gpu3":{},"gpu4":{},"gpu5":{}} "scheduler"="default"
I0723 16:41:17.940069    7682 placement_manager.go:305]  "msg"="Found best-fit"  "crossNode"=0 "nodes"=[{},{},{}] "requests"=[{},{},{},{},{},{},{},{},{},{},{},{}] "scheduler"="default"
I0723 16:41:17.940403    7682 placement_manager.go:339]  "msg"="nodeStates updated"  "new"={"gpu3":{},"gpu4":{},"gpu5":{}} "old"={"gpu3":{},"gpu4":{},"gpu5":{}} "scheduler"="default" "score"=9
I0723 16:41:17.940704    7682 placement_manager.go:387]  "msg"="jobStates updated"  "new"={"tf2-keras-cifar10-inceptionv3-elastic-20210723-042550":{},"tf2-keras-cifar10-inceptionv3-elastic-20210723-042602":{},"tf2-keras-cifar10-resnet50-elastic-20210723-042557":{},"tf2-keras-cifar10-vgg16-elastic-20210723-042659":{},"tf2-keras-transformer-elastic-20210723-042834":{},"tf2-keras-transformer-elastic-20210723-043917":{}} "old"={"tf2-keras-cifar10-inceptionv3-elastic-20210723-042550":{},"tf2-keras-cifar10-inceptionv3-elastic-20210723-042602":{},"tf2-keras-cifar10-resnet50-elastic-20210723-042557":{},"tf2-keras-cifar10-vgg16-elastic-20210723-042632":{},"tf2-keras-cifar10-vgg16-elastic-20210723-042659":{},"tf2-keras-transformer-elastic-20210723-042834":{},"tf2-keras-transformer-elastic-20210723-043917":{}} "scheduler"="default"
I0723 16:41:17.941098    7682 placement_manager.go:434]  "msg"="podNodeName updated"  "launchersToDelete"=0 "new"={"tf2-keras-cifar10-inceptionv3-elastic-20210723-042550-worker-0":"gpu3","tf2-keras-cifar10-inceptionv3-elastic-20210723-042602-worker-0":"gpu5","tf2-keras-cifar10-inceptionv3-elastic-20210723-042602-worker-1":"gpu5","tf2-keras-cifar10-resnet50-elastic-20210723-042557-worker-0":"gpu3","tf2-keras-cifar10-resnet50-elastic-20210723-042557-worker-1":"gpu3","tf2-keras-cifar10-resnet50-elastic-20210723-042557-worker-2":"gpu3","tf2-keras-cifar10-vgg16-elastic-20210723-042659-worker-0":"gpu5","tf2-keras-cifar10-vgg16-elastic-20210723-042659-worker-1":"gpu5","tf2-keras-transformer-elastic-20210723-042834-worker-0":"gpu4","tf2-keras-transformer-elastic-20210723-042834-worker-1":"gpu4","tf2-keras-transformer-elastic-20210723-043917-worker-0":"gpu4","tf2-keras-transformer-elastic-20210723-043917-worker-1":"gpu4"} "old"={"tf2-keras-cifar10-inceptionv3-elastic-20210723-042550-worker-0":"gpu3","tf2-keras-cifar10-inceptionv3-elastic-20210723-042602-worker-0":"gpu3","tf2-keras-cifar10-resnet50-elastic-20210723-042557-worker-0":"gpu3","tf2-keras-cifar10-resnet50-elastic-20210723-042557-worker-1":"gpu3","tf2-keras-cifar10-vgg16-elastic-20210723-042632-worker-0":"gpu5","tf2-keras-cifar10-vgg16-elastic-20210723-042632-worker-1":"gpu5","tf2-keras-cifar10-vgg16-elastic-20210723-042659-worker-0":"gpu5","tf2-keras-cifar10-vgg16-elastic-20210723-042659-worker-1":"gpu5","tf2-keras-transformer-elastic-20210723-042834-worker-0":"gpu4","tf2-keras-transformer-elastic-20210723-042834-worker-1":"gpu4","tf2-keras-transformer-elastic-20210723-043917-worker-0":"gpu4","tf2-keras-transformer-elastic-20210723-043917-worker-1":"gpu4"} "scheduler"="default" "workersToDelete"=1
I0723 16:41:17.941389    7682 placement_manager.go:451]  "msg"="Deleting pod that need migration"  "podName"="tf2-keras-cifar10-inceptionv3-elastic-20210723-042602-worker-0" "scheduler"="default"
I0723 16:41:17.947926    7682 placement_manager.go:183]  "msg"="Finished job placements adjustment"  "scheduler"="default"
I0723 16:41:17.948138    7682 scheduler.go:182]  "msg"="Finished resched"  "scheduler"="default"
I0723 16:41:17.967585    7682 placement_manager.go:147]  "msg"="Adding toleration to pod"  "podName"="tf2-keras-cifar10-resnet50-elastic-20210723-042557-worker-2" "scheduler"="default" "toleration"={"key":"celeste/hostname","operator":"Equal","value":"gpu3","effect":"NoExecute"}
I0723 16:41:17.998555    7682 placement_manager.go:147]  "msg"="Adding toleration to pod"  "podName"="tf2-keras-cifar10-inceptionv3-elastic-20210723-042602-worker-1" "scheduler"="default" "toleration"={"key":"celeste/hostname","operator":"Equal","value":"gpu5","effect":"NoExecute"}
I0723 16:41:34.405352    7682 placement_manager.go:147]  "msg"="Adding toleration to pod"  "podName"="tf2-keras-cifar10-inceptionv3-elastic-20210723-042602-worker-0" "scheduler"="default" "toleration"={"key":"celeste/hostname","operator":"Equal","value":"gpu5","effect":"NoExecute"}
I0723 16:42:37.911526    7682 jobmaster.go:155]  "msg"="Training job created"  "job"="tf2-keras-cifar10-inceptionv3-elastic-20210723-044237"
I0723 16:42:37.911642    7682 scheduler.go:135]  "msg"="Received resched event, may be blocked because of rate limit"  "blockedUntil"="2021-07-23T16:43:17.948284487+08:00" "lastResched"="2021-07-23T16:41:17.948284487+08:00" "received"="2021-07-23T16:42:37.911026855+08:00" "scheduler"="default"
I0723 16:43:17.948352    7682 scheduler.go:159]  "msg"="Started resched"  "scheduler"="default"
I0723 16:43:17.948403    7682 scheduler.go:193]  "msg"="Updating all jobs info"  "scheduler"="default"
I0723 16:43:17.954935    7682 afsl.go:65]  "msg"="Finished scheduling"  "algorithm"="AFS-L" "freeGpu"=0 "result"={"tf2-keras-cifar10-inceptionv3-elastic-20210723-042550":1,"tf2-keras-cifar10-inceptionv3-elastic-20210723-042602":1,"tf2-keras-cifar10-inceptionv3-elastic-20210723-044237":1,"tf2-keras-cifar10-resnet50-elastic-20210723-042557":3,"tf2-keras-cifar10-vgg16-elastic-20210723-042659":2,"tf2-keras-transformer-elastic-20210723-042834":2,"tf2-keras-transformer-elastic-20210723-043917":2} "scheduler"="default"
I0723 16:43:17.955237    7682 scheduler.go:384]  "msg"="Trying to delete multiple training jobs"  "jobs"=[] "scheduler"="default"
I0723 16:43:17.955500    7682 scheduler.go:342]  "msg"="Trying to scale multiple training jobs"  "jobs"=["tf2-keras-cifar10-inceptionv3-elastic-20210723-042602"] "scheduler"="default"
I0723 16:43:17.972541    7682 scheduler.go:292]  "msg"="Trying to start multiple training jobs"  "jobs"=["tf2-keras-cifar10-inceptionv3-elastic-20210723-044237"] "scheduler"="default"
I0723 16:43:17.982578    7682 scheduler.go:342]  "msg"="Trying to scale multiple training jobs"  "jobs"=[] "scheduler"="default"
I0723 16:43:17.985897    7682 placement_manager.go:166]  "msg"="Started job placements adjustment"  "scheduler"="default"
I0723 16:43:17.985998    7682 placement_manager.go:192]  "msg"="Releasing slots"  "jobs"={"tf2-keras-cifar10-inceptionv3-elastic-20210723-042550":{},"tf2-keras-cifar10-inceptionv3-elastic-20210723-042602":{},"tf2-keras-cifar10-resnet50-elastic-20210723-042557":{},"tf2-keras-cifar10-vgg16-elastic-20210723-042659":{},"tf2-keras-transformer-elastic-20210723-042834":{},"tf2-keras-transformer-elastic-20210723-043917":{}} "nodes"={"gpu3":{},"gpu4":{},"gpu5":{}} "scheduler"="default"
I0723 16:43:17.986079    7682 placement_manager.go:250]  "msg"="Released slots"  "jobs"={"tf2-keras-cifar10-inceptionv3-elastic-20210723-042550":{},"tf2-keras-cifar10-inceptionv3-elastic-20210723-042602":{},"tf2-keras-cifar10-resnet50-elastic-20210723-042557":{},"tf2-keras-cifar10-vgg16-elastic-20210723-042659":{},"tf2-keras-transformer-elastic-20210723-042834":{},"tf2-keras-transformer-elastic-20210723-043917":{}} "nodes"={"gpu3":{},"gpu4":{},"gpu5":{}} "scheduler"="default"
I0723 16:43:17.986503    7682 placement_manager.go:305]  "msg"="Found best-fit"  "crossNode"=0 "nodes"=[{},{},{}] "requests"=[{},{},{},{},{},{},{},{},{},{},{},{},{},{}] "scheduler"="default"
I0723 16:43:17.986845    7682 placement_manager.go:339]  "msg"="nodeStates updated"  "new"={"gpu3":{},"gpu4":{},"gpu5":{}} "old"={"gpu3":{},"gpu4":{},"gpu5":{}} "scheduler"="default" "score"=7
I0723 16:43:17.987210    7682 placement_manager.go:387]  "msg"="jobStates updated"  "new"={"tf2-keras-cifar10-inceptionv3-elastic-20210723-042550":{},"tf2-keras-cifar10-inceptionv3-elastic-20210723-042602":{},"tf2-keras-cifar10-inceptionv3-elastic-20210723-044237":{},"tf2-keras-cifar10-resnet50-elastic-20210723-042557":{},"tf2-keras-cifar10-vgg16-elastic-20210723-042659":{},"tf2-keras-transformer-elastic-20210723-042834":{},"tf2-keras-transformer-elastic-20210723-043917":{}} "old"={"tf2-keras-cifar10-inceptionv3-elastic-20210723-042550":{},"tf2-keras-cifar10-inceptionv3-elastic-20210723-042602":{},"tf2-keras-cifar10-resnet50-elastic-20210723-042557":{},"tf2-keras-cifar10-vgg16-elastic-20210723-042659":{},"tf2-keras-transformer-elastic-20210723-042834":{},"tf2-keras-transformer-elastic-20210723-043917":{}} "scheduler"="default"
I0723 16:43:17.987786    7682 placement_manager.go:434]  "msg"="podNodeName updated"  "launchersToDelete"=3 "new"={"tf2-keras-cifar10-inceptionv3-elastic-20210723-042550-worker-0":"gpu4","tf2-keras-cifar10-inceptionv3-elastic-20210723-042602-worker-0":"gpu4","tf2-keras-cifar10-inceptionv3-elastic-20210723-044237-worker-0":"gpu3","tf2-keras-cifar10-resnet50-elastic-20210723-042557-worker-0":"gpu3","tf2-keras-cifar10-resnet50-elastic-20210723-042557-worker-1":"gpu3","tf2-keras-cifar10-resnet50-elastic-20210723-042557-worker-2":"gpu3","tf2-keras-cifar10-vgg16-elastic-20210723-042659-worker-0":"gpu5","tf2-keras-cifar10-vgg16-elastic-20210723-042659-worker-1":"gpu5","tf2-keras-transformer-elastic-20210723-042834-worker-0":"gpu4","tf2-keras-transformer-elastic-20210723-042834-worker-1":"gpu4","tf2-keras-transformer-elastic-20210723-043917-worker-0":"gpu5","tf2-keras-transformer-elastic-20210723-043917-worker-1":"gpu5"} "old"={"tf2-keras-cifar10-inceptionv3-elastic-20210723-042550-worker-0":"gpu3","tf2-keras-cifar10-inceptionv3-elastic-20210723-042602-worker-0":"gpu5","tf2-keras-cifar10-inceptionv3-elastic-20210723-042602-worker-1":"gpu5","tf2-keras-cifar10-resnet50-elastic-20210723-042557-worker-0":"gpu3","tf2-keras-cifar10-resnet50-elastic-20210723-042557-worker-1":"gpu3","tf2-keras-cifar10-resnet50-elastic-20210723-042557-worker-2":"gpu3","tf2-keras-cifar10-vgg16-elastic-20210723-042659-worker-0":"gpu5","tf2-keras-cifar10-vgg16-elastic-20210723-042659-worker-1":"gpu5","tf2-keras-transformer-elastic-20210723-042834-worker-0":"gpu4","tf2-keras-transformer-elastic-20210723-042834-worker-1":"gpu4","tf2-keras-transformer-elastic-20210723-043917-worker-0":"gpu4","tf2-keras-transformer-elastic-20210723-043917-worker-1":"gpu4"} "scheduler"="default" "workersToDelete"=4
I0723 16:43:17.988156    7682 placement_manager.go:451]  "msg"="Deleting pod that need migration"  "podName"="tf2-keras-cifar10-inceptionv3-elastic-20210723-042550-worker-0" "scheduler"="default"
I0723 16:43:17.998337    7682 placement_manager.go:451]  "msg"="Deleting pod that need migration"  "podName"="tf2-keras-cifar10-inceptionv3-elastic-20210723-042550-launcher" "scheduler"="default"
I0723 16:43:18.003552    7682 placement_manager.go:451]  "msg"="Deleting pod that need migration"  "podName"="tf2-keras-cifar10-inceptionv3-elastic-20210723-042602-worker-0" "scheduler"="default"
I0723 16:43:18.016488    7682 placement_manager.go:451]  "msg"="Deleting pod that need migration"  "podName"="tf2-keras-cifar10-inceptionv3-elastic-20210723-042602-launcher" "scheduler"="default"
I0723 16:43:18.021042    7682 placement_manager.go:451]  "msg"="Deleting pod that need migration"  "podName"="tf2-keras-transformer-elastic-20210723-043917-worker-0" "scheduler"="default"
I0723 16:43:18.026034    7682 placement_manager.go:451]  "msg"="Deleting pod that need migration"  "podName"="tf2-keras-transformer-elastic-20210723-043917-worker-1" "scheduler"="default"
I0723 16:43:18.029365    7682 placement_manager.go:451]  "msg"="Deleting pod that need migration"  "podName"="tf2-keras-transformer-elastic-20210723-043917-launcher" "scheduler"="default"
I0723 16:43:18.033019    7682 placement_manager.go:183]  "msg"="Finished job placements adjustment"  "scheduler"="default"
I0723 16:43:18.033223    7682 scheduler.go:182]  "msg"="Finished resched"  "scheduler"="default"
I0723 16:43:18.388329    7682 placement_manager.go:147]  "msg"="Adding toleration to pod"  "podName"="tf2-keras-cifar10-inceptionv3-elastic-20210723-044237-worker-0" "scheduler"="default" "toleration"={"key":"celeste/hostname","operator":"Equal","value":"gpu3","effect":"NoExecute"}
I0723 16:43:18.990110    7682 placement_manager.go:147]  "msg"="Adding toleration to pod"  "podName"="tf2-keras-cifar10-inceptionv3-elastic-20210723-044237-launcher" "scheduler"="default" "toleration"={"key":"celeste/hostname","operator":"Exists","effect":"NoExecute"}
I0723 16:43:25.038409    7682 placement_manager.go:147]  "msg"="Adding toleration to pod"  "podName"="tf2-keras-transformer-elastic-20210723-043917-launcher" "scheduler"="default" "toleration"={"key":"celeste/hostname","operator":"Exists","effect":"NoExecute"}
I0723 16:43:25.862964    7682 placement_manager.go:147]  "msg"="Adding toleration to pod"  "podName"="tf2-keras-cifar10-inceptionv3-elastic-20210723-042602-worker-0" "scheduler"="default" "toleration"={"key":"celeste/hostname","operator":"Equal","value":"gpu4","effect":"NoExecute"}
I0723 16:43:27.047622    7682 placement_manager.go:147]  "msg"="Adding toleration to pod"  "podName"="tf2-keras-cifar10-inceptionv3-elastic-20210723-042550-worker-0" "scheduler"="default" "toleration"={"key":"celeste/hostname","operator":"Equal","value":"gpu4","effect":"NoExecute"}
I0723 16:43:27.455303    7682 placement_manager.go:147]  "msg"="Adding toleration to pod"  "podName"="tf2-keras-cifar10-inceptionv3-elastic-20210723-042602-launcher" "scheduler"="default" "toleration"={"key":"celeste/hostname","operator":"Exists","effect":"NoExecute"}
I0723 16:43:27.844094    7682 placement_manager.go:147]  "msg"="Adding toleration to pod"  "podName"="tf2-keras-cifar10-inceptionv3-elastic-20210723-042550-launcher" "scheduler"="default" "toleration"={"key":"celeste/hostname","operator":"Exists","effect":"NoExecute"}
I0723 16:43:35.207174    7682 placement_manager.go:147]  "msg"="Adding toleration to pod"  "podName"="tf2-keras-transformer-elastic-20210723-043917-worker-1" "scheduler"="default" "toleration"={"key":"celeste/hostname","operator":"Equal","value":"gpu5","effect":"NoExecute"}
I0723 16:43:35.997485    7682 placement_manager.go:147]  "msg"="Adding toleration to pod"  "podName"="tf2-keras-transformer-elastic-20210723-043917-worker-0" "scheduler"="default" "toleration"={"key":"celeste/hostname","operator":"Equal","value":"gpu5","effect":"NoExecute"}
I0723 16:43:47.240099    7682 scheduler.go:474]  "msg"="Training job completed"  "elaspedTotalSeconds"=1066.258351573 "gpuTotalSeconds"=2060.057388982 "job"="tf2-keras-cifar10-resnet50-elastic-20210723-042557" "ranTotalSeconds"=955.026721923 "scheduler"="default" "waitedTotalSeconds"=111.23162965
I0723 16:43:47.240254    7682 scheduler.go:135]  "msg"="Received resched event, may be blocked because of rate limit"  "blockedUntil"="2021-07-23T16:45:18.033442792+08:00" "lastResched"="2021-07-23T16:43:18.033442792+08:00" "received"="2021-07-23T16:43:47.240136017+08:00" "scheduler"="default"
I0723 16:45:18.033509    7682 scheduler.go:159]  "msg"="Started resched"  "scheduler"="default"
I0723 16:45:18.033557    7682 scheduler.go:193]  "msg"="Updating all jobs info"  "scheduler"="default"
I0723 16:45:18.040107    7682 afsl.go:65]  "msg"="Finished scheduling"  "algorithm"="AFS-L" "freeGpu"=0 "result"={"tf2-keras-cifar10-inceptionv3-elastic-20210723-042550":1,"tf2-keras-cifar10-inceptionv3-elastic-20210723-042602":2,"tf2-keras-cifar10-inceptionv3-elastic-20210723-044237":2,"tf2-keras-cifar10-vgg16-elastic-20210723-042659":3,"tf2-keras-transformer-elastic-20210723-042834":2,"tf2-keras-transformer-elastic-20210723-043917":2} "scheduler"="default"
I0723 16:45:18.040381    7682 scheduler.go:384]  "msg"="Trying to delete multiple training jobs"  "jobs"=[] "scheduler"="default"
I0723 16:45:18.040577    7682 scheduler.go:342]  "msg"="Trying to scale multiple training jobs"  "jobs"=[] "scheduler"="default"
I0723 16:45:18.040717    7682 scheduler.go:292]  "msg"="Trying to start multiple training jobs"  "jobs"=[] "scheduler"="default"
I0723 16:45:18.040886    7682 scheduler.go:342]  "msg"="Trying to scale multiple training jobs"  "jobs"=["tf2-keras-cifar10-inceptionv3-elastic-20210723-042602","tf2-keras-cifar10-vgg16-elastic-20210723-042659","tf2-keras-cifar10-inceptionv3-elastic-20210723-044237"] "scheduler"="default"
I0723 16:45:18.098039    7682 placement_manager.go:166]  "msg"="Started job placements adjustment"  "scheduler"="default"
I0723 16:45:18.098128    7682 placement_manager.go:192]  "msg"="Releasing slots"  "jobs"={"tf2-keras-cifar10-inceptionv3-elastic-20210723-042550":{},"tf2-keras-cifar10-inceptionv3-elastic-20210723-042602":{},"tf2-keras-cifar10-inceptionv3-elastic-20210723-044237":{},"tf2-keras-cifar10-resnet50-elastic-20210723-042557":{},"tf2-keras-cifar10-vgg16-elastic-20210723-042659":{},"tf2-keras-transformer-elastic-20210723-042834":{},"tf2-keras-transformer-elastic-20210723-043917":{}} "nodes"={"gpu3":{},"gpu4":{},"gpu5":{}} "scheduler"="default"
I0723 16:45:18.098186    7682 placement_manager.go:250]  "msg"="Released slots"  "jobs"={"tf2-keras-cifar10-inceptionv3-elastic-20210723-042550":{},"tf2-keras-cifar10-inceptionv3-elastic-20210723-042602":{},"tf2-keras-cifar10-inceptionv3-elastic-20210723-044237":{},"tf2-keras-cifar10-resnet50-elastic-20210723-042557":{},"tf2-keras-cifar10-vgg16-elastic-20210723-042659":{},"tf2-keras-transformer-elastic-20210723-042834":{},"tf2-keras-transformer-elastic-20210723-043917":{}} "nodes"={"gpu3":{},"gpu4":{},"gpu5":{}} "scheduler"="default"
I0723 16:45:18.098742    7682 placement_manager.go:305]  "msg"="Found best-fit"  "crossNode"=0 "nodes"=[{},{},{}] "requests"=[{},{},{},{},{},{},{},{},{},{},{},{}] "scheduler"="default"
I0723 16:45:18.099105    7682 placement_manager.go:339]  "msg"="nodeStates updated"  "new"={"gpu3":{},"gpu4":{},"gpu5":{}} "old"={"gpu3":{},"gpu4":{},"gpu5":{}} "scheduler"="default" "score"=5
I0723 16:45:18.099407    7682 placement_manager.go:387]  "msg"="jobStates updated"  "new"={"tf2-keras-cifar10-inceptionv3-elastic-20210723-042550":{},"tf2-keras-cifar10-inceptionv3-elastic-20210723-042602":{},"tf2-keras-cifar10-inceptionv3-elastic-20210723-044237":{},"tf2-keras-cifar10-vgg16-elastic-20210723-042659":{},"tf2-keras-transformer-elastic-20210723-042834":{},"tf2-keras-transformer-elastic-20210723-043917":{}} "old"={"tf2-keras-cifar10-inceptionv3-elastic-20210723-042550":{},"tf2-keras-cifar10-inceptionv3-elastic-20210723-042602":{},"tf2-keras-cifar10-inceptionv3-elastic-20210723-044237":{},"tf2-keras-cifar10-resnet50-elastic-20210723-042557":{},"tf2-keras-cifar10-vgg16-elastic-20210723-042659":{},"tf2-keras-transformer-elastic-20210723-042834":{},"tf2-keras-transformer-elastic-20210723-043917":{}} "scheduler"="default"
I0723 16:45:18.099779    7682 placement_manager.go:434]  "msg"="podNodeName updated"  "launchersToDelete"=2 "new"={"tf2-keras-cifar10-inceptionv3-elastic-20210723-042550-worker-0":"gpu5","tf2-keras-cifar10-inceptionv3-elastic-20210723-042602-worker-0":"gpu3","tf2-keras-cifar10-inceptionv3-elastic-20210723-042602-worker-1":"gpu3","tf2-keras-cifar10-inceptionv3-elastic-20210723-044237-worker-0":"gpu3","tf2-keras-cifar10-inceptionv3-elastic-20210723-044237-worker-1":"gpu3","tf2-keras-cifar10-vgg16-elastic-20210723-042659-worker-0":"gpu5","tf2-keras-cifar10-vgg16-elastic-20210723-042659-worker-1":"gpu5","tf2-keras-cifar10-vgg16-elastic-20210723-042659-worker-2":"gpu5","tf2-keras-transformer-elastic-20210723-042834-worker-0":"gpu4","tf2-keras-transformer-elastic-20210723-042834-worker-1":"gpu4","tf2-keras-transformer-elastic-20210723-043917-worker-0":"gpu4","tf2-keras-transformer-elastic-20210723-043917-worker-1":"gpu4"} "old"={"tf2-keras-cifar10-inceptionv3-elastic-20210723-042550-worker-0":"gpu4","tf2-keras-cifar10-inceptionv3-elastic-20210723-042602-worker-0":"gpu4","tf2-keras-cifar10-inceptionv3-elastic-20210723-044237-worker-0":"gpu3","tf2-keras-cifar10-resnet50-elastic-20210723-042557-worker-0":"gpu3","tf2-keras-cifar10-resnet50-elastic-20210723-042557-worker-1":"gpu3","tf2-keras-cifar10-resnet50-elastic-20210723-042557-worker-2":"gpu3","tf2-keras-cifar10-vgg16-elastic-20210723-042659-worker-0":"gpu5","tf2-keras-cifar10-vgg16-elastic-20210723-042659-worker-1":"gpu5","tf2-keras-transformer-elastic-20210723-042834-worker-0":"gpu4","tf2-keras-transformer-elastic-20210723-042834-worker-1":"gpu4","tf2-keras-transformer-elastic-20210723-043917-worker-0":"gpu5","tf2-keras-transformer-elastic-20210723-043917-worker-1":"gpu5"} "scheduler"="default" "workersToDelete"=4
I0723 16:45:18.100042    7682 placement_manager.go:451]  "msg"="Deleting pod that need migration"  "podName"="tf2-keras-cifar10-inceptionv3-elastic-20210723-042602-worker-0" "scheduler"="default"
I0723 16:45:18.112098    7682 placement_manager.go:451]  "msg"="Deleting pod that need migration"  "podName"="tf2-keras-transformer-elastic-20210723-043917-worker-0" "scheduler"="default"
I0723 16:45:18.119160    7682 placement_manager.go:147]  "msg"="Adding toleration to pod"  "podName"="tf2-keras-cifar10-vgg16-elastic-20210723-042659-worker-2" "scheduler"="default" "toleration"={"key":"celeste/hostname","operator":"Equal","value":"gpu5","effect":"NoExecute"}
I0723 16:45:18.121596    7682 placement_manager.go:451]  "msg"="Deleting pod that need migration"  "podName"="tf2-keras-transformer-elastic-20210723-043917-worker-1" "scheduler"="default"
I0723 16:45:18.126871    7682 placement_manager.go:451]  "msg"="Deleting pod that need migration"  "podName"="tf2-keras-transformer-elastic-20210723-043917-launcher" "scheduler"="default"
I0723 16:45:18.132682    7682 placement_manager.go:451]  "msg"="Deleting pod that need migration"  "podName"="tf2-keras-cifar10-inceptionv3-elastic-20210723-042550-worker-0" "scheduler"="default"
I0723 16:45:18.135628    7682 placement_manager.go:451]  "msg"="Deleting pod that need migration"  "podName"="tf2-keras-cifar10-inceptionv3-elastic-20210723-042550-launcher" "scheduler"="default"
I0723 16:45:18.141228    7682 placement_manager.go:183]  "msg"="Finished job placements adjustment"  "scheduler"="default"
I0723 16:45:18.141506    7682 scheduler.go:182]  "msg"="Finished resched"  "scheduler"="default"
I0723 16:45:18.472694    7682 placement_manager.go:147]  "msg"="Adding toleration to pod"  "podName"="tf2-keras-cifar10-inceptionv3-elastic-20210723-044237-worker-1" "scheduler"="default" "toleration"={"key":"celeste/hostname","operator":"Equal","value":"gpu3","effect":"NoExecute"}
I0723 16:45:30.382482    7682 placement_manager.go:147]  "msg"="Adding toleration to pod"  "podName"="tf2-keras-transformer-elastic-20210723-043917-worker-0" "scheduler"="default" "toleration"={"key":"celeste/hostname","operator":"Equal","value":"gpu4","effect":"NoExecute"}
I0723 16:45:31.168370    7682 placement_manager.go:147]  "msg"="Adding toleration to pod"  "podName"="tf2-keras-transformer-elastic-20210723-043917-worker-1" "scheduler"="default" "toleration"={"key":"celeste/hostname","operator":"Equal","value":"gpu4","effect":"NoExecute"}
I0723 16:45:31.970621    7682 placement_manager.go:147]  "msg"="Adding toleration to pod"  "podName"="tf2-keras-transformer-elastic-20210723-043917-launcher" "scheduler"="default" "toleration"={"key":"celeste/hostname","operator":"Exists","effect":"NoExecute"}
I0723 16:45:35.276711    7682 placement_manager.go:147]  "msg"="Adding toleration to pod"  "podName"="tf2-keras-cifar10-inceptionv3-elastic-20210723-042550-launcher" "scheduler"="default" "toleration"={"key":"celeste/hostname","operator":"Exists","effect":"NoExecute"}
I0723 16:45:36.071467    7682 placement_manager.go:147]  "msg"="Adding toleration to pod"  "podName"="tf2-keras-cifar10-inceptionv3-elastic-20210723-042550-worker-0" "scheduler"="default" "toleration"={"key":"celeste/hostname","operator":"Equal","value":"gpu5","effect":"NoExecute"}
I0723 16:45:36.858758    7682 placement_manager.go:147]  "msg"="Adding toleration to pod"  "podName"="tf2-keras-cifar10-inceptionv3-elastic-20210723-042602-worker-0" "scheduler"="default" "toleration"={"key":"celeste/hostname","operator":"Equal","value":"gpu3","effect":"NoExecute"}
I0723 16:45:57.102508    7682 placement_manager.go:147]  "msg"="Adding toleration to pod"  "podName"="tf2-keras-cifar10-inceptionv3-elastic-20210723-042602-worker-1" "scheduler"="default" "toleration"={"key":"celeste/hostname","operator":"Equal","value":"gpu3","effect":"NoExecute"}
I0723 16:47:00.024686    7682 jobmaster.go:155]  "msg"="Training job created"  "job"="tf2-keras-cifar10-resnet50-elastic-20210723-044700"
I0723 16:47:00.024825    7682 scheduler.go:135]  "msg"="Received resched event, may be blocked because of rate limit"  "blockedUntil"="2021-07-23T16:47:18.142033233+08:00" "lastResched"="2021-07-23T16:45:18.142033233+08:00" "received"="2021-07-23T16:47:00.024123126+08:00" "scheduler"="default"
I0723 16:47:18.142097    7682 scheduler.go:159]  "msg"="Started resched"  "scheduler"="default"
I0723 16:47:18.142169    7682 scheduler.go:193]  "msg"="Updating all jobs info"  "scheduler"="default"
I0723 16:47:18.150098    7682 afsl.go:65]  "msg"="Finished scheduling"  "algorithm"="AFS-L" "freeGpu"=0 "result"={"tf2-keras-cifar10-inceptionv3-elastic-20210723-042550":1,"tf2-keras-cifar10-inceptionv3-elastic-20210723-042602":1,"tf2-keras-cifar10-inceptionv3-elastic-20210723-044237":1,"tf2-keras-cifar10-resnet50-elastic-20210723-044700":3,"tf2-keras-cifar10-vgg16-elastic-20210723-042659":2,"tf2-keras-transformer-elastic-20210723-042834":2,"tf2-keras-transformer-elastic-20210723-043917":2} "scheduler"="default"
I0723 16:47:18.150329    7682 scheduler.go:384]  "msg"="Trying to delete multiple training jobs"  "jobs"=[] "scheduler"="default"
I0723 16:47:18.150642    7682 scheduler.go:342]  "msg"="Trying to scale multiple training jobs"  "jobs"=["tf2-keras-cifar10-inceptionv3-elastic-20210723-044237","tf2-keras-cifar10-inceptionv3-elastic-20210723-042602","tf2-keras-cifar10-vgg16-elastic-20210723-042659"] "scheduler"="default"
I0723 16:47:18.202643    7682 scheduler.go:292]  "msg"="Trying to start multiple training jobs"  "jobs"=["tf2-keras-cifar10-resnet50-elastic-20210723-044700"] "scheduler"="default"
I0723 16:47:18.215224    7682 scheduler.go:342]  "msg"="Trying to scale multiple training jobs"  "jobs"=[] "scheduler"="default"
I0723 16:47:18.218748    7682 placement_manager.go:166]  "msg"="Started job placements adjustment"  "scheduler"="default"
I0723 16:47:18.218824    7682 placement_manager.go:192]  "msg"="Releasing slots"  "jobs"={"tf2-keras-cifar10-inceptionv3-elastic-20210723-042550":{},"tf2-keras-cifar10-inceptionv3-elastic-20210723-042602":{},"tf2-keras-cifar10-inceptionv3-elastic-20210723-044237":{},"tf2-keras-cifar10-vgg16-elastic-20210723-042659":{},"tf2-keras-transformer-elastic-20210723-042834":{},"tf2-keras-transformer-elastic-20210723-043917":{}} "nodes"={"gpu3":{},"gpu4":{},"gpu5":{}} "scheduler"="default"
I0723 16:47:18.218889    7682 placement_manager.go:250]  "msg"="Released slots"  "jobs"={"tf2-keras-cifar10-inceptionv3-elastic-20210723-042550":{},"tf2-keras-cifar10-inceptionv3-elastic-20210723-042602":{},"tf2-keras-cifar10-inceptionv3-elastic-20210723-044237":{},"tf2-keras-cifar10-vgg16-elastic-20210723-042659":{},"tf2-keras-transformer-elastic-20210723-042834":{},"tf2-keras-transformer-elastic-20210723-043917":{}} "nodes"={"gpu3":{},"gpu4":{},"gpu5":{}} "scheduler"="default"
I0723 16:47:18.219285    7682 placement_manager.go:305]  "msg"="Found best-fit"  "crossNode"=0 "nodes"=[{},{},{}] "requests"=[{},{},{},{},{},{},{},{},{},{},{},{},{},{}] "scheduler"="default"
I0723 16:47:18.220458    7682 placement_manager.go:339]  "msg"="nodeStates updated"  "new"={"gpu3":{},"gpu4":{},"gpu5":{}} "old"={"gpu3":{},"gpu4":{},"gpu5":{}} "scheduler"="default" "score"=5
I0723 16:47:18.221234    7682 placement_manager.go:387]  "msg"="jobStates updated"  "new"={"tf2-keras-cifar10-inceptionv3-elastic-20210723-042550":{},"tf2-keras-cifar10-inceptionv3-elastic-20210723-042602":{},"tf2-keras-cifar10-inceptionv3-elastic-20210723-044237":{},"tf2-keras-cifar10-resnet50-elastic-20210723-044700":{},"tf2-keras-cifar10-vgg16-elastic-20210723-042659":{},"tf2-keras-transformer-elastic-20210723-042834":{},"tf2-keras-transformer-elastic-20210723-043917":{}} "old"={"tf2-keras-cifar10-inceptionv3-elastic-20210723-042550":{},"tf2-keras-cifar10-inceptionv3-elastic-20210723-042602":{},"tf2-keras-cifar10-inceptionv3-elastic-20210723-044237":{},"tf2-keras-cifar10-vgg16-elastic-20210723-042659":{},"tf2-keras-transformer-elastic-20210723-042834":{},"tf2-keras-transformer-elastic-20210723-043917":{}} "scheduler"="default"
I0723 16:47:18.221910    7682 placement_manager.go:434]  "msg"="podNodeName updated"  "launchersToDelete"=3 "new"={"tf2-keras-cifar10-inceptionv3-elastic-20210723-042550-worker-0":"gpu4","tf2-keras-cifar10-inceptionv3-elastic-20210723-042602-worker-0":"gpu3","tf2-keras-cifar10-inceptionv3-elastic-20210723-044237-worker-0":"gpu4","tf2-keras-cifar10-resnet50-elastic-20210723-044700-worker-0":"gpu3","tf2-keras-cifar10-resnet50-elastic-20210723-044700-worker-1":"gpu3","tf2-keras-cifar10-resnet50-elastic-20210723-044700-worker-2":"gpu3","tf2-keras-cifar10-vgg16-elastic-20210723-042659-worker-0":"gpu5","tf2-keras-cifar10-vgg16-elastic-20210723-042659-worker-1":"gpu5","tf2-keras-transformer-elastic-20210723-042834-worker-0":"gpu5","tf2-keras-transformer-elastic-20210723-042834-worker-1":"gpu5","tf2-keras-transformer-elastic-20210723-043917-worker-0":"gpu4","tf2-keras-transformer-elastic-20210723-043917-worker-1":"gpu4"} "old"={"tf2-keras-cifar10-inceptionv3-elastic-20210723-042550-worker-0":"gpu5","tf2-keras-cifar10-inceptionv3-elastic-20210723-042602-worker-0":"gpu3","tf2-keras-cifar10-inceptionv3-elastic-20210723-042602-worker-1":"gpu3","tf2-keras-cifar10-inceptionv3-elastic-20210723-044237-worker-0":"gpu3","tf2-keras-cifar10-inceptionv3-elastic-20210723-044237-worker-1":"gpu3","tf2-keras-cifar10-vgg16-elastic-20210723-042659-worker-0":"gpu5","tf2-keras-cifar10-vgg16-elastic-20210723-042659-worker-1":"gpu5","tf2-keras-cifar10-vgg16-elastic-20210723-042659-worker-2":"gpu5","tf2-keras-transformer-elastic-20210723-042834-worker-0":"gpu4","tf2-keras-transformer-elastic-20210723-042834-worker-1":"gpu4","tf2-keras-transformer-elastic-20210723-043917-worker-0":"gpu4","tf2-keras-transformer-elastic-20210723-043917-worker-1":"gpu4"} "scheduler"="default" "workersToDelete"=4
I0723 16:47:18.222193    7682 placement_manager.go:451]  "msg"="Deleting pod that need migration"  "podName"="tf2-keras-transformer-elastic-20210723-042834-worker-0" "scheduler"="default"
I0723 16:47:18.237403    7682 placement_manager.go:451]  "msg"="Deleting pod that need migration"  "podName"="tf2-keras-transformer-elastic-20210723-042834-worker-1" "scheduler"="default"
I0723 16:47:18.241844    7682 placement_manager.go:451]  "msg"="Deleting pod that need migration"  "podName"="tf2-keras-transformer-elastic-20210723-042834-launcher" "scheduler"="default"
I0723 16:47:18.246340    7682 placement_manager.go:451]  "msg"="Deleting pod that need migration"  "podName"="tf2-keras-cifar10-inceptionv3-elastic-20210723-044237-worker-0" "scheduler"="default"
I0723 16:47:18.251096    7682 placement_manager.go:451]  "msg"="Deleting pod that need migration"  "podName"="tf2-keras-cifar10-inceptionv3-elastic-20210723-044237-launcher" "scheduler"="default"
I0723 16:47:18.259340    7682 placement_manager.go:451]  "msg"="Deleting pod that need migration"  "podName"="tf2-keras-cifar10-inceptionv3-elastic-20210723-042550-worker-0" "scheduler"="default"
I0723 16:47:18.263529    7682 placement_manager.go:451]  "msg"="Deleting pod that need migration"  "podName"="tf2-keras-cifar10-inceptionv3-elastic-20210723-042550-launcher" "scheduler"="default"
I0723 16:47:18.268087    7682 placement_manager.go:183]  "msg"="Finished job placements adjustment"  "scheduler"="default"
I0723 16:47:18.268457    7682 scheduler.go:182]  "msg"="Finished resched"  "scheduler"="default"
I0723 16:47:19.985574    7682 placement_manager.go:147]  "msg"="Adding toleration to pod"  "podName"="tf2-keras-cifar10-resnet50-elastic-20210723-044700-worker-0" "scheduler"="default" "toleration"={"key":"celeste/hostname","operator":"Equal","value":"gpu3","effect":"NoExecute"}
I0723 16:47:20.585790    7682 placement_manager.go:147]  "msg"="Adding toleration to pod"  "podName"="tf2-keras-cifar10-resnet50-elastic-20210723-044700-worker-1" "scheduler"="default" "toleration"={"key":"celeste/hostname","operator":"Equal","value":"gpu3","effect":"NoExecute"}
I0723 16:47:20.986171    7682 placement_manager.go:147]  "msg"="Adding toleration to pod"  "podName"="tf2-keras-cifar10-resnet50-elastic-20210723-044700-worker-2" "scheduler"="default" "toleration"={"key":"celeste/hostname","operator":"Equal","value":"gpu3","effect":"NoExecute"}
I0723 16:47:21.386569    7682 placement_manager.go:147]  "msg"="Adding toleration to pod"  "podName"="tf2-keras-cifar10-resnet50-elastic-20210723-044700-launcher" "scheduler"="default" "toleration"={"key":"celeste/hostname","operator":"Exists","effect":"NoExecute"}
I0723 16:47:25.519346    7682 placement_manager.go:147]  "msg"="Adding toleration to pod"  "podName"="tf2-keras-transformer-elastic-20210723-042834-worker-1" "scheduler"="default" "toleration"={"key":"celeste/hostname","operator":"Equal","value":"gpu5","effect":"NoExecute"}
I0723 16:47:29.739139    7682 placement_manager.go:147]  "msg"="Adding toleration to pod"  "podName"="tf2-keras-cifar10-inceptionv3-elastic-20210723-042550-worker-0" "scheduler"="default" "toleration"={"key":"celeste/hostname","operator":"Equal","value":"gpu4","effect":"NoExecute"}
I0723 16:47:29.774731    7682 placement_manager.go:147]  "msg"="Adding toleration to pod"  "podName"="tf2-keras-transformer-elastic-20210723-042834-launcher" "scheduler"="default" "toleration"={"key":"celeste/hostname","operator":"Exists","effect":"NoExecute"}
I0723 16:47:31.069347    7682 placement_manager.go:147]  "msg"="Adding toleration to pod"  "podName"="tf2-keras-cifar10-inceptionv3-elastic-20210723-042550-launcher" "scheduler"="default" "toleration"={"key":"celeste/hostname","operator":"Exists","effect":"NoExecute"}
I0723 16:47:35.205110    7682 placement_manager.go:147]  "msg"="Adding toleration to pod"  "podName"="tf2-keras-cifar10-inceptionv3-elastic-20210723-044237-launcher" "scheduler"="default" "toleration"={"key":"celeste/hostname","operator":"Exists","effect":"NoExecute"}
I0723 16:47:35.554727    7682 placement_manager.go:147]  "msg"="Adding toleration to pod"  "podName"="tf2-keras-cifar10-inceptionv3-elastic-20210723-044237-worker-0" "scheduler"="default" "toleration"={"key":"celeste/hostname","operator":"Equal","value":"gpu4","effect":"NoExecute"}
I0723 16:47:36.003073    7682 placement_manager.go:147]  "msg"="Adding toleration to pod"  "podName"="tf2-keras-transformer-elastic-20210723-042834-worker-0" "scheduler"="default" "toleration"={"key":"celeste/hostname","operator":"Equal","value":"gpu5","effect":"NoExecute"}
I0723 16:51:26.490846    7682 jobmaster.go:155]  "msg"="Training job created"  "job"="tf2-keras-cifar10-inceptionv3-elastic-20210723-045126"
I0723 16:51:26.490958    7682 scheduler.go:135]  "msg"="Received resched event, may be blocked because of rate limit"  "blockedUntil"="2021-07-23T16:49:18.268712262+08:00" "lastResched"="2021-07-23T16:47:18.268712262+08:00" "received"="2021-07-23T16:51:26.49028782+08:00" "scheduler"="default"
I0723 16:51:26.491693    7682 scheduler.go:159]  "msg"="Started resched"  "scheduler"="default"
I0723 16:51:26.491765    7682 scheduler.go:193]  "msg"="Updating all jobs info"  "scheduler"="default"
I0723 16:51:26.501879    7682 afsl.go:65]  "msg"="Finished scheduling"  "algorithm"="AFS-L" "freeGpu"=0 "result"={"tf2-keras-cifar10-inceptionv3-elastic-20210723-042550":1,"tf2-keras-cifar10-inceptionv3-elastic-20210723-042602":1,"tf2-keras-cifar10-inceptionv3-elastic-20210723-044237":1,"tf2-keras-cifar10-inceptionv3-elastic-20210723-045126":2,"tf2-keras-cifar10-resnet50-elastic-20210723-044700":2,"tf2-keras-cifar10-vgg16-elastic-20210723-042659":2,"tf2-keras-transformer-elastic-20210723-042834":2,"tf2-keras-transformer-elastic-20210723-043917":1} "scheduler"="default"
I0723 16:51:26.502222    7682 scheduler.go:384]  "msg"="Trying to delete multiple training jobs"  "jobs"=[] "scheduler"="default"
I0723 16:51:26.502412    7682 scheduler.go:342]  "msg"="Trying to scale multiple training jobs"  "jobs"=["tf2-keras-transformer-elastic-20210723-043917","tf2-keras-cifar10-resnet50-elastic-20210723-044700"] "scheduler"="default"
I0723 16:51:26.533406    7682 scheduler.go:292]  "msg"="Trying to start multiple training jobs"  "jobs"=["tf2-keras-cifar10-inceptionv3-elastic-20210723-045126"] "scheduler"="default"
I0723 16:51:26.540660    7682 scheduler.go:342]  "msg"="Trying to scale multiple training jobs"  "jobs"=[] "scheduler"="default"
I0723 16:51:26.544559    7682 placement_manager.go:166]  "msg"="Started job placements adjustment"  "scheduler"="default"
I0723 16:51:26.544615    7682 placement_manager.go:192]  "msg"="Releasing slots"  "jobs"={"tf2-keras-cifar10-inceptionv3-elastic-20210723-042550":{},"tf2-keras-cifar10-inceptionv3-elastic-20210723-042602":{},"tf2-keras-cifar10-inceptionv3-elastic-20210723-044237":{},"tf2-keras-cifar10-resnet50-elastic-20210723-044700":{},"tf2-keras-cifar10-vgg16-elastic-20210723-042659":{},"tf2-keras-transformer-elastic-20210723-042834":{},"tf2-keras-transformer-elastic-20210723-043917":{}} "nodes"={"gpu3":{},"gpu4":{},"gpu5":{}} "scheduler"="default"
I0723 16:51:26.544667    7682 placement_manager.go:250]  "msg"="Released slots"  "jobs"={"tf2-keras-cifar10-inceptionv3-elastic-20210723-042550":{},"tf2-keras-cifar10-inceptionv3-elastic-20210723-042602":{},"tf2-keras-cifar10-inceptionv3-elastic-20210723-044237":{},"tf2-keras-cifar10-resnet50-elastic-20210723-044700":{},"tf2-keras-cifar10-vgg16-elastic-20210723-042659":{},"tf2-keras-transformer-elastic-20210723-042834":{},"tf2-keras-transformer-elastic-20210723-043917":{}} "nodes"={"gpu3":{},"gpu4":{},"gpu5":{}} "scheduler"="default"
I0723 16:51:26.545128    7682 placement_manager.go:305]  "msg"="Found best-fit"  "crossNode"=0 "nodes"=[{},{},{}] "requests"=[{},{},{},{},{},{},{},{},{},{},{},{},{},{},{},{}] "scheduler"="default"
I0723 16:51:26.545416    7682 placement_manager.go:339]  "msg"="nodeStates updated"  "new"={"gpu3":{},"gpu4":{},"gpu5":{}} "old"={"gpu3":{},"gpu4":{},"gpu5":{}} "scheduler"="default" "score"=9
I0723 16:51:26.545770    7682 placement_manager.go:387]  "msg"="jobStates updated"  "new"={"tf2-keras-cifar10-inceptionv3-elastic-20210723-042550":{},"tf2-keras-cifar10-inceptionv3-elastic-20210723-042602":{},"tf2-keras-cifar10-inceptionv3-elastic-20210723-044237":{},"tf2-keras-cifar10-inceptionv3-elastic-20210723-045126":{},"tf2-keras-cifar10-resnet50-elastic-20210723-044700":{},"tf2-keras-cifar10-vgg16-elastic-20210723-042659":{},"tf2-keras-transformer-elastic-20210723-042834":{},"tf2-keras-transformer-elastic-20210723-043917":{}} "old"={"tf2-keras-cifar10-inceptionv3-elastic-20210723-042550":{},"tf2-keras-cifar10-inceptionv3-elastic-20210723-042602":{},"tf2-keras-cifar10-inceptionv3-elastic-20210723-044237":{},"tf2-keras-cifar10-resnet50-elastic-20210723-044700":{},"tf2-keras-cifar10-vgg16-elastic-20210723-042659":{},"tf2-keras-transformer-elastic-20210723-042834":{},"tf2-keras-transformer-elastic-20210723-043917":{}} "scheduler"="default"
I0723 16:51:26.546170    7682 placement_manager.go:434]  "msg"="podNodeName updated"  "launchersToDelete"=1 "new"={"tf2-keras-cifar10-inceptionv3-elastic-20210723-042550-worker-0":"gpu4","tf2-keras-cifar10-inceptionv3-elastic-20210723-042602-worker-0":"gpu4","tf2-keras-cifar10-inceptionv3-elastic-20210723-044237-worker-0":"gpu4","tf2-keras-cifar10-inceptionv3-elastic-20210723-045126-worker-0":"gpu3","tf2-keras-cifar10-inceptionv3-elastic-20210723-045126-worker-1":"gpu3","tf2-keras-cifar10-resnet50-elastic-20210723-044700-worker-0":"gpu3","tf2-keras-cifar10-resnet50-elastic-20210723-044700-worker-1":"gpu3","tf2-keras-cifar10-vgg16-elastic-20210723-042659-worker-0":"gpu5","tf2-keras-cifar10-vgg16-elastic-20210723-042659-worker-1":"gpu5","tf2-keras-transformer-elastic-20210723-042834-worker-0":"gpu5","tf2-keras-transformer-elastic-20210723-042834-worker-1":"gpu5","tf2-keras-transformer-elastic-20210723-043917-worker-0":"gpu4"} "old"={"tf2-keras-cifar10-inceptionv3-elastic-20210723-042550-worker-0":"gpu4","tf2-keras-cifar10-inceptionv3-elastic-20210723-042602-worker-0":"gpu3","tf2-keras-cifar10-inceptionv3-elastic-20210723-044237-worker-0":"gpu4","tf2-keras-cifar10-resnet50-elastic-20210723-044700-worker-0":"gpu3","tf2-keras-cifar10-resnet50-elastic-20210723-044700-worker-1":"gpu3","tf2-keras-cifar10-resnet50-elastic-20210723-044700-worker-2":"gpu3","tf2-keras-cifar10-vgg16-elastic-20210723-042659-worker-0":"gpu5","tf2-keras-cifar10-vgg16-elastic-20210723-042659-worker-1":"gpu5","tf2-keras-transformer-elastic-20210723-042834-worker-0":"gpu5","tf2-keras-transformer-elastic-20210723-042834-worker-1":"gpu5","tf2-keras-transformer-elastic-20210723-043917-worker-0":"gpu4","tf2-keras-transformer-elastic-20210723-043917-worker-1":"gpu4"} "scheduler"="default" "workersToDelete"=1
I0723 16:51:26.546536    7682 placement_manager.go:451]  "msg"="Deleting pod that need migration"  "podName"="tf2-keras-cifar10-inceptionv3-elastic-20210723-042602-worker-0" "scheduler"="default"
I0723 16:51:26.553507    7682 placement_manager.go:451]  "msg"="Deleting pod that need migration"  "podName"="tf2-keras-cifar10-inceptionv3-elastic-20210723-042602-launcher" "scheduler"="default"
I0723 16:51:26.558216    7682 placement_manager.go:183]  "msg"="Finished job placements adjustment"  "scheduler"="default"
I0723 16:51:26.558455    7682 scheduler.go:182]  "msg"="Finished resched"  "scheduler"="default"
I0723 16:51:28.132691    7682 placement_manager.go:147]  "msg"="Adding toleration to pod"  "podName"="tf2-keras-cifar10-inceptionv3-elastic-20210723-045126-worker-0" "scheduler"="default" "toleration"={"key":"celeste/hostname","operator":"Equal","value":"gpu3","effect":"NoExecute"}
I0723 16:51:28.330612    7682 placement_manager.go:147]  "msg"="Adding toleration to pod"  "podName"="tf2-keras-cifar10-inceptionv3-elastic-20210723-045126-worker-1" "scheduler"="default" "toleration"={"key":"celeste/hostname","operator":"Equal","value":"gpu3","effect":"NoExecute"}
I0723 16:51:28.536245    7682 placement_manager.go:147]  "msg"="Adding toleration to pod"  "podName"="tf2-keras-cifar10-inceptionv3-elastic-20210723-045126-launcher" "scheduler"="default" "toleration"={"key":"celeste/hostname","operator":"Exists","effect":"NoExecute"}
I0723 16:51:43.850962    7682 placement_manager.go:147]  "msg"="Adding toleration to pod"  "podName"="tf2-keras-cifar10-inceptionv3-elastic-20210723-042602-worker-0" "scheduler"="default" "toleration"={"key":"celeste/hostname","operator":"Equal","value":"gpu4","effect":"NoExecute"}
I0723 16:51:44.502171    7682 jobmaster.go:155]  "msg"="Training job created"  "job"="tf2-keras-transformer-elastic-20210723-045144"
I0723 16:51:44.502303    7682 scheduler.go:135]  "msg"="Received resched event, may be blocked because of rate limit"  "blockedUntil"="2021-07-23T16:53:26.558712065+08:00" "lastResched"="2021-07-23T16:51:26.558712065+08:00" "received"="2021-07-23T16:51:44.501720361+08:00" "scheduler"="default"
I0723 16:51:44.585528    7682 placement_manager.go:147]  "msg"="Adding toleration to pod"  "podName"="tf2-keras-cifar10-inceptionv3-elastic-20210723-042602-launcher" "scheduler"="default" "toleration"={"key":"celeste/hostname","operator":"Exists","effect":"NoExecute"}
I0723 16:52:10.418287    7682 jobmaster.go:155]  "msg"="Training job created"  "job"="tf2-keras-cifar10-vgg16-elastic-20210723-045210"
I0723 16:53:26.558796    7682 scheduler.go:159]  "msg"="Started resched"  "scheduler"="default"
I0723 16:53:26.558873    7682 scheduler.go:193]  "msg"="Updating all jobs info"  "scheduler"="default"
I0723 16:53:26.570313    7682 afsl.go:65]  "msg"="Finished scheduling"  "algorithm"="AFS-L" "freeGpu"=0 "result"={"tf2-keras-cifar10-inceptionv3-elastic-20210723-042550":1,"tf2-keras-cifar10-inceptionv3-elastic-20210723-042602":1,"tf2-keras-cifar10-inceptionv3-elastic-20210723-044237":1,"tf2-keras-cifar10-inceptionv3-elastic-20210723-045126":1,"tf2-keras-cifar10-resnet50-elastic-20210723-044700":1,"tf2-keras-cifar10-vgg16-elastic-20210723-042659":2,"tf2-keras-cifar10-vgg16-elastic-20210723-045210":1,"tf2-keras-transformer-elastic-20210723-042834":2,"tf2-keras-transformer-elastic-20210723-043917":1,"tf2-keras-transformer-elastic-20210723-045144":1} "scheduler"="default"
I0723 16:53:26.570754    7682 scheduler.go:384]  "msg"="Trying to delete multiple training jobs"  "jobs"=[] "scheduler"="default"
I0723 16:53:26.571027    7682 scheduler.go:342]  "msg"="Trying to scale multiple training jobs"  "jobs"=["tf2-keras-cifar10-resnet50-elastic-20210723-044700","tf2-keras-cifar10-inceptionv3-elastic-20210723-045126"] "scheduler"="default"
I0723 16:53:26.608834    7682 scheduler.go:292]  "msg"="Trying to start multiple training jobs"  "jobs"=["tf2-keras-transformer-elastic-20210723-045144","tf2-keras-cifar10-vgg16-elastic-20210723-045210"] "scheduler"="default"
I0723 16:53:26.625335    7682 scheduler.go:342]  "msg"="Trying to scale multiple training jobs"  "jobs"=[] "scheduler"="default"
I0723 16:53:26.630100    7682 placement_manager.go:166]  "msg"="Started job placements adjustment"  "scheduler"="default"
I0723 16:53:26.630185    7682 placement_manager.go:192]  "msg"="Releasing slots"  "jobs"={"tf2-keras-cifar10-inceptionv3-elastic-20210723-042550":{},"tf2-keras-cifar10-inceptionv3-elastic-20210723-042602":{},"tf2-keras-cifar10-inceptionv3-elastic-20210723-044237":{},"tf2-keras-cifar10-inceptionv3-elastic-20210723-045126":{},"tf2-keras-cifar10-resnet50-elastic-20210723-044700":{},"tf2-keras-cifar10-vgg16-elastic-20210723-042659":{},"tf2-keras-transformer-elastic-20210723-042834":{},"tf2-keras-transformer-elastic-20210723-043917":{}} "nodes"={"gpu3":{},"gpu4":{},"gpu5":{}} "scheduler"="default"
I0723 16:53:26.630251    7682 placement_manager.go:250]  "msg"="Released slots"  "jobs"={"tf2-keras-cifar10-inceptionv3-elastic-20210723-042550":{},"tf2-keras-cifar10-inceptionv3-elastic-20210723-042602":{},"tf2-keras-cifar10-inceptionv3-elastic-20210723-044237":{},"tf2-keras-cifar10-inceptionv3-elastic-20210723-045126":{},"tf2-keras-cifar10-resnet50-elastic-20210723-044700":{},"tf2-keras-cifar10-vgg16-elastic-20210723-042659":{},"tf2-keras-transformer-elastic-20210723-042834":{},"tf2-keras-transformer-elastic-20210723-043917":{}} "nodes"={"gpu3":{},"gpu4":{},"gpu5":{}} "scheduler"="default"
I0723 16:53:26.630770    7682 placement_manager.go:305]  "msg"="Found best-fit"  "crossNode"=0 "nodes"=[{},{},{}] "requests"=[{},{},{},{},{},{},{},{},{},{},{},{},{},{},{},{},{},{},{},{}] "scheduler"="default"
I0723 16:53:26.631212    7682 placement_manager.go:339]  "msg"="nodeStates updated"  "new"={"gpu3":{},"gpu4":{},"gpu5":{}} "old"={"gpu3":{},"gpu4":{},"gpu5":{}} "scheduler"="default" "score"=7
I0723 16:53:26.631678    7682 placement_manager.go:387]  "msg"="jobStates updated"  "new"={"tf2-keras-cifar10-inceptionv3-elastic-20210723-042550":{},"tf2-keras-cifar10-inceptionv3-elastic-20210723-042602":{},"tf2-keras-cifar10-inceptionv3-elastic-20210723-044237":{},"tf2-keras-cifar10-inceptionv3-elastic-20210723-045126":{},"tf2-keras-cifar10-resnet50-elastic-20210723-044700":{},"tf2-keras-cifar10-vgg16-elastic-20210723-042659":{},"tf2-keras-cifar10-vgg16-elastic-20210723-045210":{},"tf2-keras-transformer-elastic-20210723-042834":{},"tf2-keras-transformer-elastic-20210723-043917":{},"tf2-keras-transformer-elastic-20210723-045144":{}} "old"={"tf2-keras-cifar10-inceptionv3-elastic-20210723-042550":{},"tf2-keras-cifar10-inceptionv3-elastic-20210723-042602":{},"tf2-keras-cifar10-inceptionv3-elastic-20210723-044237":{},"tf2-keras-cifar10-inceptionv3-elastic-20210723-045126":{},"tf2-keras-cifar10-resnet50-elastic-20210723-044700":{},"tf2-keras-cifar10-vgg16-elastic-20210723-042659":{},"tf2-keras-transformer-elastic-20210723-042834":{},"tf2-keras-transformer-elastic-20210723-043917":{}} "scheduler"="default"
I0723 16:53:26.632235    7682 placement_manager.go:434]  "msg"="podNodeName updated"  "launchersToDelete"=3 "new"={"tf2-keras-cifar10-inceptionv3-elastic-20210723-042550-worker-0":"gpu3","tf2-keras-cifar10-inceptionv3-elastic-20210723-042602-worker-0":"gpu4","tf2-keras-cifar10-inceptionv3-elastic-20210723-044237-worker-0":"gpu4","tf2-keras-cifar10-inceptionv3-elastic-20210723-045126-worker-0":"gpu3","tf2-keras-cifar10-resnet50-elastic-20210723-044700-worker-0":"gpu4","tf2-keras-cifar10-vgg16-elastic-20210723-042659-worker-0":"gpu5","tf2-keras-cifar10-vgg16-elastic-20210723-042659-worker-1":"gpu5","tf2-keras-cifar10-vgg16-elastic-20210723-045210-worker-0":"gpu3","tf2-keras-transformer-elastic-20210723-042834-worker-0":"gpu5","tf2-keras-transformer-elastic-20210723-042834-worker-1":"gpu5","tf2-keras-transformer-elastic-20210723-043917-worker-0":"gpu3","tf2-keras-transformer-elastic-20210723-045144-worker-0":"gpu4"} "old"={"tf2-keras-cifar10-inceptionv3-elastic-20210723-042550-worker-0":"gpu4","tf2-keras-cifar10-inceptionv3-elastic-20210723-042602-worker-0":"gpu4","tf2-keras-cifar10-inceptionv3-elastic-20210723-044237-worker-0":"gpu4","tf2-keras-cifar10-inceptionv3-elastic-20210723-045126-worker-0":"gpu3","tf2-keras-cifar10-inceptionv3-elastic-20210723-045126-worker-1":"gpu3","tf2-keras-cifar10-resnet50-elastic-20210723-044700-worker-0":"gpu3","tf2-keras-cifar10-resnet50-elastic-20210723-044700-worker-1":"gpu3","tf2-keras-cifar10-vgg16-elastic-20210723-042659-worker-0":"gpu5","tf2-keras-cifar10-vgg16-elastic-20210723-042659-worker-1":"gpu5","tf2-keras-transformer-elastic-20210723-042834-worker-0":"gpu5","tf2-keras-transformer-elastic-20210723-042834-worker-1":"gpu5","tf2-keras-transformer-elastic-20210723-043917-worker-0":"gpu4"} "scheduler"="default" "workersToDelete"=3
I0723 16:53:26.632665    7682 placement_manager.go:451]  "msg"="Deleting pod that need migration"  "podName"="tf2-keras-cifar10-inceptionv3-elastic-20210723-042550-worker-0" "scheduler"="default"
I0723 16:53:26.641584    7682 placement_manager.go:451]  "msg"="Deleting pod that need migration"  "podName"="tf2-keras-cifar10-inceptionv3-elastic-20210723-042550-launcher" "scheduler"="default"
I0723 16:53:26.646174    7682 placement_manager.go:451]  "msg"="Deleting pod that need migration"  "podName"="tf2-keras-transformer-elastic-20210723-043917-worker-0" "scheduler"="default"
I0723 16:53:26.650997    7682 placement_manager.go:451]  "msg"="Deleting pod that need migration"  "podName"="tf2-keras-transformer-elastic-20210723-043917-launcher" "scheduler"="default"
I0723 16:53:26.654955    7682 placement_manager.go:451]  "msg"="Deleting pod that need migration"  "podName"="tf2-keras-cifar10-resnet50-elastic-20210723-044700-worker-0" "scheduler"="default"
I0723 16:53:26.658674    7682 placement_manager.go:451]  "msg"="Deleting pod that need migration"  "podName"="tf2-keras-cifar10-resnet50-elastic-20210723-044700-launcher" "scheduler"="default"
I0723 16:53:26.662987    7682 placement_manager.go:183]  "msg"="Finished job placements adjustment"  "scheduler"="default"
I0723 16:53:26.663233    7682 scheduler.go:182]  "msg"="Finished resched"  "scheduler"="default"
I0723 16:53:28.208614    7682 placement_manager.go:147]  "msg"="Adding toleration to pod"  "podName"="tf2-keras-transformer-elastic-20210723-045144-worker-0" "scheduler"="default" "toleration"={"key":"celeste/hostname","operator":"Equal","value":"gpu4","effect":"NoExecute"}
I0723 16:53:28.610374    7682 placement_manager.go:147]  "msg"="Adding toleration to pod"  "podName"="tf2-keras-transformer-elastic-20210723-045144-launcher" "scheduler"="default" "toleration"={"key":"celeste/hostname","operator":"Exists","effect":"NoExecute"}
I0723 16:53:28.808145    7682 placement_manager.go:147]  "msg"="Adding toleration to pod"  "podName"="tf2-keras-cifar10-vgg16-elastic-20210723-045210-worker-0" "scheduler"="default" "toleration"={"key":"celeste/hostname","operator":"Equal","value":"gpu3","effect":"NoExecute"}
I0723 16:53:29.208584    7682 placement_manager.go:147]  "msg"="Adding toleration to pod"  "podName"="tf2-keras-cifar10-vgg16-elastic-20210723-045210-launcher" "scheduler"="default" "toleration"={"key":"celeste/hostname","operator":"Exists","effect":"NoExecute"}
I0723 16:53:33.881890    7682 placement_manager.go:147]  "msg"="Adding toleration to pod"  "podName"="tf2-keras-cifar10-resnet50-elastic-20210723-044700-launcher" "scheduler"="default" "toleration"={"key":"celeste/hostname","operator":"Exists","effect":"NoExecute"}
I0723 16:53:35.327719    7682 placement_manager.go:147]  "msg"="Adding toleration to pod"  "podName"="tf2-keras-transformer-elastic-20210723-043917-worker-0" "scheduler"="default" "toleration"={"key":"celeste/hostname","operator":"Equal","value":"gpu3","effect":"NoExecute"}
I0723 16:53:44.605022    7682 placement_manager.go:147]  "msg"="Adding toleration to pod"  "podName"="tf2-keras-cifar10-inceptionv3-elastic-20210723-042550-worker-0" "scheduler"="default" "toleration"={"key":"celeste/hostname","operator":"Equal","value":"gpu3","effect":"NoExecute"}
I0723 16:53:44.646572    7682 placement_manager.go:147]  "msg"="Adding toleration to pod"  "podName"="tf2-keras-transformer-elastic-20210723-043917-launcher" "scheduler"="default" "toleration"={"key":"celeste/hostname","operator":"Exists","effect":"NoExecute"}
I0723 16:53:44.657768    7682 placement_manager.go:147]  "msg"="Adding toleration to pod"  "podName"="tf2-keras-cifar10-inceptionv3-elastic-20210723-042550-launcher" "scheduler"="default" "toleration"={"key":"celeste/hostname","operator":"Exists","effect":"NoExecute"}
I0723 16:53:46.423216    7682 placement_manager.go:147]  "msg"="Adding toleration to pod"  "podName"="tf2-keras-cifar10-resnet50-elastic-20210723-044700-worker-0" "scheduler"="default" "toleration"={"key":"celeste/hostname","operator":"Equal","value":"gpu4","effect":"NoExecute"}
I0723 16:54:01.404382    7682 jobmaster.go:155]  "msg"="Training job created"  "job"="tf2-keras-cifar10-vgg16-elastic-20210723-045401"
I0723 16:54:01.404515    7682 scheduler.go:135]  "msg"="Received resched event, may be blocked because of rate limit"  "blockedUntil"="2021-07-23T16:55:26.663421529+08:00" "lastResched"="2021-07-23T16:53:26.663421529+08:00" "received"="2021-07-23T16:54:01.403821503+08:00" "scheduler"="default"
I0723 16:54:45.350875    7682 jobmaster.go:155]  "msg"="Training job created"  "job"="tf2-keras-cifar10-resnet50-elastic-20210723-045445"
I0723 16:54:47.262263    7682 jobmaster.go:155]  "msg"="Training job created"  "job"="tf2-keras-cifar10-inceptionv3-elastic-20210723-045447"
I0723 16:54:58.161638    7682 jobmaster.go:155]  "msg"="Training job created"  "job"="tf2-keras-transformer-elastic-20210723-045458"
I0723 16:55:01.107196    7682 jobmaster.go:155]  "msg"="Training job created"  "job"="tf2-keras-cifar10-inceptionv3-elastic-20210723-045501"
I0723 16:55:26.663465    7682 scheduler.go:159]  "msg"="Started resched"  "scheduler"="default"
I0723 16:55:26.663513    7682 scheduler.go:193]  "msg"="Updating all jobs info"  "scheduler"="default"
I0723 16:55:26.676002    7682 afsl.go:65]  "msg"="Finished scheduling"  "algorithm"="AFS-L" "freeGpu"=0 "result"={"tf2-keras-cifar10-inceptionv3-elastic-20210723-042550":0,"tf2-keras-cifar10-inceptionv3-elastic-20210723-042602":1,"tf2-keras-cifar10-inceptionv3-elastic-20210723-044237":1,"tf2-keras-cifar10-inceptionv3-elastic-20210723-045126":0,"tf2-keras-cifar10-inceptionv3-elastic-20210723-045447":0,"tf2-keras-cifar10-inceptionv3-elastic-20210723-045501":1,"tf2-keras-cifar10-resnet50-elastic-20210723-044700":1,"tf2-keras-cifar10-resnet50-elastic-20210723-045445":1,"tf2-keras-cifar10-vgg16-elastic-20210723-042659":1,"tf2-keras-cifar10-vgg16-elastic-20210723-045210":1,"tf2-keras-cifar10-vgg16-elastic-20210723-045401":1,"tf2-keras-transformer-elastic-20210723-042834":1,"tf2-keras-transformer-elastic-20210723-043917":1,"tf2-keras-transformer-elastic-20210723-045144":1,"tf2-keras-transformer-elastic-20210723-045458":1} "scheduler"="default"
I0723 16:55:26.677643    7682 scheduler.go:384]  "msg"="Trying to delete multiple training jobs"  "jobs"=["tf2-keras-cifar10-inceptionv3-elastic-20210723-045126","tf2-keras-cifar10-inceptionv3-elastic-20210723-042550"] "scheduler"="default"
I0723 16:55:26.696504    7682 scheduler.go:342]  "msg"="Trying to scale multiple training jobs"  "jobs"=["tf2-keras-transformer-elastic-20210723-042834","tf2-keras-cifar10-vgg16-elastic-20210723-042659"] "scheduler"="default"
I0723 16:55:26.730842    7682 scheduler.go:292]  "msg"="Trying to start multiple training jobs"  "jobs"=["tf2-keras-transformer-elastic-20210723-045458","tf2-keras-cifar10-inceptionv3-elastic-20210723-045501","tf2-keras-cifar10-vgg16-elastic-20210723-045401","tf2-keras-cifar10-resnet50-elastic-20210723-045445"] "scheduler"="default"
I0723 16:55:26.762753    7682 scheduler.go:342]  "msg"="Trying to scale multiple training jobs"  "jobs"=[] "scheduler"="default"
I0723 16:55:26.768029    7682 placement_manager.go:166]  "msg"="Started job placements adjustment"  "scheduler"="default"
I0723 16:55:26.768129    7682 placement_manager.go:192]  "msg"="Releasing slots"  "jobs"={"tf2-keras-cifar10-inceptionv3-elastic-20210723-042550":{},"tf2-keras-cifar10-inceptionv3-elastic-20210723-042602":{},"tf2-keras-cifar10-inceptionv3-elastic-20210723-044237":{},"tf2-keras-cifar10-inceptionv3-elastic-20210723-045126":{},"tf2-keras-cifar10-resnet50-elastic-20210723-044700":{},"tf2-keras-cifar10-vgg16-elastic-20210723-042659":{},"tf2-keras-cifar10-vgg16-elastic-20210723-045210":{},"tf2-keras-transformer-elastic-20210723-042834":{},"tf2-keras-transformer-elastic-20210723-043917":{},"tf2-keras-transformer-elastic-20210723-045144":{}} "nodes"={"gpu3":{},"gpu4":{},"gpu5":{}} "scheduler"="default"
I0723 16:55:26.768202    7682 placement_manager.go:250]  "msg"="Released slots"  "jobs"={"tf2-keras-cifar10-inceptionv3-elastic-20210723-042550":{},"tf2-keras-cifar10-inceptionv3-elastic-20210723-042602":{},"tf2-keras-cifar10-inceptionv3-elastic-20210723-044237":{},"tf2-keras-cifar10-inceptionv3-elastic-20210723-045126":{},"tf2-keras-cifar10-resnet50-elastic-20210723-044700":{},"tf2-keras-cifar10-vgg16-elastic-20210723-042659":{},"tf2-keras-cifar10-vgg16-elastic-20210723-045210":{},"tf2-keras-transformer-elastic-20210723-042834":{},"tf2-keras-transformer-elastic-20210723-043917":{},"tf2-keras-transformer-elastic-20210723-045144":{}} "nodes"={"gpu3":{},"gpu4":{},"gpu5":{}} "scheduler"="default"
I0723 16:55:26.768641    7682 placement_manager.go:305]  "msg"="Found best-fit"  "crossNode"=0 "nodes"=[{},{},{}] "requests"=[{},{},{},{},{},{},{},{},{},{},{},{},{},{},{},{},{},{},{},{},{},{},{},{},{},{},{},{},{},{}] "scheduler"="default"
I0723 16:55:26.768945    7682 placement_manager.go:339]  "msg"="nodeStates updated"  "new"={"gpu3":{},"gpu4":{},"gpu5":{}} "old"={"gpu3":{},"gpu4":{},"gpu5":{}} "scheduler"="default" "score"=4
I0723 16:55:26.769339    7682 placement_manager.go:387]  "msg"="jobStates updated"  "new"={"tf2-keras-cifar10-inceptionv3-elastic-20210723-042602":{},"tf2-keras-cifar10-inceptionv3-elastic-20210723-044237":{},"tf2-keras-cifar10-inceptionv3-elastic-20210723-045501":{},"tf2-keras-cifar10-resnet50-elastic-20210723-044700":{},"tf2-keras-cifar10-resnet50-elastic-20210723-045445":{},"tf2-keras-cifar10-vgg16-elastic-20210723-042659":{},"tf2-keras-cifar10-vgg16-elastic-20210723-045210":{},"tf2-keras-cifar10-vgg16-elastic-20210723-045401":{},"tf2-keras-transformer-elastic-20210723-042834":{},"tf2-keras-transformer-elastic-20210723-043917":{},"tf2-keras-transformer-elastic-20210723-045144":{},"tf2-keras-transformer-elastic-20210723-045458":{}} "old"={"tf2-keras-cifar10-inceptionv3-elastic-20210723-042550":{},"tf2-keras-cifar10-inceptionv3-elastic-20210723-042602":{},"tf2-keras-cifar10-inceptionv3-elastic-20210723-044237":{},"tf2-keras-cifar10-inceptionv3-elastic-20210723-045126":{},"tf2-keras-cifar10-resnet50-elastic-20210723-044700":{},"tf2-keras-cifar10-vgg16-elastic-20210723-042659":{},"tf2-keras-cifar10-vgg16-elastic-20210723-045210":{},"tf2-keras-transformer-elastic-20210723-042834":{},"tf2-keras-transformer-elastic-20210723-043917":{},"tf2-keras-transformer-elastic-20210723-045144":{}} "scheduler"="default"
I0723 16:55:26.769804    7682 placement_manager.go:434]  "msg"="podNodeName updated"  "launchersToDelete"=4 "new"={"tf2-keras-cifar10-inceptionv3-elastic-20210723-042602-worker-0":"gpu4","tf2-keras-cifar10-inceptionv3-elastic-20210723-044237-worker-0":"gpu5","tf2-keras-cifar10-inceptionv3-elastic-20210723-045501-worker-0":"gpu4","tf2-keras-cifar10-resnet50-elastic-20210723-044700-worker-0":"gpu4","tf2-keras-cifar10-resnet50-elastic-20210723-045445-worker-0":"gpu3","tf2-keras-cifar10-vgg16-elastic-20210723-042659-worker-0":"gpu5","tf2-keras-cifar10-vgg16-elastic-20210723-045210-worker-0":"gpu5","tf2-keras-cifar10-vgg16-elastic-20210723-045401-worker-0":"gpu4","tf2-keras-transformer-elastic-20210723-042834-worker-0":"gpu3","tf2-keras-transformer-elastic-20210723-043917-worker-0":"gpu3","tf2-keras-transformer-elastic-20210723-045144-worker-0":"gpu5","tf2-keras-transformer-elastic-20210723-045458-worker-0":"gpu3"} "old"={"tf2-keras-cifar10-inceptionv3-elastic-20210723-042550-worker-0":"gpu3","tf2-keras-cifar10-inceptionv3-elastic-20210723-042602-worker-0":"gpu4","tf2-keras-cifar10-inceptionv3-elastic-20210723-044237-worker-0":"gpu4","tf2-keras-cifar10-inceptionv3-elastic-20210723-045126-worker-0":"gpu3","tf2-keras-cifar10-resnet50-elastic-20210723-044700-worker-0":"gpu4","tf2-keras-cifar10-vgg16-elastic-20210723-042659-worker-0":"gpu5","tf2-keras-cifar10-vgg16-elastic-20210723-042659-worker-1":"gpu5","tf2-keras-cifar10-vgg16-elastic-20210723-045210-worker-0":"gpu3","tf2-keras-transformer-elastic-20210723-042834-worker-0":"gpu5","tf2-keras-transformer-elastic-20210723-042834-worker-1":"gpu5","tf2-keras-transformer-elastic-20210723-043917-worker-0":"gpu3","tf2-keras-transformer-elastic-20210723-045144-worker-0":"gpu4"} "scheduler"="default" "workersToDelete"=4
I0723 16:55:26.770142    7682 placement_manager.go:451]  "msg"="Deleting pod that need migration"  "podName"="tf2-keras-cifar10-vgg16-elastic-20210723-045210-worker-0" "scheduler"="default"
I0723 16:55:26.773563    7682 placement_manager.go:451]  "msg"="Deleting pod that need migration"  "podName"="tf2-keras-cifar10-vgg16-elastic-20210723-045210-launcher" "scheduler"="default"
I0723 16:55:26.777377    7682 placement_manager.go:451]  "msg"="Deleting pod that need migration"  "podName"="tf2-keras-transformer-elastic-20210723-042834-worker-0" "scheduler"="default"
I0723 16:55:26.784730    7682 placement_manager.go:451]  "msg"="Deleting pod that need migration"  "podName"="tf2-keras-transformer-elastic-20210723-042834-launcher" "scheduler"="default"
I0723 16:55:26.788470    7682 placement_manager.go:451]  "msg"="Deleting pod that need migration"  "podName"="tf2-keras-cifar10-inceptionv3-elastic-20210723-044237-worker-0" "scheduler"="default"
I0723 16:55:26.792951    7682 placement_manager.go:451]  "msg"="Deleting pod that need migration"  "podName"="tf2-keras-cifar10-inceptionv3-elastic-20210723-044237-launcher" "scheduler"="default"
I0723 16:55:26.796825    7682 placement_manager.go:451]  "msg"="Deleting pod that need migration"  "podName"="tf2-keras-transformer-elastic-20210723-045144-worker-0" "scheduler"="default"
I0723 16:55:26.800624    7682 placement_manager.go:451]  "msg"="Deleting pod that need migration"  "podName"="tf2-keras-transformer-elastic-20210723-045144-launcher" "scheduler"="default"
I0723 16:55:26.804713    7682 placement_manager.go:183]  "msg"="Finished job placements adjustment"  "scheduler"="default"
I0723 16:55:26.804952    7682 scheduler.go:182]  "msg"="Finished resched"  "scheduler"="default"
I0723 16:55:28.724944    7682 placement_manager.go:147]  "msg"="Adding toleration to pod"  "podName"="tf2-keras-transformer-elastic-20210723-045458-worker-0" "scheduler"="default" "toleration"={"key":"celeste/hostname","operator":"Equal","value":"gpu3","effect":"NoExecute"}
I0723 16:55:29.125840    7682 placement_manager.go:147]  "msg"="Adding toleration to pod"  "podName"="tf2-keras-transformer-elastic-20210723-045458-launcher" "scheduler"="default" "toleration"={"key":"celeste/hostname","operator":"Exists","effect":"NoExecute"}
I0723 16:55:29.327834    7682 placement_manager.go:147]  "msg"="Adding toleration to pod"  "podName"="tf2-keras-cifar10-inceptionv3-elastic-20210723-045501-worker-0" "scheduler"="default" "toleration"={"key":"celeste/hostname","operator":"Equal","value":"gpu4","effect":"NoExecute"}
I0723 16:55:29.726466    7682 placement_manager.go:147]  "msg"="Adding toleration to pod"  "podName"="tf2-keras-cifar10-inceptionv3-elastic-20210723-045501-launcher" "scheduler"="default" "toleration"={"key":"celeste/hostname","operator":"Exists","effect":"NoExecute"}
I0723 16:55:31.724306    7682 placement_manager.go:147]  "msg"="Adding toleration to pod"  "podName"="tf2-keras-cifar10-vgg16-elastic-20210723-045401-worker-0" "scheduler"="default" "toleration"={"key":"celeste/hostname","operator":"Equal","value":"gpu4","effect":"NoExecute"}
I0723 16:55:31.923965    7682 placement_manager.go:147]  "msg"="Adding toleration to pod"  "podName"="tf2-keras-cifar10-resnet50-elastic-20210723-045445-worker-0" "scheduler"="default" "toleration"={"key":"celeste/hostname","operator":"Equal","value":"gpu3","effect":"NoExecute"}
I0723 16:55:32.123560    7682 placement_manager.go:147]  "msg"="Adding toleration to pod"  "podName"="tf2-keras-cifar10-vgg16-elastic-20210723-045401-launcher" "scheduler"="default" "toleration"={"key":"celeste/hostname","operator":"Exists","effect":"NoExecute"}
I0723 16:55:32.324398    7682 placement_manager.go:147]  "msg"="Adding toleration to pod"  "podName"="tf2-keras-cifar10-resnet50-elastic-20210723-045445-launcher" "scheduler"="default" "toleration"={"key":"celeste/hostname","operator":"Exists","effect":"NoExecute"}
I0723 16:55:35.123431    7682 placement_manager.go:147]  "msg"="Adding toleration to pod"  "podName"="tf2-keras-cifar10-vgg16-elastic-20210723-045210-worker-0" "scheduler"="default" "toleration"={"key":"celeste/hostname","operator":"Equal","value":"gpu5","effect":"NoExecute"}
I0723 16:55:35.525553    7682 placement_manager.go:147]  "msg"="Adding toleration to pod"  "podName"="tf2-keras-cifar10-inceptionv3-elastic-20210723-044237-worker-0" "scheduler"="default" "toleration"={"key":"celeste/hostname","operator":"Equal","value":"gpu5","effect":"NoExecute"}
I0723 16:55:35.928976    7682 placement_manager.go:147]  "msg"="Adding toleration to pod"  "podName"="tf2-keras-transformer-elastic-20210723-045144-worker-0" "scheduler"="default" "toleration"={"key":"celeste/hostname","operator":"Equal","value":"gpu5","effect":"NoExecute"}
I0723 16:55:36.326783    7682 placement_manager.go:147]  "msg"="Adding toleration to pod"  "podName"="tf2-keras-cifar10-vgg16-elastic-20210723-045210-launcher" "scheduler"="default" "toleration"={"key":"celeste/hostname","operator":"Exists","effect":"NoExecute"}
I0723 16:55:37.576254    7682 placement_manager.go:147]  "msg"="Adding toleration to pod"  "podName"="tf2-keras-transformer-elastic-20210723-045144-launcher" "scheduler"="default" "toleration"={"key":"celeste/hostname","operator":"Exists","effect":"NoExecute"}
I0723 16:55:41.382836    7682 placement_manager.go:147]  "msg"="Adding toleration to pod"  "podName"="tf2-keras-cifar10-inceptionv3-elastic-20210723-044237-launcher" "scheduler"="default" "toleration"={"key":"celeste/hostname","operator":"Exists","effect":"NoExecute"}
I0723 16:55:44.768152    7682 placement_manager.go:147]  "msg"="Adding toleration to pod"  "podName"="tf2-keras-transformer-elastic-20210723-042834-launcher" "scheduler"="default" "toleration"={"key":"celeste/hostname","operator":"Exists","effect":"NoExecute"}
I0723 16:55:45.966632    7682 placement_manager.go:147]  "msg"="Adding toleration to pod"  "podName"="tf2-keras-transformer-elastic-20210723-042834-worker-0" "scheduler"="default" "toleration"={"key":"celeste/hostname","operator":"Equal","value":"gpu3","effect":"NoExecute"}
I0723 16:57:32.126627    7682 jobmaster.go:155]  "msg"="Training job created"  "job"="tf2-keras-cifar10-resnet50-elastic-20210723-045732"
I0723 16:57:32.126735    7682 scheduler.go:135]  "msg"="Received resched event, may be blocked because of rate limit"  "blockedUntil"="2021-07-23T16:57:26.805168271+08:00" "lastResched"="2021-07-23T16:55:26.805168271+08:00" "received"="2021-07-23T16:57:32.126232244+08:00" "scheduler"="default"
I0723 16:57:32.127293    7682 scheduler.go:159]  "msg"="Started resched"  "scheduler"="default"
I0723 16:57:32.127329    7682 scheduler.go:193]  "msg"="Updating all jobs info"  "scheduler"="default"
I0723 16:57:32.140886    7682 afsl.go:65]  "msg"="Finished scheduling"  "algorithm"="AFS-L" "freeGpu"=0 "result"={"tf2-keras-cifar10-inceptionv3-elastic-20210723-042550":1,"tf2-keras-cifar10-inceptionv3-elastic-20210723-042602":1,"tf2-keras-cifar10-inceptionv3-elastic-20210723-044237":0,"tf2-keras-cifar10-inceptionv3-elastic-20210723-045126":0,"tf2-keras-cifar10-inceptionv3-elastic-20210723-045447":0,"tf2-keras-cifar10-inceptionv3-elastic-20210723-045501":0,"tf2-keras-cifar10-resnet50-elastic-20210723-044700":1,"tf2-keras-cifar10-resnet50-elastic-20210723-045445":1,"tf2-keras-cifar10-resnet50-elastic-20210723-045732":1,"tf2-keras-cifar10-vgg16-elastic-20210723-042659":1,"tf2-keras-cifar10-vgg16-elastic-20210723-045210":1,"tf2-keras-cifar10-vgg16-elastic-20210723-045401":1,"tf2-keras-transformer-elastic-20210723-042834":1,"tf2-keras-transformer-elastic-20210723-043917":1,"tf2-keras-transformer-elastic-20210723-045144":1,"tf2-keras-transformer-elastic-20210723-045458":1} "scheduler"="default"
I0723 16:57:32.141247    7682 scheduler.go:384]  "msg"="Trying to delete multiple training jobs"  "jobs"=["tf2-keras-cifar10-inceptionv3-elastic-20210723-044237","tf2-keras-cifar10-inceptionv3-elastic-20210723-045501"] "scheduler"="default"
I0723 16:57:32.163909    7682 scheduler.go:342]  "msg"="Trying to scale multiple training jobs"  "jobs"=[] "scheduler"="default"
I0723 16:57:32.164229    7682 scheduler.go:292]  "msg"="Trying to start multiple training jobs"  "jobs"=["tf2-keras-cifar10-resnet50-elastic-20210723-045732","tf2-keras-cifar10-inceptionv3-elastic-20210723-042550"] "scheduler"="default"
I0723 16:57:32.191406    7682 scheduler.go:342]  "msg"="Trying to scale multiple training jobs"  "jobs"=[] "scheduler"="default"
I0723 16:57:32.196675    7682 placement_manager.go:166]  "msg"="Started job placements adjustment"  "scheduler"="default"
I0723 16:57:32.196755    7682 placement_manager.go:192]  "msg"="Releasing slots"  "jobs"={"tf2-keras-cifar10-inceptionv3-elastic-20210723-042602":{},"tf2-keras-cifar10-inceptionv3-elastic-20210723-044237":{},"tf2-keras-cifar10-inceptionv3-elastic-20210723-045501":{},"tf2-keras-cifar10-resnet50-elastic-20210723-044700":{},"tf2-keras-cifar10-resnet50-elastic-20210723-045445":{},"tf2-keras-cifar10-vgg16-elastic-20210723-042659":{},"tf2-keras-cifar10-vgg16-elastic-20210723-045210":{},"tf2-keras-cifar10-vgg16-elastic-20210723-045401":{},"tf2-keras-transformer-elastic-20210723-042834":{},"tf2-keras-transformer-elastic-20210723-043917":{},"tf2-keras-transformer-elastic-20210723-045144":{},"tf2-keras-transformer-elastic-20210723-045458":{}} "nodes"={"gpu3":{},"gpu4":{},"gpu5":{}} "scheduler"="default"
I0723 16:57:32.196830    7682 placement_manager.go:250]  "msg"="Released slots"  "jobs"={"tf2-keras-cifar10-inceptionv3-elastic-20210723-042602":{},"tf2-keras-cifar10-inceptionv3-elastic-20210723-044237":{},"tf2-keras-cifar10-inceptionv3-elastic-20210723-045501":{},"tf2-keras-cifar10-resnet50-elastic-20210723-044700":{},"tf2-keras-cifar10-resnet50-elastic-20210723-045445":{},"tf2-keras-cifar10-vgg16-elastic-20210723-042659":{},"tf2-keras-cifar10-vgg16-elastic-20210723-045210":{},"tf2-keras-cifar10-vgg16-elastic-20210723-045401":{},"tf2-keras-transformer-elastic-20210723-042834":{},"tf2-keras-transformer-elastic-20210723-043917":{},"tf2-keras-transformer-elastic-20210723-045144":{},"tf2-keras-transformer-elastic-20210723-045458":{}} "nodes"={"gpu3":{},"gpu4":{},"gpu5":{}} "scheduler"="default"
I0723 16:57:32.197277    7682 placement_manager.go:305]  "msg"="Found best-fit"  "crossNode"=0 "nodes"=[{},{},{}] "requests"=[{},{},{},{},{},{},{},{},{},{},{},{},{},{},{},{},{},{},{},{},{},{},{},{},{},{},{},{},{},{},{},{}] "scheduler"="default"
I0723 16:57:32.197566    7682 placement_manager.go:339]  "msg"="nodeStates updated"  "new"={"gpu3":{},"gpu4":{},"gpu5":{}} "old"={"gpu3":{},"gpu4":{},"gpu5":{}} "scheduler"="default" "score"=5
I0723 16:57:32.197915    7682 placement_manager.go:387]  "msg"="jobStates updated"  "new"={"tf2-keras-cifar10-inceptionv3-elastic-20210723-042550":{},"tf2-keras-cifar10-inceptionv3-elastic-20210723-042602":{},"tf2-keras-cifar10-resnet50-elastic-20210723-044700":{},"tf2-keras-cifar10-resnet50-elastic-20210723-045445":{},"tf2-keras-cifar10-resnet50-elastic-20210723-045732":{},"tf2-keras-cifar10-vgg16-elastic-20210723-042659":{},"tf2-keras-cifar10-vgg16-elastic-20210723-045210":{},"tf2-keras-cifar10-vgg16-elastic-20210723-045401":{},"tf2-keras-transformer-elastic-20210723-042834":{},"tf2-keras-transformer-elastic-20210723-043917":{},"tf2-keras-transformer-elastic-20210723-045144":{},"tf2-keras-transformer-elastic-20210723-045458":{}} "old"={"tf2-keras-cifar10-inceptionv3-elastic-20210723-042602":{},"tf2-keras-cifar10-inceptionv3-elastic-20210723-044237":{},"tf2-keras-cifar10-inceptionv3-elastic-20210723-045501":{},"tf2-keras-cifar10-resnet50-elastic-20210723-044700":{},"tf2-keras-cifar10-resnet50-elastic-20210723-045445":{},"tf2-keras-cifar10-vgg16-elastic-20210723-042659":{},"tf2-keras-cifar10-vgg16-elastic-20210723-045210":{},"tf2-keras-cifar10-vgg16-elastic-20210723-045401":{},"tf2-keras-transformer-elastic-20210723-042834":{},"tf2-keras-transformer-elastic-20210723-043917":{},"tf2-keras-transformer-elastic-20210723-045144":{},"tf2-keras-transformer-elastic-20210723-045458":{}} "scheduler"="default"
I0723 16:57:32.198319    7682 placement_manager.go:434]  "msg"="podNodeName updated"  "launchersToDelete"=5 "new"={"tf2-keras-cifar10-inceptionv3-elastic-20210723-042550-worker-0":"gpu5","tf2-keras-cifar10-inceptionv3-elastic-20210723-042602-worker-0":"gpu4","tf2-keras-cifar10-resnet50-elastic-20210723-044700-worker-0":"gpu3","tf2-keras-cifar10-resnet50-elastic-20210723-045445-worker-0":"gpu5","tf2-keras-cifar10-resnet50-elastic-20210723-045732-worker-0":"gpu3","tf2-keras-cifar10-vgg16-elastic-20210723-042659-worker-0":"gpu5","tf2-keras-cifar10-vgg16-elastic-20210723-045210-worker-0":"gpu5","tf2-keras-cifar10-vgg16-elastic-20210723-045401-worker-0":"gpu4","tf2-keras-transformer-elastic-20210723-042834-worker-0":"gpu4","tf2-keras-transformer-elastic-20210723-043917-worker-0":"gpu3","tf2-keras-transformer-elastic-20210723-045144-worker-0":"gpu3","tf2-keras-transformer-elastic-20210723-045458-worker-0":"gpu4"} "old"={"tf2-keras-cifar10-inceptionv3-elastic-20210723-042602-worker-0":"gpu4","tf2-keras-cifar10-inceptionv3-elastic-20210723-044237-worker-0":"gpu5","tf2-keras-cifar10-inceptionv3-elastic-20210723-045501-worker-0":"gpu4","tf2-keras-cifar10-resnet50-elastic-20210723-044700-worker-0":"gpu4","tf2-keras-cifar10-resnet50-elastic-20210723-045445-worker-0":"gpu3","tf2-keras-cifar10-vgg16-elastic-20210723-042659-worker-0":"gpu5","tf2-keras-cifar10-vgg16-elastic-20210723-045210-worker-0":"gpu5","tf2-keras-cifar10-vgg16-elastic-20210723-045401-worker-0":"gpu4","tf2-keras-transformer-elastic-20210723-042834-worker-0":"gpu3","tf2-keras-transformer-elastic-20210723-043917-worker-0":"gpu3","tf2-keras-transformer-elastic-20210723-045144-worker-0":"gpu5","tf2-keras-transformer-elastic-20210723-045458-worker-0":"gpu3"} "scheduler"="default" "workersToDelete"=5
I0723 16:57:32.198605    7682 placement_manager.go:451]  "msg"="Deleting pod that need migration"  "podName"="tf2-keras-transformer-elastic-20210723-045144-worker-0" "scheduler"="default"
I0723 16:57:32.202031    7682 placement_manager.go:451]  "msg"="Deleting pod that need migration"  "podName"="tf2-keras-transformer-elastic-20210723-045144-launcher" "scheduler"="default"
I0723 16:57:32.205788    7682 placement_manager.go:451]  "msg"="Deleting pod that need migration"  "podName"="tf2-keras-cifar10-resnet50-elastic-20210723-044700-worker-0" "scheduler"="default"
I0723 16:57:32.209462    7682 placement_manager.go:451]  "msg"="Deleting pod that need migration"  "podName"="tf2-keras-cifar10-resnet50-elastic-20210723-044700-launcher" "scheduler"="default"
I0723 16:57:32.214649    7682 placement_manager.go:451]  "msg"="Deleting pod that need migration"  "podName"="tf2-keras-cifar10-resnet50-elastic-20210723-045445-worker-0" "scheduler"="default"
I0723 16:57:32.218608    7682 placement_manager.go:451]  "msg"="Deleting pod that need migration"  "podName"="tf2-keras-cifar10-resnet50-elastic-20210723-045445-launcher" "scheduler"="default"
I0723 16:57:32.223249    7682 placement_manager.go:451]  "msg"="Deleting pod that need migration"  "podName"="tf2-keras-transformer-elastic-20210723-042834-worker-0" "scheduler"="default"
I0723 16:57:32.230466    7682 placement_manager.go:451]  "msg"="Deleting pod that need migration"  "podName"="tf2-keras-transformer-elastic-20210723-042834-launcher" "scheduler"="default"
I0723 16:57:32.237691    7682 placement_manager.go:451]  "msg"="Deleting pod that need migration"  "podName"="tf2-keras-transformer-elastic-20210723-045458-worker-0" "scheduler"="default"
I0723 16:57:32.245106    7682 placement_manager.go:451]  "msg"="Deleting pod that need migration"  "podName"="tf2-keras-transformer-elastic-20210723-045458-launcher" "scheduler"="default"
I0723 16:57:32.249650    7682 placement_manager.go:183]  "msg"="Finished job placements adjustment"  "scheduler"="default"
I0723 16:57:32.249960    7682 scheduler.go:182]  "msg"="Finished resched"  "scheduler"="default"
I0723 16:57:32.391133    7682 placement_manager.go:147]  "msg"="Adding toleration to pod"  "podName"="tf2-keras-cifar10-resnet50-elastic-20210723-045732-worker-0" "scheduler"="default" "toleration"={"key":"celeste/hostname","operator":"Equal","value":"gpu3","effect":"NoExecute"}
I0723 16:57:32.605714    7682 placement_manager.go:147]  "msg"="Adding toleration to pod"  "podName"="tf2-keras-cifar10-inceptionv3-elastic-20210723-042550-worker-0" "scheduler"="default" "toleration"={"key":"celeste/hostname","operator":"Equal","value":"gpu5","effect":"NoExecute"}
I0723 16:57:33.007301    7682 placement_manager.go:147]  "msg"="Adding toleration to pod"  "podName"="tf2-keras-cifar10-resnet50-elastic-20210723-045732-launcher" "scheduler"="default" "toleration"={"key":"celeste/hostname","operator":"Exists","effect":"NoExecute"}
I0723 16:57:33.408257    7682 placement_manager.go:147]  "msg"="Adding toleration to pod"  "podName"="tf2-keras-cifar10-inceptionv3-elastic-20210723-042550-launcher" "scheduler"="default" "toleration"={"key":"celeste/hostname","operator":"Exists","effect":"NoExecute"}
I0723 16:57:40.888139    7682 placement_manager.go:147]  "msg"="Adding toleration to pod"  "podName"="tf2-keras-cifar10-resnet50-elastic-20210723-045445-worker-0" "scheduler"="default" "toleration"={"key":"celeste/hostname","operator":"Equal","value":"gpu5","effect":"NoExecute"}
I0723 16:57:41.487120    7682 placement_manager.go:147]  "msg"="Adding toleration to pod"  "podName"="tf2-keras-cifar10-resnet50-elastic-20210723-044700-launcher" "scheduler"="default" "toleration"={"key":"celeste/hostname","operator":"Exists","effect":"NoExecute"}
I0723 16:57:42.086582    7682 placement_manager.go:147]  "msg"="Adding toleration to pod"  "podName"="tf2-keras-transformer-elastic-20210723-042834-worker-0" "scheduler"="default" "toleration"={"key":"celeste/hostname","operator":"Equal","value":"gpu4","effect":"NoExecute"}
I0723 16:57:43.086228    7682 placement_manager.go:147]  "msg"="Adding toleration to pod"  "podName"="tf2-keras-transformer-elastic-20210723-045458-worker-0" "scheduler"="default" "toleration"={"key":"celeste/hostname","operator":"Equal","value":"gpu4","effect":"NoExecute"}
I0723 16:57:46.931916    7682 placement_manager.go:147]  "msg"="Adding toleration to pod"  "podName"="tf2-keras-transformer-elastic-20210723-045458-launcher" "scheduler"="default" "toleration"={"key":"celeste/hostname","operator":"Exists","effect":"NoExecute"}
I0723 16:57:49.735864    7682 placement_manager.go:147]  "msg"="Adding toleration to pod"  "podName"="tf2-keras-transformer-elastic-20210723-042834-launcher" "scheduler"="default" "toleration"={"key":"celeste/hostname","operator":"Exists","effect":"NoExecute"}
I0723 16:57:50.338949    7682 placement_manager.go:147]  "msg"="Adding toleration to pod"  "podName"="tf2-keras-transformer-elastic-20210723-045144-worker-0" "scheduler"="default" "toleration"={"key":"celeste/hostname","operator":"Equal","value":"gpu3","effect":"NoExecute"}
I0723 16:57:55.734155    7682 placement_manager.go:147]  "msg"="Adding toleration to pod"  "podName"="tf2-keras-transformer-elastic-20210723-045144-launcher" "scheduler"="default" "toleration"={"key":"celeste/hostname","operator":"Exists","effect":"NoExecute"}
I0723 16:57:58.142493    7682 placement_manager.go:147]  "msg"="Adding toleration to pod"  "podName"="tf2-keras-cifar10-resnet50-elastic-20210723-044700-worker-0" "scheduler"="default" "toleration"={"key":"celeste/hostname","operator":"Equal","value":"gpu3","effect":"NoExecute"}
I0723 16:57:58.931316    7682 placement_manager.go:147]  "msg"="Adding toleration to pod"  "podName"="tf2-keras-cifar10-resnet50-elastic-20210723-045445-launcher" "scheduler"="default" "toleration"={"key":"celeste/hostname","operator":"Exists","effect":"NoExecute"}
I0723 17:02:39.507018    7682 scheduler.go:474]  "msg"="Training job completed"  "elaspedTotalSeconds"=2044.123960213 "gpuTotalSeconds"=3505.101194068 "job"="tf2-keras-transformer-elastic-20210723-042834" "ranTotalSeconds"=1970.058155004 "scheduler"="default" "waitedTotalSeconds"=74.065805209
I0723 17:02:39.507147    7682 scheduler.go:135]  "msg"="Received resched event, may be blocked because of rate limit"  "blockedUntil"="2021-07-23T16:59:32.250230752+08:00" "lastResched"="2021-07-23T16:57:32.250230752+08:00" "received"="2021-07-23T17:02:39.507049891+08:00" "scheduler"="default"
I0723 17:02:39.508214    7682 scheduler.go:159]  "msg"="Started resched"  "scheduler"="default"
I0723 17:02:39.508303    7682 scheduler.go:193]  "msg"="Updating all jobs info"  "scheduler"="default"
I0723 17:02:39.522057    7682 afsl.go:65]  "msg"="Finished scheduling"  "algorithm"="AFS-L" "freeGpu"=0 "result"={"tf2-keras-cifar10-inceptionv3-elastic-20210723-042550":1,"tf2-keras-cifar10-inceptionv3-elastic-20210723-042602":1,"tf2-keras-cifar10-inceptionv3-elastic-20210723-044237":1,"tf2-keras-cifar10-inceptionv3-elastic-20210723-045126":0,"tf2-keras-cifar10-inceptionv3-elastic-20210723-045447":0,"tf2-keras-cifar10-inceptionv3-elastic-20210723-045501":0,"tf2-keras-cifar10-resnet50-elastic-20210723-044700":1,"tf2-keras-cifar10-resnet50-elastic-20210723-045445":1,"tf2-keras-cifar10-resnet50-elastic-20210723-045732":1,"tf2-keras-cifar10-vgg16-elastic-20210723-042659":1,"tf2-keras-cifar10-vgg16-elastic-20210723-045210":1,"tf2-keras-cifar10-vgg16-elastic-20210723-045401":1,"tf2-keras-transformer-elastic-20210723-043917":1,"tf2-keras-transformer-elastic-20210723-045144":1,"tf2-keras-transformer-elastic-20210723-045458":1} "scheduler"="default"
I0723 17:02:39.522463    7682 scheduler.go:384]  "msg"="Trying to delete multiple training jobs"  "jobs"=[] "scheduler"="default"
I0723 17:02:39.522721    7682 scheduler.go:342]  "msg"="Trying to scale multiple training jobs"  "jobs"=[] "scheduler"="default"
I0723 17:02:39.523082    7682 scheduler.go:292]  "msg"="Trying to start multiple training jobs"  "jobs"=["tf2-keras-cifar10-inceptionv3-elastic-20210723-044237"] "scheduler"="default"
I0723 17:02:39.531202    7682 scheduler.go:342]  "msg"="Trying to scale multiple training jobs"  "jobs"=[] "scheduler"="default"
I0723 17:02:39.535768    7682 placement_manager.go:166]  "msg"="Started job placements adjustment"  "scheduler"="default"
I0723 17:02:39.535827    7682 placement_manager.go:192]  "msg"="Releasing slots"  "jobs"={"tf2-keras-cifar10-inceptionv3-elastic-20210723-042550":{},"tf2-keras-cifar10-inceptionv3-elastic-20210723-042602":{},"tf2-keras-cifar10-resnet50-elastic-20210723-044700":{},"tf2-keras-cifar10-resnet50-elastic-20210723-045445":{},"tf2-keras-cifar10-resnet50-elastic-20210723-045732":{},"tf2-keras-cifar10-vgg16-elastic-20210723-042659":{},"tf2-keras-cifar10-vgg16-elastic-20210723-045210":{},"tf2-keras-cifar10-vgg16-elastic-20210723-045401":{},"tf2-keras-transformer-elastic-20210723-042834":{},"tf2-keras-transformer-elastic-20210723-043917":{},"tf2-keras-transformer-elastic-20210723-045144":{},"tf2-keras-transformer-elastic-20210723-045458":{}} "nodes"={"gpu3":{},"gpu4":{},"gpu5":{}} "scheduler"="default"
I0723 17:02:39.535879    7682 placement_manager.go:250]  "msg"="Released slots"  "jobs"={"tf2-keras-cifar10-inceptionv3-elastic-20210723-042550":{},"tf2-keras-cifar10-inceptionv3-elastic-20210723-042602":{},"tf2-keras-cifar10-resnet50-elastic-20210723-044700":{},"tf2-keras-cifar10-resnet50-elastic-20210723-045445":{},"tf2-keras-cifar10-resnet50-elastic-20210723-045732":{},"tf2-keras-cifar10-vgg16-elastic-20210723-042659":{},"tf2-keras-cifar10-vgg16-elastic-20210723-045210":{},"tf2-keras-cifar10-vgg16-elastic-20210723-045401":{},"tf2-keras-transformer-elastic-20210723-042834":{},"tf2-keras-transformer-elastic-20210723-043917":{},"tf2-keras-transformer-elastic-20210723-045144":{},"tf2-keras-transformer-elastic-20210723-045458":{}} "nodes"={"gpu3":{},"gpu4":{},"gpu5":{}} "scheduler"="default"
I0723 17:02:39.536334    7682 placement_manager.go:305]  "msg"="Found best-fit"  "crossNode"=0 "nodes"=[{},{},{}] "requests"=[{},{},{},{},{},{},{},{},{},{},{},{},{},{},{},{},{},{},{},{},{},{},{},{},{},{},{},{},{},{}] "scheduler"="default"
I0723 17:02:39.536669    7682 placement_manager.go:339]  "msg"="nodeStates updated"  "new"={"gpu3":{},"gpu4":{},"gpu5":{}} "old"={"gpu3":{},"gpu4":{},"gpu5":{}} "scheduler"="default" "score"=7
I0723 17:02:39.536991    7682 placement_manager.go:387]  "msg"="jobStates updated"  "new"={"tf2-keras-cifar10-inceptionv3-elastic-20210723-042550":{},"tf2-keras-cifar10-inceptionv3-elastic-20210723-042602":{},"tf2-keras-cifar10-inceptionv3-elastic-20210723-044237":{},"tf2-keras-cifar10-resnet50-elastic-20210723-044700":{},"tf2-keras-cifar10-resnet50-elastic-20210723-045445":{},"tf2-keras-cifar10-resnet50-elastic-20210723-045732":{},"tf2-keras-cifar10-vgg16-elastic-20210723-042659":{},"tf2-keras-cifar10-vgg16-elastic-20210723-045210":{},"tf2-keras-cifar10-vgg16-elastic-20210723-045401":{},"tf2-keras-transformer-elastic-20210723-043917":{},"tf2-keras-transformer-elastic-20210723-045144":{},"tf2-keras-transformer-elastic-20210723-045458":{}} "old"={"tf2-keras-cifar10-inceptionv3-elastic-20210723-042550":{},"tf2-keras-cifar10-inceptionv3-elastic-20210723-042602":{},"tf2-keras-cifar10-resnet50-elastic-20210723-044700":{},"tf2-keras-cifar10-resnet50-elastic-20210723-045445":{},"tf2-keras-cifar10-resnet50-elastic-20210723-045732":{},"tf2-keras-cifar10-vgg16-elastic-20210723-042659":{},"tf2-keras-cifar10-vgg16-elastic-20210723-045210":{},"tf2-keras-cifar10-vgg16-elastic-20210723-045401":{},"tf2-keras-transformer-elastic-20210723-042834":{},"tf2-keras-transformer-elastic-20210723-043917":{},"tf2-keras-transformer-elastic-20210723-045144":{},"tf2-keras-transformer-elastic-20210723-045458":{}} "scheduler"="default"
I0723 17:02:39.537369    7682 placement_manager.go:434]  "msg"="podNodeName updated"  "launchersToDelete"=4 "new"={"tf2-keras-cifar10-inceptionv3-elastic-20210723-042550-worker-0":"gpu3","tf2-keras-cifar10-inceptionv3-elastic-20210723-042602-worker-0":"gpu4","tf2-keras-cifar10-inceptionv3-elastic-20210723-044237-worker-0":"gpu4","tf2-keras-cifar10-resnet50-elastic-20210723-044700-worker-0":"gpu5","tf2-keras-cifar10-resnet50-elastic-20210723-045445-worker-0":"gpu5","tf2-keras-cifar10-resnet50-elastic-20210723-045732-worker-0":"gpu3","tf2-keras-cifar10-vgg16-elastic-20210723-042659-worker-0":"gpu4","tf2-keras-cifar10-vgg16-elastic-20210723-045210-worker-0":"gpu5","tf2-keras-cifar10-vgg16-elastic-20210723-045401-worker-0":"gpu5","tf2-keras-transformer-elastic-20210723-043917-worker-0":"gpu3","tf2-keras-transformer-elastic-20210723-045144-worker-0":"gpu3","tf2-keras-transformer-elastic-20210723-045458-worker-0":"gpu4"} "old"={"tf2-keras-cifar10-inceptionv3-elastic-20210723-042550-worker-0":"gpu5","tf2-keras-cifar10-inceptionv3-elastic-20210723-042602-worker-0":"gpu4","tf2-keras-cifar10-resnet50-elastic-20210723-044700-worker-0":"gpu3","tf2-keras-cifar10-resnet50-elastic-20210723-045445-worker-0":"gpu5","tf2-keras-cifar10-resnet50-elastic-20210723-045732-worker-0":"gpu3","tf2-keras-cifar10-vgg16-elastic-20210723-042659-worker-0":"gpu5","tf2-keras-cifar10-vgg16-elastic-20210723-045210-worker-0":"gpu5","tf2-keras-cifar10-vgg16-elastic-20210723-045401-worker-0":"gpu4","tf2-keras-transformer-elastic-20210723-042834-worker-0":"gpu4","tf2-keras-transformer-elastic-20210723-043917-worker-0":"gpu3","tf2-keras-transformer-elastic-20210723-045144-worker-0":"gpu3","tf2-keras-transformer-elastic-20210723-045458-worker-0":"gpu4"} "scheduler"="default" "workersToDelete"=4
I0723 17:02:39.537609    7682 placement_manager.go:451]  "msg"="Deleting pod that need migration"  "podName"="tf2-keras-cifar10-vgg16-elastic-20210723-042659-worker-0" "scheduler"="default"
I0723 17:02:39.546320    7682 placement_manager.go:451]  "msg"="Deleting pod that need migration"  "podName"="tf2-keras-cifar10-vgg16-elastic-20210723-042659-launcher" "scheduler"="default"
I0723 17:02:39.555087    7682 placement_manager.go:451]  "msg"="Deleting pod that need migration"  "podName"="tf2-keras-cifar10-inceptionv3-elastic-20210723-042550-worker-0" "scheduler"="default"
I0723 17:02:39.559033    7682 placement_manager.go:451]  "msg"="Deleting pod that need migration"  "podName"="tf2-keras-cifar10-inceptionv3-elastic-20210723-042550-launcher" "scheduler"="default"
I0723 17:02:39.562718    7682 placement_manager.go:451]  "msg"="Deleting pod that need migration"  "podName"="tf2-keras-cifar10-resnet50-elastic-20210723-044700-worker-0" "scheduler"="default"
I0723 17:02:39.565731    7682 placement_manager.go:451]  "msg"="Deleting pod that need migration"  "podName"="tf2-keras-cifar10-resnet50-elastic-20210723-044700-launcher" "scheduler"="default"
I0723 17:02:39.569278    7682 placement_manager.go:451]  "msg"="Deleting pod that need migration"  "podName"="tf2-keras-cifar10-vgg16-elastic-20210723-045401-worker-0" "scheduler"="default"
I0723 17:02:39.573383    7682 placement_manager.go:451]  "msg"="Deleting pod that need migration"  "podName"="tf2-keras-cifar10-vgg16-elastic-20210723-045401-launcher" "scheduler"="default"
I0723 17:02:39.577522    7682 placement_manager.go:183]  "msg"="Finished job placements adjustment"  "scheduler"="default"
I0723 17:02:39.577745    7682 scheduler.go:182]  "msg"="Finished resched"  "scheduler"="default"
I0723 17:02:39.904404    7682 placement_manager.go:147]  "msg"="Adding toleration to pod"  "podName"="tf2-keras-cifar10-inceptionv3-elastic-20210723-044237-worker-0" "scheduler"="default" "toleration"={"key":"celeste/hostname","operator":"Equal","value":"gpu4","effect":"NoExecute"}
I0723 17:02:40.301514    7682 placement_manager.go:147]  "msg"="Adding toleration to pod"  "podName"="tf2-keras-cifar10-inceptionv3-elastic-20210723-044237-launcher" "scheduler"="default" "toleration"={"key":"celeste/hostname","operator":"Exists","effect":"NoExecute"}
I0723 17:02:47.067100    7682 placement_manager.go:147]  "msg"="Adding toleration to pod"  "podName"="tf2-keras-cifar10-inceptionv3-elastic-20210723-042550-launcher" "scheduler"="default" "toleration"={"key":"celeste/hostname","operator":"Exists","effect":"NoExecute"}
I0723 17:02:53.849606    7682 placement_manager.go:147]  "msg"="Adding toleration to pod"  "podName"="tf2-keras-cifar10-resnet50-elastic-20210723-044700-worker-0" "scheduler"="default" "toleration"={"key":"celeste/hostname","operator":"Equal","value":"gpu5","effect":"NoExecute"}
I0723 17:02:54.594800    7682 placement_manager.go:147]  "msg"="Adding toleration to pod"  "podName"="tf2-keras-cifar10-resnet50-elastic-20210723-044700-launcher" "scheduler"="default" "toleration"={"key":"celeste/hostname","operator":"Exists","effect":"NoExecute"}
I0723 17:02:54.631504    7682 placement_manager.go:147]  "msg"="Adding toleration to pod"  "podName"="tf2-keras-cifar10-vgg16-elastic-20210723-045401-worker-0" "scheduler"="default" "toleration"={"key":"celeste/hostname","operator":"Equal","value":"gpu5","effect":"NoExecute"}
I0723 17:03:01.124683    7682 placement_manager.go:147]  "msg"="Adding toleration to pod"  "podName"="tf2-keras-cifar10-vgg16-elastic-20210723-042659-launcher" "scheduler"="default" "toleration"={"key":"celeste/hostname","operator":"Exists","effect":"NoExecute"}
I0723 17:03:03.524612    7682 placement_manager.go:147]  "msg"="Adding toleration to pod"  "podName"="tf2-keras-cifar10-vgg16-elastic-20210723-045401-launcher" "scheduler"="default" "toleration"={"key":"celeste/hostname","operator":"Exists","effect":"NoExecute"}
I0723 17:03:04.740857    7682 placement_manager.go:147]  "msg"="Adding toleration to pod"  "podName"="tf2-keras-cifar10-vgg16-elastic-20210723-042659-worker-0" "scheduler"="default" "toleration"={"key":"celeste/hostname","operator":"Equal","value":"gpu4","effect":"NoExecute"}
I0723 17:03:05.526376    7682 placement_manager.go:147]  "msg"="Adding toleration to pod"  "podName"="tf2-keras-cifar10-inceptionv3-elastic-20210723-042550-worker-0" "scheduler"="default" "toleration"={"key":"celeste/hostname","operator":"Equal","value":"gpu3","effect":"NoExecute"}
I0723 17:08:26.457390    7682 scheduler.go:474]  "msg"="Training job completed"  "elaspedTotalSeconds"=2484.132311408 "gpuTotalSeconds"=4895.141546346 "job"="tf2-keras-cifar10-vgg16-elastic-20210723-042659" "ranTotalSeconds"=2435.072965701 "scheduler"="default" "waitedTotalSeconds"=49.059345707
I0723 17:08:26.457570    7682 scheduler.go:135]  "msg"="Received resched event, may be blocked because of rate limit"  "blockedUntil"="2021-07-23T17:04:39.577965896+08:00" "lastResched"="2021-07-23T17:02:39.577965896+08:00" "received"="2021-07-23T17:08:26.45744449+08:00" "scheduler"="default"
I0723 17:08:26.458001    7682 scheduler.go:159]  "msg"="Started resched"  "scheduler"="default"
I0723 17:08:26.458082    7682 scheduler.go:193]  "msg"="Updating all jobs info"  "scheduler"="default"
I0723 17:08:26.471116    7682 afsl.go:65]  "msg"="Finished scheduling"  "algorithm"="AFS-L" "freeGpu"=0 "result"={"tf2-keras-cifar10-inceptionv3-elastic-20210723-042550":1,"tf2-keras-cifar10-inceptionv3-elastic-20210723-042602":1,"tf2-keras-cifar10-inceptionv3-elastic-20210723-044237":1,"tf2-keras-cifar10-inceptionv3-elastic-20210723-045126":0,"tf2-keras-cifar10-inceptionv3-elastic-20210723-045447":0,"tf2-keras-cifar10-inceptionv3-elastic-20210723-045501":1,"tf2-keras-cifar10-resnet50-elastic-20210723-044700":1,"tf2-keras-cifar10-resnet50-elastic-20210723-045445":1,"tf2-keras-cifar10-resnet50-elastic-20210723-045732":1,"tf2-keras-cifar10-vgg16-elastic-20210723-045210":1,"tf2-keras-cifar10-vgg16-elastic-20210723-045401":1,"tf2-keras-transformer-elastic-20210723-043917":1,"tf2-keras-transformer-elastic-20210723-045144":1,"tf2-keras-transformer-elastic-20210723-045458":1} "scheduler"="default"
I0723 17:08:26.471541    7682 scheduler.go:384]  "msg"="Trying to delete multiple training jobs"  "jobs"=[] "scheduler"="default"
I0723 17:08:26.471767    7682 scheduler.go:342]  "msg"="Trying to scale multiple training jobs"  "jobs"=[] "scheduler"="default"
I0723 17:08:26.472038    7682 scheduler.go:292]  "msg"="Trying to start multiple training jobs"  "jobs"=["tf2-keras-cifar10-inceptionv3-elastic-20210723-045501"] "scheduler"="default"
I0723 17:08:26.479912    7682 scheduler.go:342]  "msg"="Trying to scale multiple training jobs"  "jobs"=[] "scheduler"="default"
I0723 17:08:26.484568    7682 placement_manager.go:166]  "msg"="Started job placements adjustment"  "scheduler"="default"
I0723 17:08:26.484646    7682 placement_manager.go:192]  "msg"="Releasing slots"  "jobs"={"tf2-keras-cifar10-inceptionv3-elastic-20210723-042550":{},"tf2-keras-cifar10-inceptionv3-elastic-20210723-042602":{},"tf2-keras-cifar10-inceptionv3-elastic-20210723-044237":{},"tf2-keras-cifar10-resnet50-elastic-20210723-044700":{},"tf2-keras-cifar10-resnet50-elastic-20210723-045445":{},"tf2-keras-cifar10-resnet50-elastic-20210723-045732":{},"tf2-keras-cifar10-vgg16-elastic-20210723-042659":{},"tf2-keras-cifar10-vgg16-elastic-20210723-045210":{},"tf2-keras-cifar10-vgg16-elastic-20210723-045401":{},"tf2-keras-transformer-elastic-20210723-043917":{},"tf2-keras-transformer-elastic-20210723-045144":{},"tf2-keras-transformer-elastic-20210723-045458":{}} "nodes"={"gpu3":{},"gpu4":{},"gpu5":{}} "scheduler"="default"
I0723 17:08:26.484712    7682 placement_manager.go:250]  "msg"="Released slots"  "jobs"={"tf2-keras-cifar10-inceptionv3-elastic-20210723-042550":{},"tf2-keras-cifar10-inceptionv3-elastic-20210723-042602":{},"tf2-keras-cifar10-inceptionv3-elastic-20210723-044237":{},"tf2-keras-cifar10-resnet50-elastic-20210723-044700":{},"tf2-keras-cifar10-resnet50-elastic-20210723-045445":{},"tf2-keras-cifar10-resnet50-elastic-20210723-045732":{},"tf2-keras-cifar10-vgg16-elastic-20210723-042659":{},"tf2-keras-cifar10-vgg16-elastic-20210723-045210":{},"tf2-keras-cifar10-vgg16-elastic-20210723-045401":{},"tf2-keras-transformer-elastic-20210723-043917":{},"tf2-keras-transformer-elastic-20210723-045144":{},"tf2-keras-transformer-elastic-20210723-045458":{}} "nodes"={"gpu3":{},"gpu4":{},"gpu5":{}} "scheduler"="default"
I0723 17:08:26.485274    7682 placement_manager.go:305]  "msg"="Found best-fit"  "crossNode"=0 "nodes"=[{},{},{}] "requests"=[{},{},{},{},{},{},{},{},{},{},{},{},{},{},{},{},{},{},{},{},{},{},{},{},{},{},{},{}] "scheduler"="default"
I0723 17:08:26.485598    7682 placement_manager.go:339]  "msg"="nodeStates updated"  "new"={"gpu3":{},"gpu4":{},"gpu5":{}} "old"={"gpu3":{},"gpu4":{},"gpu5":{}} "scheduler"="default" "score"=7
I0723 17:08:26.486127    7682 placement_manager.go:387]  "msg"="jobStates updated"  "new"={"tf2-keras-cifar10-inceptionv3-elastic-20210723-042550":{},"tf2-keras-cifar10-inceptionv3-elastic-20210723-042602":{},"tf2-keras-cifar10-inceptionv3-elastic-20210723-044237":{},"tf2-keras-cifar10-inceptionv3-elastic-20210723-045501":{},"tf2-keras-cifar10-resnet50-elastic-20210723-044700":{},"tf2-keras-cifar10-resnet50-elastic-20210723-045445":{},"tf2-keras-cifar10-resnet50-elastic-20210723-045732":{},"tf2-keras-cifar10-vgg16-elastic-20210723-045210":{},"tf2-keras-cifar10-vgg16-elastic-20210723-045401":{},"tf2-keras-transformer-elastic-20210723-043917":{},"tf2-keras-transformer-elastic-20210723-045144":{},"tf2-keras-transformer-elastic-20210723-045458":{}} "old"={"tf2-keras-cifar10-inceptionv3-elastic-20210723-042550":{},"tf2-keras-cifar10-inceptionv3-elastic-20210723-042602":{},"tf2-keras-cifar10-inceptionv3-elastic-20210723-044237":{},"tf2-keras-cifar10-resnet50-elastic-20210723-044700":{},"tf2-keras-cifar10-resnet50-elastic-20210723-045445":{},"tf2-keras-cifar10-resnet50-elastic-20210723-045732":{},"tf2-keras-cifar10-vgg16-elastic-20210723-042659":{},"tf2-keras-cifar10-vgg16-elastic-20210723-045210":{},"tf2-keras-cifar10-vgg16-elastic-20210723-045401":{},"tf2-keras-transformer-elastic-20210723-043917":{},"tf2-keras-transformer-elastic-20210723-045144":{},"tf2-keras-transformer-elastic-20210723-045458":{}} "scheduler"="default"
I0723 17:08:26.486539    7682 placement_manager.go:434]  "msg"="podNodeName updated"  "launchersToDelete"=4 "new"={"tf2-keras-cifar10-inceptionv3-elastic-20210723-042550-worker-0":"gpu3","tf2-keras-cifar10-inceptionv3-elastic-20210723-042602-worker-0":"gpu3","tf2-keras-cifar10-inceptionv3-elastic-20210723-044237-worker-0":"gpu4","tf2-keras-cifar10-inceptionv3-elastic-20210723-045501-worker-0":"gpu3","tf2-keras-cifar10-resnet50-elastic-20210723-044700-worker-0":"gpu5","tf2-keras-cifar10-resnet50-elastic-20210723-045445-worker-0":"gpu5","tf2-keras-cifar10-resnet50-elastic-20210723-045732-worker-0":"gpu3","tf2-keras-cifar10-vgg16-elastic-20210723-045210-worker-0":"gpu4","tf2-keras-cifar10-vgg16-elastic-20210723-045401-worker-0":"gpu5","tf2-keras-transformer-elastic-20210723-043917-worker-0":"gpu5","tf2-keras-transformer-elastic-20210723-045144-worker-0":"gpu4","tf2-keras-transformer-elastic-20210723-045458-worker-0":"gpu4"} "old"={"tf2-keras-cifar10-inceptionv3-elastic-20210723-042550-worker-0":"gpu3","tf2-keras-cifar10-inceptionv3-elastic-20210723-042602-worker-0":"gpu4","tf2-keras-cifar10-inceptionv3-elastic-20210723-044237-worker-0":"gpu4","tf2-keras-cifar10-resnet50-elastic-20210723-044700-worker-0":"gpu5","tf2-keras-cifar10-resnet50-elastic-20210723-045445-worker-0":"gpu5","tf2-keras-cifar10-resnet50-elastic-20210723-045732-worker-0":"gpu3","tf2-keras-cifar10-vgg16-elastic-20210723-042659-worker-0":"gpu4","tf2-keras-cifar10-vgg16-elastic-20210723-045210-worker-0":"gpu5","tf2-keras-cifar10-vgg16-elastic-20210723-045401-worker-0":"gpu5","tf2-keras-transformer-elastic-20210723-043917-worker-0":"gpu3","tf2-keras-transformer-elastic-20210723-045144-worker-0":"gpu3","tf2-keras-transformer-elastic-20210723-045458-worker-0":"gpu4"} "scheduler"="default" "workersToDelete"=4
I0723 17:08:26.486830    7682 placement_manager.go:451]  "msg"="Deleting pod that need migration"  "podName"="tf2-keras-cifar10-inceptionv3-elastic-20210723-042602-worker-0" "scheduler"="default"
I0723 17:08:26.490606    7682 placement_manager.go:451]  "msg"="Deleting pod that need migration"  "podName"="tf2-keras-cifar10-inceptionv3-elastic-20210723-042602-launcher" "scheduler"="default"
I0723 17:08:26.494928    7682 placement_manager.go:451]  "msg"="Deleting pod that need migration"  "podName"="tf2-keras-transformer-elastic-20210723-043917-worker-0" "scheduler"="default"
I0723 17:08:26.517937    7682 placement_manager.go:451]  "msg"="Deleting pod that need migration"  "podName"="tf2-keras-transformer-elastic-20210723-043917-launcher" "scheduler"="default"
I0723 17:08:26.522489    7682 placement_manager.go:451]  "msg"="Deleting pod that need migration"  "podName"="tf2-keras-transformer-elastic-20210723-045144-worker-0" "scheduler"="default"
I0723 17:08:26.526817    7682 placement_manager.go:451]  "msg"="Deleting pod that need migration"  "podName"="tf2-keras-transformer-elastic-20210723-045144-launcher" "scheduler"="default"
I0723 17:08:26.534247    7682 placement_manager.go:451]  "msg"="Deleting pod that need migration"  "podName"="tf2-keras-cifar10-vgg16-elastic-20210723-045210-worker-0" "scheduler"="default"
I0723 17:08:26.541647    7682 placement_manager.go:451]  "msg"="Deleting pod that need migration"  "podName"="tf2-keras-cifar10-vgg16-elastic-20210723-045210-launcher" "scheduler"="default"
I0723 17:08:26.549465    7682 placement_manager.go:183]  "msg"="Finished job placements adjustment"  "scheduler"="default"
I0723 17:08:26.549768    7682 scheduler.go:182]  "msg"="Finished resched"  "scheduler"="default"
I0723 17:08:26.650924    7682 placement_manager.go:147]  "msg"="Adding toleration to pod"  "podName"="tf2-keras-cifar10-inceptionv3-elastic-20210723-045501-worker-0" "scheduler"="default" "toleration"={"key":"celeste/hostname","operator":"Equal","value":"gpu3","effect":"NoExecute"}
I0723 17:08:27.053653    7682 placement_manager.go:147]  "msg"="Adding toleration to pod"  "podName"="tf2-keras-cifar10-inceptionv3-elastic-20210723-045501-launcher" "scheduler"="default" "toleration"={"key":"celeste/hostname","operator":"Exists","effect":"NoExecute"}
I0723 17:08:39.746811    7682 placement_manager.go:147]  "msg"="Adding toleration to pod"  "podName"="tf2-keras-cifar10-vgg16-elastic-20210723-045210-worker-0" "scheduler"="default" "toleration"={"key":"celeste/hostname","operator":"Equal","value":"gpu4","effect":"NoExecute"}
I0723 17:08:39.797279    7682 placement_manager.go:147]  "msg"="Adding toleration to pod"  "podName"="tf2-keras-cifar10-vgg16-elastic-20210723-045210-launcher" "scheduler"="default" "toleration"={"key":"celeste/hostname","operator":"Exists","effect":"NoExecute"}
I0723 17:08:43.851059    7682 placement_manager.go:147]  "msg"="Adding toleration to pod"  "podName"="tf2-keras-transformer-elastic-20210723-043917-launcher" "scheduler"="default" "toleration"={"key":"celeste/hostname","operator":"Exists","effect":"NoExecute"}
I0723 17:08:43.903888    7682 placement_manager.go:147]  "msg"="Adding toleration to pod"  "podName"="tf2-keras-transformer-elastic-20210723-045144-launcher" "scheduler"="default" "toleration"={"key":"celeste/hostname","operator":"Exists","effect":"NoExecute"}
I0723 17:08:43.915303    7682 placement_manager.go:147]  "msg"="Adding toleration to pod"  "podName"="tf2-keras-transformer-elastic-20210723-043917-worker-0" "scheduler"="default" "toleration"={"key":"celeste/hostname","operator":"Equal","value":"gpu5","effect":"NoExecute"}
I0723 17:08:43.923986    7682 placement_manager.go:147]  "msg"="Adding toleration to pod"  "podName"="tf2-keras-transformer-elastic-20210723-045144-worker-0" "scheduler"="default" "toleration"={"key":"celeste/hostname","operator":"Equal","value":"gpu4","effect":"NoExecute"}
I0723 17:08:45.825391    7682 placement_manager.go:147]  "msg"="Adding toleration to pod"  "podName"="tf2-keras-cifar10-inceptionv3-elastic-20210723-042602-worker-0" "scheduler"="default" "toleration"={"key":"celeste/hostname","operator":"Equal","value":"gpu3","effect":"NoExecute"}
I0723 17:08:48.830286    7682 placement_manager.go:147]  "msg"="Adding toleration to pod"  "podName"="tf2-keras-cifar10-inceptionv3-elastic-20210723-042602-launcher" "scheduler"="default" "toleration"={"key":"celeste/hostname","operator":"Exists","effect":"NoExecute"}
I0723 17:09:16.601653    7682 scheduler.go:474]  "msg"="Training job completed"  "elaspedTotalSeconds"=1333.798848064 "gpuTotalSeconds"=1940.060840191 "job"="tf2-keras-cifar10-resnet50-elastic-20210723-044700" "ranTotalSeconds"=1320.04241584 "scheduler"="default" "waitedTotalSeconds"=13.756432224
I0723 17:09:16.601798    7682 scheduler.go:135]  "msg"="Received resched event, may be blocked because of rate limit"  "blockedUntil"="2021-07-23T17:10:26.550144533+08:00" "lastResched"="2021-07-23T17:08:26.550144533+08:00" "received"="2021-07-23T17:09:16.601713546+08:00" "scheduler"="default"
I0723 17:10:26.550218    7682 scheduler.go:159]  "msg"="Started resched"  "scheduler"="default"
I0723 17:10:26.550287    7682 scheduler.go:193]  "msg"="Updating all jobs info"  "scheduler"="default"
I0723 17:10:26.563504    7682 afsl.go:65]  "msg"="Finished scheduling"  "algorithm"="AFS-L" "freeGpu"=0 "result"={"tf2-keras-cifar10-inceptionv3-elastic-20210723-042550":1,"tf2-keras-cifar10-inceptionv3-elastic-20210723-042602":1,"tf2-keras-cifar10-inceptionv3-elastic-20210723-044237":1,"tf2-keras-cifar10-inceptionv3-elastic-20210723-045126":0,"tf2-keras-cifar10-inceptionv3-elastic-20210723-045447":1,"tf2-keras-cifar10-inceptionv3-elastic-20210723-045501":1,"tf2-keras-cifar10-resnet50-elastic-20210723-045445":1,"tf2-keras-cifar10-resnet50-elastic-20210723-045732":1,"tf2-keras-cifar10-vgg16-elastic-20210723-045210":1,"tf2-keras-cifar10-vgg16-elastic-20210723-045401":1,"tf2-keras-transformer-elastic-20210723-043917":1,"tf2-keras-transformer-elastic-20210723-045144":1,"tf2-keras-transformer-elastic-20210723-045458":1} "scheduler"="default"
I0723 17:10:26.563843    7682 scheduler.go:384]  "msg"="Trying to delete multiple training jobs"  "jobs"=[] "scheduler"="default"
I0723 17:10:26.564057    7682 scheduler.go:342]  "msg"="Trying to scale multiple training jobs"  "jobs"=[] "scheduler"="default"
I0723 17:10:26.564298    7682 scheduler.go:292]  "msg"="Trying to start multiple training jobs"  "jobs"=["tf2-keras-cifar10-inceptionv3-elastic-20210723-045447"] "scheduler"="default"
I0723 17:10:26.580552    7682 scheduler.go:342]  "msg"="Trying to scale multiple training jobs"  "jobs"=[] "scheduler"="default"
I0723 17:10:26.584743    7682 placement_manager.go:166]  "msg"="Started job placements adjustment"  "scheduler"="default"
I0723 17:10:26.584885    7682 placement_manager.go:192]  "msg"="Releasing slots"  "jobs"={"tf2-keras-cifar10-inceptionv3-elastic-20210723-042550":{},"tf2-keras-cifar10-inceptionv3-elastic-20210723-042602":{},"tf2-keras-cifar10-inceptionv3-elastic-20210723-044237":{},"tf2-keras-cifar10-inceptionv3-elastic-20210723-045501":{},"tf2-keras-cifar10-resnet50-elastic-20210723-044700":{},"tf2-keras-cifar10-resnet50-elastic-20210723-045445":{},"tf2-keras-cifar10-resnet50-elastic-20210723-045732":{},"tf2-keras-cifar10-vgg16-elastic-20210723-045210":{},"tf2-keras-cifar10-vgg16-elastic-20210723-045401":{},"tf2-keras-transformer-elastic-20210723-043917":{},"tf2-keras-transformer-elastic-20210723-045144":{},"tf2-keras-transformer-elastic-20210723-045458":{}} "nodes"={"gpu3":{},"gpu4":{},"gpu5":{}} "scheduler"="default"
I0723 17:10:26.584980    7682 placement_manager.go:250]  "msg"="Released slots"  "jobs"={"tf2-keras-cifar10-inceptionv3-elastic-20210723-042550":{},"tf2-keras-cifar10-inceptionv3-elastic-20210723-042602":{},"tf2-keras-cifar10-inceptionv3-elastic-20210723-044237":{},"tf2-keras-cifar10-inceptionv3-elastic-20210723-045501":{},"tf2-keras-cifar10-resnet50-elastic-20210723-044700":{},"tf2-keras-cifar10-resnet50-elastic-20210723-045445":{},"tf2-keras-cifar10-resnet50-elastic-20210723-045732":{},"tf2-keras-cifar10-vgg16-elastic-20210723-045210":{},"tf2-keras-cifar10-vgg16-elastic-20210723-045401":{},"tf2-keras-transformer-elastic-20210723-043917":{},"tf2-keras-transformer-elastic-20210723-045144":{},"tf2-keras-transformer-elastic-20210723-045458":{}} "nodes"={"gpu3":{},"gpu4":{},"gpu5":{}} "scheduler"="default"
I0723 17:10:26.585438    7682 placement_manager.go:305]  "msg"="Found best-fit"  "crossNode"=0 "nodes"=[{},{},{}] "requests"=[{},{},{},{},{},{},{},{},{},{},{},{},{},{},{},{},{},{},{},{},{},{},{},{},{},{}] "scheduler"="default"
I0723 17:10:26.585824    7682 placement_manager.go:339]  "msg"="nodeStates updated"  "new"={"gpu3":{},"gpu4":{},"gpu5":{}} "old"={"gpu3":{},"gpu4":{},"gpu5":{}} "scheduler"="default" "score"=6
I0723 17:10:26.586132    7682 placement_manager.go:387]  "msg"="jobStates updated"  "new"={"tf2-keras-cifar10-inceptionv3-elastic-20210723-042550":{},"tf2-keras-cifar10-inceptionv3-elastic-20210723-042602":{},"tf2-keras-cifar10-inceptionv3-elastic-20210723-044237":{},"tf2-keras-cifar10-inceptionv3-elastic-20210723-045447":{},"tf2-keras-cifar10-inceptionv3-elastic-20210723-045501":{},"tf2-keras-cifar10-resnet50-elastic-20210723-045445":{},"tf2-keras-cifar10-resnet50-elastic-20210723-045732":{},"tf2-keras-cifar10-vgg16-elastic-20210723-045210":{},"tf2-keras-cifar10-vgg16-elastic-20210723-045401":{},"tf2-keras-transformer-elastic-20210723-043917":{},"tf2-keras-transformer-elastic-20210723-045144":{},"tf2-keras-transformer-elastic-20210723-045458":{}} "old"={"tf2-keras-cifar10-inceptionv3-elastic-20210723-042550":{},"tf2-keras-cifar10-inceptionv3-elastic-20210723-042602":{},"tf2-keras-cifar10-inceptionv3-elastic-20210723-044237":{},"tf2-keras-cifar10-inceptionv3-elastic-20210723-045501":{},"tf2-keras-cifar10-resnet50-elastic-20210723-044700":{},"tf2-keras-cifar10-resnet50-elastic-20210723-045445":{},"tf2-keras-cifar10-resnet50-elastic-20210723-045732":{},"tf2-keras-cifar10-vgg16-elastic-20210723-045210":{},"tf2-keras-cifar10-vgg16-elastic-20210723-045401":{},"tf2-keras-transformer-elastic-20210723-043917":{},"tf2-keras-transformer-elastic-20210723-045144":{},"tf2-keras-transformer-elastic-20210723-045458":{}} "scheduler"="default"
I0723 17:10:26.586613    7682 placement_manager.go:434]  "msg"="podNodeName updated"  "launchersToDelete"=5 "new"={"tf2-keras-cifar10-inceptionv3-elastic-20210723-042550-worker-0":"gpu3","tf2-keras-cifar10-inceptionv3-elastic-20210723-042602-worker-0":"gpu4","tf2-keras-cifar10-inceptionv3-elastic-20210723-044237-worker-0":"gpu4","tf2-keras-cifar10-inceptionv3-elastic-20210723-045447-worker-0":"gpu5","tf2-keras-cifar10-inceptionv3-elastic-20210723-045501-worker-0":"gpu4","tf2-keras-cifar10-resnet50-elastic-20210723-045445-worker-0":"gpu5","tf2-keras-cifar10-resnet50-elastic-20210723-045732-worker-0":"gpu3","tf2-keras-cifar10-vgg16-elastic-20210723-045210-worker-0":"gpu4","tf2-keras-cifar10-vgg16-elastic-20210723-045401-worker-0":"gpu5","tf2-keras-transformer-elastic-20210723-043917-worker-0":"gpu3","tf2-keras-transformer-elastic-20210723-045144-worker-0":"gpu3","tf2-keras-transformer-elastic-20210723-045458-worker-0":"gpu5"} "old"={"tf2-keras-cifar10-inceptionv3-elastic-20210723-042550-worker-0":"gpu3","tf2-keras-cifar10-inceptionv3-elastic-20210723-042602-worker-0":"gpu3","tf2-keras-cifar10-inceptionv3-elastic-20210723-044237-worker-0":"gpu4","tf2-keras-cifar10-inceptionv3-elastic-20210723-045501-worker-0":"gpu3","tf2-keras-cifar10-resnet50-elastic-20210723-044700-worker-0":"gpu5","tf2-keras-cifar10-resnet50-elastic-20210723-045445-worker-0":"gpu5","tf2-keras-cifar10-resnet50-elastic-20210723-045732-worker-0":"gpu3","tf2-keras-cifar10-vgg16-elastic-20210723-045210-worker-0":"gpu4","tf2-keras-cifar10-vgg16-elastic-20210723-045401-worker-0":"gpu5","tf2-keras-transformer-elastic-20210723-043917-worker-0":"gpu5","tf2-keras-transformer-elastic-20210723-045144-worker-0":"gpu4","tf2-keras-transformer-elastic-20210723-045458-worker-0":"gpu4"} "scheduler"="default" "workersToDelete"=5
I0723 17:10:26.586931    7682 placement_manager.go:451]  "msg"="Deleting pod that need migration"  "podName"="tf2-keras-cifar10-inceptionv3-elastic-20210723-045501-worker-0" "scheduler"="default"
I0723 17:10:26.599292    7682 placement_manager.go:451]  "msg"="Deleting pod that need migration"  "podName"="tf2-keras-cifar10-inceptionv3-elastic-20210723-045501-launcher" "scheduler"="default"
I0723 17:10:26.617237    7682 placement_manager.go:451]  "msg"="Deleting pod that need migration"  "podName"="tf2-keras-cifar10-inceptionv3-elastic-20210723-042602-worker-0" "scheduler"="default"
I0723 17:10:26.629154    7682 placement_manager.go:451]  "msg"="Deleting pod that need migration"  "podName"="tf2-keras-cifar10-inceptionv3-elastic-20210723-042602-launcher" "scheduler"="default"
I0723 17:10:26.635045    7682 placement_manager.go:451]  "msg"="Deleting pod that need migration"  "podName"="tf2-keras-transformer-elastic-20210723-045144-worker-0" "scheduler"="default"
I0723 17:10:26.639767    7682 placement_manager.go:451]  "msg"="Deleting pod that need migration"  "podName"="tf2-keras-transformer-elastic-20210723-045144-launcher" "scheduler"="default"
I0723 17:10:26.643986    7682 placement_manager.go:451]  "msg"="Deleting pod that need migration"  "podName"="tf2-keras-transformer-elastic-20210723-045458-worker-0" "scheduler"="default"
I0723 17:10:26.646740    7682 placement_manager.go:451]  "msg"="Deleting pod that need migration"  "podName"="tf2-keras-transformer-elastic-20210723-045458-launcher" "scheduler"="default"
I0723 17:10:26.650066    7682 placement_manager.go:451]  "msg"="Deleting pod that need migration"  "podName"="tf2-keras-transformer-elastic-20210723-043917-worker-0" "scheduler"="default"
I0723 17:10:26.653076    7682 placement_manager.go:147]  "msg"="Adding toleration to pod"  "podName"="tf2-keras-cifar10-inceptionv3-elastic-20210723-045447-worker-0" "scheduler"="default" "toleration"={"key":"celeste/hostname","operator":"Equal","value":"gpu5","effect":"NoExecute"}
I0723 17:10:26.653412    7682 placement_manager.go:451]  "msg"="Deleting pod that need migration"  "podName"="tf2-keras-transformer-elastic-20210723-043917-launcher" "scheduler"="default"
I0723 17:10:26.795216    7682 placement_manager.go:183]  "msg"="Finished job placements adjustment"  "scheduler"="default"
I0723 17:10:26.795509    7682 scheduler.go:182]  "msg"="Finished resched"  "scheduler"="default"
I0723 17:10:27.394422    7682 placement_manager.go:147]  "msg"="Adding toleration to pod"  "podName"="tf2-keras-cifar10-inceptionv3-elastic-20210723-045447-launcher" "scheduler"="default" "toleration"={"key":"celeste/hostname","operator":"Exists","effect":"NoExecute"}
I0723 17:10:39.090710    7682 jobmaster.go:155]  "msg"="Training job created"  "job"="tf2-keras-cifar10-vgg16-elastic-20210723-051039"
I0723 17:10:39.090875    7682 scheduler.go:135]  "msg"="Received resched event, may be blocked because of rate limit"  "blockedUntil"="2021-07-23T17:12:26.795687788+08:00" "lastResched"="2021-07-23T17:10:26.795687788+08:00" "received"="2021-07-23T17:10:39.090128193+08:00" "scheduler"="default"
I0723 17:10:39.760496    7682 placement_manager.go:147]  "msg"="Adding toleration to pod"  "podName"="tf2-keras-cifar10-inceptionv3-elastic-20210723-045501-launcher" "scheduler"="default" "toleration"={"key":"celeste/hostname","operator":"Exists","effect":"NoExecute"}
I0723 17:10:39.814131    7682 placement_manager.go:147]  "msg"="Adding toleration to pod"  "podName"="tf2-keras-transformer-elastic-20210723-043917-worker-0" "scheduler"="default" "toleration"={"key":"celeste/hostname","operator":"Equal","value":"gpu3","effect":"NoExecute"}
I0723 17:10:43.875261    7682 placement_manager.go:147]  "msg"="Adding toleration to pod"  "podName"="tf2-keras-cifar10-inceptionv3-elastic-20210723-045501-worker-0" "scheduler"="default" "toleration"={"key":"celeste/hostname","operator":"Equal","value":"gpu4","effect":"NoExecute"}
I0723 17:10:44.263993    7682 placement_manager.go:147]  "msg"="Adding toleration to pod"  "podName"="tf2-keras-cifar10-inceptionv3-elastic-20210723-042602-worker-0" "scheduler"="default" "toleration"={"key":"celeste/hostname","operator":"Equal","value":"gpu4","effect":"NoExecute"}
I0723 17:10:44.664295    7682 placement_manager.go:147]  "msg"="Adding toleration to pod"  "podName"="tf2-keras-transformer-elastic-20210723-043917-launcher" "scheduler"="default" "toleration"={"key":"celeste/hostname","operator":"Exists","effect":"NoExecute"}
I0723 17:10:45.362345    7682 placement_manager.go:147]  "msg"="Adding toleration to pod"  "podName"="tf2-keras-transformer-elastic-20210723-045458-worker-0" "scheduler"="default" "toleration"={"key":"celeste/hostname","operator":"Equal","value":"gpu5","effect":"NoExecute"}
I0723 17:10:45.462566    7682 placement_manager.go:147]  "msg"="Adding toleration to pod"  "podName"="tf2-keras-cifar10-inceptionv3-elastic-20210723-042602-launcher" "scheduler"="default" "toleration"={"key":"celeste/hostname","operator":"Exists","effect":"NoExecute"}
I0723 17:10:46.615475    7682 placement_manager.go:147]  "msg"="Adding toleration to pod"  "podName"="tf2-keras-transformer-elastic-20210723-045144-launcher" "scheduler"="default" "toleration"={"key":"celeste/hostname","operator":"Exists","effect":"NoExecute"}
I0723 17:10:47.356414    7682 placement_manager.go:147]  "msg"="Adding toleration to pod"  "podName"="tf2-keras-transformer-elastic-20210723-045458-launcher" "scheduler"="default" "toleration"={"key":"celeste/hostname","operator":"Exists","effect":"NoExecute"}
I0723 17:10:48.219152    7682 placement_manager.go:147]  "msg"="Adding toleration to pod"  "podName"="tf2-keras-transformer-elastic-20210723-045144-worker-0" "scheduler"="default" "toleration"={"key":"celeste/hostname","operator":"Equal","value":"gpu3","effect":"NoExecute"}
I0723 17:12:26.795768    7682 scheduler.go:159]  "msg"="Started resched"  "scheduler"="default"
I0723 17:12:26.795841    7682 scheduler.go:193]  "msg"="Updating all jobs info"  "scheduler"="default"
I0723 17:12:26.809733    7682 afsl.go:65]  "msg"="Finished scheduling"  "algorithm"="AFS-L" "freeGpu"=0 "result"={"tf2-keras-cifar10-inceptionv3-elastic-20210723-042550":1,"tf2-keras-cifar10-inceptionv3-elastic-20210723-042602":1,"tf2-keras-cifar10-inceptionv3-elastic-20210723-044237":1,"tf2-keras-cifar10-inceptionv3-elastic-20210723-045126":0,"tf2-keras-cifar10-inceptionv3-elastic-20210723-045447":0,"tf2-keras-cifar10-inceptionv3-elastic-20210723-045501":1,"tf2-keras-cifar10-resnet50-elastic-20210723-045445":1,"tf2-keras-cifar10-resnet50-elastic-20210723-045732":1,"tf2-keras-cifar10-vgg16-elastic-20210723-045210":1,"tf2-keras-cifar10-vgg16-elastic-20210723-045401":1,"tf2-keras-cifar10-vgg16-elastic-20210723-051039":1,"tf2-keras-transformer-elastic-20210723-043917":1,"tf2-keras-transformer-elastic-20210723-045144":1,"tf2-keras-transformer-elastic-20210723-045458":1} "scheduler"="default"
I0723 17:12:26.810081    7682 scheduler.go:384]  "msg"="Trying to delete multiple training jobs"  "jobs"=["tf2-keras-cifar10-inceptionv3-elastic-20210723-045447"] "scheduler"="default"
I0723 17:12:26.821412    7682 scheduler.go:342]  "msg"="Trying to scale multiple training jobs"  "jobs"=[] "scheduler"="default"
I0723 17:12:26.821761    7682 scheduler.go:292]  "msg"="Trying to start multiple training jobs"  "jobs"=["tf2-keras-cifar10-vgg16-elastic-20210723-051039"] "scheduler"="default"
I0723 17:12:26.839454    7682 scheduler.go:342]  "msg"="Trying to scale multiple training jobs"  "jobs"=[] "scheduler"="default"
I0723 17:12:26.843826    7682 placement_manager.go:166]  "msg"="Started job placements adjustment"  "scheduler"="default"
I0723 17:12:26.843914    7682 placement_manager.go:192]  "msg"="Releasing slots"  "jobs"={"tf2-keras-cifar10-inceptionv3-elastic-20210723-042550":{},"tf2-keras-cifar10-inceptionv3-elastic-20210723-042602":{},"tf2-keras-cifar10-inceptionv3-elastic-20210723-044237":{},"tf2-keras-cifar10-inceptionv3-elastic-20210723-045447":{},"tf2-keras-cifar10-inceptionv3-elastic-20210723-045501":{},"tf2-keras-cifar10-resnet50-elastic-20210723-045445":{},"tf2-keras-cifar10-resnet50-elastic-20210723-045732":{},"tf2-keras-cifar10-vgg16-elastic-20210723-045210":{},"tf2-keras-cifar10-vgg16-elastic-20210723-045401":{},"tf2-keras-transformer-elastic-20210723-043917":{},"tf2-keras-transformer-elastic-20210723-045144":{},"tf2-keras-transformer-elastic-20210723-045458":{}} "nodes"={"gpu3":{},"gpu4":{},"gpu5":{}} "scheduler"="default"
I0723 17:12:26.843989    7682 placement_manager.go:250]  "msg"="Released slots"  "jobs"={"tf2-keras-cifar10-inceptionv3-elastic-20210723-042550":{},"tf2-keras-cifar10-inceptionv3-elastic-20210723-042602":{},"tf2-keras-cifar10-inceptionv3-elastic-20210723-044237":{},"tf2-keras-cifar10-inceptionv3-elastic-20210723-045447":{},"tf2-keras-cifar10-inceptionv3-elastic-20210723-045501":{},"tf2-keras-cifar10-resnet50-elastic-20210723-045445":{},"tf2-keras-cifar10-resnet50-elastic-20210723-045732":{},"tf2-keras-cifar10-vgg16-elastic-20210723-045210":{},"tf2-keras-cifar10-vgg16-elastic-20210723-045401":{},"tf2-keras-transformer-elastic-20210723-043917":{},"tf2-keras-transformer-elastic-20210723-045144":{},"tf2-keras-transformer-elastic-20210723-045458":{}} "nodes"={"gpu3":{},"gpu4":{},"gpu5":{}} "scheduler"="default"
I0723 17:12:26.844540    7682 placement_manager.go:305]  "msg"="Found best-fit"  "crossNode"=0 "nodes"=[{},{},{}] "requests"=[{},{},{},{},{},{},{},{},{},{},{},{},{},{},{},{},{},{},{},{},{},{},{},{},{},{},{},{}] "scheduler"="default"
I0723 17:12:26.844972    7682 placement_manager.go:339]  "msg"="nodeStates updated"  "new"={"gpu3":{},"gpu4":{},"gpu5":{}} "old"={"gpu3":{},"gpu4":{},"gpu5":{}} "scheduler"="default" "score"=5
I0723 17:12:26.845419    7682 placement_manager.go:387]  "msg"="jobStates updated"  "new"={"tf2-keras-cifar10-inceptionv3-elastic-20210723-042550":{},"tf2-keras-cifar10-inceptionv3-elastic-20210723-042602":{},"tf2-keras-cifar10-inceptionv3-elastic-20210723-044237":{},"tf2-keras-cifar10-inceptionv3-elastic-20210723-045501":{},"tf2-keras-cifar10-resnet50-elastic-20210723-045445":{},"tf2-keras-cifar10-resnet50-elastic-20210723-045732":{},"tf2-keras-cifar10-vgg16-elastic-20210723-045210":{},"tf2-keras-cifar10-vgg16-elastic-20210723-045401":{},"tf2-keras-cifar10-vgg16-elastic-20210723-051039":{},"tf2-keras-transformer-elastic-20210723-043917":{},"tf2-keras-transformer-elastic-20210723-045144":{},"tf2-keras-transformer-elastic-20210723-045458":{}} "old"={"tf2-keras-cifar10-inceptionv3-elastic-20210723-042550":{},"tf2-keras-cifar10-inceptionv3-elastic-20210723-042602":{},"tf2-keras-cifar10-inceptionv3-elastic-20210723-044237":{},"tf2-keras-cifar10-inceptionv3-elastic-20210723-045447":{},"tf2-keras-cifar10-inceptionv3-elastic-20210723-045501":{},"tf2-keras-cifar10-resnet50-elastic-20210723-045445":{},"tf2-keras-cifar10-resnet50-elastic-20210723-045732":{},"tf2-keras-cifar10-vgg16-elastic-20210723-045210":{},"tf2-keras-cifar10-vgg16-elastic-20210723-045401":{},"tf2-keras-transformer-elastic-20210723-043917":{},"tf2-keras-transformer-elastic-20210723-045144":{},"tf2-keras-transformer-elastic-20210723-045458":{}} "scheduler"="default"
I0723 17:12:26.845870    7682 placement_manager.go:434]  "msg"="podNodeName updated"  "launchersToDelete"=6 "new"={"tf2-keras-cifar10-inceptionv3-elastic-20210723-042550-worker-0":"gpu4","tf2-keras-cifar10-inceptionv3-elastic-20210723-042602-worker-0":"gpu4","tf2-keras-cifar10-inceptionv3-elastic-20210723-044237-worker-0":"gpu5","tf2-keras-cifar10-inceptionv3-elastic-20210723-045501-worker-0":"gpu3","tf2-keras-cifar10-resnet50-elastic-20210723-045445-worker-0":"gpu5","tf2-keras-cifar10-resnet50-elastic-20210723-045732-worker-0":"gpu3","tf2-keras-cifar10-vgg16-elastic-20210723-045210-worker-0":"gpu5","tf2-keras-cifar10-vgg16-elastic-20210723-045401-worker-0":"gpu5","tf2-keras-cifar10-vgg16-elastic-20210723-051039-worker-0":"gpu3","tf2-keras-transformer-elastic-20210723-043917-worker-0":"gpu3","tf2-keras-transformer-elastic-20210723-045144-worker-0":"gpu4","tf2-keras-transformer-elastic-20210723-045458-worker-0":"gpu4"} "old"={"tf2-keras-cifar10-inceptionv3-elastic-20210723-042550-worker-0":"gpu3","tf2-keras-cifar10-inceptionv3-elastic-20210723-042602-worker-0":"gpu4","tf2-keras-cifar10-inceptionv3-elastic-20210723-044237-worker-0":"gpu4","tf2-keras-cifar10-inceptionv3-elastic-20210723-045447-worker-0":"gpu5","tf2-keras-cifar10-inceptionv3-elastic-20210723-045501-worker-0":"gpu4","tf2-keras-cifar10-resnet50-elastic-20210723-045445-worker-0":"gpu5","tf2-keras-cifar10-resnet50-elastic-20210723-045732-worker-0":"gpu3","tf2-keras-cifar10-vgg16-elastic-20210723-045210-worker-0":"gpu4","tf2-keras-cifar10-vgg16-elastic-20210723-045401-worker-0":"gpu5","tf2-keras-transformer-elastic-20210723-043917-worker-0":"gpu3","tf2-keras-transformer-elastic-20210723-045144-worker-0":"gpu3","tf2-keras-transformer-elastic-20210723-045458-worker-0":"gpu5"} "scheduler"="default" "workersToDelete"=6
I0723 17:12:26.846220    7682 placement_manager.go:451]  "msg"="Deleting pod that need migration"  "podName"="tf2-keras-transformer-elastic-20210723-045144-worker-0" "scheduler"="default"
I0723 17:12:26.852847    7682 placement_manager.go:451]  "msg"="Deleting pod that need migration"  "podName"="tf2-keras-transformer-elastic-20210723-045144-launcher" "scheduler"="default"
I0723 17:12:26.856993    7682 placement_manager.go:451]  "msg"="Deleting pod that need migration"  "podName"="tf2-keras-transformer-elastic-20210723-045458-worker-0" "scheduler"="default"
I0723 17:12:26.860755    7682 placement_manager.go:451]  "msg"="Deleting pod that need migration"  "podName"="tf2-keras-transformer-elastic-20210723-045458-launcher" "scheduler"="default"
I0723 17:12:26.868663    7682 placement_manager.go:451]  "msg"="Deleting pod that need migration"  "podName"="tf2-keras-cifar10-inceptionv3-elastic-20210723-042550-worker-0" "scheduler"="default"
I0723 17:12:26.872964    7682 placement_manager.go:451]  "msg"="Deleting pod that need migration"  "podName"="tf2-keras-cifar10-inceptionv3-elastic-20210723-042550-launcher" "scheduler"="default"
I0723 17:12:26.877610    7682 placement_manager.go:451]  "msg"="Deleting pod that need migration"  "podName"="tf2-keras-cifar10-inceptionv3-elastic-20210723-044237-worker-0" "scheduler"="default"
I0723 17:12:26.885516    7682 placement_manager.go:451]  "msg"="Deleting pod that need migration"  "podName"="tf2-keras-cifar10-inceptionv3-elastic-20210723-044237-launcher" "scheduler"="default"
I0723 17:12:26.889456    7682 placement_manager.go:451]  "msg"="Deleting pod that need migration"  "podName"="tf2-keras-cifar10-vgg16-elastic-20210723-045210-worker-0" "scheduler"="default"
I0723 17:12:26.895514    7682 placement_manager.go:451]  "msg"="Deleting pod that need migration"  "podName"="tf2-keras-cifar10-vgg16-elastic-20210723-045210-launcher" "scheduler"="default"
I0723 17:12:26.899681    7682 placement_manager.go:451]  "msg"="Deleting pod that need migration"  "podName"="tf2-keras-cifar10-inceptionv3-elastic-20210723-045501-worker-0" "scheduler"="default"
I0723 17:12:27.045802    7682 placement_manager.go:147]  "msg"="Adding toleration to pod"  "podName"="tf2-keras-cifar10-vgg16-elastic-20210723-051039-worker-0" "scheduler"="default" "toleration"={"key":"celeste/hostname","operator":"Equal","value":"gpu3","effect":"NoExecute"}
I0723 17:12:27.050463    7682 placement_manager.go:451]  "msg"="Deleting pod that need migration"  "podName"="tf2-keras-cifar10-inceptionv3-elastic-20210723-045501-launcher" "scheduler"="default"
I0723 17:12:27.452361    7682 placement_manager.go:183]  "msg"="Finished job placements adjustment"  "scheduler"="default"
I0723 17:12:27.452641    7682 scheduler.go:182]  "msg"="Finished resched"  "scheduler"="default"
I0723 17:12:27.653007    7682 placement_manager.go:147]  "msg"="Adding toleration to pod"  "podName"="tf2-keras-cifar10-vgg16-elastic-20210723-051039-launcher" "scheduler"="default" "toleration"={"key":"celeste/hostname","operator":"Exists","effect":"NoExecute"}
I0723 17:12:34.731869    7682 placement_manager.go:147]  "msg"="Adding toleration to pod"  "podName"="tf2-keras-cifar10-inceptionv3-elastic-20210723-042550-worker-0" "scheduler"="default" "toleration"={"key":"celeste/hostname","operator":"Equal","value":"gpu4","effect":"NoExecute"}
I0723 17:12:35.528457    7682 placement_manager.go:147]  "msg"="Adding toleration to pod"  "podName"="tf2-keras-transformer-elastic-20210723-045144-worker-0" "scheduler"="default" "toleration"={"key":"celeste/hostname","operator":"Equal","value":"gpu4","effect":"NoExecute"}
I0723 17:12:36.289982    7682 placement_manager.go:147]  "msg"="Adding toleration to pod"  "podName"="tf2-keras-cifar10-inceptionv3-elastic-20210723-044237-launcher" "scheduler"="default" "toleration"={"key":"celeste/hostname","operator":"Exists","effect":"NoExecute"}
I0723 17:12:38.011111    7682 placement_manager.go:147]  "msg"="Adding toleration to pod"  "podName"="tf2-keras-transformer-elastic-20210723-045458-launcher" "scheduler"="default" "toleration"={"key":"celeste/hostname","operator":"Exists","effect":"NoExecute"}
I0723 17:12:40.407277    7682 placement_manager.go:147]  "msg"="Adding toleration to pod"  "podName"="tf2-keras-transformer-elastic-20210723-045144-launcher" "scheduler"="default" "toleration"={"key":"celeste/hostname","operator":"Exists","effect":"NoExecute"}
I0723 17:12:41.231210    7682 placement_manager.go:147]  "msg"="Adding toleration to pod"  "podName"="tf2-keras-cifar10-inceptionv3-elastic-20210723-042550-launcher" "scheduler"="default" "toleration"={"key":"celeste/hostname","operator":"Exists","effect":"NoExecute"}
I0723 17:12:41.608999    7682 placement_manager.go:147]  "msg"="Adding toleration to pod"  "podName"="tf2-keras-transformer-elastic-20210723-045458-worker-0" "scheduler"="default" "toleration"={"key":"celeste/hostname","operator":"Equal","value":"gpu4","effect":"NoExecute"}
I0723 17:12:45.826586    7682 placement_manager.go:147]  "msg"="Adding toleration to pod"  "podName"="tf2-keras-cifar10-inceptionv3-elastic-20210723-045501-worker-0" "scheduler"="default" "toleration"={"key":"celeste/hostname","operator":"Equal","value":"gpu3","effect":"NoExecute"}
I0723 17:12:46.627395    7682 placement_manager.go:147]  "msg"="Adding toleration to pod"  "podName"="tf2-keras-cifar10-inceptionv3-elastic-20210723-044237-worker-0" "scheduler"="default" "toleration"={"key":"celeste/hostname","operator":"Equal","value":"gpu5","effect":"NoExecute"}
I0723 17:12:47.426906    7682 placement_manager.go:147]  "msg"="Adding toleration to pod"  "podName"="tf2-keras-cifar10-vgg16-elastic-20210723-045210-launcher" "scheduler"="default" "toleration"={"key":"celeste/hostname","operator":"Exists","effect":"NoExecute"}
I0723 17:12:48.229759    7682 placement_manager.go:147]  "msg"="Adding toleration to pod"  "podName"="tf2-keras-cifar10-inceptionv3-elastic-20210723-045501-launcher" "scheduler"="default" "toleration"={"key":"celeste/hostname","operator":"Exists","effect":"NoExecute"}
I0723 17:12:49.026322    7682 placement_manager.go:147]  "msg"="Adding toleration to pod"  "podName"="tf2-keras-cifar10-vgg16-elastic-20210723-045210-worker-0" "scheduler"="default" "toleration"={"key":"celeste/hostname","operator":"Equal","value":"gpu5","effect":"NoExecute"}
I0723 17:16:49.176030    7682 jobmaster.go:155]  "msg"="Training job created"  "job"="tf2-keras-transformer-elastic-20210723-051649"
I0723 17:16:49.176177    7682 scheduler.go:135]  "msg"="Received resched event, may be blocked because of rate limit"  "blockedUntil"="2021-07-23T17:14:27.452888468+08:00" "lastResched"="2021-07-23T17:12:27.452888468+08:00" "received"="2021-07-23T17:16:49.175460876+08:00" "scheduler"="default"
I0723 17:16:49.176759    7682 scheduler.go:159]  "msg"="Started resched"  "scheduler"="default"
I0723 17:16:49.176825    7682 scheduler.go:193]  "msg"="Updating all jobs info"  "scheduler"="default"
I0723 17:16:49.192337    7682 afsl.go:65]  "msg"="Finished scheduling"  "algorithm"="AFS-L" "freeGpu"=0 "result"={"tf2-keras-cifar10-inceptionv3-elastic-20210723-042550":1,"tf2-keras-cifar10-inceptionv3-elastic-20210723-042602":1,"tf2-keras-cifar10-inceptionv3-elastic-20210723-044237":1,"tf2-keras-cifar10-inceptionv3-elastic-20210723-045126":0,"tf2-keras-cifar10-inceptionv3-elastic-20210723-045447":0,"tf2-keras-cifar10-inceptionv3-elastic-20210723-045501":0,"tf2-keras-cifar10-resnet50-elastic-20210723-045445":1,"tf2-keras-cifar10-resnet50-elastic-20210723-045732":1,"tf2-keras-cifar10-vgg16-elastic-20210723-045210":1,"tf2-keras-cifar10-vgg16-elastic-20210723-045401":1,"tf2-keras-cifar10-vgg16-elastic-20210723-051039":1,"tf2-keras-transformer-elastic-20210723-043917":1,"tf2-keras-transformer-elastic-20210723-045144":1,"tf2-keras-transformer-elastic-20210723-045458":1,"tf2-keras-transformer-elastic-20210723-051649":1} "scheduler"="default"
I0723 17:16:49.192791    7682 scheduler.go:384]  "msg"="Trying to delete multiple training jobs"  "jobs"=["tf2-keras-cifar10-inceptionv3-elastic-20210723-045501"] "scheduler"="default"
I0723 17:16:49.203134    7682 scheduler.go:342]  "msg"="Trying to scale multiple training jobs"  "jobs"=[] "scheduler"="default"
I0723 17:16:49.203327    7682 scheduler.go:292]  "msg"="Trying to start multiple training jobs"  "jobs"=["tf2-keras-transformer-elastic-20210723-051649"] "scheduler"="default"
I0723 17:16:49.230323    7682 scheduler.go:342]  "msg"="Trying to scale multiple training jobs"  "jobs"=[] "scheduler"="default"
I0723 17:16:49.235700    7682 placement_manager.go:166]  "msg"="Started job placements adjustment"  "scheduler"="default"
I0723 17:16:49.236621    7682 placement_manager.go:192]  "msg"="Releasing slots"  "jobs"={"tf2-keras-cifar10-inceptionv3-elastic-20210723-042550":{},"tf2-keras-cifar10-inceptionv3-elastic-20210723-042602":{},"tf2-keras-cifar10-inceptionv3-elastic-20210723-044237":{},"tf2-keras-cifar10-inceptionv3-elastic-20210723-045501":{},"tf2-keras-cifar10-resnet50-elastic-20210723-045445":{},"tf2-keras-cifar10-resnet50-elastic-20210723-045732":{},"tf2-keras-cifar10-vgg16-elastic-20210723-045210":{},"tf2-keras-cifar10-vgg16-elastic-20210723-045401":{},"tf2-keras-cifar10-vgg16-elastic-20210723-051039":{},"tf2-keras-transformer-elastic-20210723-043917":{},"tf2-keras-transformer-elastic-20210723-045144":{},"tf2-keras-transformer-elastic-20210723-045458":{}} "nodes"={"gpu3":{},"gpu4":{},"gpu5":{}} "scheduler"="default"
I0723 17:16:49.236917    7682 placement_manager.go:250]  "msg"="Released slots"  "jobs"={"tf2-keras-cifar10-inceptionv3-elastic-20210723-042550":{},"tf2-keras-cifar10-inceptionv3-elastic-20210723-042602":{},"tf2-keras-cifar10-inceptionv3-elastic-20210723-044237":{},"tf2-keras-cifar10-inceptionv3-elastic-20210723-045501":{},"tf2-keras-cifar10-resnet50-elastic-20210723-045445":{},"tf2-keras-cifar10-resnet50-elastic-20210723-045732":{},"tf2-keras-cifar10-vgg16-elastic-20210723-045210":{},"tf2-keras-cifar10-vgg16-elastic-20210723-045401":{},"tf2-keras-cifar10-vgg16-elastic-20210723-051039":{},"tf2-keras-transformer-elastic-20210723-043917":{},"tf2-keras-transformer-elastic-20210723-045144":{},"tf2-keras-transformer-elastic-20210723-045458":{}} "nodes"={"gpu3":{},"gpu4":{},"gpu5":{}} "scheduler"="default"
I0723 17:16:49.237556    7682 placement_manager.go:305]  "msg"="Found best-fit"  "crossNode"=0 "nodes"=[{},{},{}] "requests"=[{},{},{},{},{},{},{},{},{},{},{},{},{},{},{},{},{},{},{},{},{},{},{},{},{},{},{},{},{},{}] "scheduler"="default"
I0723 17:16:49.238038    7682 placement_manager.go:339]  "msg"="nodeStates updated"  "new"={"gpu3":{},"gpu4":{},"gpu5":{}} "old"={"gpu3":{},"gpu4":{},"gpu5":{}} "scheduler"="default" "score"=7
I0723 17:16:49.238436    7682 placement_manager.go:387]  "msg"="jobStates updated"  "new"={"tf2-keras-cifar10-inceptionv3-elastic-20210723-042550":{},"tf2-keras-cifar10-inceptionv3-elastic-20210723-042602":{},"tf2-keras-cifar10-inceptionv3-elastic-20210723-044237":{},"tf2-keras-cifar10-resnet50-elastic-20210723-045445":{},"tf2-keras-cifar10-resnet50-elastic-20210723-045732":{},"tf2-keras-cifar10-vgg16-elastic-20210723-045210":{},"tf2-keras-cifar10-vgg16-elastic-20210723-045401":{},"tf2-keras-cifar10-vgg16-elastic-20210723-051039":{},"tf2-keras-transformer-elastic-20210723-043917":{},"tf2-keras-transformer-elastic-20210723-045144":{},"tf2-keras-transformer-elastic-20210723-045458":{},"tf2-keras-transformer-elastic-20210723-051649":{}} "old"={"tf2-keras-cifar10-inceptionv3-elastic-20210723-042550":{},"tf2-keras-cifar10-inceptionv3-elastic-20210723-042602":{},"tf2-keras-cifar10-inceptionv3-elastic-20210723-044237":{},"tf2-keras-cifar10-inceptionv3-elastic-20210723-045501":{},"tf2-keras-cifar10-resnet50-elastic-20210723-045445":{},"tf2-keras-cifar10-resnet50-elastic-20210723-045732":{},"tf2-keras-cifar10-vgg16-elastic-20210723-045210":{},"tf2-keras-cifar10-vgg16-elastic-20210723-045401":{},"tf2-keras-cifar10-vgg16-elastic-20210723-051039":{},"tf2-keras-transformer-elastic-20210723-043917":{},"tf2-keras-transformer-elastic-20210723-045144":{},"tf2-keras-transformer-elastic-20210723-045458":{}} "scheduler"="default"
I0723 17:16:49.238945    7682 placement_manager.go:434]  "msg"="podNodeName updated"  "launchersToDelete"=4 "new"={"tf2-keras-cifar10-inceptionv3-elastic-20210723-042550-worker-0":"gpu4","tf2-keras-cifar10-inceptionv3-elastic-20210723-042602-worker-0":"gpu3","tf2-keras-cifar10-inceptionv3-elastic-20210723-044237-worker-0":"gpu5","tf2-keras-cifar10-resnet50-elastic-20210723-045445-worker-0":"gpu4","tf2-keras-cifar10-resnet50-elastic-20210723-045732-worker-0":"gpu3","tf2-keras-cifar10-vgg16-elastic-20210723-045210-worker-0":"gpu5","tf2-keras-cifar10-vgg16-elastic-20210723-045401-worker-0":"gpu4","tf2-keras-cifar10-vgg16-elastic-20210723-051039-worker-0":"gpu3","tf2-keras-transformer-elastic-20210723-043917-worker-0":"gpu3","tf2-keras-transformer-elastic-20210723-045144-worker-0":"gpu5","tf2-keras-transformer-elastic-20210723-045458-worker-0":"gpu4","tf2-keras-transformer-elastic-20210723-051649-worker-0":"gpu5"} "old"={"tf2-keras-cifar10-inceptionv3-elastic-20210723-042550-worker-0":"gpu4","tf2-keras-cifar10-inceptionv3-elastic-20210723-042602-worker-0":"gpu4","tf2-keras-cifar10-inceptionv3-elastic-20210723-044237-worker-0":"gpu5","tf2-keras-cifar10-inceptionv3-elastic-20210723-045501-worker-0":"gpu3","tf2-keras-cifar10-resnet50-elastic-20210723-045445-worker-0":"gpu5","tf2-keras-cifar10-resnet50-elastic-20210723-045732-worker-0":"gpu3","tf2-keras-cifar10-vgg16-elastic-20210723-045210-worker-0":"gpu5","tf2-keras-cifar10-vgg16-elastic-20210723-045401-worker-0":"gpu5","tf2-keras-cifar10-vgg16-elastic-20210723-051039-worker-0":"gpu3","tf2-keras-transformer-elastic-20210723-043917-worker-0":"gpu3","tf2-keras-transformer-elastic-20210723-045144-worker-0":"gpu4","tf2-keras-transformer-elastic-20210723-045458-worker-0":"gpu4"} "scheduler"="default" "workersToDelete"=4
I0723 17:16:49.239378    7682 placement_manager.go:451]  "msg"="Deleting pod that need migration"  "podName"="tf2-keras-transformer-elastic-20210723-045144-worker-0" "scheduler"="default"
I0723 17:16:49.244356    7682 placement_manager.go:451]  "msg"="Deleting pod that need migration"  "podName"="tf2-keras-transformer-elastic-20210723-045144-launcher" "scheduler"="default"
I0723 17:16:49.249677    7682 placement_manager.go:451]  "msg"="Deleting pod that need migration"  "podName"="tf2-keras-cifar10-resnet50-elastic-20210723-045445-worker-0" "scheduler"="default"
I0723 17:16:49.261490    7682 placement_manager.go:451]  "msg"="Deleting pod that need migration"  "podName"="tf2-keras-cifar10-resnet50-elastic-20210723-045445-launcher" "scheduler"="default"
I0723 17:16:49.265786    7682 placement_manager.go:451]  "msg"="Deleting pod that need migration"  "podName"="tf2-keras-cifar10-vgg16-elastic-20210723-045401-worker-0" "scheduler"="default"
I0723 17:16:49.269483    7682 placement_manager.go:451]  "msg"="Deleting pod that need migration"  "podName"="tf2-keras-cifar10-vgg16-elastic-20210723-045401-launcher" "scheduler"="default"
I0723 17:16:49.274380    7682 placement_manager.go:451]  "msg"="Deleting pod that need migration"  "podName"="tf2-keras-cifar10-inceptionv3-elastic-20210723-042602-worker-0" "scheduler"="default"
I0723 17:16:49.278133    7682 placement_manager.go:451]  "msg"="Deleting pod that need migration"  "podName"="tf2-keras-cifar10-inceptionv3-elastic-20210723-042602-launcher" "scheduler"="default"
I0723 17:16:49.282255    7682 placement_manager.go:183]  "msg"="Finished job placements adjustment"  "scheduler"="default"
I0723 17:16:49.282451    7682 scheduler.go:182]  "msg"="Finished resched"  "scheduler"="default"
I0723 17:16:49.290802    7682 placement_manager.go:147]  "msg"="Adding toleration to pod"  "podName"="tf2-keras-transformer-elastic-20210723-051649-worker-0" "scheduler"="default" "toleration"={"key":"celeste/hostname","operator":"Equal","value":"gpu5","effect":"NoExecute"}
I0723 17:16:50.079900    7682 placement_manager.go:147]  "msg"="Adding toleration to pod"  "podName"="tf2-keras-transformer-elastic-20210723-051649-launcher" "scheduler"="default" "toleration"={"key":"celeste/hostname","operator":"Exists","effect":"NoExecute"}
I0723 17:17:04.603067    7682 placement_manager.go:147]  "msg"="Adding toleration to pod"  "podName"="tf2-keras-cifar10-inceptionv3-elastic-20210723-042602-launcher" "scheduler"="default" "toleration"={"key":"celeste/hostname","operator":"Exists","effect":"NoExecute"}
I0723 17:17:04.644668    7682 placement_manager.go:147]  "msg"="Adding toleration to pod"  "podName"="tf2-keras-transformer-elastic-20210723-045144-worker-0" "scheduler"="default" "toleration"={"key":"celeste/hostname","operator":"Equal","value":"gpu5","effect":"NoExecute"}
I0723 17:17:04.653654    7682 placement_manager.go:147]  "msg"="Adding toleration to pod"  "podName"="tf2-keras-transformer-elastic-20210723-045144-launcher" "scheduler"="default" "toleration"={"key":"celeste/hostname","operator":"Exists","effect":"NoExecute"}
I0723 17:17:04.666454    7682 placement_manager.go:147]  "msg"="Adding toleration to pod"  "podName"="tf2-keras-cifar10-inceptionv3-elastic-20210723-042602-worker-0" "scheduler"="default" "toleration"={"key":"celeste/hostname","operator":"Equal","value":"gpu3","effect":"NoExecute"}
I0723 17:17:07.127540    7682 jobmaster.go:155]  "msg"="Training job created"  "job"="tf2-keras-cifar10-vgg16-elastic-20210723-051707"
I0723 17:17:07.127709    7682 scheduler.go:135]  "msg"="Received resched event, may be blocked because of rate limit"  "blockedUntil"="2021-07-23T17:18:49.282629058+08:00" "lastResched"="2021-07-23T17:16:49.282629058+08:00" "received"="2021-07-23T17:17:07.127037302+08:00" "scheduler"="default"
I0723 17:17:12.484985    7682 placement_manager.go:147]  "msg"="Adding toleration to pod"  "podName"="tf2-keras-cifar10-resnet50-elastic-20210723-045445-launcher" "scheduler"="default" "toleration"={"key":"celeste/hostname","operator":"Exists","effect":"NoExecute"}
I0723 17:17:13.286599    7682 placement_manager.go:147]  "msg"="Adding toleration to pod"  "podName"="tf2-keras-cifar10-vgg16-elastic-20210723-045401-worker-0" "scheduler"="default" "toleration"={"key":"celeste/hostname","operator":"Equal","value":"gpu4","effect":"NoExecute"}
I0723 17:17:14.882930    7682 placement_manager.go:147]  "msg"="Adding toleration to pod"  "podName"="tf2-keras-cifar10-resnet50-elastic-20210723-045445-worker-0" "scheduler"="default" "toleration"={"key":"celeste/hostname","operator":"Equal","value":"gpu4","effect":"NoExecute"}
I0723 17:17:16.683760    7682 placement_manager.go:147]  "msg"="Adding toleration to pod"  "podName"="tf2-keras-cifar10-vgg16-elastic-20210723-045401-launcher" "scheduler"="default" "toleration"={"key":"celeste/hostname","operator":"Exists","effect":"NoExecute"}
I0723 17:17:22.051707    7682 jobmaster.go:155]  "msg"="Training job created"  "job"="tf2-keras-cifar10-resnet50-elastic-20210723-051722"
I0723 17:18:49.282700    7682 scheduler.go:159]  "msg"="Started resched"  "scheduler"="default"
I0723 17:18:49.282800    7682 scheduler.go:193]  "msg"="Updating all jobs info"  "scheduler"="default"
I0723 17:18:49.297506    7682 afsl.go:65]  "msg"="Finished scheduling"  "algorithm"="AFS-L" "freeGpu"=0 "result"={"tf2-keras-cifar10-inceptionv3-elastic-20210723-042550":1,"tf2-keras-cifar10-inceptionv3-elastic-20210723-042602":1,"tf2-keras-cifar10-inceptionv3-elastic-20210723-044237":0,"tf2-keras-cifar10-inceptionv3-elastic-20210723-045126":0,"tf2-keras-cifar10-inceptionv3-elastic-20210723-045447":0,"tf2-keras-cifar10-inceptionv3-elastic-20210723-045501":0,"tf2-keras-cifar10-resnet50-elastic-20210723-045445":1,"tf2-keras-cifar10-resnet50-elastic-20210723-045732":1,"tf2-keras-cifar10-resnet50-elastic-20210723-051722":1,"tf2-keras-cifar10-vgg16-elastic-20210723-045210":1,"tf2-keras-cifar10-vgg16-elastic-20210723-045401":1,"tf2-keras-cifar10-vgg16-elastic-20210723-051039":1,"tf2-keras-cifar10-vgg16-elastic-20210723-051707":1,"tf2-keras-transformer-elastic-20210723-043917":1,"tf2-keras-transformer-elastic-20210723-045144":1,"tf2-keras-transformer-elastic-20210723-045458":1,"tf2-keras-transformer-elastic-20210723-051649":0} "scheduler"="default"
I0723 17:18:49.297900    7682 scheduler.go:384]  "msg"="Trying to delete multiple training jobs"  "jobs"=["tf2-keras-cifar10-inceptionv3-elastic-20210723-044237","tf2-keras-transformer-elastic-20210723-051649"] "scheduler"="default"
I0723 17:18:49.316303    7682 scheduler.go:342]  "msg"="Trying to scale multiple training jobs"  "jobs"=[] "scheduler"="default"
I0723 17:18:49.316651    7682 scheduler.go:292]  "msg"="Trying to start multiple training jobs"  "jobs"=["tf2-keras-cifar10-resnet50-elastic-20210723-051722","tf2-keras-cifar10-vgg16-elastic-20210723-051707"] "scheduler"="default"
I0723 17:18:49.345228    7682 scheduler.go:342]  "msg"="Trying to scale multiple training jobs"  "jobs"=[] "scheduler"="default"
I0723 17:18:49.349873    7682 placement_manager.go:166]  "msg"="Started job placements adjustment"  "scheduler"="default"
I0723 17:18:49.350027    7682 placement_manager.go:192]  "msg"="Releasing slots"  "jobs"={"tf2-keras-cifar10-inceptionv3-elastic-20210723-042550":{},"tf2-keras-cifar10-inceptionv3-elastic-20210723-042602":{},"tf2-keras-cifar10-inceptionv3-elastic-20210723-044237":{},"tf2-keras-cifar10-resnet50-elastic-20210723-045445":{},"tf2-keras-cifar10-resnet50-elastic-20210723-045732":{},"tf2-keras-cifar10-vgg16-elastic-20210723-045210":{},"tf2-keras-cifar10-vgg16-elastic-20210723-045401":{},"tf2-keras-cifar10-vgg16-elastic-20210723-051039":{},"tf2-keras-transformer-elastic-20210723-043917":{},"tf2-keras-transformer-elastic-20210723-045144":{},"tf2-keras-transformer-elastic-20210723-045458":{},"tf2-keras-transformer-elastic-20210723-051649":{}} "nodes"={"gpu3":{},"gpu4":{},"gpu5":{}} "scheduler"="default"
I0723 17:18:49.350169    7682 placement_manager.go:250]  "msg"="Released slots"  "jobs"={"tf2-keras-cifar10-inceptionv3-elastic-20210723-042550":{},"tf2-keras-cifar10-inceptionv3-elastic-20210723-042602":{},"tf2-keras-cifar10-inceptionv3-elastic-20210723-044237":{},"tf2-keras-cifar10-resnet50-elastic-20210723-045445":{},"tf2-keras-cifar10-resnet50-elastic-20210723-045732":{},"tf2-keras-cifar10-vgg16-elastic-20210723-045210":{},"tf2-keras-cifar10-vgg16-elastic-20210723-045401":{},"tf2-keras-cifar10-vgg16-elastic-20210723-051039":{},"tf2-keras-transformer-elastic-20210723-043917":{},"tf2-keras-transformer-elastic-20210723-045144":{},"tf2-keras-transformer-elastic-20210723-045458":{},"tf2-keras-transformer-elastic-20210723-051649":{}} "nodes"={"gpu3":{},"gpu4":{},"gpu5":{}} "scheduler"="default"
I0723 17:18:49.350717    7682 placement_manager.go:305]  "msg"="Found best-fit"  "crossNode"=0 "nodes"=[{},{},{}] "requests"=[{},{},{},{},{},{},{},{},{},{},{},{},{},{},{},{},{},{},{},{},{},{},{},{},{},{},{},{},{},{},{},{},{},{}] "scheduler"="default"
I0723 17:18:49.351216    7682 placement_manager.go:339]  "msg"="nodeStates updated"  "new"={"gpu3":{},"gpu4":{},"gpu5":{}} "old"={"gpu3":{},"gpu4":{},"gpu5":{}} "scheduler"="default" "score"=5
I0723 17:18:49.351597    7682 placement_manager.go:387]  "msg"="jobStates updated"  "new"={"tf2-keras-cifar10-inceptionv3-elastic-20210723-042550":{},"tf2-keras-cifar10-inceptionv3-elastic-20210723-042602":{},"tf2-keras-cifar10-resnet50-elastic-20210723-045445":{},"tf2-keras-cifar10-resnet50-elastic-20210723-045732":{},"tf2-keras-cifar10-resnet50-elastic-20210723-051722":{},"tf2-keras-cifar10-vgg16-elastic-20210723-045210":{},"tf2-keras-cifar10-vgg16-elastic-20210723-045401":{},"tf2-keras-cifar10-vgg16-elastic-20210723-051039":{},"tf2-keras-cifar10-vgg16-elastic-20210723-051707":{},"tf2-keras-transformer-elastic-20210723-043917":{},"tf2-keras-transformer-elastic-20210723-045144":{},"tf2-keras-transformer-elastic-20210723-045458":{}} "old"={"tf2-keras-cifar10-inceptionv3-elastic-20210723-042550":{},"tf2-keras-cifar10-inceptionv3-elastic-20210723-042602":{},"tf2-keras-cifar10-inceptionv3-elastic-20210723-044237":{},"tf2-keras-cifar10-resnet50-elastic-20210723-045445":{},"tf2-keras-cifar10-resnet50-elastic-20210723-045732":{},"tf2-keras-cifar10-vgg16-elastic-20210723-045210":{},"tf2-keras-cifar10-vgg16-elastic-20210723-045401":{},"tf2-keras-cifar10-vgg16-elastic-20210723-051039":{},"tf2-keras-transformer-elastic-20210723-043917":{},"tf2-keras-transformer-elastic-20210723-045144":{},"tf2-keras-transformer-elastic-20210723-045458":{},"tf2-keras-transformer-elastic-20210723-051649":{}} "scheduler"="default"
I0723 17:18:49.352060    7682 placement_manager.go:434]  "msg"="podNodeName updated"  "launchersToDelete"=5 "new"={"tf2-keras-cifar10-inceptionv3-elastic-20210723-042550-worker-0":"gpu5","tf2-keras-cifar10-inceptionv3-elastic-20210723-042602-worker-0":"gpu3","tf2-keras-cifar10-resnet50-elastic-20210723-045445-worker-0":"gpu4","tf2-keras-cifar10-resnet50-elastic-20210723-045732-worker-0":"gpu5","tf2-keras-cifar10-resnet50-elastic-20210723-051722-worker-0":"gpu3","tf2-keras-cifar10-vgg16-elastic-20210723-045210-worker-0":"gpu4","tf2-keras-cifar10-vgg16-elastic-20210723-045401-worker-0":"gpu3","tf2-keras-cifar10-vgg16-elastic-20210723-051039-worker-0":"gpu3","tf2-keras-cifar10-vgg16-elastic-20210723-051707-worker-0":"gpu4","tf2-keras-transformer-elastic-20210723-043917-worker-0":"gpu5","tf2-keras-transformer-elastic-20210723-045144-worker-0":"gpu5","tf2-keras-transformer-elastic-20210723-045458-worker-0":"gpu4"} "old"={"tf2-keras-cifar10-inceptionv3-elastic-20210723-042550-worker-0":"gpu4","tf2-keras-cifar10-inceptionv3-elastic-20210723-042602-worker-0":"gpu3","tf2-keras-cifar10-inceptionv3-elastic-20210723-044237-worker-0":"gpu5","tf2-keras-cifar10-resnet50-elastic-20210723-045445-worker-0":"gpu4","tf2-keras-cifar10-resnet50-elastic-20210723-045732-worker-0":"gpu3","tf2-keras-cifar10-vgg16-elastic-20210723-045210-worker-0":"gpu5","tf2-keras-cifar10-vgg16-elastic-20210723-045401-worker-0":"gpu4","tf2-keras-cifar10-vgg16-elastic-20210723-051039-worker-0":"gpu3","tf2-keras-transformer-elastic-20210723-043917-worker-0":"gpu3","tf2-keras-transformer-elastic-20210723-045144-worker-0":"gpu5","tf2-keras-transformer-elastic-20210723-045458-worker-0":"gpu4","tf2-keras-transformer-elastic-20210723-051649-worker-0":"gpu5"} "scheduler"="default" "workersToDelete"=5
I0723 17:18:49.352528    7682 placement_manager.go:451]  "msg"="Deleting pod that need migration"  "podName"="tf2-keras-cifar10-inceptionv3-elastic-20210723-042550-worker-0" "scheduler"="default"
I0723 17:18:49.357577    7682 placement_manager.go:451]  "msg"="Deleting pod that need migration"  "podName"="tf2-keras-cifar10-inceptionv3-elastic-20210723-042550-launcher" "scheduler"="default"
I0723 17:18:49.361770    7682 placement_manager.go:451]  "msg"="Deleting pod that need migration"  "podName"="tf2-keras-cifar10-vgg16-elastic-20210723-045401-worker-0" "scheduler"="default"
I0723 17:18:49.367534    7682 placement_manager.go:451]  "msg"="Deleting pod that need migration"  "podName"="tf2-keras-cifar10-vgg16-elastic-20210723-045401-launcher" "scheduler"="default"
I0723 17:18:49.375446    7682 placement_manager.go:451]  "msg"="Deleting pod that need migration"  "podName"="tf2-keras-cifar10-vgg16-elastic-20210723-045210-worker-0" "scheduler"="default"
I0723 17:18:49.380757    7682 placement_manager.go:451]  "msg"="Deleting pod that need migration"  "podName"="tf2-keras-cifar10-vgg16-elastic-20210723-045210-launcher" "scheduler"="default"
I0723 17:18:49.385524    7682 placement_manager.go:451]  "msg"="Deleting pod that need migration"  "podName"="tf2-keras-cifar10-resnet50-elastic-20210723-045732-worker-0" "scheduler"="default"
I0723 17:18:49.392289    7682 placement_manager.go:451]  "msg"="Deleting pod that need migration"  "podName"="tf2-keras-cifar10-resnet50-elastic-20210723-045732-launcher" "scheduler"="default"
I0723 17:18:49.396914    7682 placement_manager.go:451]  "msg"="Deleting pod that need migration"  "podName"="tf2-keras-transformer-elastic-20210723-043917-worker-0" "scheduler"="default"
I0723 17:18:49.400940    7682 placement_manager.go:451]  "msg"="Deleting pod that need migration"  "podName"="tf2-keras-transformer-elastic-20210723-043917-launcher" "scheduler"="default"
I0723 17:18:49.405808    7682 placement_manager.go:183]  "msg"="Finished job placements adjustment"  "scheduler"="default"
I0723 17:18:49.406018    7682 scheduler.go:182]  "msg"="Finished resched"  "scheduler"="default"
I0723 17:18:49.546302    7682 placement_manager.go:147]  "msg"="Adding toleration to pod"  "podName"="tf2-keras-cifar10-resnet50-elastic-20210723-051722-worker-0" "scheduler"="default" "toleration"={"key":"celeste/hostname","operator":"Equal","value":"gpu3","effect":"NoExecute"}
I0723 17:18:49.758433    7682 placement_manager.go:147]  "msg"="Adding toleration to pod"  "podName"="tf2-keras-cifar10-vgg16-elastic-20210723-051707-worker-0" "scheduler"="default" "toleration"={"key":"celeste/hostname","operator":"Equal","value":"gpu4","effect":"NoExecute"}
I0723 17:18:50.163039    7682 placement_manager.go:147]  "msg"="Adding toleration to pod"  "podName"="tf2-keras-cifar10-resnet50-elastic-20210723-051722-launcher" "scheduler"="default" "toleration"={"key":"celeste/hostname","operator":"Exists","effect":"NoExecute"}
I0723 17:18:50.563306    7682 placement_manager.go:147]  "msg"="Adding toleration to pod"  "podName"="tf2-keras-cifar10-vgg16-elastic-20210723-051707-launcher" "scheduler"="default" "toleration"={"key":"celeste/hostname","operator":"Exists","effect":"NoExecute"}
I0723 17:18:57.775451    7682 placement_manager.go:147]  "msg"="Adding toleration to pod"  "podName"="tf2-keras-cifar10-inceptionv3-elastic-20210723-042550-worker-0" "scheduler"="default" "toleration"={"key":"celeste/hostname","operator":"Equal","value":"gpu5","effect":"NoExecute"}
I0723 17:18:58.994665    7682 placement_manager.go:147]  "msg"="Adding toleration to pod"  "podName"="tf2-keras-cifar10-resnet50-elastic-20210723-045732-launcher" "scheduler"="default" "toleration"={"key":"celeste/hostname","operator":"Exists","effect":"NoExecute"}
I0723 17:18:59.593750    7682 placement_manager.go:147]  "msg"="Adding toleration to pod"  "podName"="tf2-keras-cifar10-inceptionv3-elastic-20210723-042550-launcher" "scheduler"="default" "toleration"={"key":"celeste/hostname","operator":"Exists","effect":"NoExecute"}
I0723 17:19:01.482813    7682 placement_manager.go:147]  "msg"="Adding toleration to pod"  "podName"="tf2-keras-cifar10-vgg16-elastic-20210723-045210-worker-0" "scheduler"="default" "toleration"={"key":"celeste/hostname","operator":"Equal","value":"gpu4","effect":"NoExecute"}
I0723 17:19:01.590922    7682 placement_manager.go:147]  "msg"="Adding toleration to pod"  "podName"="tf2-keras-cifar10-vgg16-elastic-20210723-045401-launcher" "scheduler"="default" "toleration"={"key":"celeste/hostname","operator":"Exists","effect":"NoExecute"}
I0723 17:19:02.296130    7682 placement_manager.go:147]  "msg"="Adding toleration to pod"  "podName"="tf2-keras-cifar10-vgg16-elastic-20210723-045210-launcher" "scheduler"="default" "toleration"={"key":"celeste/hostname","operator":"Exists","effect":"NoExecute"}
I0723 17:19:03.847659    7682 placement_manager.go:147]  "msg"="Adding toleration to pod"  "podName"="tf2-keras-transformer-elastic-20210723-043917-worker-0" "scheduler"="default" "toleration"={"key":"celeste/hostname","operator":"Equal","value":"gpu5","effect":"NoExecute"}
I0723 17:19:03.880975    7682 placement_manager.go:147]  "msg"="Adding toleration to pod"  "podName"="tf2-keras-transformer-elastic-20210723-043917-launcher" "scheduler"="default" "toleration"={"key":"celeste/hostname","operator":"Exists","effect":"NoExecute"}
I0723 17:19:03.891302    7682 placement_manager.go:147]  "msg"="Adding toleration to pod"  "podName"="tf2-keras-cifar10-resnet50-elastic-20210723-045732-worker-0" "scheduler"="default" "toleration"={"key":"celeste/hostname","operator":"Equal","value":"gpu5","effect":"NoExecute"}
I0723 17:19:03.989197    7682 placement_manager.go:147]  "msg"="Adding toleration to pod"  "podName"="tf2-keras-cifar10-vgg16-elastic-20210723-045401-worker-0" "scheduler"="default" "toleration"={"key":"celeste/hostname","operator":"Equal","value":"gpu3","effect":"NoExecute"}
I0723 17:19:25.074613    7682 jobmaster.go:155]  "msg"="Training job created"  "job"="tf2-keras-cifar10-resnet50-elastic-20210723-051925"
I0723 17:19:25.074735    7682 scheduler.go:135]  "msg"="Received resched event, may be blocked because of rate limit"  "blockedUntil"="2021-07-23T17:20:49.406169231+08:00" "lastResched"="2021-07-23T17:18:49.406169231+08:00" "received"="2021-07-23T17:19:25.073885662+08:00" "scheduler"="default"
I0723 17:19:50.061706    7682 jobmaster.go:155]  "msg"="Training job created"  "job"="tf2-keras-transformer-elastic-20210723-051950"
I0723 17:20:30.843325    7682 scheduler.go:474]  "msg"="Training job completed"  "elaspedTotalSeconds"=1698.426293193 "gpuTotalSeconds"=1625.052716305 "job"="tf2-keras-cifar10-vgg16-elastic-20210723-045210" "ranTotalSeconds"=1625.052716305 "scheduler"="default" "waitedTotalSeconds"=73.373576888
I0723 17:20:49.406225    7682 scheduler.go:159]  "msg"="Started resched"  "scheduler"="default"
I0723 17:20:49.406338    7682 scheduler.go:193]  "msg"="Updating all jobs info"  "scheduler"="default"
I0723 17:20:49.423054    7682 afsl.go:65]  "msg"="Finished scheduling"  "algorithm"="AFS-L" "freeGpu"=0 "result"={"tf2-keras-cifar10-inceptionv3-elastic-20210723-042550":1,"tf2-keras-cifar10-inceptionv3-elastic-20210723-042602":1,"tf2-keras-cifar10-inceptionv3-elastic-20210723-044237":0,"tf2-keras-cifar10-inceptionv3-elastic-20210723-045126":0,"tf2-keras-cifar10-inceptionv3-elastic-20210723-045447":0,"tf2-keras-cifar10-inceptionv3-elastic-20210723-045501":0,"tf2-keras-cifar10-resnet50-elastic-20210723-045445":1,"tf2-keras-cifar10-resnet50-elastic-20210723-045732":1,"tf2-keras-cifar10-resnet50-elastic-20210723-051722":1,"tf2-keras-cifar10-resnet50-elastic-20210723-051925":1,"tf2-keras-cifar10-vgg16-elastic-20210723-045401":1,"tf2-keras-cifar10-vgg16-elastic-20210723-051039":1,"tf2-keras-cifar10-vgg16-elastic-20210723-051707":1,"tf2-keras-transformer-elastic-20210723-043917":1,"tf2-keras-transformer-elastic-20210723-045144":1,"tf2-keras-transformer-elastic-20210723-045458":1,"tf2-keras-transformer-elastic-20210723-051649":0,"tf2-keras-transformer-elastic-20210723-051950":0} "scheduler"="default"
I0723 17:20:49.423489    7682 scheduler.go:384]  "msg"="Trying to delete multiple training jobs"  "jobs"=[] "scheduler"="default"
I0723 17:20:49.423762    7682 scheduler.go:342]  "msg"="Trying to scale multiple training jobs"  "jobs"=[] "scheduler"="default"
I0723 17:20:49.424018    7682 scheduler.go:292]  "msg"="Trying to start multiple training jobs"  "jobs"=["tf2-keras-cifar10-resnet50-elastic-20210723-051925"] "scheduler"="default"
I0723 17:20:49.435483    7682 scheduler.go:342]  "msg"="Trying to scale multiple training jobs"  "jobs"=[] "scheduler"="default"
I0723 17:20:49.440071    7682 placement_manager.go:166]  "msg"="Started job placements adjustment"  "scheduler"="default"
I0723 17:20:49.440171    7682 placement_manager.go:192]  "msg"="Releasing slots"  "jobs"={"tf2-keras-cifar10-inceptionv3-elastic-20210723-042550":{},"tf2-keras-cifar10-inceptionv3-elastic-20210723-042602":{},"tf2-keras-cifar10-resnet50-elastic-20210723-045445":{},"tf2-keras-cifar10-resnet50-elastic-20210723-045732":{},"tf2-keras-cifar10-resnet50-elastic-20210723-051722":{},"tf2-keras-cifar10-vgg16-elastic-20210723-045210":{},"tf2-keras-cifar10-vgg16-elastic-20210723-045401":{},"tf2-keras-cifar10-vgg16-elastic-20210723-051039":{},"tf2-keras-cifar10-vgg16-elastic-20210723-051707":{},"tf2-keras-transformer-elastic-20210723-043917":{},"tf2-keras-transformer-elastic-20210723-045144":{},"tf2-keras-transformer-elastic-20210723-045458":{}} "nodes"={"gpu3":{},"gpu4":{},"gpu5":{}} "scheduler"="default"
I0723 17:20:49.440253    7682 placement_manager.go:250]  "msg"="Released slots"  "jobs"={"tf2-keras-cifar10-inceptionv3-elastic-20210723-042550":{},"tf2-keras-cifar10-inceptionv3-elastic-20210723-042602":{},"tf2-keras-cifar10-resnet50-elastic-20210723-045445":{},"tf2-keras-cifar10-resnet50-elastic-20210723-045732":{},"tf2-keras-cifar10-resnet50-elastic-20210723-051722":{},"tf2-keras-cifar10-vgg16-elastic-20210723-045210":{},"tf2-keras-cifar10-vgg16-elastic-20210723-045401":{},"tf2-keras-cifar10-vgg16-elastic-20210723-051039":{},"tf2-keras-cifar10-vgg16-elastic-20210723-051707":{},"tf2-keras-transformer-elastic-20210723-043917":{},"tf2-keras-transformer-elastic-20210723-045144":{},"tf2-keras-transformer-elastic-20210723-045458":{}} "nodes"={"gpu3":{},"gpu4":{},"gpu5":{}} "scheduler"="default"
I0723 17:20:49.440690    7682 placement_manager.go:305]  "msg"="Found best-fit"  "crossNode"=0 "nodes"=[{},{},{}] "requests"=[{},{},{},{},{},{},{},{},{},{},{},{},{},{},{},{},{},{},{},{},{},{},{},{},{},{},{},{},{},{},{},{},{},{},{},{}] "scheduler"="default"
I0723 17:20:49.440969    7682 placement_manager.go:339]  "msg"="nodeStates updated"  "new"={"gpu3":{},"gpu4":{},"gpu5":{}} "old"={"gpu3":{},"gpu4":{},"gpu5":{}} "scheduler"="default" "score"=6
I0723 17:20:49.441312    7682 placement_manager.go:387]  "msg"="jobStates updated"  "new"={"tf2-keras-cifar10-inceptionv3-elastic-20210723-042550":{},"tf2-keras-cifar10-inceptionv3-elastic-20210723-042602":{},"tf2-keras-cifar10-resnet50-elastic-20210723-045445":{},"tf2-keras-cifar10-resnet50-elastic-20210723-045732":{},"tf2-keras-cifar10-resnet50-elastic-20210723-051722":{},"tf2-keras-cifar10-resnet50-elastic-20210723-051925":{},"tf2-keras-cifar10-vgg16-elastic-20210723-045401":{},"tf2-keras-cifar10-vgg16-elastic-20210723-051039":{},"tf2-keras-cifar10-vgg16-elastic-20210723-051707":{},"tf2-keras-transformer-elastic-20210723-043917":{},"tf2-keras-transformer-elastic-20210723-045144":{},"tf2-keras-transformer-elastic-20210723-045458":{}} "old"={"tf2-keras-cifar10-inceptionv3-elastic-20210723-042550":{},"tf2-keras-cifar10-inceptionv3-elastic-20210723-042602":{},"tf2-keras-cifar10-resnet50-elastic-20210723-045445":{},"tf2-keras-cifar10-resnet50-elastic-20210723-045732":{},"tf2-keras-cifar10-resnet50-elastic-20210723-051722":{},"tf2-keras-cifar10-vgg16-elastic-20210723-045210":{},"tf2-keras-cifar10-vgg16-elastic-20210723-045401":{},"tf2-keras-cifar10-vgg16-elastic-20210723-051039":{},"tf2-keras-cifar10-vgg16-elastic-20210723-051707":{},"tf2-keras-transformer-elastic-20210723-043917":{},"tf2-keras-transformer-elastic-20210723-045144":{},"tf2-keras-transformer-elastic-20210723-045458":{}} "scheduler"="default"
I0723 17:20:49.441836    7682 placement_manager.go:434]  "msg"="podNodeName updated"  "launchersToDelete"=5 "new"={"tf2-keras-cifar10-inceptionv3-elastic-20210723-042550-worker-0":"gpu4","tf2-keras-cifar10-inceptionv3-elastic-20210723-042602-worker-0":"gpu4","tf2-keras-cifar10-resnet50-elastic-20210723-045445-worker-0":"gpu4","tf2-keras-cifar10-resnet50-elastic-20210723-045732-worker-0":"gpu5","tf2-keras-cifar10-resnet50-elastic-20210723-051722-worker-0":"gpu3","tf2-keras-cifar10-resnet50-elastic-20210723-051925-worker-0":"gpu3","tf2-keras-cifar10-vgg16-elastic-20210723-045401-worker-0":"gpu4","tf2-keras-cifar10-vgg16-elastic-20210723-051039-worker-0":"gpu3","tf2-keras-cifar10-vgg16-elastic-20210723-051707-worker-0":"gpu5","tf2-keras-transformer-elastic-20210723-043917-worker-0":"gpu5","tf2-keras-transformer-elastic-20210723-045144-worker-0":"gpu5","tf2-keras-transformer-elastic-20210723-045458-worker-0":"gpu3"} "old"={"tf2-keras-cifar10-inceptionv3-elastic-20210723-042550-worker-0":"gpu5","tf2-keras-cifar10-inceptionv3-elastic-20210723-042602-worker-0":"gpu3","tf2-keras-cifar10-resnet50-elastic-20210723-045445-worker-0":"gpu4","tf2-keras-cifar10-resnet50-elastic-20210723-045732-worker-0":"gpu5","tf2-keras-cifar10-resnet50-elastic-20210723-051722-worker-0":"gpu3","tf2-keras-cifar10-vgg16-elastic-20210723-045210-worker-0":"gpu4","tf2-keras-cifar10-vgg16-elastic-20210723-045401-worker-0":"gpu3","tf2-keras-cifar10-vgg16-elastic-20210723-051039-worker-0":"gpu3","tf2-keras-cifar10-vgg16-elastic-20210723-051707-worker-0":"gpu4","tf2-keras-transformer-elastic-20210723-043917-worker-0":"gpu5","tf2-keras-transformer-elastic-20210723-045144-worker-0":"gpu5","tf2-keras-transformer-elastic-20210723-045458-worker-0":"gpu4"} "scheduler"="default" "workersToDelete"=5
I0723 17:20:49.442209    7682 placement_manager.go:451]  "msg"="Deleting pod that need migration"  "podName"="tf2-keras-cifar10-vgg16-elastic-20210723-045401-worker-0" "scheduler"="default"
I0723 17:20:49.447049    7682 placement_manager.go:451]  "msg"="Deleting pod that need migration"  "podName"="tf2-keras-cifar10-vgg16-elastic-20210723-045401-launcher" "scheduler"="default"
I0723 17:20:49.452804    7682 placement_manager.go:451]  "msg"="Deleting pod that need migration"  "podName"="tf2-keras-cifar10-inceptionv3-elastic-20210723-042550-worker-0" "scheduler"="default"
I0723 17:20:49.457864    7682 placement_manager.go:451]  "msg"="Deleting pod that need migration"  "podName"="tf2-keras-cifar10-inceptionv3-elastic-20210723-042550-launcher" "scheduler"="default"
I0723 17:20:49.479959    7682 placement_manager.go:451]  "msg"="Deleting pod that need migration"  "podName"="tf2-keras-cifar10-inceptionv3-elastic-20210723-042602-worker-0" "scheduler"="default"
I0723 17:20:49.484352    7682 placement_manager.go:451]  "msg"="Deleting pod that need migration"  "podName"="tf2-keras-cifar10-inceptionv3-elastic-20210723-042602-launcher" "scheduler"="default"
I0723 17:20:49.489023    7682 placement_manager.go:451]  "msg"="Deleting pod that need migration"  "podName"="tf2-keras-cifar10-vgg16-elastic-20210723-051707-worker-0" "scheduler"="default"
I0723 17:20:49.495213    7682 placement_manager.go:451]  "msg"="Deleting pod that need migration"  "podName"="tf2-keras-cifar10-vgg16-elastic-20210723-051707-launcher" "scheduler"="default"
I0723 17:20:49.499799    7682 placement_manager.go:451]  "msg"="Deleting pod that need migration"  "podName"="tf2-keras-transformer-elastic-20210723-045458-worker-0" "scheduler"="default"
I0723 17:20:49.507109    7682 placement_manager.go:451]  "msg"="Deleting pod that need migration"  "podName"="tf2-keras-transformer-elastic-20210723-045458-launcher" "scheduler"="default"
I0723 17:20:49.513929    7682 placement_manager.go:183]  "msg"="Finished job placements adjustment"  "scheduler"="default"
I0723 17:20:49.514241    7682 scheduler.go:182]  "msg"="Finished resched"  "scheduler"="default"
I0723 17:20:49.845586    7682 scheduler.go:474]  "msg"="Training job completed"  "elaspedTotalSeconds"=2491.047540853 "gpuTotalSeconds"=3217.038914039 "job"="tf2-keras-transformer-elastic-20210723-043917" "ranTotalSeconds"=2491.047540853 "scheduler"="default" "waitedTotalSeconds"=0
I0723 17:20:49.845629    7682 placement_manager.go:147]  "msg"="Adding toleration to pod"  "podName"="tf2-keras-cifar10-resnet50-elastic-20210723-051925-worker-0" "scheduler"="default" "toleration"={"key":"celeste/hostname","operator":"Equal","value":"gpu3","effect":"NoExecute"}
I0723 17:20:49.845750    7682 scheduler.go:135]  "msg"="Received resched event, may be blocked because of rate limit"  "blockedUntil"="2021-07-23T17:22:49.514670497+08:00" "lastResched"="2021-07-23T17:20:49.514670497+08:00" "received"="2021-07-23T17:20:49.845625727+08:00" "scheduler"="default"
I0723 17:20:50.250521    7682 placement_manager.go:147]  "msg"="Adding toleration to pod"  "podName"="tf2-keras-cifar10-resnet50-elastic-20210723-051925-launcher" "scheduler"="default" "toleration"={"key":"celeste/hostname","operator":"Exists","effect":"NoExecute"}
I0723 17:20:56.887283    7682 placement_manager.go:147]  "msg"="Adding toleration to pod"  "podName"="tf2-keras-transformer-elastic-20210723-045458-worker-0" "scheduler"="default" "toleration"={"key":"celeste/hostname","operator":"Equal","value":"gpu3","effect":"NoExecute"}
I0723 17:20:56.922738    7682 placement_manager.go:147]  "msg"="Adding toleration to pod"  "podName"="tf2-keras-cifar10-vgg16-elastic-20210723-051707-worker-0" "scheduler"="default" "toleration"={"key":"celeste/hostname","operator":"Equal","value":"gpu5","effect":"NoExecute"}
I0723 17:20:56.932234    7682 placement_manager.go:147]  "msg"="Adding toleration to pod"  "podName"="tf2-keras-cifar10-vgg16-elastic-20210723-045401-launcher" "scheduler"="default" "toleration"={"key":"celeste/hostname","operator":"Exists","effect":"NoExecute"}
I0723 17:21:00.271111    7682 placement_manager.go:147]  "msg"="Adding toleration to pod"  "podName"="tf2-keras-cifar10-inceptionv3-elastic-20210723-042602-launcher" "scheduler"="default" "toleration"={"key":"celeste/hostname","operator":"Exists","effect":"NoExecute"}
I0723 17:21:04.584187    7682 placement_manager.go:147]  "msg"="Adding toleration to pod"  "podName"="tf2-keras-cifar10-vgg16-elastic-20210723-051707-launcher" "scheduler"="default" "toleration"={"key":"celeste/hostname","operator":"Exists","effect":"NoExecute"}
I0723 17:21:04.762570    7682 placement_manager.go:147]  "msg"="Adding toleration to pod"  "podName"="tf2-keras-cifar10-vgg16-elastic-20210723-045401-worker-0" "scheduler"="default" "toleration"={"key":"celeste/hostname","operator":"Equal","value":"gpu4","effect":"NoExecute"}
I0723 17:21:05.564201    7682 placement_manager.go:147]  "msg"="Adding toleration to pod"  "podName"="tf2-keras-cifar10-inceptionv3-elastic-20210723-042602-worker-0" "scheduler"="default" "toleration"={"key":"celeste/hostname","operator":"Equal","value":"gpu4","effect":"NoExecute"}
I0723 17:21:09.740656    7682 placement_manager.go:147]  "msg"="Adding toleration to pod"  "podName"="tf2-keras-transformer-elastic-20210723-045458-launcher" "scheduler"="default" "toleration"={"key":"celeste/hostname","operator":"Exists","effect":"NoExecute"}
I0723 17:21:09.796565    7682 placement_manager.go:147]  "msg"="Adding toleration to pod"  "podName"="tf2-keras-cifar10-inceptionv3-elastic-20210723-042550-launcher" "scheduler"="default" "toleration"={"key":"celeste/hostname","operator":"Exists","effect":"NoExecute"}
I0723 17:21:09.865883    7682 placement_manager.go:147]  "msg"="Adding toleration to pod"  "podName"="tf2-keras-cifar10-inceptionv3-elastic-20210723-042550-worker-0" "scheduler"="default" "toleration"={"key":"celeste/hostname","operator":"Equal","value":"gpu4","effect":"NoExecute"}
I0723 17:22:12.222890    7682 scheduler.go:474]  "msg"="Training job completed"  "elaspedTotalSeconds"=1687.442682841 "gpuTotalSeconds"=1605.052059651 "job"="tf2-keras-cifar10-vgg16-elastic-20210723-045401" "ranTotalSeconds"=1605.052059651 "scheduler"="default" "waitedTotalSeconds"=82.39062319
I0723 17:22:13.274276    7682 scheduler.go:474]  "msg"="Training job completed"  "elaspedTotalSeconds"=1643.496145954 "gpuTotalSeconds"=1605.052027 "job"="tf2-keras-cifar10-resnet50-elastic-20210723-045445" "ranTotalSeconds"=1605.052027 "scheduler"="default" "waitedTotalSeconds"=38.444118954
I0723 17:22:44.284763    7682 scheduler.go:474]  "msg"="Training job completed"  "elaspedTotalSeconds"=1511.721386192 "gpuTotalSeconds"=1511.721386192 "job"="tf2-keras-cifar10-resnet50-elastic-20210723-045732" "ranTotalSeconds"=1511.721386192 "scheduler"="default" "waitedTotalSeconds"=0
I0723 17:22:49.514736    7682 scheduler.go:159]  "msg"="Started resched"  "scheduler"="default"
I0723 17:22:49.514828    7682 scheduler.go:193]  "msg"="Updating all jobs info"  "scheduler"="default"
I0723 17:22:49.525870    7682 afsl.go:65]  "msg"="Finished scheduling"  "algorithm"="AFS-L" "freeGpu"=0 "result"={"tf2-keras-cifar10-inceptionv3-elastic-20210723-042550":1,"tf2-keras-cifar10-inceptionv3-elastic-20210723-042602":1,"tf2-keras-cifar10-inceptionv3-elastic-20210723-044237":1,"tf2-keras-cifar10-inceptionv3-elastic-20210723-045126":0,"tf2-keras-cifar10-inceptionv3-elastic-20210723-045447":0,"tf2-keras-cifar10-inceptionv3-elastic-20210723-045501":1,"tf2-keras-cifar10-resnet50-elastic-20210723-051722":1,"tf2-keras-cifar10-resnet50-elastic-20210723-051925":1,"tf2-keras-cifar10-vgg16-elastic-20210723-051039":1,"tf2-keras-cifar10-vgg16-elastic-20210723-051707":1,"tf2-keras-transformer-elastic-20210723-045144":1,"tf2-keras-transformer-elastic-20210723-045458":1,"tf2-keras-transformer-elastic-20210723-051649":1,"tf2-keras-transformer-elastic-20210723-051950":1} "scheduler"="default"
I0723 17:22:49.526289    7682 scheduler.go:384]  "msg"="Trying to delete multiple training jobs"  "jobs"=[] "scheduler"="default"
I0723 17:22:49.526488    7682 scheduler.go:342]  "msg"="Trying to scale multiple training jobs"  "jobs"=[] "scheduler"="default"
I0723 17:22:49.526700    7682 scheduler.go:292]  "msg"="Trying to start multiple training jobs"  "jobs"=["tf2-keras-cifar10-inceptionv3-elastic-20210723-044237","tf2-keras-cifar10-inceptionv3-elastic-20210723-045501","tf2-keras-transformer-elastic-20210723-051950","tf2-keras-transformer-elastic-20210723-051649"] "scheduler"="default"
I0723 17:22:49.580691    7682 scheduler.go:342]  "msg"="Trying to scale multiple training jobs"  "jobs"=[] "scheduler"="default"
I0723 17:22:49.584631    7682 placement_manager.go:166]  "msg"="Started job placements adjustment"  "scheduler"="default"
I0723 17:22:49.584702    7682 placement_manager.go:192]  "msg"="Releasing slots"  "jobs"={"tf2-keras-cifar10-inceptionv3-elastic-20210723-042550":{},"tf2-keras-cifar10-inceptionv3-elastic-20210723-042602":{},"tf2-keras-cifar10-resnet50-elastic-20210723-045445":{},"tf2-keras-cifar10-resnet50-elastic-20210723-045732":{},"tf2-keras-cifar10-resnet50-elastic-20210723-051722":{},"tf2-keras-cifar10-resnet50-elastic-20210723-051925":{},"tf2-keras-cifar10-vgg16-elastic-20210723-045401":{},"tf2-keras-cifar10-vgg16-elastic-20210723-051039":{},"tf2-keras-cifar10-vgg16-elastic-20210723-051707":{},"tf2-keras-transformer-elastic-20210723-043917":{},"tf2-keras-transformer-elastic-20210723-045144":{},"tf2-keras-transformer-elastic-20210723-045458":{}} "nodes"={"gpu3":{},"gpu4":{},"gpu5":{}} "scheduler"="default"
I0723 17:22:49.584807    7682 placement_manager.go:250]  "msg"="Released slots"  "jobs"={"tf2-keras-cifar10-inceptionv3-elastic-20210723-042550":{},"tf2-keras-cifar10-inceptionv3-elastic-20210723-042602":{},"tf2-keras-cifar10-resnet50-elastic-20210723-045445":{},"tf2-keras-cifar10-resnet50-elastic-20210723-045732":{},"tf2-keras-cifar10-resnet50-elastic-20210723-051722":{},"tf2-keras-cifar10-resnet50-elastic-20210723-051925":{},"tf2-keras-cifar10-vgg16-elastic-20210723-045401":{},"tf2-keras-cifar10-vgg16-elastic-20210723-051039":{},"tf2-keras-cifar10-vgg16-elastic-20210723-051707":{},"tf2-keras-transformer-elastic-20210723-043917":{},"tf2-keras-transformer-elastic-20210723-045144":{},"tf2-keras-transformer-elastic-20210723-045458":{}} "nodes"={"gpu3":{},"gpu4":{},"gpu5":{}} "scheduler"="default"
I0723 17:22:49.585236    7682 placement_manager.go:305]  "msg"="Found best-fit"  "crossNode"=0 "nodes"=[{},{},{}] "requests"=[{},{},{},{},{},{},{},{},{},{},{},{},{},{},{},{},{},{},{},{},{},{},{},{},{},{},{},{}] "scheduler"="default"
I0723 17:22:49.585523    7682 placement_manager.go:339]  "msg"="nodeStates updated"  "new"={"gpu3":{},"gpu4":{},"gpu5":{}} "old"={"gpu3":{},"gpu4":{},"gpu5":{}} "scheduler"="default" "score"=4
I0723 17:22:49.585823    7682 placement_manager.go:387]  "msg"="jobStates updated"  "new"={"tf2-keras-cifar10-inceptionv3-elastic-20210723-042550":{},"tf2-keras-cifar10-inceptionv3-elastic-20210723-042602":{},"tf2-keras-cifar10-inceptionv3-elastic-20210723-044237":{},"tf2-keras-cifar10-inceptionv3-elastic-20210723-045501":{},"tf2-keras-cifar10-resnet50-elastic-20210723-051722":{},"tf2-keras-cifar10-resnet50-elastic-20210723-051925":{},"tf2-keras-cifar10-vgg16-elastic-20210723-051039":{},"tf2-keras-cifar10-vgg16-elastic-20210723-051707":{},"tf2-keras-transformer-elastic-20210723-045144":{},"tf2-keras-transformer-elastic-20210723-045458":{},"tf2-keras-transformer-elastic-20210723-051649":{},"tf2-keras-transformer-elastic-20210723-051950":{}} "old"={"tf2-keras-cifar10-inceptionv3-elastic-20210723-042550":{},"tf2-keras-cifar10-inceptionv3-elastic-20210723-042602":{},"tf2-keras-cifar10-resnet50-elastic-20210723-045445":{},"tf2-keras-cifar10-resnet50-elastic-20210723-045732":{},"tf2-keras-cifar10-resnet50-elastic-20210723-051722":{},"tf2-keras-cifar10-resnet50-elastic-20210723-051925":{},"tf2-keras-cifar10-vgg16-elastic-20210723-045401":{},"tf2-keras-cifar10-vgg16-elastic-20210723-051039":{},"tf2-keras-cifar10-vgg16-elastic-20210723-051707":{},"tf2-keras-transformer-elastic-20210723-043917":{},"tf2-keras-transformer-elastic-20210723-045144":{},"tf2-keras-transformer-elastic-20210723-045458":{}} "scheduler"="default"
I0723 17:22:49.586203    7682 placement_manager.go:434]  "msg"="podNodeName updated"  "launchersToDelete"=4 "new"={"tf2-keras-cifar10-inceptionv3-elastic-20210723-042550-worker-0":"gpu5","tf2-keras-cifar10-inceptionv3-elastic-20210723-042602-worker-0":"gpu4","tf2-keras-cifar10-inceptionv3-elastic-20210723-044237-worker-0":"gpu4","tf2-keras-cifar10-inceptionv3-elastic-20210723-045501-worker-0":"gpu4","tf2-keras-cifar10-resnet50-elastic-20210723-051722-worker-0":"gpu4","tf2-keras-cifar10-resnet50-elastic-20210723-051925-worker-0":"gpu3","tf2-keras-cifar10-vgg16-elastic-20210723-051039-worker-0":"gpu5","tf2-keras-cifar10-vgg16-elastic-20210723-051707-worker-0":"gpu3","tf2-keras-transformer-elastic-20210723-045144-worker-0":"gpu5","tf2-keras-transformer-elastic-20210723-045458-worker-0":"gpu3","tf2-keras-transformer-elastic-20210723-051649-worker-0":"gpu3","tf2-keras-transformer-elastic-20210723-051950-worker-0":"gpu5"} "old"={"tf2-keras-cifar10-inceptionv3-elastic-20210723-042550-worker-0":"gpu4","tf2-keras-cifar10-inceptionv3-elastic-20210723-042602-worker-0":"gpu4","tf2-keras-cifar10-resnet50-elastic-20210723-045445-worker-0":"gpu4","tf2-keras-cifar10-resnet50-elastic-20210723-045732-worker-0":"gpu5","tf2-keras-cifar10-resnet50-elastic-20210723-051722-worker-0":"gpu3","tf2-keras-cifar10-resnet50-elastic-20210723-051925-worker-0":"gpu3","tf2-keras-cifar10-vgg16-elastic-20210723-045401-worker-0":"gpu4","tf2-keras-cifar10-vgg16-elastic-20210723-051039-worker-0":"gpu3","tf2-keras-cifar10-vgg16-elastic-20210723-051707-worker-0":"gpu5","tf2-keras-transformer-elastic-20210723-043917-worker-0":"gpu5","tf2-keras-transformer-elastic-20210723-045144-worker-0":"gpu5","tf2-keras-transformer-elastic-20210723-045458-worker-0":"gpu3"} "scheduler"="default" "workersToDelete"=4
I0723 17:22:49.586437    7682 placement_manager.go:451]  "msg"="Deleting pod that need migration"  "podName"="tf2-keras-cifar10-resnet50-elastic-20210723-051722-worker-0" "scheduler"="default"
I0723 17:22:49.590267    7682 placement_manager.go:451]  "msg"="Deleting pod that need migration"  "podName"="tf2-keras-cifar10-resnet50-elastic-20210723-051722-launcher" "scheduler"="default"
I0723 17:22:49.593715    7682 placement_manager.go:451]  "msg"="Deleting pod that need migration"  "podName"="tf2-keras-cifar10-inceptionv3-elastic-20210723-042550-worker-0" "scheduler"="default"
I0723 17:22:49.599256    7682 placement_manager.go:451]  "msg"="Deleting pod that need migration"  "podName"="tf2-keras-cifar10-inceptionv3-elastic-20210723-042550-launcher" "scheduler"="default"
I0723 17:22:49.603649    7682 placement_manager.go:451]  "msg"="Deleting pod that need migration"  "podName"="tf2-keras-cifar10-vgg16-elastic-20210723-051039-worker-0" "scheduler"="default"
I0723 17:22:49.608164    7682 placement_manager.go:451]  "msg"="Deleting pod that need migration"  "podName"="tf2-keras-cifar10-vgg16-elastic-20210723-051039-launcher" "scheduler"="default"
I0723 17:22:49.614205    7682 placement_manager.go:451]  "msg"="Deleting pod that need migration"  "podName"="tf2-keras-cifar10-vgg16-elastic-20210723-051707-worker-0" "scheduler"="default"
I0723 17:22:49.618029    7682 placement_manager.go:451]  "msg"="Deleting pod that need migration"  "podName"="tf2-keras-cifar10-vgg16-elastic-20210723-051707-launcher" "scheduler"="default"
I0723 17:22:49.626803    7682 placement_manager.go:183]  "msg"="Finished job placements adjustment"  "scheduler"="default"
I0723 17:22:49.627062    7682 scheduler.go:182]  "msg"="Finished resched"  "scheduler"="default"
I0723 17:22:49.945065    7682 placement_manager.go:147]  "msg"="Adding toleration to pod"  "podName"="tf2-keras-cifar10-inceptionv3-elastic-20210723-044237-worker-0" "scheduler"="default" "toleration"={"key":"celeste/hostname","operator":"Equal","value":"gpu4","effect":"NoExecute"}
I0723 17:22:50.346226    7682 placement_manager.go:147]  "msg"="Adding toleration to pod"  "podName"="tf2-keras-cifar10-inceptionv3-elastic-20210723-044237-launcher" "scheduler"="default" "toleration"={"key":"celeste/hostname","operator":"Exists","effect":"NoExecute"}
I0723 17:22:50.800170    7682 placement_manager.go:147]  "msg"="Adding toleration to pod"  "podName"="tf2-keras-cifar10-inceptionv3-elastic-20210723-045501-worker-0" "scheduler"="default" "toleration"={"key":"celeste/hostname","operator":"Equal","value":"gpu4","effect":"NoExecute"}
I0723 17:22:51.194785    7682 placement_manager.go:147]  "msg"="Adding toleration to pod"  "podName"="tf2-keras-cifar10-inceptionv3-elastic-20210723-045501-launcher" "scheduler"="default" "toleration"={"key":"celeste/hostname","operator":"Exists","effect":"NoExecute"}
I0723 17:22:52.345794    7682 placement_manager.go:147]  "msg"="Adding toleration to pod"  "podName"="tf2-keras-transformer-elastic-20210723-051950-worker-0" "scheduler"="default" "toleration"={"key":"celeste/hostname","operator":"Equal","value":"gpu5","effect":"NoExecute"}
I0723 17:22:52.745856    7682 placement_manager.go:147]  "msg"="Adding toleration to pod"  "podName"="tf2-keras-transformer-elastic-20210723-051950-launcher" "scheduler"="default" "toleration"={"key":"celeste/hostname","operator":"Exists","effect":"NoExecute"}
I0723 17:22:53.195995    7682 placement_manager.go:147]  "msg"="Adding toleration to pod"  "podName"="tf2-keras-transformer-elastic-20210723-051649-worker-0" "scheduler"="default" "toleration"={"key":"celeste/hostname","operator":"Equal","value":"gpu3","effect":"NoExecute"}
I0723 17:22:53.596138    7682 placement_manager.go:147]  "msg"="Adding toleration to pod"  "podName"="tf2-keras-transformer-elastic-20210723-051649-launcher" "scheduler"="default" "toleration"={"key":"celeste/hostname","operator":"Exists","effect":"NoExecute"}
I0723 17:22:56.559346    7682 placement_manager.go:147]  "msg"="Adding toleration to pod"  "podName"="tf2-keras-cifar10-vgg16-elastic-20210723-051039-worker-0" "scheduler"="default" "toleration"={"key":"celeste/hostname","operator":"Equal","value":"gpu5","effect":"NoExecute"}
I0723 17:23:03.856648    7682 placement_manager.go:147]  "msg"="Adding toleration to pod"  "podName"="tf2-keras-cifar10-resnet50-elastic-20210723-051722-worker-0" "scheduler"="default" "toleration"={"key":"celeste/hostname","operator":"Equal","value":"gpu4","effect":"NoExecute"}
I0723 17:23:03.887205    7682 placement_manager.go:147]  "msg"="Adding toleration to pod"  "podName"="tf2-keras-cifar10-vgg16-elastic-20210723-051039-launcher" "scheduler"="default" "toleration"={"key":"celeste/hostname","operator":"Exists","effect":"NoExecute"}
I0723 17:23:05.429404    7682 placement_manager.go:147]  "msg"="Adding toleration to pod"  "podName"="tf2-keras-cifar10-inceptionv3-elastic-20210723-042550-worker-0" "scheduler"="default" "toleration"={"key":"celeste/hostname","operator":"Equal","value":"gpu5","effect":"NoExecute"}
I0723 17:23:06.222549    7682 placement_manager.go:147]  "msg"="Adding toleration to pod"  "podName"="tf2-keras-cifar10-vgg16-elastic-20210723-051707-worker-0" "scheduler"="default" "toleration"={"key":"celeste/hostname","operator":"Equal","value":"gpu3","effect":"NoExecute"}
I0723 17:23:07.018972    7682 placement_manager.go:147]  "msg"="Adding toleration to pod"  "podName"="tf2-keras-cifar10-vgg16-elastic-20210723-051707-launcher" "scheduler"="default" "toleration"={"key":"celeste/hostname","operator":"Exists","effect":"NoExecute"}
I0723 17:23:11.427357    7682 placement_manager.go:147]  "msg"="Adding toleration to pod"  "podName"="tf2-keras-cifar10-resnet50-elastic-20210723-051722-launcher" "scheduler"="default" "toleration"={"key":"celeste/hostname","operator":"Exists","effect":"NoExecute"}
I0723 17:23:12.222749    7682 placement_manager.go:147]  "msg"="Adding toleration to pod"  "podName"="tf2-keras-cifar10-inceptionv3-elastic-20210723-042550-launcher" "scheduler"="default" "toleration"={"key":"celeste/hostname","operator":"Exists","effect":"NoExecute"}
I0723 17:36:49.346677    7682 scheduler.go:474]  "msg"="Training job completed"  "elaspedTotalSeconds"=1569.786298403 "gpuTotalSeconds"=1465.048670021 "job"="tf2-keras-cifar10-vgg16-elastic-20210723-051039" "ranTotalSeconds"=1465.048670021 "scheduler"="default" "waitedTotalSeconds"=104.737628382
I0723 17:36:49.346826    7682 scheduler.go:135]  "msg"="Received resched event, may be blocked because of rate limit"  "blockedUntil"="2021-07-23T17:24:49.62726962+08:00" "lastResched"="2021-07-23T17:22:49.62726962+08:00" "received"="2021-07-23T17:36:49.346712053+08:00" "scheduler"="default"
I0723 17:36:49.409176    7682 scheduler.go:159]  "msg"="Started resched"  "scheduler"="default"
I0723 17:36:49.409313    7682 scheduler.go:193]  "msg"="Updating all jobs info"  "scheduler"="default"
I0723 17:36:49.422885    7682 afsl.go:65]  "msg"="Finished scheduling"  "algorithm"="AFS-L" "freeGpu"=0 "result"={"tf2-keras-cifar10-inceptionv3-elastic-20210723-042550":1,"tf2-keras-cifar10-inceptionv3-elastic-20210723-042602":1,"tf2-keras-cifar10-inceptionv3-elastic-20210723-044237":1,"tf2-keras-cifar10-inceptionv3-elastic-20210723-045126":0,"tf2-keras-cifar10-inceptionv3-elastic-20210723-045447":1,"tf2-keras-cifar10-inceptionv3-elastic-20210723-045501":1,"tf2-keras-cifar10-resnet50-elastic-20210723-051722":1,"tf2-keras-cifar10-resnet50-elastic-20210723-051925":1,"tf2-keras-cifar10-vgg16-elastic-20210723-051707":1,"tf2-keras-transformer-elastic-20210723-045144":1,"tf2-keras-transformer-elastic-20210723-045458":1,"tf2-keras-transformer-elastic-20210723-051649":1,"tf2-keras-transformer-elastic-20210723-051950":1} "scheduler"="default"
I0723 17:36:49.423293    7682 scheduler.go:384]  "msg"="Trying to delete multiple training jobs"  "jobs"=[] "scheduler"="default"
I0723 17:36:49.423599    7682 scheduler.go:342]  "msg"="Trying to scale multiple training jobs"  "jobs"=[] "scheduler"="default"
I0723 17:36:49.423814    7682 scheduler.go:292]  "msg"="Trying to start multiple training jobs"  "jobs"=["tf2-keras-cifar10-inceptionv3-elastic-20210723-045447"] "scheduler"="default"
I0723 17:36:49.432908    7682 scheduler.go:342]  "msg"="Trying to scale multiple training jobs"  "jobs"=[] "scheduler"="default"
I0723 17:36:49.436099    7682 placement_manager.go:166]  "msg"="Started job placements adjustment"  "scheduler"="default"
I0723 17:36:49.436165    7682 placement_manager.go:192]  "msg"="Releasing slots"  "jobs"={"tf2-keras-cifar10-inceptionv3-elastic-20210723-042550":{},"tf2-keras-cifar10-inceptionv3-elastic-20210723-042602":{},"tf2-keras-cifar10-inceptionv3-elastic-20210723-044237":{},"tf2-keras-cifar10-inceptionv3-elastic-20210723-045501":{},"tf2-keras-cifar10-resnet50-elastic-20210723-051722":{},"tf2-keras-cifar10-resnet50-elastic-20210723-051925":{},"tf2-keras-cifar10-vgg16-elastic-20210723-051039":{},"tf2-keras-cifar10-vgg16-elastic-20210723-051707":{},"tf2-keras-transformer-elastic-20210723-045144":{},"tf2-keras-transformer-elastic-20210723-045458":{},"tf2-keras-transformer-elastic-20210723-051649":{},"tf2-keras-transformer-elastic-20210723-051950":{}} "nodes"={"gpu3":{},"gpu4":{},"gpu5":{}} "scheduler"="default"
I0723 17:36:49.436239    7682 placement_manager.go:250]  "msg"="Released slots"  "jobs"={"tf2-keras-cifar10-inceptionv3-elastic-20210723-042550":{},"tf2-keras-cifar10-inceptionv3-elastic-20210723-042602":{},"tf2-keras-cifar10-inceptionv3-elastic-20210723-044237":{},"tf2-keras-cifar10-inceptionv3-elastic-20210723-045501":{},"tf2-keras-cifar10-resnet50-elastic-20210723-051722":{},"tf2-keras-cifar10-resnet50-elastic-20210723-051925":{},"tf2-keras-cifar10-vgg16-elastic-20210723-051039":{},"tf2-keras-cifar10-vgg16-elastic-20210723-051707":{},"tf2-keras-transformer-elastic-20210723-045144":{},"tf2-keras-transformer-elastic-20210723-045458":{},"tf2-keras-transformer-elastic-20210723-051649":{},"tf2-keras-transformer-elastic-20210723-051950":{}} "nodes"={"gpu3":{},"gpu4":{},"gpu5":{}} "scheduler"="default"
I0723 17:36:49.436592    7682 placement_manager.go:305]  "msg"="Found best-fit"  "crossNode"=0 "nodes"=[{},{},{}] "requests"=[{},{},{},{},{},{},{},{},{},{},{},{},{},{},{},{},{},{},{},{},{},{},{},{},{},{}] "scheduler"="default"
I0723 17:36:49.436955    7682 placement_manager.go:339]  "msg"="nodeStates updated"  "new"={"gpu3":{},"gpu4":{},"gpu5":{}} "old"={"gpu3":{},"gpu4":{},"gpu5":{}} "scheduler"="default" "score"=6
I0723 17:36:49.437247    7682 placement_manager.go:387]  "msg"="jobStates updated"  "new"={"tf2-keras-cifar10-inceptionv3-elastic-20210723-042550":{},"tf2-keras-cifar10-inceptionv3-elastic-20210723-042602":{},"tf2-keras-cifar10-inceptionv3-elastic-20210723-044237":{},"tf2-keras-cifar10-inceptionv3-elastic-20210723-045447":{},"tf2-keras-cifar10-inceptionv3-elastic-20210723-045501":{},"tf2-keras-cifar10-resnet50-elastic-20210723-051722":{},"tf2-keras-cifar10-resnet50-elastic-20210723-051925":{},"tf2-keras-cifar10-vgg16-elastic-20210723-051707":{},"tf2-keras-transformer-elastic-20210723-045144":{},"tf2-keras-transformer-elastic-20210723-045458":{},"tf2-keras-transformer-elastic-20210723-051649":{},"tf2-keras-transformer-elastic-20210723-051950":{}} "old"={"tf2-keras-cifar10-inceptionv3-elastic-20210723-042550":{},"tf2-keras-cifar10-inceptionv3-elastic-20210723-042602":{},"tf2-keras-cifar10-inceptionv3-elastic-20210723-044237":{},"tf2-keras-cifar10-inceptionv3-elastic-20210723-045501":{},"tf2-keras-cifar10-resnet50-elastic-20210723-051722":{},"tf2-keras-cifar10-resnet50-elastic-20210723-051925":{},"tf2-keras-cifar10-vgg16-elastic-20210723-051039":{},"tf2-keras-cifar10-vgg16-elastic-20210723-051707":{},"tf2-keras-transformer-elastic-20210723-045144":{},"tf2-keras-transformer-elastic-20210723-045458":{},"tf2-keras-transformer-elastic-20210723-051649":{},"tf2-keras-transformer-elastic-20210723-051950":{}} "scheduler"="default"
I0723 17:36:49.437580    7682 placement_manager.go:434]  "msg"="podNodeName updated"  "launchersToDelete"=5 "new"={"tf2-keras-cifar10-inceptionv3-elastic-20210723-042550-worker-0":"gpu4","tf2-keras-cifar10-inceptionv3-elastic-20210723-042602-worker-0":"gpu3","tf2-keras-cifar10-inceptionv3-elastic-20210723-044237-worker-0":"gpu5","tf2-keras-cifar10-inceptionv3-elastic-20210723-045447-worker-0":"gpu3","tf2-keras-cifar10-inceptionv3-elastic-20210723-045501-worker-0":"gpu4","tf2-keras-cifar10-resnet50-elastic-20210723-051722-worker-0":"gpu4","tf2-keras-cifar10-resnet50-elastic-20210723-051925-worker-0":"gpu3","tf2-keras-cifar10-vgg16-elastic-20210723-051707-worker-0":"gpu4","tf2-keras-transformer-elastic-20210723-045144-worker-0":"gpu5","tf2-keras-transformer-elastic-20210723-045458-worker-0":"gpu5","tf2-keras-transformer-elastic-20210723-051649-worker-0":"gpu3","tf2-keras-transformer-elastic-20210723-051950-worker-0":"gpu5"} "old"={"tf2-keras-cifar10-inceptionv3-elastic-20210723-042550-worker-0":"gpu5","tf2-keras-cifar10-inceptionv3-elastic-20210723-042602-worker-0":"gpu4","tf2-keras-cifar10-inceptionv3-elastic-20210723-044237-worker-0":"gpu4","tf2-keras-cifar10-inceptionv3-elastic-20210723-045501-worker-0":"gpu4","tf2-keras-cifar10-resnet50-elastic-20210723-051722-worker-0":"gpu4","tf2-keras-cifar10-resnet50-elastic-20210723-051925-worker-0":"gpu3","tf2-keras-cifar10-vgg16-elastic-20210723-051039-worker-0":"gpu5","tf2-keras-cifar10-vgg16-elastic-20210723-051707-worker-0":"gpu3","tf2-keras-transformer-elastic-20210723-045144-worker-0":"gpu5","tf2-keras-transformer-elastic-20210723-045458-worker-0":"gpu3","tf2-keras-transformer-elastic-20210723-051649-worker-0":"gpu3","tf2-keras-transformer-elastic-20210723-051950-worker-0":"gpu5"} "scheduler"="default" "workersToDelete"=5
I0723 17:36:49.437851    7682 placement_manager.go:451]  "msg"="Deleting pod that need migration"  "podName"="tf2-keras-cifar10-vgg16-elastic-20210723-051707-worker-0" "scheduler"="default"
I0723 17:36:49.442844    7682 placement_manager.go:451]  "msg"="Deleting pod that need migration"  "podName"="tf2-keras-cifar10-vgg16-elastic-20210723-051707-launcher" "scheduler"="default"
I0723 17:36:49.447884    7682 placement_manager.go:451]  "msg"="Deleting pod that need migration"  "podName"="tf2-keras-transformer-elastic-20210723-045458-worker-0" "scheduler"="default"
I0723 17:36:49.458803    7682 placement_manager.go:451]  "msg"="Deleting pod that need migration"  "podName"="tf2-keras-transformer-elastic-20210723-045458-launcher" "scheduler"="default"
I0723 17:36:49.470481    7682 placement_manager.go:451]  "msg"="Deleting pod that need migration"  "podName"="tf2-keras-cifar10-inceptionv3-elastic-20210723-044237-worker-0" "scheduler"="default"
I0723 17:36:49.478939    7682 placement_manager.go:451]  "msg"="Deleting pod that need migration"  "podName"="tf2-keras-cifar10-inceptionv3-elastic-20210723-044237-launcher" "scheduler"="default"
I0723 17:36:49.490385    7682 placement_manager.go:451]  "msg"="Deleting pod that need migration"  "podName"="tf2-keras-cifar10-inceptionv3-elastic-20210723-042550-worker-0" "scheduler"="default"
I0723 17:36:49.494543    7682 placement_manager.go:451]  "msg"="Deleting pod that need migration"  "podName"="tf2-keras-cifar10-inceptionv3-elastic-20210723-042550-launcher" "scheduler"="default"
I0723 17:36:49.497794    7682 placement_manager.go:451]  "msg"="Deleting pod that need migration"  "podName"="tf2-keras-cifar10-inceptionv3-elastic-20210723-042602-worker-0" "scheduler"="default"
I0723 17:36:49.501022    7682 placement_manager.go:451]  "msg"="Deleting pod that need migration"  "podName"="tf2-keras-cifar10-inceptionv3-elastic-20210723-042602-launcher" "scheduler"="default"
I0723 17:36:49.504980    7682 placement_manager.go:183]  "msg"="Finished job placements adjustment"  "scheduler"="default"
I0723 17:36:49.505199    7682 scheduler.go:182]  "msg"="Finished resched"  "scheduler"="default"
I0723 17:36:49.943099    7682 placement_manager.go:147]  "msg"="Adding toleration to pod"  "podName"="tf2-keras-cifar10-inceptionv3-elastic-20210723-045447-worker-0" "scheduler"="default" "toleration"={"key":"celeste/hostname","operator":"Equal","value":"gpu3","effect":"NoExecute"}
I0723 17:36:50.342022    7682 placement_manager.go:147]  "msg"="Adding toleration to pod"  "podName"="tf2-keras-cifar10-inceptionv3-elastic-20210723-045447-launcher" "scheduler"="default" "toleration"={"key":"celeste/hostname","operator":"Exists","effect":"NoExecute"}
I0723 17:36:56.737189    7682 placement_manager.go:147]  "msg"="Adding toleration to pod"  "podName"="tf2-keras-cifar10-inceptionv3-elastic-20210723-044237-launcher" "scheduler"="default" "toleration"={"key":"celeste/hostname","operator":"Exists","effect":"NoExecute"}
I0723 17:36:56.778194    7682 placement_manager.go:147]  "msg"="Adding toleration to pod"  "podName"="tf2-keras-cifar10-inceptionv3-elastic-20210723-042602-worker-0" "scheduler"="default" "toleration"={"key":"celeste/hostname","operator":"Equal","value":"gpu3","effect":"NoExecute"}
I0723 17:36:56.787045    7682 placement_manager.go:147]  "msg"="Adding toleration to pod"  "podName"="tf2-keras-cifar10-inceptionv3-elastic-20210723-044237-worker-0" "scheduler"="default" "toleration"={"key":"celeste/hostname","operator":"Equal","value":"gpu5","effect":"NoExecute"}
I0723 17:36:58.310066    7682 placement_manager.go:147]  "msg"="Adding toleration to pod"  "podName"="tf2-keras-cifar10-inceptionv3-elastic-20210723-042550-worker-0" "scheduler"="default" "toleration"={"key":"celeste/hostname","operator":"Equal","value":"gpu4","effect":"NoExecute"}
I0723 17:37:01.099601    7682 placement_manager.go:147]  "msg"="Adding toleration to pod"  "podName"="tf2-keras-cifar10-inceptionv3-elastic-20210723-042602-launcher" "scheduler"="default" "toleration"={"key":"celeste/hostname","operator":"Exists","effect":"NoExecute"}
I0723 17:37:01.902621    7682 placement_manager.go:147]  "msg"="Adding toleration to pod"  "podName"="tf2-keras-cifar10-inceptionv3-elastic-20210723-042550-launcher" "scheduler"="default" "toleration"={"key":"celeste/hostname","operator":"Exists","effect":"NoExecute"}
I0723 17:37:04.740694    7682 placement_manager.go:147]  "msg"="Adding toleration to pod"  "podName"="tf2-keras-cifar10-vgg16-elastic-20210723-051707-worker-0" "scheduler"="default" "toleration"={"key":"celeste/hostname","operator":"Equal","value":"gpu4","effect":"NoExecute"}
I0723 17:37:05.534400    7682 placement_manager.go:147]  "msg"="Adding toleration to pod"  "podName"="tf2-keras-transformer-elastic-20210723-045458-worker-0" "scheduler"="default" "toleration"={"key":"celeste/hostname","operator":"Equal","value":"gpu5","effect":"NoExecute"}
I0723 17:37:06.339592    7682 placement_manager.go:147]  "msg"="Adding toleration to pod"  "podName"="tf2-keras-transformer-elastic-20210723-045458-launcher" "scheduler"="default" "toleration"={"key":"celeste/hostname","operator":"Exists","effect":"NoExecute"}
I0723 17:37:07.137246    7682 placement_manager.go:147]  "msg"="Adding toleration to pod"  "podName"="tf2-keras-cifar10-vgg16-elastic-20210723-051707-launcher" "scheduler"="default" "toleration"={"key":"celeste/hostname","operator":"Exists","effect":"NoExecute"}
I0723 17:40:19.129631    7682 scheduler.go:474]  "msg"="Training job completed"  "elaspedTotalSeconds"=2914.38202215 "gpuTotalSeconds"=2815.092343342 "job"="tf2-keras-transformer-elastic-20210723-045144" "ranTotalSeconds"=2815.092343342 "scheduler"="default" "waitedTotalSeconds"=99.289678808
I0723 17:40:19.129889    7682 scheduler.go:135]  "msg"="Received resched event, may be blocked because of rate limit"  "blockedUntil"="2021-07-23T17:38:49.505414521+08:00" "lastResched"="2021-07-23T17:36:49.505414521+08:00" "received"="2021-07-23T17:40:19.129699571+08:00" "scheduler"="default"
I0723 17:40:19.130444    7682 scheduler.go:159]  "msg"="Started resched"  "scheduler"="default"
I0723 17:40:19.130574    7682 scheduler.go:193]  "msg"="Updating all jobs info"  "scheduler"="default"
I0723 17:40:19.143808    7682 afsl.go:65]  "msg"="Finished scheduling"  "algorithm"="AFS-L" "freeGpu"=0 "result"={"tf2-keras-cifar10-inceptionv3-elastic-20210723-042550":1,"tf2-keras-cifar10-inceptionv3-elastic-20210723-042602":1,"tf2-keras-cifar10-inceptionv3-elastic-20210723-044237":1,"tf2-keras-cifar10-inceptionv3-elastic-20210723-045126":1,"tf2-keras-cifar10-inceptionv3-elastic-20210723-045447":1,"tf2-keras-cifar10-inceptionv3-elastic-20210723-045501":1,"tf2-keras-cifar10-resnet50-elastic-20210723-051722":1,"tf2-keras-cifar10-resnet50-elastic-20210723-051925":1,"tf2-keras-cifar10-vgg16-elastic-20210723-051707":1,"tf2-keras-transformer-elastic-20210723-045458":1,"tf2-keras-transformer-elastic-20210723-051649":1,"tf2-keras-transformer-elastic-20210723-051950":1} "scheduler"="default"
I0723 17:40:19.144329    7682 scheduler.go:384]  "msg"="Trying to delete multiple training jobs"  "jobs"=[] "scheduler"="default"
I0723 17:40:19.144591    7682 scheduler.go:342]  "msg"="Trying to scale multiple training jobs"  "jobs"=[] "scheduler"="default"
I0723 17:40:19.144843    7682 scheduler.go:292]  "msg"="Trying to start multiple training jobs"  "jobs"=["tf2-keras-cifar10-inceptionv3-elastic-20210723-045126"] "scheduler"="default"
I0723 17:40:19.154287    7682 scheduler.go:342]  "msg"="Trying to scale multiple training jobs"  "jobs"=[] "scheduler"="default"
I0723 17:40:19.159247    7682 placement_manager.go:166]  "msg"="Started job placements adjustment"  "scheduler"="default"
I0723 17:40:19.159323    7682 placement_manager.go:192]  "msg"="Releasing slots"  "jobs"={"tf2-keras-cifar10-inceptionv3-elastic-20210723-042550":{},"tf2-keras-cifar10-inceptionv3-elastic-20210723-042602":{},"tf2-keras-cifar10-inceptionv3-elastic-20210723-044237":{},"tf2-keras-cifar10-inceptionv3-elastic-20210723-045447":{},"tf2-keras-cifar10-inceptionv3-elastic-20210723-045501":{},"tf2-keras-cifar10-resnet50-elastic-20210723-051722":{},"tf2-keras-cifar10-resnet50-elastic-20210723-051925":{},"tf2-keras-cifar10-vgg16-elastic-20210723-051707":{},"tf2-keras-transformer-elastic-20210723-045144":{},"tf2-keras-transformer-elastic-20210723-045458":{},"tf2-keras-transformer-elastic-20210723-051649":{},"tf2-keras-transformer-elastic-20210723-051950":{}} "nodes"={"gpu3":{},"gpu4":{},"gpu5":{}} "scheduler"="default"
I0723 17:40:19.159400    7682 placement_manager.go:250]  "msg"="Released slots"  "jobs"={"tf2-keras-cifar10-inceptionv3-elastic-20210723-042550":{},"tf2-keras-cifar10-inceptionv3-elastic-20210723-042602":{},"tf2-keras-cifar10-inceptionv3-elastic-20210723-044237":{},"tf2-keras-cifar10-inceptionv3-elastic-20210723-045447":{},"tf2-keras-cifar10-inceptionv3-elastic-20210723-045501":{},"tf2-keras-cifar10-resnet50-elastic-20210723-051722":{},"tf2-keras-cifar10-resnet50-elastic-20210723-051925":{},"tf2-keras-cifar10-vgg16-elastic-20210723-051707":{},"tf2-keras-transformer-elastic-20210723-045144":{},"tf2-keras-transformer-elastic-20210723-045458":{},"tf2-keras-transformer-elastic-20210723-051649":{},"tf2-keras-transformer-elastic-20210723-051950":{}} "nodes"={"gpu3":{},"gpu4":{},"gpu5":{}} "scheduler"="default"
I0723 17:40:19.159910    7682 placement_manager.go:305]  "msg"="Found best-fit"  "crossNode"=0 "nodes"=[{},{},{}] "requests"=[{},{},{},{},{},{},{},{},{},{},{},{},{},{},{},{},{},{},{},{},{},{},{},{}] "scheduler"="default"
I0723 17:40:19.160163    7682 placement_manager.go:339]  "msg"="nodeStates updated"  "new"={"gpu3":{},"gpu4":{},"gpu5":{}} "old"={"gpu3":{},"gpu4":{},"gpu5":{}} "scheduler"="default" "score"=6
I0723 17:40:19.160440    7682 placement_manager.go:387]  "msg"="jobStates updated"  "new"={"tf2-keras-cifar10-inceptionv3-elastic-20210723-042550":{},"tf2-keras-cifar10-inceptionv3-elastic-20210723-042602":{},"tf2-keras-cifar10-inceptionv3-elastic-20210723-044237":{},"tf2-keras-cifar10-inceptionv3-elastic-20210723-045126":{},"tf2-keras-cifar10-inceptionv3-elastic-20210723-045447":{},"tf2-keras-cifar10-inceptionv3-elastic-20210723-045501":{},"tf2-keras-cifar10-resnet50-elastic-20210723-051722":{},"tf2-keras-cifar10-resnet50-elastic-20210723-051925":{},"tf2-keras-cifar10-vgg16-elastic-20210723-051707":{},"tf2-keras-transformer-elastic-20210723-045458":{},"tf2-keras-transformer-elastic-20210723-051649":{},"tf2-keras-transformer-elastic-20210723-051950":{}} "old"={"tf2-keras-cifar10-inceptionv3-elastic-20210723-042550":{},"tf2-keras-cifar10-inceptionv3-elastic-20210723-042602":{},"tf2-keras-cifar10-inceptionv3-elastic-20210723-044237":{},"tf2-keras-cifar10-inceptionv3-elastic-20210723-045447":{},"tf2-keras-cifar10-inceptionv3-elastic-20210723-045501":{},"tf2-keras-cifar10-resnet50-elastic-20210723-051722":{},"tf2-keras-cifar10-resnet50-elastic-20210723-051925":{},"tf2-keras-cifar10-vgg16-elastic-20210723-051707":{},"tf2-keras-transformer-elastic-20210723-045144":{},"tf2-keras-transformer-elastic-20210723-045458":{},"tf2-keras-transformer-elastic-20210723-051649":{},"tf2-keras-transformer-elastic-20210723-051950":{}} "scheduler"="default"
I0723 17:40:19.160826    7682 placement_manager.go:434]  "msg"="podNodeName updated"  "launchersToDelete"=5 "new"={"tf2-keras-cifar10-inceptionv3-elastic-20210723-042550-worker-0":"gpu3","tf2-keras-cifar10-inceptionv3-elastic-20210723-042602-worker-0":"gpu5","tf2-keras-cifar10-inceptionv3-elastic-20210723-044237-worker-0":"gpu5","tf2-keras-cifar10-inceptionv3-elastic-20210723-045126-worker-0":"gpu5","tf2-keras-cifar10-inceptionv3-elastic-20210723-045447-worker-0":"gpu3","tf2-keras-cifar10-inceptionv3-elastic-20210723-045501-worker-0":"gpu4","tf2-keras-cifar10-resnet50-elastic-20210723-051722-worker-0":"gpu4","tf2-keras-cifar10-resnet50-elastic-20210723-051925-worker-0":"gpu4","tf2-keras-cifar10-vgg16-elastic-20210723-051707-worker-0":"gpu3","tf2-keras-transformer-elastic-20210723-045458-worker-0":"gpu5","tf2-keras-transformer-elastic-20210723-051649-worker-0":"gpu3","tf2-keras-transformer-elastic-20210723-051950-worker-0":"gpu4"} "old"={"tf2-keras-cifar10-inceptionv3-elastic-20210723-042550-worker-0":"gpu4","tf2-keras-cifar10-inceptionv3-elastic-20210723-042602-worker-0":"gpu3","tf2-keras-cifar10-inceptionv3-elastic-20210723-044237-worker-0":"gpu5","tf2-keras-cifar10-inceptionv3-elastic-20210723-045447-worker-0":"gpu3","tf2-keras-cifar10-inceptionv3-elastic-20210723-045501-worker-0":"gpu4","tf2-keras-cifar10-resnet50-elastic-20210723-051722-worker-0":"gpu4","tf2-keras-cifar10-resnet50-elastic-20210723-051925-worker-0":"gpu3","tf2-keras-cifar10-vgg16-elastic-20210723-051707-worker-0":"gpu4","tf2-keras-transformer-elastic-20210723-045144-worker-0":"gpu5","tf2-keras-transformer-elastic-20210723-045458-worker-0":"gpu5","tf2-keras-transformer-elastic-20210723-051649-worker-0":"gpu3","tf2-keras-transformer-elastic-20210723-051950-worker-0":"gpu5"} "scheduler"="default" "workersToDelete"=5
I0723 17:40:19.161098    7682 placement_manager.go:451]  "msg"="Deleting pod that need migration"  "podName"="tf2-keras-cifar10-inceptionv3-elastic-20210723-042602-worker-0" "scheduler"="default"
I0723 17:40:19.164906    7682 placement_manager.go:451]  "msg"="Deleting pod that need migration"  "podName"="tf2-keras-cifar10-inceptionv3-elastic-20210723-042602-launcher" "scheduler"="default"
I0723 17:40:19.170426    7682 placement_manager.go:451]  "msg"="Deleting pod that need migration"  "podName"="tf2-keras-cifar10-resnet50-elastic-20210723-051925-worker-0" "scheduler"="default"
I0723 17:40:19.175659    7682 placement_manager.go:451]  "msg"="Deleting pod that need migration"  "podName"="tf2-keras-cifar10-resnet50-elastic-20210723-051925-launcher" "scheduler"="default"
I0723 17:40:19.186836    7682 placement_manager.go:451]  "msg"="Deleting pod that need migration"  "podName"="tf2-keras-transformer-elastic-20210723-051950-worker-0" "scheduler"="default"
I0723 17:40:19.193873    7682 placement_manager.go:451]  "msg"="Deleting pod that need migration"  "podName"="tf2-keras-transformer-elastic-20210723-051950-launcher" "scheduler"="default"
I0723 17:40:19.199349    7682 placement_manager.go:451]  "msg"="Deleting pod that need migration"  "podName"="tf2-keras-cifar10-vgg16-elastic-20210723-051707-worker-0" "scheduler"="default"
I0723 17:40:19.211758    7682 placement_manager.go:451]  "msg"="Deleting pod that need migration"  "podName"="tf2-keras-cifar10-vgg16-elastic-20210723-051707-launcher" "scheduler"="default"
I0723 17:40:19.215722    7682 placement_manager.go:451]  "msg"="Deleting pod that need migration"  "podName"="tf2-keras-cifar10-inceptionv3-elastic-20210723-042550-worker-0" "scheduler"="default"
I0723 17:40:19.220191    7682 placement_manager.go:451]  "msg"="Deleting pod that need migration"  "podName"="tf2-keras-cifar10-inceptionv3-elastic-20210723-042550-launcher" "scheduler"="default"
I0723 17:40:19.225518    7682 placement_manager.go:183]  "msg"="Finished job placements adjustment"  "scheduler"="default"
I0723 17:40:19.225857    7682 scheduler.go:182]  "msg"="Finished resched"  "scheduler"="default"
I0723 17:40:19.723947    7682 placement_manager.go:147]  "msg"="Adding toleration to pod"  "podName"="tf2-keras-cifar10-inceptionv3-elastic-20210723-045126-worker-0" "scheduler"="default" "toleration"={"key":"celeste/hostname","operator":"Equal","value":"gpu5","effect":"NoExecute"}
I0723 17:40:20.126196    7682 placement_manager.go:147]  "msg"="Adding toleration to pod"  "podName"="tf2-keras-cifar10-inceptionv3-elastic-20210723-045126-launcher" "scheduler"="default" "toleration"={"key":"celeste/hostname","operator":"Exists","effect":"NoExecute"}
I0723 17:40:26.413468    7682 placement_manager.go:147]  "msg"="Adding toleration to pod"  "podName"="tf2-keras-cifar10-inceptionv3-elastic-20210723-042602-worker-0" "scheduler"="default" "toleration"={"key":"celeste/hostname","operator":"Equal","value":"gpu5","effect":"NoExecute"}
I0723 17:40:26.449372    7682 placement_manager.go:147]  "msg"="Adding toleration to pod"  "podName"="tf2-keras-cifar10-resnet50-elastic-20210723-051925-worker-0" "scheduler"="default" "toleration"={"key":"celeste/hostname","operator":"Equal","value":"gpu4","effect":"NoExecute"}
I0723 17:40:27.396332    7682 placement_manager.go:147]  "msg"="Adding toleration to pod"  "podName"="tf2-keras-cifar10-vgg16-elastic-20210723-051707-worker-0" "scheduler"="default" "toleration"={"key":"celeste/hostname","operator":"Equal","value":"gpu3","effect":"NoExecute"}
I0723 17:40:27.474750    7682 placement_manager.go:147]  "msg"="Adding toleration to pod"  "podName"="tf2-keras-transformer-elastic-20210723-051950-worker-0" "scheduler"="default" "toleration"={"key":"celeste/hostname","operator":"Equal","value":"gpu4","effect":"NoExecute"}
I0723 17:40:28.286716    7682 placement_manager.go:147]  "msg"="Adding toleration to pod"  "podName"="tf2-keras-transformer-elastic-20210723-051950-launcher" "scheduler"="default" "toleration"={"key":"celeste/hostname","operator":"Exists","effect":"NoExecute"}
I0723 17:40:28.411328    7682 placement_manager.go:147]  "msg"="Adding toleration to pod"  "podName"="tf2-keras-cifar10-resnet50-elastic-20210723-051925-launcher" "scheduler"="default" "toleration"={"key":"celeste/hostname","operator":"Exists","effect":"NoExecute"}
I0723 17:40:33.866397    7682 placement_manager.go:147]  "msg"="Adding toleration to pod"  "podName"="tf2-keras-cifar10-inceptionv3-elastic-20210723-042602-launcher" "scheduler"="default" "toleration"={"key":"celeste/hostname","operator":"Exists","effect":"NoExecute"}
I0723 17:40:35.196749    7682 placement_manager.go:147]  "msg"="Adding toleration to pod"  "podName"="tf2-keras-cifar10-inceptionv3-elastic-20210723-042550-worker-0" "scheduler"="default" "toleration"={"key":"celeste/hostname","operator":"Equal","value":"gpu3","effect":"NoExecute"}
I0723 17:40:35.996221    7682 placement_manager.go:147]  "msg"="Adding toleration to pod"  "podName"="tf2-keras-cifar10-inceptionv3-elastic-20210723-042550-launcher" "scheduler"="default" "toleration"={"key":"celeste/hostname","operator":"Exists","effect":"NoExecute"}
I0723 17:40:36.807118    7682 placement_manager.go:147]  "msg"="Adding toleration to pod"  "podName"="tf2-keras-cifar10-vgg16-elastic-20210723-051707-launcher" "scheduler"="default" "toleration"={"key":"celeste/hostname","operator":"Exists","effect":"NoExecute"}
I0723 17:41:40.240713    7682 scheduler.go:474]  "msg"="Training job completed"  "elaspedTotalSeconds"=2800.725379053 "gpuTotalSeconds"=2775.092012965 "job"="tf2-keras-transformer-elastic-20210723-045458" "ranTotalSeconds"=2775.092012965 "scheduler"="default" "waitedTotalSeconds"=25.633366088
I0723 17:41:40.240837    7682 scheduler.go:135]  "msg"="Received resched event, may be blocked because of rate limit"  "blockedUntil"="2021-07-23T17:42:19.226160578+08:00" "lastResched"="2021-07-23T17:40:19.226160578+08:00" "received"="2021-07-23T17:41:40.240752801+08:00" "scheduler"="default"
I0723 17:42:19.226226    7682 scheduler.go:159]  "msg"="Started resched"  "scheduler"="default"
I0723 17:42:19.226296    7682 scheduler.go:193]  "msg"="Updating all jobs info"  "scheduler"="default"
I0723 17:42:19.237289    7682 afsl.go:65]  "msg"="Finished scheduling"  "algorithm"="AFS-L" "freeGpu"=0 "result"={"tf2-keras-cifar10-inceptionv3-elastic-20210723-042550":1,"tf2-keras-cifar10-inceptionv3-elastic-20210723-042602":1,"tf2-keras-cifar10-inceptionv3-elastic-20210723-044237":1,"tf2-keras-cifar10-inceptionv3-elastic-20210723-045126":1,"tf2-keras-cifar10-inceptionv3-elastic-20210723-045447":1,"tf2-keras-cifar10-inceptionv3-elastic-20210723-045501":1,"tf2-keras-cifar10-resnet50-elastic-20210723-051722":2,"tf2-keras-cifar10-resnet50-elastic-20210723-051925":1,"tf2-keras-cifar10-vgg16-elastic-20210723-051707":1,"tf2-keras-transformer-elastic-20210723-051649":1,"tf2-keras-transformer-elastic-20210723-051950":1} "scheduler"="default"
I0723 17:42:19.237615    7682 scheduler.go:384]  "msg"="Trying to delete multiple training jobs"  "jobs"=[] "scheduler"="default"
I0723 17:42:19.237890    7682 scheduler.go:342]  "msg"="Trying to scale multiple training jobs"  "jobs"=[] "scheduler"="default"
I0723 17:42:19.238152    7682 scheduler.go:292]  "msg"="Trying to start multiple training jobs"  "jobs"=[] "scheduler"="default"
I0723 17:42:19.238425    7682 scheduler.go:342]  "msg"="Trying to scale multiple training jobs"  "jobs"=["tf2-keras-cifar10-resnet50-elastic-20210723-051722"] "scheduler"="default"
I0723 17:42:19.258499    7682 placement_manager.go:166]  "msg"="Started job placements adjustment"  "scheduler"="default"
I0723 17:42:19.258632    7682 placement_manager.go:192]  "msg"="Releasing slots"  "jobs"={"tf2-keras-cifar10-inceptionv3-elastic-20210723-042550":{},"tf2-keras-cifar10-inceptionv3-elastic-20210723-042602":{},"tf2-keras-cifar10-inceptionv3-elastic-20210723-044237":{},"tf2-keras-cifar10-inceptionv3-elastic-20210723-045126":{},"tf2-keras-cifar10-inceptionv3-elastic-20210723-045447":{},"tf2-keras-cifar10-inceptionv3-elastic-20210723-045501":{},"tf2-keras-cifar10-resnet50-elastic-20210723-051722":{},"tf2-keras-cifar10-resnet50-elastic-20210723-051925":{},"tf2-keras-cifar10-vgg16-elastic-20210723-051707":{},"tf2-keras-transformer-elastic-20210723-045458":{},"tf2-keras-transformer-elastic-20210723-051649":{},"tf2-keras-transformer-elastic-20210723-051950":{}} "nodes"={"gpu3":{},"gpu4":{},"gpu5":{}} "scheduler"="default"
I0723 17:42:19.258710    7682 placement_manager.go:250]  "msg"="Released slots"  "jobs"={"tf2-keras-cifar10-inceptionv3-elastic-20210723-042550":{},"tf2-keras-cifar10-inceptionv3-elastic-20210723-042602":{},"tf2-keras-cifar10-inceptionv3-elastic-20210723-044237":{},"tf2-keras-cifar10-inceptionv3-elastic-20210723-045126":{},"tf2-keras-cifar10-inceptionv3-elastic-20210723-045447":{},"tf2-keras-cifar10-inceptionv3-elastic-20210723-045501":{},"tf2-keras-cifar10-resnet50-elastic-20210723-051722":{},"tf2-keras-cifar10-resnet50-elastic-20210723-051925":{},"tf2-keras-cifar10-vgg16-elastic-20210723-051707":{},"tf2-keras-transformer-elastic-20210723-045458":{},"tf2-keras-transformer-elastic-20210723-051649":{},"tf2-keras-transformer-elastic-20210723-051950":{}} "nodes"={"gpu3":{},"gpu4":{},"gpu5":{}} "scheduler"="default"
I0723 17:42:19.259080    7682 placement_manager.go:305]  "msg"="Found best-fit"  "crossNode"=0 "nodes"=[{},{},{}] "requests"=[{},{},{},{},{},{},{},{},{},{},{},{},{},{},{},{},{},{},{},{},{},{}] "scheduler"="default"
I0723 17:42:19.259378    7682 placement_manager.go:339]  "msg"="nodeStates updated"  "new"={"gpu3":{},"gpu4":{},"gpu5":{}} "old"={"gpu3":{},"gpu4":{},"gpu5":{}} "scheduler"="default" "score"=6
I0723 17:42:19.259681    7682 placement_manager.go:387]  "msg"="jobStates updated"  "new"={"tf2-keras-cifar10-inceptionv3-elastic-20210723-042550":{},"tf2-keras-cifar10-inceptionv3-elastic-20210723-042602":{},"tf2-keras-cifar10-inceptionv3-elastic-20210723-044237":{},"tf2-keras-cifar10-inceptionv3-elastic-20210723-045126":{},"tf2-keras-cifar10-inceptionv3-elastic-20210723-045447":{},"tf2-keras-cifar10-inceptionv3-elastic-20210723-045501":{},"tf2-keras-cifar10-resnet50-elastic-20210723-051722":{},"tf2-keras-cifar10-resnet50-elastic-20210723-051925":{},"tf2-keras-cifar10-vgg16-elastic-20210723-051707":{},"tf2-keras-transformer-elastic-20210723-051649":{},"tf2-keras-transformer-elastic-20210723-051950":{}} "old"={"tf2-keras-cifar10-inceptionv3-elastic-20210723-042550":{},"tf2-keras-cifar10-inceptionv3-elastic-20210723-042602":{},"tf2-keras-cifar10-inceptionv3-elastic-20210723-044237":{},"tf2-keras-cifar10-inceptionv3-elastic-20210723-045126":{},"tf2-keras-cifar10-inceptionv3-elastic-20210723-045447":{},"tf2-keras-cifar10-inceptionv3-elastic-20210723-045501":{},"tf2-keras-cifar10-resnet50-elastic-20210723-051722":{},"tf2-keras-cifar10-resnet50-elastic-20210723-051925":{},"tf2-keras-cifar10-vgg16-elastic-20210723-051707":{},"tf2-keras-transformer-elastic-20210723-045458":{},"tf2-keras-transformer-elastic-20210723-051649":{},"tf2-keras-transformer-elastic-20210723-051950":{}} "scheduler"="default"
I0723 17:42:19.260070    7682 placement_manager.go:434]  "msg"="podNodeName updated"  "launchersToDelete"=5 "new"={"tf2-keras-cifar10-inceptionv3-elastic-20210723-042550-worker-0":"gpu4","tf2-keras-cifar10-inceptionv3-elastic-20210723-042602-worker-0":"gpu3","tf2-keras-cifar10-inceptionv3-elastic-20210723-044237-worker-0":"gpu5","tf2-keras-cifar10-inceptionv3-elastic-20210723-045126-worker-0":"gpu5","tf2-keras-cifar10-inceptionv3-elastic-20210723-045447-worker-0":"gpu3","tf2-keras-cifar10-inceptionv3-elastic-20210723-045501-worker-0":"gpu5","tf2-keras-cifar10-resnet50-elastic-20210723-051722-worker-0":"gpu4","tf2-keras-cifar10-resnet50-elastic-20210723-051722-worker-1":"gpu4","tf2-keras-cifar10-resnet50-elastic-20210723-051925-worker-0":"gpu3","tf2-keras-cifar10-vgg16-elastic-20210723-051707-worker-0":"gpu3","tf2-keras-transformer-elastic-20210723-051649-worker-0":"gpu5","tf2-keras-transformer-elastic-20210723-051950-worker-0":"gpu4"} "old"={"tf2-keras-cifar10-inceptionv3-elastic-20210723-042550-worker-0":"gpu3","tf2-keras-cifar10-inceptionv3-elastic-20210723-042602-worker-0":"gpu5","tf2-keras-cifar10-inceptionv3-elastic-20210723-044237-worker-0":"gpu5","tf2-keras-cifar10-inceptionv3-elastic-20210723-045126-worker-0":"gpu5","tf2-keras-cifar10-inceptionv3-elastic-20210723-045447-worker-0":"gpu3","tf2-keras-cifar10-inceptionv3-elastic-20210723-045501-worker-0":"gpu4","tf2-keras-cifar10-resnet50-elastic-20210723-051722-worker-0":"gpu4","tf2-keras-cifar10-resnet50-elastic-20210723-051925-worker-0":"gpu4","tf2-keras-cifar10-vgg16-elastic-20210723-051707-worker-0":"gpu3","tf2-keras-transformer-elastic-20210723-045458-worker-0":"gpu5","tf2-keras-transformer-elastic-20210723-051649-worker-0":"gpu3","tf2-keras-transformer-elastic-20210723-051950-worker-0":"gpu4"} "scheduler"="default" "workersToDelete"=5
I0723 17:42:19.260371    7682 placement_manager.go:451]  "msg"="Deleting pod that need migration"  "podName"="tf2-keras-cifar10-inceptionv3-elastic-20210723-045501-worker-0" "scheduler"="default"
I0723 17:42:19.265809    7682 placement_manager.go:451]  "msg"="Deleting pod that need migration"  "podName"="tf2-keras-cifar10-inceptionv3-elastic-20210723-045501-launcher" "scheduler"="default"
I0723 17:42:19.276108    7682 placement_manager.go:451]  "msg"="Deleting pod that need migration"  "podName"="tf2-keras-cifar10-resnet50-elastic-20210723-051925-worker-0" "scheduler"="default"
I0723 17:42:19.280897    7682 placement_manager.go:451]  "msg"="Deleting pod that need migration"  "podName"="tf2-keras-cifar10-resnet50-elastic-20210723-051925-launcher" "scheduler"="default"
I0723 17:42:19.286460    7682 placement_manager.go:451]  "msg"="Deleting pod that need migration"  "podName"="tf2-keras-cifar10-inceptionv3-elastic-20210723-042550-worker-0" "scheduler"="default"
I0723 17:42:19.292421    7682 placement_manager.go:451]  "msg"="Deleting pod that need migration"  "podName"="tf2-keras-cifar10-inceptionv3-elastic-20210723-042550-launcher" "scheduler"="default"
I0723 17:42:19.294809    7682 placement_manager.go:147]  "msg"="Adding toleration to pod"  "podName"="tf2-keras-cifar10-resnet50-elastic-20210723-051722-worker-1" "scheduler"="default" "toleration"={"key":"celeste/hostname","operator":"Equal","value":"gpu4","effect":"NoExecute"}
I0723 17:42:19.298762    7682 placement_manager.go:451]  "msg"="Deleting pod that need migration"  "podName"="tf2-keras-cifar10-inceptionv3-elastic-20210723-042602-worker-0" "scheduler"="default"
I0723 17:42:19.312983    7682 placement_manager.go:451]  "msg"="Deleting pod that need migration"  "podName"="tf2-keras-cifar10-inceptionv3-elastic-20210723-042602-launcher" "scheduler"="default"
I0723 17:42:19.317488    7682 placement_manager.go:451]  "msg"="Deleting pod that need migration"  "podName"="tf2-keras-transformer-elastic-20210723-051649-worker-0" "scheduler"="default"
I0723 17:42:19.466580    7682 placement_manager.go:451]  "msg"="Deleting pod that need migration"  "podName"="tf2-keras-transformer-elastic-20210723-051649-launcher" "scheduler"="default"
I0723 17:42:19.866471    7682 placement_manager.go:183]  "msg"="Finished job placements adjustment"  "scheduler"="default"
I0723 17:42:19.866858    7682 scheduler.go:182]  "msg"="Finished resched"  "scheduler"="default"
I0723 17:42:26.222756    7682 placement_manager.go:147]  "msg"="Adding toleration to pod"  "podName"="tf2-keras-cifar10-inceptionv3-elastic-20210723-042602-launcher" "scheduler"="default" "toleration"={"key":"celeste/hostname","operator":"Exists","effect":"NoExecute"}
I0723 17:42:28.148599    7682 placement_manager.go:147]  "msg"="Adding toleration to pod"  "podName"="tf2-keras-cifar10-inceptionv3-elastic-20210723-042602-worker-0" "scheduler"="default" "toleration"={"key":"celeste/hostname","operator":"Equal","value":"gpu3","effect":"NoExecute"}
I0723 17:42:28.558228    7682 placement_manager.go:147]  "msg"="Adding toleration to pod"  "podName"="tf2-keras-transformer-elastic-20210723-051649-launcher" "scheduler"="default" "toleration"={"key":"celeste/hostname","operator":"Exists","effect":"NoExecute"}
I0723 17:42:33.847186    7682 placement_manager.go:147]  "msg"="Adding toleration to pod"  "podName"="tf2-keras-cifar10-inceptionv3-elastic-20210723-042550-worker-0" "scheduler"="default" "toleration"={"key":"celeste/hostname","operator":"Equal","value":"gpu4","effect":"NoExecute"}
I0723 17:42:33.885056    7682 placement_manager.go:147]  "msg"="Adding toleration to pod"  "podName"="tf2-keras-transformer-elastic-20210723-051649-worker-0" "scheduler"="default" "toleration"={"key":"celeste/hostname","operator":"Equal","value":"gpu5","effect":"NoExecute"}
I0723 17:42:33.898921    7682 placement_manager.go:147]  "msg"="Adding toleration to pod"  "podName"="tf2-keras-cifar10-inceptionv3-elastic-20210723-042550-launcher" "scheduler"="default" "toleration"={"key":"celeste/hostname","operator":"Exists","effect":"NoExecute"}
I0723 17:42:35.309005    7682 placement_manager.go:147]  "msg"="Adding toleration to pod"  "podName"="tf2-keras-cifar10-inceptionv3-elastic-20210723-045501-worker-0" "scheduler"="default" "toleration"={"key":"celeste/hostname","operator":"Equal","value":"gpu5","effect":"NoExecute"}
I0723 17:42:36.126376    7682 placement_manager.go:147]  "msg"="Adding toleration to pod"  "podName"="tf2-keras-cifar10-inceptionv3-elastic-20210723-045501-launcher" "scheduler"="default" "toleration"={"key":"celeste/hostname","operator":"Exists","effect":"NoExecute"}
I0723 17:42:36.713444    7682 placement_manager.go:147]  "msg"="Adding toleration to pod"  "podName"="tf2-keras-cifar10-resnet50-elastic-20210723-051925-launcher" "scheduler"="default" "toleration"={"key":"celeste/hostname","operator":"Exists","effect":"NoExecute"}
I0723 17:42:37.111003    7682 placement_manager.go:147]  "msg"="Adding toleration to pod"  "podName"="tf2-keras-cifar10-resnet50-elastic-20210723-051925-worker-0" "scheduler"="default" "toleration"={"key":"celeste/hostname","operator":"Equal","value":"gpu3","effect":"NoExecute"}
I0723 17:44:32.995437    7682 scheduler.go:474]  "msg"="Training job completed"  "elaspedTotalSeconds"=1626.841452443 "gpuTotalSeconds"=1670.0572272 "job"="tf2-keras-cifar10-resnet50-elastic-20210723-051722" "ranTotalSeconds"=1540.052440328 "scheduler"="default" "waitedTotalSeconds"=86.789012115
I0723 17:44:32.995568    7682 scheduler.go:135]  "msg"="Received resched event, may be blocked because of rate limit"  "blockedUntil"="2021-07-23T17:44:19.867103087+08:00" "lastResched"="2021-07-23T17:42:19.867103087+08:00" "received"="2021-07-23T17:44:32.9954704+08:00" "scheduler"="default"
I0723 17:44:32.996102    7682 scheduler.go:159]  "msg"="Started resched"  "scheduler"="default"
I0723 17:44:32.996150    7682 scheduler.go:193]  "msg"="Updating all jobs info"  "scheduler"="default"
I0723 17:44:33.005766    7682 afsl.go:65]  "msg"="Finished scheduling"  "algorithm"="AFS-L" "freeGpu"=0 "result"={"tf2-keras-cifar10-inceptionv3-elastic-20210723-042550":1,"tf2-keras-cifar10-inceptionv3-elastic-20210723-042602":1,"tf2-keras-cifar10-inceptionv3-elastic-20210723-044237":1,"tf2-keras-cifar10-inceptionv3-elastic-20210723-045126":1,"tf2-keras-cifar10-inceptionv3-elastic-20210723-045447":1,"tf2-keras-cifar10-inceptionv3-elastic-20210723-045501":1,"tf2-keras-cifar10-resnet50-elastic-20210723-051925":2,"tf2-keras-cifar10-vgg16-elastic-20210723-051707":2,"tf2-keras-transformer-elastic-20210723-051649":1,"tf2-keras-transformer-elastic-20210723-051950":1} "scheduler"="default"
I0723 17:44:33.006227    7682 scheduler.go:384]  "msg"="Trying to delete multiple training jobs"  "jobs"=[] "scheduler"="default"
I0723 17:44:33.006525    7682 scheduler.go:342]  "msg"="Trying to scale multiple training jobs"  "jobs"=[] "scheduler"="default"
I0723 17:44:33.006807    7682 scheduler.go:292]  "msg"="Trying to start multiple training jobs"  "jobs"=[] "scheduler"="default"
I0723 17:44:33.007050    7682 scheduler.go:342]  "msg"="Trying to scale multiple training jobs"  "jobs"=["tf2-keras-cifar10-vgg16-elastic-20210723-051707","tf2-keras-cifar10-resnet50-elastic-20210723-051925"] "scheduler"="default"
I0723 17:44:33.054185    7682 placement_manager.go:166]  "msg"="Started job placements adjustment"  "scheduler"="default"
I0723 17:44:33.054285    7682 placement_manager.go:192]  "msg"="Releasing slots"  "jobs"={"tf2-keras-cifar10-inceptionv3-elastic-20210723-042550":{},"tf2-keras-cifar10-inceptionv3-elastic-20210723-042602":{},"tf2-keras-cifar10-inceptionv3-elastic-20210723-044237":{},"tf2-keras-cifar10-inceptionv3-elastic-20210723-045126":{},"tf2-keras-cifar10-inceptionv3-elastic-20210723-045447":{},"tf2-keras-cifar10-inceptionv3-elastic-20210723-045501":{},"tf2-keras-cifar10-resnet50-elastic-20210723-051722":{},"tf2-keras-cifar10-resnet50-elastic-20210723-051925":{},"tf2-keras-cifar10-vgg16-elastic-20210723-051707":{},"tf2-keras-transformer-elastic-20210723-051649":{},"tf2-keras-transformer-elastic-20210723-051950":{}} "nodes"={"gpu3":{},"gpu4":{},"gpu5":{}} "scheduler"="default"
I0723 17:44:33.054367    7682 placement_manager.go:250]  "msg"="Released slots"  "jobs"={"tf2-keras-cifar10-inceptionv3-elastic-20210723-042550":{},"tf2-keras-cifar10-inceptionv3-elastic-20210723-042602":{},"tf2-keras-cifar10-inceptionv3-elastic-20210723-044237":{},"tf2-keras-cifar10-inceptionv3-elastic-20210723-045126":{},"tf2-keras-cifar10-inceptionv3-elastic-20210723-045447":{},"tf2-keras-cifar10-inceptionv3-elastic-20210723-045501":{},"tf2-keras-cifar10-resnet50-elastic-20210723-051722":{},"tf2-keras-cifar10-resnet50-elastic-20210723-051925":{},"tf2-keras-cifar10-vgg16-elastic-20210723-051707":{},"tf2-keras-transformer-elastic-20210723-051649":{},"tf2-keras-transformer-elastic-20210723-051950":{}} "nodes"={"gpu3":{},"gpu4":{},"gpu5":{}} "scheduler"="default"
I0723 17:44:33.054980    7682 placement_manager.go:305]  "msg"="Found best-fit"  "crossNode"=0 "nodes"=[{},{},{}] "requests"=[{},{},{},{},{},{},{},{},{},{},{},{},{},{},{},{},{},{},{},{}] "scheduler"="default"
I0723 17:44:33.055464    7682 placement_manager.go:339]  "msg"="nodeStates updated"  "new"={"gpu3":{},"gpu4":{},"gpu5":{}} "old"={"gpu3":{},"gpu4":{},"gpu5":{}} "scheduler"="default" "score"=6
I0723 17:44:33.055852    7682 placement_manager.go:387]  "msg"="jobStates updated"  "new"={"tf2-keras-cifar10-inceptionv3-elastic-20210723-042550":{},"tf2-keras-cifar10-inceptionv3-elastic-20210723-042602":{},"tf2-keras-cifar10-inceptionv3-elastic-20210723-044237":{},"tf2-keras-cifar10-inceptionv3-elastic-20210723-045126":{},"tf2-keras-cifar10-inceptionv3-elastic-20210723-045447":{},"tf2-keras-cifar10-inceptionv3-elastic-20210723-045501":{},"tf2-keras-cifar10-resnet50-elastic-20210723-051925":{},"tf2-keras-cifar10-vgg16-elastic-20210723-051707":{},"tf2-keras-transformer-elastic-20210723-051649":{},"tf2-keras-transformer-elastic-20210723-051950":{}} "old"={"tf2-keras-cifar10-inceptionv3-elastic-20210723-042550":{},"tf2-keras-cifar10-inceptionv3-elastic-20210723-042602":{},"tf2-keras-cifar10-inceptionv3-elastic-20210723-044237":{},"tf2-keras-cifar10-inceptionv3-elastic-20210723-045126":{},"tf2-keras-cifar10-inceptionv3-elastic-20210723-045447":{},"tf2-keras-cifar10-inceptionv3-elastic-20210723-045501":{},"tf2-keras-cifar10-resnet50-elastic-20210723-051722":{},"tf2-keras-cifar10-resnet50-elastic-20210723-051925":{},"tf2-keras-cifar10-vgg16-elastic-20210723-051707":{},"tf2-keras-transformer-elastic-20210723-051649":{},"tf2-keras-transformer-elastic-20210723-051950":{}} "scheduler"="default"
I0723 17:44:33.056323    7682 placement_manager.go:434]  "msg"="podNodeName updated"  "launchersToDelete"=4 "new"={"tf2-keras-cifar10-inceptionv3-elastic-20210723-042550-worker-0":"gpu4","tf2-keras-cifar10-inceptionv3-elastic-20210723-042602-worker-0":"gpu4","tf2-keras-cifar10-inceptionv3-elastic-20210723-044237-worker-0":"gpu5","tf2-keras-cifar10-inceptionv3-elastic-20210723-045126-worker-0":"gpu4","tf2-keras-cifar10-inceptionv3-elastic-20210723-045447-worker-0":"gpu4","tf2-keras-cifar10-inceptionv3-elastic-20210723-045501-worker-0":"gpu5","tf2-keras-cifar10-resnet50-elastic-20210723-051925-worker-0":"gpu3","tf2-keras-cifar10-resnet50-elastic-20210723-051925-worker-1":"gpu3","tf2-keras-cifar10-vgg16-elastic-20210723-051707-worker-0":"gpu3","tf2-keras-cifar10-vgg16-elastic-20210723-051707-worker-1":"gpu3","tf2-keras-transformer-elastic-20210723-051649-worker-0":"gpu5","tf2-keras-transformer-elastic-20210723-051950-worker-0":"gpu5"} "old"={"tf2-keras-cifar10-inceptionv3-elastic-20210723-042550-worker-0":"gpu4","tf2-keras-cifar10-inceptionv3-elastic-20210723-042602-worker-0":"gpu3","tf2-keras-cifar10-inceptionv3-elastic-20210723-044237-worker-0":"gpu5","tf2-keras-cifar10-inceptionv3-elastic-20210723-045126-worker-0":"gpu5","tf2-keras-cifar10-inceptionv3-elastic-20210723-045447-worker-0":"gpu3","tf2-keras-cifar10-inceptionv3-elastic-20210723-045501-worker-0":"gpu5","tf2-keras-cifar10-resnet50-elastic-20210723-051722-worker-0":"gpu4","tf2-keras-cifar10-resnet50-elastic-20210723-051722-worker-1":"gpu4","tf2-keras-cifar10-resnet50-elastic-20210723-051925-worker-0":"gpu3","tf2-keras-cifar10-vgg16-elastic-20210723-051707-worker-0":"gpu3","tf2-keras-transformer-elastic-20210723-051649-worker-0":"gpu5","tf2-keras-transformer-elastic-20210723-051950-worker-0":"gpu4"} "scheduler"="default" "workersToDelete"=4
I0723 17:44:33.056655    7682 placement_manager.go:451]  "msg"="Deleting pod that need migration"  "podName"="tf2-keras-transformer-elastic-20210723-051950-worker-0" "scheduler"="default"
I0723 17:44:33.061910    7682 placement_manager.go:451]  "msg"="Deleting pod that need migration"  "podName"="tf2-keras-transformer-elastic-20210723-051950-launcher" "scheduler"="default"
I0723 17:44:33.063852    7682 placement_manager.go:147]  "msg"="Adding toleration to pod"  "podName"="tf2-keras-cifar10-vgg16-elastic-20210723-051707-worker-1" "scheduler"="default" "toleration"={"key":"celeste/hostname","operator":"Equal","value":"gpu3","effect":"NoExecute"}
I0723 17:44:33.066197    7682 placement_manager.go:451]  "msg"="Deleting pod that need migration"  "podName"="tf2-keras-cifar10-inceptionv3-elastic-20210723-042602-worker-0" "scheduler"="default"
I0723 17:44:33.070638    7682 placement_manager.go:451]  "msg"="Deleting pod that need migration"  "podName"="tf2-keras-cifar10-inceptionv3-elastic-20210723-042602-launcher" "scheduler"="default"
I0723 17:44:33.075420    7682 placement_manager.go:451]  "msg"="Deleting pod that need migration"  "podName"="tf2-keras-cifar10-inceptionv3-elastic-20210723-045126-worker-0" "scheduler"="default"
I0723 17:44:33.078752    7682 placement_manager.go:451]  "msg"="Deleting pod that need migration"  "podName"="tf2-keras-cifar10-inceptionv3-elastic-20210723-045126-launcher" "scheduler"="default"
I0723 17:44:33.082266    7682 placement_manager.go:451]  "msg"="Deleting pod that need migration"  "podName"="tf2-keras-cifar10-inceptionv3-elastic-20210723-045447-worker-0" "scheduler"="default"
I0723 17:44:33.086239    7682 placement_manager.go:451]  "msg"="Deleting pod that need migration"  "podName"="tf2-keras-cifar10-inceptionv3-elastic-20210723-045447-launcher" "scheduler"="default"
I0723 17:44:33.090745    7682 placement_manager.go:183]  "msg"="Finished job placements adjustment"  "scheduler"="default"
I0723 17:44:33.091037    7682 scheduler.go:182]  "msg"="Finished resched"  "scheduler"="default"
I0723 17:44:33.464346    7682 placement_manager.go:147]  "msg"="Adding toleration to pod"  "podName"="tf2-keras-cifar10-resnet50-elastic-20210723-051925-worker-1" "scheduler"="default" "toleration"={"key":"celeste/hostname","operator":"Equal","value":"gpu3","effect":"NoExecute"}
I0723 17:44:40.295876    7682 placement_manager.go:147]  "msg"="Adding toleration to pod"  "podName"="tf2-keras-cifar10-inceptionv3-elastic-20210723-045447-worker-0" "scheduler"="default" "toleration"={"key":"celeste/hostname","operator":"Equal","value":"gpu4","effect":"NoExecute"}
I0723 17:44:40.328955    7682 placement_manager.go:147]  "msg"="Adding toleration to pod"  "podName"="tf2-keras-cifar10-inceptionv3-elastic-20210723-042602-worker-0" "scheduler"="default" "toleration"={"key":"celeste/hostname","operator":"Equal","value":"gpu4","effect":"NoExecute"}
I0723 17:44:44.755474    7682 placement_manager.go:147]  "msg"="Adding toleration to pod"  "podName"="tf2-keras-transformer-elastic-20210723-051950-launcher" "scheduler"="default" "toleration"={"key":"celeste/hostname","operator":"Exists","effect":"NoExecute"}
I0723 17:44:49.745698    7682 placement_manager.go:147]  "msg"="Adding toleration to pod"  "podName"="tf2-keras-cifar10-inceptionv3-elastic-20210723-045447-launcher" "scheduler"="default" "toleration"={"key":"celeste/hostname","operator":"Exists","effect":"NoExecute"}
I0723 17:44:49.759705    7682 placement_manager.go:147]  "msg"="Adding toleration to pod"  "podName"="tf2-keras-cifar10-inceptionv3-elastic-20210723-045126-worker-0" "scheduler"="default" "toleration"={"key":"celeste/hostname","operator":"Equal","value":"gpu4","effect":"NoExecute"}
I0723 17:44:49.770865    7682 placement_manager.go:147]  "msg"="Adding toleration to pod"  "podName"="tf2-keras-cifar10-inceptionv3-elastic-20210723-042602-launcher" "scheduler"="default" "toleration"={"key":"celeste/hostname","operator":"Exists","effect":"NoExecute"}
I0723 17:44:49.784310    7682 placement_manager.go:147]  "msg"="Adding toleration to pod"  "podName"="tf2-keras-cifar10-inceptionv3-elastic-20210723-045126-launcher" "scheduler"="default" "toleration"={"key":"celeste/hostname","operator":"Exists","effect":"NoExecute"}
I0723 17:44:55.355333    7682 placement_manager.go:147]  "msg"="Adding toleration to pod"  "podName"="tf2-keras-transformer-elastic-20210723-051950-worker-0" "scheduler"="default" "toleration"={"key":"celeste/hostname","operator":"Equal","value":"gpu5","effect":"NoExecute"}
I0723 17:45:26.634052    7682 scheduler.go:474]  "msg"="Training job completed"  "elaspedTotalSeconds"=1696.767703255 "gpuTotalSeconds"=1650.056633126 "job"="tf2-keras-cifar10-vgg16-elastic-20210723-051707" "ranTotalSeconds"=1595.054522517 "scheduler"="default" "waitedTotalSeconds"=101.713180738
I0723 17:45:26.634208    7682 scheduler.go:135]  "msg"="Received resched event, may be blocked because of rate limit"  "blockedUntil"="2021-07-23T17:46:33.091310929+08:00" "lastResched"="2021-07-23T17:44:33.091310929+08:00" "received"="2021-07-23T17:45:26.634103915+08:00" "scheduler"="default"
I0723 17:46:33.091353    7682 scheduler.go:159]  "msg"="Started resched"  "scheduler"="default"
I0723 17:46:33.091393    7682 scheduler.go:193]  "msg"="Updating all jobs info"  "scheduler"="default"
I0723 17:46:33.099018    7682 afsl.go:65]  "msg"="Finished scheduling"  "algorithm"="AFS-L" "freeGpu"=0 "result"={"tf2-keras-cifar10-inceptionv3-elastic-20210723-042550":1,"tf2-keras-cifar10-inceptionv3-elastic-20210723-042602":2,"tf2-keras-cifar10-inceptionv3-elastic-20210723-044237":1,"tf2-keras-cifar10-inceptionv3-elastic-20210723-045126":1,"tf2-keras-cifar10-inceptionv3-elastic-20210723-045447":1,"tf2-keras-cifar10-inceptionv3-elastic-20210723-045501":1,"tf2-keras-cifar10-resnet50-elastic-20210723-051925":3,"tf2-keras-transformer-elastic-20210723-051649":1,"tf2-keras-transformer-elastic-20210723-051950":1} "scheduler"="default"
I0723 17:46:33.099276    7682 scheduler.go:384]  "msg"="Trying to delete multiple training jobs"  "jobs"=[] "scheduler"="default"
I0723 17:46:33.099483    7682 scheduler.go:342]  "msg"="Trying to scale multiple training jobs"  "jobs"=[] "scheduler"="default"
I0723 17:46:33.099677    7682 scheduler.go:292]  "msg"="Trying to start multiple training jobs"  "jobs"=[] "scheduler"="default"
I0723 17:46:33.099905    7682 scheduler.go:342]  "msg"="Trying to scale multiple training jobs"  "jobs"=["tf2-keras-cifar10-resnet50-elastic-20210723-051925","tf2-keras-cifar10-inceptionv3-elastic-20210723-042602"] "scheduler"="default"
I0723 17:46:33.140900    7682 placement_manager.go:166]  "msg"="Started job placements adjustment"  "scheduler"="default"
I0723 17:46:33.140972    7682 placement_manager.go:192]  "msg"="Releasing slots"  "jobs"={"tf2-keras-cifar10-inceptionv3-elastic-20210723-042550":{},"tf2-keras-cifar10-inceptionv3-elastic-20210723-042602":{},"tf2-keras-cifar10-inceptionv3-elastic-20210723-044237":{},"tf2-keras-cifar10-inceptionv3-elastic-20210723-045126":{},"tf2-keras-cifar10-inceptionv3-elastic-20210723-045447":{},"tf2-keras-cifar10-inceptionv3-elastic-20210723-045501":{},"tf2-keras-cifar10-resnet50-elastic-20210723-051925":{},"tf2-keras-cifar10-vgg16-elastic-20210723-051707":{},"tf2-keras-transformer-elastic-20210723-051649":{},"tf2-keras-transformer-elastic-20210723-051950":{}} "nodes"={"gpu3":{},"gpu4":{},"gpu5":{}} "scheduler"="default"
I0723 17:46:33.141051    7682 placement_manager.go:250]  "msg"="Released slots"  "jobs"={"tf2-keras-cifar10-inceptionv3-elastic-20210723-042550":{},"tf2-keras-cifar10-inceptionv3-elastic-20210723-042602":{},"tf2-keras-cifar10-inceptionv3-elastic-20210723-044237":{},"tf2-keras-cifar10-inceptionv3-elastic-20210723-045126":{},"tf2-keras-cifar10-inceptionv3-elastic-20210723-045447":{},"tf2-keras-cifar10-inceptionv3-elastic-20210723-045501":{},"tf2-keras-cifar10-resnet50-elastic-20210723-051925":{},"tf2-keras-cifar10-vgg16-elastic-20210723-051707":{},"tf2-keras-transformer-elastic-20210723-051649":{},"tf2-keras-transformer-elastic-20210723-051950":{}} "nodes"={"gpu3":{},"gpu4":{},"gpu5":{}} "scheduler"="default"
I0723 17:46:33.141541    7682 placement_manager.go:305]  "msg"="Found best-fit"  "crossNode"=0 "nodes"=[{},{},{}] "requests"=[{},{},{},{},{},{},{},{},{},{},{},{},{},{},{},{},{},{}] "scheduler"="default"
I0723 17:46:33.141860    7682 placement_manager.go:339]  "msg"="nodeStates updated"  "new"={"gpu3":{},"gpu4":{},"gpu5":{}} "old"={"gpu3":{},"gpu4":{},"gpu5":{}} "scheduler"="default" "score"=7
I0723 17:46:33.142675    7682 placement_manager.go:387]  "msg"="jobStates updated"  "new"={"tf2-keras-cifar10-inceptionv3-elastic-20210723-042550":{},"tf2-keras-cifar10-inceptionv3-elastic-20210723-042602":{},"tf2-keras-cifar10-inceptionv3-elastic-20210723-044237":{},"tf2-keras-cifar10-inceptionv3-elastic-20210723-045126":{},"tf2-keras-cifar10-inceptionv3-elastic-20210723-045447":{},"tf2-keras-cifar10-inceptionv3-elastic-20210723-045501":{},"tf2-keras-cifar10-resnet50-elastic-20210723-051925":{},"tf2-keras-transformer-elastic-20210723-051649":{},"tf2-keras-transformer-elastic-20210723-051950":{}} "old"={"tf2-keras-cifar10-inceptionv3-elastic-20210723-042550":{},"tf2-keras-cifar10-inceptionv3-elastic-20210723-042602":{},"tf2-keras-cifar10-inceptionv3-elastic-20210723-044237":{},"tf2-keras-cifar10-inceptionv3-elastic-20210723-045126":{},"tf2-keras-cifar10-inceptionv3-elastic-20210723-045447":{},"tf2-keras-cifar10-inceptionv3-elastic-20210723-045501":{},"tf2-keras-cifar10-resnet50-elastic-20210723-051925":{},"tf2-keras-cifar10-vgg16-elastic-20210723-051707":{},"tf2-keras-transformer-elastic-20210723-051649":{},"tf2-keras-transformer-elastic-20210723-051950":{}} "scheduler"="default"
I0723 17:46:33.144308    7682 placement_manager.go:434]  "msg"="podNodeName updated"  "launchersToDelete"=3 "new"={"tf2-keras-cifar10-inceptionv3-elastic-20210723-042550-worker-0":"gpu3","tf2-keras-cifar10-inceptionv3-elastic-20210723-042602-worker-0":"gpu4","tf2-keras-cifar10-inceptionv3-elastic-20210723-042602-worker-1":"gpu4","tf2-keras-cifar10-inceptionv3-elastic-20210723-044237-worker-0":"gpu4","tf2-keras-cifar10-inceptionv3-elastic-20210723-045126-worker-0":"gpu5","tf2-keras-cifar10-inceptionv3-elastic-20210723-045447-worker-0":"gpu4","tf2-keras-cifar10-inceptionv3-elastic-20210723-045501-worker-0":"gpu5","tf2-keras-cifar10-resnet50-elastic-20210723-051925-worker-0":"gpu3","tf2-keras-cifar10-resnet50-elastic-20210723-051925-worker-1":"gpu3","tf2-keras-cifar10-resnet50-elastic-20210723-051925-worker-2":"gpu3","tf2-keras-transformer-elastic-20210723-051649-worker-0":"gpu5","tf2-keras-transformer-elastic-20210723-051950-worker-0":"gpu5"} "old"={"tf2-keras-cifar10-inceptionv3-elastic-20210723-042550-worker-0":"gpu4","tf2-keras-cifar10-inceptionv3-elastic-20210723-042602-worker-0":"gpu4","tf2-keras-cifar10-inceptionv3-elastic-20210723-044237-worker-0":"gpu5","tf2-keras-cifar10-inceptionv3-elastic-20210723-045126-worker-0":"gpu4","tf2-keras-cifar10-inceptionv3-elastic-20210723-045447-worker-0":"gpu4","tf2-keras-cifar10-inceptionv3-elastic-20210723-045501-worker-0":"gpu5","tf2-keras-cifar10-resnet50-elastic-20210723-051925-worker-0":"gpu3","tf2-keras-cifar10-resnet50-elastic-20210723-051925-worker-1":"gpu3","tf2-keras-cifar10-vgg16-elastic-20210723-051707-worker-0":"gpu3","tf2-keras-cifar10-vgg16-elastic-20210723-051707-worker-1":"gpu3","tf2-keras-transformer-elastic-20210723-051649-worker-0":"gpu5","tf2-keras-transformer-elastic-20210723-051950-worker-0":"gpu5"} "scheduler"="default" "workersToDelete"=3
I0723 17:46:33.144652    7682 placement_manager.go:451]  "msg"="Deleting pod that need migration"  "podName"="tf2-keras-cifar10-inceptionv3-elastic-20210723-045126-worker-0" "scheduler"="default"
I0723 17:46:33.153343    7682 placement_manager.go:451]  "msg"="Deleting pod that need migration"  "podName"="tf2-keras-cifar10-inceptionv3-elastic-20210723-045126-launcher" "scheduler"="default"
I0723 17:46:33.164914    7682 placement_manager.go:147]  "msg"="Adding toleration to pod"  "podName"="tf2-keras-cifar10-resnet50-elastic-20210723-051925-worker-2" "scheduler"="default" "toleration"={"key":"celeste/hostname","operator":"Equal","value":"gpu3","effect":"NoExecute"}
I0723 17:46:33.170214    7682 placement_manager.go:451]  "msg"="Deleting pod that need migration"  "podName"="tf2-keras-cifar10-inceptionv3-elastic-20210723-042550-worker-0" "scheduler"="default"
I0723 17:46:33.192499    7682 placement_manager.go:451]  "msg"="Deleting pod that need migration"  "podName"="tf2-keras-cifar10-inceptionv3-elastic-20210723-042550-launcher" "scheduler"="default"
I0723 17:46:33.221887    7682 placement_manager.go:451]  "msg"="Deleting pod that need migration"  "podName"="tf2-keras-cifar10-inceptionv3-elastic-20210723-044237-worker-0" "scheduler"="default"
I0723 17:46:33.230523    7682 placement_manager.go:451]  "msg"="Deleting pod that need migration"  "podName"="tf2-keras-cifar10-inceptionv3-elastic-20210723-044237-launcher" "scheduler"="default"
I0723 17:46:33.241724    7682 placement_manager.go:183]  "msg"="Finished job placements adjustment"  "scheduler"="default"
I0723 17:46:33.241956    7682 scheduler.go:182]  "msg"="Finished resched"  "scheduler"="default"
I0723 17:46:33.254964    7682 placement_manager.go:147]  "msg"="Adding toleration to pod"  "podName"="tf2-keras-cifar10-inceptionv3-elastic-20210723-042602-worker-1" "scheduler"="default" "toleration"={"key":"celeste/hostname","operator":"Equal","value":"gpu4","effect":"NoExecute"}
I0723 17:46:40.748485    7682 placement_manager.go:147]  "msg"="Adding toleration to pod"  "podName"="tf2-keras-cifar10-inceptionv3-elastic-20210723-044237-launcher" "scheduler"="default" "toleration"={"key":"celeste/hostname","operator":"Exists","effect":"NoExecute"}
I0723 17:46:44.604123    7682 placement_manager.go:147]  "msg"="Adding toleration to pod"  "podName"="tf2-keras-cifar10-inceptionv3-elastic-20210723-045126-worker-0" "scheduler"="default" "toleration"={"key":"celeste/hostname","operator":"Equal","value":"gpu5","effect":"NoExecute"}
I0723 17:46:44.645853    7682 placement_manager.go:147]  "msg"="Adding toleration to pod"  "podName"="tf2-keras-cifar10-inceptionv3-elastic-20210723-045126-launcher" "scheduler"="default" "toleration"={"key":"celeste/hostname","operator":"Exists","effect":"NoExecute"}
I0723 17:46:44.673098    7682 placement_manager.go:147]  "msg"="Adding toleration to pod"  "podName"="tf2-keras-cifar10-inceptionv3-elastic-20210723-042550-worker-0" "scheduler"="default" "toleration"={"key":"celeste/hostname","operator":"Equal","value":"gpu3","effect":"NoExecute"}
I0723 17:46:44.684594    7682 placement_manager.go:147]  "msg"="Adding toleration to pod"  "podName"="tf2-keras-cifar10-inceptionv3-elastic-20210723-042550-launcher" "scheduler"="default" "toleration"={"key":"celeste/hostname","operator":"Exists","effect":"NoExecute"}
I0723 17:46:49.754923    7682 placement_manager.go:147]  "msg"="Adding toleration to pod"  "podName"="tf2-keras-cifar10-inceptionv3-elastic-20210723-044237-worker-0" "scheduler"="default" "toleration"={"key":"celeste/hostname","operator":"Equal","value":"gpu4","effect":"NoExecute"}
I0723 17:47:45.329697    7682 scheduler.go:474]  "msg"="Training job completed"  "elaspedTotalSeconds"=1698.825128662 "gpuTotalSeconds"=1885.063830323 "job"="tf2-keras-cifar10-resnet50-elastic-20210723-051925" "ranTotalSeconds"=1615.054419751 "scheduler"="default" "waitedTotalSeconds"=83.770708911
I0723 17:47:45.329833    7682 scheduler.go:135]  "msg"="Received resched event, may be blocked because of rate limit"  "blockedUntil"="2021-07-23T17:48:33.242182217+08:00" "lastResched"="2021-07-23T17:46:33.242182217+08:00" "received"="2021-07-23T17:47:45.329717764+08:00" "scheduler"="default"
I0723 17:48:33.242260    7682 scheduler.go:159]  "msg"="Started resched"  "scheduler"="default"
I0723 17:48:33.242361    7682 scheduler.go:193]  "msg"="Updating all jobs info"  "scheduler"="default"
I0723 17:48:33.250678    7682 afsl.go:65]  "msg"="Finished scheduling"  "algorithm"="AFS-L" "freeGpu"=0 "result"={"tf2-keras-cifar10-inceptionv3-elastic-20210723-042550":2,"tf2-keras-cifar10-inceptionv3-elastic-20210723-042602":3,"tf2-keras-cifar10-inceptionv3-elastic-20210723-044237":1,"tf2-keras-cifar10-inceptionv3-elastic-20210723-045126":1,"tf2-keras-cifar10-inceptionv3-elastic-20210723-045447":1,"tf2-keras-cifar10-inceptionv3-elastic-20210723-045501":1,"tf2-keras-transformer-elastic-20210723-051649":2,"tf2-keras-transformer-elastic-20210723-051950":1} "scheduler"="default"
I0723 17:48:33.250946    7682 scheduler.go:384]  "msg"="Trying to delete multiple training jobs"  "jobs"=[] "scheduler"="default"
I0723 17:48:33.251157    7682 scheduler.go:342]  "msg"="Trying to scale multiple training jobs"  "jobs"=[] "scheduler"="default"
I0723 17:48:33.251385    7682 scheduler.go:292]  "msg"="Trying to start multiple training jobs"  "jobs"=[] "scheduler"="default"
I0723 17:48:33.251614    7682 scheduler.go:342]  "msg"="Trying to scale multiple training jobs"  "jobs"=["tf2-keras-transformer-elastic-20210723-051649","tf2-keras-cifar10-inceptionv3-elastic-20210723-042602","tf2-keras-cifar10-inceptionv3-elastic-20210723-042550"] "scheduler"="default"
I0723 17:48:33.302883    7682 placement_manager.go:166]  "msg"="Started job placements adjustment"  "scheduler"="default"
I0723 17:48:33.302988    7682 placement_manager.go:192]  "msg"="Releasing slots"  "jobs"={"tf2-keras-cifar10-inceptionv3-elastic-20210723-042550":{},"tf2-keras-cifar10-inceptionv3-elastic-20210723-042602":{},"tf2-keras-cifar10-inceptionv3-elastic-20210723-044237":{},"tf2-keras-cifar10-inceptionv3-elastic-20210723-045126":{},"tf2-keras-cifar10-inceptionv3-elastic-20210723-045447":{},"tf2-keras-cifar10-inceptionv3-elastic-20210723-045501":{},"tf2-keras-cifar10-resnet50-elastic-20210723-051925":{},"tf2-keras-transformer-elastic-20210723-051649":{},"tf2-keras-transformer-elastic-20210723-051950":{}} "nodes"={"gpu3":{},"gpu4":{},"gpu5":{}} "scheduler"="default"
I0723 17:48:33.303062    7682 placement_manager.go:250]  "msg"="Released slots"  "jobs"={"tf2-keras-cifar10-inceptionv3-elastic-20210723-042550":{},"tf2-keras-cifar10-inceptionv3-elastic-20210723-042602":{},"tf2-keras-cifar10-inceptionv3-elastic-20210723-044237":{},"tf2-keras-cifar10-inceptionv3-elastic-20210723-045126":{},"tf2-keras-cifar10-inceptionv3-elastic-20210723-045447":{},"tf2-keras-cifar10-inceptionv3-elastic-20210723-045501":{},"tf2-keras-cifar10-resnet50-elastic-20210723-051925":{},"tf2-keras-transformer-elastic-20210723-051649":{},"tf2-keras-transformer-elastic-20210723-051950":{}} "nodes"={"gpu3":{},"gpu4":{},"gpu5":{}} "scheduler"="default"
I0723 17:48:33.303599    7682 placement_manager.go:305]  "msg"="Found best-fit"  "crossNode"=0 "nodes"=[{},{},{}] "requests"=[{},{},{},{},{},{},{},{},{},{},{},{},{},{},{},{}] "scheduler"="default"
I0723 17:48:33.303948    7682 placement_manager.go:339]  "msg"="nodeStates updated"  "new"={"gpu3":{},"gpu4":{},"gpu5":{}} "old"={"gpu3":{},"gpu4":{},"gpu5":{}} "scheduler"="default" "score"=5
I0723 17:48:33.304304    7682 placement_manager.go:387]  "msg"="jobStates updated"  "new"={"tf2-keras-cifar10-inceptionv3-elastic-20210723-042550":{},"tf2-keras-cifar10-inceptionv3-elastic-20210723-042602":{},"tf2-keras-cifar10-inceptionv3-elastic-20210723-044237":{},"tf2-keras-cifar10-inceptionv3-elastic-20210723-045126":{},"tf2-keras-cifar10-inceptionv3-elastic-20210723-045447":{},"tf2-keras-cifar10-inceptionv3-elastic-20210723-045501":{},"tf2-keras-transformer-elastic-20210723-051649":{},"tf2-keras-transformer-elastic-20210723-051950":{}} "old"={"tf2-keras-cifar10-inceptionv3-elastic-20210723-042550":{},"tf2-keras-cifar10-inceptionv3-elastic-20210723-042602":{},"tf2-keras-cifar10-inceptionv3-elastic-20210723-044237":{},"tf2-keras-cifar10-inceptionv3-elastic-20210723-045126":{},"tf2-keras-cifar10-inceptionv3-elastic-20210723-045447":{},"tf2-keras-cifar10-inceptionv3-elastic-20210723-045501":{},"tf2-keras-cifar10-resnet50-elastic-20210723-051925":{},"tf2-keras-transformer-elastic-20210723-051649":{},"tf2-keras-transformer-elastic-20210723-051950":{}} "scheduler"="default"
I0723 17:48:33.304739    7682 placement_manager.go:434]  "msg"="podNodeName updated"  "launchersToDelete"=3 "new"={"tf2-keras-cifar10-inceptionv3-elastic-20210723-042550-worker-0":"gpu3","tf2-keras-cifar10-inceptionv3-elastic-20210723-042550-worker-1":"gpu3","tf2-keras-cifar10-inceptionv3-elastic-20210723-042602-worker-0":"gpu4","tf2-keras-cifar10-inceptionv3-elastic-20210723-042602-worker-1":"gpu4","tf2-keras-cifar10-inceptionv3-elastic-20210723-042602-worker-2":"gpu4","tf2-keras-cifar10-inceptionv3-elastic-20210723-044237-worker-0":"gpu5","tf2-keras-cifar10-inceptionv3-elastic-20210723-045126-worker-0":"gpu5","tf2-keras-cifar10-inceptionv3-elastic-20210723-045447-worker-0":"gpu5","tf2-keras-cifar10-inceptionv3-elastic-20210723-045501-worker-0":"gpu5","tf2-keras-transformer-elastic-20210723-051649-worker-0":"gpu3","tf2-keras-transformer-elastic-20210723-051649-worker-1":"gpu3","tf2-keras-transformer-elastic-20210723-051950-worker-0":"gpu4"} "old"={"tf2-keras-cifar10-inceptionv3-elastic-20210723-042550-worker-0":"gpu3","tf2-keras-cifar10-inceptionv3-elastic-20210723-042602-worker-0":"gpu4","tf2-keras-cifar10-inceptionv3-elastic-20210723-042602-worker-1":"gpu4","tf2-keras-cifar10-inceptionv3-elastic-20210723-044237-worker-0":"gpu4","tf2-keras-cifar10-inceptionv3-elastic-20210723-045126-worker-0":"gpu5","tf2-keras-cifar10-inceptionv3-elastic-20210723-045447-worker-0":"gpu4","tf2-keras-cifar10-inceptionv3-elastic-20210723-045501-worker-0":"gpu5","tf2-keras-cifar10-resnet50-elastic-20210723-051925-worker-0":"gpu3","tf2-keras-cifar10-resnet50-elastic-20210723-051925-worker-1":"gpu3","tf2-keras-cifar10-resnet50-elastic-20210723-051925-worker-2":"gpu3","tf2-keras-transformer-elastic-20210723-051649-worker-0":"gpu5","tf2-keras-transformer-elastic-20210723-051950-worker-0":"gpu5"} "scheduler"="default" "workersToDelete"=4
I0723 17:48:33.305061    7682 placement_manager.go:451]  "msg"="Deleting pod that need migration"  "podName"="tf2-keras-transformer-elastic-20210723-051950-worker-0" "scheduler"="default"
I0723 17:48:33.309004    7682 placement_manager.go:451]  "msg"="Deleting pod that need migration"  "podName"="tf2-keras-transformer-elastic-20210723-051950-launcher" "scheduler"="default"
I0723 17:48:33.315424    7682 placement_manager.go:451]  "msg"="Deleting pod that need migration"  "podName"="tf2-keras-transformer-elastic-20210723-051649-worker-0" "scheduler"="default"
I0723 17:48:33.326366    7682 placement_manager.go:451]  "msg"="Deleting pod that need migration"  "podName"="tf2-keras-cifar10-inceptionv3-elastic-20210723-044237-worker-0" "scheduler"="default"
I0723 17:48:33.340845    7682 placement_manager.go:147]  "msg"="Adding toleration to pod"  "podName"="tf2-keras-cifar10-inceptionv3-elastic-20210723-042602-worker-2" "scheduler"="default" "toleration"={"key":"celeste/hostname","operator":"Equal","value":"gpu4","effect":"NoExecute"}
I0723 17:48:33.344831    7682 placement_manager.go:451]  "msg"="Deleting pod that need migration"  "podName"="tf2-keras-cifar10-inceptionv3-elastic-20210723-044237-launcher" "scheduler"="default"
I0723 17:48:33.352956    7682 placement_manager.go:451]  "msg"="Deleting pod that need migration"  "podName"="tf2-keras-cifar10-inceptionv3-elastic-20210723-045447-worker-0" "scheduler"="default"
I0723 17:48:33.359974    7682 placement_manager.go:451]  "msg"="Deleting pod that need migration"  "podName"="tf2-keras-cifar10-inceptionv3-elastic-20210723-045447-launcher" "scheduler"="default"
I0723 17:48:33.363983    7682 placement_manager.go:183]  "msg"="Finished job placements adjustment"  "scheduler"="default"
I0723 17:48:33.364229    7682 scheduler.go:182]  "msg"="Finished resched"  "scheduler"="default"
I0723 17:48:33.512199    7682 placement_manager.go:147]  "msg"="Adding toleration to pod"  "podName"="tf2-keras-transformer-elastic-20210723-051649-worker-1" "scheduler"="default" "toleration"={"key":"celeste/hostname","operator":"Equal","value":"gpu3","effect":"NoExecute"}
I0723 17:48:33.914417    7682 placement_manager.go:147]  "msg"="Adding toleration to pod"  "podName"="tf2-keras-cifar10-inceptionv3-elastic-20210723-042550-worker-1" "scheduler"="default" "toleration"={"key":"celeste/hostname","operator":"Equal","value":"gpu3","effect":"NoExecute"}
I0723 17:48:41.098060    7682 placement_manager.go:147]  "msg"="Adding toleration to pod"  "podName"="tf2-keras-transformer-elastic-20210723-051950-worker-0" "scheduler"="default" "toleration"={"key":"celeste/hostname","operator":"Equal","value":"gpu4","effect":"NoExecute"}
I0723 17:48:42.136370    7682 placement_manager.go:147]  "msg"="Adding toleration to pod"  "podName"="tf2-keras-transformer-elastic-20210723-051649-worker-0" "scheduler"="default" "toleration"={"key":"celeste/hostname","operator":"Equal","value":"gpu3","effect":"NoExecute"}
I0723 17:48:42.946136    7682 placement_manager.go:147]  "msg"="Adding toleration to pod"  "podName"="tf2-keras-cifar10-inceptionv3-elastic-20210723-045447-worker-0" "scheduler"="default" "toleration"={"key":"celeste/hostname","operator":"Equal","value":"gpu5","effect":"NoExecute"}
I0723 17:48:42.982218    7682 placement_manager.go:147]  "msg"="Adding toleration to pod"  "podName"="tf2-keras-cifar10-inceptionv3-elastic-20210723-045447-launcher" "scheduler"="default" "toleration"={"key":"celeste/hostname","operator":"Exists","effect":"NoExecute"}
I0723 17:48:42.995715    7682 placement_manager.go:147]  "msg"="Adding toleration to pod"  "podName"="tf2-keras-transformer-elastic-20210723-051950-launcher" "scheduler"="default" "toleration"={"key":"celeste/hostname","operator":"Exists","effect":"NoExecute"}
I0723 17:48:43.089206    7682 placement_manager.go:147]  "msg"="Adding toleration to pod"  "podName"="tf2-keras-cifar10-inceptionv3-elastic-20210723-044237-worker-0" "scheduler"="default" "toleration"={"key":"celeste/hostname","operator":"Equal","value":"gpu5","effect":"NoExecute"}
I0723 17:48:52.448337    7682 placement_manager.go:147]  "msg"="Adding toleration to pod"  "podName"="tf2-keras-cifar10-inceptionv3-elastic-20210723-044237-launcher" "scheduler"="default" "toleration"={"key":"celeste/hostname","operator":"Exists","effect":"NoExecute"}
I0723 17:51:38.658891    7682 scheduler.go:474]  "msg"="Training job completed"  "elaspedTotalSeconds"=5131.256174124 "gpuTotalSeconds"=6560.20442972 "job"="tf2-keras-cifar10-inceptionv3-elastic-20210723-042602" "ranTotalSeconds"=5025.158417044 "scheduler"="default" "waitedTotalSeconds"=106.09775708
I0723 17:51:38.659203    7682 scheduler.go:135]  "msg"="Received resched event, may be blocked because of rate limit"  "blockedUntil"="2021-07-23T17:50:33.364437443+08:00" "lastResched"="2021-07-23T17:48:33.364437443+08:00" "received"="2021-07-23T17:51:38.658955318+08:00" "scheduler"="default"
I0723 17:51:38.659779    7682 scheduler.go:159]  "msg"="Started resched"  "scheduler"="default"
I0723 17:51:38.659861    7682 scheduler.go:193]  "msg"="Updating all jobs info"  "scheduler"="default"
I0723 17:51:38.668527    7682 afsl.go:65]  "msg"="Finished scheduling"  "algorithm"="AFS-L" "freeGpu"=0 "result"={"tf2-keras-cifar10-inceptionv3-elastic-20210723-042550":3,"tf2-keras-cifar10-inceptionv3-elastic-20210723-044237":2,"tf2-keras-cifar10-inceptionv3-elastic-20210723-045126":1,"tf2-keras-cifar10-inceptionv3-elastic-20210723-045447":1,"tf2-keras-cifar10-inceptionv3-elastic-20210723-045501":1,"tf2-keras-transformer-elastic-20210723-051649":2,"tf2-keras-transformer-elastic-20210723-051950":2} "scheduler"="default"
I0723 17:51:38.668928    7682 scheduler.go:384]  "msg"="Trying to delete multiple training jobs"  "jobs"=[] "scheduler"="default"
I0723 17:51:38.669209    7682 scheduler.go:342]  "msg"="Trying to scale multiple training jobs"  "jobs"=[] "scheduler"="default"
I0723 17:51:38.669457    7682 scheduler.go:292]  "msg"="Trying to start multiple training jobs"  "jobs"=[] "scheduler"="default"
I0723 17:51:38.669771    7682 scheduler.go:342]  "msg"="Trying to scale multiple training jobs"  "jobs"=["tf2-keras-transformer-elastic-20210723-051950","tf2-keras-cifar10-inceptionv3-elastic-20210723-042550","tf2-keras-cifar10-inceptionv3-elastic-20210723-044237"] "scheduler"="default"
I0723 17:51:38.719663    7682 placement_manager.go:166]  "msg"="Started job placements adjustment"  "scheduler"="default"
I0723 17:51:38.719782    7682 placement_manager.go:192]  "msg"="Releasing slots"  "jobs"={"tf2-keras-cifar10-inceptionv3-elastic-20210723-042550":{},"tf2-keras-cifar10-inceptionv3-elastic-20210723-042602":{},"tf2-keras-cifar10-inceptionv3-elastic-20210723-044237":{},"tf2-keras-cifar10-inceptionv3-elastic-20210723-045126":{},"tf2-keras-cifar10-inceptionv3-elastic-20210723-045447":{},"tf2-keras-cifar10-inceptionv3-elastic-20210723-045501":{},"tf2-keras-transformer-elastic-20210723-051649":{},"tf2-keras-transformer-elastic-20210723-051950":{}} "nodes"={"gpu3":{},"gpu4":{},"gpu5":{}} "scheduler"="default"
I0723 17:51:38.719863    7682 placement_manager.go:250]  "msg"="Released slots"  "jobs"={"tf2-keras-cifar10-inceptionv3-elastic-20210723-042550":{},"tf2-keras-cifar10-inceptionv3-elastic-20210723-042602":{},"tf2-keras-cifar10-inceptionv3-elastic-20210723-044237":{},"tf2-keras-cifar10-inceptionv3-elastic-20210723-045126":{},"tf2-keras-cifar10-inceptionv3-elastic-20210723-045447":{},"tf2-keras-cifar10-inceptionv3-elastic-20210723-045501":{},"tf2-keras-transformer-elastic-20210723-051649":{},"tf2-keras-transformer-elastic-20210723-051950":{}} "nodes"={"gpu3":{},"gpu4":{},"gpu5":{}} "scheduler"="default"
I0723 17:51:38.720327    7682 placement_manager.go:305]  "msg"="Found best-fit"  "crossNode"=0 "nodes"=[{},{},{}] "requests"=[{},{},{},{},{},{},{},{},{},{},{},{},{},{}] "scheduler"="default"
I0723 17:51:38.720722    7682 placement_manager.go:339]  "msg"="nodeStates updated"  "new"={"gpu3":{},"gpu4":{},"gpu5":{}} "old"={"gpu3":{},"gpu4":{},"gpu5":{}} "scheduler"="default" "score"=4
I0723 17:51:38.721142    7682 placement_manager.go:387]  "msg"="jobStates updated"  "new"={"tf2-keras-cifar10-inceptionv3-elastic-20210723-042550":{},"tf2-keras-cifar10-inceptionv3-elastic-20210723-044237":{},"tf2-keras-cifar10-inceptionv3-elastic-20210723-045126":{},"tf2-keras-cifar10-inceptionv3-elastic-20210723-045447":{},"tf2-keras-cifar10-inceptionv3-elastic-20210723-045501":{},"tf2-keras-transformer-elastic-20210723-051649":{},"tf2-keras-transformer-elastic-20210723-051950":{}} "old"={"tf2-keras-cifar10-inceptionv3-elastic-20210723-042550":{},"tf2-keras-cifar10-inceptionv3-elastic-20210723-042602":{},"tf2-keras-cifar10-inceptionv3-elastic-20210723-044237":{},"tf2-keras-cifar10-inceptionv3-elastic-20210723-045126":{},"tf2-keras-cifar10-inceptionv3-elastic-20210723-045447":{},"tf2-keras-cifar10-inceptionv3-elastic-20210723-045501":{},"tf2-keras-transformer-elastic-20210723-051649":{},"tf2-keras-transformer-elastic-20210723-051950":{}} "scheduler"="default"
I0723 17:51:38.721643    7682 placement_manager.go:434]  "msg"="podNodeName updated"  "launchersToDelete"=2 "new"={"tf2-keras-cifar10-inceptionv3-elastic-20210723-042550-worker-0":"gpu3","tf2-keras-cifar10-inceptionv3-elastic-20210723-042550-worker-1":"gpu3","tf2-keras-cifar10-inceptionv3-elastic-20210723-042550-worker-2":"gpu3","tf2-keras-cifar10-inceptionv3-elastic-20210723-044237-worker-0":"gpu4","tf2-keras-cifar10-inceptionv3-elastic-20210723-044237-worker-1":"gpu4","tf2-keras-cifar10-inceptionv3-elastic-20210723-045126-worker-0":"gpu3","tf2-keras-cifar10-inceptionv3-elastic-20210723-045447-worker-0":"gpu5","tf2-keras-cifar10-inceptionv3-elastic-20210723-045501-worker-0":"gpu5","tf2-keras-transformer-elastic-20210723-051649-worker-0":"gpu4","tf2-keras-transformer-elastic-20210723-051649-worker-1":"gpu4","tf2-keras-transformer-elastic-20210723-051950-worker-0":"gpu5","tf2-keras-transformer-elastic-20210723-051950-worker-1":"gpu5"} "old"={"tf2-keras-cifar10-inceptionv3-elastic-20210723-042550-worker-0":"gpu3","tf2-keras-cifar10-inceptionv3-elastic-20210723-042550-worker-1":"gpu3","tf2-keras-cifar10-inceptionv3-elastic-20210723-042602-worker-0":"gpu4","tf2-keras-cifar10-inceptionv3-elastic-20210723-042602-worker-1":"gpu4","tf2-keras-cifar10-inceptionv3-elastic-20210723-042602-worker-2":"gpu4","tf2-keras-cifar10-inceptionv3-elastic-20210723-044237-worker-0":"gpu5","tf2-keras-cifar10-inceptionv3-elastic-20210723-045126-worker-0":"gpu5","tf2-keras-cifar10-inceptionv3-elastic-20210723-045447-worker-0":"gpu5","tf2-keras-cifar10-inceptionv3-elastic-20210723-045501-worker-0":"gpu5","tf2-keras-transformer-elastic-20210723-051649-worker-0":"gpu3","tf2-keras-transformer-elastic-20210723-051649-worker-1":"gpu3","tf2-keras-transformer-elastic-20210723-051950-worker-0":"gpu4"} "scheduler"="default" "workersToDelete"=5
I0723 17:51:38.722199    7682 placement_manager.go:451]  "msg"="Deleting pod that need migration"  "podName"="tf2-keras-cifar10-inceptionv3-elastic-20210723-045126-worker-0" "scheduler"="default"
I0723 17:51:38.742294    7682 placement_manager.go:451]  "msg"="Deleting pod that need migration"  "podName"="tf2-keras-cifar10-inceptionv3-elastic-20210723-045126-launcher" "scheduler"="default"
I0723 17:51:38.747880    7682 placement_manager.go:451]  "msg"="Deleting pod that need migration"  "podName"="tf2-keras-cifar10-inceptionv3-elastic-20210723-044237-worker-0" "scheduler"="default"
I0723 17:51:38.751570    7682 placement_manager.go:451]  "msg"="Deleting pod that need migration"  "podName"="tf2-keras-transformer-elastic-20210723-051649-worker-0" "scheduler"="default"
I0723 17:51:38.755513    7682 placement_manager.go:451]  "msg"="Deleting pod that need migration"  "podName"="tf2-keras-transformer-elastic-20210723-051649-worker-1" "scheduler"="default"
I0723 17:51:38.759356    7682 placement_manager.go:451]  "msg"="Deleting pod that need migration"  "podName"="tf2-keras-transformer-elastic-20210723-051649-launcher" "scheduler"="default"
I0723 17:51:38.763007    7682 placement_manager.go:451]  "msg"="Deleting pod that need migration"  "podName"="tf2-keras-transformer-elastic-20210723-051950-worker-0" "scheduler"="default"
I0723 17:51:38.767371    7682 placement_manager.go:183]  "msg"="Finished job placements adjustment"  "scheduler"="default"
I0723 17:51:38.767688    7682 scheduler.go:182]  "msg"="Finished resched"  "scheduler"="default"
I0723 17:51:39.480998    7682 placement_manager.go:147]  "msg"="Adding toleration to pod"  "podName"="tf2-keras-cifar10-inceptionv3-elastic-20210723-042550-worker-2" "scheduler"="default" "toleration"={"key":"celeste/hostname","operator":"Equal","value":"gpu3","effect":"NoExecute"}
I0723 17:51:39.676841    7682 placement_manager.go:147]  "msg"="Adding toleration to pod"  "podName"="tf2-keras-cifar10-inceptionv3-elastic-20210723-044237-worker-1" "scheduler"="default" "toleration"={"key":"celeste/hostname","operator":"Equal","value":"gpu4","effect":"NoExecute"}
I0723 17:51:46.117817    7682 placement_manager.go:147]  "msg"="Adding toleration to pod"  "podName"="tf2-keras-transformer-elastic-20210723-051649-launcher" "scheduler"="default" "toleration"={"key":"celeste/hostname","operator":"Exists","effect":"NoExecute"}
I0723 17:51:47.743932    7682 placement_manager.go:147]  "msg"="Adding toleration to pod"  "podName"="tf2-keras-transformer-elastic-20210723-051950-worker-0" "scheduler"="default" "toleration"={"key":"celeste/hostname","operator":"Equal","value":"gpu5","effect":"NoExecute"}
I0723 17:51:51.134939    7682 placement_manager.go:147]  "msg"="Adding toleration to pod"  "podName"="tf2-keras-cifar10-inceptionv3-elastic-20210723-045126-launcher" "scheduler"="default" "toleration"={"key":"celeste/hostname","operator":"Exists","effect":"NoExecute"}
I0723 17:51:52.313842    7682 placement_manager.go:147]  "msg"="Adding toleration to pod"  "podName"="tf2-keras-cifar10-inceptionv3-elastic-20210723-045126-worker-0" "scheduler"="default" "toleration"={"key":"celeste/hostname","operator":"Equal","value":"gpu3","effect":"NoExecute"}
I0723 17:51:52.713325    7682 placement_manager.go:147]  "msg"="Adding toleration to pod"  "podName"="tf2-keras-cifar10-inceptionv3-elastic-20210723-044237-worker-0" "scheduler"="default" "toleration"={"key":"celeste/hostname","operator":"Equal","value":"gpu4","effect":"NoExecute"}
I0723 17:51:53.840810    7682 placement_manager.go:147]  "msg"="Adding toleration to pod"  "podName"="tf2-keras-transformer-elastic-20210723-051649-worker-1" "scheduler"="default" "toleration"={"key":"celeste/hostname","operator":"Equal","value":"gpu4","effect":"NoExecute"}
I0723 17:51:53.873591    7682 placement_manager.go:147]  "msg"="Adding toleration to pod"  "podName"="tf2-keras-transformer-elastic-20210723-051649-worker-0" "scheduler"="default" "toleration"={"key":"celeste/hostname","operator":"Equal","value":"gpu4","effect":"NoExecute"}
I0723 17:58:07.041223    7682 scheduler.go:474]  "msg"="Training job completed"  "elaspedTotalSeconds"=5533.640922386 "gpuTotalSeconds"=6729.077288331 "job"="tf2-keras-cifar10-inceptionv3-elastic-20210723-042550" "ranTotalSeconds"=5408.636733829 "scheduler"="default" "waitedTotalSeconds"=125.004188557
I0723 17:58:07.041399    7682 scheduler.go:135]  "msg"="Received resched event, may be blocked because of rate limit"  "blockedUntil"="2021-07-23T17:53:38.767982882+08:00" "lastResched"="2021-07-23T17:51:38.767982882+08:00" "received"="2021-07-23T17:58:07.041281011+08:00" "scheduler"="default"
I0723 17:58:07.042033    7682 scheduler.go:159]  "msg"="Started resched"  "scheduler"="default"
I0723 17:58:07.042125    7682 scheduler.go:193]  "msg"="Updating all jobs info"  "scheduler"="default"
I0723 17:58:07.048740    7682 afsl.go:65]  "msg"="Finished scheduling"  "algorithm"="AFS-L" "freeGpu"=0 "result"={"tf2-keras-cifar10-inceptionv3-elastic-20210723-044237":3,"tf2-keras-cifar10-inceptionv3-elastic-20210723-045126":1,"tf2-keras-cifar10-inceptionv3-elastic-20210723-045447":2,"tf2-keras-cifar10-inceptionv3-elastic-20210723-045501":2,"tf2-keras-transformer-elastic-20210723-051649":2,"tf2-keras-transformer-elastic-20210723-051950":2} "scheduler"="default"
I0723 17:58:07.049051    7682 scheduler.go:384]  "msg"="Trying to delete multiple training jobs"  "jobs"=[] "scheduler"="default"
I0723 17:58:07.049312    7682 scheduler.go:342]  "msg"="Trying to scale multiple training jobs"  "jobs"=[] "scheduler"="default"
I0723 17:58:07.049514    7682 scheduler.go:292]  "msg"="Trying to start multiple training jobs"  "jobs"=[] "scheduler"="default"
I0723 17:58:07.049774    7682 scheduler.go:342]  "msg"="Trying to scale multiple training jobs"  "jobs"=["tf2-keras-cifar10-inceptionv3-elastic-20210723-044237","tf2-keras-cifar10-inceptionv3-elastic-20210723-045447","tf2-keras-cifar10-inceptionv3-elastic-20210723-045501"] "scheduler"="default"
I0723 17:58:07.094382    7682 placement_manager.go:166]  "msg"="Started job placements adjustment"  "scheduler"="default"
I0723 17:58:07.094461    7682 placement_manager.go:192]  "msg"="Releasing slots"  "jobs"={"tf2-keras-cifar10-inceptionv3-elastic-20210723-042550":{},"tf2-keras-cifar10-inceptionv3-elastic-20210723-044237":{},"tf2-keras-cifar10-inceptionv3-elastic-20210723-045126":{},"tf2-keras-cifar10-inceptionv3-elastic-20210723-045447":{},"tf2-keras-cifar10-inceptionv3-elastic-20210723-045501":{},"tf2-keras-transformer-elastic-20210723-051649":{},"tf2-keras-transformer-elastic-20210723-051950":{}} "nodes"={"gpu3":{},"gpu4":{},"gpu5":{}} "scheduler"="default"
I0723 17:58:07.094522    7682 placement_manager.go:250]  "msg"="Released slots"  "jobs"={"tf2-keras-cifar10-inceptionv3-elastic-20210723-042550":{},"tf2-keras-cifar10-inceptionv3-elastic-20210723-044237":{},"tf2-keras-cifar10-inceptionv3-elastic-20210723-045126":{},"tf2-keras-cifar10-inceptionv3-elastic-20210723-045447":{},"tf2-keras-cifar10-inceptionv3-elastic-20210723-045501":{},"tf2-keras-transformer-elastic-20210723-051649":{},"tf2-keras-transformer-elastic-20210723-051950":{}} "nodes"={"gpu3":{},"gpu4":{},"gpu5":{}} "scheduler"="default"
I0723 17:58:07.094988    7682 placement_manager.go:305]  "msg"="Found best-fit"  "crossNode"=0 "nodes"=[{},{},{}] "requests"=[{},{},{},{},{},{},{},{},{},{},{},{}] "scheduler"="default"
I0723 17:58:07.095289    7682 placement_manager.go:339]  "msg"="nodeStates updated"  "new"={"gpu3":{},"gpu4":{},"gpu5":{}} "old"={"gpu3":{},"gpu4":{},"gpu5":{}} "scheduler"="default" "score"=5
I0723 17:58:07.095560    7682 placement_manager.go:387]  "msg"="jobStates updated"  "new"={"tf2-keras-cifar10-inceptionv3-elastic-20210723-044237":{},"tf2-keras-cifar10-inceptionv3-elastic-20210723-045126":{},"tf2-keras-cifar10-inceptionv3-elastic-20210723-045447":{},"tf2-keras-cifar10-inceptionv3-elastic-20210723-045501":{},"tf2-keras-transformer-elastic-20210723-051649":{},"tf2-keras-transformer-elastic-20210723-051950":{}} "old"={"tf2-keras-cifar10-inceptionv3-elastic-20210723-042550":{},"tf2-keras-cifar10-inceptionv3-elastic-20210723-044237":{},"tf2-keras-cifar10-inceptionv3-elastic-20210723-045126":{},"tf2-keras-cifar10-inceptionv3-elastic-20210723-045447":{},"tf2-keras-cifar10-inceptionv3-elastic-20210723-045501":{},"tf2-keras-transformer-elastic-20210723-051649":{},"tf2-keras-transformer-elastic-20210723-051950":{}} "scheduler"="default"
I0723 17:58:07.095910    7682 placement_manager.go:434]  "msg"="podNodeName updated"  "launchersToDelete"=1 "new"={"tf2-keras-cifar10-inceptionv3-elastic-20210723-044237-worker-0":"gpu3","tf2-keras-cifar10-inceptionv3-elastic-20210723-044237-worker-1":"gpu3","tf2-keras-cifar10-inceptionv3-elastic-20210723-044237-worker-2":"gpu3","tf2-keras-cifar10-inceptionv3-elastic-20210723-045126-worker-0":"gpu3","tf2-keras-cifar10-inceptionv3-elastic-20210723-045447-worker-0":"gpu5","tf2-keras-cifar10-inceptionv3-elastic-20210723-045447-worker-1":"gpu5","tf2-keras-cifar10-inceptionv3-elastic-20210723-045501-worker-0":"gpu5","tf2-keras-cifar10-inceptionv3-elastic-20210723-045501-worker-1":"gpu5","tf2-keras-transformer-elastic-20210723-051649-worker-0":"gpu4","tf2-keras-transformer-elastic-20210723-051649-worker-1":"gpu4","tf2-keras-transformer-elastic-20210723-051950-worker-0":"gpu4","tf2-keras-transformer-elastic-20210723-051950-worker-1":"gpu4"} "old"={"tf2-keras-cifar10-inceptionv3-elastic-20210723-042550-worker-0":"gpu3","tf2-keras-cifar10-inceptionv3-elastic-20210723-042550-worker-1":"gpu3","tf2-keras-cifar10-inceptionv3-elastic-20210723-042550-worker-2":"gpu3","tf2-keras-cifar10-inceptionv3-elastic-20210723-044237-worker-0":"gpu4","tf2-keras-cifar10-inceptionv3-elastic-20210723-044237-worker-1":"gpu4","tf2-keras-cifar10-inceptionv3-elastic-20210723-045126-worker-0":"gpu3","tf2-keras-cifar10-inceptionv3-elastic-20210723-045447-worker-0":"gpu5","tf2-keras-cifar10-inceptionv3-elastic-20210723-045501-worker-0":"gpu5","tf2-keras-transformer-elastic-20210723-051649-worker-0":"gpu4","tf2-keras-transformer-elastic-20210723-051649-worker-1":"gpu4","tf2-keras-transformer-elastic-20210723-051950-worker-0":"gpu5","tf2-keras-transformer-elastic-20210723-051950-worker-1":"gpu5"} "scheduler"="default" "workersToDelete"=4
I0723 17:58:07.096190    7682 placement_manager.go:451]  "msg"="Deleting pod that need migration"  "podName"="tf2-keras-transformer-elastic-20210723-051950-worker-0" "scheduler"="default"
I0723 17:58:07.102519    7682 placement_manager.go:451]  "msg"="Deleting pod that need migration"  "podName"="tf2-keras-transformer-elastic-20210723-051950-worker-1" "scheduler"="default"
I0723 17:58:07.110895    7682 placement_manager.go:451]  "msg"="Deleting pod that need migration"  "podName"="tf2-keras-transformer-elastic-20210723-051950-launcher" "scheduler"="default"
I0723 17:58:07.115001    7682 placement_manager.go:451]  "msg"="Deleting pod that need migration"  "podName"="tf2-keras-cifar10-inceptionv3-elastic-20210723-044237-worker-0" "scheduler"="default"
I0723 17:58:07.118630    7682 placement_manager.go:451]  "msg"="Deleting pod that need migration"  "podName"="tf2-keras-cifar10-inceptionv3-elastic-20210723-044237-worker-1" "scheduler"="default"
I0723 17:58:07.122690    7682 placement_manager.go:183]  "msg"="Finished job placements adjustment"  "scheduler"="default"
I0723 17:58:07.122893    7682 scheduler.go:182]  "msg"="Finished resched"  "scheduler"="default"
I0723 17:58:08.032654    7682 placement_manager.go:147]  "msg"="Adding toleration to pod"  "podName"="tf2-keras-cifar10-inceptionv3-elastic-20210723-045447-worker-1" "scheduler"="default" "toleration"={"key":"celeste/hostname","operator":"Equal","value":"gpu5","effect":"NoExecute"}
I0723 17:58:08.232202    7682 placement_manager.go:147]  "msg"="Adding toleration to pod"  "podName"="tf2-keras-cifar10-inceptionv3-elastic-20210723-045501-worker-1" "scheduler"="default" "toleration"={"key":"celeste/hostname","operator":"Equal","value":"gpu5","effect":"NoExecute"}
I0723 17:58:08.431241    7682 placement_manager.go:147]  "msg"="Adding toleration to pod"  "podName"="tf2-keras-transformer-elastic-20210723-051950-worker-1" "scheduler"="default" "toleration"={"key":"celeste/hostname","operator":"Equal","value":"gpu4","effect":"NoExecute"}
I0723 17:58:14.507520    7682 placement_manager.go:147]  "msg"="Adding toleration to pod"  "podName"="tf2-keras-transformer-elastic-20210723-051950-worker-0" "scheduler"="default" "toleration"={"key":"celeste/hostname","operator":"Equal","value":"gpu4","effect":"NoExecute"}
I0723 17:58:14.932857    7682 placement_manager.go:147]  "msg"="Adding toleration to pod"  "podName"="tf2-keras-transformer-elastic-20210723-051950-launcher" "scheduler"="default" "toleration"={"key":"celeste/hostname","operator":"Exists","effect":"NoExecute"}
I0723 17:58:25.334039    7682 placement_manager.go:147]  "msg"="Adding toleration to pod"  "podName"="tf2-keras-cifar10-inceptionv3-elastic-20210723-044237-worker-1" "scheduler"="default" "toleration"={"key":"celeste/hostname","operator":"Equal","value":"gpu3","effect":"NoExecute"}
I0723 17:58:26.141041    7682 placement_manager.go:147]  "msg"="Adding toleration to pod"  "podName"="tf2-keras-cifar10-inceptionv3-elastic-20210723-044237-worker-0" "scheduler"="default" "toleration"={"key":"celeste/hostname","operator":"Equal","value":"gpu3","effect":"NoExecute"}
I0723 17:59:23.929382    7682 placement_manager.go:147]  "msg"="Adding toleration to pod"  "podName"="tf2-keras-cifar10-inceptionv3-elastic-20210723-044237-worker-2" "scheduler"="default" "toleration"={"key":"celeste/hostname","operator":"Equal","value":"gpu3","effect":"NoExecute"}
I0723 18:00:26.223118    7682 scheduler.go:474]  "msg"="Training job completed"  "elaspedTotalSeconds"=2614.749643865 "gpuTotalSeconds"=3089.766706695 "job"="tf2-keras-transformer-elastic-20210723-051649" "ranTotalSeconds"=2374.741956259 "scheduler"="default" "waitedTotalSeconds"=240.007687606
I0723 18:00:26.223296    7682 scheduler.go:135]  "msg"="Received resched event, may be blocked because of rate limit"  "blockedUntil"="2021-07-23T18:00:07.123051745+08:00" "lastResched"="2021-07-23T17:58:07.123051745+08:00" "received"="2021-07-23T18:00:26.223152383+08:00" "scheduler"="default"
I0723 18:00:26.223859    7682 scheduler.go:159]  "msg"="Started resched"  "scheduler"="default"
I0723 18:00:26.223912    7682 scheduler.go:193]  "msg"="Updating all jobs info"  "scheduler"="default"
I0723 18:00:26.231657    7682 afsl.go:65]  "msg"="Finished scheduling"  "algorithm"="AFS-L" "freeGpu"=0 "result"={"tf2-keras-cifar10-inceptionv3-elastic-20210723-044237":3,"tf2-keras-cifar10-inceptionv3-elastic-20210723-045126":1,"tf2-keras-cifar10-inceptionv3-elastic-20210723-045447":2,"tf2-keras-cifar10-inceptionv3-elastic-20210723-045501":3,"tf2-keras-transformer-elastic-20210723-051950":3} "scheduler"="default"
I0723 18:00:26.232290    7682 scheduler.go:384]  "msg"="Trying to delete multiple training jobs"  "jobs"=[] "scheduler"="default"
I0723 18:00:26.232763    7682 scheduler.go:342]  "msg"="Trying to scale multiple training jobs"  "jobs"=[] "scheduler"="default"
I0723 18:00:26.233513    7682 scheduler.go:292]  "msg"="Trying to start multiple training jobs"  "jobs"=[] "scheduler"="default"
I0723 18:00:26.234151    7682 scheduler.go:342]  "msg"="Trying to scale multiple training jobs"  "jobs"=["tf2-keras-transformer-elastic-20210723-051950","tf2-keras-cifar10-inceptionv3-elastic-20210723-045501"] "scheduler"="default"
I0723 18:00:26.265459    7682 placement_manager.go:166]  "msg"="Started job placements adjustment"  "scheduler"="default"
I0723 18:00:26.265535    7682 placement_manager.go:192]  "msg"="Releasing slots"  "jobs"={"tf2-keras-cifar10-inceptionv3-elastic-20210723-044237":{},"tf2-keras-cifar10-inceptionv3-elastic-20210723-045126":{},"tf2-keras-cifar10-inceptionv3-elastic-20210723-045447":{},"tf2-keras-cifar10-inceptionv3-elastic-20210723-045501":{},"tf2-keras-transformer-elastic-20210723-051649":{},"tf2-keras-transformer-elastic-20210723-051950":{}} "nodes"={"gpu3":{},"gpu4":{},"gpu5":{}} "scheduler"="default"
I0723 18:00:26.265593    7682 placement_manager.go:250]  "msg"="Released slots"  "jobs"={"tf2-keras-cifar10-inceptionv3-elastic-20210723-044237":{},"tf2-keras-cifar10-inceptionv3-elastic-20210723-045126":{},"tf2-keras-cifar10-inceptionv3-elastic-20210723-045447":{},"tf2-keras-cifar10-inceptionv3-elastic-20210723-045501":{},"tf2-keras-transformer-elastic-20210723-051649":{},"tf2-keras-transformer-elastic-20210723-051950":{}} "nodes"={"gpu3":{},"gpu4":{},"gpu5":{}} "scheduler"="default"
I0723 18:00:26.266045    7682 placement_manager.go:305]  "msg"="Found best-fit"  "crossNode"=0 "nodes"=[{},{},{}] "requests"=[{},{},{},{},{},{},{},{},{},{}] "scheduler"="default"
I0723 18:00:26.266336    7682 placement_manager.go:339]  "msg"="nodeStates updated"  "new"={"gpu3":{},"gpu4":{},"gpu5":{}} "old"={"gpu3":{},"gpu4":{},"gpu5":{}} "scheduler"="default" "score"=9
I0723 18:00:26.266560    7682 placement_manager.go:387]  "msg"="jobStates updated"  "new"={"tf2-keras-cifar10-inceptionv3-elastic-20210723-044237":{},"tf2-keras-cifar10-inceptionv3-elastic-20210723-045126":{},"tf2-keras-cifar10-inceptionv3-elastic-20210723-045447":{},"tf2-keras-cifar10-inceptionv3-elastic-20210723-045501":{},"tf2-keras-transformer-elastic-20210723-051950":{}} "old"={"tf2-keras-cifar10-inceptionv3-elastic-20210723-044237":{},"tf2-keras-cifar10-inceptionv3-elastic-20210723-045126":{},"tf2-keras-cifar10-inceptionv3-elastic-20210723-045447":{},"tf2-keras-cifar10-inceptionv3-elastic-20210723-045501":{},"tf2-keras-transformer-elastic-20210723-051649":{},"tf2-keras-transformer-elastic-20210723-051950":{}} "scheduler"="default"
I0723 18:00:26.266934    7682 placement_manager.go:434]  "msg"="podNodeName updated"  "launchersToDelete"=0 "new"={"tf2-keras-cifar10-inceptionv3-elastic-20210723-044237-worker-0":"gpu3","tf2-keras-cifar10-inceptionv3-elastic-20210723-044237-worker-1":"gpu3","tf2-keras-cifar10-inceptionv3-elastic-20210723-044237-worker-2":"gpu3","tf2-keras-cifar10-inceptionv3-elastic-20210723-045126-worker-0":"gpu3","tf2-keras-cifar10-inceptionv3-elastic-20210723-045447-worker-0":"gpu5","tf2-keras-cifar10-inceptionv3-elastic-20210723-045447-worker-1":"gpu4","tf2-keras-cifar10-inceptionv3-elastic-20210723-045447-worker-2":"gpu4","tf2-keras-cifar10-inceptionv3-elastic-20210723-045501-worker-0":"gpu5","tf2-keras-cifar10-inceptionv3-elastic-20210723-045501-worker-1":"gpu5","tf2-keras-cifar10-inceptionv3-elastic-20210723-045501-worker-2":"gpu5","tf2-keras-transformer-elastic-20210723-051950-worker-0":"gpu4","tf2-keras-transformer-elastic-20210723-051950-worker-1":"gpu4","tf2-keras-transformer-elastic-20210723-051950-worker-2":"gpu4"} "old"={"tf2-keras-cifar10-inceptionv3-elastic-20210723-044237-worker-0":"gpu3","tf2-keras-cifar10-inceptionv3-elastic-20210723-044237-worker-1":"gpu3","tf2-keras-cifar10-inceptionv3-elastic-20210723-044237-worker-2":"gpu3","tf2-keras-cifar10-inceptionv3-elastic-20210723-045126-worker-0":"gpu3","tf2-keras-cifar10-inceptionv3-elastic-20210723-045447-worker-0":"gpu5","tf2-keras-cifar10-inceptionv3-elastic-20210723-045447-worker-1":"gpu5","tf2-keras-cifar10-inceptionv3-elastic-20210723-045501-worker-0":"gpu5","tf2-keras-cifar10-inceptionv3-elastic-20210723-045501-worker-1":"gpu5","tf2-keras-transformer-elastic-20210723-051649-worker-0":"gpu4","tf2-keras-transformer-elastic-20210723-051649-worker-1":"gpu4","tf2-keras-transformer-elastic-20210723-051950-worker-0":"gpu4","tf2-keras-transformer-elastic-20210723-051950-worker-1":"gpu4"} "scheduler"="default" "workersToDelete"=1
I0723 18:00:26.267233    7682 placement_manager.go:451]  "msg"="Deleting pod that need migration"  "podName"="tf2-keras-cifar10-inceptionv3-elastic-20210723-045447-worker-1" "scheduler"="default"
I0723 18:00:26.271712    7682 placement_manager.go:183]  "msg"="Finished job placements adjustment"  "scheduler"="default"
I0723 18:00:26.271910    7682 scheduler.go:182]  "msg"="Finished resched"  "scheduler"="default"
I0723 18:00:26.273073    7682 placement_manager.go:147]  "msg"="Adding toleration to pod"  "podName"="tf2-keras-transformer-elastic-20210723-051950-worker-2" "scheduler"="default" "toleration"={"key":"celeste/hostname","operator":"Equal","value":"gpu4","effect":"NoExecute"}
I0723 18:00:26.616940    7682 placement_manager.go:147]  "msg"="Adding toleration to pod"  "podName"="tf2-keras-cifar10-inceptionv3-elastic-20210723-045501-worker-2" "scheduler"="default" "toleration"={"key":"celeste/hostname","operator":"Equal","value":"gpu5","effect":"NoExecute"}
I0723 18:00:33.900138    7682 placement_manager.go:147]  "msg"="Adding toleration to pod"  "podName"="tf2-keras-cifar10-inceptionv3-elastic-20210723-045447-worker-1" "scheduler"="default" "toleration"={"key":"celeste/hostname","operator":"Equal","value":"gpu4","effect":"NoExecute"}
I0723 18:04:48.359015    7682 scheduler.go:474]  "msg"="Training job completed"  "elaspedTotalSeconds"=2693.87243913 "gpuTotalSeconds"=3565.120817136 "job"="tf2-keras-transformer-elastic-20210723-051950" "ranTotalSeconds"=2515.085696527 "scheduler"="default" "waitedTotalSeconds"=178.786742603
I0723 18:04:48.359171    7682 scheduler.go:135]  "msg"="Received resched event, may be blocked because of rate limit"  "blockedUntil"="2021-07-23T18:02:26.272056636+08:00" "lastResched"="2021-07-23T18:00:26.272056636+08:00" "received"="2021-07-23T18:04:48.359062161+08:00" "scheduler"="default"
I0723 18:04:48.359720    7682 scheduler.go:159]  "msg"="Started resched"  "scheduler"="default"
I0723 18:04:48.359758    7682 scheduler.go:193]  "msg"="Updating all jobs info"  "scheduler"="default"
I0723 18:04:48.364583    7682 afsl.go:65]  "msg"="Finished scheduling"  "algorithm"="AFS-L" "freeGpu"=0 "result"={"tf2-keras-cifar10-inceptionv3-elastic-20210723-044237":4,"tf2-keras-cifar10-inceptionv3-elastic-20210723-045126":3,"tf2-keras-cifar10-inceptionv3-elastic-20210723-045447":1,"tf2-keras-cifar10-inceptionv3-elastic-20210723-045501":4} "scheduler"="default"
I0723 18:04:48.364958    7682 scheduler.go:384]  "msg"="Trying to delete multiple training jobs"  "jobs"=[] "scheduler"="default"
I0723 18:04:48.365271    7682 scheduler.go:342]  "msg"="Trying to scale multiple training jobs"  "jobs"=["tf2-keras-cifar10-inceptionv3-elastic-20210723-045447"] "scheduler"="default"
I0723 18:04:48.381831    7682 scheduler.go:292]  "msg"="Trying to start multiple training jobs"  "jobs"=[] "scheduler"="default"
I0723 18:04:48.382181    7682 scheduler.go:342]  "msg"="Trying to scale multiple training jobs"  "jobs"=["tf2-keras-cifar10-inceptionv3-elastic-20210723-045126","tf2-keras-cifar10-inceptionv3-elastic-20210723-045501","tf2-keras-cifar10-inceptionv3-elastic-20210723-044237"] "scheduler"="default"
I0723 18:04:48.460305    7682 placement_manager.go:166]  "msg"="Started job placements adjustment"  "scheduler"="default"
I0723 18:04:48.460385    7682 placement_manager.go:192]  "msg"="Releasing slots"  "jobs"={"tf2-keras-cifar10-inceptionv3-elastic-20210723-044237":{},"tf2-keras-cifar10-inceptionv3-elastic-20210723-045126":{},"tf2-keras-cifar10-inceptionv3-elastic-20210723-045447":{},"tf2-keras-cifar10-inceptionv3-elastic-20210723-045501":{},"tf2-keras-transformer-elastic-20210723-051950":{}} "nodes"={"gpu3":{},"gpu4":{},"gpu5":{}} "scheduler"="default"
I0723 18:04:48.460447    7682 placement_manager.go:250]  "msg"="Released slots"  "jobs"={"tf2-keras-cifar10-inceptionv3-elastic-20210723-044237":{},"tf2-keras-cifar10-inceptionv3-elastic-20210723-045126":{},"tf2-keras-cifar10-inceptionv3-elastic-20210723-045447":{},"tf2-keras-cifar10-inceptionv3-elastic-20210723-045501":{},"tf2-keras-transformer-elastic-20210723-051950":{}} "nodes"={"gpu3":{},"gpu4":{},"gpu5":{}} "scheduler"="default"
I0723 18:04:48.461073    7682 placement_manager.go:305]  "msg"="Found best-fit"  "crossNode"=0 "nodes"=[{},{},{}] "requests"=[{},{},{},{},{},{},{},{}] "scheduler"="default"
I0723 18:04:48.461466    7682 placement_manager.go:339]  "msg"="nodeStates updated"  "new"={"gpu3":{},"gpu4":{},"gpu5":{}} "old"={"gpu3":{},"gpu4":{},"gpu5":{}} "scheduler"="default" "score"=6
I0723 18:04:48.461840    7682 placement_manager.go:387]  "msg"="jobStates updated"  "new"={"tf2-keras-cifar10-inceptionv3-elastic-20210723-044237":{},"tf2-keras-cifar10-inceptionv3-elastic-20210723-045126":{},"tf2-keras-cifar10-inceptionv3-elastic-20210723-045447":{},"tf2-keras-cifar10-inceptionv3-elastic-20210723-045501":{}} "old"={"tf2-keras-cifar10-inceptionv3-elastic-20210723-044237":{},"tf2-keras-cifar10-inceptionv3-elastic-20210723-045126":{},"tf2-keras-cifar10-inceptionv3-elastic-20210723-045447":{},"tf2-keras-cifar10-inceptionv3-elastic-20210723-045501":{},"tf2-keras-transformer-elastic-20210723-051950":{}} "scheduler"="default"
I0723 18:04:48.462584    7682 placement_manager.go:434]  "msg"="podNodeName updated"  "launchersToDelete"=1 "new"={"tf2-keras-cifar10-inceptionv3-elastic-20210723-044237-worker-0":"gpu3","tf2-keras-cifar10-inceptionv3-elastic-20210723-044237-worker-1":"gpu3","tf2-keras-cifar10-inceptionv3-elastic-20210723-044237-worker-2":"gpu3","tf2-keras-cifar10-inceptionv3-elastic-20210723-044237-worker-3":"gpu3","tf2-keras-cifar10-inceptionv3-elastic-20210723-045126-worker-0":"gpu4","tf2-keras-cifar10-inceptionv3-elastic-20210723-045126-worker-1":"gpu4","tf2-keras-cifar10-inceptionv3-elastic-20210723-045126-worker-2":"gpu4","tf2-keras-cifar10-inceptionv3-elastic-20210723-045447-worker-0":"gpu4","tf2-keras-cifar10-inceptionv3-elastic-20210723-045501-worker-0":"gpu5","tf2-keras-cifar10-inceptionv3-elastic-20210723-045501-worker-1":"gpu5","tf2-keras-cifar10-inceptionv3-elastic-20210723-045501-worker-2":"gpu5","tf2-keras-cifar10-inceptionv3-elastic-20210723-045501-worker-3":"gpu5"} "old"={"tf2-keras-cifar10-inceptionv3-elastic-20210723-044237-worker-0":"gpu3","tf2-keras-cifar10-inceptionv3-elastic-20210723-044237-worker-1":"gpu3","tf2-keras-cifar10-inceptionv3-elastic-20210723-044237-worker-2":"gpu3","tf2-keras-cifar10-inceptionv3-elastic-20210723-045126-worker-0":"gpu3","tf2-keras-cifar10-inceptionv3-elastic-20210723-045447-worker-0":"gpu5","tf2-keras-cifar10-inceptionv3-elastic-20210723-045447-worker-1":"gpu4","tf2-keras-cifar10-inceptionv3-elastic-20210723-045447-worker-2":"gpu4","tf2-keras-cifar10-inceptionv3-elastic-20210723-045501-worker-0":"gpu5","tf2-keras-cifar10-inceptionv3-elastic-20210723-045501-worker-1":"gpu5","tf2-keras-cifar10-inceptionv3-elastic-20210723-045501-worker-2":"gpu5","tf2-keras-transformer-elastic-20210723-051950-worker-0":"gpu4","tf2-keras-transformer-elastic-20210723-051950-worker-1":"gpu4","tf2-keras-transformer-elastic-20210723-051950-worker-2":"gpu4"} "scheduler"="default" "workersToDelete"=2
I0723 18:04:48.463066    7682 placement_manager.go:451]  "msg"="Deleting pod that need migration"  "podName"="tf2-keras-cifar10-inceptionv3-elastic-20210723-045126-worker-0" "scheduler"="default"
I0723 18:04:48.470997    7682 placement_manager.go:451]  "msg"="Deleting pod that need migration"  "podName"="tf2-keras-cifar10-inceptionv3-elastic-20210723-045447-worker-0" "scheduler"="default"
I0723 18:04:48.476800    7682 placement_manager.go:451]  "msg"="Deleting pod that need migration"  "podName"="tf2-keras-cifar10-inceptionv3-elastic-20210723-045447-launcher" "scheduler"="default"
I0723 18:04:48.484028    7682 placement_manager.go:183]  "msg"="Finished job placements adjustment"  "scheduler"="default"
I0723 18:04:48.484333    7682 scheduler.go:182]  "msg"="Finished resched"  "scheduler"="default"
I0723 18:04:49.551647    7682 placement_manager.go:147]  "msg"="Adding toleration to pod"  "podName"="tf2-keras-cifar10-inceptionv3-elastic-20210723-045126-worker-1" "scheduler"="default" "toleration"={"key":"celeste/hostname","operator":"Equal","value":"gpu4","effect":"NoExecute"}
I0723 18:04:49.946502    7682 placement_manager.go:147]  "msg"="Adding toleration to pod"  "podName"="tf2-keras-cifar10-inceptionv3-elastic-20210723-045126-worker-2" "scheduler"="default" "toleration"={"key":"celeste/hostname","operator":"Equal","value":"gpu4","effect":"NoExecute"}
I0723 18:04:51.146089    7682 placement_manager.go:147]  "msg"="Adding toleration to pod"  "podName"="tf2-keras-cifar10-inceptionv3-elastic-20210723-045501-worker-3" "scheduler"="default" "toleration"={"key":"celeste/hostname","operator":"Equal","value":"gpu5","effect":"NoExecute"}
I0723 18:04:51.346444    7682 placement_manager.go:147]  "msg"="Adding toleration to pod"  "podName"="tf2-keras-cifar10-inceptionv3-elastic-20210723-044237-worker-3" "scheduler"="default" "toleration"={"key":"celeste/hostname","operator":"Equal","value":"gpu3","effect":"NoExecute"}
I0723 18:04:56.593700    7682 placement_manager.go:147]  "msg"="Adding toleration to pod"  "podName"="tf2-keras-cifar10-inceptionv3-elastic-20210723-045447-launcher" "scheduler"="default" "toleration"={"key":"celeste/hostname","operator":"Exists","effect":"NoExecute"}
I0723 18:04:56.612399    7682 placement_manager.go:147]  "msg"="Adding toleration to pod"  "podName"="tf2-keras-cifar10-inceptionv3-elastic-20210723-045447-worker-0" "scheduler"="default" "toleration"={"key":"celeste/hostname","operator":"Equal","value":"gpu4","effect":"NoExecute"}
I0723 18:04:56.646926    7682 placement_manager.go:147]  "msg"="Adding toleration to pod"  "podName"="tf2-keras-cifar10-inceptionv3-elastic-20210723-045126-worker-0" "scheduler"="default" "toleration"={"key":"celeste/hostname","operator":"Equal","value":"gpu4","effect":"NoExecute"}
I0723 18:05:00.691432    7682 scheduler.go:474]  "msg"="Training job completed"  "elaspedTotalSeconds"=4941.022958529 "gpuTotalSeconds"=5710.186487481 "job"="tf2-keras-cifar10-inceptionv3-elastic-20210723-044237" "ranTotalSeconds"=4355.141254101 "scheduler"="default" "waitedTotalSeconds"=585.881704428
I0723 18:05:00.691609    7682 scheduler.go:135]  "msg"="Received resched event, may be blocked because of rate limit"  "blockedUntil"="2021-07-23T18:06:48.484545546+08:00" "lastResched"="2021-07-23T18:04:48.484545546+08:00" "received"="2021-07-23T18:05:00.691477742+08:00" "scheduler"="default"
I0723 18:06:48.484610    7682 scheduler.go:159]  "msg"="Started resched"  "scheduler"="default"
I0723 18:06:48.484651    7682 scheduler.go:193]  "msg"="Updating all jobs info"  "scheduler"="default"
I0723 18:06:48.487934    7682 afsl.go:65]  "msg"="Finished scheduling"  "algorithm"="AFS-L" "freeGpu"=0 "result"={"tf2-keras-cifar10-inceptionv3-elastic-20210723-045126":4,"tf2-keras-cifar10-inceptionv3-elastic-20210723-045447":4,"tf2-keras-cifar10-inceptionv3-elastic-20210723-045501":4} "scheduler"="default"
I0723 18:06:48.488224    7682 scheduler.go:384]  "msg"="Trying to delete multiple training jobs"  "jobs"=[] "scheduler"="default"
I0723 18:06:48.488468    7682 scheduler.go:342]  "msg"="Trying to scale multiple training jobs"  "jobs"=[] "scheduler"="default"
I0723 18:06:48.488696    7682 scheduler.go:292]  "msg"="Trying to start multiple training jobs"  "jobs"=[] "scheduler"="default"
I0723 18:06:48.488930    7682 scheduler.go:342]  "msg"="Trying to scale multiple training jobs"  "jobs"=["tf2-keras-cifar10-inceptionv3-elastic-20210723-045126","tf2-keras-cifar10-inceptionv3-elastic-20210723-045447"] "scheduler"="default"
I0723 18:06:48.538734    7682 placement_manager.go:166]  "msg"="Started job placements adjustment"  "scheduler"="default"
I0723 18:06:48.538818    7682 placement_manager.go:192]  "msg"="Releasing slots"  "jobs"={"tf2-keras-cifar10-inceptionv3-elastic-20210723-044237":{},"tf2-keras-cifar10-inceptionv3-elastic-20210723-045126":{},"tf2-keras-cifar10-inceptionv3-elastic-20210723-045447":{},"tf2-keras-cifar10-inceptionv3-elastic-20210723-045501":{}} "nodes"={"gpu3":{},"gpu4":{},"gpu5":{}} "scheduler"="default"
I0723 18:06:48.538879    7682 placement_manager.go:250]  "msg"="Released slots"  "jobs"={"tf2-keras-cifar10-inceptionv3-elastic-20210723-044237":{},"tf2-keras-cifar10-inceptionv3-elastic-20210723-045126":{},"tf2-keras-cifar10-inceptionv3-elastic-20210723-045447":{},"tf2-keras-cifar10-inceptionv3-elastic-20210723-045501":{}} "nodes"={"gpu3":{},"gpu4":{},"gpu5":{}} "scheduler"="default"
I0723 18:06:48.539328    7682 placement_manager.go:305]  "msg"="Found best-fit"  "crossNode"=0 "nodes"=[{},{},{}] "requests"=[{},{},{},{},{},{}] "scheduler"="default"
I0723 18:06:48.539663    7682 placement_manager.go:339]  "msg"="nodeStates updated"  "new"={"gpu3":{},"gpu4":{},"gpu5":{}} "old"={"gpu3":{},"gpu4":{},"gpu5":{}} "scheduler"="default" "score"=7
I0723 18:06:48.540044    7682 placement_manager.go:387]  "msg"="jobStates updated"  "new"={"tf2-keras-cifar10-inceptionv3-elastic-20210723-045126":{},"tf2-keras-cifar10-inceptionv3-elastic-20210723-045447":{},"tf2-keras-cifar10-inceptionv3-elastic-20210723-045501":{}} "old"={"tf2-keras-cifar10-inceptionv3-elastic-20210723-044237":{},"tf2-keras-cifar10-inceptionv3-elastic-20210723-045126":{},"tf2-keras-cifar10-inceptionv3-elastic-20210723-045447":{},"tf2-keras-cifar10-inceptionv3-elastic-20210723-045501":{}} "scheduler"="default"
I0723 18:06:48.540554    7682 placement_manager.go:434]  "msg"="podNodeName updated"  "launchersToDelete"=0 "new"={"tf2-keras-cifar10-inceptionv3-elastic-20210723-045126-worker-0":"gpu4","tf2-keras-cifar10-inceptionv3-elastic-20210723-045126-worker-1":"gpu4","tf2-keras-cifar10-inceptionv3-elastic-20210723-045126-worker-2":"gpu4","tf2-keras-cifar10-inceptionv3-elastic-20210723-045126-worker-3":"gpu4","tf2-keras-cifar10-inceptionv3-elastic-20210723-045447-worker-0":"gpu3","tf2-keras-cifar10-inceptionv3-elastic-20210723-045447-worker-1":"gpu3","tf2-keras-cifar10-inceptionv3-elastic-20210723-045447-worker-2":"gpu3","tf2-keras-cifar10-inceptionv3-elastic-20210723-045447-worker-3":"gpu3","tf2-keras-cifar10-inceptionv3-elastic-20210723-045501-worker-0":"gpu5","tf2-keras-cifar10-inceptionv3-elastic-20210723-045501-worker-1":"gpu5","tf2-keras-cifar10-inceptionv3-elastic-20210723-045501-worker-2":"gpu5","tf2-keras-cifar10-inceptionv3-elastic-20210723-045501-worker-3":"gpu5"} "old"={"tf2-keras-cifar10-inceptionv3-elastic-20210723-044237-worker-0":"gpu3","tf2-keras-cifar10-inceptionv3-elastic-20210723-044237-worker-1":"gpu3","tf2-keras-cifar10-inceptionv3-elastic-20210723-044237-worker-2":"gpu3","tf2-keras-cifar10-inceptionv3-elastic-20210723-044237-worker-3":"gpu3","tf2-keras-cifar10-inceptionv3-elastic-20210723-045126-worker-0":"gpu4","tf2-keras-cifar10-inceptionv3-elastic-20210723-045126-worker-1":"gpu4","tf2-keras-cifar10-inceptionv3-elastic-20210723-045126-worker-2":"gpu4","tf2-keras-cifar10-inceptionv3-elastic-20210723-045447-worker-0":"gpu4","tf2-keras-cifar10-inceptionv3-elastic-20210723-045501-worker-0":"gpu5","tf2-keras-cifar10-inceptionv3-elastic-20210723-045501-worker-1":"gpu5","tf2-keras-cifar10-inceptionv3-elastic-20210723-045501-worker-2":"gpu5","tf2-keras-cifar10-inceptionv3-elastic-20210723-045501-worker-3":"gpu5"} "scheduler"="default" "workersToDelete"=1
I0723 18:06:48.540997    7682 placement_manager.go:451]  "msg"="Deleting pod that need migration"  "podName"="tf2-keras-cifar10-inceptionv3-elastic-20210723-045447-worker-0" "scheduler"="default"
I0723 18:06:48.548061    7682 placement_manager.go:183]  "msg"="Finished job placements adjustment"  "scheduler"="default"
I0723 18:06:48.548346    7682 scheduler.go:182]  "msg"="Finished resched"  "scheduler"="default"
I0723 18:06:48.558722    7682 placement_manager.go:147]  "msg"="Adding toleration to pod"  "podName"="tf2-keras-cifar10-inceptionv3-elastic-20210723-045126-worker-3" "scheduler"="default" "toleration"={"key":"celeste/hostname","operator":"Equal","value":"gpu4","effect":"NoExecute"}
I0723 18:06:48.601995    7682 placement_manager.go:147]  "msg"="Adding toleration to pod"  "podName"="tf2-keras-cifar10-inceptionv3-elastic-20210723-045447-worker-1" "scheduler"="default" "toleration"={"key":"celeste/hostname","operator":"Equal","value":"gpu3","effect":"NoExecute"}
I0723 18:06:48.611402    7682 placement_manager.go:147]  "msg"="Adding toleration to pod"  "podName"="tf2-keras-cifar10-inceptionv3-elastic-20210723-045447-worker-2" "scheduler"="default" "toleration"={"key":"celeste/hostname","operator":"Equal","value":"gpu3","effect":"NoExecute"}
I0723 18:06:48.620859    7682 placement_manager.go:147]  "msg"="Adding toleration to pod"  "podName"="tf2-keras-cifar10-inceptionv3-elastic-20210723-045447-worker-3" "scheduler"="default" "toleration"={"key":"celeste/hostname","operator":"Equal","value":"gpu3","effect":"NoExecute"}
I0723 18:07:04.591396    7682 placement_manager.go:147]  "msg"="Adding toleration to pod"  "podName"="tf2-keras-cifar10-inceptionv3-elastic-20210723-045447-worker-0" "scheduler"="default" "toleration"={"key":"celeste/hostname","operator":"Equal","value":"gpu3","effect":"NoExecute"}
I0723 18:10:44.941059    7682 scheduler.go:474]  "msg"="Training job completed"  "elaspedTotalSeconds"=4542.837722545 "gpuTotalSeconds"=5245.17094474 "job"="tf2-keras-cifar10-inceptionv3-elastic-20210723-045501" "ranTotalSeconds"=3505.116405968 "scheduler"="default" "waitedTotalSeconds"=1037.721316577
I0723 18:10:44.941201    7682 scheduler.go:135]  "msg"="Received resched event, may be blocked because of rate limit"  "blockedUntil"="2021-07-23T18:08:48.548589128+08:00" "lastResched"="2021-07-23T18:06:48.548589128+08:00" "received"="2021-07-23T18:10:44.941098477+08:00" "scheduler"="default"
I0723 18:10:44.941654    7682 scheduler.go:159]  "msg"="Started resched"  "scheduler"="default"
I0723 18:10:44.941698    7682 scheduler.go:193]  "msg"="Updating all jobs info"  "scheduler"="default"
I0723 18:10:44.944819    7682 afsl.go:65]  "msg"="Finished scheduling"  "algorithm"="AFS-L" "freeGpu"=4 "result"={"tf2-keras-cifar10-inceptionv3-elastic-20210723-045126":4,"tf2-keras-cifar10-inceptionv3-elastic-20210723-045447":4} "scheduler"="default"
I0723 18:10:44.945088    7682 scheduler.go:384]  "msg"="Trying to delete multiple training jobs"  "jobs"=[] "scheduler"="default"
I0723 18:10:44.945385    7682 scheduler.go:342]  "msg"="Trying to scale multiple training jobs"  "jobs"=[] "scheduler"="default"
I0723 18:10:44.945644    7682 scheduler.go:292]  "msg"="Trying to start multiple training jobs"  "jobs"=[] "scheduler"="default"
I0723 18:10:44.945931    7682 scheduler.go:342]  "msg"="Trying to scale multiple training jobs"  "jobs"=[] "scheduler"="default"
I0723 18:10:44.946216    7682 scheduler.go:180]  "msg"="Nothing changed, skipped ajust placements"  "scheduler"="default"
I0723 18:10:44.946244    7682 scheduler.go:182]  "msg"="Finished resched"  "scheduler"="default"
I0723 18:20:00.980980    7682 scheduler.go:474]  "msg"="Training job completed"  "elaspedTotalSeconds"=5312.472155715 "gpuTotalSeconds"=5359.767396641 "job"="tf2-keras-cifar10-inceptionv3-elastic-20210723-045126" "ranTotalSeconds"=2617.382788393 "scheduler"="default" "waitedTotalSeconds"=2695.089367322
I0723 18:20:00.981167    7682 scheduler.go:135]  "msg"="Received resched event, may be blocked because of rate limit"  "blockedUntil"="2021-07-23T18:12:44.9465255+08:00" "lastResched"="2021-07-23T18:10:44.9465255+08:00" "received"="2021-07-23T18:20:00.981019836+08:00" "scheduler"="default"
I0723 18:20:00.981826    7682 scheduler.go:159]  "msg"="Started resched"  "scheduler"="default"
I0723 18:20:00.981906    7682 scheduler.go:193]  "msg"="Updating all jobs info"  "scheduler"="default"
I0723 18:20:00.984123    7682 afsl.go:65]  "msg"="Finished scheduling"  "algorithm"="AFS-L" "freeGpu"=8 "result"={"tf2-keras-cifar10-inceptionv3-elastic-20210723-045447":4} "scheduler"="default"
I0723 18:20:00.984464    7682 scheduler.go:384]  "msg"="Trying to delete multiple training jobs"  "jobs"=[] "scheduler"="default"
I0723 18:20:00.984839    7682 scheduler.go:342]  "msg"="Trying to scale multiple training jobs"  "jobs"=[] "scheduler"="default"
I0723 18:20:00.985199    7682 scheduler.go:292]  "msg"="Trying to start multiple training jobs"  "jobs"=[] "scheduler"="default"
I0723 18:20:00.985431    7682 scheduler.go:342]  "msg"="Trying to scale multiple training jobs"  "jobs"=[] "scheduler"="default"
I0723 18:20:00.985631    7682 scheduler.go:180]  "msg"="Nothing changed, skipped ajust placements"  "scheduler"="default"
I0723 18:20:00.985689    7682 scheduler.go:182]  "msg"="Finished resched"  "scheduler"="default"
I0723 18:20:43.312328    7682 scheduler.go:474]  "msg"="Training job completed"  "elaspedTotalSeconds"=5151.702531759 "gpuTotalSeconds"=5655.186813093 "job"="tf2-keras-cifar10-inceptionv3-elastic-20210723-045447" "ranTotalSeconds"=2750.090640432 "scheduler"="default" "waitedTotalSeconds"=2401.611891327
I0723 18:20:43.312479    7682 scheduler.go:135]  "msg"="Received resched event, may be blocked because of rate limit"  "blockedUntil"="2021-07-23T18:22:00.985878496+08:00" "lastResched"="2021-07-23T18:20:00.985878496+08:00" "received"="2021-07-23T18:20:43.312371271+08:00" "scheduler"="default"
I0723 18:22:00.986048    7682 scheduler.go:159]  "msg"="Started resched"  "scheduler"="default"
I0723 18:22:00.986119    7682 scheduler.go:193]  "msg"="Updating all jobs info"  "scheduler"="default"
I0723 18:22:00.986871    7682 afsl.go:65]  "msg"="Finished scheduling"  "algorithm"="AFS-L" "freeGpu"=12 "result"={} "scheduler"="default"
I0723 18:22:00.987246    7682 scheduler.go:384]  "msg"="Trying to delete multiple training jobs"  "jobs"=[] "scheduler"="default"
I0723 18:22:00.987526    7682 scheduler.go:342]  "msg"="Trying to scale multiple training jobs"  "jobs"=[] "scheduler"="default"
I0723 18:22:00.987929    7682 scheduler.go:292]  "msg"="Trying to start multiple training jobs"  "jobs"=[] "scheduler"="default"
I0723 18:22:00.988234    7682 scheduler.go:342]  "msg"="Trying to scale multiple training jobs"  "jobs"=[] "scheduler"="default"
I0723 18:22:00.988514    7682 scheduler.go:180]  "msg"="Nothing changed, skipped ajust placements"  "scheduler"="default"
I0723 18:22:00.988542    7682 scheduler.go:182]  "msg"="Finished resched"  "scheduler"="default"
